t_recv,kind,type,name,detail
0.0211,Node,ADDED,kind-control-plane,taints=1
0.025,Node,ADDED,kind-worker,taints=0
0.0265,Node,ADDED,kind-worker2,taints=0
0.0279,Node,ADDED,kind-worker3,taints=0
0.0292,Node,ADDED,kind-worker4,taints=0
0.0306,Node,ADDED,kind-worker5,taints=0
0.0398,TaskRequest,ADDED,eval-sanitize-20-r0-000,phase=None job=None
0.0461,TaskRequest,MODIFIED,eval-sanitize-20-r0-000,phase=Pending job=None
0.0642,Job,ADDED,eval-sanitize-20-r0-000,
0.0692,TaskRequest,MODIFIED,eval-sanitize-20-r0-000,phase=Scheduled job=None
0.0757,Pod,ADDED,eval-sanitize-20-r0-000-jg679,phase=Pending node=None
0.0781,Job,MODIFIED,eval-sanitize-20-r0-000,
0.0878,TaskRequest,MODIFIED,eval-sanitize-20-r0-000,phase=Scheduled job=None
0.0912,Event,ADDED,eval-sanitize-20-r0-000.18d41a5866c332d2,reason=SuccessfulCreate count=1 msg=Created pod: eval-sanitize-20-r0-000-jg679
0.0964,Pod,MODIFIED,eval-sanitize-20-r0-000-jg679,phase=Pending node=kind-worker5
0.1007,Event,ADDED,eval-sanitize-20-r0-000-jg679.18d41a5867e4105c,reason=Scheduled count=None msg=Successfully assigned compute/eval-sanitize-20-r0-000-jg679 to kind-worker5
0.1053,Node,MODIFIED,kind-worker5,taints=0
0.1072,Pod,MODIFIED,eval-sanitize-20-r0-000-jg679,phase=Pending node=kind-worker5
0.1197,Node,MODIFIED,kind-worker5,taints=0
0.5218,Event,ADDED,eval-sanitize-20-r0-000-jg679.18d41a588119baf3,"reason=Pulled count=1 msg=Container image ""busybox:musl"" already present on machine"
0.5394,Event,ADDED,eval-sanitize-20-r0-000-jg679.18d41a58822e87b6,reason=Created count=1 msg=Created container: task
0.5737,Event,ADDED,eval-sanitize-20-r0-000-jg679.18d41a5884353e59,reason=Started count=1 msg=Started container task
0.706,Pod,MODIFIED,eval-sanitize-20-r0-000-jg679,phase=Running node=kind-worker5
1.0151,TaskRequest,ADDED,eval-sanitize-20-r0-001,phase=None job=None
1.0199,TaskRequest,MODIFIED,eval-sanitize-20-r0-001,phase=Pending job=None
1.0386,Job,ADDED,eval-sanitize-20-r0-001,
1.0446,TaskRequest,MODIFIED,eval-sanitize-20-r0-001,phase=Scheduled job=None
1.047,Pod,ADDED,eval-sanitize-20-r0-001-d2nvh,phase=Pending node=None
1.0499,Job,MODIFIED,eval-sanitize-20-r0-001,
1.0522,Event,ADDED,eval-sanitize-20-r0-001.18d41a58a0a15f94,reason=SuccessfulCreate count=1 msg=Created pod: eval-sanitize-20-r0-001-d2nvh
1.053,TaskRequest,MODIFIED,eval-sanitize-20-r0-001,phase=Scheduled job=None
1.066,Pod,MODIFIED,eval-sanitize-20-r0-001-d2nvh,phase=Pending node=kind-worker3
1.0698,Event,ADDED,eval-sanitize-20-r0-001-d2nvh.18d41a58a1c75e62,reason=Scheduled count=None msg=Successfully assigned compute/eval-sanitize-20-r0-001-d2nvh to kind-worker3
1.0764,Pod,MODIFIED,eval-sanitize-20-r0-001-d2nvh,phase=Pending node=kind-worker3
1.0783,Node,MODIFIED,kind-worker3,taints=0
1.0831,Job,MODIFIED,eval-sanitize-20-r0-000,
1.0899,Node,MODIFIED,kind-worker3,taints=0
1.0926,Job,MODIFIED,eval-sanitize-20-r0-000,
1.4954,Event,ADDED,eval-sanitize-20-r0-001-d2nvh.18d41a58bb0908b2,"reason=Pulled count=1 msg=Container image ""busybox:musl"" already present on machine"
1.5123,Event,ADDED,eval-sanitize-20-r0-001-d2nvh.18d41a58bc28dcd5,reason=Created count=1 msg=Created container: task
1.5447,Event,ADDED,eval-sanitize-20-r0-001-d2nvh.18d41a58be16d294,reason=Started count=1 msg=Started container task
2.016,TaskRequest,ADDED,eval-sanitize-20-r0-002,phase=None job=None
2.0253,TaskRequest,MODIFIED,eval-sanitize-20-r0-002,phase=Pending job=None
2.043,Job,ADDED,eval-sanitize-20-r0-002,
2.0502,Pod,ADDED,eval-sanitize-20-r0-002-q96k2,phase=Pending node=None
2.0504,TaskRequest,MODIFIED,eval-sanitize-20-r0-002,phase=Scheduled job=None
2.0557,Job,MODIFIED,eval-sanitize-20-r0-001,
2.0564,Job,MODIFIED,eval-sanitize-20-r0-002,
2.0568,Event,ADDED,eval-sanitize-20-r0-002.18d41a58dc6f7811,reason=SuccessfulCreate count=1 msg=Created pod: eval-sanitize-20-r0-002-q96k2
2.0588,TaskRequest,MODIFIED,eval-sanitize-20-r0-002,phase=Scheduled job=None
2.0682,Job,MODIFIED,eval-sanitize-20-r0-001,
2.0704,Pod,MODIFIED,eval-sanitize-20-r0-002-q96k2,phase=Pending node=kind-worker
2.0748,Event,ADDED,eval-sanitize-20-r0-002-q96k2.18d41a58dda3a457,reason=Scheduled count=None msg=Successfully assigned compute/eval-sanitize-20-r0-002-q96k2 to kind-worker
2.0815,Pod,MODIFIED,eval-sanitize-20-r0-002-q96k2,phase=Pending node=kind-worker
2.0836,Node,MODIFIED,kind-worker,taints=0
2.0957,Node,MODIFIED,kind-worker,taints=0
2.125,Pod,MODIFIED,eval-sanitize-20-r0-001-d2nvh,phase=Running node=kind-worker3
2.5069,Event,ADDED,eval-sanitize-20-r0-002-q96k2.18d41a58f76962ed,"reason=Pulled count=1 msg=Container image ""busybox:musl"" already present on machine"
2.5264,Event,ADDED,eval-sanitize-20-r0-002-q96k2.18d41a58f88e7cdd,reason=Created count=1 msg=Created container: task
2.5682,Event,ADDED,eval-sanitize-20-r0-002-q96k2.18d41a58fb10f8fb,reason=Started count=1 msg=Started container task
3.0138,TaskRequest,ADDED,eval-sanitize-20-r0-003,phase=None job=None
3.0186,TaskRequest,MODIFIED,eval-sanitize-20-r0-003,phase=Pending job=None
3.0367,Job,ADDED,eval-sanitize-20-r0-003,
3.0421,TaskRequest,MODIFIED,eval-sanitize-20-r0-003,phase=Scheduled job=None
3.0454,Pod,ADDED,eval-sanitize-20-r0-003-48wrn,phase=Pending node=None
3.0469,Job,MODIFIED,eval-sanitize-20-r0-003,
3.0514,Event,ADDED,eval-sanitize-20-r0-003.18d41a5917bd6c37,reason=SuccessfulCreate count=1 msg=Created pod: eval-sanitize-20-r0-003-48wrn
3.052,TaskRequest,MODIFIED,eval-sanitize-20-r0-003,phase=Scheduled job=None
3.0563,Job,MODIFIED,eval-sanitize-20-r0-002,
3.0607,Job,MODIFIED,eval-sanitize-20-r0-001,
3.0646,Pod,MODIFIED,eval-sanitize-20-r0-003-48wrn,phase=Pending node=kind-worker5
3.067,Job,MODIFIED,eval-sanitize-20-r0-002,
3.0712,Job,MODIFIED,eval-sanitize-20-r0-001,
3.0725,Event,ADDED,eval-sanitize-20-r0-003-48wrn.18d41a5918eea5d2,reason=Scheduled count=None msg=Successfully assigned compute/eval-sanitize-20-r0-003-48wrn to kind-worker5
3.074,Pod,MODIFIED,eval-sanitize-20-r0-002-q96k2,phase=Running node=kind-worker
3.0768,Node,MODIFIED,kind-worker5,taints=0
3.0804,Pod,MODIFIED,eval-sanitize-20-r0-003-48wrn,phase=Pending node=kind-worker5
3.0884,Node,MODIFIED,kind-worker5,taints=0
3.4763,Event,ADDED,eval-sanitize-20-r0-003-48wrn.18d41a59311cfd1c,"reason=Pulled count=1 msg=Container image ""busybox:musl"" already present on machine"
3.4929,Event,ADDED,eval-sanitize-20-r0-003-48wrn.18d41a5932318ce4,reason=Created count=1 msg=Created container: task
3.5273,Event,ADDED,eval-sanitize-20-r0-003-48wrn.18d41a5934428d75,reason=Started count=1 msg=Started container task
3.7115,Pod,MODIFIED,eval-sanitize-20-r0-003-48wrn,phase=Running node=kind-worker5
4.0106,TaskRequest,ADDED,eval-sanitize-20-r0-004,phase=None job=None
4.0147,TaskRequest,MODIFIED,eval-sanitize-20-r0-004,phase=Pending job=None
4.0325,Job,ADDED,eval-sanitize-20-r0-004,
4.0373,TaskRequest,MODIFIED,eval-sanitize-20-r0-004,phase=Scheduled job=None
4.041,Pod,ADDED,eval-sanitize-20-r0-004-6h9f8,phase=Pending node=None
4.0441,Job,MODIFIED,eval-sanitize-20-r0-004,
4.0457,TaskRequest,MODIFIED,eval-sanitize-20-r0-004,phase=Scheduled job=None
4.0464,Event,ADDED,eval-sanitize-20-r0-004.18d41a595316df17,reason=SuccessfulCreate count=1 msg=Created pod: eval-sanitize-20-r0-004-6h9f8
4.0496,Job,MODIFIED,eval-sanitize-20-r0-003,
4.0635,Job,MODIFIED,eval-sanitize-20-r0-003,
4.0646,Pod,MODIFIED,eval-sanitize-20-r0-004-6h9f8,phase=Pending node=kind-worker5
4.0655,Job,MODIFIED,eval-sanitize-20-r0-002,
4.0694,Event,ADDED,eval-sanitize-20-r0-004-6h9f8.18d41a595481c0d6,reason=Scheduled count=None msg=Successfully assigned compute/eval-sanitize-20-r0-004-6h9f8 to kind-worker5
4.0734,Job,MODIFIED,eval-sanitize-20-r0-002,
4.076,Pod,MODIFIED,eval-sanitize-20-r0-004-6h9f8,phase=Pending node=kind-worker5
4.5017,Event,ADDED,eval-sanitize-20-r0-004-6h9f8.18d41a596e448c31,"reason=Pulled count=1 msg=Container image ""busybox:musl"" already present on machine"
4.5187,Event,ADDED,eval-sanitize-20-r0-004-6h9f8.18d41a596f5cff1f,reason=Created count=1 msg=Created container: task
4.5506,Event,ADDED,eval-sanitize-20-r0-004-6h9f8.18d41a5971461201,reason=Started count=1 msg=Started container task
4.714,Pod,MODIFIED,eval-sanitize-20-r0-004-6h9f8,phase=Running node=kind-worker5
5.008,TaskRequest,ADDED,eval-sanitize-20-r0-005,phase=None job=None
5.0121,TaskRequest,MODIFIED,eval-sanitize-20-r0-005,phase=Pending job=None
5.0293,Job,ADDED,eval-sanitize-20-r0-005,
5.034,TaskRequest,MODIFIED,eval-sanitize-20-r0-005,phase=Scheduled job=None
5.038,Pod,ADDED,eval-sanitize-20-r0-005-p9pcb,phase=Pending node=None
5.0399,Job,MODIFIED,eval-sanitize-20-r0-005,
5.0432,Event,ADDED,eval-sanitize-20-r0-005.18d41a598e89098d,reason=SuccessfulCreate count=1 msg=Created pod: eval-sanitize-20-r0-005-p9pcb
5.0434,TaskRequest,MODIFIED,eval-sanitize-20-r0-005,phase=Scheduled job=None
5.0457,Job,MODIFIED,eval-sanitize-20-r0-004,
5.0552,Job,MODIFIED,eval-sanitize-20-r0-004,
5.057,Pod,MODIFIED,eval-sanitize-20-r0-005-p9pcb,phase=Pending node=kind-worker3
5.0606,Event,ADDED,eval-sanitize-20-r0-005-p9pcb.18d41a598fb003d8,reason=Scheduled count=None msg=Successfully assigned compute/eval-sanitize-20-r0-005-p9pcb to kind-worker3
5.067,Pod,MODIFIED,eval-sanitize-20-r0-005-p9pcb,phase=Pending node=kind-worker3
5.4756,Event,ADDED,eval-sanitize-20-r0-005-p9pcb.18d41a59a861e0b2,"reason=Pulled count=1 msg=Container image ""busybox:musl"" already present on machine"
5.4967,Event,ADDED,eval-sanitize-20-r0-005-p9pcb.18d41a59a981defd,reason=Created count=1 msg=Created container: task
5.5312,Event,ADDED,eval-sanitize-20-r0-005-p9pcb.18d41a59abb29e94,reason=Started count=1 msg=Started container task
6.0131,TaskRequest,ADDED,eval-sanitize-20-r0-006,phase=None job=None
6.0179,TaskRequest,MODIFIED,eval-sanitize-20-r0-006,phase=Pending job=None
6.0343,Job,ADDED,eval-sanitize-20-r0-006,
6.0415,Pod,ADDED,eval-sanitize-20-r0-006-ppwvx,phase=Pending node=None
6.0425,TaskRequest,MODIFIED,eval-sanitize-20-r0-006,phase=Scheduled job=None
6.0432,Job,MODIFIED,eval-sanitize-20-r0-005,
6.0452,Job,MODIFIED,eval-sanitize-20-r0-006,
6.0469,Event,ADDED,eval-sanitize-20-r0-006.18d41a59ca5b184c,reason=SuccessfulCreate count=1 msg=Created pod: eval-sanitize-20-r0-006-ppwvx
6.0541,TaskRequest,MODIFIED,eval-sanitize-20-r0-006,phase=Scheduled job=None
6.0642,Job,MODIFIED,eval-sanitize-20-r0-005,
6.0684,Pod,MODIFIED,eval-sanitize-20-r0-006-ppwvx,phase=Pending node=kind-worker4
6.0734,Event,ADDED,eval-sanitize-20-r0-006-ppwvx.18d41a59cbec11bc,reason=Scheduled count=None msg=Successfully assigned compute/eval-sanitize-20-r0-006-ppwvx to kind-worker4
6.0798,Node,MODIFIED,kind-worker4,taints=0
6.0814,Pod,MODIFIED,eval-sanitize-20-r0-006-ppwvx,phase=Pending node=kind-worker4
6.0901,Node,MODIFIED,kind-worker4,taints=0
6.132,Pod,MODIFIED,eval-sanitize-20-r0-005-p9pcb,phase=Running node=kind-worker3
6.4914,Event,ADDED,eval-sanitize-20-r0-006-ppwvx.18d41a59e4d1ba14,"reason=Pulled count=1 msg=Container image ""busybox:musl"" already present on machine"
6.5073,Event,ADDED,eval-sanitize-20-r0-006-ppwvx.18d41a59e5ed5fbe,reason=Created count=1 msg=Created container: task
6.5396,Event,ADDED,eval-sanitize-20-r0-006-ppwvx.18d41a59e7d9b041,reason=Started count=1 msg=Started container task
7.0125,TaskRequest,ADDED,eval-sanitize-20-r0-007,phase=None job=None
7.0164,TaskRequest,MODIFIED,eval-sanitize-20-r0-007,phase=Pending job=None
7.0351,Job,ADDED,eval-sanitize-20-r0-007,
7.0413,Pod,ADDED,eval-sanitize-20-r0-007-4g6pt,phase=Pending node=None
7.0428,TaskRequest,MODIFIED,eval-sanitize-20-r0-007,phase=Scheduled job=None
7.0459,Job,MODIFIED,eval-sanitize-20-r0-007,
7.0486,Event,ADDED,eval-sanitize-20-r0-007.18d41a5a05dde1ba,reason=SuccessfulCreate count=1 msg=Created pod: eval-sanitize-20-r0-007-4g6pt
7.0495,Job,MODIFIED,eval-sanitize-20-r0-006,
7.0505,Job,MODIFIED,eval-sanitize-20-r0-005,
7.0509,TaskRequest,MODIFIED,eval-sanitize-20-r0-007,phase=Scheduled job=None
7.06,Job,MODIFIED,eval-sanitize-20-r0-006,
7.0622,Job,MODIFIED,eval-sanitize-20-r0-005,
7.067,Pod,MODIFIED,eval-sanitize-20-r0-007-4g6pt,phase=Pending node=kind-worker2
7.0712,Event,ADDED,eval-sanitize-20-r0-007-4g6pt.18d41a5a076ee859,reason=Scheduled count=None msg=Successfully assigned compute/eval-sanitize-20-r0-007-4g6pt to kind-worker2
7.0775,Pod,MODIFIED,eval-sanitize-20-r0-007-4g6pt,phase=Pending node=kind-worker2
7.0798,Node,MODIFIED,kind-worker2,taints=0
7.0907,Node,MODIFIED,kind-worker2,taints=0
7.4892,Event,ADDED,eval-sanitize-20-r0-007-4g6pt.18d41a5a203b91b6,"reason=Pulled count=1 msg=Container image ""busybox:musl"" already present on machine"
7.5056,Event,ADDED,eval-sanitize-20-r0-007-4g6pt.18d41a5a21563479,reason=Created count=1 msg=Created container: task
7.5374,Pod,MODIFIED,eval-sanitize-20-r0-006-ppwvx,phase=Running node=kind-worker4
7.5403,Event,ADDED,eval-sanitize-20-r0-007-4g6pt.18d41a5a23661384,reason=Started count=1 msg=Started container task
7.7178,Pod,MODIFIED,eval-sanitize-20-r0-007-4g6pt,phase=Running node=kind-worker2
8.0096,TaskRequest,ADDED,eval-sanitize-20-r0-008,phase=None job=None
8.0139,TaskRequest,MODIFIED,eval-sanitize-20-r0-008,phase=Pending job=None
8.0334,Job,ADDED,eval-sanitize-20-r0-008,
8.0423,Pod,ADDED,eval-sanitize-20-r0-008-hmcww,phase=Pending node=None
8.0425,TaskRequest,MODIFIED,eval-sanitize-20-r0-008,phase=Scheduled job=None
8.0461,Job,MODIFIED,eval-sanitize-20-r0-008,
8.0498,Event,ADDED,eval-sanitize-20-r0-008.18d41a5a417b43ce,reason=SuccessfulCreate count=1 msg=Created pod: eval-sanitize-20-r0-008-hmcww
8.0508,Job,MODIFIED,eval-sanitize-20-r0-007,
8.0524,TaskRequest,MODIFIED,eval-sanitize-20-r0-008,phase=Scheduled job=None
8.0558,Job,MODIFIED,eval-sanitize-20-r0-006,
8.0598,Job,MODIFIED,eval-sanitize-20-r0-007,
8.1011,Job,MODIFIED,eval-sanitize-20-r0-006,
8.1541,Pod,MODIFIED,eval-sanitize-20-r0-008-hmcww,phase=Pending node=kind-worker4
8.1578,Event,ADDED,eval-sanitize-20-r0-008-hmcww.18d41a5a4830aa1e,reason=Scheduled count=None msg=Successfully assigned compute/eval-sanitize-20-r0-008-hmcww to kind-worker4
8.1645,Pod,MODIFIED,eval-sanitize-20-r0-008-hmcww,phase=Pending node=kind-worker4
8.1669,Node,MODIFIED,kind-worker4,taints=0
8.1776,Node,MODIFIED,kind-worker4,taints=0
8.5798,Event,ADDED,eval-sanitize-20-r0-008-hmcww.18d41a5a6152e1e8,"reason=Pulled count=1 msg=Container image ""busybox:musl"" already present on machine"
8.5983,Event,ADDED,eval-sanitize-20-r0-008-hmcww.18d41a5a6273402b,reason=Created count=1 msg=Created container: task
8.6365,Event,ADDED,eval-sanitize-20-r0-008-hmcww.18d41a5a64a3614b,reason=Started count=1 msg=Started container task
9.0196,TaskRequest,ADDED,eval-sanitize-20-r0-009,phase=None job=None
9.0243,TaskRequest,MODIFIED,eval-sanitize-20-r0-009,phase=Pending job=None
9.0407,Job,ADDED,eval-sanitize-20-r0-009,
9.0465,Job,MODIFIED,eval-sanitize-20-r0-008,
9.0476,TaskRequest,MODIFIED,eval-sanitize-20-r0-009,phase=Scheduled job=None
9.0487,Pod,ADDED,eval-sanitize-20-r0-009-mgjls,phase=Pending node=None
9.0504,Job,MODIFIED,eval-sanitize-20-r0-009,
9.0532,Event,ADDED,eval-sanitize-20-r0-009.18d41a5a7d87c7f7,reason=SuccessfulCreate count=1 msg=Created pod: eval-sanitize-20-r0-009-mgjls
9.0545,TaskRequest,MODIFIED,eval-sanitize-20-r0-009,phase=Scheduled job=None
9.0608,Job,MODIFIED,eval-sanitize-20-r0-008,
9.2507,Pod,MODIFIED,eval-sanitize-20-r0-009-mgjls,phase=Pending node=kind-worker
9.2554,Event,ADDED,eval-sanitize-20-r0-009-mgjls.18d41a5a8993292b,reason=Scheduled count=None msg=Successfully assigned compute/eval-sanitize-20-r0-009-mgjls to kind-worker
9.2606,Node,MODIFIED,kind-worker,taints=0
9.2631,Pod,MODIFIED,eval-sanitize-20-r0-009-mgjls,phase=Pending node=kind-worker
9.2721,Node,MODIFIED,kind-worker,taints=0
9.5412,Pod,MODIFIED,eval-sanitize-20-r0-008-hmcww,phase=Running node=kind-worker4
9.6635,Event,ADDED,eval-sanitize-20-r0-009-mgjls.18d41a5aa1d43172,"reason=Pulled count=1 msg=Container image ""busybox:musl"" already present on machine"
9.6798,Event,ADDED,eval-sanitize-20-r0-009-mgjls.18d41a5aa2f18f06,reason=Created count=1 msg=Created container: task
9.7158,Event,ADDED,eval-sanitize-20-r0-009-mgjls.18d41a5aa50f9106,reason=Started count=1 msg=Started container task
10.0138,TaskRequest,ADDED,eval-sanitize-20-r0-010,phase=None job=None
10.0178,TaskRequest,MODIFIED,eval-sanitize-20-r0-010,phase=Pending job=None
10.0363,Job,ADDED,eval-sanitize-20-r0-010,
10.0413,TaskRequest,MODIFIED,eval-sanitize-20-r0-010,phase=Scheduled job=None
10.0445,Pod,ADDED,eval-sanitize-20-r0-010-9ls26,phase=Pending node=None
10.0467,Job,MODIFIED,eval-sanitize-20-r0-010,
10.0508,Event,ADDED,eval-sanitize-20-r0-010.18d41a5ab8eb0de5,reason=SuccessfulCreate count=1 msg=Created pod: eval-sanitize-20-r0-010-9ls26
10.051,TaskRequest,MODIFIED,eval-sanitize-20-r0-010,phase=Scheduled job=None
10.0518,Job,MODIFIED,eval-sanitize-20-r0-008,
10.054,Job,MODIFIED,eval-sanitize-20-r0-009,
10.0892,Pod,MODIFIED,eval-sanitize-20-r0-009-mgjls,phase=Running node=kind-worker
10.1476,Pod,MODIFIED,eval-sanitize-20-r0-010-9ls26,phase=Pending node=kind-worker3
10.1513,Event,ADDED,eval-sanitize-20-r0-010-9ls26.18d41a5abf0972df,reason=Scheduled count=None msg=Successfully assigned compute/eval-sanitize-20-r0-010-9ls26 to kind-worker3
10.1578,Pod,MODIFIED,eval-sanitize-20-r0-010-9ls26,phase=Pending node=kind-worker3
10.1602,Node,MODIFIED,kind-worker3,taints=0
10.1704,Node,MODIFIED,kind-worker3,taints=0
10.2345,Job,MODIFIED,eval-sanitize-20-r0-008,
10.2364,Job,MODIFIED,eval-sanitize-20-r0-009,
10.5878,Event,ADDED,eval-sanitize-20-r0-010-9ls26.18d41a5ad8fc4e0f,"reason=Pulled count=1 msg=Container image ""busybox:musl"" already present on machine"
10.6108,Event,ADDED,eval-sanitize-20-r0-010-9ls26.18d41a5ada539c18,reason=Created count=1 msg=Created container: task
10.681,Event,ADDED,eval-sanitize-20-r0-010-9ls26.18d41a5ade93b462,reason=Started count=1 msg=Started container task
10.725,Pod,MODIFIED,eval-sanitize-20-r0-000-jg679,phase=Running node=kind-worker5
11.0096,TaskRequest,ADDED,eval-sanitize-20-r0-011,phase=None job=None
11.014,TaskRequest,MODIFIED,eval-sanitize-20-r0-011,phase=Pending job=None
11.0314,Job,ADDED,eval-sanitize-20-r0-011,
11.0365,TaskRequest,MODIFIED,eval-sanitize-20-r0-011,phase=Scheduled job=None
11.04,Pod,ADDED,eval-sanitize-20-r0-011-kcksm,phase=Pending node=None
11.0421,Job,MODIFIED,eval-sanitize-20-r0-011,
11.045,Event,ADDED,eval-sanitize-20-r0-011.18d41a5af43a74f3,reason=SuccessfulCreate count=1 msg=Created pod: eval-sanitize-20-r0-011-kcksm
11.0451,TaskRequest,MODIFIED,eval-sanitize-20-r0-011,phase=Scheduled job=None
11.0495,Job,MODIFIED,eval-sanitize-20-r0-010,
11.0591,Job,MODIFIED,eval-sanitize-20-r0-009,
11.0611,Job,MODIFIED,eval-sanitize-20-r0-010,
11.0676,Job,MODIFIED,eval-sanitize-20-r0-009,
11.1408,Pod,MODIFIED,eval-sanitize-20-r0-010-9ls26,phase=Running node=kind-worker3
11.1473,Pod,MODIFIED,eval-sanitize-20-r0-011-kcksm,phase=Pending node=kind-worker3
11.1503,Event,ADDED,eval-sanitize-20-r0-011-kcksm.18d41a5afa9c4077,reason=Scheduled count=None msg=Successfully assigned compute/eval-sanitize-20-r0-011-kcksm to kind-worker3
11.1565,Pod,MODIFIED,eval-sanitize-20-r0-011-kcksm,phase=Pending node=kind-worker3
11.5274,Node,MODIFIED,kind-worker,taints=1
11.5404,Node,MODIFIED,kind-worker,taints=1
11.5812,Event,ADDED,eval-sanitize-20-r0-011-kcksm.18d41a5b143e9ddc,"reason=Pulled count=1 msg=Container image ""busybox:musl"" already present on machine"
11.5995,Event,ADDED,eval-sanitize-20-r0-011-kcksm.18d41a5b155db165,reason=Created count=1 msg=Created container: task
11.6359,Event,ADDED,eval-sanitize-20-r0-011-kcksm.18d41a5b1767e116,reason=Started count=1 msg=Started container task
11.6911,Node,MODIFIED,kind-worker4,taints=1
11.6924,Node,MODIFIED,kind-worker3,taints=1
11.6944,Node,MODIFIED,kind-worker2,taints=1
11.7306,Job,MODIFIED,eval-sanitize-20-r0-000,
11.7429,Job,MODIFIED,eval-sanitize-20-r0-000,
11.8187,Pod,MODIFIED,eval-sanitize-20-r0-000-jg679,phase=Succeeded node=kind-worker5
11.9408,Node,MODIFIED,kind-worker5,taints=1
11.9945,Node,MODIFIED,kind-worker4,taints=1
12.0146,TaskRequest,ADDED,eval-sanitize-20-r0-012,phase=None job=None
12.0197,TaskRequest,MODIFIED,eval-sanitize-20-r0-012,phase=Pending job=None
12.0384,Job,ADDED,eval-sanitize-20-r0-012,
12.0459,Job,MODIFIED,eval-sanitize-20-r0-011,
12.0482,Pod,ADDED,eval-sanitize-20-r0-012-q6srf,phase=Pending node=None
12.0483,TaskRequest,MODIFIED,eval-sanitize-20-r0-012,phase=Scheduled job=None
12.0498,Job,MODIFIED,eval-sanitize-20-r0-012,
12.0538,Event,ADDED,eval-sanitize-20-r0-012.18d41a5b30525497,reason=SuccessfulCreate count=1 msg=Created pod: eval-sanitize-20-r0-012-q6srf
12.0541,Event,ADDED,eval-sanitize-20-r0-012-q6srf.18d41a5b305fa520,"reason=FailedScheduling count=None msg=0/6 nodes are available: 6 node(s) had untolerated taint(s). no new claims to deallocate, preemption: 0/6 nodes are available: 6 Preemption is not helpful for scheduling."
12.0548,Job,MODIFIED,eval-sanitize-20-r0-010,
12.056,TaskRequest,MODIFIED,eval-sanitize-20-r0-012,phase=Scheduled job=None
12.0569,Pod,MODIFIED,eval-sanitize-20-r0-012-q6srf,phase=Pending node=None
12.0584,Job,MODIFIED,eval-sanitize-20-r0-011,
12.0628,Job,MODIFIED,eval-sanitize-20-r0-010,
12.1446,Pod,MODIFIED,eval-sanitize-20-r0-001-d2nvh,phase=Running node=kind-worker3
12.1514,Pod,MODIFIED,eval-sanitize-20-r0-011-kcksm,phase=Running node=kind-worker3
12.3921,Node,MODIFIED,kind-worker5,taints=1
12.4411,Node,MODIFIED,kind-worker3,taints=1
12.4431,Node,MODIFIED,kind-worker2,taints=1
12.7368,Job,MODIFIED,eval-sanitize-20-r0-000,
12.7454,Pod,MODIFIED,eval-sanitize-20-r0-000-jg679,phase=Succeeded node=kind-worker5
12.7464,Job,MODIFIED,eval-sanitize-20-r0-000,
13.0118,TaskRequest,ADDED,eval-sanitize-20-r0-013,phase=None job=None
13.0164,TaskRequest,MODIFIED,eval-sanitize-20-r0-013,phase=Pending job=None
13.0357,Job,ADDED,eval-sanitize-20-r0-013,
13.0428,Pod,ADDED,eval-sanitize-20-r0-013-s7vkg,phase=Pending node=None
13.0442,TaskRequest,MODIFIED,eval-sanitize-20-r0-013,phase=Scheduled job=None
13.045,Job,MODIFIED,eval-sanitize-20-r0-013,
13.0492,Event,ADDED,eval-sanitize-20-r0-013.18d41a5b6b9cf09e,reason=SuccessfulCreate count=1 msg=Created pod: eval-sanitize-20-r0-013-s7vkg
13.0495,Event,ADDED,eval-sanitize-20-r0-013-s7vkg.18d41a5b6baadbf2,"reason=FailedScheduling count=None msg=0/6 nodes are available: 6 node(s) had untolerated taint(s). no new claims to deallocate, preemption: 0/6 nodes are available: 6 Preemption is not helpful for scheduling."
13.0506,Pod,MODIFIED,eval-sanitize-20-r0-013-s7vkg,phase=Pending node=None
13.0527,Job,MODIFIED,eval-sanitize-20-r0-011,
13.0545,Job,MODIFIED,eval-sanitize-20-r0-012,
13.0546,TaskRequest,MODIFIED,eval-sanitize-20-r0-013,phase=Scheduled job=None
13.0628,Job,MODIFIED,eval-sanitize-20-r0-011,
13.0647,Job,MODIFIED,eval-sanitize-20-r0-012,
13.0936,Pod,MODIFIED,eval-sanitize-20-r0-002-q96k2,phase=Running node=kind-worker
13.1508,Job,MODIFIED,eval-sanitize-20-r0-001,
13.1622,Job,MODIFIED,eval-sanitize-20-r0-001,
13.2399,Pod,MODIFIED,eval-sanitize-20-r0-001-d2nvh,phase=Succeeded node=kind-worker3
13.7328,Pod,MODIFIED,eval-sanitize-20-r0-003-48wrn,phase=Running node=kind-worker5
13.7421,Job,MODIFIED,eval-sanitize-20-r0-000,
13.7462,Job,MODIFIED,eval-sanitize-20-r0-000,
13.7516,Event,ADDED,eval-sanitize-20-r0-000.18d41a5b95957099,reason=Completed count=1 msg=Job completed
13.7563,Job,MODIFIED,eval-sanitize-20-r0-000,
13.7622,TaskRequest,MODIFIED,eval-sanitize-20-r0-000,phase=Complete job=None
13.7716,Job,MODIFIED,eval-sanitize-20-r0-000,
14.0137,TaskRequest,ADDED,eval-sanitize-20-r0-014,phase=None job=None
14.0195,TaskRequest,MODIFIED,eval-sanitize-20-r0-014,phase=Pending job=None
14.0373,Job,ADDED,eval-sanitize-20-r0-014,
14.0445,Pod,ADDED,eval-sanitize-20-r0-014-nzkw8,phase=Pending node=None
14.0446,TaskRequest,MODIFIED,eval-sanitize-20-r0-014,phase=Scheduled job=None
14.0475,Job,MODIFIED,eval-sanitize-20-r0-014,
14.0501,Pod,MODIFIED,eval-sanitize-20-r0-014-nzkw8,phase=Pending node=None
14.0505,Event,ADDED,eval-sanitize-20-r0-014.18d41a5ba750eaf4,reason=SuccessfulCreate count=1 msg=Created pod: eval-sanitize-20-r0-014-nzkw8
14.0507,Event,ADDED,eval-sanitize-20-r0-014-nzkw8.18d41a5ba75d38be,"reason=FailedScheduling count=None msg=0/6 nodes are available: 6 node(s) had untolerated taint(s). no new claims to deallocate, preemption: 0/6 nodes are available: 6 Preemption is not helpful for scheduling."
14.0514,Job,MODIFIED,eval-sanitize-20-r0-013,
14.0539,TaskRequest,MODIFIED,eval-sanitize-20-r0-014,phase=Scheduled job=None
14.0582,Job,MODIFIED,eval-sanitize-20-r0-013,
14.1029,Job,MODIFIED,eval-sanitize-20-r0-002,
14.112,Job,MODIFIED,eval-sanitize-20-r0-002,
14.1578,Job,MODIFIED,eval-sanitize-20-r0-001,
14.167,Pod,MODIFIED,eval-sanitize-20-r0-001-d2nvh,phase=Succeeded node=kind-worker3
14.168,Job,MODIFIED,eval-sanitize-20-r0-001,
14.2829,Pod,MODIFIED,eval-sanitize-20-r0-002-q96k2,phase=Succeeded node=kind-worker
14.7402,Pod,MODIFIED,eval-sanitize-20-r0-004-6h9f8,phase=Running node=kind-worker5
14.7417,Job,MODIFIED,eval-sanitize-20-r0-003,
14.7512,Job,MODIFIED,eval-sanitize-20-r0-003,
14.8267,Pod,MODIFIED,eval-sanitize-20-r0-003-48wrn,phase=Succeeded node=kind-worker5
15.0171,TaskRequest,ADDED,eval-sanitize-20-r0-015,phase=None job=None
15.0222,TaskRequest,MODIFIED,eval-sanitize-20-r0-015,phase=Pending job=None
15.0391,Job,ADDED,eval-sanitize-20-r0-015,
15.0451,Pod,ADDED,eval-sanitize-20-r0-015-txnkr,phase=Pending node=None
15.0464,TaskRequest,MODIFIED,eval-sanitize-20-r0-015,phase=Scheduled job=None
15.0492,Job,MODIFIED,eval-sanitize-20-r0-015,
15.0511,Event,ADDED,eval-sanitize-20-r0-015.18d41a5be2f25f06,reason=SuccessfulCreate count=1 msg=Created pod: eval-sanitize-20-r0-015-txnkr
15.0513,Event,ADDED,eval-sanitize-20-r0-015-txnkr.18d41a5be3006d98,"reason=FailedScheduling count=None msg=0/6 nodes are available: 6 node(s) had untolerated taint(s). no new claims to deallocate, preemption: 0/6 nodes are available: 6 Preemption is not helpful for scheduling."
15.052,Job,MODIFIED,eval-sanitize-20-r0-014,
15.0529,Pod,MODIFIED,eval-sanitize-20-r0-015-txnkr,phase=Pending node=None
15.0533,TaskRequest,MODIFIED,eval-sanitize-20-r0-015,phase=Scheduled job=None
15.0601,Job,MODIFIED,eval-sanitize-20-r0-014,
15.1096,Job,MODIFIED,eval-sanitize-20-r0-002,
15.1177,Pod,MODIFIED,eval-sanitize-20-r0-002-q96k2,phase=Succeeded node=kind-worker
15.119,Job,MODIFIED,eval-sanitize-20-r0-002,
15.1649,Job,MODIFIED,eval-sanitize-20-r0-001,
15.1694,Job,MODIFIED,eval-sanitize-20-r0-001,
15.1739,Event,ADDED,eval-sanitize-20-r0-001.18d41a5bea676867,reason=Completed count=1 msg=Job completed
15.1803,Job,MODIFIED,eval-sanitize-20-r0-001,
15.1846,TaskRequest,MODIFIED,eval-sanitize-20-r0-001,phase=Complete job=None
15.1942,Job,MODIFIED,eval-sanitize-20-r0-001,
15.746,Job,MODIFIED,eval-sanitize-20-r0-004,
15.748,Job,MODIFIED,eval-sanitize-20-r0-003,
15.7559,Job,MODIFIED,eval-sanitize-20-r0-004,
15.7586,Job,MODIFIED,eval-sanitize-20-r0-003,
15.7599,Pod,MODIFIED,eval-sanitize-20-r0-003-48wrn,phase=Succeeded node=kind-worker5
15.834,Pod,MODIFIED,eval-sanitize-20-r0-004-6h9f8,phase=Succeeded node=kind-worker5
16.0091,TaskRequest,ADDED,eval-sanitize-20-r0-016,phase=None job=None
16.0149,TaskRequest,MODIFIED,eval-sanitize-20-r0-016,phase=Pending job=None
16.0327,Job,ADDED,eval-sanitize-20-r0-016,
16.0418,Pod,ADDED,eval-sanitize-20-r0-016-wsgf9,phase=Pending node=None
16.042,TaskRequest,MODIFIED,eval-sanitize-20-r0-016,phase=Scheduled job=None
16.044,Job,MODIFIED,eval-sanitize-20-r0-016,
16.0473,Pod,MODIFIED,eval-sanitize-20-r0-016-wsgf9,phase=Pending node=None
16.0482,Event,ADDED,eval-sanitize-20-r0-016.18d41a5c1e51f08e,reason=SuccessfulCreate count=1 msg=Created pod: eval-sanitize-20-r0-016-wsgf9
16.0486,Event,ADDED,eval-sanitize-20-r0-016-wsgf9.18d41a5c1e5748b1,"reason=FailedScheduling count=None msg=0/6 nodes are available: 6 node(s) had untolerated taint(s). no new claims to deallocate, preemption: 0/6 nodes are available: 6 Preemption is not helpful for scheduling."
16.051,Job,MODIFIED,eval-sanitize-20-r0-015,
16.0523,TaskRequest,MODIFIED,eval-sanitize-20-r0-016,phase=Scheduled job=None
16.0603,Job,MODIFIED,eval-sanitize-20-r0-015,
16.1171,Job,MODIFIED,eval-sanitize-20-r0-002,
16.1238,Job,MODIFIED,eval-sanitize-20-r0-002,
16.1279,Event,ADDED,eval-sanitize-20-r0-002.18d41a5c234a5813,reason=Completed count=1 msg=Job completed
16.1357,Job,MODIFIED,eval-sanitize-20-r0-002,
16.1414,TaskRequest,MODIFIED,eval-sanitize-20-r0-002,phase=Complete job=None
16.15,Job,MODIFIED,eval-sanitize-20-r0-002,
16.1556,Pod,MODIFIED,eval-sanitize-20-r0-005-p9pcb,phase=Running node=kind-worker3
16.7519,Job,MODIFIED,eval-sanitize-20-r0-004,
16.7544,Job,MODIFIED,eval-sanitize-20-r0-003,
16.7589,Job,MODIFIED,eval-sanitize-20-r0-003,
16.7612,Job,MODIFIED,eval-sanitize-20-r0-004,
16.7628,Pod,MODIFIED,eval-sanitize-20-r0-004-6h9f8,phase=Succeeded node=kind-worker5
16.765,Event,ADDED,eval-sanitize-20-r0-003.18d41a5c49233d4d,reason=Completed count=1 msg=Job completed
16.7694,Job,MODIFIED,eval-sanitize-20-r0-003,
16.7747,TaskRequest,MODIFIED,eval-sanitize-20-r0-003,phase=Complete job=None
16.784,Job,MODIFIED,eval-sanitize-20-r0-003,
17.0085,TaskRequest,ADDED,eval-sanitize-20-r0-017,phase=None job=None
17.0138,TaskRequest,MODIFIED,eval-sanitize-20-r0-017,phase=Pending job=None
17.0296,Job,ADDED,eval-sanitize-20-r0-017,
17.0373,Pod,ADDED,eval-sanitize-20-r0-017-tq46z,phase=Pending node=None
17.0392,Job,MODIFIED,eval-sanitize-20-r0-017,
17.0394,TaskRequest,MODIFIED,eval-sanitize-20-r0-017,phase=Scheduled job=None
17.0423,Event,ADDED,eval-sanitize-20-r0-017.18d41a5c59b9cd80,reason=SuccessfulCreate count=1 msg=Created pod: eval-sanitize-20-r0-017-tq46z
17.0428,Event,ADDED,eval-sanitize-20-r0-017-tq46z.18d41a5c59bf3701,"reason=FailedScheduling count=None msg=0/6 nodes are available: 6 node(s) had untolerated taint(s). no new claims to deallocate, preemption: 0/6 nodes are available: 6 Preemption is not helpful for scheduling."
17.0436,Pod,MODIFIED,eval-sanitize-20-r0-017-tq46z,phase=Pending node=None
17.0472,Job,MODIFIED,eval-sanitize-20-r0-016,
17.0481,TaskRequest,MODIFIED,eval-sanitize-20-r0-017,phase=Scheduled job=None
17.0555,Job,MODIFIED,eval-sanitize-20-r0-016,
17.1606,Job,MODIFIED,eval-sanitize-20-r0-005,
17.1709,Job,MODIFIED,eval-sanitize-20-r0-005,
17.2475,Pod,MODIFIED,eval-sanitize-20-r0-005-p9pcb,phase=Succeeded node=kind-worker3
17.558,Pod,MODIFIED,eval-sanitize-20-r0-006-ppwvx,phase=Running node=kind-worker4
17.7366,Pod,MODIFIED,eval-sanitize-20-r0-007-4g6pt,phase=Running node=kind-worker2
17.7569,Job,MODIFIED,eval-sanitize-20-r0-004,
17.7624,Job,MODIFIED,eval-sanitize-20-r0-004,
17.7675,Event,ADDED,eval-sanitize-20-r0-004.18d41a5c84f392d8,reason=Completed count=1 msg=Job completed
17.7737,Job,MODIFIED,eval-sanitize-20-r0-004,
17.7888,TaskRequest,MODIFIED,eval-sanitize-20-r0-004,phase=Complete job=None
17.8001,Job,MODIFIED,eval-sanitize-20-r0-004,
18.0095,TaskRequest,ADDED,eval-sanitize-20-r0-018,phase=None job=None
18.0133,TaskRequest,MODIFIED,eval-sanitize-20-r0-018,phase=Pending job=None
18.0312,Job,ADDED,eval-sanitize-20-r0-018,
18.0408,Pod,ADDED,eval-sanitize-20-r0-018-hz2rn,phase=Pending node=None
18.0417,TaskRequest,MODIFIED,eval-sanitize-20-r0-018,phase=Scheduled job=None
18.0428,Job,MODIFIED,eval-sanitize-20-r0-018,
18.0435,Job,MODIFIED,eval-sanitize-20-r0-017,
18.0463,Event,ADDED,eval-sanitize-20-r0-018.18d41a5c95822d3b,reason=SuccessfulCreate count=1 msg=Created pod: eval-sanitize-20-r0-018-hz2rn
18.0474,Pod,MODIFIED,eval-sanitize-20-r0-018-hz2rn,phase=Pending node=None
18.0482,Event,ADDED,eval-sanitize-20-r0-018-hz2rn.18d41a5c95959412,"reason=FailedScheduling count=None msg=0/6 nodes are available: 6 node(s) had untolerated taint(s). no new claims to deallocate, preemption: 0/6 nodes are available: 6 Preemption is not helpful for scheduling."
18.0514,TaskRequest,MODIFIED,eval-sanitize-20-r0-018,phase=Scheduled job=None
18.0547,Job,MODIFIED,eval-sanitize-20-r0-017,
18.1674,Job,MODIFIED,eval-sanitize-20-r0-005,
18.1759,Pod,MODIFIED,eval-sanitize-20-r0-005-p9pcb,phase=Succeeded node=kind-worker3
18.1771,Job,MODIFIED,eval-sanitize-20-r0-005,
18.5673,Job,MODIFIED,eval-sanitize-20-r0-006,
18.5791,Job,MODIFIED,eval-sanitize-20-r0-006,
18.6481,Pod,MODIFIED,eval-sanitize-20-r0-006-ppwvx,phase=Succeeded node=kind-worker4
18.743,Job,MODIFIED,eval-sanitize-20-r0-007,
18.7525,Job,MODIFIED,eval-sanitize-20-r0-007,
18.8388,Pod,MODIFIED,eval-sanitize-20-r0-007-4g6pt,phase=Succeeded node=kind-worker2
19.008,TaskRequest,ADDED,eval-sanitize-20-r0-019,phase=None job=None
19.0127,TaskRequest,MODIFIED,eval-sanitize-20-r0-019,phase=Pending job=None
19.0278,Job,ADDED,eval-sanitize-20-r0-019,
19.0323,TaskRequest,MODIFIED,eval-sanitize-20-r0-019,phase=Scheduled job=None
19.0357,Pod,ADDED,eval-sanitize-20-r0-019-7rmqh,phase=Pending node=None
19.037,Job,MODIFIED,eval-sanitize-20-r0-019,
19.0432,Event,ADDED,eval-sanitize-20-r0-019.18d41a5cd0d9bb0c,reason=SuccessfulCreate count=1 msg=Created pod: eval-sanitize-20-r0-019-7rmqh
19.0434,Event,ADDED,eval-sanitize-20-r0-019-7rmqh.18d41a5cd0e395fd,"reason=FailedScheduling count=None msg=0/6 nodes are available: 6 node(s) had untolerated taint(s). no new claims to deallocate, preemption: 0/6 nodes are available: 6 Preemption is not helpful for scheduling."
19.0435,TaskRequest,MODIFIED,eval-sanitize-20-r0-019,phase=Scheduled job=None
19.0444,Pod,MODIFIED,eval-sanitize-20-r0-019-7rmqh,phase=Pending node=None
19.0453,Job,MODIFIED,eval-sanitize-20-r0-018,
19.0543,Job,MODIFIED,eval-sanitize-20-r0-018,
19.1762,Job,MODIFIED,eval-sanitize-20-r0-005,
19.1807,Job,MODIFIED,eval-sanitize-20-r0-005,
19.187,Event,ADDED,eval-sanitize-20-r0-005.18d41a5cd980d8b0,reason=Completed count=1 msg=Job completed
19.1917,Job,MODIFIED,eval-sanitize-20-r0-005,
19.1999,TaskRequest,MODIFIED,eval-sanitize-20-r0-005,phase=Complete job=None
19.2067,Job,MODIFIED,eval-sanitize-20-r0-005,
19.5625,Pod,MODIFIED,eval-sanitize-20-r0-008-hmcww,phase=Running node=kind-worker4
19.5718,Job,MODIFIED,eval-sanitize-20-r0-006,
19.5801,Pod,MODIFIED,eval-sanitize-20-r0-006-ppwvx,phase=Succeeded node=kind-worker4
19.5818,Job,MODIFIED,eval-sanitize-20-r0-006,
19.7481,Job,MODIFIED,eval-sanitize-20-r0-007,
19.7563,Pod,MODIFIED,eval-sanitize-20-r0-007-4g6pt,phase=Succeeded node=kind-worker2
19.7574,Job,MODIFIED,eval-sanitize-20-r0-007,
20.0235,TaskRequest,ADDED,eval-sanitize-20-r0-020,phase=None job=None
20.0281,TaskRequest,MODIFIED,eval-sanitize-20-r0-020,phase=Pending job=None
20.0425,Job,MODIFIED,eval-sanitize-20-r0-019,
20.0431,Job,ADDED,eval-sanitize-20-r0-020,
20.0494,Pod,ADDED,eval-sanitize-20-r0-020-hjlkw,phase=Pending node=None
20.0508,TaskRequest,MODIFIED,eval-sanitize-20-r0-020,phase=Scheduled job=None
20.0535,Job,MODIFIED,eval-sanitize-20-r0-020,
20.0565,Event,ADDED,eval-sanitize-20-r0-020.18d41a5d0d47bf78,reason=SuccessfulCreate count=1 msg=Created pod: eval-sanitize-20-r0-020-hjlkw
20.0567,Event,ADDED,eval-sanitize-20-r0-020-hjlkw.18d41a5d0d529aa5,"reason=FailedScheduling count=None msg=0/6 nodes are available: 6 node(s) had untolerated taint(s). no new claims to deallocate, preemption: 0/6 nodes are available: 6 Preemption is not helpful for scheduling."
20.0578,Pod,MODIFIED,eval-sanitize-20-r0-020-hjlkw,phase=Pending node=None
20.058,TaskRequest,MODIFIED,eval-sanitize-20-r0-020,phase=Scheduled job=None
20.0608,Job,MODIFIED,eval-sanitize-20-r0-019,
20.1105,Pod,MODIFIED,eval-sanitize-20-r0-009-mgjls,phase=Running node=kind-worker
20.5727,Job,MODIFIED,eval-sanitize-20-r0-008,
20.5777,Job,MODIFIED,eval-sanitize-20-r0-006,
20.5823,Job,MODIFIED,eval-sanitize-20-r0-006,
20.5842,Job,MODIFIED,eval-sanitize-20-r0-008,
20.5875,Event,ADDED,eval-sanitize-20-r0-006.18d41a5d2d0c790c,reason=Completed count=1 msg=Job completed
20.593,Job,MODIFIED,eval-sanitize-20-r0-006,
20.5974,TaskRequest,MODIFIED,eval-sanitize-20-r0-006,phase=Complete job=None
20.607,Job,MODIFIED,eval-sanitize-20-r0-006,
20.6543,Pod,MODIFIED,eval-sanitize-20-r0-008-hmcww,phase=Succeeded node=kind-worker4
20.7575,Job,MODIFIED,eval-sanitize-20-r0-007,
20.7614,Job,MODIFIED,eval-sanitize-20-r0-007,
20.7648,Event,ADDED,eval-sanitize-20-r0-007.18d41a5d37bae740,reason=Completed count=1 msg=Job completed
20.7745,Job,MODIFIED,eval-sanitize-20-r0-007,
20.7789,TaskRequest,MODIFIED,eval-sanitize-20-r0-007,phase=Complete job=None
20.7884,Job,MODIFIED,eval-sanitize-20-r0-007,
21.0152,TaskRequest,ADDED,eval-sanitize-20-r0-021,phase=None job=None
21.0201,TaskRequest,MODIFIED,eval-sanitize-20-r0-021,phase=Pending job=None
21.0374,Job,ADDED,eval-sanitize-20-r0-021,
21.0419,TaskRequest,MODIFIED,eval-sanitize-20-r0-021,phase=Scheduled job=None
21.0451,Pod,ADDED,eval-sanitize-20-r0-021-clzvc,phase=Pending node=None
21.0469,Job,MODIFIED,eval-sanitize-20-r0-021,
21.0514,Event,ADDED,eval-sanitize-20-r0-021.18d41a5d489d4155,reason=SuccessfulCreate count=1 msg=Created pod: eval-sanitize-20-r0-021-clzvc
21.0524,Pod,MODIFIED,eval-sanitize-20-r0-021-clzvc,phase=Pending node=None
21.053,Event,ADDED,eval-sanitize-20-r0-021-clzvc.18d41a5d48ab6f27,"reason=FailedScheduling count=None msg=0/6 nodes are available: 6 node(s) had untolerated taint(s). no new claims to deallocate, preemption: 0/6 nodes are available: 6 Preemption is not helpful for scheduling."
21.0532,TaskRequest,MODIFIED,eval-sanitize-20-r0-021,phase=Scheduled job=None
21.0558,Job,MODIFIED,eval-sanitize-20-r0-020,
21.0644,Job,MODIFIED,eval-sanitize-20-r0-020,
21.1171,Job,MODIFIED,eval-sanitize-20-r0-009,
21.1285,Job,MODIFIED,eval-sanitize-20-r0-009,
21.1698,Pod,MODIFIED,eval-sanitize-20-r0-010-9ls26,phase=Running node=kind-worker3
21.2467,Pod,MODIFIED,eval-sanitize-20-r0-009-mgjls,phase=Succeeded node=kind-worker
21.5819,Job,MODIFIED,eval-sanitize-20-r0-008,
21.5899,Pod,MODIFIED,eval-sanitize-20-r0-008-hmcww,phase=Succeeded node=kind-worker4
21.5917,Job,MODIFIED,eval-sanitize-20-r0-008,
22.0141,TaskRequest,ADDED,eval-sanitize-20-r0-022,phase=None job=None
22.0182,TaskRequest,MODIFIED,eval-sanitize-20-r0-022,phase=Pending job=None
22.035,Job,ADDED,eval-sanitize-20-r0-022,
22.0406,Pod,ADDED,eval-sanitize-20-r0-022-bj2qs,phase=Pending node=None
22.0414,TaskRequest,MODIFIED,eval-sanitize-20-r0-022,phase=Scheduled job=None
22.0441,Job,MODIFIED,eval-sanitize-20-r0-022,
22.0463,Event,ADDED,eval-sanitize-20-r0-022.18d41a5d83f4f7a3,reason=SuccessfulCreate count=1 msg=Created pod: eval-sanitize-20-r0-022-bj2qs
22.0466,Event,ADDED,eval-sanitize-20-r0-022-bj2qs.18d41a5d8400fbeb,"reason=FailedScheduling count=None msg=0/6 nodes are available: 6 node(s) had untolerated taint(s). no new claims to deallocate, preemption: 0/6 nodes are available: 6 Preemption is not helpful for scheduling."
22.0479,Pod,MODIFIED,eval-sanitize-20-r0-022-bj2qs,phase=Pending node=None
22.0498,Job,MODIFIED,eval-sanitize-20-r0-021,
22.0511,TaskRequest,MODIFIED,eval-sanitize-20-r0-022,phase=Scheduled job=None
22.0591,Job,MODIFIED,eval-sanitize-20-r0-021,
22.1267,Job,MODIFIED,eval-sanitize-20-r0-009,
22.1379,Pod,MODIFIED,eval-sanitize-20-r0-009-mgjls,phase=Succeeded node=kind-worker
22.1405,Job,MODIFIED,eval-sanitize-20-r0-009,
22.1713,Pod,MODIFIED,eval-sanitize-20-r0-011-kcksm,phase=Running node=kind-worker3
22.1747,Job,MODIFIED,eval-sanitize-20-r0-010,
22.1855,Job,MODIFIED,eval-sanitize-20-r0-010,
22.2466,Pod,MODIFIED,eval-sanitize-20-r0-010-9ls26,phase=Succeeded node=kind-worker3
22.5891,Job,MODIFIED,eval-sanitize-20-r0-008,
22.5931,Job,MODIFIED,eval-sanitize-20-r0-008,
22.5994,Event,ADDED,eval-sanitize-20-r0-008.18d41a5da4e4eb46,reason=Completed count=1 msg=Job completed
22.6063,Job,MODIFIED,eval-sanitize-20-r0-008,
22.6107,TaskRequest,MODIFIED,eval-sanitize-20-r0-008,phase=Complete job=None
22.6201,Job,MODIFIED,eval-sanitize-20-r0-008,
23.0193,TaskRequest,ADDED,eval-sanitize-20-r0-023,phase=None job=None
23.0232,TaskRequest,MODIFIED,eval-sanitize-20-r0-023,phase=Pending job=None
23.0411,Job,ADDED,eval-sanitize-20-r0-023,
23.0449,Job,MODIFIED,eval-sanitize-20-r0-022,
23.0473,Pod,ADDED,eval-sanitize-20-r0-023-5gj96,phase=Pending node=None
23.0474,TaskRequest,MODIFIED,eval-sanitize-20-r0-023,phase=Scheduled job=None
23.0515,Job,MODIFIED,eval-sanitize-20-r0-023,
23.0537,Event,ADDED,eval-sanitize-20-r0-023.18d41a5dbff8fef9,reason=SuccessfulCreate count=1 msg=Created pod: eval-sanitize-20-r0-023-5gj96
23.054,Event,ADDED,eval-sanitize-20-r0-023-5gj96.18d41a5dc00437a8,"reason=FailedScheduling count=None msg=0/6 nodes are available: 6 node(s) had untolerated taint(s). no new claims to deallocate, preemption: 0/6 nodes are available: 6 Preemption is not helpful for scheduling."
23.055,Pod,MODIFIED,eval-sanitize-20-r0-023-5gj96,phase=Pending node=None
23.0553,TaskRequest,MODIFIED,eval-sanitize-20-r0-023,phase=Scheduled job=None
23.0582,Job,MODIFIED,eval-sanitize-20-r0-022,
23.1334,Job,MODIFIED,eval-sanitize-20-r0-009,
23.138,Job,MODIFIED,eval-sanitize-20-r0-009,
23.1426,Event,ADDED,eval-sanitize-20-r0-009.18d41a5dc55a939c,reason=Completed count=1 msg=Job completed
23.1489,Job,MODIFIED,eval-sanitize-20-r0-009,
23.154,TaskRequest,MODIFIED,eval-sanitize-20-r0-009,phase=Complete job=None
23.163,Job,MODIFIED,eval-sanitize-20-r0-009,
23.1768,Job,MODIFIED,eval-sanitize-20-r0-011,
23.18,Job,MODIFIED,eval-sanitize-20-r0-010,
23.1863,Job,MODIFIED,eval-sanitize-20-r0-011,
23.1903,Pod,MODIFIED,eval-sanitize-20-r0-010-9ls26,phase=Succeeded node=kind-worker3
23.1941,Job,MODIFIED,eval-sanitize-20-r0-010,
23.2823,Pod,MODIFIED,eval-sanitize-20-r0-011-kcksm,phase=Succeeded node=kind-worker3
24.011,TaskRequest,ADDED,eval-sanitize-20-r0-024,phase=None job=None
24.017,TaskRequest,MODIFIED,eval-sanitize-20-r0-024,phase=Pending job=None
24.0343,Job,ADDED,eval-sanitize-20-r0-024,
24.0417,TaskRequest,MODIFIED,eval-sanitize-20-r0-024,phase=Scheduled job=None
24.0452,Pod,ADDED,eval-sanitize-20-r0-024-g6xwd,phase=Pending node=None
24.0458,Job,MODIFIED,eval-sanitize-20-r0-024,
24.0509,Pod,MODIFIED,eval-sanitize-20-r0-024-g6xwd,phase=Pending node=None
24.0545,Event,ADDED,eval-sanitize-20-r0-024-g6xwd.18d41a5dfb7a88af,"reason=FailedScheduling count=None msg=0/6 nodes are available: 6 node(s) had untolerated taint(s). no new claims to deallocate, preemption: 0/6 nodes are available: 6 Preemption is not helpful for scheduling."
24.0547,Event,ADDED,eval-sanitize-20-r0-024.18d41a5dfb754a92,reason=SuccessfulCreate count=1 msg=Created pod: eval-sanitize-20-r0-024-g6xwd
24.0549,TaskRequest,MODIFIED,eval-sanitize-20-r0-024,phase=Scheduled job=None
24.0558,Job,MODIFIED,eval-sanitize-20-r0-023,
24.0663,Job,MODIFIED,eval-sanitize-20-r0-023,
24.183,Job,MODIFIED,eval-sanitize-20-r0-011,
24.1862,Job,MODIFIED,eval-sanitize-20-r0-010,
24.1906,Job,MODIFIED,eval-sanitize-20-r0-010,
24.1927,Job,MODIFIED,eval-sanitize-20-r0-011,
24.1945,Pod,MODIFIED,eval-sanitize-20-r0-011-kcksm,phase=Succeeded node=kind-worker3
24.1969,Event,ADDED,eval-sanitize-20-r0-010.18d41a5e042101de,reason=Completed count=1 msg=Job completed
24.2028,Job,MODIFIED,eval-sanitize-20-r0-010,
24.2089,TaskRequest,MODIFIED,eval-sanitize-20-r0-010,phase=Complete job=None
24.2198,Job,MODIFIED,eval-sanitize-20-r0-010,
25.0135,TaskRequest,ADDED,eval-sanitize-20-r0-025,phase=None job=None
25.02,TaskRequest,MODIFIED,eval-sanitize-20-r0-025,phase=Pending job=None
25.0363,Job,ADDED,eval-sanitize-20-r0-025,
25.0421,TaskRequest,MODIFIED,eval-sanitize-20-r0-025,phase=Scheduled job=None
25.0441,Pod,ADDED,eval-sanitize-20-r0-025-gp5dc,phase=Pending node=None
25.0461,Job,MODIFIED,eval-sanitize-20-r0-025,
25.0513,Event,ADDED,eval-sanitize-20-r0-025.18d41a5e36fb0b11,reason=SuccessfulCreate count=1 msg=Created pod: eval-sanitize-20-r0-025-gp5dc
25.0516,Event,ADDED,eval-sanitize-20-r0-025-gp5dc.18d41a5e37097bcf,"reason=FailedScheduling count=None msg=0/6 nodes are available: 6 node(s) had untolerated taint(s). no new claims to deallocate, preemption: 0/6 nodes are available: 6 Preemption is not helpful for scheduling."
25.0529,Pod,MODIFIED,eval-sanitize-20-r0-025-gp5dc,phase=Pending node=None
25.0536,Job,MODIFIED,eval-sanitize-20-r0-024,
25.0538,TaskRequest,MODIFIED,eval-sanitize-20-r0-025,phase=Scheduled job=None
25.0614,Job,MODIFIED,eval-sanitize-20-r0-024,
25.191,Job,MODIFIED,eval-sanitize-20-r0-011,
25.1963,Job,MODIFIED,eval-sanitize-20-r0-011,
25.2013,Event,ADDED,eval-sanitize-20-r0-011.18d41a5e4011111c,reason=Completed count=1 msg=Job completed
25.206,Job,MODIFIED,eval-sanitize-20-r0-011,
25.2119,TaskRequest,MODIFIED,eval-sanitize-20-r0-011,phase=Complete job=None
25.2216,Job,MODIFIED,eval-sanitize-20-r0-011,
26.0107,TaskRequest,ADDED,eval-sanitize-20-r0-026,phase=None job=None
26.0161,TaskRequest,MODIFIED,eval-sanitize-20-r0-026,phase=Pending job=None
26.0311,Job,ADDED,eval-sanitize-20-r0-026,
26.0369,TaskRequest,MODIFIED,eval-sanitize-20-r0-026,phase=Scheduled job=None
26.0394,Pod,ADDED,eval-sanitize-20-r0-026-2vx96,phase=Pending node=None
26.0406,Job,MODIFIED,eval-sanitize-20-r0-026,
26.0454,Event,ADDED,eval-sanitize-20-r0-026.18d41a5e72480828,reason=SuccessfulCreate count=1 msg=Created pod: eval-sanitize-20-r0-026-2vx96
26.0456,Event,ADDED,eval-sanitize-20-r0-026-2vx96.18d41a5e7252b1b8,"reason=FailedScheduling count=None msg=0/6 nodes are available: 6 node(s) had untolerated taint(s). no new claims to deallocate, preemption: 0/6 nodes are available: 6 Preemption is not helpful for scheduling."
26.0458,TaskRequest,MODIFIED,eval-sanitize-20-r0-026,phase=Scheduled job=None
26.0466,Pod,MODIFIED,eval-sanitize-20-r0-026-2vx96,phase=Pending node=None
26.0488,Job,MODIFIED,eval-sanitize-20-r0-025,
26.0572,Job,MODIFIED,eval-sanitize-20-r0-025,
27.0107,TaskRequest,ADDED,eval-sanitize-20-r0-027,phase=None job=None
27.0148,TaskRequest,MODIFIED,eval-sanitize-20-r0-027,phase=Pending job=None
27.0324,Job,ADDED,eval-sanitize-20-r0-027,
27.0392,Pod,ADDED,eval-sanitize-20-r0-027-mccff,phase=Pending node=None
27.0402,TaskRequest,MODIFIED,eval-sanitize-20-r0-027,phase=Scheduled job=None
27.041,Job,MODIFIED,eval-sanitize-20-r0-027,
27.0429,Job,MODIFIED,eval-sanitize-20-r0-026,
27.0454,Event,ADDED,eval-sanitize-20-r0-027.18d41a5eade6f1f3,reason=SuccessfulCreate count=1 msg=Created pod: eval-sanitize-20-r0-027-mccff
27.0456,Event,ADDED,eval-sanitize-20-r0-027-mccff.18d41a5eadf144e2,"reason=FailedScheduling count=None msg=0/6 nodes are available: 6 node(s) had untolerated taint(s). no new claims to deallocate, preemption: 0/6 nodes are available: 6 Preemption is not helpful for scheduling."
27.0465,Pod,MODIFIED,eval-sanitize-20-r0-027-mccff,phase=Pending node=None
27.0496,TaskRequest,MODIFIED,eval-sanitize-20-r0-027,phase=Scheduled job=None
27.0524,Job,MODIFIED,eval-sanitize-20-r0-026,
28.0116,TaskRequest,ADDED,eval-sanitize-20-r0-028,phase=None job=None
28.0156,TaskRequest,MODIFIED,eval-sanitize-20-r0-028,phase=Pending job=None
28.0355,Job,ADDED,eval-sanitize-20-r0-028,
28.0448,Pod,ADDED,eval-sanitize-20-r0-028-nr6jw,phase=Pending node=None
28.0452,TaskRequest,MODIFIED,eval-sanitize-20-r0-028,phase=Scheduled job=None
28.0462,Job,MODIFIED,eval-sanitize-20-r0-027,
28.0485,Job,MODIFIED,eval-sanitize-20-r0-028,
28.05,Event,ADDED,eval-sanitize-20-r0-028.18d41a5ee9c7fc7e,reason=SuccessfulCreate count=1 msg=Created pod: eval-sanitize-20-r0-028-nr6jw
28.0534,TaskRequest,MODIFIED,eval-sanitize-20-r0-028,phase=Scheduled job=None
28.0613,Job,MODIFIED,eval-sanitize-20-r0-027,
28.1202,Pod,MODIFIED,eval-sanitize-20-r0-028-nr6jw,phase=Pending node=None
28.1205,Event,ADDED,eval-sanitize-20-r0-028-nr6jw.18d41a5ee9d4a98a,"reason=FailedScheduling count=None msg=0/6 nodes are available: 6 node(s) had untolerated taint(s). no new claims to deallocate, preemption: 0/6 nodes are available: 6 Preemption is not helpful for scheduling."
29.0084,TaskRequest,ADDED,eval-sanitize-20-r0-029,phase=None job=None
29.0134,TaskRequest,MODIFIED,eval-sanitize-20-r0-029,phase=Pending job=None
29.0296,Job,ADDED,eval-sanitize-20-r0-029,
29.0344,TaskRequest,MODIFIED,eval-sanitize-20-r0-029,phase=Scheduled job=None
29.0367,Pod,ADDED,eval-sanitize-20-r0-029-z4hhp,phase=Pending node=None
29.0404,Job,MODIFIED,eval-sanitize-20-r0-029,
29.0422,Event,ADDED,eval-sanitize-20-r0-029.18d41a5f24f88901,reason=SuccessfulCreate count=1 msg=Created pod: eval-sanitize-20-r0-029-z4hhp
29.0432,Pod,MODIFIED,eval-sanitize-20-r0-029-z4hhp,phase=Pending node=None
29.0436,Event,ADDED,eval-sanitize-20-r0-029-z4hhp.18d41a5f25061e16,"reason=FailedScheduling count=None msg=0/6 nodes are available: 6 node(s) had untolerated taint(s). no new claims to deallocate, preemption: 0/6 nodes are available: 6 Preemption is not helpful for scheduling."
29.0437,TaskRequest,MODIFIED,eval-sanitize-20-r0-029,phase=Scheduled job=None
29.0475,Job,MODIFIED,eval-sanitize-20-r0-028,
29.0562,Job,MODIFIED,eval-sanitize-20-r0-028,
30.011,TaskRequest,ADDED,eval-sanitize-20-r0-030,phase=None job=None
30.0159,TaskRequest,MODIFIED,eval-sanitize-20-r0-030,phase=Pending job=None
30.036,Job,ADDED,eval-sanitize-20-r0-030,
30.0433,Job,MODIFIED,eval-sanitize-20-r0-029,
30.0445,TaskRequest,MODIFIED,eval-sanitize-20-r0-030,phase=Scheduled job=None
30.0456,Pod,ADDED,eval-sanitize-20-r0-030-vsswq,phase=Pending node=None
30.048,Job,MODIFIED,eval-sanitize-20-r0-030,
30.0533,Event,ADDED,eval-sanitize-20-r0-030.18d41a5f611805a5,reason=SuccessfulCreate count=1 msg=Created pod: eval-sanitize-20-r0-030-vsswq
30.0536,Event,ADDED,eval-sanitize-20-r0-030-vsswq.18d41a5f6128f682,"reason=FailedScheduling count=None msg=0/6 nodes are available: 6 node(s) had untolerated taint(s). no new claims to deallocate, preemption: 0/6 nodes are available: 6 Preemption is not helpful for scheduling."
30.0545,Pod,MODIFIED,eval-sanitize-20-r0-030-vsswq,phase=Pending node=None
30.0552,TaskRequest,MODIFIED,eval-sanitize-20-r0-030,phase=Scheduled job=None
30.0578,Job,MODIFIED,eval-sanitize-20-r0-029,
31.0104,TaskRequest,ADDED,eval-sanitize-20-r0-031,phase=None job=None
31.015,TaskRequest,MODIFIED,eval-sanitize-20-r0-031,phase=Pending job=None
31.0317,Job,ADDED,eval-sanitize-20-r0-031,
31.0348,TaskRequest,MODIFIED,eval-sanitize-20-r0-031,phase=Scheduled job=None
31.0399,Pod,ADDED,eval-sanitize-20-r0-031-rj57f,phase=Pending node=None
31.042,Job,MODIFIED,eval-sanitize-20-r0-031,
31.0433,TaskRequest,MODIFIED,eval-sanitize-20-r0-031,phase=Scheduled job=None
31.0457,Event,ADDED,eval-sanitize-20-r0-031.18d41a5f9c63eeb6,reason=SuccessfulCreate count=1 msg=Created pod: eval-sanitize-20-r0-031-rj57f
31.0459,Event,ADDED,eval-sanitize-20-r0-031-rj57f.18d41a5f9c74c312,"reason=FailedScheduling count=None msg=0/6 nodes are available: 6 node(s) had untolerated taint(s). no new claims to deallocate, preemption: 0/6 nodes are available: 6 Preemption is not helpful for scheduling."
31.0467,Pod,MODIFIED,eval-sanitize-20-r0-031-rj57f,phase=Pending node=None
31.0505,Job,MODIFIED,eval-sanitize-20-r0-030,
31.0583,Job,MODIFIED,eval-sanitize-20-r0-030,
31.7411,Node,MODIFIED,kind-worker,taints=1
31.7574,Node,MODIFIED,kind-worker,taints=0
31.7641,Pod,MODIFIED,eval-sanitize-20-r0-012-q6srf,phase=Pending node=kind-worker
31.7728,Node,MODIFIED,kind-worker,taints=0
31.7757,Event,ADDED,eval-sanitize-20-r0-012-q6srf.18d41a5fc78c592c,reason=Scheduled count=None msg=Successfully assigned compute/eval-sanitize-20-r0-012-q6srf to kind-worker
31.7759,Event,ADDED,eval-sanitize-20-r0-013-s7vkg.18d41a5fc7c53074,"reason=FailedScheduling count=None msg=0/6 nodes are available: 1 c_wall violated: 1 conflicting context pair(s) with node memory, 5 node(s) had untolerated taint(s). no new claims to deallocate, preemption: 0/6 nodes are available: 1 No preemption victims found for incoming pod, 5 Preemption is not helpful for scheduling."
31.7769,Pod,MODIFIED,eval-sanitize-20-r0-013-s7vkg,phase=Pending node=None
31.7821,Pod,MODIFIED,eval-sanitize-20-r0-012-q6srf,phase=Pending node=kind-worker
31.7845,Node,MODIFIED,kind-worker,taints=0
31.7861,Pod,MODIFIED,eval-sanitize-20-r0-014-nzkw8,phase=Pending node=None
31.7864,Event,ADDED,eval-sanitize-20-r0-014-nzkw8.18d41a5fc88bfbb1,"reason=FailedScheduling count=None msg=0/6 nodes are available: 1 c_wall violated: 1 conflicting context pair(s) with node memory, 5 node(s) had untolerated taint(s). no new claims to deallocate, preemption: 0/6 nodes are available: 1 No preemption victims found for incoming pod, 5 Preemption is not helpful for scheduling."
31.7955,Pod,MODIFIED,eval-sanitize-20-r0-015-txnkr,phase=Pending node=None
31.7972,Event,ADDED,eval-sanitize-20-r0-015-txnkr.18d41a5fc917dbc1,"reason=FailedScheduling count=None msg=0/6 nodes are available: 1 c_wall violated: 1 conflicting context pair(s) with node memory, 5 node(s) had untolerated taint(s). no new claims to deallocate, preemption: 0/6 nodes are available: 1 No preemption victims found for incoming pod, 5 Preemption is not helpful for scheduling."
31.7992,Node,MODIFIED,kind-worker,taints=0
31.8208,Pod,MODIFIED,eval-sanitize-20-r0-016-wsgf9,phase=Pending node=None
31.8213,Event,ADDED,eval-sanitize-20-r0-016-wsgf9.18d41a5fca88b0a0,"reason=FailedScheduling count=None msg=0/6 nodes are available: 1 c_wall violated: 1 conflicting context pair(s) with node memory, 5 node(s) had untolerated taint(s). no new claims to deallocate, preemption: 0/6 nodes are available: 1 No preemption victims found for incoming pod, 5 Preemption is not helpful for scheduling."
31.8304,Pod,MODIFIED,eval-sanitize-20-r0-017-tq46z,phase=Pending node=None
31.8307,Event,ADDED,eval-sanitize-20-r0-017-tq46z.18d41a5fcb274ccc,"reason=FailedScheduling count=None msg=0/6 nodes are available: 1 c_wall violated: 1 conflicting context pair(s) with node memory, 5 node(s) had untolerated taint(s). no new claims to deallocate, preemption: 0/6 nodes are available: 1 No preemption victims found for incoming pod, 5 Preemption is not helpful for scheduling."
31.8399,Node,MODIFIED,kind-worker,taints=0
31.8479,Pod,MODIFIED,eval-sanitize-20-r0-018-hz2rn,phase=Pending node=kind-worker
31.8486,Pod,MODIFIED,eval-sanitize-20-r0-019-7rmqh,phase=Pending node=None
31.8498,Event,ADDED,eval-sanitize-20-r0-019-7rmqh.18d41a5fcc5685de,"reason=FailedScheduling count=None msg=0/6 nodes are available: 1 c_wall violated: 1 conflicting context pair(s) with node memory, 5 node(s) had untolerated taint(s). no new claims to deallocate, preemption: 0/6 nodes are available: 1 No preemption victims found for incoming pod, 5 Preemption is not helpful for scheduling."
31.8511,Event,ADDED,eval-sanitize-20-r0-018-hz2rn.18d41a5fcc7ebb6f,reason=Scheduled count=None msg=Successfully assigned compute/eval-sanitize-20-r0-018-hz2rn to kind-worker
31.8593,Node,MODIFIED,kind-worker,taints=0
31.8615,Pod,MODIFIED,eval-sanitize-20-r0-018-hz2rn,phase=Pending node=kind-worker
31.8697,Node,MODIFIED,kind-worker,taints=0
31.8719,Pod,MODIFIED,eval-sanitize-20-r0-020-hjlkw,phase=Pending node=None
31.8724,Event,ADDED,eval-sanitize-20-r0-020-hjlkw.18d41a5fcdb2700b,"reason=FailedScheduling count=None msg=0/6 nodes are available: 1 c_wall violated: 1 conflicting context pair(s) with node memory, 5 node(s) had untolerated taint(s). no new claims to deallocate, preemption: 0/6 nodes are available: 1 No preemption victims found for incoming pod, 5 Preemption is not helpful for scheduling."
31.8806,Pod,MODIFIED,eval-sanitize-20-r0-021-clzvc,phase=Pending node=None
31.8811,Event,ADDED,eval-sanitize-20-r0-021-clzvc.18d41a5fce364982,"reason=FailedScheduling count=None msg=0/6 nodes are available: 1 c_wall violated: 1 conflicting context pair(s) with node memory, 5 node(s) had untolerated taint(s). no new claims to deallocate, preemption: 0/6 nodes are available: 1 No preemption victims found for incoming pod, 5 Preemption is not helpful for scheduling."
31.9203,Pod,MODIFIED,eval-sanitize-20-r0-022-bj2qs,phase=Pending node=None
31.921,Event,ADDED,eval-sanitize-20-r0-022-bj2qs.18d41a5fd080c548,"reason=FailedScheduling count=None msg=0/6 nodes are available: 1 c_wall violated: 1 conflicting context pair(s) with node memory, 5 node(s) had untolerated taint(s). no new claims to deallocate, preemption: 0/6 nodes are available: 1 No preemption victims found for incoming pod, 5 Preemption is not helpful for scheduling."
31.9273,Pod,MODIFIED,eval-sanitize-20-r0-023-5gj96,phase=Pending node=None
31.9289,Event,ADDED,eval-sanitize-20-r0-023-5gj96.18d41a5fd114e04d,"reason=FailedScheduling count=None msg=0/6 nodes are available: 1 c_wall violated: 1 conflicting context pair(s) with node memory, 5 node(s) had untolerated taint(s). no new claims to deallocate, preemption: 0/6 nodes are available: 1 No preemption victims found for incoming pod, 5 Preemption is not helpful for scheduling."
31.9447,Pod,MODIFIED,eval-sanitize-20-r0-024-g6xwd,phase=Pending node=None
31.9449,Event,ADDED,eval-sanitize-20-r0-024-g6xwd.18d41a5fd208f63b,"reason=FailedScheduling count=None msg=0/6 nodes are available: 1 c_wall violated: 1 conflicting context pair(s) with node memory, 5 node(s) had untolerated taint(s). no new claims to deallocate, preemption: 0/6 nodes are available: 1 No preemption victims found for incoming pod, 5 Preemption is not helpful for scheduling."
31.9525,Pod,MODIFIED,eval-sanitize-20-r0-025-gp5dc,phase=Pending node=None
31.9528,Event,ADDED,eval-sanitize-20-r0-025-gp5dc.18d41a5fd283d507,"reason=FailedScheduling count=None msg=0/6 nodes are available: 1 c_wall violated: 1 conflicting context pair(s) with node memory, 5 node(s) had untolerated taint(s). no new claims to deallocate, preemption: 0/6 nodes are available: 1 No preemption victims found for incoming pod, 5 Preemption is not helpful for scheduling."
31.9718,Pod,MODIFIED,eval-sanitize-20-r0-026-2vx96,phase=Pending node=None
31.9722,Event,ADDED,eval-sanitize-20-r0-026-2vx96.18d41a5fd3a8ca16,"reason=FailedScheduling count=None msg=0/6 nodes are available: 1 c_wall violated: 1 conflicting context pair(s) with node memory, 5 node(s) had untolerated taint(s). no new claims to deallocate, preemption: 0/6 nodes are available: 1 No preemption victims found for incoming pod, 5 Preemption is not helpful for scheduling."
31.9801,Pod,MODIFIED,eval-sanitize-20-r0-027-mccff,phase=Pending node=None
31.9809,Event,ADDED,eval-sanitize-20-r0-027-mccff.18d41a5fd4294248,"reason=FailedScheduling count=None msg=0/6 nodes are available: 1 c_wall violated: 2 conflicting context pair(s) with node memory, 5 node(s) had untolerated taint(s). no new claims to deallocate, preemption: 0/6 nodes are available: 1 No preemption victims found for incoming pod, 5 Preemption is not helpful for scheduling."
31.9872,Pod,MODIFIED,eval-sanitize-20-r0-028-nr6jw,phase=Pending node=None
31.9876,Event,ADDED,eval-sanitize-20-r0-028-nr6jw.18d41a5fd49bc368,"reason=FailedScheduling count=None msg=0/6 nodes are available: 1 c_wall violated: 1 conflicting context pair(s) with node memory, 5 node(s) had untolerated taint(s). no new claims to deallocate, preemption: 0/6 nodes are available: 1 No preemption victims found for incoming pod, 5 Preemption is not helpful for scheduling."
32.0064,TaskRequest,ADDED,eval-sanitize-20-r0-032,phase=None job=None
32.0101,TaskRequest,MODIFIED,eval-sanitize-20-r0-032,phase=Pending job=None
32.0191,Pod,MODIFIED,eval-sanitize-20-r0-029-z4hhp,phase=Pending node=None
32.021,Event,ADDED,eval-sanitize-20-r0-029-z4hhp.18d41a5fd66cfe38,"reason=FailedScheduling count=None msg=0/6 nodes are available: 1 c_wall violated: 1 conflicting context pair(s) with node memory, 5 node(s) had untolerated taint(s). no new claims to deallocate, preemption: 0/6 nodes are available: 1 No preemption victims found for incoming pod, 5 Preemption is not helpful for scheduling."
32.0267,Job,ADDED,eval-sanitize-20-r0-032,
32.0346,Pod,ADDED,eval-sanitize-20-r0-032-7bknl,phase=Pending node=None
32.0358,TaskRequest,MODIFIED,eval-sanitize-20-r0-032,phase=Scheduled job=None
32.0368,Job,MODIFIED,eval-sanitize-20-r0-032,
32.0399,Event,ADDED,eval-sanitize-20-r0-032.18d41a5fd7aaa084,reason=SuccessfulCreate count=1 msg=Created pod: eval-sanitize-20-r0-032-7bknl
32.0443,Pod,MODIFIED,eval-sanitize-20-r0-030-vsswq,phase=Pending node=None
32.0456,Event,ADDED,eval-sanitize-20-r0-030-vsswq.18d41a5fd7ee6c8b,"reason=FailedScheduling count=None msg=0/6 nodes are available: 1 c_wall violated: 1 conflicting context pair(s) with node memory, 5 node(s) had untolerated taint(s). no new claims to deallocate, preemption: 0/6 nodes are available: 1 No preemption victims found for incoming pod, 5 Preemption is not helpful for scheduling."
32.0465,Job,MODIFIED,eval-sanitize-20-r0-031,
32.0474,TaskRequest,MODIFIED,eval-sanitize-20-r0-032,phase=Scheduled job=None
32.0527,Pod,MODIFIED,eval-sanitize-20-r0-032-7bknl,phase=Pending node=None
32.053,Event,ADDED,eval-sanitize-20-r0-032-7bknl.18d41a5fd87cb265,"reason=FailedScheduling count=None msg=0/6 nodes are available: 1 c_wall violated: 2 conflicting context pair(s) with node memory, 5 node(s) had untolerated taint(s). no new claims to deallocate, preemption: 0/6 nodes are available: 1 No preemption victims found for incoming pod, 5 Preemption is not helpful for scheduling."
32.0553,Job,MODIFIED,eval-sanitize-20-r0-031,
32.0726,Pod,MODIFIED,eval-sanitize-20-r0-031-rj57f,phase=Pending node=None
32.0734,Event,ADDED,eval-sanitize-20-r0-031-rj57f.18d41a5fd99e19cd,"reason=FailedScheduling count=None msg=0/6 nodes are available: 1 c_wall violated: 1 conflicting context pair(s) with node memory, 5 node(s) had untolerated taint(s). no new claims to deallocate, preemption: 0/6 nodes are available: 1 No preemption victims found for incoming pod, 5 Preemption is not helpful for scheduling."
32.0812,Pod,MODIFIED,eval-sanitize-20-r0-013-s7vkg,phase=Pending node=None
32.0815,Event,ADDED,eval-sanitize-20-r0-013-s7vkg.18d41a5fda2ed63e,"reason=FailedScheduling count=None msg=0/6 nodes are available: 1 c_wall violated: 2 conflicting context pair(s) with node memory, 5 node(s) had untolerated taint(s). no new claims to deallocate, preemption: 0/6 nodes are available: 1 No preemption victims found for incoming pod, 5 Preemption is not helpful for scheduling."
32.0881,Event,ADDED,eval-sanitize-20-r0-014-nzkw8.18d41a5fdaa73aae,"reason=FailedScheduling count=None msg=0/6 nodes are available: 1 c_wall violated: 1 conflicting context pair(s) with node memory, 5 node(s) had untolerated taint(s). no new claims to deallocate, preemption: 0/6 nodes are available: 1 No preemption victims found for incoming pod, 5 Preemption is not helpful for scheduling."
32.1104,Event,ADDED,eval-sanitize-20-r0-015-txnkr.18d41a5fdbf3ed84,"reason=FailedScheduling count=None msg=0/6 nodes are available: 1 c_wall violated: 1 conflicting context pair(s) with node memory, 5 node(s) had untolerated taint(s). no new claims to deallocate, preemption: 0/6 nodes are available: 1 No preemption victims found for incoming pod, 5 Preemption is not helpful for scheduling."
32.1451,Event,ADDED,eval-sanitize-20-r0-016-wsgf9.18d41a5fdde06f25,"reason=FailedScheduling count=None msg=0/6 nodes are available: 1 c_wall violated: 1 conflicting context pair(s) with node memory, 5 node(s) had untolerated taint(s). no new claims to deallocate, preemption: 0/6 nodes are available: 1 No preemption victims found for incoming pod, 5 Preemption is not helpful for scheduling."
32.1456,Event,ADDED,eval-sanitize-20-r0-017-tq46z.18d41a5fde135abc,"reason=FailedScheduling count=None msg=0/6 nodes are available: 1 c_wall violated: 1 conflicting context pair(s) with node memory, 5 node(s) had untolerated taint(s). no new claims to deallocate, preemption: 0/6 nodes are available: 1 No preemption victims found for incoming pod, 5 Preemption is not helpful for scheduling."
32.148,Event,ADDED,eval-sanitize-20-r0-019-7rmqh.18d41a5fde416f32,"reason=FailedScheduling count=None msg=0/6 nodes are available: 1 c_wall violated: 1 conflicting context pair(s) with node memory, 5 node(s) had untolerated taint(s). no new claims to deallocate, preemption: 0/6 nodes are available: 1 No preemption victims found for incoming pod, 5 Preemption is not helpful for scheduling."
32.1522,Event,ADDED,eval-sanitize-20-r0-020-hjlkw.18d41a5fde715d3d,"reason=FailedScheduling count=None msg=0/6 nodes are available: 1 c_wall violated: 1 conflicting context pair(s) with node memory, 5 node(s) had untolerated taint(s). no new claims to deallocate, preemption: 0/6 nodes are available: 1 No preemption victims found for incoming pod, 5 Preemption is not helpful for scheduling."
32.154,Event,ADDED,eval-sanitize-20-r0-021-clzvc.18d41a5fde9c3473,"reason=FailedScheduling count=None msg=0/6 nodes are available: 1 c_wall violated: 1 conflicting context pair(s) with node memory, 5 node(s) had untolerated taint(s). no new claims to deallocate, preemption: 0/6 nodes are available: 1 No preemption victims found for incoming pod, 5 Preemption is not helpful for scheduling."
32.1566,Event,ADDED,eval-sanitize-20-r0-022-bj2qs.18d41a5fdec8e577,"reason=FailedScheduling count=None msg=0/6 nodes are available: 1 c_wall violated: 1 conflicting context pair(s) with node memory, 5 node(s) had untolerated taint(s). no new claims to deallocate, preemption: 0/6 nodes are available: 1 No preemption victims found for incoming pod, 5 Preemption is not helpful for scheduling."
32.2116,Event,ADDED,eval-sanitize-20-r0-023-5gj96.18d41a5fe1eba739,"reason=FailedScheduling count=None msg=0/6 nodes are available: 1 c_wall violated: 1 conflicting context pair(s) with node memory, 5 node(s) had untolerated taint(s). no new claims to deallocate, preemption: 0/6 nodes are available: 1 No preemption victims found for incoming pod, 5 Preemption is not helpful for scheduling."
32.2199,Event,ADDED,eval-sanitize-20-r0-012-q6srf.18d41a5fe26aeb00,"reason=Pulled count=1 msg=Container image ""busybox:musl"" already present on machine"
32.2388,Event,ADDED,eval-sanitize-20-r0-012-q6srf.18d41a5fe3993f48,reason=Created count=1 msg=Created container: task
32.2607,Event,ADDED,eval-sanitize-20-r0-018-hz2rn.18d41a5fe4e79d6a,"reason=Pulled count=1 msg=Container image ""busybox:musl"" already present on machine"
32.2713,Event,ADDED,eval-sanitize-20-r0-024-g6xwd.18d41a5fe58bdaa8,"reason=FailedScheduling count=None msg=0/6 nodes are available: 1 c_wall violated: 1 conflicting context pair(s) with node memory, 5 node(s) had untolerated taint(s). no new claims to deallocate, preemption: 0/6 nodes are available: 1 No preemption victims found for incoming pod, 5 Preemption is not helpful for scheduling."
32.2745,Event,ADDED,eval-sanitize-20-r0-012-q6srf.18d41a5fe5ab2e02,reason=Started count=1 msg=Started container task
32.2755,Event,ADDED,eval-sanitize-20-r0-025-gp5dc.18d41a5fe5cc4388,"reason=FailedScheduling count=None msg=0/6 nodes are available: 1 c_wall violated: 1 conflicting context pair(s) with node memory, 5 node(s) had untolerated taint(s). no new claims to deallocate, preemption: 0/6 nodes are available: 1 No preemption victims found for incoming pod, 5 Preemption is not helpful for scheduling."
32.2778,Event,ADDED,eval-sanitize-20-r0-026-2vx96.18d41a5fe5fd9577,"reason=FailedScheduling count=None msg=0/6 nodes are available: 1 c_wall violated: 1 conflicting context pair(s) with node memory, 5 node(s) had untolerated taint(s). no new claims to deallocate, preemption: 0/6 nodes are available: 1 No preemption victims found for incoming pod, 5 Preemption is not helpful for scheduling."
32.2806,Event,ADDED,eval-sanitize-20-r0-027-mccff.18d41a5fe628cf64,"reason=FailedScheduling count=None msg=0/6 nodes are available: 1 c_wall violated: 2 conflicting context pair(s) with node memory, 5 node(s) had untolerated taint(s). no new claims to deallocate, preemption: 0/6 nodes are available: 1 No preemption victims found for incoming pod, 5 Preemption is not helpful for scheduling."
32.283,Event,ADDED,eval-sanitize-20-r0-018-hz2rn.18d41a5fe632d88f,reason=Created count=1 msg=Created container: task
32.2848,Event,ADDED,eval-sanitize-20-r0-028-nr6jw.18d41a5fe65d429e,"reason=FailedScheduling count=None msg=0/6 nodes are available: 1 c_wall violated: 1 conflicting context pair(s) with node memory, 5 node(s) had untolerated taint(s). no new claims to deallocate, preemption: 0/6 nodes are available: 1 No preemption victims found for incoming pod, 5 Preemption is not helpful for scheduling."
32.2882,Event,ADDED,eval-sanitize-20-r0-029-z4hhp.18d41a5fe694b9a8,"reason=FailedScheduling count=None msg=0/6 nodes are available: 1 c_wall violated: 1 conflicting context pair(s) with node memory, 5 node(s) had untolerated taint(s). no new claims to deallocate, preemption: 0/6 nodes are available: 1 No preemption victims found for incoming pod, 5 Preemption is not helpful for scheduling."
32.3191,Event,ADDED,eval-sanitize-20-r0-018-hz2rn.18d41a5fe8582a06,reason=Started count=1 msg=Started container task
32.3428,Event,ADDED,eval-sanitize-20-r0-030-vsswq.18d41a5fe9cdada2,"reason=FailedScheduling count=None msg=0/6 nodes are available: 1 c_wall violated: 1 conflicting context pair(s) with node memory, 5 node(s) had untolerated taint(s). no new claims to deallocate, preemption: 0/6 nodes are available: 1 No preemption victims found for incoming pod, 5 Preemption is not helpful for scheduling."
32.3464,Event,ADDED,eval-sanitize-20-r0-032-7bknl.18d41a5fea04202e,"reason=FailedScheduling count=None msg=0/6 nodes are available: 1 c_wall violated: 2 conflicting context pair(s) with node memory, 5 node(s) had untolerated taint(s). no new claims to deallocate, preemption: 0/6 nodes are available: 1 No preemption victims found for incoming pod, 5 Preemption is not helpful for scheduling."
32.3482,Event,ADDED,eval-sanitize-20-r0-031-rj57f.18d41a5fea310099,"reason=FailedScheduling count=None msg=0/6 nodes are available: 1 c_wall violated: 1 conflicting context pair(s) with node memory, 5 node(s) had untolerated taint(s). no new claims to deallocate, preemption: 0/6 nodes are available: 1 No preemption victims found for incoming pod, 5 Preemption is not helpful for scheduling."
32.3523,Event,ADDED,eval-sanitize-20-r0-013-s7vkg.18d41a5fea60481e,"reason=FailedScheduling count=None msg=0/6 nodes are available: 1 c_wall violated: 2 conflicting context pair(s) with node memory, 5 node(s) had untolerated taint(s). no new claims to deallocate, preemption: 0/6 nodes are available: 1 No preemption victims found for incoming pod, 5 Preemption is not helpful for scheduling."
32.494,Node,MODIFIED,kind-worker4,taints=1
32.5042,Event,MODIFIED,eval-sanitize-20-r0-014-nzkw8.18d41a5fdaa73aae,"reason=FailedScheduling count=None msg=0/6 nodes are available: 1 c_wall violated: 1 conflicting context pair(s) with node memory, 5 node(s) had untolerated taint(s). no new claims to deallocate, preemption: 0/6 nodes are available: 1 No preemption victims found for incoming pod, 5 Preemption is not helpful for scheduling."
32.5048,Event,MODIFIED,eval-sanitize-20-r0-015-txnkr.18d41a5fdbf3ed84,"reason=FailedScheduling count=None msg=0/6 nodes are available: 1 c_wall violated: 1 conflicting context pair(s) with node memory, 5 node(s) had untolerated taint(s). no new claims to deallocate, preemption: 0/6 nodes are available: 1 No preemption victims found for incoming pod, 5 Preemption is not helpful for scheduling."
32.508,Event,MODIFIED,eval-sanitize-20-r0-016-wsgf9.18d41a5fdde06f25,"reason=FailedScheduling count=None msg=0/6 nodes are available: 1 c_wall violated: 1 conflicting context pair(s) with node memory, 5 node(s) had untolerated taint(s). no new claims to deallocate, preemption: 0/6 nodes are available: 1 No preemption victims found for incoming pod, 5 Preemption is not helpful for scheduling."
32.5124,Event,MODIFIED,eval-sanitize-20-r0-017-tq46z.18d41a5fde135abc,"reason=FailedScheduling count=None msg=0/6 nodes are available: 1 c_wall violated: 1 conflicting context pair(s) with node memory, 5 node(s) had untolerated taint(s). no new claims to deallocate, preemption: 0/6 nodes are available: 1 No preemption victims found for incoming pod, 5 Preemption is not helpful for scheduling."
32.5133,Event,MODIFIED,eval-sanitize-20-r0-019-7rmqh.18d41a5fde416f32,"reason=FailedScheduling count=None msg=0/6 nodes are available: 1 c_wall violated: 1 conflicting context pair(s) with node memory, 5 node(s) had untolerated taint(s). no new claims to deallocate, preemption: 0/6 nodes are available: 1 No preemption victims found for incoming pod, 5 Preemption is not helpful for scheduling."
32.516,Event,MODIFIED,eval-sanitize-20-r0-020-hjlkw.18d41a5fde715d3d,"reason=FailedScheduling count=None msg=0/6 nodes are available: 1 c_wall violated: 1 conflicting context pair(s) with node memory, 5 node(s) had untolerated taint(s). no new claims to deallocate, preemption: 0/6 nodes are available: 1 No preemption victims found for incoming pod, 5 Preemption is not helpful for scheduling."
32.5201,Event,MODIFIED,eval-sanitize-20-r0-021-clzvc.18d41a5fde9c3473,"reason=FailedScheduling count=None msg=0/6 nodes are available: 1 c_wall violated: 1 conflicting context pair(s) with node memory, 5 node(s) had untolerated taint(s). no new claims to deallocate, preemption: 0/6 nodes are available: 1 No preemption victims found for incoming pod, 5 Preemption is not helpful for scheduling."
32.5431,Event,MODIFIED,eval-sanitize-20-r0-022-bj2qs.18d41a5fdec8e577,"reason=FailedScheduling count=None msg=0/6 nodes are available: 1 c_wall violated: 1 conflicting context pair(s) with node memory, 5 node(s) had untolerated taint(s). no new claims to deallocate, preemption: 0/6 nodes are available: 1 No preemption victims found for incoming pod, 5 Preemption is not helpful for scheduling."
32.5453,Event,MODIFIED,eval-sanitize-20-r0-023-5gj96.18d41a5fe1eba739,"reason=FailedScheduling count=None msg=0/6 nodes are available: 1 c_wall violated: 1 conflicting context pair(s) with node memory, 5 node(s) had untolerated taint(s). no new claims to deallocate, preemption: 0/6 nodes are available: 1 No preemption victims found for incoming pod, 5 Preemption is not helpful for scheduling."
32.5494,Event,MODIFIED,eval-sanitize-20-r0-024-g6xwd.18d41a5fe58bdaa8,"reason=FailedScheduling count=None msg=0/6 nodes are available: 1 c_wall violated: 1 conflicting context pair(s) with node memory, 5 node(s) had untolerated taint(s). no new claims to deallocate, preemption: 0/6 nodes are available: 1 No preemption victims found for incoming pod, 5 Preemption is not helpful for scheduling."
32.5501,Event,MODIFIED,eval-sanitize-20-r0-025-gp5dc.18d41a5fe5cc4388,"reason=FailedScheduling count=None msg=0/6 nodes are available: 1 c_wall violated: 1 conflicting context pair(s) with node memory, 5 node(s) had untolerated taint(s). no new claims to deallocate, preemption: 0/6 nodes are available: 1 No preemption victims found for incoming pod, 5 Preemption is not helpful for scheduling."
32.5933,Node,MODIFIED,kind-worker4,taints=1
32.6173,Event,MODIFIED,eval-sanitize-20-r0-026-2vx96.18d41a5fe5fd9577,"reason=FailedScheduling count=None msg=0/6 nodes are available: 1 c_wall violated: 1 conflicting context pair(s) with node memory, 5 node(s) had untolerated taint(s). no new claims to deallocate, preemption: 0/6 nodes are available: 1 No preemption victims found for incoming pod, 5 Preemption is not helpful for scheduling."
32.6183,Event,MODIFIED,eval-sanitize-20-r0-027-mccff.18d41a5fe628cf64,"reason=FailedScheduling count=None msg=0/6 nodes are available: 1 c_wall violated: 2 conflicting context pair(s) with node memory, 5 node(s) had untolerated taint(s). no new claims to deallocate, preemption: 0/6 nodes are available: 1 No preemption victims found for incoming pod, 5 Preemption is not helpful for scheduling."
32.6217,Event,MODIFIED,eval-sanitize-20-r0-028-nr6jw.18d41a5fe65d429e,"reason=FailedScheduling count=None msg=0/6 nodes are available: 1 c_wall violated: 1 conflicting context pair(s) with node memory, 5 node(s) had untolerated taint(s). no new claims to deallocate, preemption: 0/6 nodes are available: 1 No preemption victims found for incoming pod, 5 Preemption is not helpful for scheduling."
32.6224,Event,MODIFIED,eval-sanitize-20-r0-029-z4hhp.18d41a5fe694b9a8,"reason=FailedScheduling count=None msg=0/6 nodes are available: 1 c_wall violated: 1 conflicting context pair(s) with node memory, 5 node(s) had untolerated taint(s). no new claims to deallocate, preemption: 0/6 nodes are available: 1 No preemption victims found for incoming pod, 5 Preemption is not helpful for scheduling."
32.6443,Event,MODIFIED,eval-sanitize-20-r0-030-vsswq.18d41a5fe9cdada2,"reason=FailedScheduling count=None msg=0/6 nodes are available: 1 c_wall violated: 1 conflicting context pair(s) with node memory, 5 node(s) had untolerated taint(s). no new claims to deallocate, preemption: 0/6 nodes are available: 1 No preemption victims found for incoming pod, 5 Preemption is not helpful for scheduling."
32.648,Event,MODIFIED,eval-sanitize-20-r0-032-7bknl.18d41a5fea04202e,"reason=FailedScheduling count=None msg=0/6 nodes are available: 1 c_wall violated: 2 conflicting context pair(s) with node memory, 5 node(s) had untolerated taint(s). no new claims to deallocate, preemption: 0/6 nodes are available: 1 No preemption victims found for incoming pod, 5 Preemption is not helpful for scheduling."
32.6487,Event,MODIFIED,eval-sanitize-20-r0-031-rj57f.18d41a5fea310099,"reason=FailedScheduling count=None msg=0/6 nodes are available: 1 c_wall violated: 1 conflicting context pair(s) with node memory, 5 node(s) had untolerated taint(s). no new claims to deallocate, preemption: 0/6 nodes are available: 1 No preemption victims found for incoming pod, 5 Preemption is not helpful for scheduling."
32.7152,Event,MODIFIED,eval-sanitize-20-r0-013-s7vkg.18d41a5fea60481e,"reason=FailedScheduling count=None msg=0/6 nodes are available: 1 c_wall violated: 2 conflicting context pair(s) with node memory, 5 node(s) had untolerated taint(s). no new claims to deallocate, preemption: 0/6 nodes are available: 1 No preemption victims found for incoming pod, 5 Preemption is not helpful for scheduling."
32.8027,Node,MODIFIED,kind-worker4,taints=0
32.8156,Pod,MODIFIED,eval-sanitize-20-r0-021-clzvc,phase=Pending node=kind-worker4
32.8191,Event,ADDED,eval-sanitize-20-r0-021-clzvc.18d41a6006350542,reason=Scheduled count=None msg=Successfully assigned compute/eval-sanitize-20-r0-021-clzvc to kind-worker4
32.8229,Pod,MODIFIED,eval-sanitize-20-r0-022-bj2qs,phase=Pending node=kind-worker4
32.8275,Node,MODIFIED,kind-worker4,taints=0
32.8305,Event,ADDED,eval-sanitize-20-r0-022-bj2qs.18d41a6006a25910,reason=Scheduled count=None msg=Successfully assigned compute/eval-sanitize-20-r0-022-bj2qs to kind-worker4
32.832,Pod,MODIFIED,eval-sanitize-20-r0-021-clzvc,phase=Pending node=kind-worker4
32.8386,Pod,MODIFIED,eval-sanitize-20-r0-022-bj2qs,phase=Pending node=kind-worker4
32.8488,Pod,MODIFIED,eval-sanitize-20-r0-023-5gj96,phase=Pending node=None
32.8552,Node,MODIFIED,kind-worker4,taints=0
32.8909,Node,MODIFIED,kind-worker4,taints=0
32.9189,Pod,MODIFIED,eval-sanitize-20-r0-024-g6xwd,phase=Pending node=None
32.9297,Pod,MODIFIED,eval-sanitize-20-r0-025-gp5dc,phase=Pending node=None
32.9461,Pod,MODIFIED,eval-sanitize-20-r0-026-2vx96,phase=Pending node=None
32.9907,Node,MODIFIED,kind-worker4,taints=0
33.0062,TaskRequest,ADDED,eval-sanitize-20-r0-033,phase=None job=None
33.0122,Pod,MODIFIED,eval-sanitize-20-r0-027-mccff,phase=Pending node=kind-worker4
33.0123,TaskRequest,MODIFIED,eval-sanitize-20-r0-033,phase=Pending job=None
33.016,Event,ADDED,eval-sanitize-20-r0-027-mccff.18d41a6011eba381,reason=Scheduled count=None msg=Successfully assigned compute/eval-sanitize-20-r0-027-mccff to kind-worker4
33.0199,Pod,MODIFIED,eval-sanitize-20-r0-028-nr6jw,phase=Pending node=None
33.0238,Node,MODIFIED,kind-worker4,taints=0
33.0267,Pod,MODIFIED,eval-sanitize-20-r0-027-mccff,phase=Pending node=kind-worker4
33.0307,Job,ADDED,eval-sanitize-20-r0-033,
33.0379,Pod,ADDED,eval-sanitize-20-r0-033-5lzzb,phase=Pending node=None
33.038,TaskRequest,MODIFIED,eval-sanitize-20-r0-033,phase=Scheduled job=None
33.041,Job,MODIFIED,eval-sanitize-20-r0-032,
33.0421,Job,MODIFIED,eval-sanitize-20-r0-033,
33.0433,Event,ADDED,eval-sanitize-20-r0-033.18d41a6013780082,reason=SuccessfulCreate count=1 msg=Created pod: eval-sanitize-20-r0-033-5lzzb
33.0463,Pod,MODIFIED,eval-sanitize-20-r0-029-z4hhp,phase=Pending node=None
33.0464,TaskRequest,MODIFIED,eval-sanitize-20-r0-033,phase=Scheduled job=None
33.0526,Job,MODIFIED,eval-sanitize-20-r0-032,
33.0896,Node,MODIFIED,kind-worker4,taints=0
33.1177,Pod,MODIFIED,eval-sanitize-20-r0-033-5lzzb,phase=Pending node=None
33.1181,Event,ADDED,eval-sanitize-20-r0-033-5lzzb.18d41a6017a3670b,"reason=FailedScheduling count=None msg=0/6 nodes are available: 2 c_wall violated: 1 conflicting context pair(s) with node memory, 4 node(s) had untolerated taint(s). no new claims to deallocate, preemption: 0/6 nodes are available: 2 No preemption victims found for incoming pod, 4 Preemption is not helpful for scheduling."
33.1299,Pod,MODIFIED,eval-sanitize-20-r0-030-vsswq,phase=Pending node=kind-worker4
33.1355,Event,ADDED,eval-sanitize-20-r0-030-vsswq.18d41a6018f31e11,reason=Scheduled count=None msg=Successfully assigned compute/eval-sanitize-20-r0-030-vsswq to kind-worker4
33.1412,Pod,MODIFIED,eval-sanitize-20-r0-018-hz2rn,phase=Running node=kind-worker
33.1441,Pod,MODIFIED,eval-sanitize-20-r0-030-vsswq,phase=Pending node=kind-worker4
33.1479,Pod,MODIFIED,eval-sanitize-20-r0-032-7bknl,phase=Pending node=kind-worker4
33.1509,Pod,MODIFIED,eval-sanitize-20-r0-012-q6srf,phase=Running node=kind-worker
33.1553,Event,ADDED,eval-sanitize-20-r0-032-7bknl.18d41a601a0aa861,reason=Scheduled count=None msg=Successfully assigned compute/eval-sanitize-20-r0-032-7bknl to kind-worker4
33.1622,Pod,MODIFIED,eval-sanitize-20-r0-032-7bknl,phase=Pending node=kind-worker4
33.2151,Pod,MODIFIED,eval-sanitize-20-r0-031-rj57f,phase=Pending node=None
33.2253,Pod,MODIFIED,eval-sanitize-20-r0-013-s7vkg,phase=Pending node=kind-worker4
33.2299,Event,ADDED,eval-sanitize-20-r0-013-s7vkg.18d41a601eaa49f4,reason=Scheduled count=None msg=Successfully assigned compute/eval-sanitize-20-r0-013-s7vkg to kind-worker4
33.2355,Pod,MODIFIED,eval-sanitize-20-r0-013-s7vkg,phase=Pending node=kind-worker4
33.2472,Pod,MODIFIED,eval-sanitize-20-r0-014-nzkw8,phase=Pending node=kind-worker4
33.2505,Event,ADDED,eval-sanitize-20-r0-014-nzkw8.18d41a601ff5e687,reason=Scheduled count=None msg=Successfully assigned compute/eval-sanitize-20-r0-014-nzkw8 to kind-worker4
33.2595,Pod,MODIFIED,eval-sanitize-20-r0-014-nzkw8,phase=Pending node=kind-worker4
33.2697,Event,ADDED,eval-sanitize-20-r0-021-clzvc.18d41a60210ebb00,"reason=Pulled count=1 msg=Container image ""busybox:musl"" already present on machine"
33.2807,Event,ADDED,eval-sanitize-20-r0-022-bj2qs.18d41a60219aca64,"reason=Pulled count=1 msg=Container image ""busybox:musl"" already present on machine"
33.2924,Event,ADDED,eval-sanitize-20-r0-021-clzvc.18d41a60227695f8,reason=Created count=1 msg=Created container: task
33.3019,Event,ADDED,eval-sanitize-20-r0-022-bj2qs.18d41a6023077416,reason=Created count=1 msg=Created container: task
33.3189,Pod,MODIFIED,eval-sanitize-20-r0-015-txnkr,phase=Pending node=None
33.3312,Pod,MODIFIED,eval-sanitize-20-r0-016-wsgf9,phase=Pending node=None
33.3467,Pod,MODIFIED,eval-sanitize-20-r0-017-tq46z,phase=Pending node=kind-worker4
33.3501,Event,ADDED,eval-sanitize-20-r0-017-tq46z.18d41a6025de2d25,reason=Scheduled count=None msg=Successfully assigned compute/eval-sanitize-20-r0-017-tq46z to kind-worker4
33.354,Event,ADDED,eval-sanitize-20-r0-021-clzvc.18d41a602623dcdc,reason=Started count=1 msg=Started container task
33.3626,Pod,MODIFIED,eval-sanitize-20-r0-017-tq46z,phase=Pending node=kind-worker4
33.3629,Event,ADDED,eval-sanitize-20-r0-022-bj2qs.18d41a602670d557,reason=Started count=1 msg=Started container task
33.4143,Pod,MODIFIED,eval-sanitize-20-r0-019-7rmqh,phase=Pending node=None
33.4386,Event,ADDED,eval-sanitize-20-r0-027-mccff.18d41a602b1f024d,"reason=Pulled count=1 msg=Container image ""busybox:musl"" already present on machine"
33.4441,Pod,MODIFIED,eval-sanitize-20-r0-020-hjlkw,phase=Pending node=None
33.4547,Pod,MODIFIED,eval-sanitize-20-r0-023-5gj96,phase=Pending node=None
33.455,Event,ADDED,eval-sanitize-20-r0-023-5gj96.18d41a602c0414f3,"reason=FailedScheduling count=None msg=0/6 nodes are available: 1 c_wall violated: 1 conflicting context pair(s) with node memory, 1 c_wall violated: 3 conflicting context pair(s) with node memory, 4 node(s) had untolerated taint(s). no new claims to deallocate, preemption: 0/6 nodes are available: 2 No preemption victims found for incoming pod, 4 Preemption is not helpful for scheduling."
33.4659,Event,ADDED,eval-sanitize-20-r0-027-mccff.18d41a602ca2f1b5,reason=Created count=1 msg=Created container: task
33.5187,Pod,MODIFIED,eval-sanitize-20-r0-024-g6xwd,phase=Pending node=None
33.5224,Event,ADDED,eval-sanitize-20-r0-024-g6xwd.18d41a602fafdb9b,"reason=FailedScheduling count=None msg=0/6 nodes are available: 1 c_wall violated: 1 conflicting context pair(s) with node memory, 1 c_wall violated: 3 conflicting context pair(s) with node memory, 4 node(s) had untolerated taint(s). no new claims to deallocate, preemption: 0/6 nodes are available: 2 No preemption victims found for incoming pod, 4 Preemption is not helpful for scheduling."
33.5251,Event,ADDED,eval-sanitize-20-r0-027-mccff.18d41a60304cf278,reason=Started count=1 msg=Started container task
33.5468,Pod,MODIFIED,eval-sanitize-20-r0-025-gp5dc,phase=Pending node=None
33.5471,Event,ADDED,eval-sanitize-20-r0-025-gp5dc.18d41a60315cd3f6,"reason=FailedScheduling count=None msg=0/6 nodes are available: 1 c_wall violated: 1 conflicting context pair(s) with node memory, 1 c_wall violated: 2 conflicting context pair(s) with node memory, 4 node(s) had untolerated taint(s). no new claims to deallocate, preemption: 0/6 nodes are available: 2 No preemption victims found for incoming pod, 4 Preemption is not helpful for scheduling."
33.5473,Event,ADDED,eval-sanitize-20-r0-030-vsswq.18d41a6031664c45,"reason=Pulled count=1 msg=Container image ""busybox:musl"" already present on machine"
33.5719,Event,ADDED,eval-sanitize-20-r0-030-vsswq.18d41a6032e54335,reason=Created count=1 msg=Created container: task
33.5815,Event,ADDED,eval-sanitize-20-r0-032-7bknl.18d41a60338d9086,"reason=Pulled count=1 msg=Container image ""busybox:musl"" already present on machine"
33.5902,Pod,MODIFIED,eval-sanitize-20-r0-022-bj2qs,phase=Running node=kind-worker4
33.5993,Pod,MODIFIED,eval-sanitize-20-r0-027-mccff,phase=Running node=kind-worker4
33.6082,Pod,MODIFIED,eval-sanitize-20-r0-021-clzvc,phase=Running node=kind-worker4
33.61,Event,ADDED,eval-sanitize-20-r0-030-vsswq.18d41a603547bbaa,reason=Started count=1 msg=Started container task
33.6129,Event,ADDED,eval-sanitize-20-r0-026-2vx96.18d41a60356157fe,"reason=FailedScheduling count=None msg=0/6 nodes are available: 1 c_wall violated: 1 conflicting context pair(s) with node memory, 1 c_wall violated: 2 conflicting context pair(s) with node memory, 4 node(s) had untolerated taint(s). no new claims to deallocate, preemption: 0/6 nodes are available: 2 No preemption victims found for incoming pod, 4 Preemption is not helpful for scheduling."
33.6146,Pod,MODIFIED,eval-sanitize-20-r0-026-2vx96,phase=Pending node=None
33.6152,Event,ADDED,eval-sanitize-20-r0-032-7bknl.18d41a6035aca9a7,reason=Created count=1 msg=Created container: task
33.6278,Event,ADDED,eval-sanitize-20-r0-028-nr6jw.18d41a60364515c1,"reason=FailedScheduling count=None msg=0/6 nodes are available: 2 c_wall violated: 1 conflicting context pair(s) with node memory, 4 node(s) had untolerated taint(s). no new claims to deallocate, preemption: 0/6 nodes are available: 2 No preemption victims found for incoming pod, 4 Preemption is not helpful for scheduling."
33.6436,Event,ADDED,eval-sanitize-20-r0-013-s7vkg.18d41a60374f0540,"reason=Pulled count=1 msg=Container image ""busybox:musl"" already present on machine"
33.6444,Event,ADDED,eval-sanitize-20-r0-029-z4hhp.18d41a60376a0698,"reason=FailedScheduling count=None msg=0/6 nodes are available: 1 c_wall violated: 1 conflicting context pair(s) with node memory, 1 c_wall violated: 2 conflicting context pair(s) with node memory, 4 node(s) had untolerated taint(s). no new claims to deallocate, preemption: 0/6 nodes are available: 2 No preemption victims found for incoming pod, 4 Preemption is not helpful for scheduling."
33.6583,Event,ADDED,eval-sanitize-20-r0-032-7bknl.18d41a6038340231,reason=Started count=1 msg=Started container task
33.6645,Event,ADDED,eval-sanitize-20-r0-013-s7vkg.18d41a60387a353c,reason=Created count=1 msg=Created container: task
33.6693,Event,ADDED,eval-sanitize-20-r0-014-nzkw8.18d41a6038e2b44b,"reason=Pulled count=1 msg=Container image ""busybox:musl"" already present on machine"
33.6834,Node,MODIFIED,kind-worker3,taints=1
33.6879,Event,ADDED,eval-sanitize-20-r0-014-nzkw8.18d41a603a08cb5a,reason=Created count=1 msg=Created container: task
33.7169,Event,ADDED,eval-sanitize-20-r0-033-5lzzb.18d41a603b69feec,"reason=FailedScheduling count=None msg=0/6 nodes are available: 2 c_wall violated: 1 conflicting context pair(s) with node memory, 4 node(s) had untolerated taint(s). no new claims to deallocate, preemption: 0/6 nodes are available: 2 No preemption victims found for incoming pod, 4 Preemption is not helpful for scheduling."
33.7175,Event,ADDED,eval-sanitize-20-r0-031-rj57f.18d41a603bc2ddde,"reason=FailedScheduling count=None msg=0/6 nodes are available: 2 c_wall violated: 1 conflicting context pair(s) with node memory, 4 node(s) had untolerated taint(s). no new claims to deallocate, preemption: 0/6 nodes are available: 2 No preemption victims found for incoming pod, 4 Preemption is not helpful for scheduling."
33.7331,Event,ADDED,eval-sanitize-20-r0-013-s7vkg.18d41a603c99b4a5,reason=Started count=1 msg=Started container task
33.7374,Event,ADDED,eval-sanitize-20-r0-014-nzkw8.18d41a603cde09de,reason=Started count=1 msg=Started container task
33.7435,Event,ADDED,eval-sanitize-20-r0-015-txnkr.18d41a603d56c737,"reason=FailedScheduling count=None msg=0/6 nodes are available: 1 c_wall violated: 1 conflicting context pair(s) with node memory, 1 c_wall violated: 3 conflicting context pair(s) with node memory, 4 node(s) had untolerated taint(s). no new claims to deallocate, preemption: 0/6 nodes are available: 2 No preemption victims found for incoming pod, 4 Preemption is not helpful for scheduling."
33.7823,Event,ADDED,eval-sanitize-20-r0-017-tq46z.18d41a603fa1726f,"reason=Pulled count=1 msg=Container image ""busybox:musl"" already present on machine"
33.7859,Node,MODIFIED,kind-worker5,taints=1
33.788,Node,MODIFIED,kind-worker3,taints=1
33.8023,Event,ADDED,eval-sanitize-20-r0-017-tq46z.18d41a6040db631f,reason=Created count=1 msg=Created container: task
33.8123,Event,ADDED,eval-sanitize-20-r0-016-wsgf9.18d41a60416dd3fb,"reason=FailedScheduling count=None msg=0/6 nodes are available: 2 c_wall violated: 1 conflicting context pair(s) with node memory, 4 node(s) had untolerated taint(s). no new claims to deallocate, preemption: 0/6 nodes are available: 2 No preemption victims found for incoming pod, 4 Preemption is not helpful for scheduling."
33.8187,Event,ADDED,eval-sanitize-20-r0-019-7rmqh.18d41a6041c489ff,"reason=FailedScheduling count=None msg=0/6 nodes are available: 1 c_wall violated: 1 conflicting context pair(s) with node memory, 1 c_wall violated: 3 conflicting context pair(s) with node memory, 4 node(s) had untolerated taint(s). no new claims to deallocate, preemption: 0/6 nodes are available: 2 No preemption victims found for incoming pod, 4 Preemption is not helpful for scheduling."
33.8469,Event,ADDED,eval-sanitize-20-r0-020-hjlkw.18d41a60435d0fc8,"reason=FailedScheduling count=None msg=0/6 nodes are available: 2 c_wall violated: 1 conflicting context pair(s) with node memory, 4 node(s) had untolerated taint(s). no new claims to deallocate, preemption: 0/6 nodes are available: 2 No preemption victims found for incoming pod, 4 Preemption is not helpful for scheduling."
33.8814,Event,ADDED,eval-sanitize-20-r0-017-tq46z.18d41a6045874cf2,reason=Started count=1 msg=Started container task
33.886,Node,MODIFIED,kind-worker2,taints=1
33.8875,Node,MODIFIED,kind-worker5,taints=1
33.8976,Node,MODIFIED,kind-worker3,taints=0
33.9129,Event,ADDED,eval-sanitize-20-r0-023-5gj96.18d41a604758bf12,"reason=FailedScheduling count=None msg=0/6 nodes are available: 1 c_wall violated: 1 conflicting context pair(s) with node memory, 1 c_wall violated: 3 conflicting context pair(s) with node memory, 4 node(s) had untolerated taint(s). no new claims to deallocate, preemption: 0/6 nodes are available: 2 No preemption victims found for incoming pod, 4 Preemption is not helpful for scheduling."
33.9183,Pod,MODIFIED,eval-sanitize-20-r0-024-g6xwd,phase=Pending node=kind-worker3
33.9215,Event,ADDED,eval-sanitize-20-r0-024-g6xwd.18d41a6047f6089e,reason=Scheduled count=None msg=Successfully assigned compute/eval-sanitize-20-r0-024-g6xwd to kind-worker3
33.9279,Node,MODIFIED,kind-worker3,taints=0
33.9296,Pod,MODIFIED,eval-sanitize-20-r0-024-g6xwd,phase=Pending node=kind-worker3
33.9912,Node,MODIFIED,kind-worker2,taints=1
33.9958,Node,MODIFIED,kind-worker3,taints=0
34.0128,Pod,MODIFIED,eval-sanitize-20-r0-025-gp5dc,phase=Pending node=kind-worker3
34.0158,Event,ADDED,eval-sanitize-20-r0-025-gp5dc.18d41a604d85b2c8,reason=Scheduled count=None msg=Successfully assigned compute/eval-sanitize-20-r0-025-gp5dc to kind-worker3
34.0194,Job,MODIFIED,eval-sanitize-20-r0-027,
34.0253,Node,MODIFIED,kind-worker3,taints=0
34.0279,Pod,MODIFIED,eval-sanitize-20-r0-025-gp5dc,phase=Pending node=kind-worker3
34.0294,Job,MODIFIED,eval-sanitize-20-r0-027,
34.0426,Job,MODIFIED,eval-sanitize-20-r0-033,
34.0516,Pod,MODIFIED,eval-sanitize-20-r0-026-2vx96,phase=Pending node=kind-worker3
34.0551,Job,MODIFIED,eval-sanitize-20-r0-033,
34.0555,Event,ADDED,eval-sanitize-20-r0-026-2vx96.18d41a604fdeacd3,reason=Scheduled count=None msg=Successfully assigned compute/eval-sanitize-20-r0-026-2vx96 to kind-worker3
34.0635,Pod,MODIFIED,eval-sanitize-20-r0-026-2vx96,phase=Pending node=kind-worker3
34.0923,Node,MODIFIED,kind-worker3,taints=0
34.1074,TaskRequest,ADDED,eval-sanitize-20-r0-034,phase=None job=None
34.1111,TaskRequest,MODIFIED,eval-sanitize-20-r0-034,phase=Pending job=None
34.1266,Job,ADDED,eval-sanitize-20-r0-034,
34.1311,TaskRequest,MODIFIED,eval-sanitize-20-r0-034,phase=Scheduled job=None
34.1338,Pod,ADDED,eval-sanitize-20-r0-034-977cj,phase=Pending node=None
34.1356,Job,MODIFIED,eval-sanitize-20-r0-034,
34.1399,Event,ADDED,eval-sanitize-20-r0-034.18d41a6054d33cef,reason=SuccessfulCreate count=1 msg=Created pod: eval-sanitize-20-r0-034-977cj
34.14,TaskRequest,MODIFIED,eval-sanitize-20-r0-034,phase=Scheduled job=None
34.1435,Pod,MODIFIED,eval-sanitize-20-r0-028-nr6jw,phase=Pending node=None
34.1445,Event,MODIFIED,eval-sanitize-20-r0-028-nr6jw.18d41a60364515c1,"reason=FailedScheduling count=None msg=0/6 nodes are available: 2 c_wall violated: 1 conflicting context pair(s) with node memory, 4 node(s) had untolerated taint(s). no new claims to deallocate, preemption: 0/6 nodes are available: 2 No preemption victims found for incoming pod, 4 Preemption is not helpful for scheduling."
34.1457,Job,MODIFIED,eval-sanitize-20-r0-018,
34.154,Job,MODIFIED,eval-sanitize-20-r0-018,
34.1557,Job,MODIFIED,eval-sanitize-20-r0-012,
34.1644,Job,MODIFIED,eval-sanitize-20-r0-012,
34.1875,Node,MODIFIED,kind-worker3,taints=0
34.19,Node,MODIFIED,kind-worker5,taints=0
34.1913,Node,MODIFIED,kind-worker2,taints=0
34.2159,Pod,MODIFIED,eval-sanitize-20-r0-034-977cj,phase=Pending node=kind-worker4
34.2192,Event,ADDED,eval-sanitize-20-r0-034-977cj.18d41a6059ae0e29,reason=Scheduled count=None msg=Successfully assigned compute/eval-sanitize-20-r0-034-977cj to kind-worker4
34.227,Pod,MODIFIED,eval-sanitize-20-r0-034-977cj,phase=Pending node=kind-worker4
34.2388,Node,MODIFIED,kind-worker5,taints=0
34.2841,Node,MODIFIED,kind-worker2,taints=0
34.3254,Pod,MODIFIED,eval-sanitize-20-r0-029-z4hhp,phase=Pending node=kind-worker5
34.3368,Event,ADDED,eval-sanitize-20-r0-029-z4hhp.18d41a6060387ab4,reason=Scheduled count=None msg=Successfully assigned compute/eval-sanitize-20-r0-029-z4hhp to kind-worker5
34.3477,Node,MODIFIED,kind-worker5,taints=0
34.3499,Pod,MODIFIED,eval-sanitize-20-r0-029-z4hhp,phase=Pending node=kind-worker5
34.3508,Pod,MODIFIED,eval-sanitize-20-r0-033-5lzzb,phase=Pending node=kind-worker2
34.3612,Node,MODIFIED,kind-worker5,taints=0
34.3616,Event,ADDED,eval-sanitize-20-r0-024-g6xwd.18d41a6061d5d834,"reason=Pulled count=1 msg=Container image ""busybox:musl"" already present on machine"
34.3628,Pod,MODIFIED,eval-sanitize-20-r0-033-5lzzb,phase=Pending node=kind-worker2
34.3713,Event,ADDED,eval-sanitize-20-r0-033-5lzzb.18d41a6062b4104b,reason=Scheduled count=None msg=Successfully assigned compute/eval-sanitize-20-r0-033-5lzzb to kind-worker2
34.3768,Node,MODIFIED,kind-worker2,taints=0
34.3873,Node,MODIFIED,kind-worker2,taints=0
34.3938,Event,ADDED,eval-sanitize-20-r0-024-g6xwd.18d41a6063fc1d84,reason=Created count=1 msg=Created container: task
34.453,Event,ADDED,eval-sanitize-20-r0-024-g6xwd.18d41a6067966998,reason=Started count=1 msg=Started container task
34.4583,Event,ADDED,eval-sanitize-20-r0-025-gp5dc.18d41a6067f8149a,"reason=Pulled count=1 msg=Container image ""busybox:musl"" already present on machine"
34.4734,Event,ADDED,eval-sanitize-20-r0-026-2vx96.18d41a6068d71ff5,"reason=Pulled count=1 msg=Container image ""busybox:musl"" already present on machine"
34.4813,Event,ADDED,eval-sanitize-20-r0-025-gp5dc.18d41a606937762f,reason=Created count=1 msg=Created container: task
34.4945,Event,ADDED,eval-sanitize-20-r0-026-2vx96.18d41a606a1583c0,reason=Created count=1 msg=Created container: task
34.5138,Pod,MODIFIED,eval-sanitize-20-r0-031-rj57f,phase=Pending node=kind-worker2
34.5157,Event,ADDED,eval-sanitize-20-r0-025-gp5dc.18d41a606b4fabb8,reason=Started count=1 msg=Started container task
34.5173,Event,ADDED,eval-sanitize-20-r0-031-rj57f.18d41a606b7624a7,reason=Scheduled count=None msg=Successfully assigned compute/eval-sanitize-20-r0-031-rj57f to kind-worker2
34.5239,Pod,MODIFIED,eval-sanitize-20-r0-031-rj57f,phase=Pending node=kind-worker2
34.527,Node,MODIFIED,kind-worker2,taints=0
34.5329,Event,ADDED,eval-sanitize-20-r0-026-2vx96.18d41a606c6660fd,reason=Started count=1 msg=Started container task
34.5383,Node,MODIFIED,kind-worker2,taints=0
34.5955,Pod,MODIFIED,eval-sanitize-20-r0-030-vsswq,phase=Running node=kind-worker4
34.5964,Job,MODIFIED,eval-sanitize-20-r0-022,
34.6043,Pod,MODIFIED,eval-sanitize-20-r0-014-nzkw8,phase=Running node=kind-worker4
34.606,Job,MODIFIED,eval-sanitize-20-r0-022,
34.6113,Pod,MODIFIED,eval-sanitize-20-r0-032-7bknl,phase=Running node=kind-worker4
34.613,Job,MODIFIED,eval-sanitize-20-r0-021,
34.6196,Pod,MODIFIED,eval-sanitize-20-r0-013-s7vkg,phase=Running node=kind-worker4
34.6214,Pod,MODIFIED,eval-sanitize-20-r0-015-txnkr,phase=Pending node=kind-worker5
34.6236,Job,MODIFIED,eval-sanitize-20-r0-021,
34.6279,Pod,MODIFIED,eval-sanitize-20-r0-017-tq46z,phase=Running node=kind-worker4
34.6282,Event,ADDED,eval-sanitize-20-r0-015-txnkr.18d41a6071dd6c19,reason=Scheduled count=None msg=Successfully assigned compute/eval-sanitize-20-r0-015-txnkr to kind-worker5
34.6321,Node,MODIFIED,kind-worker5,taints=0
34.6347,Pod,MODIFIED,eval-sanitize-20-r0-015-txnkr,phase=Pending node=kind-worker5
34.6435,Node,MODIFIED,kind-worker5,taints=0
34.653,Event,ADDED,eval-sanitize-20-r0-034-977cj.18d41a607386fa6b,"reason=Pulled count=1 msg=Container image ""busybox:musl"" already present on machine"
34.6786,Event,ADDED,eval-sanitize-20-r0-034-977cj.18d41a6075085208,reason=Created count=1 msg=Created container: task
34.7229,Pod,MODIFIED,eval-sanitize-20-r0-016-wsgf9,phase=Pending node=kind-worker2
34.7295,Event,ADDED,eval-sanitize-20-r0-016-wsgf9.18d41a6077ee7325,reason=Scheduled count=None msg=Successfully assigned compute/eval-sanitize-20-r0-016-wsgf9 to kind-worker2
34.7371,Pod,MODIFIED,eval-sanitize-20-r0-016-wsgf9,phase=Pending node=kind-worker2
34.7421,Event,ADDED,eval-sanitize-20-r0-034-977cj.18d41a6078d48cb7,reason=Started count=1 msg=Started container task
34.7451,Event,ADDED,eval-sanitize-20-r0-029-z4hhp.18d41a6079080141,"reason=Pulled count=1 msg=Container image ""busybox:musl"" already present on machine"
34.7611,Event,ADDED,eval-sanitize-20-r0-033-5lzzb.18d41a6079f4ba86,"reason=Pulled count=1 msg=Container image ""busybox:musl"" already present on machine"
34.7661,Event,ADDED,eval-sanitize-20-r0-029-z4hhp.18d41a607a2a02ac,reason=Created count=1 msg=Created container: task
34.7808,Event,ADDED,eval-sanitize-20-r0-033-5lzzb.18d41a607b2edaf9,reason=Created count=1 msg=Created container: task
34.8378,Event,ADDED,eval-sanitize-20-r0-029-z4hhp.18d41a607e7debda,reason=Started count=1 msg=Started container task
34.8432,Event,ADDED,eval-sanitize-20-r0-033-5lzzb.18d41a607ec595c5,reason=Started count=1 msg=Started container task
34.8506,Pod,MODIFIED,eval-sanitize-20-r0-019-7rmqh,phase=Pending node=kind-worker5
34.8563,Event,ADDED,eval-sanitize-20-r0-019-7rmqh.18d41a607f854ae5,reason=Scheduled count=None msg=Successfully assigned compute/eval-sanitize-20-r0-019-7rmqh to kind-worker5
34.8619,Node,MODIFIED,kind-worker5,taints=0
34.8638,Pod,MODIFIED,eval-sanitize-20-r0-019-7rmqh,phase=Pending node=kind-worker5
34.8728,Node,MODIFIED,kind-worker5,taints=0
34.9456,Event,ADDED,eval-sanitize-20-r0-031-rj57f.18d41a6084e71eaa,"reason=Pulled count=1 msg=Container image ""busybox:musl"" already present on machine"
34.9663,Event,ADDED,eval-sanitize-20-r0-031-rj57f.18d41a608625f4c3,reason=Created count=1 msg=Created container: task
35.0134,TaskRequest,ADDED,eval-sanitize-20-r0-035,phase=None job=None
35.02,TaskRequest,MODIFIED,eval-sanitize-20-r0-035,phase=Pending job=None
35.0221,Pod,MODIFIED,eval-sanitize-20-r0-020-hjlkw,phase=Pending node=kind-worker2
35.03,Event,ADDED,eval-sanitize-20-r0-020-hjlkw.18d41a6089aeb021,reason=Scheduled count=None msg=Successfully assigned compute/eval-sanitize-20-r0-020-hjlkw to kind-worker2
35.0404,Pod,MODIFIED,eval-sanitize-20-r0-020-hjlkw,phase=Pending node=kind-worker2
35.0419,Job,ADDED,eval-sanitize-20-r0-035,
35.05,Pod,ADDED,eval-sanitize-20-r0-035-g79jb,phase=Pending node=None
35.0511,TaskRequest,MODIFIED,eval-sanitize-20-r0-035,phase=Scheduled job=None
35.0558,Job,MODIFIED,eval-sanitize-20-r0-035,
35.0582,Event,ADDED,eval-sanitize-20-r0-035.18d41a608b62e3d9,reason=SuccessfulCreate count=1 msg=Created pod: eval-sanitize-20-r0-035-g79jb
35.0591,Event,ADDED,eval-sanitize-20-r0-031-rj57f.18d41a608bae8c4f,reason=Started count=1 msg=Started container task
35.0621,TaskRequest,MODIFIED,eval-sanitize-20-r0-035,phase=Scheduled job=None
35.0731,Event,ADDED,eval-sanitize-20-r0-015-txnkr.18d41a608c8a2d7c,"reason=Pulled count=1 msg=Container image ""busybox:musl"" already present on machine"
35.0949,Event,ADDED,eval-sanitize-20-r0-015-txnkr.18d41a608ddd4e9f,reason=Created count=1 msg=Created container: task
35.1266,Pod,MODIFIED,eval-sanitize-20-r0-023-5gj96,phase=Pending node=kind-worker3
35.1298,Event,ADDED,eval-sanitize-20-r0-023-5gj96.18d41a608ff15f7b,reason=Scheduled count=None msg=Successfully assigned compute/eval-sanitize-20-r0-023-5gj96 to kind-worker3
35.1377,Pod,MODIFIED,eval-sanitize-20-r0-023-5gj96,phase=Pending node=kind-worker3
35.1396,Job,MODIFIED,eval-sanitize-20-r0-034,
35.1496,Job,MODIFIED,eval-sanitize-20-r0-034,
35.1625,Event,ADDED,eval-sanitize-20-r0-016-wsgf9.18d41a6091f45892,"reason=Pulled count=1 msg=Container image ""busybox:musl"" already present on machine"
35.1681,Event,ADDED,eval-sanitize-20-r0-015-txnkr.18d41a60921c4c58,reason=Started count=1 msg=Started container task
35.1857,Event,ADDED,eval-sanitize-20-r0-016-wsgf9.18d41a609346c238,reason=Created count=1 msg=Created container: task
35.1987,Pod,MODIFIED,eval-sanitize-20-r0-026-2vx96,phase=Running node=kind-worker3
35.2046,Pod,MODIFIED,eval-sanitize-20-r0-024-g6xwd,phase=Running node=kind-worker3
35.2109,Pod,MODIFIED,eval-sanitize-20-r0-025-gp5dc,phase=Running node=kind-worker3
35.2504,Pod,MODIFIED,eval-sanitize-20-r0-035-g79jb,phase=Pending node=kind-worker2
35.2526,Event,ADDED,eval-sanitize-20-r0-016-wsgf9.18d41a6097408e6d,reason=Started count=1 msg=Started container task
35.2538,Event,ADDED,eval-sanitize-20-r0-035-g79jb.18d41a60975afca6,reason=Scheduled count=None msg=Successfully assigned compute/eval-sanitize-20-r0-035-g79jb to kind-worker2
35.2606,Pod,MODIFIED,eval-sanitize-20-r0-035-g79jb,phase=Pending node=kind-worker2
35.2629,Node,MODIFIED,kind-worker2,taints=0
35.2736,Node,MODIFIED,kind-worker2,taints=0
35.2739,Event,ADDED,eval-sanitize-20-r0-019-7rmqh.18d41a60987425a3,"reason=Pulled count=1 msg=Container image ""busybox:musl"" already present on machine"
35.2916,Event,ADDED,eval-sanitize-20-r0-019-7rmqh.18d41a60999670c9,reason=Created count=1 msg=Created container: task
35.355,Event,ADDED,eval-sanitize-20-r0-019-7rmqh.18d41a609d528bda,reason=Started count=1 msg=Started container task
35.4156,Pod,MODIFIED,eval-sanitize-20-r0-028-nr6jw,phase=Pending node=kind-worker2
35.4189,Event,ADDED,eval-sanitize-20-r0-028-nr6jw.18d41a60a132d6ed,reason=Scheduled count=None msg=Successfully assigned compute/eval-sanitize-20-r0-028-nr6jw to kind-worker2
35.4325,Pod,MODIFIED,eval-sanitize-20-r0-028-nr6jw,phase=Pending node=kind-worker2
35.4543,Event,ADDED,eval-sanitize-20-r0-020-hjlkw.18d41a60a346d35a,"reason=Pulled count=1 msg=Container image ""busybox:musl"" already present on machine"
35.4777,Event,ADDED,eval-sanitize-20-r0-020-hjlkw.18d41a60a4b1922d,reason=Created count=1 msg=Created container: task
35.5716,Event,ADDED,eval-sanitize-20-r0-020-hjlkw.18d41a60aa3f7eea,reason=Started count=1 msg=Started container task
35.5778,Event,ADDED,eval-sanitize-20-r0-023-5gj96.18d41a60aaab3dac,"reason=Pulled count=1 msg=Container image ""busybox:musl"" already present on machine"
35.6007,Job,MODIFIED,eval-sanitize-20-r0-030,
35.6076,Event,ADDED,eval-sanitize-20-r0-023-5gj96.18d41a60abf7f1e4,reason=Created count=1 msg=Created container: task
35.6091,Pod,MODIFIED,eval-sanitize-20-r0-034-977cj,phase=Running node=kind-worker4
35.6106,Job,MODIFIED,eval-sanitize-20-r0-014,
35.6125,Job,MODIFIED,eval-sanitize-20-r0-030,
35.6166,Job,MODIFIED,eval-sanitize-20-r0-032,
35.6199,Job,MODIFIED,eval-sanitize-20-r0-014,
35.6239,Job,MODIFIED,eval-sanitize-20-r0-013,
35.6263,Job,MODIFIED,eval-sanitize-20-r0-032,
35.6327,Job,MODIFIED,eval-sanitize-20-r0-017,
35.6351,Job,MODIFIED,eval-sanitize-20-r0-013,
35.6431,Job,MODIFIED,eval-sanitize-20-r0-017,
35.6554,Event,ADDED,eval-sanitize-20-r0-023-5gj96.18d41a60af47f7b0,reason=Started count=1 msg=Started container task
35.6591,Event,ADDED,eval-sanitize-20-r0-035-g79jb.18d41a60af84b7fa,"reason=Pulled count=1 msg=Container image ""busybox:musl"" already present on machine"
35.676,Event,ADDED,eval-sanitize-20-r0-035-g79jb.18d41a60b092c839,reason=Created count=1 msg=Created container: task
35.7116,Event,ADDED,eval-sanitize-20-r0-035-g79jb.18d41a60b2a89032,reason=Started count=1 msg=Started container task
35.7664,Pod,MODIFIED,eval-sanitize-20-r0-031-rj57f,phase=Running node=kind-worker2
35.7725,Pod,MODIFIED,eval-sanitize-20-r0-020-hjlkw,phase=Running node=kind-worker2
35.7748,Pod,MODIFIED,eval-sanitize-20-r0-029-z4hhp,phase=Running node=kind-worker5
35.7794,Pod,MODIFIED,eval-sanitize-20-r0-033-5lzzb,phase=Running node=kind-worker2
35.7814,Pod,MODIFIED,eval-sanitize-20-r0-015-txnkr,phase=Running node=kind-worker5
35.7856,Pod,MODIFIED,eval-sanitize-20-r0-035-g79jb,phase=Running node=kind-worker2
35.7877,Pod,MODIFIED,eval-sanitize-20-r0-019-7rmqh,phase=Running node=kind-worker5
35.7926,Pod,MODIFIED,eval-sanitize-20-r0-016-wsgf9,phase=Running node=kind-worker2
35.8285,Event,ADDED,eval-sanitize-20-r0-028-nr6jw.18d41a60b9982fbc,"reason=Pulled count=1 msg=Container image ""busybox:musl"" already present on machine"
35.8472,Event,ADDED,eval-sanitize-20-r0-028-nr6jw.18d41a60ba9e0b97,reason=Created count=1 msg=Created container: task
35.8557,Job,MODIFIED,eval-sanitize-20-r0-019,
35.8651,Job,MODIFIED,eval-sanitize-20-r0-019,
35.8805,Event,ADDED,eval-sanitize-20-r0-028-nr6jw.18d41a60bca12c96,reason=Started count=1 msg=Started container task
36.0076,TaskRequest,ADDED,eval-sanitize-20-r0-036,phase=None job=None
36.0113,TaskRequest,MODIFIED,eval-sanitize-20-r0-036,phase=Pending job=None
36.0268,Job,MODIFIED,eval-sanitize-20-r0-020,
36.0272,Job,ADDED,eval-sanitize-20-r0-036,
36.0338,Pod,ADDED,eval-sanitize-20-r0-036-gt8rv,phase=Pending node=None
36.034,TaskRequest,MODIFIED,eval-sanitize-20-r0-036,phase=Scheduled job=None
36.0377,Job,MODIFIED,eval-sanitize-20-r0-036,
36.0391,Event,ADDED,eval-sanitize-20-r0-036.18d41a60c60c3045,reason=SuccessfulCreate count=1 msg=Created pod: eval-sanitize-20-r0-036-gt8rv
36.0429,TaskRequest,MODIFIED,eval-sanitize-20-r0-036,phase=Scheduled job=None
36.0471,Job,MODIFIED,eval-sanitize-20-r0-020,
36.0545,Job,MODIFIED,eval-sanitize-20-r0-035,
36.0629,Job,MODIFIED,eval-sanitize-20-r0-035,
36.1461,Job,MODIFIED,eval-sanitize-20-r0-034,
36.1482,Pod,MODIFIED,eval-sanitize-20-r0-036-gt8rv,phase=Pending node=kind-worker5
36.1543,Event,ADDED,eval-sanitize-20-r0-036-gt8rv.18d41a60ccddcce2,reason=Scheduled count=None msg=Successfully assigned compute/eval-sanitize-20-r0-036-gt8rv to kind-worker5
36.1558,Job,MODIFIED,eval-sanitize-20-r0-034,
36.1598,Pod,MODIFIED,eval-sanitize-20-r0-036-gt8rv,phase=Pending node=kind-worker5
36.205,Job,MODIFIED,eval-sanitize-20-r0-026,
36.208,Pod,MODIFIED,eval-sanitize-20-r0-023-5gj96,phase=Running node=kind-worker3
36.2094,Job,MODIFIED,eval-sanitize-20-r0-024,
36.2142,Job,MODIFIED,eval-sanitize-20-r0-026,
36.2161,Job,MODIFIED,eval-sanitize-20-r0-025,
36.218,Job,MODIFIED,eval-sanitize-20-r0-024,
36.2238,Job,MODIFIED,eval-sanitize-20-r0-025,
36.5912,Event,ADDED,eval-sanitize-20-r0-036-gt8rv.18d41a60e70df5f9,"reason=Pulled count=1 msg=Container image ""busybox:musl"" already present on machine"
36.6087,Event,ADDED,eval-sanitize-20-r0-036-gt8rv.18d41a60e81e3228,reason=Created count=1 msg=Created container: task
36.6451,Event,ADDED,eval-sanitize-20-r0-036-gt8rv.18d41a60ea415157,reason=Started count=1 msg=Started container task
36.772,Job,MODIFIED,eval-sanitize-20-r0-031,
36.7801,Pod,MODIFIED,eval-sanitize-20-r0-028-nr6jw,phase=Running node=kind-worker2
36.7813,Job,MODIFIED,eval-sanitize-20-r0-029,
36.7828,Job,MODIFIED,eval-sanitize-20-r0-031,
36.7874,Pod,MODIFIED,eval-sanitize-20-r0-036-gt8rv,phase=Running node=kind-worker5
36.7894,Job,MODIFIED,eval-sanitize-20-r0-033,
36.7901,Job,MODIFIED,eval-sanitize-20-r0-015,
36.7931,Job,MODIFIED,eval-sanitize-20-r0-029,
36.7984,Job,MODIFIED,eval-sanitize-20-r0-016,
36.8008,Job,MODIFIED,eval-sanitize-20-r0-033,
36.8034,Job,MODIFIED,eval-sanitize-20-r0-015,
36.8066,Job,MODIFIED,eval-sanitize-20-r0-016,
37.0081,TaskRequest,ADDED,eval-sanitize-20-r0-037,phase=None job=None
37.0119,TaskRequest,MODIFIED,eval-sanitize-20-r0-037,phase=Pending job=None
37.0288,Job,ADDED,eval-sanitize-20-r0-037,
37.0319,TaskRequest,MODIFIED,eval-sanitize-20-r0-037,phase=Scheduled job=None
37.0364,Pod,ADDED,eval-sanitize-20-r0-037-r99cc,phase=Pending node=None
37.0388,Job,MODIFIED,eval-sanitize-20-r0-037,
37.0411,Job,MODIFIED,eval-sanitize-20-r0-036,
37.0414,Event,ADDED,eval-sanitize-20-r0-037.18d41a6101b68bd5,reason=SuccessfulCreate count=1 msg=Created pod: eval-sanitize-20-r0-037-r99cc
37.0415,TaskRequest,MODIFIED,eval-sanitize-20-r0-037,phase=Scheduled job=None
37.0507,Job,MODIFIED,eval-sanitize-20-r0-036,
37.1439,Pod,MODIFIED,eval-sanitize-20-r0-037-r99cc,phase=Pending node=kind-worker
37.1483,Event,ADDED,eval-sanitize-20-r0-037-r99cc.18d41a61081ca743,reason=Scheduled count=None msg=Successfully assigned compute/eval-sanitize-20-r0-037-r99cc to kind-worker
37.1537,Pod,MODIFIED,eval-sanitize-20-r0-037-r99cc,phase=Pending node=kind-worker
37.2152,Job,MODIFIED,eval-sanitize-20-r0-023,
37.2238,Job,MODIFIED,eval-sanitize-20-r0-023,
37.5792,Event,ADDED,eval-sanitize-20-r0-037-r99cc.18d41a6121d71e9f,"reason=Pulled count=1 msg=Container image ""busybox:musl"" already present on machine"
37.5963,Event,ADDED,eval-sanitize-20-r0-037-r99cc.18d41a6122e6234d,reason=Created count=1 msg=Created container: task
37.6304,Event,ADDED,eval-sanitize-20-r0-037-r99cc.18d41a6124ea52a6,reason=Started count=1 msg=Started container task
37.785,Job,MODIFIED,eval-sanitize-20-r0-028,
37.7938,Job,MODIFIED,eval-sanitize-20-r0-028,
38.0082,TaskRequest,ADDED,eval-sanitize-20-r0-038,phase=None job=None
38.0119,TaskRequest,MODIFIED,eval-sanitize-20-r0-038,phase=Pending job=None
38.0305,Job,ADDED,eval-sanitize-20-r0-038,
38.039,Pod,ADDED,eval-sanitize-20-r0-038-2j57b,phase=Pending node=None
38.0391,TaskRequest,MODIFIED,eval-sanitize-20-r0-038,phase=Scheduled job=None
38.0423,Job,MODIFIED,eval-sanitize-20-r0-038,
38.0432,Job,MODIFIED,eval-sanitize-20-r0-037,
38.0447,Event,ADDED,eval-sanitize-20-r0-038.18d41a613d70bc97,reason=SuccessfulCreate count=1 msg=Created pod: eval-sanitize-20-r0-038-2j57b
38.0475,TaskRequest,MODIFIED,eval-sanitize-20-r0-038,phase=Scheduled job=None
38.0526,Job,MODIFIED,eval-sanitize-20-r0-037,
38.1512,Pod,MODIFIED,eval-sanitize-20-r0-038-2j57b,phase=Pending node=kind-worker2
38.1542,Pod,MODIFIED,eval-sanitize-20-r0-037-r99cc,phase=Running node=kind-worker
38.1546,Event,ADDED,eval-sanitize-20-r0-038-2j57b.18d41a6144279bc9,reason=Scheduled count=None msg=Successfully assigned compute/eval-sanitize-20-r0-038-2j57b to kind-worker2
38.1625,Pod,MODIFIED,eval-sanitize-20-r0-038-2j57b,phase=Pending node=kind-worker2
38.5825,Event,ADDED,eval-sanitize-20-r0-038-2j57b.18d41a615da7c5e5,"reason=Pulled count=1 msg=Container image ""busybox:musl"" already present on machine"
38.6003,Event,ADDED,eval-sanitize-20-r0-038-2j57b.18d41a615eac5218,reason=Created count=1 msg=Created container: task
38.6294,Event,ADDED,eval-sanitize-20-r0-038-2j57b.18d41a616077e089,reason=Started count=1 msg=Started container task
38.7805,Pod,MODIFIED,eval-sanitize-20-r0-038-2j57b,phase=Running node=kind-worker2
39.0152,TaskRequest,ADDED,eval-sanitize-20-r0-039,phase=None job=None
39.0196,TaskRequest,MODIFIED,eval-sanitize-20-r0-039,phase=Pending job=None
39.0367,Job,ADDED,eval-sanitize-20-r0-039,
39.0425,Pod,ADDED,eval-sanitize-20-r0-039-4ckrh,phase=Pending node=None
39.0453,Job,MODIFIED,eval-sanitize-20-r0-038,
39.0466,TaskRequest,MODIFIED,eval-sanitize-20-r0-039,phase=Scheduled job=None
39.0473,Job,MODIFIED,eval-sanitize-20-r0-039,
39.049,Event,ADDED,eval-sanitize-20-r0-039.18d41a617946e097,reason=SuccessfulCreate count=1 msg=Created pod: eval-sanitize-20-r0-039-4ckrh
39.0498,Job,MODIFIED,eval-sanitize-20-r0-037,
39.0561,Job,MODIFIED,eval-sanitize-20-r0-039,
39.0579,TaskRequest,MODIFIED,eval-sanitize-20-r0-039,phase=Scheduled job=None
39.0587,Job,MODIFIED,eval-sanitize-20-r0-038,
39.0612,Job,MODIFIED,eval-sanitize-20-r0-037,
39.0656,Job,MODIFIED,eval-sanitize-20-r0-039,
39.1542,Pod,MODIFIED,eval-sanitize-20-r0-039-4ckrh,phase=Pending node=kind-worker
39.1589,Event,ADDED,eval-sanitize-20-r0-039-4ckrh.18d41a617fefc4a0,reason=Scheduled count=None msg=Successfully assigned compute/eval-sanitize-20-r0-039-4ckrh to kind-worker
39.165,Pod,MODIFIED,eval-sanitize-20-r0-039-4ckrh,phase=Pending node=kind-worker
39.5795,Event,ADDED,eval-sanitize-20-r0-039-4ckrh.18d41a6199124142,"reason=Pulled count=1 msg=Container image ""busybox:musl"" already present on machine"
39.5976,Event,ADDED,eval-sanitize-20-r0-039-4ckrh.18d41a619a2d2621,reason=Created count=1 msg=Created container: task
39.6575,Event,ADDED,eval-sanitize-20-r0-039-4ckrh.18d41a619dbd90b2,reason=Started count=1 msg=Started container task
40.0138,TaskRequest,ADDED,eval-sanitize-20-r0-040,phase=None job=None
40.0179,TaskRequest,MODIFIED,eval-sanitize-20-r0-040,phase=Pending job=None
40.0354,Job,ADDED,eval-sanitize-20-r0-040,
40.0409,TaskRequest,MODIFIED,eval-sanitize-20-r0-040,phase=Scheduled job=None
40.0443,Pod,ADDED,eval-sanitize-20-r0-040-x5pl9,phase=Pending node=None
40.0463,Job,MODIFIED,eval-sanitize-20-r0-040,
40.0482,Event,ADDED,eval-sanitize-20-r0-040.18d41a61b4f96e41,reason=SuccessfulCreate count=1 msg=Created pod: eval-sanitize-20-r0-040-x5pl9
40.0494,TaskRequest,MODIFIED,eval-sanitize-20-r0-040,phase=Scheduled job=None
40.1506,Pod,MODIFIED,eval-sanitize-20-r0-040-x5pl9,phase=Pending node=kind-worker2
40.1569,Pod,MODIFIED,eval-sanitize-20-r0-039-4ckrh,phase=Running node=kind-worker
40.1572,Event,ADDED,eval-sanitize-20-r0-040-x5pl9.18d41a61bb4f95f9,reason=Scheduled count=None msg=Successfully assigned compute/eval-sanitize-20-r0-040-x5pl9 to kind-worker2
40.1612,Pod,MODIFIED,eval-sanitize-20-r0-040-x5pl9,phase=Pending node=kind-worker2
40.5935,Event,ADDED,eval-sanitize-20-r0-040-x5pl9.18d41a61d555ea78,"reason=Pulled count=1 msg=Container image ""busybox:musl"" already present on machine"
40.61,Event,ADDED,eval-sanitize-20-r0-040-x5pl9.18d41a61d6850606,reason=Created count=1 msg=Created container: task
40.672,Event,ADDED,eval-sanitize-20-r0-040-x5pl9.18d41a61da24ba86,reason=Started count=1 msg=Started container task
40.7849,Pod,MODIFIED,eval-sanitize-20-r0-040-x5pl9,phase=Running node=kind-worker2
41.0088,TaskRequest,ADDED,eval-sanitize-20-r0-041,phase=None job=None
41.0132,TaskRequest,MODIFIED,eval-sanitize-20-r0-041,phase=Pending job=None
41.0318,Job,ADDED,eval-sanitize-20-r0-041,
41.0364,TaskRequest,MODIFIED,eval-sanitize-20-r0-041,phase=Scheduled job=None
41.0412,Pod,ADDED,eval-sanitize-20-r0-041-c54qx,phase=Pending node=None
41.0426,Job,MODIFIED,eval-sanitize-20-r0-041,
41.0465,Event,ADDED,eval-sanitize-20-r0-041.18d41a61f0649f31,reason=SuccessfulCreate count=1 msg=Created pod: eval-sanitize-20-r0-041-c54qx
41.0466,TaskRequest,MODIFIED,eval-sanitize-20-r0-041,phase=Scheduled job=None
41.0491,Job,MODIFIED,eval-sanitize-20-r0-040,
41.0589,Job,MODIFIED,eval-sanitize-20-r0-040,
41.1486,Pod,MODIFIED,eval-sanitize-20-r0-041-c54qx,phase=Pending node=kind-worker2
41.1508,Event,ADDED,eval-sanitize-20-r0-041-c54qx.18d41a61f6bed432,reason=Scheduled count=None msg=Successfully assigned compute/eval-sanitize-20-r0-041-c54qx to kind-worker2
41.1572,Pod,MODIFIED,eval-sanitize-20-r0-041-c54qx,phase=Pending node=kind-worker2
41.1609,Job,MODIFIED,eval-sanitize-20-r0-039,
41.1706,Job,MODIFIED,eval-sanitize-20-r0-039,
41.5864,Event,ADDED,eval-sanitize-20-r0-041-c54qx.18d41a6210950bd0,"reason=Pulled count=1 msg=Container image ""busybox:musl"" already present on machine"
41.6038,Event,ADDED,eval-sanitize-20-r0-041-c54qx.18d41a6211bc43b5,reason=Created count=1 msg=Created container: task
41.642,Event,ADDED,eval-sanitize-20-r0-041-c54qx.18d41a6213f8228c,reason=Started count=1 msg=Started container task
41.7936,Pod,MODIFIED,eval-sanitize-20-r0-041-c54qx,phase=Running node=kind-worker2
42.009,TaskRequest,ADDED,eval-sanitize-20-r0-042,phase=None job=None
42.0148,TaskRequest,MODIFIED,eval-sanitize-20-r0-042,phase=Pending job=None
42.0336,Job,ADDED,eval-sanitize-20-r0-042,
42.0424,Pod,ADDED,eval-sanitize-20-r0-042-rkjnj,phase=Pending node=None
42.0427,TaskRequest,MODIFIED,eval-sanitize-20-r0-042,phase=Scheduled job=None
42.0459,Job,MODIFIED,eval-sanitize-20-r0-042,
42.0483,Job,MODIFIED,eval-sanitize-20-r0-041,
42.0487,Event,ADDED,eval-sanitize-20-r0-042.18d41a622c151520,reason=SuccessfulCreate count=1 msg=Created pod: eval-sanitize-20-r0-042-rkjnj
42.0535,TaskRequest,MODIFIED,eval-sanitize-20-r0-042,phase=Scheduled job=None
42.0587,Job,MODIFIED,eval-sanitize-20-r0-041,
42.1484,Pod,MODIFIED,eval-sanitize-20-r0-042-rkjnj,phase=Pending node=kind-worker2
42.1529,Event,ADDED,eval-sanitize-20-r0-042-rkjnj.18d41a6232703036,reason=Scheduled count=None msg=Successfully assigned compute/eval-sanitize-20-r0-042-rkjnj to kind-worker2
42.1589,Pod,MODIFIED,eval-sanitize-20-r0-042-rkjnj,phase=Pending node=kind-worker2
42.5713,Event,ADDED,eval-sanitize-20-r0-042-rkjnj.18d41a624b645585,"reason=Pulled count=1 msg=Container image ""busybox:musl"" already present on machine"
42.5909,Event,ADDED,eval-sanitize-20-r0-042-rkjnj.18d41a624c7873e9,reason=Created count=1 msg=Created container: task
42.6229,Event,ADDED,eval-sanitize-20-r0-042-rkjnj.18d41a624e79c632,reason=Started count=1 msg=Started container task
42.7949,Pod,MODIFIED,eval-sanitize-20-r0-042-rkjnj,phase=Running node=kind-worker2
43.0096,TaskRequest,ADDED,eval-sanitize-20-r0-043,phase=None job=None
43.0139,TaskRequest,MODIFIED,eval-sanitize-20-r0-043,phase=Pending job=None
43.0308,Job,ADDED,eval-sanitize-20-r0-043,
43.037,Pod,ADDED,eval-sanitize-20-r0-043-d7z76,phase=Pending node=None
43.0384,TaskRequest,MODIFIED,eval-sanitize-20-r0-043,phase=Scheduled job=None
43.0415,Job,MODIFIED,eval-sanitize-20-r0-043,
43.0426,Event,ADDED,eval-sanitize-20-r0-043.18d41a62676998a8,reason=SuccessfulCreate count=1 msg=Created pod: eval-sanitize-20-r0-043-d7z76
43.0465,Job,MODIFIED,eval-sanitize-20-r0-042,
43.0479,TaskRequest,MODIFIED,eval-sanitize-20-r0-043,phase=Scheduled job=None
43.0561,Job,MODIFIED,eval-sanitize-20-r0-042,
43.1476,Pod,MODIFIED,eval-sanitize-20-r0-043-d7z76,phase=Pending node=kind-worker3
43.1512,Event,ADDED,eval-sanitize-20-r0-043-d7z76.18d41a626dfe9bbd,reason=Scheduled count=None msg=Successfully assigned compute/eval-sanitize-20-r0-043-d7z76 to kind-worker3
43.1578,Pod,MODIFIED,eval-sanitize-20-r0-043-d7z76,phase=Pending node=kind-worker3
43.1636,Pod,MODIFIED,eval-sanitize-20-r0-018-hz2rn,phase=Running node=kind-worker
43.1696,Pod,MODIFIED,eval-sanitize-20-r0-012-q6srf,phase=Running node=kind-worker
43.6193,Pod,MODIFIED,eval-sanitize-20-r0-021-clzvc,phase=Running node=kind-worker4
43.6271,Pod,MODIFIED,eval-sanitize-20-r0-022-bj2qs,phase=Running node=kind-worker4
43.633,Pod,MODIFIED,eval-sanitize-20-r0-027-mccff,phase=Running node=kind-worker4
43.7527,Event,ADDED,eval-sanitize-20-r0-043-d7z76.18d41a6291c1ac2e,"reason=Pulled count=1 msg=Container image ""busybox:musl"" already present on machine"
43.7721,Event,ADDED,eval-sanitize-20-r0-043-d7z76.18d41a6292ffc9df,reason=Created count=1 msg=Created container: task
43.895,Event,ADDED,eval-sanitize-20-r0-043-d7z76.18d41a629a46902e,reason=Started count=1 msg=Started container task
44.0096,TaskRequest,ADDED,eval-sanitize-20-r0-044,phase=None job=None
44.014,TaskRequest,MODIFIED,eval-sanitize-20-r0-044,phase=Pending job=None
44.0325,Job,ADDED,eval-sanitize-20-r0-044,
44.0406,Pod,ADDED,eval-sanitize-20-r0-044-tlwkv,phase=Pending node=None
44.042,TaskRequest,MODIFIED,eval-sanitize-20-r0-044,phase=Scheduled job=None
44.0429,Job,MODIFIED,eval-sanitize-20-r0-044,
44.0436,Job,MODIFIED,eval-sanitize-20-r0-043,
44.0456,Event,ADDED,eval-sanitize-20-r0-044.18d41a62a3351a54,reason=SuccessfulCreate count=1 msg=Created pod: eval-sanitize-20-r0-044-tlwkv
44.0532,TaskRequest,MODIFIED,eval-sanitize-20-r0-044,phase=Scheduled job=None
44.0558,Job,MODIFIED,eval-sanitize-20-r0-043,
44.1475,Pod,MODIFIED,eval-sanitize-20-r0-044-tlwkv,phase=Pending node=kind-worker3
44.1509,Event,ADDED,eval-sanitize-20-r0-044-tlwkv.18d41a62a994f3f6,reason=Scheduled count=None msg=Successfully assigned compute/eval-sanitize-20-r0-044-tlwkv to kind-worker3
44.1572,Pod,MODIFIED,eval-sanitize-20-r0-044-tlwkv,phase=Pending node=kind-worker3
44.1593,Node,MODIFIED,kind-worker3,taints=0
44.1692,Job,MODIFIED,eval-sanitize-20-r0-018,
44.172,Node,MODIFIED,kind-worker3,taints=0
44.174,Job,MODIFIED,eval-sanitize-20-r0-012,
44.1784,Job,MODIFIED,eval-sanitize-20-r0-018,
44.1828,Job,MODIFIED,eval-sanitize-20-r0-012,
44.221,Pod,MODIFIED,eval-sanitize-20-r0-043-d7z76,phase=Running node=kind-worker3
44.3534,Pod,MODIFIED,eval-sanitize-20-r0-018-hz2rn,phase=Succeeded node=kind-worker
44.4136,Pod,MODIFIED,eval-sanitize-20-r0-012-q6srf,phase=Succeeded node=kind-worker
44.5751,Event,ADDED,eval-sanitize-20-r0-044-tlwkv.18d41a62c2d6843a,"reason=Pulled count=1 msg=Container image ""busybox:musl"" already present on machine"
44.5931,Event,ADDED,eval-sanitize-20-r0-044-tlwkv.18d41a62c3dfc66d,reason=Created count=1 msg=Created container: task
44.6257,Job,MODIFIED,eval-sanitize-20-r0-021,
44.6293,Pod,MODIFIED,eval-sanitize-20-r0-017-tq46z,phase=Running node=kind-worker4
44.6322,Job,MODIFIED,eval-sanitize-20-r0-022,
44.642,Job,MODIFIED,eval-sanitize-20-r0-021,
44.6454,Job,MODIFIED,eval-sanitize-20-r0-027,
44.6469,Pod,MODIFIED,eval-sanitize-20-r0-032-7bknl,phase=Running node=kind-worker4
44.6478,Job,MODIFIED,eval-sanitize-20-r0-022,
44.6558,Pod,MODIFIED,eval-sanitize-20-r0-013-s7vkg,phase=Running node=kind-worker4
44.6567,Job,MODIFIED,eval-sanitize-20-r0-027,
44.6629,Pod,MODIFIED,eval-sanitize-20-r0-030-vsswq,phase=Running node=kind-worker4
44.6702,Pod,MODIFIED,eval-sanitize-20-r0-014-nzkw8,phase=Running node=kind-worker4
44.7233,Event,ADDED,eval-sanitize-20-r0-044-tlwkv.18d41a62cbb16fef,reason=Started count=1 msg=Started container task
44.8248,Pod,MODIFIED,eval-sanitize-20-r0-022-bj2qs,phase=Succeeded node=kind-worker4
44.8649,Pod,MODIFIED,eval-sanitize-20-r0-021-clzvc,phase=Succeeded node=kind-worker4
44.8711,Pod,MODIFIED,eval-sanitize-20-r0-027-mccff,phase=Succeeded node=kind-worker4
45.0092,TaskRequest,ADDED,eval-sanitize-20-r0-045,phase=None job=None
45.013,TaskRequest,MODIFIED,eval-sanitize-20-r0-045,phase=Pending job=None
45.0293,Job,ADDED,eval-sanitize-20-r0-045,
45.0326,TaskRequest,MODIFIED,eval-sanitize-20-r0-045,phase=Scheduled job=None
45.0377,Pod,ADDED,eval-sanitize-20-r0-045-l6mr9,phase=Pending node=None
45.0392,Job,MODIFIED,eval-sanitize-20-r0-045,
45.0432,Event,ADDED,eval-sanitize-20-r0-045.18d41a62dea08fd8,reason=SuccessfulCreate count=1 msg=Created pod: eval-sanitize-20-r0-045-l6mr9
45.0433,TaskRequest,MODIFIED,eval-sanitize-20-r0-045,phase=Scheduled job=None
45.0458,Job,MODIFIED,eval-sanitize-20-r0-044,
45.0481,Job,MODIFIED,eval-sanitize-20-r0-043,
45.0556,Job,MODIFIED,eval-sanitize-20-r0-044,
45.0576,Job,MODIFIED,eval-sanitize-20-r0-043,
45.1474,Pod,MODIFIED,eval-sanitize-20-r0-045-l6mr9,phase=Pending node=kind-worker4
45.1505,Event,ADDED,eval-sanitize-20-r0-045-l6mr9.18d41a62e52ba2b9,reason=Scheduled count=None msg=Successfully assigned compute/eval-sanitize-20-r0-045-l6mr9 to kind-worker4
45.157,Pod,MODIFIED,eval-sanitize-20-r0-045-l6mr9,phase=Pending node=kind-worker4
45.1747,Job,MODIFIED,eval-sanitize-20-r0-018,
45.1787,Job,MODIFIED,eval-sanitize-20-r0-012,
45.1835,Pod,MODIFIED,eval-sanitize-20-r0-018-hz2rn,phase=Succeeded node=kind-worker
45.1866,Job,MODIFIED,eval-sanitize-20-r0-018,
45.1903,Job,MODIFIED,eval-sanitize-20-r0-012,
45.1915,Pod,MODIFIED,eval-sanitize-20-r0-012-q6srf,phase=Succeeded node=kind-worker
45.2243,Pod,MODIFIED,eval-sanitize-20-r0-026-2vx96,phase=Running node=kind-worker3
45.2305,Pod,MODIFIED,eval-sanitize-20-r0-025-gp5dc,phase=Running node=kind-worker3
45.2361,Pod,MODIFIED,eval-sanitize-20-r0-044-tlwkv,phase=Running node=kind-worker3
45.2419,Pod,MODIFIED,eval-sanitize-20-r0-024-g6xwd,phase=Running node=kind-worker3
45.6129,Event,ADDED,eval-sanitize-20-r0-045-l6mr9.18d41a63009e80a8,"reason=Pulled count=1 msg=Container image ""busybox:musl"" already present on machine"
45.6323,Job,MODIFIED,eval-sanitize-20-r0-021,
45.6333,Event,ADDED,eval-sanitize-20-r0-045-l6mr9.18d41a6301bb6bdc,reason=Created count=1 msg=Created container: task
45.6386,Job,MODIFIED,eval-sanitize-20-r0-017,
45.6445,Job,MODIFIED,eval-sanitize-20-r0-022,
45.6466,Pod,MODIFIED,eval-sanitize-20-r0-034-977cj,phase=Running node=kind-worker4
45.6488,Pod,MODIFIED,eval-sanitize-20-r0-021-clzvc,phase=Succeeded node=kind-worker4
45.6495,Job,MODIFIED,eval-sanitize-20-r0-021,
45.6511,Job,MODIFIED,eval-sanitize-20-r0-027,
45.6545,Pod,MODIFIED,eval-sanitize-20-r0-022-bj2qs,phase=Succeeded node=kind-worker4
45.6561,Job,MODIFIED,eval-sanitize-20-r0-032,
45.6571,Job,MODIFIED,eval-sanitize-20-r0-017,
45.6579,Job,MODIFIED,eval-sanitize-20-r0-022,
45.66,Job,MODIFIED,eval-sanitize-20-r0-013,
45.6636,Pod,MODIFIED,eval-sanitize-20-r0-027-mccff,phase=Succeeded node=kind-worker4
45.6645,Job,MODIFIED,eval-sanitize-20-r0-027,
45.667,Job,MODIFIED,eval-sanitize-20-r0-032,
45.6688,Job,MODIFIED,eval-sanitize-20-r0-030,
45.6765,Job,MODIFIED,eval-sanitize-20-r0-014,
45.7316,Job,MODIFIED,eval-sanitize-20-r0-013,
45.7336,Job,MODIFIED,eval-sanitize-20-r0-030,
45.7342,Job,MODIFIED,eval-sanitize-20-r0-014,
45.7791,Event,ADDED,eval-sanitize-20-r0-045-l6mr9.18d41a630a3df714,reason=Started count=1 msg=Started container task
45.8006,Pod,MODIFIED,eval-sanitize-20-r0-031-rj57f,phase=Running node=kind-worker2
45.8022,Pod,MODIFIED,eval-sanitize-20-r0-029-z4hhp,phase=Running node=kind-worker5
45.8069,Pod,MODIFIED,eval-sanitize-20-r0-033-5lzzb,phase=Running node=kind-worker2
45.8091,Pod,MODIFIED,eval-sanitize-20-r0-019-7rmqh,phase=Running node=kind-worker5
45.8134,Pod,MODIFIED,eval-sanitize-20-r0-035-g79jb,phase=Running node=kind-worker2
45.8154,Pod,MODIFIED,eval-sanitize-20-r0-015-txnkr,phase=Running node=kind-worker5
45.8207,Pod,MODIFIED,eval-sanitize-20-r0-016-wsgf9,phase=Running node=kind-worker2
45.8263,Pod,MODIFIED,eval-sanitize-20-r0-020-hjlkw,phase=Running node=kind-worker2
45.885,Pod,MODIFIED,eval-sanitize-20-r0-030-vsswq,phase=Succeeded node=kind-worker4
45.9212,Pod,MODIFIED,eval-sanitize-20-r0-013-s7vkg,phase=Succeeded node=kind-worker4
45.9268,Pod,MODIFIED,eval-sanitize-20-r0-014-nzkw8,phase=Succeeded node=kind-worker4
45.9325,Pod,MODIFIED,eval-sanitize-20-r0-017-tq46z,phase=Succeeded node=kind-worker4
45.9591,Pod,MODIFIED,eval-sanitize-20-r0-032-7bknl,phase=Succeeded node=kind-worker4
46.0067,TaskRequest,ADDED,eval-sanitize-20-r0-046,phase=None job=None
46.0115,TaskRequest,MODIFIED,eval-sanitize-20-r0-046,phase=Pending job=None
46.0266,Job,ADDED,eval-sanitize-20-r0-046,
46.034,Pod,ADDED,eval-sanitize-20-r0-046-ptdmq,phase=Pending node=None
46.0375,TaskRequest,MODIFIED,eval-sanitize-20-r0-046,phase=Scheduled job=None
46.0397,Event,ADDED,eval-sanitize-20-r0-046.18d41a631a00134b,reason=SuccessfulCreate count=1 msg=Created pod: eval-sanitize-20-r0-046-ptdmq
46.0404,Job,MODIFIED,eval-sanitize-20-r0-046,
46.0425,Job,MODIFIED,eval-sanitize-20-r0-045,
46.0457,TaskRequest,MODIFIED,eval-sanitize-20-r0-046,phase=Scheduled job=None
46.0506,Job,MODIFIED,eval-sanitize-20-r0-044,
46.0524,Job,MODIFIED,eval-sanitize-20-r0-045,
46.0587,Job,MODIFIED,eval-sanitize-20-r0-044,
46.1445,Pod,MODIFIED,eval-sanitize-20-r0-046-ptdmq,phase=Pending node=kind-worker2
46.1479,Event,ADDED,eval-sanitize-20-r0-046-ptdmq.18d41a63209dde09,reason=Scheduled count=None msg=Successfully assigned compute/eval-sanitize-20-r0-046-ptdmq to kind-worker2
46.1537,Pod,MODIFIED,eval-sanitize-20-r0-046-ptdmq,phase=Pending node=kind-worker2
46.1808,Job,MODIFIED,eval-sanitize-20-r0-018,
46.1831,Job,MODIFIED,eval-sanitize-20-r0-012,
46.1854,Job,MODIFIED,eval-sanitize-20-r0-018,
46.1875,Job,MODIFIED,eval-sanitize-20-r0-012,
46.1908,Event,ADDED,eval-sanitize-20-r0-018.18d41a632315acda,reason=Completed count=1 msg=Job completed
46.1963,Job,MODIFIED,eval-sanitize-20-r0-018,
46.1976,Event,ADDED,eval-sanitize-20-r0-012.18d41a6323377421,reason=Completed count=1 msg=Job completed
46.1985,Job,MODIFIED,eval-sanitize-20-r0-012,
46.2043,TaskRequest,MODIFIED,eval-sanitize-20-r0-018,phase=Complete job=None
46.2077,TaskRequest,MODIFIED,eval-sanitize-20-r0-012,phase=Complete job=None
46.2133,Job,MODIFIED,eval-sanitize-20-r0-018,
46.2159,Job,MODIFIED,eval-sanitize-20-r0-012,
46.2293,Job,MODIFIED,eval-sanitize-20-r0-026,
46.233,Pod,MODIFIED,eval-sanitize-20-r0-023-5gj96,phase=Running node=kind-worker3
46.2364,Job,MODIFIED,eval-sanitize-20-r0-025,
46.2405,Job,MODIFIED,eval-sanitize-20-r0-026,
46.2451,Job,MODIFIED,eval-sanitize-20-r0-025,
46.2471,Job,MODIFIED,eval-sanitize-20-r0-024,
46.257,Job,MODIFIED,eval-sanitize-20-r0-024,
46.4286,Pod,MODIFIED,eval-sanitize-20-r0-024-g6xwd,phase=Succeeded node=kind-worker3
46.4344,Pod,MODIFIED,eval-sanitize-20-r0-026-2vx96,phase=Succeeded node=kind-worker3
46.4767,Pod,MODIFIED,eval-sanitize-20-r0-025-gp5dc,phase=Succeeded node=kind-worker3
46.5794,Event,ADDED,eval-sanitize-20-r0-046-ptdmq.18d41a633a3d3db6,"reason=Pulled count=1 msg=Container image ""busybox:musl"" already present on machine"
46.5945,Event,ADDED,eval-sanitize-20-r0-046-ptdmq.18d41a633b49107c,reason=Created count=1 msg=Created container: task
46.641,Job,MODIFIED,eval-sanitize-20-r0-021,
46.6459,Job,MODIFIED,eval-sanitize-20-r0-017,
46.6486,Pod,MODIFIED,eval-sanitize-20-r0-045-l6mr9,phase=Running node=kind-worker4
46.65,Job,MODIFIED,eval-sanitize-20-r0-021,
46.6511,Job,MODIFIED,eval-sanitize-20-r0-034,
46.6528,Job,MODIFIED,eval-sanitize-20-r0-022,
46.6597,Event,ADDED,eval-sanitize-20-r0-021.18d41a633ea24c23,reason=Completed count=1 msg=Job completed
46.6616,Pod,MODIFIED,eval-sanitize-20-r0-017-tq46z,phase=Succeeded node=kind-worker4
46.6641,Job,MODIFIED,eval-sanitize-20-r0-022,
46.6679,Job,MODIFIED,eval-sanitize-20-r0-017,
46.6693,Job,MODIFIED,eval-sanitize-20-r0-027,
46.6709,Job,MODIFIED,eval-sanitize-20-r0-032,
46.6727,Job,MODIFIED,eval-sanitize-20-r0-027,
46.6747,Event,ADDED,eval-sanitize-20-r0-022.18d41a633f61669a,reason=Completed count=1 msg=Job completed
46.6764,Job,MODIFIED,eval-sanitize-20-r0-034,
46.6774,Job,MODIFIED,eval-sanitize-20-r0-021,
46.6782,Job,MODIFIED,eval-sanitize-20-r0-013,
46.6799,Job,MODIFIED,eval-sanitize-20-r0-030,
46.682,Event,ADDED,eval-sanitize-20-r0-027.18d41a634008cc98,reason=Completed count=1 msg=Job completed
46.6829,Job,MODIFIED,eval-sanitize-20-r0-014,
46.6842,Pod,MODIFIED,eval-sanitize-20-r0-032-7bknl,phase=Succeeded node=kind-worker4
46.686,Job,MODIFIED,eval-sanitize-20-r0-022,
46.6874,Pod,MODIFIED,eval-sanitize-20-r0-013-s7vkg,phase=Succeeded node=kind-worker4
46.689,Job,MODIFIED,eval-sanitize-20-r0-032,
46.6905,Pod,MODIFIED,eval-sanitize-20-r0-030-vsswq,phase=Succeeded node=kind-worker4
46.6914,Job,MODIFIED,eval-sanitize-20-r0-027,
46.6926,Pod,MODIFIED,eval-sanitize-20-r0-014-nzkw8,phase=Succeeded node=kind-worker4
46.6934,Job,MODIFIED,eval-sanitize-20-r0-013,
46.7334,Job,MODIFIED,eval-sanitize-20-r0-032,
46.7362,Event,ADDED,eval-sanitize-20-r0-032.18d41a63411596de,reason=Completed count=1 msg=Job completed
46.7365,TaskRequest,MODIFIED,eval-sanitize-20-r0-021,phase=Complete job=None
46.7373,Event,ADDED,eval-sanitize-20-r0-046-ptdmq.18d41a63439f30a7,reason=Started count=1 msg=Started container task
46.7458,TaskRequest,MODIFIED,eval-sanitize-20-r0-022,phase=Complete job=None
46.7488,Job,MODIFIED,eval-sanitize-20-r0-021,
46.7498,Job,MODIFIED,eval-sanitize-20-r0-013,
46.7506,Job,MODIFIED,eval-sanitize-20-r0-030,
46.7507,TaskRequest,MODIFIED,eval-sanitize-20-r0-027,phase=Complete job=None
46.7516,Job,MODIFIED,eval-sanitize-20-r0-014,
46.7977,Pod,MODIFIED,eval-sanitize-20-r0-034-977cj,phase=Succeeded node=kind-worker4
46.8132,Pod,MODIFIED,eval-sanitize-20-r0-036-gt8rv,phase=Running node=kind-worker5
46.8155,Pod,MODIFIED,eval-sanitize-20-r0-028-nr6jw,phase=Running node=kind-worker2
46.8229,Pod,MODIFIED,eval-sanitize-20-r0-046-ptdmq,phase=Running node=kind-worker2
46.8321,TaskRequest,MODIFIED,eval-sanitize-20-r0-032,phase=Complete job=None
46.8384,Job,MODIFIED,eval-sanitize-20-r0-027,
46.8407,Job,MODIFIED,eval-sanitize-20-r0-022,
46.8409,TaskRequest,MODIFIED,eval-sanitize-20-r0-013,phase=Complete job=None
46.8443,Job,MODIFIED,eval-sanitize-20-r0-032,
46.8497,Job,MODIFIED,eval-sanitize-20-r0-013,
46.8836,Event,ADDED,eval-sanitize-20-r0-013.18d41a63413f62b1,reason=Completed count=1 msg=Job completed
46.9325,Job,MODIFIED,eval-sanitize-20-r0-031,
46.944,Job,MODIFIED,eval-sanitize-20-r0-031,
46.9823,Job,MODIFIED,eval-sanitize-20-r0-029,
46.9921,Job,MODIFIED,eval-sanitize-20-r0-029,
47.0059,TaskRequest,ADDED,eval-sanitize-20-r0-047,phase=None job=None
47.0106,TaskRequest,MODIFIED,eval-sanitize-20-r0-047,phase=Pending job=None
47.0324,Job,ADDED,eval-sanitize-20-r0-047,
47.0352,Pod,MODIFIED,eval-sanitize-20-r0-020-hjlkw,phase=Succeeded node=kind-worker2
47.0368,Job,MODIFIED,eval-sanitize-20-r0-033,
47.0387,Pod,MODIFIED,eval-sanitize-20-r0-015-txnkr,phase=Succeeded node=kind-worker5
47.0413,TaskRequest,MODIFIED,eval-sanitize-20-r0-047,phase=Scheduled job=None
47.0444,Job,MODIFIED,eval-sanitize-20-r0-047,
47.0458,Pod,MODIFIED,eval-sanitize-20-r0-035-g79jb,phase=Succeeded node=kind-worker2
47.0488,Pod,MODIFIED,eval-sanitize-20-r0-029-z4hhp,phase=Succeeded node=kind-worker5
47.0519,TaskRequest,MODIFIED,eval-sanitize-20-r0-047,phase=Scheduled job=None
47.0546,Job,MODIFIED,eval-sanitize-20-r0-033,
47.0572,Pod,MODIFIED,eval-sanitize-20-r0-019-7rmqh,phase=Succeeded node=kind-worker5
47.0612,Pod,MODIFIED,eval-sanitize-20-r0-016-wsgf9,phase=Succeeded node=kind-worker2
47.0818,Job,MODIFIED,eval-sanitize-20-r0-019,
47.0901,Pod,MODIFIED,eval-sanitize-20-r0-033-5lzzb,phase=Succeeded node=kind-worker2
47.0911,Job,MODIFIED,eval-sanitize-20-r0-019,
47.1437,Job,MODIFIED,eval-sanitize-20-r0-035,
47.1501,Pod,MODIFIED,eval-sanitize-20-r0-031-rj57f,phase=Succeeded node=kind-worker2
47.1528,Job,MODIFIED,eval-sanitize-20-r0-035,
47.1821,Job,MODIFIED,eval-sanitize-20-r0-015,
47.1918,Job,MODIFIED,eval-sanitize-20-r0-015,
47.2459,Job,MODIFIED,eval-sanitize-20-r0-016,
47.2559,Job,MODIFIED,eval-sanitize-20-r0-016,
47.286,Job,MODIFIED,eval-sanitize-20-r0-020,
47.2946,Job,MODIFIED,eval-sanitize-20-r0-020,
47.3487,Pod,ADDED,eval-sanitize-20-r0-047-lprs4,phase=Pending node=None
47.3823,Job,MODIFIED,eval-sanitize-20-r0-046,
47.3907,Job,MODIFIED,eval-sanitize-20-r0-046,
47.4446,Job,MODIFIED,eval-sanitize-20-r0-045,
47.4478,Pod,MODIFIED,eval-sanitize-20-r0-047-lprs4,phase=Pending node=kind-worker4
47.4543,Pod,MODIFIED,eval-sanitize-20-r0-023-5gj96,phase=Succeeded node=kind-worker3
47.4546,Event,ADDED,eval-sanitize-20-r0-047-lprs4.18d41a636e46d509,reason=Scheduled count=None msg=Successfully assigned compute/eval-sanitize-20-r0-047-lprs4 to kind-worker4
47.4554,Job,MODIFIED,eval-sanitize-20-r0-045,
47.459,Pod,MODIFIED,eval-sanitize-20-r0-047-lprs4,phase=Pending node=kind-worker4
47.4868,Job,MODIFIED,eval-sanitize-20-r0-026,
47.4955,Job,MODIFIED,eval-sanitize-20-r0-026,
47.5376,Pod,MODIFIED,eval-sanitize-20-r0-020-hjlkw,phase=Succeeded node=kind-worker2
47.6062,Job,MODIFIED,eval-sanitize-20-r0-047,
47.615,Job,MODIFIED,eval-sanitize-20-r0-047,
47.6295,Event,ADDED,eval-sanitize-20-r0-047.18d41a63686db2cb,reason=SuccessfulCreate count=1 msg=Created pod: eval-sanitize-20-r0-047-lprs4
47.6872,Job,MODIFIED,eval-sanitize-20-r0-023,
47.6955,Job,MODIFIED,eval-sanitize-20-r0-023,
47.7595,Job,MODIFIED,eval-sanitize-20-r0-025,
47.7695,Job,MODIFIED,eval-sanitize-20-r0-025,
47.7854,Pod,MODIFIED,eval-sanitize-20-r0-026-2vx96,phase=Succeeded node=kind-worker3
47.882,Job,MODIFIED,eval-sanitize-20-r0-024,
47.8916,Job,MODIFIED,eval-sanitize-20-r0-024,
47.9317,Job,MODIFIED,eval-sanitize-20-r0-017,
47.9406,Job,MODIFIED,eval-sanitize-20-r0-017,
47.9512,Event,ADDED,eval-sanitize-20-r0-047-lprs4.18d41a638c054d8e,"reason=Pulled count=1 msg=Container image ""busybox:musl"" already present on machine"
47.9692,Event,ADDED,eval-sanitize-20-r0-047-lprs4.18d41a638d2c8b4e,reason=Created count=1 msg=Created container: task
47.9859,Pod,MODIFIED,eval-sanitize-20-r0-025-gp5dc,phase=Succeeded node=kind-worker3
48.011,Pod,MODIFIED,eval-sanitize-20-r0-028-nr6jw,phase=Succeeded node=kind-worker2
48.0252,TaskRequest,ADDED,eval-sanitize-20-r0-048,phase=None job=None
48.0289,Pod,MODIFIED,eval-sanitize-20-r0-036-gt8rv,phase=Succeeded node=kind-worker5
48.0294,Event,ADDED,eval-sanitize-20-r0-047-lprs4.18d41a63909cb6bc,reason=Started count=1 msg=Started container task
48.0297,TaskRequest,MODIFIED,eval-sanitize-20-r0-048,phase=Pending job=None
48.0462,Job,ADDED,eval-sanitize-20-r0-048,
48.0518,TaskRequest,MODIFIED,eval-sanitize-20-r0-048,phase=Scheduled job=None
48.0542,Job,MODIFIED,eval-sanitize-20-r0-048,
48.0583,TaskRequest,MODIFIED,eval-sanitize-20-r0-048,phase=Scheduled job=None
48.0808,Job,MODIFIED,eval-sanitize-20-r0-034,
48.0895,Job,MODIFIED,eval-sanitize-20-r0-034,
48.1446,Pod,MODIFIED,eval-sanitize-20-r0-024-g6xwd,phase=Succeeded node=kind-worker3
48.1777,Pod,MODIFIED,eval-sanitize-20-r0-037-r99cc,phase=Running node=kind-worker
48.2819,Job,MODIFIED,eval-sanitize-20-r0-030,
48.2915,Job,MODIFIED,eval-sanitize-20-r0-030,
48.3365,Pod,MODIFIED,eval-sanitize-20-r0-034-977cj,phase=Succeeded node=kind-worker4
48.4323,Job,MODIFIED,eval-sanitize-20-r0-014,
48.4665,Job,MODIFIED,eval-sanitize-20-r0-014,
48.4821,Job,MODIFIED,eval-sanitize-20-r0-036,
48.4917,Job,MODIFIED,eval-sanitize-20-r0-036,
48.6589,Job,MODIFIED,eval-sanitize-20-r0-028,
48.6653,Pod,MODIFIED,eval-sanitize-20-r0-047-lprs4,phase=Running node=kind-worker4
48.6687,Job,MODIFIED,eval-sanitize-20-r0-028,
48.7615,Pod,MODIFIED,eval-sanitize-20-r0-036-gt8rv,phase=Succeeded node=kind-worker5
48.7812,Job,MODIFIED,eval-sanitize-20-r0-031,
48.7903,Job,MODIFIED,eval-sanitize-20-r0-031,
48.8275,Pod,MODIFIED,eval-sanitize-20-r0-038-2j57b,phase=Running node=kind-worker2
48.8311,Job,MODIFIED,eval-sanitize-20-r0-029,
48.8418,Job,MODIFIED,eval-sanitize-20-r0-029,
48.8871,Pod,MODIFIED,eval-sanitize-20-r0-028-nr6jw,phase=Succeeded node=kind-worker2
48.9426,Job,MODIFIED,eval-sanitize-20-r0-020,
48.953,Job,MODIFIED,eval-sanitize-20-r0-020,
49.0081,TaskRequest,ADDED,eval-sanitize-20-r0-049,phase=None job=None
49.0125,TaskRequest,MODIFIED,eval-sanitize-20-r0-049,phase=Pending job=None
49.0302,Job,ADDED,eval-sanitize-20-r0-049,
49.0358,Pod,MODIFIED,eval-sanitize-20-r0-031-rj57f,phase=Succeeded node=kind-worker2
49.0359,TaskRequest,MODIFIED,eval-sanitize-20-r0-049,phase=Scheduled job=None
49.0399,Job,MODIFIED,eval-sanitize-20-r0-049,
49.0433,TaskRequest,MODIFIED,eval-sanitize-20-r0-049,phase=Scheduled job=None
49.0984,Pod,MODIFIED,eval-sanitize-20-r0-029-z4hhp,phase=Succeeded node=kind-worker5
49.2536,Job,MODIFIED,eval-sanitize-20-r0-033,
49.2628,Job,MODIFIED,eval-sanitize-20-r0-033,
49.2704,Pod,MODIFIED,eval-sanitize-20-r0-037-r99cc,phase=Succeeded node=kind-worker
49.3831,Job,MODIFIED,eval-sanitize-20-r0-015,
49.3911,Job,MODIFIED,eval-sanitize-20-r0-015,
49.4355,Job,MODIFIED,eval-sanitize-20-r0-047,
49.4477,Job,MODIFIED,eval-sanitize-20-r0-047,
49.5112,Pod,MODIFIED,eval-sanitize-20-r0-033-5lzzb,phase=Succeeded node=kind-worker2
49.5302,Job,MODIFIED,eval-sanitize-20-r0-035,
49.5418,Job,MODIFIED,eval-sanitize-20-r0-035,
49.5847,Pod,ADDED,eval-sanitize-20-r0-048-7lhfc,phase=Pending node=None
49.6357,Pod,MODIFIED,eval-sanitize-20-r0-015-txnkr,phase=Succeeded node=kind-worker5
49.6537,Pod,MODIFIED,eval-sanitize-20-r0-048-7lhfc,phase=Pending node=kind-worker3
49.6574,Event,ADDED,eval-sanitize-20-r0-048-7lhfc.18d41a63f1ceca48,reason=Scheduled count=None msg=Successfully assigned compute/eval-sanitize-20-r0-048-7lhfc to kind-worker3
49.6646,Pod,MODIFIED,eval-sanitize-20-r0-048-7lhfc,phase=Pending node=kind-worker3
49.682,Job,MODIFIED,eval-sanitize-20-r0-019,
49.6909,Job,MODIFIED,eval-sanitize-20-r0-019,
49.8015,Pod,MODIFIED,eval-sanitize-20-r0-035-g79jb,phase=Succeeded node=kind-worker2
49.8327,Job,MODIFIED,eval-sanitize-20-r0-048,
49.8427,Job,MODIFIED,eval-sanitize-20-r0-048,
49.8808,Event,ADDED,eval-sanitize-20-r0-048.18d41a63edae521d,reason=SuccessfulCreate count=1 msg=Created pod: eval-sanitize-20-r0-048-7lhfc
49.9175,Pod,MODIFIED,eval-sanitize-20-r0-038-2j57b,phase=Succeeded node=kind-worker2
49.9879,Pod,MODIFIED,eval-sanitize-20-r0-019-7rmqh,phase=Succeeded node=kind-worker5
50.0068,TaskRequest,ADDED,eval-sanitize-20-r0-050,phase=None job=None
50.0105,TaskRequest,MODIFIED,eval-sanitize-20-r0-050,phase=Pending job=None
50.0284,Job,ADDED,eval-sanitize-20-r0-050,
50.031,Job,MODIFIED,eval-sanitize-20-r0-016,
50.0339,TaskRequest,MODIFIED,eval-sanitize-20-r0-050,phase=Scheduled job=None
50.0382,Job,MODIFIED,eval-sanitize-20-r0-050,
50.0409,TaskRequest,MODIFIED,eval-sanitize-20-r0-050,phase=Scheduled job=None
50.0438,Job,MODIFIED,eval-sanitize-20-r0-016,
50.081,Event,ADDED,eval-sanitize-20-r0-048-7lhfc.18d41a640b0cfc1a,"reason=Pulled count=1 msg=Container image ""busybox:musl"" already present on machine"
50.098,Event,ADDED,eval-sanitize-20-r0-048-7lhfc.18d41a640c1ce16b,reason=Created count=1 msg=Created container: task
50.1549,Job,MODIFIED,eval-sanitize-20-r0-023,
50.1579,Event,ADDED,eval-sanitize-20-r0-048-7lhfc.18d41a640facf689,reason=Started count=1 msg=Started container task
50.1634,Job,MODIFIED,eval-sanitize-20-r0-023,
50.181,Job,MODIFIED,eval-sanitize-20-r0-026,
50.1842,Pod,MODIFIED,eval-sanitize-20-r0-039-4ckrh,phase=Running node=kind-worker
50.1904,Job,MODIFIED,eval-sanitize-20-r0-026,
50.2451,Pod,MODIFIED,eval-sanitize-20-r0-048-7lhfc,phase=Running node=kind-worker3
50.2864,Pod,MODIFIED,eval-sanitize-20-r0-016-wsgf9,phase=Succeeded node=kind-worker2
50.3563,Job,MODIFIED,eval-sanitize-20-r0-025,
50.3652,Job,MODIFIED,eval-sanitize-20-r0-025,
50.3847,Pod,MODIFIED,eval-sanitize-20-r0-023-5gj96,phase=Succeeded node=kind-worker3
50.4848,Job,MODIFIED,eval-sanitize-20-r0-024,
50.4935,Job,MODIFIED,eval-sanitize-20-r0-024,
50.6853,Job,MODIFIED,eval-sanitize-20-r0-017,
50.6897,TaskRequest,MODIFIED,eval-sanitize-20-r0-017,phase=Complete job=None
50.7004,Job,MODIFIED,eval-sanitize-20-r0-017,
50.7813,Job,MODIFIED,eval-sanitize-20-r0-036,
50.7903,Job,MODIFIED,eval-sanitize-20-r0-036,
50.833,Pod,ADDED,eval-sanitize-20-r0-049-j5lj6,phase=Pending node=None
50.8354,Pod,MODIFIED,eval-sanitize-20-r0-040-x5pl9,phase=Running node=kind-worker2
50.912,Job,MODIFIED,eval-sanitize-20-r0-034,
50.9142,Pod,MODIFIED,eval-sanitize-20-r0-049-j5lj6,phase=Pending node=kind-worker4
50.9176,Event,ADDED,eval-sanitize-20-r0-049-j5lj6.18d41a643cef587d,reason=Scheduled count=None msg=Successfully assigned compute/eval-sanitize-20-r0-049-j5lj6 to kind-worker4
50.922,Job,MODIFIED,eval-sanitize-20-r0-034,
50.9246,Pod,MODIFIED,eval-sanitize-20-r0-049-j5lj6,phase=Pending node=kind-worker4
50.9294,Event,ADDED,eval-sanitize-20-r0-017.18d41a642f4b534a,reason=Completed count=1 msg=Job completed
51.0048,Job,MODIFIED,eval-sanitize-20-r0-028,
51.0082,TaskRequest,ADDED,eval-sanitize-20-r0-051,phase=None job=None
51.0119,TaskRequest,MODIFIED,eval-sanitize-20-r0-051,phase=Pending job=None
51.0152,Job,MODIFIED,eval-sanitize-20-r0-028,
51.0298,Job,ADDED,eval-sanitize-20-r0-051,
51.0322,Job,MODIFIED,eval-sanitize-20-r0-037,
51.0358,TaskRequest,MODIFIED,eval-sanitize-20-r0-051,phase=Scheduled job=None
51.0405,Job,MODIFIED,eval-sanitize-20-r0-051,
51.0445,TaskRequest,MODIFIED,eval-sanitize-20-r0-051,phase=Scheduled job=None
51.0471,Job,MODIFIED,eval-sanitize-20-r0-037,
51.1383,Job,MODIFIED,eval-sanitize-20-r0-049,
51.1471,Job,MODIFIED,eval-sanitize-20-r0-049,
51.2362,Event,ADDED,eval-sanitize-20-r0-049.18d41a6438179225,reason=SuccessfulCreate count=1 msg=Created pod: eval-sanitize-20-r0-049-j5lj6
51.3487,Pod,MODIFIED,eval-sanitize-20-r0-037-r99cc,phase=Succeeded node=kind-worker
51.3732,Event,ADDED,eval-sanitize-20-r0-049-j5lj6.18d41a64581244f0,"reason=Pulled count=1 msg=Container image ""busybox:musl"" already present on machine"
51.3815,Job,MODIFIED,eval-sanitize-20-r0-030,
51.3849,TaskRequest,MODIFIED,eval-sanitize-20-r0-030,phase=Complete job=None
51.3929,Event,ADDED,eval-sanitize-20-r0-049-j5lj6.18d41a64593687a0,reason=Created count=1 msg=Created container: task
51.3956,Job,MODIFIED,eval-sanitize-20-r0-030,
51.4075,Pod,MODIFIED,eval-sanitize-20-r0-039-4ckrh,phase=Succeeded node=kind-worker
51.4251,Event,ADDED,eval-sanitize-20-r0-049-j5lj6.18d41a645b2e7ee8,reason=Started count=1 msg=Started container task
51.4304,Job,MODIFIED,eval-sanitize-20-r0-014,
51.4338,TaskRequest,MODIFIED,eval-sanitize-20-r0-014,phase=Complete job=None
51.4443,Job,MODIFIED,eval-sanitize-20-r0-014,
51.4985,Job,MODIFIED,eval-sanitize-20-r0-031,
51.5071,Job,MODIFIED,eval-sanitize-20-r0-031,
51.5341,Job,MODIFIED,eval-sanitize-20-r0-038,
51.5428,Job,MODIFIED,eval-sanitize-20-r0-038,
51.6314,Job,MODIFIED,eval-sanitize-20-r0-029,
51.6409,Job,MODIFIED,eval-sanitize-20-r0-029,
51.6634,Pod,MODIFIED,eval-sanitize-20-r0-049-j5lj6,phase=Running node=kind-worker4
51.6796,Event,ADDED,eval-sanitize-20-r0-030.18d41a6458cecb87,reason=Completed count=1 msg=Job completed
51.7342,Job,MODIFIED,eval-sanitize-20-r0-020,
51.7381,TaskRequest,MODIFIED,eval-sanitize-20-r0-020,phase=Complete job=None
51.7475,Job,MODIFIED,eval-sanitize-20-r0-020,
51.8048,Node,MODIFIED,kind-worker,taints=1
51.8186,Node,MODIFIED,kind-worker,taints=1
51.8352,Pod,MODIFIED,eval-sanitize-20-r0-038-2j57b,phase=Succeeded node=kind-worker2
51.8393,Pod,MODIFIED,eval-sanitize-20-r0-041-c54qx,phase=Running node=kind-worker2
51.8852,Pod,ADDED,eval-sanitize-20-r0-050-7ggpc,phase=Pending node=None
51.9165,Node,MODIFIED,kind-worker,taints=1
51.9195,Pod,MODIFIED,eval-sanitize-20-r0-050-7ggpc,phase=Pending node=kind-worker5
51.9266,Pod,MODIFIED,eval-sanitize-20-r0-040-x5pl9,phase=Succeeded node=kind-worker2
51.927,Event,ADDED,eval-sanitize-20-r0-050-7ggpc.18d41a6478da79ec,reason=Scheduled count=None msg=Successfully assigned compute/eval-sanitize-20-r0-050-7ggpc to kind-worker5
51.9312,Node,MODIFIED,kind-worker,taints=1
51.933,Pod,MODIFIED,eval-sanitize-20-r0-050-7ggpc,phase=Pending node=kind-worker5
51.9384,Node,MODIFIED,kind-worker,taints=0
51.9819,Event,ADDED,eval-sanitize-20-r0-014.18d41a645bb9dcc2,reason=Completed count=1 msg=Job completed
51.9856,Node,MODIFIED,kind-worker,taints=0
52.0124,TaskRequest,ADDED,eval-sanitize-20-r0-052,phase=None job=None
52.0179,TaskRequest,MODIFIED,eval-sanitize-20-r0-052,phase=Pending job=None
52.0323,Job,MODIFIED,eval-sanitize-20-r0-033,
52.0341,Job,ADDED,eval-sanitize-20-r0-052,
52.0398,TaskRequest,MODIFIED,eval-sanitize-20-r0-052,phase=Scheduled job=None
52.0455,Job,MODIFIED,eval-sanitize-20-r0-052,
52.048,TaskRequest,MODIFIED,eval-sanitize-20-r0-052,phase=Scheduled job=None
52.0504,Job,MODIFIED,eval-sanitize-20-r0-033,
52.0812,Job,MODIFIED,eval-sanitize-20-r0-015,
52.09,Job,MODIFIED,eval-sanitize-20-r0-015,
52.1805,Job,MODIFIED,eval-sanitize-20-r0-050,
52.19,Job,MODIFIED,eval-sanitize-20-r0-050,
52.2347,Job,MODIFIED,eval-sanitize-20-r0-035,
52.2435,Job,MODIFIED,eval-sanitize-20-r0-035,
52.2805,Event,ADDED,eval-sanitize-20-r0-020.18d41a646dd5617b,reason=Completed count=1 msg=Job completed
52.3535,Event,ADDED,eval-sanitize-20-r0-050-7ggpc.18d41a649285bf6c,"reason=Pulled count=1 msg=Container image ""busybox:musl"" already present on machine"
52.3716,Event,ADDED,eval-sanitize-20-r0-050-7ggpc.18d41a64938f355f,reason=Created count=1 msg=Created container: task
52.4404,Job,MODIFIED,eval-sanitize-20-r0-048,
52.4494,Job,MODIFIED,eval-sanitize-20-r0-048,
52.4525,Event,ADDED,eval-sanitize-20-r0-050-7ggpc.18d41a6498611be8,reason=Started count=1 msg=Started container task
52.4844,Job,MODIFIED,eval-sanitize-20-r0-019,
52.4935,Job,MODIFIED,eval-sanitize-20-r0-019,
52.5879,Event,ADDED,eval-sanitize-20-r0-050.18d41a6476cfddf7,reason=SuccessfulCreate count=1 msg=Created pod: eval-sanitize-20-r0-050-7ggpc
52.6383,Pod,ADDED,eval-sanitize-20-r0-051-88qrg,phase=Pending node=None
52.6605,Pod,MODIFIED,eval-sanitize-20-r0-051-88qrg,phase=Pending node=kind-worker
52.6638,Event,ADDED,eval-sanitize-20-r0-051-88qrg.18d41a64a50bf561,reason=Scheduled count=None msg=Successfully assigned compute/eval-sanitize-20-r0-051-88qrg to kind-worker
52.6699,Node,MODIFIED,kind-worker,taints=0
52.6717,Pod,MODIFIED,eval-sanitize-20-r0-051-88qrg,phase=Pending node=kind-worker
52.6794,Node,MODIFIED,kind-worker,taints=0
52.6807,Job,MODIFIED,eval-sanitize-20-r0-016,
52.6914,Job,MODIFIED,eval-sanitize-20-r0-016,
52.7412,Job,MODIFIED,eval-sanitize-20-r0-023,
52.7499,Job,MODIFIED,eval-sanitize-20-r0-023,
52.837,Pod,MODIFIED,eval-sanitize-20-r0-050-7ggpc,phase=Running node=kind-worker5
52.8386,Job,MODIFIED,eval-sanitize-20-r0-026,
52.8422,Pod,MODIFIED,eval-sanitize-20-r0-042-rkjnj,phase=Running node=kind-worker2
52.8433,TaskRequest,MODIFIED,eval-sanitize-20-r0-026,phase=Complete job=None
52.8532,Job,MODIFIED,eval-sanitize-20-r0-026,
52.8885,Job,MODIFIED,eval-sanitize-20-r0-051,
52.8977,Job,MODIFIED,eval-sanitize-20-r0-051,
52.9301,Event,ADDED,eval-sanitize-20-r0-051.18d41a64a3b70919,reason=SuccessfulCreate count=1 msg=Created pod: eval-sanitize-20-r0-051-88qrg
52.9343,Pod,MODIFIED,eval-sanitize-20-r0-041-c54qx,phase=Succeeded node=kind-worker2
53.0118,TaskRequest,ADDED,eval-sanitize-20-r0-053,phase=None job=None
53.0165,TaskRequest,MODIFIED,eval-sanitize-20-r0-053,phase=Pending job=None
53.0348,Job,ADDED,eval-sanitize-20-r0-053,
53.0398,TaskRequest,MODIFIED,eval-sanitize-20-r0-053,phase=Scheduled job=None
53.044,Job,MODIFIED,eval-sanitize-20-r0-053,
53.047,TaskRequest,MODIFIED,eval-sanitize-20-r0-053,phase=Scheduled job=None
53.0868,Job,MODIFIED,eval-sanitize-20-r0-039,
53.0971,Job,MODIFIED,eval-sanitize-20-r0-039,
53.0975,Event,ADDED,eval-sanitize-20-r0-051-88qrg.18d41a64bed76b80,"reason=Pulled count=1 msg=Container image ""busybox:musl"" already present on machine"
53.1176,Event,ADDED,eval-sanitize-20-r0-051-88qrg.18d41a64c013b5ca,reason=Created count=1 msg=Created container: task
53.131,Job,MODIFIED,eval-sanitize-20-r0-025,
53.1348,TaskRequest,MODIFIED,eval-sanitize-20-r0-025,phase=Complete job=None
53.1448,Job,MODIFIED,eval-sanitize-20-r0-025,
53.1813,Job,MODIFIED,eval-sanitize-20-r0-024,
53.1818,Event,ADDED,eval-sanitize-20-r0-051-88qrg.18d41a64c3be4d5d,reason=Started count=1 msg=Started container task
53.1858,TaskRequest,MODIFIED,eval-sanitize-20-r0-024,phase=Complete job=None
53.1947,Pod,MODIFIED,eval-sanitize-20-r0-051-88qrg,phase=Running node=kind-worker
53.1959,Job,MODIFIED,eval-sanitize-20-r0-024,
53.1985,Node,MODIFIED,kind-worker4,taints=1
53.2113,Node,MODIFIED,kind-worker4,taints=1
53.2294,Event,ADDED,eval-sanitize-20-r0-026.18d41a64af9ff872,reason=Completed count=1 msg=Job completed
53.2857,Job,MODIFIED,eval-sanitize-20-r0-036,
53.2889,TaskRequest,MODIFIED,eval-sanitize-20-r0-036,phase=Complete job=None
53.2988,Job,MODIFIED,eval-sanitize-20-r0-036,
53.3303,Job,MODIFIED,eval-sanitize-20-r0-049,
53.339,Job,MODIFIED,eval-sanitize-20-r0-049,
53.3848,Pod,MODIFIED,eval-sanitize-20-r0-039-4ckrh,phase=Succeeded node=kind-worker
53.4308,Job,MODIFIED,eval-sanitize-20-r0-040,
53.4395,Job,MODIFIED,eval-sanitize-20-r0-040,
53.4864,Job,MODIFIED,eval-sanitize-20-r0-034,
53.4912,TaskRequest,MODIFIED,eval-sanitize-20-r0-034,phase=Complete job=None
53.5005,Job,MODIFIED,eval-sanitize-20-r0-034,
53.53,Event,ADDED,eval-sanitize-20-r0-025.18d41a64c116373b,reason=Completed count=1 msg=Job completed
53.5875,Job,MODIFIED,eval-sanitize-20-r0-028,
53.5908,TaskRequest,MODIFIED,eval-sanitize-20-r0-028,phase=Complete job=None
53.6,Job,MODIFIED,eval-sanitize-20-r0-028,
53.6301,Job,MODIFIED,eval-sanitize-20-r0-037,
53.639,Job,MODIFIED,eval-sanitize-20-r0-037,
53.7338,Pod,MODIFIED,eval-sanitize-20-r0-040-x5pl9,phase=Succeeded node=kind-worker2
53.7889,Pod,ADDED,eval-sanitize-20-r0-052-4zhkt,phase=Pending node=None
53.8076,Pod,MODIFIED,eval-sanitize-20-r0-052-4zhkt,phase=Pending node=kind-worker5
53.8111,Event,ADDED,eval-sanitize-20-r0-052-4zhkt.18d41a64e96ae1eb,reason=Scheduled count=None msg=Successfully assigned compute/eval-sanitize-20-r0-052-4zhkt to kind-worker5
53.8167,Pod,MODIFIED,eval-sanitize-20-r0-052-4zhkt,phase=Pending node=kind-worker5
53.8301,Event,ADDED,eval-sanitize-20-r0-024.18d41a64c4125aca,reason=Completed count=1 msg=Job completed
53.881,Job,MODIFIED,eval-sanitize-20-r0-031,
53.8845,TaskRequest,MODIFIED,eval-sanitize-20-r0-031,phase=Complete job=None
53.8938,Job,MODIFIED,eval-sanitize-20-r0-031,
53.9867,Job,MODIFIED,eval-sanitize-20-r0-038,
53.9964,Job,MODIFIED,eval-sanitize-20-r0-038,
54.0131,TaskRequest,ADDED,eval-sanitize-20-r0-054,phase=None job=None
54.0167,TaskRequest,MODIFIED,eval-sanitize-20-r0-054,phase=Pending job=None
54.0341,Job,ADDED,eval-sanitize-20-r0-054,
54.0373,Pod,MODIFIED,eval-sanitize-20-r0-042-rkjnj,phase=Succeeded node=kind-worker2
54.0385,TaskRequest,MODIFIED,eval-sanitize-20-r0-054,phase=Scheduled job=None
54.0446,Job,MODIFIED,eval-sanitize-20-r0-054,
54.0453,TaskRequest,MODIFIED,eval-sanitize-20-r0-054,phase=Scheduled job=None
54.0985,Job,MODIFIED,eval-sanitize-20-r0-052,
54.107,Job,MODIFIED,eval-sanitize-20-r0-052,
54.111,Node,MODIFIED,kind-worker3,taints=1
54.1237,Node,MODIFIED,kind-worker3,taints=1
54.1296,Event,ADDED,eval-sanitize-20-r0-036.18d41a64ca4ffa8c,reason=Completed count=1 msg=Job completed
54.1939,Job,MODIFIED,eval-sanitize-20-r0-029,
54.1973,TaskRequest,MODIFIED,eval-sanitize-20-r0-029,phase=Complete job=None
54.2064,Job,MODIFIED,eval-sanitize-20-r0-029,
54.2365,Job,MODIFIED,eval-sanitize-20-r0-041,
54.2425,Event,ADDED,eval-sanitize-20-r0-052-4zhkt.18d41a65030d23ab,"reason=Pulled count=1 msg=Container image ""busybox:musl"" already present on machine"
54.2457,Job,MODIFIED,eval-sanitize-20-r0-041,
54.2531,Pod,MODIFIED,eval-sanitize-20-r0-043-d7z76,phase=Running node=kind-worker3
54.2625,Event,ADDED,eval-sanitize-20-r0-052-4zhkt.18d41a65043fb0fa,reason=Created count=1 msg=Created container: task
54.2865,Node,MODIFIED,kind-worker5,taints=1
54.2881,Node,MODIFIED,kind-worker2,taints=1
54.2951,Event,ADDED,eval-sanitize-20-r0-052-4zhkt.18d41a6506467af1,reason=Started count=1 msg=Started container task
54.341,Job,MODIFIED,eval-sanitize-20-r0-050,
54.3501,Job,MODIFIED,eval-sanitize-20-r0-050,
54.3861,Job,MODIFIED,eval-sanitize-20-r0-033,
54.3921,Node,MODIFIED,kind-worker5,taints=1
54.3922,TaskRequest,MODIFIED,eval-sanitize-20-r0-033,phase=Complete job=None
54.4008,Job,MODIFIED,eval-sanitize-20-r0-033,
54.4305,Event,ADDED,eval-sanitize-20-r0-034.18d41a64d6490fb8,reason=Completed count=1 msg=Job completed
54.4838,Pod,ADDED,eval-sanitize-20-r0-053-9pj9s,phase=Pending node=None
54.4904,Node,MODIFIED,kind-worker2,taints=1
54.4926,Pod,MODIFIED,eval-sanitize-20-r0-053-9pj9s,phase=Pending node=kind-worker
54.4963,Event,ADDED,eval-sanitize-20-r0-053-9pj9s.18d41a65123deb5b,reason=Scheduled count=None msg=Successfully assigned compute/eval-sanitize-20-r0-053-9pj9s to kind-worker
54.5034,Pod,MODIFIED,eval-sanitize-20-r0-053-9pj9s,phase=Pending node=kind-worker
54.5055,Node,MODIFIED,kind-worker,taints=0
54.5514,Pod,MODIFIED,eval-sanitize-20-r0-041-c54qx,phase=Succeeded node=kind-worker2
54.5839,Job,MODIFIED,eval-sanitize-20-r0-015,
54.5882,Node,MODIFIED,kind-worker,taints=0
54.5884,TaskRequest,MODIFIED,eval-sanitize-20-r0-015,phase=Complete job=None
54.5974,Job,MODIFIED,eval-sanitize-20-r0-015,
54.6446,Job,MODIFIED,eval-sanitize-20-r0-035,
54.6495,TaskRequest,MODIFIED,eval-sanitize-20-r0-035,phase=Complete job=None
54.6584,Job,MODIFIED,eval-sanitize-20-r0-035,
54.6898,Job,MODIFIED,eval-sanitize-20-r0-019,
54.6931,TaskRequest,MODIFIED,eval-sanitize-20-r0-019,phase=Complete job=None
54.7022,Job,MODIFIED,eval-sanitize-20-r0-019,
54.7303,Event,ADDED,eval-sanitize-20-r0-028.18d41a64dc4b782b,reason=Completed count=1 msg=Job completed
54.7936,Job,MODIFIED,eval-sanitize-20-r0-053,
54.8016,Job,MODIFIED,eval-sanitize-20-r0-053,
54.8313,Pod,MODIFIED,eval-sanitize-20-r0-052-4zhkt,phase=Running node=kind-worker5
54.8879,Job,MODIFIED,eval-sanitize-20-r0-051,
54.8974,Job,MODIFIED,eval-sanitize-20-r0-051,
54.9433,Job,MODIFIED,eval-sanitize-20-r0-016,
54.9486,TaskRequest,MODIFIED,eval-sanitize-20-r0-016,phase=Complete job=None
54.9592,Job,MODIFIED,eval-sanitize-20-r0-016,
54.9606,Event,ADDED,eval-sanitize-20-r0-053-9pj9s.18d41a652dbbdc7e,"reason=Pulled count=1 msg=Container image ""busybox:musl"" already present on machine"
54.9762,Event,ADDED,eval-sanitize-20-r0-053-9pj9s.18d41a652eda0e36,reason=Created count=1 msg=Created container: task
54.9807,Job,MODIFIED,eval-sanitize-20-r0-023,
54.9853,TaskRequest,MODIFIED,eval-sanitize-20-r0-023,phase=Complete job=None
54.994,Job,MODIFIED,eval-sanitize-20-r0-023,
55.0075,TaskRequest,ADDED,eval-sanitize-20-r0-055,phase=None job=None
55.0104,TaskRequest,MODIFIED,eval-sanitize-20-r0-055,phase=Pending job=None
55.0261,Job,ADDED,eval-sanitize-20-r0-055,
55.03,Event,ADDED,eval-sanitize-20-r0-052.18d41a64e850f06f,reason=SuccessfulCreate count=1 msg=Created pod: eval-sanitize-20-r0-052-4zhkt
55.0309,TaskRequest,MODIFIED,eval-sanitize-20-r0-055,phase=Scheduled job=None
55.0369,Job,MODIFIED,eval-sanitize-20-r0-055,
55.0396,TaskRequest,MODIFIED,eval-sanitize-20-r0-055,phase=Scheduled job=None
55.0542,Event,ADDED,eval-sanitize-20-r0-053-9pj9s.18d41a65337fb856,reason=Started count=1 msg=Started container task
55.0859,Job,MODIFIED,eval-sanitize-20-r0-042,
55.0953,Job,MODIFIED,eval-sanitize-20-r0-042,
55.1473,Pod,ADDED,eval-sanitize-20-r0-054-qhjlr,phase=Pending node=None
55.1554,Pod,MODIFIED,eval-sanitize-20-r0-054-qhjlr,phase=Pending node=kind-worker
55.1588,Event,ADDED,eval-sanitize-20-r0-054-qhjlr.18d41a6539c28a83,reason=Scheduled count=None msg=Successfully assigned compute/eval-sanitize-20-r0-054-qhjlr to kind-worker
55.1647,Node,MODIFIED,kind-worker,taints=0
55.1666,Pod,MODIFIED,eval-sanitize-20-r0-054-qhjlr,phase=Pending node=kind-worker
55.1739,Node,MODIFIED,kind-worker,taints=0
55.1807,Job,MODIFIED,eval-sanitize-20-r0-039,
55.19,Job,MODIFIED,eval-sanitize-20-r0-039,
55.1992,Pod,MODIFIED,eval-sanitize-20-r0-053-9pj9s,phase=Running node=kind-worker
55.2339,Job,MODIFIED,eval-sanitize-20-r0-040,
55.2431,Job,MODIFIED,eval-sanitize-20-r0-040,
55.2544,Pod,MODIFIED,eval-sanitize-20-r0-044-tlwkv,phase=Running node=kind-worker3
55.2817,Job,MODIFIED,eval-sanitize-20-r0-037,
55.2861,TaskRequest,MODIFIED,eval-sanitize-20-r0-037,phase=Complete job=None
55.2954,Job,MODIFIED,eval-sanitize-20-r0-037,
55.3345,Event,ADDED,eval-sanitize-20-r0-031.18d41a64edc6f94d,reason=Completed count=1 msg=Job completed
55.3465,Pod,MODIFIED,eval-sanitize-20-r0-043-d7z76,phase=Succeeded node=kind-worker3
55.3927,Pod,MODIFIED,eval-sanitize-20-r0-042-rkjnj,phase=Succeeded node=kind-worker2
55.4356,Job,MODIFIED,eval-sanitize-20-r0-054,
55.4454,Job,MODIFIED,eval-sanitize-20-r0-054,
55.5835,Job,MODIFIED,eval-sanitize-20-r0-052,
55.596,Event,ADDED,eval-sanitize-20-r0-054-qhjlr.18d41a6553467274,"reason=Pulled count=1 msg=Container image ""busybox:musl"" already present on machine"
55.5991,Job,MODIFIED,eval-sanitize-20-r0-052,
55.622,Event,ADDED,eval-sanitize-20-r0-054-qhjlr.18d41a65555839f3,reason=Created count=1 msg=Created container: task
55.6292,Event,ADDED,eval-sanitize-20-r0-029.18d41a65006e9271,reason=Completed count=1 msg=Job completed
55.6841,Event,ADDED,eval-sanitize-20-r0-054-qhjlr.18d41a6558fef771,reason=Started count=1 msg=Started container task
55.734,Job,MODIFIED,eval-sanitize-20-r0-041,
55.7436,Job,MODIFIED,eval-sanitize-20-r0-041,
55.7937,Job,MODIFIED,eval-sanitize-20-r0-038,
55.7976,TaskRequest,MODIFIED,eval-sanitize-20-r0-038,phase=Complete job=None
55.8075,Job,MODIFIED,eval-sanitize-20-r0-038,
55.8429,Pod,ADDED,eval-sanitize-20-r0-055-2z5sr,phase=Pending node=None
55.8512,Pod,MODIFIED,eval-sanitize-20-r0-055-2z5sr,phase=Pending node=None
55.8516,Event,ADDED,eval-sanitize-20-r0-055-2z5sr.18d41a6562f671d7,"reason=FailedScheduling count=None msg=0/6 nodes are available: 1 c_wall violated: 2 conflicting context pair(s) with node memory, 5 node(s) had untolerated taint(s). no new claims to deallocate, preemption: 0/6 nodes are available: 1 No preemption victims found for incoming pod, 5 Preemption is not helpful for scheduling."
55.858,Event,ADDED,eval-sanitize-20-r0-055-2z5sr.18d41a65636e323b,"reason=FailedScheduling count=None msg=0/6 nodes are available: 1 c_wall violated: 2 conflicting context pair(s) with node memory, 5 node(s) had untolerated taint(s). no new claims to deallocate, preemption: 0/6 nodes are available: 1 No preemption victims found for incoming pod, 5 Preemption is not helpful for scheduling."
55.8857,Job,MODIFIED,eval-sanitize-20-r0-043,
55.8941,Job,MODIFIED,eval-sanitize-20-r0-043,
55.9461,Event,ADDED,eval-sanitize-20-r0-033.18d41a650be6160d,reason=Completed count=1 msg=Job completed
55.9973,Job,MODIFIED,eval-sanitize-20-r0-053,
56.0062,Job,MODIFIED,eval-sanitize-20-r0-053,
56.0064,TaskRequest,ADDED,eval-sanitize-20-r0-056,phase=None job=None
56.0109,TaskRequest,MODIFIED,eval-sanitize-20-r0-056,phase=Pending job=None
56.0258,Job,ADDED,eval-sanitize-20-r0-056,
56.0327,TaskRequest,MODIFIED,eval-sanitize-20-r0-056,phase=Scheduled job=None
56.0354,Job,MODIFIED,eval-sanitize-20-r0-056,
56.0393,TaskRequest,MODIFIED,eval-sanitize-20-r0-056,phase=Scheduled job=None
56.0923,Job,MODIFIED,eval-sanitize-20-r0-042,
56.1114,Job,MODIFIED,eval-sanitize-20-r0-042,
56.1315,Job,MODIFIED,eval-sanitize-20-r0-055,
56.1402,Job,MODIFIED,eval-sanitize-20-r0-055,
56.1995,Pod,MODIFIED,eval-sanitize-20-r0-043-d7z76,phase=Succeeded node=kind-worker3
56.2042,Pod,MODIFIED,eval-sanitize-20-r0-054-qhjlr,phase=Running node=kind-worker
56.2133,Event,MODIFIED,eval-sanitize-20-r0-055-2z5sr.18d41a65636e323b,"reason=FailedScheduling count=None msg=0/6 nodes are available: 1 c_wall violated: 2 conflicting context pair(s) with node memory, 5 node(s) had untolerated taint(s). no new claims to deallocate, preemption: 0/6 nodes are available: 1 No preemption victims found for incoming pod, 5 Preemption is not helpful for scheduling."
56.2287,Event,ADDED,eval-sanitize-20-r0-053.18d41a6511bbaec5,reason=SuccessfulCreate count=1 msg=Created pod: eval-sanitize-20-r0-053-9pj9s
56.2838,Pod,ADDED,eval-sanitize-20-r0-056-6bgct,phase=Pending node=None
56.2937,Pod,MODIFIED,eval-sanitize-20-r0-056-6bgct,phase=Pending node=None
56.294,Event,ADDED,eval-sanitize-20-r0-056-6bgct.18d41a657d45de91,"reason=FailedScheduling count=None msg=0/6 nodes are available: 1 c_wall violated: 1 conflicting context pair(s) with node memory, 5 node(s) had untolerated taint(s). no new claims to deallocate, preemption: 0/6 nodes are available: 1 No preemption victims found for incoming pod, 5 Preemption is not helpful for scheduling."
56.3008,Event,ADDED,eval-sanitize-20-r0-056-6bgct.18d41a657dd52669,"reason=FailedScheduling count=None msg=0/6 nodes are available: 1 c_wall violated: 1 conflicting context pair(s) with node memory, 5 node(s) had untolerated taint(s). no new claims to deallocate, preemption: 0/6 nodes are available: 1 No preemption victims found for incoming pod, 5 Preemption is not helpful for scheduling."
56.3715,Pod,MODIFIED,eval-sanitize-20-r0-044-tlwkv,phase=Succeeded node=kind-worker3
56.3808,Job,MODIFIED,eval-sanitize-20-r0-039,
56.3835,Event,MODIFIED,eval-sanitize-20-r0-056-6bgct.18d41a657dd52669,"reason=FailedScheduling count=None msg=0/6 nodes are available: 1 c_wall violated: 1 conflicting context pair(s) with node memory, 5 node(s) had untolerated taint(s). no new claims to deallocate, preemption: 0/6 nodes are available: 1 No preemption victims found for incoming pod, 5 Preemption is not helpful for scheduling."
56.3854,TaskRequest,MODIFIED,eval-sanitize-20-r0-039,phase=Complete job=None
56.3942,Job,MODIFIED,eval-sanitize-20-r0-039,
56.4798,Event,ADDED,eval-sanitize-20-r0-015.18d41a6517b36c21,reason=Completed count=1 msg=Job completed
56.5382,Job,MODIFIED,eval-sanitize-20-r0-040,
56.5418,TaskRequest,MODIFIED,eval-sanitize-20-r0-040,phase=Complete job=None
56.5507,Job,MODIFIED,eval-sanitize-20-r0-040,
56.6457,Job,MODIFIED,eval-sanitize-20-r0-044,
56.6554,Job,MODIFIED,eval-sanitize-20-r0-044,
56.6753,Pod,MODIFIED,eval-sanitize-20-r0-045-l6mr9,phase=Running node=kind-worker4
56.6802,Job,MODIFIED,eval-sanitize-20-r0-042,
56.6852,TaskRequest,MODIFIED,eval-sanitize-20-r0-042,phase=Complete job=None
56.6953,Job,MODIFIED,eval-sanitize-20-r0-042,
56.7458,Job,MODIFIED,eval-sanitize-20-r0-043,
56.7568,Job,MODIFIED,eval-sanitize-20-r0-043,
56.7847,Event,ADDED,eval-sanitize-20-r0-035.18d41a651b5038bb,reason=Completed count=1 msg=Job completed
56.8359,Job,MODIFIED,eval-sanitize-20-r0-041,
56.8414,TaskRequest,MODIFIED,eval-sanitize-20-r0-041,phase=Complete job=None
56.8504,Job,MODIFIED,eval-sanitize-20-r0-041,
56.8537,Pod,MODIFIED,eval-sanitize-20-r0-046-ptdmq,phase=Running node=kind-worker2
56.93,Event,ADDED,eval-sanitize-20-r0-019.18d41a651e031f48,reason=Completed count=1 msg=Job completed
56.9872,Event,ADDED,eval-sanitize-20-r0-016.18d41a652d1b8d2f,reason=Completed count=1 msg=Job completed
57.0059,TaskRequest,ADDED,eval-sanitize-20-r0-057,phase=None job=None
57.0116,TaskRequest,MODIFIED,eval-sanitize-20-r0-057,phase=Pending job=None
57.0278,Job,ADDED,eval-sanitize-20-r0-057,
57.0309,Event,ADDED,eval-sanitize-20-r0-023.18d41a652f57cd76,reason=Completed count=1 msg=Job completed
57.0329,TaskRequest,MODIFIED,eval-sanitize-20-r0-057,phase=Scheduled job=None
57.0364,Job,MODIFIED,eval-sanitize-20-r0-057,
57.0409,TaskRequest,MODIFIED,eval-sanitize-20-r0-057,phase=Scheduled job=None
57.089,Pod,ADDED,eval-sanitize-20-r0-057-st55d,phase=Pending node=None
57.098,Pod,MODIFIED,eval-sanitize-20-r0-057-st55d,phase=Pending node=None
57.0984,Event,ADDED,eval-sanitize-20-r0-057-st55d.18d41a65ad3e36d5,"reason=FailedScheduling count=None msg=0/6 nodes are available: 1 c_wall violated: 1 conflicting context pair(s) with node memory, 5 node(s) had untolerated taint(s). no new claims to deallocate, preemption: 0/6 nodes are available: 1 No preemption victims found for incoming pod, 5 Preemption is not helpful for scheduling."
57.1049,Event,ADDED,eval-sanitize-20-r0-057-st55d.18d41a65adbee167,"reason=FailedScheduling count=None msg=0/6 nodes are available: 1 c_wall violated: 1 conflicting context pair(s) with node memory, 5 node(s) had untolerated taint(s). no new claims to deallocate, preemption: 0/6 nodes are available: 1 No preemption victims found for incoming pod, 5 Preemption is not helpful for scheduling."
57.129,Event,ADDED,eval-sanitize-20-r0-054.18d41a653948fd4a,reason=SuccessfulCreate count=1 msg=Created pod: eval-sanitize-20-r0-054-qhjlr
57.1909,Job,MODIFIED,eval-sanitize-20-r0-056,
57.2014,Job,MODIFIED,eval-sanitize-20-r0-056,
57.2948,Event,ADDED,eval-sanitize-20-r0-037.18d41a654147e93a,reason=Completed count=1 msg=Job completed
57.341,Job,MODIFIED,eval-sanitize-20-r0-054,
57.3502,Job,MODIFIED,eval-sanitize-20-r0-054,
57.3951,Event,ADDED,eval-sanitize-20-r0-038.18d41a655fd0ef51,reason=Completed count=1 msg=Job completed
57.4452,Job,MODIFIED,eval-sanitize-20-r0-044,
57.4543,Job,MODIFIED,eval-sanitize-20-r0-044,
57.4937,Event,ADDED,eval-sanitize-20-r0-055.18d41a6562bae34b,reason=SuccessfulCreate count=1 msg=Created pod: eval-sanitize-20-r0-055-2z5sr
57.537,Job,MODIFIED,eval-sanitize-20-r0-043,
57.5417,TaskRequest,MODIFIED,eval-sanitize-20-r0-043,phase=Complete job=None
57.5542,Job,MODIFIED,eval-sanitize-20-r0-043,
57.6001,Pod,MODIFIED,eval-sanitize-20-r0-044-tlwkv,phase=Succeeded node=kind-worker3
57.6438,Event,ADDED,eval-sanitize-20-r0-056.18d41a657d0248a3,reason=SuccessfulCreate count=1 msg=Created pod: eval-sanitize-20-r0-056-6bgct
57.7331,Event,ADDED,eval-sanitize-20-r0-039.18d41a6582cf07d6,reason=Completed count=1 msg=Job completed
57.7816,Job,MODIFIED,eval-sanitize-20-r0-045,
57.792,Job,MODIFIED,eval-sanitize-20-r0-045,
57.8175,Pod,MODIFIED,eval-sanitize-20-r0-045-l6mr9,phase=Succeeded node=kind-worker4
57.8319,Event,ADDED,eval-sanitize-20-r0-040.18d41a658c2a5d9b,reason=Completed count=1 msg=Job completed
57.8325,Event,MODIFIED,eval-sanitize-20-r0-057-st55d.18d41a65adbee167,"reason=FailedScheduling count=None msg=0/6 nodes are available: 1 c_wall violated: 1 conflicting context pair(s) with node memory, 5 node(s) had untolerated taint(s). no new claims to deallocate, preemption: 0/6 nodes are available: 1 No preemption victims found for incoming pod, 5 Preemption is not helpful for scheduling."
57.8828,Event,ADDED,eval-sanitize-20-r0-042.18d41a6594a826cb,reason=Completed count=1 msg=Job completed
57.939,Job,MODIFIED,eval-sanitize-20-r0-046,
57.9482,Job,MODIFIED,eval-sanitize-20-r0-046,
57.9713,Pod,MODIFIED,eval-sanitize-20-r0-046-ptdmq,phase=Succeeded node=kind-worker2
57.9797,Event,ADDED,eval-sanitize-20-r0-041.18d41a659deeb63c,reason=Completed count=1 msg=Job completed
58.0109,TaskRequest,ADDED,eval-sanitize-20-r0-058,phase=None job=None
58.0169,TaskRequest,MODIFIED,eval-sanitize-20-r0-058,phase=Pending job=None
58.0307,Event,ADDED,eval-sanitize-20-r0-057.18d41a65ad01325f,reason=SuccessfulCreate count=1 msg=Created pod: eval-sanitize-20-r0-057-st55d
58.0335,Job,ADDED,eval-sanitize-20-r0-058,
58.0385,TaskRequest,MODIFIED,eval-sanitize-20-r0-058,phase=Scheduled job=None
58.0428,Job,MODIFIED,eval-sanitize-20-r0-058,
58.0479,TaskRequest,MODIFIED,eval-sanitize-20-r0-058,phase=Scheduled job=None
58.0969,Event,ADDED,eval-sanitize-20-r0-043.18d41a65c7b9b039,reason=Completed count=1 msg=Job completed
58.1479,Pod,ADDED,eval-sanitize-20-r0-058-9b88s,phase=Pending node=None
58.1576,Pod,MODIFIED,eval-sanitize-20-r0-058-9b88s,phase=Pending node=None
58.158,Event,ADDED,eval-sanitize-20-r0-058-9b88s.18d41a65ec5cb01f,"reason=FailedScheduling count=None msg=0/6 nodes are available: 1 c_wall violated: 3 conflicting context pair(s) with node memory, 5 node(s) had untolerated taint(s). no new claims to deallocate, preemption: 0/6 nodes are available: 1 No preemption victims found for incoming pod, 5 Preemption is not helpful for scheduling."
58.1645,Event,ADDED,eval-sanitize-20-r0-058-9b88s.18d41a65ecea317a,"reason=FailedScheduling count=None msg=0/6 nodes are available: 1 c_wall violated: 3 conflicting context pair(s) with node memory, 5 node(s) had untolerated taint(s). no new claims to deallocate, preemption: 0/6 nodes are available: 1 No preemption victims found for incoming pod, 5 Preemption is not helpful for scheduling."
58.181,Job,MODIFIED,eval-sanitize-20-r0-057,
58.1906,Job,MODIFIED,eval-sanitize-20-r0-057,
58.2907,Event,ADDED,eval-sanitize-20-r0-058.18d41a65ec20eac8,reason=SuccessfulCreate count=1 msg=Created pod: eval-sanitize-20-r0-058-9b88s
58.4594,Job,MODIFIED,eval-sanitize-20-r0-044,
58.4642,Job,MODIFIED,eval-sanitize-20-r0-044,
58.4672,Event,ADDED,eval-sanitize-20-r0-044.18d41a65fefa3cb8,reason=Completed count=1 msg=Job completed
58.4768,Job,MODIFIED,eval-sanitize-20-r0-044,
58.4842,TaskRequest,MODIFIED,eval-sanitize-20-r0-044,phase=Complete job=None
58.4943,Job,MODIFIED,eval-sanitize-20-r0-044,
58.6912,Pod,MODIFIED,eval-sanitize-20-r0-047-lprs4,phase=Running node=kind-worker4
58.7094,Event,MODIFIED,eval-sanitize-20-r0-058-9b88s.18d41a65ecea317a,"reason=FailedScheduling count=None msg=0/6 nodes are available: 1 c_wall violated: 3 conflicting context pair(s) with node memory, 5 node(s) had untolerated taint(s). no new claims to deallocate, preemption: 0/6 nodes are available: 1 No preemption victims found for incoming pod, 5 Preemption is not helpful for scheduling."
58.7954,Job,MODIFIED,eval-sanitize-20-r0-045,
58.8035,Pod,MODIFIED,eval-sanitize-20-r0-045-l6mr9,phase=Succeeded node=kind-worker4
58.8049,Job,MODIFIED,eval-sanitize-20-r0-045,
58.9498,Job,MODIFIED,eval-sanitize-20-r0-046,
58.9585,Pod,MODIFIED,eval-sanitize-20-r0-046-ptdmq,phase=Succeeded node=kind-worker2
58.9598,Job,MODIFIED,eval-sanitize-20-r0-046,
59.0145,TaskRequest,ADDED,eval-sanitize-20-r0-059,phase=None job=None
59.0206,TaskRequest,MODIFIED,eval-sanitize-20-r0-059,phase=Pending job=None
59.0384,Job,ADDED,eval-sanitize-20-r0-059,
59.0448,Pod,ADDED,eval-sanitize-20-r0-059-zqwtk,phase=Pending node=None
59.0465,TaskRequest,MODIFIED,eval-sanitize-20-r0-059,phase=Scheduled job=None
59.0497,Job,MODIFIED,eval-sanitize-20-r0-058,
59.0503,Job,MODIFIED,eval-sanitize-20-r0-059,
59.0509,Event,ADDED,eval-sanitize-20-r0-059.18d41a662195fc62,reason=SuccessfulCreate count=1 msg=Created pod: eval-sanitize-20-r0-059-zqwtk
59.0539,Pod,MODIFIED,eval-sanitize-20-r0-059-zqwtk,phase=Pending node=None
59.0565,Event,ADDED,eval-sanitize-20-r0-059-zqwtk.18d41a6621d924e0,"reason=FailedScheduling count=None msg=0/6 nodes are available: 1 c_wall violated: 1 conflicting context pair(s) with node memory, 5 node(s) had untolerated taint(s). no new claims to deallocate, preemption: 0/6 nodes are available: 1 No preemption victims found for incoming pod, 5 Preemption is not helpful for scheduling."
59.0565,TaskRequest,MODIFIED,eval-sanitize-20-r0-059,phase=Scheduled job=None
59.0596,Job,MODIFIED,eval-sanitize-20-r0-059,
59.0604,Job,MODIFIED,eval-sanitize-20-r0-058,
59.0619,Event,ADDED,eval-sanitize-20-r0-059-zqwtk.18d41a6622683cd3,"reason=FailedScheduling count=None msg=0/6 nodes are available: 1 c_wall violated: 1 conflicting context pair(s) with node memory, 5 node(s) had untolerated taint(s). no new claims to deallocate, preemption: 0/6 nodes are available: 1 No preemption victims found for incoming pod, 5 Preemption is not helpful for scheduling."
59.0698,Job,MODIFIED,eval-sanitize-20-r0-059,
59.5324,Node,MODIFIED,kind-worker2,taints=1
59.7013,Job,MODIFIED,eval-sanitize-20-r0-047,
59.7116,Job,MODIFIED,eval-sanitize-20-r0-047,
59.8009,Pod,MODIFIED,eval-sanitize-20-r0-047-lprs4,phase=Succeeded node=kind-worker4
59.8023,Job,MODIFIED,eval-sanitize-20-r0-045,
59.807,Job,MODIFIED,eval-sanitize-20-r0-045,
59.8106,Event,ADDED,eval-sanitize-20-r0-045.18d41a664f052bbb,reason=Completed count=1 msg=Job completed
59.8205,Job,MODIFIED,eval-sanitize-20-r0-045,
59.821,Event,MODIFIED,eval-sanitize-20-r0-059-zqwtk.18d41a6622683cd3,"reason=FailedScheduling count=None msg=0/6 nodes are available: 1 c_wall violated: 1 conflicting context pair(s) with node memory, 5 node(s) had untolerated taint(s). no new claims to deallocate, preemption: 0/6 nodes are available: 1 No preemption victims found for incoming pod, 5 Preemption is not helpful for scheduling."
59.8262,TaskRequest,MODIFIED,eval-sanitize-20-r0-045,phase=Complete job=None
59.8362,Job,MODIFIED,eval-sanitize-20-r0-045,
59.9575,Job,MODIFIED,eval-sanitize-20-r0-046,
59.9619,Job,MODIFIED,eval-sanitize-20-r0-046,
59.9672,Event,ADDED,eval-sanitize-20-r0-046.18d41a665849a1e8,reason=Completed count=1 msg=Job completed
59.9738,Job,MODIFIED,eval-sanitize-20-r0-046,
59.9789,TaskRequest,MODIFIED,eval-sanitize-20-r0-046,phase=Complete job=None
59.9877,Job,MODIFIED,eval-sanitize-20-r0-046,
60.0069,TaskRequest,ADDED,eval-sanitize-20-r0-060,phase=None job=None
60.0103,TaskRequest,MODIFIED,eval-sanitize-20-r0-060,phase=Pending job=None
60.0204,Node,ADDED,kind-control-plane,taints=1
60.0216,TaskRequest,ADDED,eval-sanitize-20-r0-000,phase=Complete job=None
60.0218,TaskRequest,ADDED,eval-sanitize-20-r0-001,phase=Complete job=None
60.0219,TaskRequest,ADDED,eval-sanitize-20-r0-002,phase=Complete job=None
60.022,TaskRequest,ADDED,eval-sanitize-20-r0-003,phase=Complete job=None
60.022,TaskRequest,ADDED,eval-sanitize-20-r0-004,phase=Complete job=None
60.0221,TaskRequest,ADDED,eval-sanitize-20-r0-005,phase=Complete job=None
60.0227,Event,ADDED,eval-sanitize-20-r0-000-jg679.18d41a5867e4105c,reason=Scheduled count=None msg=Successfully assigned compute/eval-sanitize-20-r0-000-jg679 to kind-worker5
60.0256,Pod,ADDED,eval-sanitize-20-r0-000-jg679,phase=Succeeded node=kind-worker5
60.0271,Job,ADDED,eval-sanitize-20-r0-000,
60.0275,Event,ADDED,eval-sanitize-20-r0-000-jg679.18d41a588119baf3,"reason=Pulled count=1 msg=Container image ""busybox:musl"" already present on machine"
60.0278,Event,ADDED,eval-sanitize-20-r0-000-jg679.18d41a58822e87b6,reason=Created count=1 msg=Created container: task
60.028,Event,ADDED,eval-sanitize-20-r0-000-jg679.18d41a5884353e59,reason=Started count=1 msg=Started container task
60.0283,Event,ADDED,eval-sanitize-20-r0-000.18d41a5866c332d2,reason=SuccessfulCreate count=1 msg=Created pod: eval-sanitize-20-r0-000-jg679
60.0284,TaskRequest,ADDED,eval-sanitize-20-r0-006,phase=Complete job=None
60.0285,TaskRequest,ADDED,eval-sanitize-20-r0-007,phase=Complete job=None
60.0285,TaskRequest,ADDED,eval-sanitize-20-r0-008,phase=Complete job=None
60.0303,Pod,ADDED,eval-sanitize-20-r0-001-d2nvh,phase=Succeeded node=kind-worker3
60.0321,Node,ADDED,kind-worker,taints=0
60.0324,TaskRequest,ADDED,eval-sanitize-20-r0-009,phase=Complete job=None
60.0324,TaskRequest,ADDED,eval-sanitize-20-r0-010,phase=Complete job=None
60.0342,Pod,ADDED,eval-sanitize-20-r0-002-q96k2,phase=Succeeded node=kind-worker
60.0347,Event,ADDED,eval-sanitize-20-r0-000.18d41a5b95957099,reason=Completed count=1 msg=Job completed
60.0349,Event,ADDED,eval-sanitize-20-r0-001-d2nvh.18d41a58a1c75e62,reason=Scheduled count=None msg=Successfully assigned compute/eval-sanitize-20-r0-001-d2nvh to kind-worker3
60.0352,Event,ADDED,eval-sanitize-20-r0-001-d2nvh.18d41a58bb0908b2,"reason=Pulled count=1 msg=Container image ""busybox:musl"" already present on machine"
60.0354,Event,ADDED,eval-sanitize-20-r0-001-d2nvh.18d41a58bc28dcd5,reason=Created count=1 msg=Created container: task
60.0374,Node,ADDED,kind-worker2,taints=1
60.0383,Job,ADDED,eval-sanitize-20-r0-001,
60.0385,TaskRequest,ADDED,eval-sanitize-20-r0-011,phase=Complete job=None
60.0385,TaskRequest,ADDED,eval-sanitize-20-r0-012,phase=Complete job=None
60.0385,TaskRequest,ADDED,eval-sanitize-20-r0-013,phase=Complete job=None
60.0386,TaskRequest,ADDED,eval-sanitize-20-r0-014,phase=Complete job=None
60.0386,TaskRequest,ADDED,eval-sanitize-20-r0-015,phase=Complete job=None
60.0387,TaskRequest,ADDED,eval-sanitize-20-r0-016,phase=Complete job=None
60.0397,Job,ADDED,eval-sanitize-20-r0-002,
60.0402,Event,ADDED,eval-sanitize-20-r0-001-d2nvh.18d41a58be16d294,reason=Started count=1 msg=Started container task
60.0405,Event,ADDED,eval-sanitize-20-r0-001.18d41a58a0a15f94,reason=SuccessfulCreate count=1 msg=Created pod: eval-sanitize-20-r0-001-d2nvh
60.0407,Event,ADDED,eval-sanitize-20-r0-001.18d41a5bea676867,reason=Completed count=1 msg=Job completed
60.0427,Pod,ADDED,eval-sanitize-20-r0-003-48wrn,phase=Succeeded node=kind-worker5
60.0428,TaskRequest,ADDED,eval-sanitize-20-r0-017,phase=Complete job=None
60.0428,TaskRequest,ADDED,eval-sanitize-20-r0-018,phase=Complete job=None
60.0444,Node,ADDED,kind-worker3,taints=1
60.0459,Node,ADDED,kind-worker4,taints=1
60.0473,Pod,ADDED,eval-sanitize-20-r0-004-6h9f8,phase=Succeeded node=kind-worker5
60.0485,Job,ADDED,eval-sanitize-20-r0-003,
60.0499,Job,ADDED,eval-sanitize-20-r0-004,
60.0504,Event,ADDED,eval-sanitize-20-r0-002-q96k2.18d41a58dda3a457,reason=Scheduled count=None msg=Successfully assigned compute/eval-sanitize-20-r0-002-q96k2 to kind-worker
60.0506,Event,ADDED,eval-sanitize-20-r0-002-q96k2.18d41a58f76962ed,"reason=Pulled count=1 msg=Container image ""busybox:musl"" already present on machine"
60.0509,Event,ADDED,eval-sanitize-20-r0-002-q96k2.18d41a58f88e7cdd,reason=Created count=1 msg=Created container: task
60.0511,Event,ADDED,eval-sanitize-20-r0-002-q96k2.18d41a58fb10f8fb,reason=Started count=1 msg=Started container task
60.0525,Node,ADDED,kind-worker5,taints=1
60.0525,TaskRequest,ADDED,eval-sanitize-20-r0-019,phase=Complete job=None
60.0526,TaskRequest,ADDED,eval-sanitize-20-r0-020,phase=Complete job=None
60.0526,TaskRequest,ADDED,eval-sanitize-20-r0-021,phase=Complete job=None
60.053,Event,ADDED,eval-sanitize-20-r0-002.18d41a58dc6f7811,reason=SuccessfulCreate count=1 msg=Created pod: eval-sanitize-20-r0-002-q96k2
60.0533,Event,ADDED,eval-sanitize-20-r0-002.18d41a5c234a5813,reason=Completed count=1 msg=Job completed
60.0535,Event,ADDED,eval-sanitize-20-r0-003-48wrn.18d41a5918eea5d2,reason=Scheduled count=None msg=Successfully assigned compute/eval-sanitize-20-r0-003-48wrn to kind-worker5
60.0538,Event,ADDED,eval-sanitize-20-r0-003-48wrn.18d41a59311cfd1c,"reason=Pulled count=1 msg=Container image ""busybox:musl"" already present on machine"
60.0551,Pod,ADDED,eval-sanitize-20-r0-005-p9pcb,phase=Succeeded node=kind-worker3
60.056,Job,ADDED,eval-sanitize-20-r0-005,
60.0561,TaskRequest,ADDED,eval-sanitize-20-r0-022,phase=Complete job=None
60.0561,TaskRequest,ADDED,eval-sanitize-20-r0-023,phase=Complete job=None
60.0562,TaskRequest,ADDED,eval-sanitize-20-r0-024,phase=Complete job=None
60.0562,TaskRequest,ADDED,eval-sanitize-20-r0-025,phase=Complete job=None
60.0563,TaskRequest,ADDED,eval-sanitize-20-r0-026,phase=Complete job=None
60.0574,Pod,ADDED,eval-sanitize-20-r0-006-ppwvx,phase=Succeeded node=kind-worker4
60.0585,Job,ADDED,eval-sanitize-20-r0-006,
60.0588,Event,ADDED,eval-sanitize-20-r0-003-48wrn.18d41a5932318ce4,reason=Created count=1 msg=Created container: task
60.0591,Event,ADDED,eval-sanitize-20-r0-003-48wrn.18d41a5934428d75,reason=Started count=1 msg=Started container task
60.0593,Event,ADDED,eval-sanitize-20-r0-003.18d41a5917bd6c37,reason=SuccessfulCreate count=1 msg=Created pod: eval-sanitize-20-r0-003-48wrn
60.0596,Event,ADDED,eval-sanitize-20-r0-003.18d41a5c49233d4d,reason=Completed count=1 msg=Job completed
60.0599,Event,ADDED,eval-sanitize-20-r0-004-6h9f8.18d41a595481c0d6,reason=Scheduled count=None msg=Successfully assigned compute/eval-sanitize-20-r0-004-6h9f8 to kind-worker5
60.0601,Event,ADDED,eval-sanitize-20-r0-004-6h9f8.18d41a596e448c31,"reason=Pulled count=1 msg=Container image ""busybox:musl"" already present on machine"
60.0603,Event,ADDED,eval-sanitize-20-r0-004-6h9f8.18d41a596f5cff1f,reason=Created count=1 msg=Created container: task
60.0607,Event,ADDED,eval-sanitize-20-r0-004-6h9f8.18d41a5971461201,reason=Started count=1 msg=Started container task
60.0609,Event,ADDED,eval-sanitize-20-r0-004.18d41a595316df17,reason=SuccessfulCreate count=1 msg=Created pod: eval-sanitize-20-r0-004-6h9f8
60.0611,Event,ADDED,eval-sanitize-20-r0-004.18d41a5c84f392d8,reason=Completed count=1 msg=Job completed
60.0613,Event,ADDED,eval-sanitize-20-r0-005-p9pcb.18d41a598fb003d8,reason=Scheduled count=None msg=Successfully assigned compute/eval-sanitize-20-r0-005-p9pcb to kind-worker3
60.0614,TaskRequest,ADDED,eval-sanitize-20-r0-027,phase=Complete job=None
60.0614,TaskRequest,ADDED,eval-sanitize-20-r0-028,phase=Complete job=None
60.0615,TaskRequest,ADDED,eval-sanitize-20-r0-029,phase=Complete job=None
60.0634,Pod,ADDED,eval-sanitize-20-r0-007-4g6pt,phase=Succeeded node=kind-worker2
60.0638,Event,ADDED,eval-sanitize-20-r0-005-p9pcb.18d41a59a861e0b2,"reason=Pulled count=1 msg=Container image ""busybox:musl"" already present on machine"
60.0641,Event,ADDED,eval-sanitize-20-r0-005-p9pcb.18d41a59a981defd,reason=Created count=1 msg=Created container: task
60.0643,Event,ADDED,eval-sanitize-20-r0-005-p9pcb.18d41a59abb29e94,reason=Started count=1 msg=Started container task
60.0643,TaskRequest,ADDED,eval-sanitize-20-r0-030,phase=Complete job=None
60.0644,TaskRequest,ADDED,eval-sanitize-20-r0-031,phase=Complete job=None
60.0653,Job,ADDED,eval-sanitize-20-r0-007,
60.067,Pod,ADDED,eval-sanitize-20-r0-008-hmcww,phase=Succeeded node=kind-worker4
60.0673,Event,ADDED,eval-sanitize-20-r0-005.18d41a598e89098d,reason=SuccessfulCreate count=1 msg=Created pod: eval-sanitize-20-r0-005-p9pcb
60.0675,Event,ADDED,eval-sanitize-20-r0-005.18d41a5cd980d8b0,reason=Completed count=1 msg=Job completed
60.0677,Event,ADDED,eval-sanitize-20-r0-006-ppwvx.18d41a59cbec11bc,reason=Scheduled count=None msg=Successfully assigned compute/eval-sanitize-20-r0-006-ppwvx to kind-worker4
60.0679,Event,ADDED,eval-sanitize-20-r0-006-ppwvx.18d41a59e4d1ba14,"reason=Pulled count=1 msg=Container image ""busybox:musl"" already present on machine"
60.0679,TaskRequest,ADDED,eval-sanitize-20-r0-032,phase=Complete job=None
60.068,TaskRequest,ADDED,eval-sanitize-20-r0-033,phase=Complete job=None
60.068,TaskRequest,ADDED,eval-sanitize-20-r0-034,phase=Complete job=None
60.069,Job,ADDED,eval-sanitize-20-r0-008,
60.0698,Event,ADDED,eval-sanitize-20-r0-006-ppwvx.18d41a59e5ed5fbe,reason=Created count=1 msg=Created container: task
60.07,Event,ADDED,eval-sanitize-20-r0-006-ppwvx.18d41a59e7d9b041,reason=Started count=1 msg=Started container task
60.0703,Event,ADDED,eval-sanitize-20-r0-006.18d41a59ca5b184c,reason=SuccessfulCreate count=1 msg=Created pod: eval-sanitize-20-r0-006-ppwvx
60.0704,Event,ADDED,eval-sanitize-20-r0-006.18d41a5d2d0c790c,reason=Completed count=1 msg=Job completed
60.0705,TaskRequest,ADDED,eval-sanitize-20-r0-035,phase=Complete job=None
60.0706,TaskRequest,ADDED,eval-sanitize-20-r0-036,phase=Complete job=None
60.0709,Event,ADDED,eval-sanitize-20-r0-007-4g6pt.18d41a5a076ee859,reason=Scheduled count=None msg=Successfully assigned compute/eval-sanitize-20-r0-007-4g6pt to kind-worker2
60.0711,Event,ADDED,eval-sanitize-20-r0-007-4g6pt.18d41a5a203b91b6,"reason=Pulled count=1 msg=Container image ""busybox:musl"" already present on machine"
60.0713,Event,ADDED,eval-sanitize-20-r0-007-4g6pt.18d41a5a21563479,reason=Created count=1 msg=Created container: task
60.0714,TaskRequest,ADDED,eval-sanitize-20-r0-037,phase=Complete job=None
60.0714,TaskRequest,ADDED,eval-sanitize-20-r0-038,phase=Complete job=None
60.0715,TaskRequest,ADDED,eval-sanitize-20-r0-039,phase=Complete job=None
60.0728,Job,ADDED,eval-sanitize-20-r0-009,
60.0741,Pod,ADDED,eval-sanitize-20-r0-009-mgjls,phase=Succeeded node=kind-worker
60.0743,Event,ADDED,eval-sanitize-20-r0-007-4g6pt.18d41a5a23661384,reason=Started count=1 msg=Started container task
60.0746,Event,ADDED,eval-sanitize-20-r0-007.18d41a5a05dde1ba,reason=SuccessfulCreate count=1 msg=Created pod: eval-sanitize-20-r0-007-4g6pt
60.0748,Event,ADDED,eval-sanitize-20-r0-007.18d41a5d37bae740,reason=Completed count=1 msg=Job completed
60.075,Event,ADDED,eval-sanitize-20-r0-008-hmcww.18d41a5a4830aa1e,reason=Scheduled count=None msg=Successfully assigned compute/eval-sanitize-20-r0-008-hmcww to kind-worker4
60.075,TaskRequest,ADDED,eval-sanitize-20-r0-040,phase=Complete job=None
60.0751,TaskRequest,ADDED,eval-sanitize-20-r0-041,phase=Complete job=None
60.0751,TaskRequest,ADDED,eval-sanitize-20-r0-042,phase=Complete job=None
60.0761,Job,ADDED,eval-sanitize-20-r0-010,
60.0772,Pod,ADDED,eval-sanitize-20-r0-010-9ls26,phase=Succeeded node=kind-worker3
60.0785,Pod,ADDED,eval-sanitize-20-r0-011-kcksm,phase=Succeeded node=kind-worker3
60.0786,TaskRequest,ADDED,eval-sanitize-20-r0-043,phase=Complete job=None
60.0787,TaskRequest,ADDED,eval-sanitize-20-r0-044,phase=Complete job=None
60.0791,Event,ADDED,eval-sanitize-20-r0-008-hmcww.18d41a5a6152e1e8,"reason=Pulled count=1 msg=Container image ""busybox:musl"" already present on machine"
60.0793,Event,ADDED,eval-sanitize-20-r0-008-hmcww.18d41a5a6273402b,reason=Created count=1 msg=Created container: task
60.0795,Event,ADDED,eval-sanitize-20-r0-008-hmcww.18d41a5a64a3614b,reason=Started count=1 msg=Started container task
60.0797,Event,ADDED,eval-sanitize-20-r0-008.18d41a5a417b43ce,reason=SuccessfulCreate count=1 msg=Created pod: eval-sanitize-20-r0-008-hmcww
60.08,Event,ADDED,eval-sanitize-20-r0-008.18d41a5da4e4eb46,reason=Completed count=1 msg=Job completed
60.0802,Event,ADDED,eval-sanitize-20-r0-009-mgjls.18d41a5a8993292b,reason=Scheduled count=None msg=Successfully assigned compute/eval-sanitize-20-r0-009-mgjls to kind-worker
60.0804,Event,ADDED,eval-sanitize-20-r0-009-mgjls.18d41a5aa1d43172,"reason=Pulled count=1 msg=Container image ""busybox:musl"" already present on machine"
60.0805,TaskRequest,ADDED,eval-sanitize-20-r0-045,phase=Complete job=None
60.0806,TaskRequest,ADDED,eval-sanitize-20-r0-046,phase=Complete job=None
60.0806,TaskRequest,ADDED,eval-sanitize-20-r0-047,phase=Scheduled job=None
60.0815,Job,ADDED,eval-sanitize-20-r0-011,
60.0827,Pod,ADDED,eval-sanitize-20-r0-012-q6srf,phase=Succeeded node=kind-worker
60.0831,Event,ADDED,eval-sanitize-20-r0-009-mgjls.18d41a5aa2f18f06,reason=Created count=1 msg=Created container: task
60.0833,Event,ADDED,eval-sanitize-20-r0-009-mgjls.18d41a5aa50f9106,reason=Started count=1 msg=Started container task
60.0836,Event,ADDED,eval-sanitize-20-r0-009.18d41a5a7d87c7f7,reason=SuccessfulCreate count=1 msg=Created pod: eval-sanitize-20-r0-009-mgjls
60.0838,Event,ADDED,eval-sanitize-20-r0-009.18d41a5dc55a939c,reason=Completed count=1 msg=Job completed
60.0839,TaskRequest,ADDED,eval-sanitize-20-r0-048,phase=Scheduled job=None
60.084,TaskRequest,ADDED,eval-sanitize-20-r0-049,phase=Scheduled job=None
60.084,TaskRequest,ADDED,eval-sanitize-20-r0-050,phase=Scheduled job=None
60.0848,Job,ADDED,eval-sanitize-20-r0-012,
60.0856,Job,ADDED,eval-sanitize-20-r0-013,
60.0859,Event,ADDED,eval-sanitize-20-r0-010-9ls26.18d41a5abf0972df,reason=Scheduled count=None msg=Successfully assigned compute/eval-sanitize-20-r0-010-9ls26 to kind-worker3
60.0861,Event,ADDED,eval-sanitize-20-r0-010-9ls26.18d41a5ad8fc4e0f,"reason=Pulled count=1 msg=Container image ""busybox:musl"" already present on machine"
60.0863,Event,ADDED,eval-sanitize-20-r0-010-9ls26.18d41a5ada539c18,reason=Created count=1 msg=Created container: task
60.0865,Event,ADDED,eval-sanitize-20-r0-010-9ls26.18d41a5ade93b462,reason=Started count=1 msg=Started container task
60.0877,Pod,ADDED,eval-sanitize-20-r0-013-s7vkg,phase=Succeeded node=kind-worker4
60.0878,TaskRequest,ADDED,eval-sanitize-20-r0-051,phase=Scheduled job=None
60.0878,TaskRequest,ADDED,eval-sanitize-20-r0-052,phase=Scheduled job=None
60.0879,TaskRequest,ADDED,eval-sanitize-20-r0-053,phase=Scheduled job=None
60.0879,TaskRequest,ADDED,eval-sanitize-20-r0-054,phase=Scheduled job=None
60.0879,TaskRequest,ADDED,eval-sanitize-20-r0-055,phase=Scheduled job=None
60.088,TaskRequest,ADDED,eval-sanitize-20-r0-056,phase=Scheduled job=None
60.088,TaskRequest,ADDED,eval-sanitize-20-r0-057,phase=Scheduled job=None
60.088,TaskRequest,ADDED,eval-sanitize-20-r0-058,phase=Scheduled job=None
60.0892,Pod,ADDED,eval-sanitize-20-r0-014-nzkw8,phase=Succeeded node=kind-worker4
60.09,Job,ADDED,eval-sanitize-20-r0-014,
60.0906,Event,ADDED,eval-sanitize-20-r0-010.18d41a5ab8eb0de5,reason=SuccessfulCreate count=1 msg=Created pod: eval-sanitize-20-r0-010-9ls26
60.0908,Event,ADDED,eval-sanitize-20-r0-010.18d41a5e042101de,reason=Completed count=1 msg=Job completed
60.091,Event,ADDED,eval-sanitize-20-r0-011-kcksm.18d41a5afa9c4077,reason=Scheduled count=None msg=Successfully assigned compute/eval-sanitize-20-r0-011-kcksm to kind-worker3
60.0911,TaskRequest,ADDED,eval-sanitize-20-r0-059,phase=Scheduled job=None
60.0911,TaskRequest,ADDED,eval-sanitize-20-r0-060,phase=Pending job=None
60.0922,Pod,ADDED,eval-sanitize-20-r0-015-txnkr,phase=Succeeded node=kind-worker5
60.0936,Pod,ADDED,eval-sanitize-20-r0-016-wsgf9,phase=Succeeded node=kind-worker2
60.0939,Event,ADDED,eval-sanitize-20-r0-011-kcksm.18d41a5b143e9ddc,"reason=Pulled count=1 msg=Container image ""busybox:musl"" already present on machine"
60.0941,Event,ADDED,eval-sanitize-20-r0-011-kcksm.18d41a5b155db165,reason=Created count=1 msg=Created container: task
60.0944,Event,ADDED,eval-sanitize-20-r0-011-kcksm.18d41a5b1767e116,reason=Started count=1 msg=Started container task
60.0947,Event,ADDED,eval-sanitize-20-r0-011.18d41a5af43a74f3,reason=SuccessfulCreate count=1 msg=Created pod: eval-sanitize-20-r0-011-kcksm
60.0948,TaskRequest,MODIFIED,eval-sanitize-20-r0-060,phase=Scheduled job=None
60.0953,Event,ADDED,eval-sanitize-20-r0-011.18d41a5e4011111c,reason=Completed count=1 msg=Job completed
60.0955,Event,ADDED,eval-sanitize-20-r0-012-q6srf.18d41a5b305fa520,"reason=FailedScheduling count=None msg=0/6 nodes are available: 6 node(s) had untolerated taint(s). no new claims to deallocate, preemption: 0/6 nodes are available: 6 Preemption is not helpful for scheduling."
60.0957,Event,ADDED,eval-sanitize-20-r0-012-q6srf.18d41a5fc78c592c,reason=Scheduled count=None msg=Successfully assigned compute/eval-sanitize-20-r0-012-q6srf to kind-worker
60.0958,TaskRequest,MODIFIED,eval-sanitize-20-r0-060,phase=Scheduled job=None
60.0965,Job,ADDED,eval-sanitize-20-r0-015,
60.0977,Pod,ADDED,eval-sanitize-20-r0-017-tq46z,phase=Succeeded node=kind-worker4
60.0979,Event,ADDED,eval-sanitize-20-r0-012-q6srf.18d41a5fe26aeb00,"reason=Pulled count=1 msg=Container image ""busybox:musl"" already present on machine"
60.0981,Event,ADDED,eval-sanitize-20-r0-012-q6srf.18d41a5fe3993f48,reason=Created count=1 msg=Created container: task
60.0983,Event,ADDED,eval-sanitize-20-r0-012-q6srf.18d41a5fe5ab2e02,reason=Started count=1 msg=Started container task
60.0985,Event,ADDED,eval-sanitize-20-r0-012.18d41a5b30525497,reason=SuccessfulCreate count=1 msg=Created pod: eval-sanitize-20-r0-012-q6srf
60.0994,Job,ADDED,eval-sanitize-20-r0-016,
60.1005,Pod,ADDED,eval-sanitize-20-r0-018-hz2rn,phase=Succeeded node=kind-worker
60.1008,Event,ADDED,eval-sanitize-20-r0-012.18d41a6323377421,reason=Completed count=1 msg=Job completed
60.101,Event,ADDED,eval-sanitize-20-r0-013-s7vkg.18d41a5b6baadbf2,"reason=FailedScheduling count=None msg=0/6 nodes are available: 6 node(s) had untolerated taint(s). no new claims to deallocate, preemption: 0/6 nodes are available: 6 Preemption is not helpful for scheduling."
60.1012,Event,ADDED,eval-sanitize-20-r0-013-s7vkg.18d41a5fc7c53074,"reason=FailedScheduling count=None msg=0/6 nodes are available: 1 c_wall violated: 1 conflicting context pair(s) with node memory, 5 node(s) had untolerated taint(s). no new claims to deallocate, preemption: 0/6 nodes are available: 1 No preemption victims found for incoming pod, 5 Preemption is not helpful for scheduling."
60.1015,Event,ADDED,eval-sanitize-20-r0-013-s7vkg.18d41a5fda2ed63e,"reason=FailedScheduling count=None msg=0/6 nodes are available: 1 c_wall violated: 2 conflicting context pair(s) with node memory, 5 node(s) had untolerated taint(s). no new claims to deallocate, preemption: 0/6 nodes are available: 1 No preemption victims found for incoming pod, 5 Preemption is not helpful for scheduling."
60.1018,Event,ADDED,eval-sanitize-20-r0-013-s7vkg.18d41a5fea60481e,"reason=FailedScheduling count=None msg=0/6 nodes are available: 1 c_wall violated: 2 conflicting context pair(s) with node memory, 5 node(s) had untolerated taint(s). no new claims to deallocate, preemption: 0/6 nodes are available: 1 No preemption victims found for incoming pod, 5 Preemption is not helpful for scheduling."
60.1019,Event,ADDED,eval-sanitize-20-r0-013-s7vkg.18d41a601eaa49f4,reason=Scheduled count=None msg=Successfully assigned compute/eval-sanitize-20-r0-013-s7vkg to kind-worker4
60.1021,Event,ADDED,eval-sanitize-20-r0-013-s7vkg.18d41a60374f0540,"reason=Pulled count=1 msg=Container image ""busybox:musl"" already present on machine"
60.1029,Job,ADDED,eval-sanitize-20-r0-017,
60.1041,Pod,ADDED,eval-sanitize-20-r0-019-7rmqh,phase=Succeeded node=kind-worker5
60.1044,Event,ADDED,eval-sanitize-20-r0-013-s7vkg.18d41a60387a353c,reason=Created count=1 msg=Created container: task
60.1046,Event,ADDED,eval-sanitize-20-r0-013-s7vkg.18d41a603c99b4a5,reason=Started count=1 msg=Started container task
60.1048,Event,ADDED,eval-sanitize-20-r0-013.18d41a5b6b9cf09e,reason=SuccessfulCreate count=1 msg=Created pod: eval-sanitize-20-r0-013-s7vkg
60.1056,Job,ADDED,eval-sanitize-20-r0-018,
60.1068,Pod,ADDED,eval-sanitize-20-r0-020-hjlkw,phase=Succeeded node=kind-worker2
60.1072,Event,ADDED,eval-sanitize-20-r0-013.18d41a63413f62b1,reason=Completed count=1 msg=Job completed
60.1073,Event,ADDED,eval-sanitize-20-r0-014-nzkw8.18d41a5ba75d38be,"reason=FailedScheduling count=None msg=0/6 nodes are available: 6 node(s) had untolerated taint(s). no new claims to deallocate, preemption: 0/6 nodes are available: 6 Preemption is not helpful for scheduling."
60.1075,Event,ADDED,eval-sanitize-20-r0-014-nzkw8.18d41a5fc88bfbb1,"reason=FailedScheduling count=None msg=0/6 nodes are available: 1 c_wall violated: 1 conflicting context pair(s) with node memory, 5 node(s) had untolerated taint(s). no new claims to deallocate, preemption: 0/6 nodes are available: 1 No preemption victims found for incoming pod, 5 Preemption is not helpful for scheduling."
60.1078,Event,ADDED,eval-sanitize-20-r0-014-nzkw8.18d41a5fdaa73aae,"reason=FailedScheduling count=None msg=0/6 nodes are available: 1 c_wall violated: 1 conflicting context pair(s) with node memory, 5 node(s) had untolerated taint(s). no new claims to deallocate, preemption: 0/6 nodes are available: 1 No preemption victims found for incoming pod, 5 Preemption is not helpful for scheduling."
60.108,Event,ADDED,eval-sanitize-20-r0-014-nzkw8.18d41a601ff5e687,reason=Scheduled count=None msg=Successfully assigned compute/eval-sanitize-20-r0-014-nzkw8 to kind-worker4
60.1082,Event,ADDED,eval-sanitize-20-r0-014-nzkw8.18d41a6038e2b44b,"reason=Pulled count=1 msg=Container image ""busybox:musl"" already present on machine"
60.1084,Event,ADDED,eval-sanitize-20-r0-014-nzkw8.18d41a603a08cb5a,reason=Created count=1 msg=Created container: task
60.1087,Event,ADDED,eval-sanitize-20-r0-014-nzkw8.18d41a603cde09de,reason=Started count=1 msg=Started container task
60.1089,Event,ADDED,eval-sanitize-20-r0-014.18d41a5ba750eaf4,reason=SuccessfulCreate count=1 msg=Created pod: eval-sanitize-20-r0-014-nzkw8
60.1091,Event,ADDED,eval-sanitize-20-r0-014.18d41a645bb9dcc2,reason=Completed count=1 msg=Job completed
60.1093,Event,ADDED,eval-sanitize-20-r0-015-txnkr.18d41a5be3006d98,"reason=FailedScheduling count=None msg=0/6 nodes are available: 6 node(s) had untolerated taint(s). no new claims to deallocate, preemption: 0/6 nodes are available: 6 Preemption is not helpful for scheduling."
60.1101,Job,ADDED,eval-sanitize-20-r0-019,
60.1116,Pod,ADDED,eval-sanitize-20-r0-021-clzvc,phase=Succeeded node=kind-worker4
60.1119,Event,ADDED,eval-sanitize-20-r0-015-txnkr.18d41a5fc917dbc1,"reason=FailedScheduling count=None msg=0/6 nodes are available: 1 c_wall violated: 1 conflicting context pair(s) with node memory, 5 node(s) had untolerated taint(s). no new claims to deallocate, preemption: 0/6 nodes are available: 1 No preemption victims found for incoming pod, 5 Preemption is not helpful for scheduling."
60.1121,Event,ADDED,eval-sanitize-20-r0-015-txnkr.18d41a5fdbf3ed84,"reason=FailedScheduling count=None msg=0/6 nodes are available: 1 c_wall violated: 1 conflicting context pair(s) with node memory, 5 node(s) had untolerated taint(s). no new claims to deallocate, preemption: 0/6 nodes are available: 1 No preemption victims found for incoming pod, 5 Preemption is not helpful for scheduling."
60.1124,Event,ADDED,eval-sanitize-20-r0-015-txnkr.18d41a603d56c737,"reason=FailedScheduling count=None msg=0/6 nodes are available: 1 c_wall violated: 1 conflicting context pair(s) with node memory, 1 c_wall violated: 3 conflicting context pair(s) with node memory, 4 node(s) had untolerated taint(s). no new claims to deallocate, preemption: 0/6 nodes are available: 2 No preemption victims found for incoming pod, 4 Preemption is not helpful for scheduling."
60.1132,Job,ADDED,eval-sanitize-20-r0-020,
60.1155,Pod,ADDED,eval-sanitize-20-r0-022-bj2qs,phase=Succeeded node=kind-worker4
60.1157,Event,ADDED,eval-sanitize-20-r0-015-txnkr.18d41a6071dd6c19,reason=Scheduled count=None msg=Successfully assigned compute/eval-sanitize-20-r0-015-txnkr to kind-worker5
60.116,Event,ADDED,eval-sanitize-20-r0-015-txnkr.18d41a608c8a2d7c,"reason=Pulled count=1 msg=Container image ""busybox:musl"" already present on machine"
60.1162,Event,ADDED,eval-sanitize-20-r0-015-txnkr.18d41a608ddd4e9f,reason=Created count=1 msg=Created container: task
60.1164,Event,ADDED,eval-sanitize-20-r0-015-txnkr.18d41a60921c4c58,reason=Started count=1 msg=Started container task
60.1166,Event,ADDED,eval-sanitize-20-r0-015.18d41a5be2f25f06,reason=SuccessfulCreate count=1 msg=Created pod: eval-sanitize-20-r0-015-txnkr
60.1168,Event,ADDED,eval-sanitize-20-r0-015.18d41a6517b36c21,reason=Completed count=1 msg=Job completed
60.117,Event,ADDED,eval-sanitize-20-r0-016-wsgf9.18d41a5c1e5748b1,"reason=FailedScheduling count=None msg=0/6 nodes are available: 6 node(s) had untolerated taint(s). no new claims to deallocate, preemption: 0/6 nodes are available: 6 Preemption is not helpful for scheduling."
60.1172,Event,ADDED,eval-sanitize-20-r0-016-wsgf9.18d41a5fca88b0a0,"reason=FailedScheduling count=None msg=0/6 nodes are available: 1 c_wall violated: 1 conflicting context pair(s) with node memory, 5 node(s) had untolerated taint(s). no new claims to deallocate, preemption: 0/6 nodes are available: 1 No preemption victims found for incoming pod, 5 Preemption is not helpful for scheduling."
60.1175,Event,ADDED,eval-sanitize-20-r0-016-wsgf9.18d41a5fdde06f25,"reason=FailedScheduling count=None msg=0/6 nodes are available: 1 c_wall violated: 1 conflicting context pair(s) with node memory, 5 node(s) had untolerated taint(s). no new claims to deallocate, preemption: 0/6 nodes are available: 1 No preemption victims found for incoming pod, 5 Preemption is not helpful for scheduling."
60.1177,Event,ADDED,eval-sanitize-20-r0-016-wsgf9.18d41a60416dd3fb,"reason=FailedScheduling count=None msg=0/6 nodes are available: 2 c_wall violated: 1 conflicting context pair(s) with node memory, 4 node(s) had untolerated taint(s). no new claims to deallocate, preemption: 0/6 nodes are available: 2 No preemption victims found for incoming pod, 4 Preemption is not helpful for scheduling."
60.1185,Job,ADDED,eval-sanitize-20-r0-021,
60.1196,Pod,ADDED,eval-sanitize-20-r0-023-5gj96,phase=Succeeded node=kind-worker3
60.1199,Event,ADDED,eval-sanitize-20-r0-016-wsgf9.18d41a6077ee7325,reason=Scheduled count=None msg=Successfully assigned compute/eval-sanitize-20-r0-016-wsgf9 to kind-worker2
60.1201,Event,ADDED,eval-sanitize-20-r0-016-wsgf9.18d41a6091f45892,"reason=Pulled count=1 msg=Container image ""busybox:musl"" already present on machine"
60.1203,Event,ADDED,eval-sanitize-20-r0-016-wsgf9.18d41a609346c238,reason=Created count=1 msg=Created container: task
60.1215,Job,ADDED,eval-sanitize-20-r0-022,
60.1227,Pod,ADDED,eval-sanitize-20-r0-024-g6xwd,phase=Succeeded node=kind-worker3
60.123,Event,ADDED,eval-sanitize-20-r0-016-wsgf9.18d41a6097408e6d,reason=Started count=1 msg=Started container task
60.1233,Event,ADDED,eval-sanitize-20-r0-016.18d41a5c1e51f08e,reason=SuccessfulCreate count=1 msg=Created pod: eval-sanitize-20-r0-016-wsgf9
60.1235,Event,ADDED,eval-sanitize-20-r0-016.18d41a652d1b8d2f,reason=Completed count=1 msg=Job completed
60.1236,Event,ADDED,eval-sanitize-20-r0-017-tq46z.18d41a5c59bf3701,"reason=FailedScheduling count=None msg=0/6 nodes are available: 6 node(s) had untolerated taint(s). no new claims to deallocate, preemption: 0/6 nodes are available: 6 Preemption is not helpful for scheduling."
60.1238,Event,ADDED,eval-sanitize-20-r0-017-tq46z.18d41a5fcb274ccc,"reason=FailedScheduling count=None msg=0/6 nodes are available: 1 c_wall violated: 1 conflicting context pair(s) with node memory, 5 node(s) had untolerated taint(s). no new claims to deallocate, preemption: 0/6 nodes are available: 1 No preemption victims found for incoming pod, 5 Preemption is not helpful for scheduling."
60.124,Event,ADDED,eval-sanitize-20-r0-017-tq46z.18d41a5fde135abc,"reason=FailedScheduling count=None msg=0/6 nodes are available: 1 c_wall violated: 1 conflicting context pair(s) with node memory, 5 node(s) had untolerated taint(s). no new claims to deallocate, preemption: 0/6 nodes are available: 1 No preemption victims found for incoming pod, 5 Preemption is not helpful for scheduling."
60.1242,Event,ADDED,eval-sanitize-20-r0-017-tq46z.18d41a6025de2d25,reason=Scheduled count=None msg=Successfully assigned compute/eval-sanitize-20-r0-017-tq46z to kind-worker4
60.1249,Job,ADDED,eval-sanitize-20-r0-023,
60.1257,Job,ADDED,eval-sanitize-20-r0-024,
60.1264,Event,ADDED,eval-sanitize-20-r0-017-tq46z.18d41a603fa1726f,"reason=Pulled count=1 msg=Container image ""busybox:musl"" already present on machine"
60.1269,Event,ADDED,eval-sanitize-20-r0-017-tq46z.18d41a6040db631f,reason=Created count=1 msg=Created container: task
60.1271,Event,ADDED,eval-sanitize-20-r0-017-tq46z.18d41a6045874cf2,reason=Started count=1 msg=Started container task
60.1273,Event,ADDED,eval-sanitize-20-r0-017.18d41a5c59b9cd80,reason=SuccessfulCreate count=1 msg=Created pod: eval-sanitize-20-r0-017-tq46z
60.1285,Pod,ADDED,eval-sanitize-20-r0-025-gp5dc,phase=Succeeded node=kind-worker3
60.1289,Event,ADDED,eval-sanitize-20-r0-017.18d41a642f4b534a,reason=Completed count=1 msg=Job completed
60.1291,Event,ADDED,eval-sanitize-20-r0-018-hz2rn.18d41a5c95959412,"reason=FailedScheduling count=None msg=0/6 nodes are available: 6 node(s) had untolerated taint(s). no new claims to deallocate, preemption: 0/6 nodes are available: 6 Preemption is not helpful for scheduling."
60.1292,Event,ADDED,eval-sanitize-20-r0-018-hz2rn.18d41a5fcc7ebb6f,reason=Scheduled count=None msg=Successfully assigned compute/eval-sanitize-20-r0-018-hz2rn to kind-worker
60.1304,Pod,ADDED,eval-sanitize-20-r0-026-2vx96,phase=Succeeded node=kind-worker3
60.1312,Job,ADDED,eval-sanitize-20-r0-025,
60.1319,Event,ADDED,eval-sanitize-20-r0-018-hz2rn.18d41a5fe4e79d6a,"reason=Pulled count=1 msg=Container image ""busybox:musl"" already present on machine"
60.1321,Event,ADDED,eval-sanitize-20-r0-018-hz2rn.18d41a5fe632d88f,reason=Created count=1 msg=Created container: task
60.1323,Event,ADDED,eval-sanitize-20-r0-018-hz2rn.18d41a5fe8582a06,reason=Started count=1 msg=Started container task
60.1325,Event,ADDED,eval-sanitize-20-r0-018.18d41a5c95822d3b,reason=SuccessfulCreate count=1 msg=Created pod: eval-sanitize-20-r0-018-hz2rn
60.1327,Event,ADDED,eval-sanitize-20-r0-018.18d41a632315acda,reason=Completed count=1 msg=Job completed
60.1328,Event,ADDED,eval-sanitize-20-r0-019-7rmqh.18d41a5cd0e395fd,"reason=FailedScheduling count=None msg=0/6 nodes are available: 6 node(s) had untolerated taint(s). no new claims to deallocate, preemption: 0/6 nodes are available: 6 Preemption is not helpful for scheduling."
60.1331,Event,ADDED,eval-sanitize-20-r0-019-7rmqh.18d41a5fcc5685de,"reason=FailedScheduling count=None msg=0/6 nodes are available: 1 c_wall violated: 1 conflicting context pair(s) with node memory, 5 node(s) had untolerated taint(s). no new claims to deallocate, preemption: 0/6 nodes are available: 1 No preemption victims found for incoming pod, 5 Preemption is not helpful for scheduling."
60.1343,Pod,ADDED,eval-sanitize-20-r0-027-mccff,phase=Succeeded node=kind-worker4
60.1353,Job,ADDED,eval-sanitize-20-r0-026,
60.1356,Event,ADDED,eval-sanitize-20-r0-019-7rmqh.18d41a5fde416f32,"reason=FailedScheduling count=None msg=0/6 nodes are available: 1 c_wall violated: 1 conflicting context pair(s) with node memory, 5 node(s) had untolerated taint(s). no new claims to deallocate, preemption: 0/6 nodes are available: 1 No preemption victims found for incoming pod, 5 Preemption is not helpful for scheduling."
60.1358,Event,ADDED,eval-sanitize-20-r0-019-7rmqh.18d41a6041c489ff,"reason=FailedScheduling count=None msg=0/6 nodes are available: 1 c_wall violated: 1 conflicting context pair(s) with node memory, 1 c_wall violated: 3 conflicting context pair(s) with node memory, 4 node(s) had untolerated taint(s). no new claims to deallocate, preemption: 0/6 nodes are available: 2 No preemption victims found for incoming pod, 4 Preemption is not helpful for scheduling."
60.1359,Event,ADDED,eval-sanitize-20-r0-019-7rmqh.18d41a607f854ae5,reason=Scheduled count=None msg=Successfully assigned compute/eval-sanitize-20-r0-019-7rmqh to kind-worker5
60.1361,Event,ADDED,eval-sanitize-20-r0-019-7rmqh.18d41a60987425a3,"reason=Pulled count=1 msg=Container image ""busybox:musl"" already present on machine"
60.1373,Pod,ADDED,eval-sanitize-20-r0-028-nr6jw,phase=Succeeded node=kind-worker2
60.1381,Job,ADDED,eval-sanitize-20-r0-027,
60.1384,Event,ADDED,eval-sanitize-20-r0-019-7rmqh.18d41a60999670c9,reason=Created count=1 msg=Created container: task
60.1386,Event,ADDED,eval-sanitize-20-r0-019-7rmqh.18d41a609d528bda,reason=Started count=1 msg=Started container task
60.1388,Event,ADDED,eval-sanitize-20-r0-019.18d41a5cd0d9bb0c,reason=SuccessfulCreate count=1 msg=Created pod: eval-sanitize-20-r0-019-7rmqh
60.14,Pod,ADDED,eval-sanitize-20-r0-029-z4hhp,phase=Succeeded node=kind-worker5
60.1408,Job,ADDED,eval-sanitize-20-r0-028,
60.1411,Event,ADDED,eval-sanitize-20-r0-019.18d41a651e031f48,reason=Completed count=1 msg=Job completed
60.1413,Event,ADDED,eval-sanitize-20-r0-020-hjlkw.18d41a5d0d529aa5,"reason=FailedScheduling count=None msg=0/6 nodes are available: 6 node(s) had untolerated taint(s). no new claims to deallocate, preemption: 0/6 nodes are available: 6 Preemption is not helpful for scheduling."
60.1415,Event,ADDED,eval-sanitize-20-r0-020-hjlkw.18d41a5fcdb2700b,"reason=FailedScheduling count=None msg=0/6 nodes are available: 1 c_wall violated: 1 conflicting context pair(s) with node memory, 5 node(s) had untolerated taint(s). no new claims to deallocate, preemption: 0/6 nodes are available: 1 No preemption victims found for incoming pod, 5 Preemption is not helpful for scheduling."
60.1431,Pod,ADDED,eval-sanitize-20-r0-030-vsswq,phase=Succeeded node=kind-worker4
60.1444,Job,ADDED,eval-sanitize-20-r0-029,
60.1447,Event,ADDED,eval-sanitize-20-r0-020-hjlkw.18d41a5fde715d3d,"reason=FailedScheduling count=None msg=0/6 nodes are available: 1 c_wall violated: 1 conflicting context pair(s) with node memory, 5 node(s) had untolerated taint(s). no new claims to deallocate, preemption: 0/6 nodes are available: 1 No preemption victims found for incoming pod, 5 Preemption is not helpful for scheduling."
60.1449,Event,ADDED,eval-sanitize-20-r0-020-hjlkw.18d41a60435d0fc8,"reason=FailedScheduling count=None msg=0/6 nodes are available: 2 c_wall violated: 1 conflicting context pair(s) with node memory, 4 node(s) had untolerated taint(s). no new claims to deallocate, preemption: 0/6 nodes are available: 2 No preemption victims found for incoming pod, 4 Preemption is not helpful for scheduling."
60.1451,Event,ADDED,eval-sanitize-20-r0-020-hjlkw.18d41a6089aeb021,reason=Scheduled count=None msg=Successfully assigned compute/eval-sanitize-20-r0-020-hjlkw to kind-worker2
60.1454,Event,ADDED,eval-sanitize-20-r0-020-hjlkw.18d41a60a346d35a,"reason=Pulled count=1 msg=Container image ""busybox:musl"" already present on machine"
60.1463,Job,ADDED,eval-sanitize-20-r0-030,
60.1466,Event,ADDED,eval-sanitize-20-r0-020-hjlkw.18d41a60a4b1922d,reason=Created count=1 msg=Created container: task
60.1469,Event,ADDED,eval-sanitize-20-r0-020-hjlkw.18d41a60aa3f7eea,reason=Started count=1 msg=Started container task
60.1471,Event,ADDED,eval-sanitize-20-r0-020.18d41a5d0d47bf78,reason=SuccessfulCreate count=1 msg=Created pod: eval-sanitize-20-r0-020-hjlkw
60.1473,Event,ADDED,eval-sanitize-20-r0-020.18d41a646dd5617b,reason=Completed count=1 msg=Job completed
60.1485,Pod,ADDED,eval-sanitize-20-r0-031-rj57f,phase=Succeeded node=kind-worker2
60.1488,Event,ADDED,eval-sanitize-20-r0-021-clzvc.18d41a5d48ab6f27,"reason=FailedScheduling count=None msg=0/6 nodes are available: 6 node(s) had untolerated taint(s). no new claims to deallocate, preemption: 0/6 nodes are available: 6 Preemption is not helpful for scheduling."
60.149,Event,ADDED,eval-sanitize-20-r0-021-clzvc.18d41a5fce364982,"reason=FailedScheduling count=None msg=0/6 nodes are available: 1 c_wall violated: 1 conflicting context pair(s) with node memory, 5 node(s) had untolerated taint(s). no new claims to deallocate, preemption: 0/6 nodes are available: 1 No preemption victims found for incoming pod, 5 Preemption is not helpful for scheduling."
60.1492,Event,ADDED,eval-sanitize-20-r0-021-clzvc.18d41a5fde9c3473,"reason=FailedScheduling count=None msg=0/6 nodes are available: 1 c_wall violated: 1 conflicting context pair(s) with node memory, 5 node(s) had untolerated taint(s). no new claims to deallocate, preemption: 0/6 nodes are available: 1 No preemption victims found for incoming pod, 5 Preemption is not helpful for scheduling."
60.1504,Pod,ADDED,eval-sanitize-20-r0-032-7bknl,phase=Succeeded node=kind-worker4
60.1514,Job,ADDED,eval-sanitize-20-r0-031,
60.1516,Event,ADDED,eval-sanitize-20-r0-021-clzvc.18d41a6006350542,reason=Scheduled count=None msg=Successfully assigned compute/eval-sanitize-20-r0-021-clzvc to kind-worker4
60.1518,Event,ADDED,eval-sanitize-20-r0-021-clzvc.18d41a60210ebb00,"reason=Pulled count=1 msg=Container image ""busybox:musl"" already present on machine"
60.152,Event,ADDED,eval-sanitize-20-r0-021-clzvc.18d41a60227695f8,reason=Created count=1 msg=Created container: task
60.153,Job,ADDED,eval-sanitize-20-r0-032,
60.1533,Event,ADDED,eval-sanitize-20-r0-021-clzvc.18d41a602623dcdc,reason=Started count=1 msg=Started container task
60.1535,Event,ADDED,eval-sanitize-20-r0-021.18d41a5d489d4155,reason=SuccessfulCreate count=1 msg=Created pod: eval-sanitize-20-r0-021-clzvc
60.1537,Event,ADDED,eval-sanitize-20-r0-021.18d41a633ea24c23,reason=Completed count=1 msg=Job completed
60.1539,Event,ADDED,eval-sanitize-20-r0-022-bj2qs.18d41a5d8400fbeb,"reason=FailedScheduling count=None msg=0/6 nodes are available: 6 node(s) had untolerated taint(s). no new claims to deallocate, preemption: 0/6 nodes are available: 6 Preemption is not helpful for scheduling."
60.1551,Pod,ADDED,eval-sanitize-20-r0-033-5lzzb,phase=Succeeded node=kind-worker2
60.1568,Pod,ADDED,eval-sanitize-20-r0-034-977cj,phase=Succeeded node=kind-worker4
60.1577,Job,ADDED,eval-sanitize-20-r0-033,
60.1579,Event,ADDED,eval-sanitize-20-r0-022-bj2qs.18d41a5fd080c548,"reason=FailedScheduling count=None msg=0/6 nodes are available: 1 c_wall violated: 1 conflicting context pair(s) with node memory, 5 node(s) had untolerated taint(s). no new claims to deallocate, preemption: 0/6 nodes are available: 1 No preemption victims found for incoming pod, 5 Preemption is not helpful for scheduling."
60.1582,Event,ADDED,eval-sanitize-20-r0-022-bj2qs.18d41a5fdec8e577,"reason=FailedScheduling count=None msg=0/6 nodes are available: 1 c_wall violated: 1 conflicting context pair(s) with node memory, 5 node(s) had untolerated taint(s). no new claims to deallocate, preemption: 0/6 nodes are available: 1 No preemption victims found for incoming pod, 5 Preemption is not helpful for scheduling."
60.1584,Event,ADDED,eval-sanitize-20-r0-022-bj2qs.18d41a6006a25910,reason=Scheduled count=None msg=Successfully assigned compute/eval-sanitize-20-r0-022-bj2qs to kind-worker4
60.1588,Event,ADDED,eval-sanitize-20-r0-022-bj2qs.18d41a60219aca64,"reason=Pulled count=1 msg=Container image ""busybox:musl"" already present on machine"
60.159,Event,ADDED,eval-sanitize-20-r0-022-bj2qs.18d41a6023077416,reason=Created count=1 msg=Created container: task
60.1592,Event,ADDED,eval-sanitize-20-r0-022-bj2qs.18d41a602670d557,reason=Started count=1 msg=Started container task
60.1594,Event,ADDED,eval-sanitize-20-r0-022.18d41a5d83f4f7a3,reason=SuccessfulCreate count=1 msg=Created pod: eval-sanitize-20-r0-022-bj2qs
60.1609,Pod,ADDED,eval-sanitize-20-r0-035-g79jb,phase=Succeeded node=kind-worker2
60.1622,Job,ADDED,eval-sanitize-20-r0-034,
60.1625,Event,ADDED,eval-sanitize-20-r0-022.18d41a633f61669a,reason=Completed count=1 msg=Job completed
60.1628,Event,ADDED,eval-sanitize-20-r0-023-5gj96.18d41a5dc00437a8,"reason=FailedScheduling count=None msg=0/6 nodes are available: 6 node(s) had untolerated taint(s). no new claims to deallocate, preemption: 0/6 nodes are available: 6 Preemption is not helpful for scheduling."
60.1629,Event,ADDED,eval-sanitize-20-r0-023-5gj96.18d41a5fd114e04d,"reason=FailedScheduling count=None msg=0/6 nodes are available: 1 c_wall violated: 1 conflicting context pair(s) with node memory, 5 node(s) had untolerated taint(s). no new claims to deallocate, preemption: 0/6 nodes are available: 1 No preemption victims found for incoming pod, 5 Preemption is not helpful for scheduling."
60.1641,Pod,ADDED,eval-sanitize-20-r0-036-gt8rv,phase=Succeeded node=kind-worker5
60.1649,Job,ADDED,eval-sanitize-20-r0-035,
60.166,Pod,ADDED,eval-sanitize-20-r0-037-r99cc,phase=Succeeded node=kind-worker
60.1663,Event,ADDED,eval-sanitize-20-r0-023-5gj96.18d41a5fe1eba739,"reason=FailedScheduling count=None msg=0/6 nodes are available: 1 c_wall violated: 1 conflicting context pair(s) with node memory, 5 node(s) had untolerated taint(s). no new claims to deallocate, preemption: 0/6 nodes are available: 1 No preemption victims found for incoming pod, 5 Preemption is not helpful for scheduling."
60.1665,Event,ADDED,eval-sanitize-20-r0-023-5gj96.18d41a602c0414f3,"reason=FailedScheduling count=None msg=0/6 nodes are available: 1 c_wall violated: 1 conflicting context pair(s) with node memory, 1 c_wall violated: 3 conflicting context pair(s) with node memory, 4 node(s) had untolerated taint(s). no new claims to deallocate, preemption: 0/6 nodes are available: 2 No preemption victims found for incoming pod, 4 Preemption is not helpful for scheduling."
60.1667,Event,ADDED,eval-sanitize-20-r0-023-5gj96.18d41a604758bf12,"reason=FailedScheduling count=None msg=0/6 nodes are available: 1 c_wall violated: 1 conflicting context pair(s) with node memory, 1 c_wall violated: 3 conflicting context pair(s) with node memory, 4 node(s) had untolerated taint(s). no new claims to deallocate, preemption: 0/6 nodes are available: 2 No preemption victims found for incoming pod, 4 Preemption is not helpful for scheduling."
60.1674,Job,ADDED,eval-sanitize-20-r0-036,
60.1687,Pod,ADDED,eval-sanitize-20-r0-038-2j57b,phase=Succeeded node=kind-worker2
60.169,Event,ADDED,eval-sanitize-20-r0-023-5gj96.18d41a608ff15f7b,reason=Scheduled count=None msg=Successfully assigned compute/eval-sanitize-20-r0-023-5gj96 to kind-worker3
60.1693,Event,ADDED,eval-sanitize-20-r0-023-5gj96.18d41a60aaab3dac,"reason=Pulled count=1 msg=Container image ""busybox:musl"" already present on machine"
60.1694,Event,ADDED,eval-sanitize-20-r0-023-5gj96.18d41a60abf7f1e4,reason=Created count=1 msg=Created container: task
60.1703,Job,ADDED,eval-sanitize-20-r0-037,
60.1706,Event,ADDED,eval-sanitize-20-r0-023-5gj96.18d41a60af47f7b0,reason=Started count=1 msg=Started container task
60.1708,Event,ADDED,eval-sanitize-20-r0-023.18d41a5dbff8fef9,reason=SuccessfulCreate count=1 msg=Created pod: eval-sanitize-20-r0-023-5gj96
60.171,Event,ADDED,eval-sanitize-20-r0-023.18d41a652f57cd76,reason=Completed count=1 msg=Job completed
60.1712,Event,ADDED,eval-sanitize-20-r0-024-g6xwd.18d41a5dfb7a88af,"reason=FailedScheduling count=None msg=0/6 nodes are available: 6 node(s) had untolerated taint(s). no new claims to deallocate, preemption: 0/6 nodes are available: 6 Preemption is not helpful for scheduling."
60.1721,Job,ADDED,eval-sanitize-20-r0-038,
60.1724,Event,ADDED,eval-sanitize-20-r0-024-g6xwd.18d41a5fd208f63b,"reason=FailedScheduling count=None msg=0/6 nodes are available: 1 c_wall violated: 1 conflicting context pair(s) with node memory, 5 node(s) had untolerated taint(s). no new claims to deallocate, preemption: 0/6 nodes are available: 1 No preemption victims found for incoming pod, 5 Preemption is not helpful for scheduling."
60.1726,Event,ADDED,eval-sanitize-20-r0-024-g6xwd.18d41a5fe58bdaa8,"reason=FailedScheduling count=None msg=0/6 nodes are available: 1 c_wall violated: 1 conflicting context pair(s) with node memory, 5 node(s) had untolerated taint(s). no new claims to deallocate, preemption: 0/6 nodes are available: 1 No preemption victims found for incoming pod, 5 Preemption is not helpful for scheduling."
60.1728,Event,ADDED,eval-sanitize-20-r0-024-g6xwd.18d41a602fafdb9b,"reason=FailedScheduling count=None msg=0/6 nodes are available: 1 c_wall violated: 1 conflicting context pair(s) with node memory, 1 c_wall violated: 3 conflicting context pair(s) with node memory, 4 node(s) had untolerated taint(s). no new claims to deallocate, preemption: 0/6 nodes are available: 2 No preemption victims found for incoming pod, 4 Preemption is not helpful for scheduling."
60.174,Pod,ADDED,eval-sanitize-20-r0-039-4ckrh,phase=Succeeded node=kind-worker
60.1743,Event,ADDED,eval-sanitize-20-r0-024-g6xwd.18d41a6047f6089e,reason=Scheduled count=None msg=Successfully assigned compute/eval-sanitize-20-r0-024-g6xwd to kind-worker3
60.1745,Event,ADDED,eval-sanitize-20-r0-024-g6xwd.18d41a6061d5d834,"reason=Pulled count=1 msg=Container image ""busybox:musl"" already present on machine"
60.1748,Event,ADDED,eval-sanitize-20-r0-024-g6xwd.18d41a6063fc1d84,reason=Created count=1 msg=Created container: task
60.175,Event,ADDED,eval-sanitize-20-r0-024-g6xwd.18d41a6067966998,reason=Started count=1 msg=Started container task
60.1763,Pod,ADDED,eval-sanitize-20-r0-040-x5pl9,phase=Succeeded node=kind-worker2
60.1774,Job,ADDED,eval-sanitize-20-r0-039,
60.1777,Event,ADDED,eval-sanitize-20-r0-024.18d41a5dfb754a92,reason=SuccessfulCreate count=1 msg=Created pod: eval-sanitize-20-r0-024-g6xwd
60.1779,Event,ADDED,eval-sanitize-20-r0-024.18d41a64c4125aca,reason=Completed count=1 msg=Job completed
60.1781,Event,ADDED,eval-sanitize-20-r0-025-gp5dc.18d41a5e37097bcf,"reason=FailedScheduling count=None msg=0/6 nodes are available: 6 node(s) had untolerated taint(s). no new claims to deallocate, preemption: 0/6 nodes are available: 6 Preemption is not helpful for scheduling."
60.1794,Job,ADDED,eval-sanitize-20-r0-040,
60.1797,Event,ADDED,eval-sanitize-20-r0-025-gp5dc.18d41a5fd283d507,"reason=FailedScheduling count=None msg=0/6 nodes are available: 1 c_wall violated: 1 conflicting context pair(s) with node memory, 5 node(s) had untolerated taint(s). no new claims to deallocate, preemption: 0/6 nodes are available: 1 No preemption victims found for incoming pod, 5 Preemption is not helpful for scheduling."
60.18,Event,ADDED,eval-sanitize-20-r0-025-gp5dc.18d41a5fe5cc4388,"reason=FailedScheduling count=None msg=0/6 nodes are available: 1 c_wall violated: 1 conflicting context pair(s) with node memory, 5 node(s) had untolerated taint(s). no new claims to deallocate, preemption: 0/6 nodes are available: 1 No preemption victims found for incoming pod, 5 Preemption is not helpful for scheduling."
60.1802,Event,ADDED,eval-sanitize-20-r0-025-gp5dc.18d41a60315cd3f6,"reason=FailedScheduling count=None msg=0/6 nodes are available: 1 c_wall violated: 1 conflicting context pair(s) with node memory, 1 c_wall violated: 2 conflicting context pair(s) with node memory, 4 node(s) had untolerated taint(s). no new claims to deallocate, preemption: 0/6 nodes are available: 2 No preemption victims found for incoming pod, 4 Preemption is not helpful for scheduling."
60.1816,Pod,ADDED,eval-sanitize-20-r0-041-c54qx,phase=Succeeded node=kind-worker2
60.1821,Event,ADDED,eval-sanitize-20-r0-025-gp5dc.18d41a604d85b2c8,reason=Scheduled count=None msg=Successfully assigned compute/eval-sanitize-20-r0-025-gp5dc to kind-worker3
60.1824,Event,ADDED,eval-sanitize-20-r0-025-gp5dc.18d41a6067f8149a,"reason=Pulled count=1 msg=Container image ""busybox:musl"" already present on machine"
60.1826,Event,ADDED,eval-sanitize-20-r0-025-gp5dc.18d41a606937762f,reason=Created count=1 msg=Created container: task
60.1829,Event,ADDED,eval-sanitize-20-r0-025-gp5dc.18d41a606b4fabb8,reason=Started count=1 msg=Started container task
60.1842,Pod,ADDED,eval-sanitize-20-r0-042-rkjnj,phase=Succeeded node=kind-worker2
60.1852,Job,ADDED,eval-sanitize-20-r0-041,
60.1855,Event,ADDED,eval-sanitize-20-r0-025.18d41a5e36fb0b11,reason=SuccessfulCreate count=1 msg=Created pod: eval-sanitize-20-r0-025-gp5dc
60.1858,Event,ADDED,eval-sanitize-20-r0-025.18d41a64c116373b,reason=Completed count=1 msg=Job completed
60.1859,Event,ADDED,eval-sanitize-20-r0-026-2vx96.18d41a5e7252b1b8,"reason=FailedScheduling count=None msg=0/6 nodes are available: 6 node(s) had untolerated taint(s). no new claims to deallocate, preemption: 0/6 nodes are available: 6 Preemption is not helpful for scheduling."
60.1868,Job,ADDED,eval-sanitize-20-r0-042,
60.187,Event,ADDED,eval-sanitize-20-r0-026-2vx96.18d41a5fd3a8ca16,"reason=FailedScheduling count=None msg=0/6 nodes are available: 1 c_wall violated: 1 conflicting context pair(s) with node memory, 5 node(s) had untolerated taint(s). no new claims to deallocate, preemption: 0/6 nodes are available: 1 No preemption victims found for incoming pod, 5 Preemption is not helpful for scheduling."
60.1873,Event,ADDED,eval-sanitize-20-r0-026-2vx96.18d41a5fe5fd9577,"reason=FailedScheduling count=None msg=0/6 nodes are available: 1 c_wall violated: 1 conflicting context pair(s) with node memory, 5 node(s) had untolerated taint(s). no new claims to deallocate, preemption: 0/6 nodes are available: 1 No preemption victims found for incoming pod, 5 Preemption is not helpful for scheduling."
60.1876,Event,ADDED,eval-sanitize-20-r0-026-2vx96.18d41a60356157fe,"reason=FailedScheduling count=None msg=0/6 nodes are available: 1 c_wall violated: 1 conflicting context pair(s) with node memory, 1 c_wall violated: 2 conflicting context pair(s) with node memory, 4 node(s) had untolerated taint(s). no new claims to deallocate, preemption: 0/6 nodes are available: 2 No preemption victims found for incoming pod, 4 Preemption is not helpful for scheduling."
60.1887,Pod,ADDED,eval-sanitize-20-r0-043-d7z76,phase=Succeeded node=kind-worker3
60.1891,Event,ADDED,eval-sanitize-20-r0-026-2vx96.18d41a604fdeacd3,reason=Scheduled count=None msg=Successfully assigned compute/eval-sanitize-20-r0-026-2vx96 to kind-worker3
60.1893,Event,ADDED,eval-sanitize-20-r0-026-2vx96.18d41a6068d71ff5,"reason=Pulled count=1 msg=Container image ""busybox:musl"" already present on machine"
60.1895,Event,ADDED,eval-sanitize-20-r0-026-2vx96.18d41a606a1583c0,reason=Created count=1 msg=Created container: task
60.1897,Event,ADDED,eval-sanitize-20-r0-026-2vx96.18d41a606c6660fd,reason=Started count=1 msg=Started container task
60.1909,Pod,ADDED,eval-sanitize-20-r0-044-tlwkv,phase=Succeeded node=kind-worker3
60.1917,Job,ADDED,eval-sanitize-20-r0-043,
60.1922,Event,ADDED,eval-sanitize-20-r0-026.18d41a5e72480828,reason=SuccessfulCreate count=1 msg=Created pod: eval-sanitize-20-r0-026-2vx96
60.1924,Event,ADDED,eval-sanitize-20-r0-026.18d41a64af9ff872,reason=Completed count=1 msg=Job completed
60.1926,Event,ADDED,eval-sanitize-20-r0-027-mccff.18d41a5eadf144e2,"reason=FailedScheduling count=None msg=0/6 nodes are available: 6 node(s) had untolerated taint(s). no new claims to deallocate, preemption: 0/6 nodes are available: 6 Preemption is not helpful for scheduling."
60.1934,Job,ADDED,eval-sanitize-20-r0-044,
60.1937,Event,ADDED,eval-sanitize-20-r0-027-mccff.18d41a5fd4294248,"reason=FailedScheduling count=None msg=0/6 nodes are available: 1 c_wall violated: 2 conflicting context pair(s) with node memory, 5 node(s) had untolerated taint(s). no new claims to deallocate, preemption: 0/6 nodes are available: 1 No preemption victims found for incoming pod, 5 Preemption is not helpful for scheduling."
60.1939,Event,ADDED,eval-sanitize-20-r0-027-mccff.18d41a5fe628cf64,"reason=FailedScheduling count=None msg=0/6 nodes are available: 1 c_wall violated: 2 conflicting context pair(s) with node memory, 5 node(s) had untolerated taint(s). no new claims to deallocate, preemption: 0/6 nodes are available: 1 No preemption victims found for incoming pod, 5 Preemption is not helpful for scheduling."
60.1941,Event,ADDED,eval-sanitize-20-r0-027-mccff.18d41a6011eba381,reason=Scheduled count=None msg=Successfully assigned compute/eval-sanitize-20-r0-027-mccff to kind-worker4
60.1943,Event,ADDED,eval-sanitize-20-r0-027-mccff.18d41a602b1f024d,"reason=Pulled count=1 msg=Container image ""busybox:musl"" already present on machine"
60.1951,Job,ADDED,eval-sanitize-20-r0-045,
60.1964,Pod,ADDED,eval-sanitize-20-r0-045-l6mr9,phase=Succeeded node=kind-worker4
60.1967,Event,ADDED,eval-sanitize-20-r0-027-mccff.18d41a602ca2f1b5,reason=Created count=1 msg=Created container: task
60.1969,Event,ADDED,eval-sanitize-20-r0-027-mccff.18d41a60304cf278,reason=Started count=1 msg=Started container task
60.1971,Event,ADDED,eval-sanitize-20-r0-027.18d41a5eade6f1f3,reason=SuccessfulCreate count=1 msg=Created pod: eval-sanitize-20-r0-027-mccff
60.1978,Job,ADDED,eval-sanitize-20-r0-046,
60.1989,Pod,ADDED,eval-sanitize-20-r0-046-ptdmq,phase=Succeeded node=kind-worker2
60.1992,Event,ADDED,eval-sanitize-20-r0-027.18d41a634008cc98,reason=Completed count=1 msg=Job completed
60.1994,Event,ADDED,eval-sanitize-20-r0-028-nr6jw.18d41a5ee9d4a98a,"reason=FailedScheduling count=None msg=0/6 nodes are available: 6 node(s) had untolerated taint(s). no new claims to deallocate, preemption: 0/6 nodes are available: 6 Preemption is not helpful for scheduling."
60.1996,Event,ADDED,eval-sanitize-20-r0-028-nr6jw.18d41a5fd49bc368,"reason=FailedScheduling count=None msg=0/6 nodes are available: 1 c_wall violated: 1 conflicting context pair(s) with node memory, 5 node(s) had untolerated taint(s). no new claims to deallocate, preemption: 0/6 nodes are available: 1 No preemption victims found for incoming pod, 5 Preemption is not helpful for scheduling."
60.1998,Event,ADDED,eval-sanitize-20-r0-028-nr6jw.18d41a5fe65d429e,"reason=FailedScheduling count=None msg=0/6 nodes are available: 1 c_wall violated: 1 conflicting context pair(s) with node memory, 5 node(s) had untolerated taint(s). no new claims to deallocate, preemption: 0/6 nodes are available: 1 No preemption victims found for incoming pod, 5 Preemption is not helpful for scheduling."
60.2005,Job,ADDED,eval-sanitize-20-r0-047,
60.2012,Event,ADDED,eval-sanitize-20-r0-028-nr6jw.18d41a60364515c1,"reason=FailedScheduling count=None msg=0/6 nodes are available: 2 c_wall violated: 1 conflicting context pair(s) with node memory, 4 node(s) had untolerated taint(s). no new claims to deallocate, preemption: 0/6 nodes are available: 2 No preemption victims found for incoming pod, 4 Preemption is not helpful for scheduling."
60.2014,Event,ADDED,eval-sanitize-20-r0-028-nr6jw.18d41a60a132d6ed,reason=Scheduled count=None msg=Successfully assigned compute/eval-sanitize-20-r0-028-nr6jw to kind-worker2
60.2016,Event,ADDED,eval-sanitize-20-r0-028-nr6jw.18d41a60b9982fbc,"reason=Pulled count=1 msg=Container image ""busybox:musl"" already present on machine"
60.2027,Pod,ADDED,eval-sanitize-20-r0-047-lprs4,phase=Succeeded node=kind-worker4
60.2034,Job,ADDED,eval-sanitize-20-r0-048,
60.204,Event,ADDED,eval-sanitize-20-r0-028-nr6jw.18d41a60ba9e0b97,reason=Created count=1 msg=Created container: task
60.2042,Event,ADDED,eval-sanitize-20-r0-028-nr6jw.18d41a60bca12c96,reason=Started count=1 msg=Started container task
60.2045,Event,ADDED,eval-sanitize-20-r0-028.18d41a5ee9c7fc7e,reason=SuccessfulCreate count=1 msg=Created pod: eval-sanitize-20-r0-028-nr6jw
60.2047,Event,ADDED,eval-sanitize-20-r0-028.18d41a64dc4b782b,reason=Completed count=1 msg=Job completed
60.2058,Pod,ADDED,eval-sanitize-20-r0-048-7lhfc,phase=Running node=kind-worker3
60.2066,Job,ADDED,eval-sanitize-20-r0-049,
60.2078,Pod,ADDED,eval-sanitize-20-r0-049-j5lj6,phase=Running node=kind-worker4
60.208,Event,ADDED,eval-sanitize-20-r0-029-z4hhp.18d41a5f25061e16,"reason=FailedScheduling count=None msg=0/6 nodes are available: 6 node(s) had untolerated taint(s). no new claims to deallocate, preemption: 0/6 nodes are available: 6 Preemption is not helpful for scheduling."
60.2082,Event,ADDED,eval-sanitize-20-r0-029-z4hhp.18d41a5fd66cfe38,"reason=FailedScheduling count=None msg=0/6 nodes are available: 1 c_wall violated: 1 conflicting context pair(s) with node memory, 5 node(s) had untolerated taint(s). no new claims to deallocate, preemption: 0/6 nodes are available: 1 No preemption victims found for incoming pod, 5 Preemption is not helpful for scheduling."
60.2084,Event,ADDED,eval-sanitize-20-r0-029-z4hhp.18d41a5fe694b9a8,"reason=FailedScheduling count=None msg=0/6 nodes are available: 1 c_wall violated: 1 conflicting context pair(s) with node memory, 5 node(s) had untolerated taint(s). no new claims to deallocate, preemption: 0/6 nodes are available: 1 No preemption victims found for incoming pod, 5 Preemption is not helpful for scheduling."
60.2093,Job,ADDED,eval-sanitize-20-r0-050,
60.2105,Pod,ADDED,eval-sanitize-20-r0-050-7ggpc,phase=Running node=kind-worker5
60.2108,Event,ADDED,eval-sanitize-20-r0-029-z4hhp.18d41a60376a0698,"reason=FailedScheduling count=None msg=0/6 nodes are available: 1 c_wall violated: 1 conflicting context pair(s) with node memory, 1 c_wall violated: 2 conflicting context pair(s) with node memory, 4 node(s) had untolerated taint(s). no new claims to deallocate, preemption: 0/6 nodes are available: 2 No preemption victims found for incoming pod, 4 Preemption is not helpful for scheduling."
60.211,Event,ADDED,eval-sanitize-20-r0-029-z4hhp.18d41a6060387ab4,reason=Scheduled count=None msg=Successfully assigned compute/eval-sanitize-20-r0-029-z4hhp to kind-worker5
60.2112,Event,ADDED,eval-sanitize-20-r0-029-z4hhp.18d41a6079080141,"reason=Pulled count=1 msg=Container image ""busybox:musl"" already present on machine"
60.212,Event,ADDED,eval-sanitize-20-r0-029-z4hhp.18d41a607a2a02ac,reason=Created count=1 msg=Created container: task
60.2122,Event,ADDED,eval-sanitize-20-r0-029-z4hhp.18d41a607e7debda,reason=Started count=1 msg=Started container task
60.2124,Event,ADDED,eval-sanitize-20-r0-029.18d41a5f24f88901,reason=SuccessfulCreate count=1 msg=Created pod: eval-sanitize-20-r0-029-z4hhp
60.2126,Event,ADDED,eval-sanitize-20-r0-029.18d41a65006e9271,reason=Completed count=1 msg=Job completed
60.2129,Event,ADDED,eval-sanitize-20-r0-030-vsswq.18d41a5f6128f682,"reason=FailedScheduling count=None msg=0/6 nodes are available: 6 node(s) had untolerated taint(s). no new claims to deallocate, preemption: 0/6 nodes are available: 6 Preemption is not helpful for scheduling."
60.213,Event,ADDED,eval-sanitize-20-r0-030-vsswq.18d41a5fd7ee6c8b,"reason=FailedScheduling count=None msg=0/6 nodes are available: 1 c_wall violated: 1 conflicting context pair(s) with node memory, 5 node(s) had untolerated taint(s). no new claims to deallocate, preemption: 0/6 nodes are available: 1 No preemption victims found for incoming pod, 5 Preemption is not helpful for scheduling."
60.2133,Event,ADDED,eval-sanitize-20-r0-030-vsswq.18d41a5fe9cdada2,"reason=FailedScheduling count=None msg=0/6 nodes are available: 1 c_wall violated: 1 conflicting context pair(s) with node memory, 5 node(s) had untolerated taint(s). no new claims to deallocate, preemption: 0/6 nodes are available: 1 No preemption victims found for incoming pod, 5 Preemption is not helpful for scheduling."
60.2136,Event,ADDED,eval-sanitize-20-r0-030-vsswq.18d41a6018f31e11,reason=Scheduled count=None msg=Successfully assigned compute/eval-sanitize-20-r0-030-vsswq to kind-worker4
60.2138,Event,ADDED,eval-sanitize-20-r0-030-vsswq.18d41a6031664c45,"reason=Pulled count=1 msg=Container image ""busybox:musl"" already present on machine"
60.214,Event,ADDED,eval-sanitize-20-r0-030-vsswq.18d41a6032e54335,reason=Created count=1 msg=Created container: task
60.2151,Pod,ADDED,eval-sanitize-20-r0-051-88qrg,phase=Running node=kind-worker
60.2157,Job,ADDED,eval-sanitize-20-r0-051,
60.216,Event,ADDED,eval-sanitize-20-r0-030-vsswq.18d41a603547bbaa,reason=Started count=1 msg=Started container task
60.2162,Event,ADDED,eval-sanitize-20-r0-030.18d41a5f611805a5,reason=SuccessfulCreate count=1 msg=Created pod: eval-sanitize-20-r0-030-vsswq
60.2164,Event,ADDED,eval-sanitize-20-r0-030.18d41a6458cecb87,reason=Completed count=1 msg=Job completed
60.2166,Event,ADDED,eval-sanitize-20-r0-031-rj57f.18d41a5f9c74c312,"reason=FailedScheduling count=None msg=0/6 nodes are available: 6 node(s) had untolerated taint(s). no new claims to deallocate, preemption: 0/6 nodes are available: 6 Preemption is not helpful for scheduling."
60.2177,Pod,ADDED,eval-sanitize-20-r0-052-4zhkt,phase=Running node=kind-worker5
60.2183,Job,ADDED,eval-sanitize-20-r0-052,
60.2186,Event,ADDED,eval-sanitize-20-r0-031-rj57f.18d41a5fd99e19cd,"reason=FailedScheduling count=None msg=0/6 nodes are available: 1 c_wall violated: 1 conflicting context pair(s) with node memory, 5 node(s) had untolerated taint(s). no new claims to deallocate, preemption: 0/6 nodes are available: 1 No preemption victims found for incoming pod, 5 Preemption is not helpful for scheduling."
60.2188,Event,ADDED,eval-sanitize-20-r0-031-rj57f.18d41a5fea310099,"reason=FailedScheduling count=None msg=0/6 nodes are available: 1 c_wall violated: 1 conflicting context pair(s) with node memory, 5 node(s) had untolerated taint(s). no new claims to deallocate, preemption: 0/6 nodes are available: 1 No preemption victims found for incoming pod, 5 Preemption is not helpful for scheduling."
60.219,Event,ADDED,eval-sanitize-20-r0-031-rj57f.18d41a603bc2ddde,"reason=FailedScheduling count=None msg=0/6 nodes are available: 2 c_wall violated: 1 conflicting context pair(s) with node memory, 4 node(s) had untolerated taint(s). no new claims to deallocate, preemption: 0/6 nodes are available: 2 No preemption victims found for incoming pod, 4 Preemption is not helpful for scheduling."
60.2192,Event,ADDED,eval-sanitize-20-r0-031-rj57f.18d41a606b7624a7,reason=Scheduled count=None msg=Successfully assigned compute/eval-sanitize-20-r0-031-rj57f to kind-worker2
60.2196,Event,ADDED,eval-sanitize-20-r0-031-rj57f.18d41a6084e71eaa,"reason=Pulled count=1 msg=Container image ""busybox:musl"" already present on machine"
60.2198,Event,ADDED,eval-sanitize-20-r0-031-rj57f.18d41a608625f4c3,reason=Created count=1 msg=Created container: task
60.2199,Event,ADDED,eval-sanitize-20-r0-031-rj57f.18d41a608bae8c4f,reason=Started count=1 msg=Started container task
60.2202,Event,ADDED,eval-sanitize-20-r0-031.18d41a5f9c63eeb6,reason=SuccessfulCreate count=1 msg=Created pod: eval-sanitize-20-r0-031-rj57f
60.227,Event,ADDED,eval-sanitize-20-r0-031.18d41a64edc6f94d,reason=Completed count=1 msg=Job completed
60.2313,Event,ADDED,eval-sanitize-20-r0-032-7bknl.18d41a5fd87cb265,"reason=FailedScheduling count=None msg=0/6 nodes are available: 1 c_wall violated: 2 conflicting context pair(s) with node memory, 5 node(s) had untolerated taint(s). no new claims to deallocate, preemption: 0/6 nodes are available: 1 No preemption victims found for incoming pod, 5 Preemption is not helpful for scheduling."
60.2328,Event,ADDED,eval-sanitize-20-r0-032-7bknl.18d41a5fea04202e,"reason=FailedScheduling count=None msg=0/6 nodes are available: 1 c_wall violated: 2 conflicting context pair(s) with node memory, 5 node(s) had untolerated taint(s). no new claims to deallocate, preemption: 0/6 nodes are available: 1 No preemption victims found for incoming pod, 5 Preemption is not helpful for scheduling."
60.234,Event,ADDED,eval-sanitize-20-r0-032-7bknl.18d41a601a0aa861,reason=Scheduled count=None msg=Successfully assigned compute/eval-sanitize-20-r0-032-7bknl to kind-worker4
60.2343,Job,ADDED,eval-sanitize-20-r0-053,
60.2355,Event,ADDED,eval-sanitize-20-r0-032-7bknl.18d41a60338d9086,"reason=Pulled count=1 msg=Container image ""busybox:musl"" already present on machine"
60.2372,Event,ADDED,eval-sanitize-20-r0-032-7bknl.18d41a6035aca9a7,reason=Created count=1 msg=Created container: task
60.2385,Event,ADDED,eval-sanitize-20-r0-032-7bknl.18d41a6038340231,reason=Started count=1 msg=Started container task
60.2398,Event,ADDED,eval-sanitize-20-r0-032.18d41a5fd7aaa084,reason=SuccessfulCreate count=1 msg=Created pod: eval-sanitize-20-r0-032-7bknl
60.2409,Job,ADDED,eval-sanitize-20-r0-054,
60.241,Pod,ADDED,eval-sanitize-20-r0-053-9pj9s,phase=Running node=kind-worker
60.2414,Event,ADDED,eval-sanitize-20-r0-032.18d41a63411596de,reason=Completed count=1 msg=Job completed
60.243,Event,ADDED,eval-sanitize-20-r0-033-5lzzb.18d41a6017a3670b,"reason=FailedScheduling count=None msg=0/6 nodes are available: 2 c_wall violated: 1 conflicting context pair(s) with node memory, 4 node(s) had untolerated taint(s). no new claims to deallocate, preemption: 0/6 nodes are available: 2 No preemption victims found for incoming pod, 4 Preemption is not helpful for scheduling."
60.2443,Event,ADDED,eval-sanitize-20-r0-033-5lzzb.18d41a603b69feec,"reason=FailedScheduling count=None msg=0/6 nodes are available: 2 c_wall violated: 1 conflicting context pair(s) with node memory, 4 node(s) had untolerated taint(s). no new claims to deallocate, preemption: 0/6 nodes are available: 2 No preemption victims found for incoming pod, 4 Preemption is not helpful for scheduling."
60.2453,Event,ADDED,eval-sanitize-20-r0-033-5lzzb.18d41a6062b4104b,reason=Scheduled count=None msg=Successfully assigned compute/eval-sanitize-20-r0-033-5lzzb to kind-worker2
60.2467,Event,ADDED,eval-sanitize-20-r0-033-5lzzb.18d41a6079f4ba86,"reason=Pulled count=1 msg=Container image ""busybox:musl"" already present on machine"
60.2472,Job,ADDED,eval-sanitize-20-r0-055,
60.2481,Event,ADDED,eval-sanitize-20-r0-033-5lzzb.18d41a607b2edaf9,reason=Created count=1 msg=Created container: task
60.2492,Event,ADDED,eval-sanitize-20-r0-033-5lzzb.18d41a607ec595c5,reason=Started count=1 msg=Started container task
60.2504,Event,ADDED,eval-sanitize-20-r0-033.18d41a6013780082,reason=SuccessfulCreate count=1 msg=Created pod: eval-sanitize-20-r0-033-5lzzb
60.2516,Event,ADDED,eval-sanitize-20-r0-033.18d41a650be6160d,reason=Completed count=1 msg=Job completed
60.2525,Event,ADDED,eval-sanitize-20-r0-034-977cj.18d41a6059ae0e29,reason=Scheduled count=None msg=Successfully assigned compute/eval-sanitize-20-r0-034-977cj to kind-worker4
60.2531,Pod,ADDED,eval-sanitize-20-r0-054-qhjlr,phase=Running node=kind-worker
60.2539,Event,ADDED,eval-sanitize-20-r0-034-977cj.18d41a607386fa6b,"reason=Pulled count=1 msg=Container image ""busybox:musl"" already present on machine"
60.2543,Job,ADDED,eval-sanitize-20-r0-056,
60.2552,Event,ADDED,eval-sanitize-20-r0-034-977cj.18d41a6075085208,reason=Created count=1 msg=Created container: task
60.2566,Event,ADDED,eval-sanitize-20-r0-034-977cj.18d41a6078d48cb7,reason=Started count=1 msg=Started container task
60.2577,Event,ADDED,eval-sanitize-20-r0-034.18d41a6054d33cef,reason=SuccessfulCreate count=1 msg=Created pod: eval-sanitize-20-r0-034-977cj
60.2586,Event,ADDED,eval-sanitize-20-r0-034.18d41a64d6490fb8,reason=Completed count=1 msg=Job completed
60.2595,Job,ADDED,eval-sanitize-20-r0-057,
60.2599,Event,ADDED,eval-sanitize-20-r0-035-g79jb.18d41a60975afca6,reason=Scheduled count=None msg=Successfully assigned compute/eval-sanitize-20-r0-035-g79jb to kind-worker2
60.2612,Pod,ADDED,eval-sanitize-20-r0-055-2z5sr,phase=Pending node=None
60.2612,Event,ADDED,eval-sanitize-20-r0-035-g79jb.18d41a60af84b7fa,"reason=Pulled count=1 msg=Container image ""busybox:musl"" already present on machine"
60.2627,Event,ADDED,eval-sanitize-20-r0-035-g79jb.18d41a60b092c839,reason=Created count=1 msg=Created container: task
60.2638,Event,ADDED,eval-sanitize-20-r0-035-g79jb.18d41a60b2a89032,reason=Started count=1 msg=Started container task
60.2651,Event,ADDED,eval-sanitize-20-r0-035.18d41a608b62e3d9,reason=SuccessfulCreate count=1 msg=Created pod: eval-sanitize-20-r0-035-g79jb
60.2653,Job,ADDED,eval-sanitize-20-r0-058,
60.2665,Event,ADDED,eval-sanitize-20-r0-035.18d41a651b5038bb,reason=Completed count=1 msg=Job completed
60.2681,Event,ADDED,eval-sanitize-20-r0-036-gt8rv.18d41a60ccddcce2,reason=Scheduled count=None msg=Successfully assigned compute/eval-sanitize-20-r0-036-gt8rv to kind-worker5
60.2691,Event,ADDED,eval-sanitize-20-r0-036-gt8rv.18d41a60e70df5f9,"reason=Pulled count=1 msg=Container image ""busybox:musl"" already present on machine"
60.2694,Pod,ADDED,eval-sanitize-20-r0-056-6bgct,phase=Pending node=None
60.2705,Event,ADDED,eval-sanitize-20-r0-036-gt8rv.18d41a60e81e3228,reason=Created count=1 msg=Created container: task
60.2715,Job,ADDED,eval-sanitize-20-r0-059,
60.2722,Event,ADDED,eval-sanitize-20-r0-036-gt8rv.18d41a60ea415157,reason=Started count=1 msg=Started container task
60.2731,Event,ADDED,eval-sanitize-20-r0-036.18d41a60c60c3045,reason=SuccessfulCreate count=1 msg=Created pod: eval-sanitize-20-r0-036-gt8rv
60.2741,Event,ADDED,eval-sanitize-20-r0-036.18d41a64ca4ffa8c,reason=Completed count=1 msg=Job completed
60.2751,Event,ADDED,eval-sanitize-20-r0-037-r99cc.18d41a61081ca743,reason=Scheduled count=None msg=Successfully assigned compute/eval-sanitize-20-r0-037-r99cc to kind-worker
60.2755,Job,ADDED,eval-sanitize-20-r0-060,
60.2766,Event,ADDED,eval-sanitize-20-r0-037-r99cc.18d41a6121d71e9f,"reason=Pulled count=1 msg=Container image ""busybox:musl"" already present on machine"
60.2772,Pod,ADDED,eval-sanitize-20-r0-057-st55d,phase=Pending node=None
60.2781,Event,ADDED,eval-sanitize-20-r0-037-r99cc.18d41a6122e6234d,reason=Created count=1 msg=Created container: task
60.2792,Event,ADDED,eval-sanitize-20-r0-037-r99cc.18d41a6124ea52a6,reason=Started count=1 msg=Started container task
60.2802,Event,ADDED,eval-sanitize-20-r0-037.18d41a6101b68bd5,reason=SuccessfulCreate count=1 msg=Created pod: eval-sanitize-20-r0-037-r99cc
60.2808,Job,MODIFIED,eval-sanitize-20-r0-060,
60.2812,Event,ADDED,eval-sanitize-20-r0-037.18d41a654147e93a,reason=Completed count=1 msg=Job completed
60.2818,Event,ADDED,eval-sanitize-20-r0-038-2j57b.18d41a6144279bc9,reason=Scheduled count=None msg=Successfully assigned compute/eval-sanitize-20-r0-038-2j57b to kind-worker2
60.2823,Pod,ADDED,eval-sanitize-20-r0-058-9b88s,phase=Pending node=None
60.2829,Event,ADDED,eval-sanitize-20-r0-038-2j57b.18d41a615da7c5e5,"reason=Pulled count=1 msg=Container image ""busybox:musl"" already present on machine"
60.2831,Event,ADDED,eval-sanitize-20-r0-038-2j57b.18d41a615eac5218,reason=Created count=1 msg=Created container: task
60.2833,Event,ADDED,eval-sanitize-20-r0-038-2j57b.18d41a616077e089,reason=Started count=1 msg=Started container task
60.284,Pod,ADDED,eval-sanitize-20-r0-059-zqwtk,phase=Pending node=None
60.2844,Event,ADDED,eval-sanitize-20-r0-038.18d41a613d70bc97,reason=SuccessfulCreate count=1 msg=Created pod: eval-sanitize-20-r0-038-2j57b
60.2846,Event,ADDED,eval-sanitize-20-r0-038.18d41a655fd0ef51,reason=Completed count=1 msg=Job completed
60.2848,Event,ADDED,eval-sanitize-20-r0-039-4ckrh.18d41a617fefc4a0,reason=Scheduled count=None msg=Successfully assigned compute/eval-sanitize-20-r0-039-4ckrh to kind-worker
60.2849,Event,ADDED,eval-sanitize-20-r0-039-4ckrh.18d41a6199124142,"reason=Pulled count=1 msg=Container image ""busybox:musl"" already present on machine"
60.2853,Event,ADDED,eval-sanitize-20-r0-039-4ckrh.18d41a619a2d2621,reason=Created count=1 msg=Created container: task
60.2855,Event,ADDED,eval-sanitize-20-r0-039-4ckrh.18d41a619dbd90b2,reason=Started count=1 msg=Started container task
60.2857,Event,ADDED,eval-sanitize-20-r0-039.18d41a617946e097,reason=SuccessfulCreate count=1 msg=Created pod: eval-sanitize-20-r0-039-4ckrh
60.2859,Event,ADDED,eval-sanitize-20-r0-039.18d41a6582cf07d6,reason=Completed count=1 msg=Job completed
60.2865,Pod,ADDED,eval-sanitize-20-r0-060-b7mgm,phase=Pending node=None
60.2868,Event,ADDED,eval-sanitize-20-r0-040-x5pl9.18d41a61bb4f95f9,reason=Scheduled count=None msg=Successfully assigned compute/eval-sanitize-20-r0-040-x5pl9 to kind-worker2
60.287,Event,ADDED,eval-sanitize-20-r0-040-x5pl9.18d41a61d555ea78,"reason=Pulled count=1 msg=Container image ""busybox:musl"" already present on machine"
60.2872,Event,ADDED,eval-sanitize-20-r0-040-x5pl9.18d41a61d6850606,reason=Created count=1 msg=Created container: task
60.2874,Event,ADDED,eval-sanitize-20-r0-040-x5pl9.18d41a61da24ba86,reason=Started count=1 msg=Started container task
60.2876,Event,ADDED,eval-sanitize-20-r0-040.18d41a61b4f96e41,reason=SuccessfulCreate count=1 msg=Created pod: eval-sanitize-20-r0-040-x5pl9
60.2879,Event,ADDED,eval-sanitize-20-r0-040.18d41a658c2a5d9b,reason=Completed count=1 msg=Job completed
60.288,Event,ADDED,eval-sanitize-20-r0-041-c54qx.18d41a61f6bed432,reason=Scheduled count=None msg=Successfully assigned compute/eval-sanitize-20-r0-041-c54qx to kind-worker2
60.2887,Pod,MODIFIED,eval-sanitize-20-r0-060-b7mgm,phase=Pending node=None
60.289,Event,ADDED,eval-sanitize-20-r0-041-c54qx.18d41a6210950bd0,"reason=Pulled count=1 msg=Container image ""busybox:musl"" already present on machine"
60.2892,Event,ADDED,eval-sanitize-20-r0-041-c54qx.18d41a6211bc43b5,reason=Created count=1 msg=Created container: task
60.2894,Event,ADDED,eval-sanitize-20-r0-041-c54qx.18d41a6213f8228c,reason=Started count=1 msg=Started container task
60.2896,Event,ADDED,eval-sanitize-20-r0-041.18d41a61f0649f31,reason=SuccessfulCreate count=1 msg=Created pod: eval-sanitize-20-r0-041-c54qx
60.29,Event,ADDED,eval-sanitize-20-r0-041.18d41a659deeb63c,reason=Completed count=1 msg=Job completed
60.2902,Event,ADDED,eval-sanitize-20-r0-042-rkjnj.18d41a6232703036,reason=Scheduled count=None msg=Successfully assigned compute/eval-sanitize-20-r0-042-rkjnj to kind-worker2
60.2904,Event,ADDED,eval-sanitize-20-r0-042-rkjnj.18d41a624b645585,"reason=Pulled count=1 msg=Container image ""busybox:musl"" already present on machine"
60.2916,Pod,MODIFIED,eval-sanitize-20-r0-048-7lhfc,phase=Running node=kind-worker3
60.2919,Event,ADDED,eval-sanitize-20-r0-042-rkjnj.18d41a624c7873e9,reason=Created count=1 msg=Created container: task
60.2921,Event,ADDED,eval-sanitize-20-r0-042-rkjnj.18d41a624e79c632,reason=Started count=1 msg=Started container task
60.2923,Event,ADDED,eval-sanitize-20-r0-042.18d41a622c151520,reason=SuccessfulCreate count=1 msg=Created pod: eval-sanitize-20-r0-042-rkjnj
60.2924,Event,ADDED,eval-sanitize-20-r0-042.18d41a6594a826cb,reason=Completed count=1 msg=Job completed
60.293,Event,ADDED,eval-sanitize-20-r0-043-d7z76.18d41a626dfe9bbd,reason=Scheduled count=None msg=Successfully assigned compute/eval-sanitize-20-r0-043-d7z76 to kind-worker3
60.2933,Event,ADDED,eval-sanitize-20-r0-043-d7z76.18d41a6291c1ac2e,"reason=Pulled count=1 msg=Container image ""busybox:musl"" already present on machine"
60.2936,Event,ADDED,eval-sanitize-20-r0-043-d7z76.18d41a6292ffc9df,reason=Created count=1 msg=Created container: task
60.2937,Event,ADDED,eval-sanitize-20-r0-043-d7z76.18d41a629a46902e,reason=Started count=1 msg=Started container task
60.294,Event,ADDED,eval-sanitize-20-r0-043.18d41a62676998a8,reason=SuccessfulCreate count=1 msg=Created pod: eval-sanitize-20-r0-043-d7z76
60.2942,Event,ADDED,eval-sanitize-20-r0-043.18d41a65c7b9b039,reason=Completed count=1 msg=Job completed
60.2944,Event,ADDED,eval-sanitize-20-r0-044-tlwkv.18d41a62a994f3f6,reason=Scheduled count=None msg=Successfully assigned compute/eval-sanitize-20-r0-044-tlwkv to kind-worker3
60.2948,Event,ADDED,eval-sanitize-20-r0-044-tlwkv.18d41a62c2d6843a,"reason=Pulled count=1 msg=Container image ""busybox:musl"" already present on machine"
60.295,Event,ADDED,eval-sanitize-20-r0-044-tlwkv.18d41a62c3dfc66d,reason=Created count=1 msg=Created container: task
60.2952,Event,ADDED,eval-sanitize-20-r0-044-tlwkv.18d41a62cbb16fef,reason=Started count=1 msg=Started container task
60.2953,Event,ADDED,eval-sanitize-20-r0-044.18d41a62a3351a54,reason=SuccessfulCreate count=1 msg=Created pod: eval-sanitize-20-r0-044-tlwkv
60.2957,Event,ADDED,eval-sanitize-20-r0-044.18d41a65fefa3cb8,reason=Completed count=1 msg=Job completed
60.2958,Event,ADDED,eval-sanitize-20-r0-045-l6mr9.18d41a62e52ba2b9,reason=Scheduled count=None msg=Successfully assigned compute/eval-sanitize-20-r0-045-l6mr9 to kind-worker4
60.296,Event,ADDED,eval-sanitize-20-r0-045-l6mr9.18d41a63009e80a8,"reason=Pulled count=1 msg=Container image ""busybox:musl"" already present on machine"
60.2962,Event,ADDED,eval-sanitize-20-r0-045-l6mr9.18d41a6301bb6bdc,reason=Created count=1 msg=Created container: task
60.2965,Event,ADDED,eval-sanitize-20-r0-045-l6mr9.18d41a630a3df714,reason=Started count=1 msg=Started container task
60.2967,Event,ADDED,eval-sanitize-20-r0-045.18d41a62dea08fd8,reason=SuccessfulCreate count=1 msg=Created pod: eval-sanitize-20-r0-045-l6mr9
60.2969,Event,ADDED,eval-sanitize-20-r0-045.18d41a664f052bbb,reason=Completed count=1 msg=Job completed
60.2972,Event,ADDED,eval-sanitize-20-r0-046-ptdmq.18d41a63209dde09,reason=Scheduled count=None msg=Successfully assigned compute/eval-sanitize-20-r0-046-ptdmq to kind-worker2
60.2973,Event,ADDED,eval-sanitize-20-r0-046-ptdmq.18d41a633a3d3db6,"reason=Pulled count=1 msg=Container image ""busybox:musl"" already present on machine"
60.2975,Event,ADDED,eval-sanitize-20-r0-046-ptdmq.18d41a633b49107c,reason=Created count=1 msg=Created container: task
60.2977,Event,ADDED,eval-sanitize-20-r0-046-ptdmq.18d41a63439f30a7,reason=Started count=1 msg=Started container task
60.298,Event,ADDED,eval-sanitize-20-r0-046.18d41a631a00134b,reason=SuccessfulCreate count=1 msg=Created pod: eval-sanitize-20-r0-046-ptdmq
60.2982,Event,ADDED,eval-sanitize-20-r0-046.18d41a665849a1e8,reason=Completed count=1 msg=Job completed
60.2984,Event,ADDED,eval-sanitize-20-r0-047-lprs4.18d41a636e46d509,reason=Scheduled count=None msg=Successfully assigned compute/eval-sanitize-20-r0-047-lprs4 to kind-worker4
60.2985,Event,ADDED,eval-sanitize-20-r0-047-lprs4.18d41a638c054d8e,"reason=Pulled count=1 msg=Container image ""busybox:musl"" already present on machine"
60.2988,Event,ADDED,eval-sanitize-20-r0-047-lprs4.18d41a638d2c8b4e,reason=Created count=1 msg=Created container: task
60.299,Event,ADDED,eval-sanitize-20-r0-047-lprs4.18d41a63909cb6bc,reason=Started count=1 msg=Started container task
60.2994,Event,ADDED,eval-sanitize-20-r0-047.18d41a63686db2cb,reason=SuccessfulCreate count=1 msg=Created pod: eval-sanitize-20-r0-047-lprs4
60.2997,Event,ADDED,eval-sanitize-20-r0-048-7lhfc.18d41a63f1ceca48,reason=Scheduled count=None msg=Successfully assigned compute/eval-sanitize-20-r0-048-7lhfc to kind-worker3
60.2999,Event,ADDED,eval-sanitize-20-r0-048-7lhfc.18d41a640b0cfc1a,"reason=Pulled count=1 msg=Container image ""busybox:musl"" already present on machine"
60.3002,Event,ADDED,eval-sanitize-20-r0-048-7lhfc.18d41a640c1ce16b,reason=Created count=1 msg=Created container: task
60.3003,Event,ADDED,eval-sanitize-20-r0-048-7lhfc.18d41a640facf689,reason=Started count=1 msg=Started container task
60.3006,Event,ADDED,eval-sanitize-20-r0-048.18d41a63edae521d,reason=SuccessfulCreate count=1 msg=Created pod: eval-sanitize-20-r0-048-7lhfc
60.3008,Event,ADDED,eval-sanitize-20-r0-049-j5lj6.18d41a643cef587d,reason=Scheduled count=None msg=Successfully assigned compute/eval-sanitize-20-r0-049-j5lj6 to kind-worker4
60.301,Event,ADDED,eval-sanitize-20-r0-049-j5lj6.18d41a64581244f0,"reason=Pulled count=1 msg=Container image ""busybox:musl"" already present on machine"
60.3017,Event,ADDED,eval-sanitize-20-r0-049-j5lj6.18d41a64593687a0,reason=Created count=1 msg=Created container: task
60.302,Event,ADDED,eval-sanitize-20-r0-049-j5lj6.18d41a645b2e7ee8,reason=Started count=1 msg=Started container task
60.3022,Event,ADDED,eval-sanitize-20-r0-049.18d41a6438179225,reason=SuccessfulCreate count=1 msg=Created pod: eval-sanitize-20-r0-049-j5lj6
60.3024,Event,ADDED,eval-sanitize-20-r0-050-7ggpc.18d41a6478da79ec,reason=Scheduled count=None msg=Successfully assigned compute/eval-sanitize-20-r0-050-7ggpc to kind-worker5
60.3026,Event,ADDED,eval-sanitize-20-r0-050-7ggpc.18d41a649285bf6c,"reason=Pulled count=1 msg=Container image ""busybox:musl"" already present on machine"
60.3029,Event,ADDED,eval-sanitize-20-r0-050-7ggpc.18d41a64938f355f,reason=Created count=1 msg=Created container: task
60.3031,Event,ADDED,eval-sanitize-20-r0-050-7ggpc.18d41a6498611be8,reason=Started count=1 msg=Started container task
60.3033,Event,ADDED,eval-sanitize-20-r0-050.18d41a6476cfddf7,reason=SuccessfulCreate count=1 msg=Created pod: eval-sanitize-20-r0-050-7ggpc
60.3035,Event,ADDED,eval-sanitize-20-r0-051-88qrg.18d41a64a50bf561,reason=Scheduled count=None msg=Successfully assigned compute/eval-sanitize-20-r0-051-88qrg to kind-worker
60.3037,Event,ADDED,eval-sanitize-20-r0-051-88qrg.18d41a64bed76b80,"reason=Pulled count=1 msg=Container image ""busybox:musl"" already present on machine"
60.3039,Event,ADDED,eval-sanitize-20-r0-051-88qrg.18d41a64c013b5ca,reason=Created count=1 msg=Created container: task
60.3043,Event,ADDED,eval-sanitize-20-r0-051-88qrg.18d41a64c3be4d5d,reason=Started count=1 msg=Started container task
60.3045,Event,ADDED,eval-sanitize-20-r0-051.18d41a64a3b70919,reason=SuccessfulCreate count=1 msg=Created pod: eval-sanitize-20-r0-051-88qrg
60.3047,Event,ADDED,eval-sanitize-20-r0-052-4zhkt.18d41a64e96ae1eb,reason=Scheduled count=None msg=Successfully assigned compute/eval-sanitize-20-r0-052-4zhkt to kind-worker5
60.3049,Event,ADDED,eval-sanitize-20-r0-052-4zhkt.18d41a65030d23ab,"reason=Pulled count=1 msg=Container image ""busybox:musl"" already present on machine"
60.3052,Event,ADDED,eval-sanitize-20-r0-052-4zhkt.18d41a65043fb0fa,reason=Created count=1 msg=Created container: task
60.3054,Event,ADDED,eval-sanitize-20-r0-052-4zhkt.18d41a6506467af1,reason=Started count=1 msg=Started container task
60.3055,Event,ADDED,eval-sanitize-20-r0-052.18d41a64e850f06f,reason=SuccessfulCreate count=1 msg=Created pod: eval-sanitize-20-r0-052-4zhkt
60.3057,Event,ADDED,eval-sanitize-20-r0-053-9pj9s.18d41a65123deb5b,reason=Scheduled count=None msg=Successfully assigned compute/eval-sanitize-20-r0-053-9pj9s to kind-worker
60.3059,Event,ADDED,eval-sanitize-20-r0-053-9pj9s.18d41a652dbbdc7e,"reason=Pulled count=1 msg=Container image ""busybox:musl"" already present on machine"
60.3062,Event,ADDED,eval-sanitize-20-r0-053-9pj9s.18d41a652eda0e36,reason=Created count=1 msg=Created container: task
60.3063,Event,ADDED,eval-sanitize-20-r0-053-9pj9s.18d41a65337fb856,reason=Started count=1 msg=Started container task
60.3066,Event,ADDED,eval-sanitize-20-r0-053.18d41a6511bbaec5,reason=SuccessfulCreate count=1 msg=Created pod: eval-sanitize-20-r0-053-9pj9s
60.3068,Event,ADDED,eval-sanitize-20-r0-054-qhjlr.18d41a6539c28a83,reason=Scheduled count=None msg=Successfully assigned compute/eval-sanitize-20-r0-054-qhjlr to kind-worker
60.307,Event,ADDED,eval-sanitize-20-r0-054-qhjlr.18d41a6553467274,"reason=Pulled count=1 msg=Container image ""busybox:musl"" already present on machine"
60.3072,Event,ADDED,eval-sanitize-20-r0-054-qhjlr.18d41a65555839f3,reason=Created count=1 msg=Created container: task
60.3074,Event,ADDED,eval-sanitize-20-r0-054-qhjlr.18d41a6558fef771,reason=Started count=1 msg=Started container task
60.3076,Event,ADDED,eval-sanitize-20-r0-054.18d41a653948fd4a,reason=SuccessfulCreate count=1 msg=Created pod: eval-sanitize-20-r0-054-qhjlr
60.3078,Event,ADDED,eval-sanitize-20-r0-055-2z5sr.18d41a6562f671d7,"reason=FailedScheduling count=None msg=0/6 nodes are available: 1 c_wall violated: 2 conflicting context pair(s) with node memory, 5 node(s) had untolerated taint(s). no new claims to deallocate, preemption: 0/6 nodes are available: 1 No preemption victims found for incoming pod, 5 Preemption is not helpful for scheduling."
60.3082,Event,ADDED,eval-sanitize-20-r0-055-2z5sr.18d41a65636e323b,"reason=FailedScheduling count=None msg=0/6 nodes are available: 1 c_wall violated: 2 conflicting context pair(s) with node memory, 5 node(s) had untolerated taint(s). no new claims to deallocate, preemption: 0/6 nodes are available: 1 No preemption victims found for incoming pod, 5 Preemption is not helpful for scheduling."
60.3084,Event,ADDED,eval-sanitize-20-r0-055.18d41a6562bae34b,reason=SuccessfulCreate count=1 msg=Created pod: eval-sanitize-20-r0-055-2z5sr
60.3086,Event,ADDED,eval-sanitize-20-r0-056-6bgct.18d41a657d45de91,"reason=FailedScheduling count=None msg=0/6 nodes are available: 1 c_wall violated: 1 conflicting context pair(s) with node memory, 5 node(s) had untolerated taint(s). no new claims to deallocate, preemption: 0/6 nodes are available: 1 No preemption victims found for incoming pod, 5 Preemption is not helpful for scheduling."
60.3089,Event,ADDED,eval-sanitize-20-r0-056-6bgct.18d41a657dd52669,"reason=FailedScheduling count=None msg=0/6 nodes are available: 1 c_wall violated: 1 conflicting context pair(s) with node memory, 5 node(s) had untolerated taint(s). no new claims to deallocate, preemption: 0/6 nodes are available: 1 No preemption victims found for incoming pod, 5 Preemption is not helpful for scheduling."
60.3091,Event,ADDED,eval-sanitize-20-r0-056.18d41a657d0248a3,reason=SuccessfulCreate count=1 msg=Created pod: eval-sanitize-20-r0-056-6bgct
60.3093,Event,ADDED,eval-sanitize-20-r0-057-st55d.18d41a65ad3e36d5,"reason=FailedScheduling count=None msg=0/6 nodes are available: 1 c_wall violated: 1 conflicting context pair(s) with node memory, 5 node(s) had untolerated taint(s). no new claims to deallocate, preemption: 0/6 nodes are available: 1 No preemption victims found for incoming pod, 5 Preemption is not helpful for scheduling."
60.3096,Event,ADDED,eval-sanitize-20-r0-057-st55d.18d41a65adbee167,"reason=FailedScheduling count=None msg=0/6 nodes are available: 1 c_wall violated: 1 conflicting context pair(s) with node memory, 5 node(s) had untolerated taint(s). no new claims to deallocate, preemption: 0/6 nodes are available: 1 No preemption victims found for incoming pod, 5 Preemption is not helpful for scheduling."
60.3098,Event,ADDED,eval-sanitize-20-r0-057.18d41a65ad01325f,reason=SuccessfulCreate count=1 msg=Created pod: eval-sanitize-20-r0-057-st55d
60.31,Event,ADDED,eval-sanitize-20-r0-058-9b88s.18d41a65ec5cb01f,"reason=FailedScheduling count=None msg=0/6 nodes are available: 1 c_wall violated: 3 conflicting context pair(s) with node memory, 5 node(s) had untolerated taint(s). no new claims to deallocate, preemption: 0/6 nodes are available: 1 No preemption victims found for incoming pod, 5 Preemption is not helpful for scheduling."
60.3105,Event,ADDED,eval-sanitize-20-r0-058-9b88s.18d41a65ecea317a,"reason=FailedScheduling count=None msg=0/6 nodes are available: 1 c_wall violated: 3 conflicting context pair(s) with node memory, 5 node(s) had untolerated taint(s). no new claims to deallocate, preemption: 0/6 nodes are available: 1 No preemption victims found for incoming pod, 5 Preemption is not helpful for scheduling."
60.3108,Event,ADDED,eval-sanitize-20-r0-058.18d41a65ec20eac8,reason=SuccessfulCreate count=1 msg=Created pod: eval-sanitize-20-r0-058-9b88s
60.311,Event,ADDED,eval-sanitize-20-r0-059-zqwtk.18d41a6621d924e0,"reason=FailedScheduling count=None msg=0/6 nodes are available: 1 c_wall violated: 1 conflicting context pair(s) with node memory, 5 node(s) had untolerated taint(s). no new claims to deallocate, preemption: 0/6 nodes are available: 1 No preemption victims found for incoming pod, 5 Preemption is not helpful for scheduling."
60.3112,Event,ADDED,eval-sanitize-20-r0-059-zqwtk.18d41a6622683cd3,"reason=FailedScheduling count=None msg=0/6 nodes are available: 1 c_wall violated: 1 conflicting context pair(s) with node memory, 5 node(s) had untolerated taint(s). no new claims to deallocate, preemption: 0/6 nodes are available: 1 No preemption victims found for incoming pod, 5 Preemption is not helpful for scheduling."
60.3115,Event,ADDED,eval-sanitize-20-r0-059.18d41a662195fc62,reason=SuccessfulCreate count=1 msg=Created pod: eval-sanitize-20-r0-059-zqwtk
60.312,Event,ADDED,eval-sanitize-20-r0-060.18d41a665cc16ac2,reason=SuccessfulCreate count=1 msg=Created pod: eval-sanitize-20-r0-060-b7mgm
60.3123,Event,ADDED,eval-sanitize-20-r0-060-b7mgm.18d41a665d140370,"reason=FailedScheduling count=None msg=0/6 nodes are available: 1 c_wall violated: 2 conflicting context pair(s) with node memory, 5 node(s) had untolerated taint(s). no new claims to deallocate, preemption: 0/6 nodes are available: 1 No preemption victims found for incoming pod, 5 Preemption is not helpful for scheduling."
60.3126,Event,ADDED,eval-sanitize-20-r0-060-b7mgm.18d41a665dbc876a,"reason=FailedScheduling count=None msg=0/6 nodes are available: 1 c_wall violated: 2 conflicting context pair(s) with node memory, 5 node(s) had untolerated taint(s). no new claims to deallocate, preemption: 0/6 nodes are available: 1 No preemption victims found for incoming pod, 5 Preemption is not helpful for scheduling."
60.3129,Event,MODIFIED,eval-sanitize-20-r0-060-b7mgm.18d41a665dbc876a,"reason=FailedScheduling count=None msg=0/6 nodes are available: 1 c_wall violated: 2 conflicting context pair(s) with node memory, 5 node(s) had untolerated taint(s). no new claims to deallocate, preemption: 0/6 nodes are available: 1 No preemption victims found for incoming pod, 5 Preemption is not helpful for scheduling."
60.7073,Job,MODIFIED,eval-sanitize-20-r0-047,
60.7155,Pod,MODIFIED,eval-sanitize-20-r0-047-lprs4,phase=Succeeded node=kind-worker4
60.7169,Job,MODIFIED,eval-sanitize-20-r0-047,
61.0245,TaskRequest,ADDED,eval-sanitize-20-r0-061,phase=None job=None
61.0287,TaskRequest,MODIFIED,eval-sanitize-20-r0-061,phase=Pending job=None
61.0437,Job,MODIFIED,eval-sanitize-20-r0-060,
61.0442,Job,ADDED,eval-sanitize-20-r0-061,
61.0503,TaskRequest,MODIFIED,eval-sanitize-20-r0-061,phase=Scheduled job=None
61.0531,Pod,ADDED,eval-sanitize-20-r0-061-g2xd9,phase=Pending node=None
61.0566,Job,MODIFIED,eval-sanitize-20-r0-061,
61.0612,Job,MODIFIED,eval-sanitize-20-r0-060,
61.0613,TaskRequest,MODIFIED,eval-sanitize-20-r0-061,phase=Scheduled job=None
61.0636,Event,ADDED,eval-sanitize-20-r0-061-g2xd9.18d41a669993ae75,"reason=FailedScheduling count=None msg=0/6 nodes are available: 1 c_wall violated: 2 conflicting context pair(s) with node memory, 5 node(s) had untolerated taint(s). no new claims to deallocate, preemption: 0/6 nodes are available: 1 No preemption victims found for incoming pod, 5 Preemption is not helpful for scheduling."
61.0645,Pod,MODIFIED,eval-sanitize-20-r0-061-g2xd9,phase=Pending node=None
61.0649,Event,ADDED,eval-sanitize-20-r0-061.18d41a6699561e61,reason=SuccessfulCreate count=1 msg=Created pod: eval-sanitize-20-r0-061-g2xd9
61.0713,Event,ADDED,eval-sanitize-20-r0-061-g2xd9.18d41a669a3291ff,"reason=FailedScheduling count=None msg=0/6 nodes are available: 1 c_wall violated: 2 conflicting context pair(s) with node memory, 5 node(s) had untolerated taint(s). no new claims to deallocate, preemption: 0/6 nodes are available: 1 No preemption victims found for incoming pod, 5 Preemption is not helpful for scheduling."
61.2796,Job,MODIFIED,eval-sanitize-20-r0-048,
61.2894,Job,MODIFIED,eval-sanitize-20-r0-048,
61.3582,Pod,MODIFIED,eval-sanitize-20-r0-048-7lhfc,phase=Succeeded node=kind-worker3
61.3845,Event,MODIFIED,eval-sanitize-20-r0-061-g2xd9.18d41a669a3291ff,"reason=FailedScheduling count=None msg=0/6 nodes are available: 1 c_wall violated: 2 conflicting context pair(s) with node memory, 5 node(s) had untolerated taint(s). no new claims to deallocate, preemption: 0/6 nodes are available: 1 No preemption victims found for incoming pod, 5 Preemption is not helpful for scheduling."
61.6931,Pod,MODIFIED,eval-sanitize-20-r0-049-j5lj6,phase=Running node=kind-worker4
61.7129,Job,MODIFIED,eval-sanitize-20-r0-047,
61.7171,Job,MODIFIED,eval-sanitize-20-r0-047,
61.7202,Event,ADDED,eval-sanitize-20-r0-047.18d41a66c0e1ec06,reason=Completed count=1 msg=Job completed
61.7289,Job,MODIFIED,eval-sanitize-20-r0-047,
61.7332,TaskRequest,MODIFIED,eval-sanitize-20-r0-047,phase=Complete job=None
61.7416,Job,MODIFIED,eval-sanitize-20-r0-047,
62.0107,TaskRequest,ADDED,eval-sanitize-20-r0-062,phase=None job=None
62.0148,TaskRequest,MODIFIED,eval-sanitize-20-r0-062,phase=Pending job=None
62.032,Job,ADDED,eval-sanitize-20-r0-062,
62.0386,Pod,ADDED,eval-sanitize-20-r0-062-ddt2f,phase=Pending node=None
62.0388,TaskRequest,MODIFIED,eval-sanitize-20-r0-062,phase=Scheduled job=None
62.0417,Job,MODIFIED,eval-sanitize-20-r0-062,
62.044,Event,ADDED,eval-sanitize-20-r0-062.18d41a66d419ead7,reason=SuccessfulCreate count=1 msg=Created pod: eval-sanitize-20-r0-062-ddt2f
62.0458,TaskRequest,MODIFIED,eval-sanitize-20-r0-062,phase=Scheduled job=None
62.0489,Pod,MODIFIED,eval-sanitize-20-r0-062-ddt2f,phase=Pending node=kind-worker
62.0526,Event,ADDED,eval-sanitize-20-r0-062-ddt2f.18d41a66d4a70b2e,reason=Scheduled count=None msg=Successfully assigned compute/eval-sanitize-20-r0-062-ddt2f to kind-worker
62.0584,Job,MODIFIED,eval-sanitize-20-r0-061,
62.0617,Pod,MODIFIED,eval-sanitize-20-r0-062-ddt2f,phase=Pending node=kind-worker
62.0685,Job,MODIFIED,eval-sanitize-20-r0-061,
62.286,Job,MODIFIED,eval-sanitize-20-r0-048,
62.2942,Pod,MODIFIED,eval-sanitize-20-r0-048-7lhfc,phase=Succeeded node=kind-worker3
62.2957,Job,MODIFIED,eval-sanitize-20-r0-048,
62.4858,Event,ADDED,eval-sanitize-20-r0-062-ddt2f.18d41a66ee52283a,"reason=Pulled count=1 msg=Container image ""busybox:musl"" already present on machine"
62.5015,Event,ADDED,eval-sanitize-20-r0-062-ddt2f.18d41a66ef6bd7b9,reason=Created count=1 msg=Created container: task
62.572,Event,ADDED,eval-sanitize-20-r0-062-ddt2f.18d41a66f3977bab,reason=Started count=1 msg=Started container task
62.6982,Job,MODIFIED,eval-sanitize-20-r0-049,
62.71,Job,MODIFIED,eval-sanitize-20-r0-049,
62.8466,Pod,MODIFIED,eval-sanitize-20-r0-050-7ggpc,phase=Running node=kind-worker5
62.8482,Pod,MODIFIED,eval-sanitize-20-r0-049-j5lj6,phase=Succeeded node=kind-worker4
63.0087,TaskRequest,ADDED,eval-sanitize-20-r0-063,phase=None job=None
63.0128,TaskRequest,MODIFIED,eval-sanitize-20-r0-063,phase=Pending job=None
63.0306,Job,ADDED,eval-sanitize-20-r0-063,
63.0378,Pod,ADDED,eval-sanitize-20-r0-063-92bx6,phase=Pending node=None
63.0381,TaskRequest,MODIFIED,eval-sanitize-20-r0-063,phase=Scheduled job=None
63.0409,Job,MODIFIED,eval-sanitize-20-r0-063,
63.0451,Event,ADDED,eval-sanitize-20-r0-063.18d41a670f9c7230,reason=SuccessfulCreate count=1 msg=Created pod: eval-sanitize-20-r0-063-92bx6
63.046,Job,MODIFIED,eval-sanitize-20-r0-062,
63.048,Event,ADDED,eval-sanitize-20-r0-063-92bx6.18d41a670fe82424,"reason=FailedScheduling count=None msg=0/6 nodes are available: 1 c_wall violated: 2 conflicting context pair(s) with node memory, 5 node(s) had untolerated taint(s). no new claims to deallocate, preemption: 0/6 nodes are available: 1 No preemption victims found for incoming pod, 5 Preemption is not helpful for scheduling."
63.0481,TaskRequest,MODIFIED,eval-sanitize-20-r0-063,phase=Scheduled job=None
63.049,Pod,MODIFIED,eval-sanitize-20-r0-063-92bx6,phase=Pending node=None
63.055,Job,MODIFIED,eval-sanitize-20-r0-062,
63.0554,Event,ADDED,eval-sanitize-20-r0-063-92bx6.18d41a67106a106c,"reason=FailedScheduling count=None msg=0/6 nodes are available: 1 c_wall violated: 2 conflicting context pair(s) with node memory, 5 node(s) had untolerated taint(s). no new claims to deallocate, preemption: 0/6 nodes are available: 1 No preemption victims found for incoming pod, 5 Preemption is not helpful for scheduling."
63.2201,Pod,MODIFIED,eval-sanitize-20-r0-062-ddt2f,phase=Running node=kind-worker
63.2282,Pod,MODIFIED,eval-sanitize-20-r0-051-88qrg,phase=Running node=kind-worker
63.2943,Job,MODIFIED,eval-sanitize-20-r0-048,
63.2985,Job,MODIFIED,eval-sanitize-20-r0-048,
63.3017,Event,ADDED,eval-sanitize-20-r0-048.18d41a671f28fc93,reason=Completed count=1 msg=Job completed
63.3092,Event,MODIFIED,eval-sanitize-20-r0-063-92bx6.18d41a67106a106c,"reason=FailedScheduling count=None msg=0/6 nodes are available: 1 c_wall violated: 2 conflicting context pair(s) with node memory, 5 node(s) had untolerated taint(s). no new claims to deallocate, preemption: 0/6 nodes are available: 1 No preemption victims found for incoming pod, 5 Preemption is not helpful for scheduling."
63.3121,Job,MODIFIED,eval-sanitize-20-r0-048,
63.3162,TaskRequest,MODIFIED,eval-sanitize-20-r0-048,phase=Complete job=None
63.328,Job,MODIFIED,eval-sanitize-20-r0-048,
63.7039,Job,MODIFIED,eval-sanitize-20-r0-049,
63.7134,Pod,MODIFIED,eval-sanitize-20-r0-049-j5lj6,phase=Succeeded node=kind-worker4
63.715,Job,MODIFIED,eval-sanitize-20-r0-049,
63.8534,Job,MODIFIED,eval-sanitize-20-r0-050,
63.8642,Job,MODIFIED,eval-sanitize-20-r0-050,
63.9298,Pod,MODIFIED,eval-sanitize-20-r0-050-7ggpc,phase=Succeeded node=kind-worker5
64.0265,TaskRequest,ADDED,eval-sanitize-20-r0-064,phase=None job=None
64.0309,TaskRequest,MODIFIED,eval-sanitize-20-r0-064,phase=Pending job=None
64.0438,Job,MODIFIED,eval-sanitize-20-r0-063,
64.048,Job,ADDED,eval-sanitize-20-r0-064,
64.0501,Job,MODIFIED,eval-sanitize-20-r0-062,
64.0545,Pod,ADDED,eval-sanitize-20-r0-064-sj2r4,phase=Pending node=None
64.0546,TaskRequest,MODIFIED,eval-sanitize-20-r0-064,phase=Scheduled job=None
64.0581,Job,MODIFIED,eval-sanitize-20-r0-064,
64.0603,Event,ADDED,eval-sanitize-20-r0-064.18d41a674c3bc93e,reason=SuccessfulCreate count=1 msg=Created pod: eval-sanitize-20-r0-064-sj2r4
64.0637,Pod,MODIFIED,eval-sanitize-20-r0-064-sj2r4,phase=Pending node=kind-worker
64.0647,TaskRequest,MODIFIED,eval-sanitize-20-r0-064,phase=Scheduled job=None
64.07,Job,MODIFIED,eval-sanitize-20-r0-063,
64.0703,Event,ADDED,eval-sanitize-20-r0-064-sj2r4.18d41a674cbe1c9f,reason=Scheduled count=None msg=Successfully assigned compute/eval-sanitize-20-r0-064-sj2r4 to kind-worker
64.0711,Job,MODIFIED,eval-sanitize-20-r0-062,
64.0752,Pod,MODIFIED,eval-sanitize-20-r0-064-sj2r4,phase=Pending node=kind-worker
64.2351,Job,MODIFIED,eval-sanitize-20-r0-051,
64.2454,Job,MODIFIED,eval-sanitize-20-r0-051,
64.3703,Pod,MODIFIED,eval-sanitize-20-r0-051-88qrg,phase=Succeeded node=kind-worker
64.4878,Event,ADDED,eval-sanitize-20-r0-064-sj2r4.18d41a6765c1ce0d,"reason=Pulled count=1 msg=Container image ""busybox:musl"" already present on machine"
64.5062,Event,ADDED,eval-sanitize-20-r0-064-sj2r4.18d41a6766e0b2eb,reason=Created count=1 msg=Created container: task
64.5418,Event,ADDED,eval-sanitize-20-r0-064-sj2r4.18d41a6768f43cb6,reason=Started count=1 msg=Started container task
64.7128,Job,MODIFIED,eval-sanitize-20-r0-049,
64.7171,Job,MODIFIED,eval-sanitize-20-r0-049,
64.7199,Event,ADDED,eval-sanitize-20-r0-049.18d41a6773b6d1f3,reason=Completed count=1 msg=Job completed
64.7289,Job,MODIFIED,eval-sanitize-20-r0-049,
64.7333,TaskRequest,MODIFIED,eval-sanitize-20-r0-049,phase=Complete job=None
64.7434,Job,MODIFIED,eval-sanitize-20-r0-049,
64.8545,Pod,MODIFIED,eval-sanitize-20-r0-052-4zhkt,phase=Running node=kind-worker5
64.8597,Job,MODIFIED,eval-sanitize-20-r0-050,
64.8686,Pod,MODIFIED,eval-sanitize-20-r0-050-7ggpc,phase=Succeeded node=kind-worker5
64.8702,Job,MODIFIED,eval-sanitize-20-r0-050,
65.0085,TaskRequest,ADDED,eval-sanitize-20-r0-065,phase=None job=None
65.0128,TaskRequest,MODIFIED,eval-sanitize-20-r0-065,phase=Pending job=None
65.0293,Job,ADDED,eval-sanitize-20-r0-065,
65.0367,Pod,ADDED,eval-sanitize-20-r0-065-pjdh6,phase=Pending node=None
65.0368,TaskRequest,MODIFIED,eval-sanitize-20-r0-065,phase=Scheduled job=None
65.0389,Job,MODIFIED,eval-sanitize-20-r0-065,
65.0411,Event,ADDED,eval-sanitize-20-r0-065.18d41a6786b86c0e,reason=SuccessfulCreate count=1 msg=Created pod: eval-sanitize-20-r0-065-pjdh6
65.0442,TaskRequest,MODIFIED,eval-sanitize-20-r0-065,phase=Scheduled job=None
65.0464,Event,ADDED,eval-sanitize-20-r0-065-pjdh6.18d41a67870582d8,"reason=FailedScheduling count=None msg=0/6 nodes are available: 1 c_wall violated: 3 conflicting context pair(s) with node memory, 5 node(s) had untolerated taint(s). no new claims to deallocate, preemption: 0/6 nodes are available: 1 No preemption victims found for incoming pod, 5 Preemption is not helpful for scheduling."
65.0476,Pod,MODIFIED,eval-sanitize-20-r0-065-pjdh6,phase=Pending node=None
65.0538,Event,ADDED,eval-sanitize-20-r0-065-pjdh6.18d41a678792ff18,"reason=FailedScheduling count=None msg=0/6 nodes are available: 1 c_wall violated: 3 conflicting context pair(s) with node memory, 5 node(s) had untolerated taint(s). no new claims to deallocate, preemption: 0/6 nodes are available: 1 No preemption victims found for incoming pod, 5 Preemption is not helpful for scheduling."
65.0598,Job,MODIFIED,eval-sanitize-20-r0-064,
65.0701,Job,MODIFIED,eval-sanitize-20-r0-064,
65.2299,Pod,MODIFIED,eval-sanitize-20-r0-053-9pj9s,phase=Running node=kind-worker
65.2369,Pod,MODIFIED,eval-sanitize-20-r0-064-sj2r4,phase=Running node=kind-worker
65.2402,Job,MODIFIED,eval-sanitize-20-r0-051,
65.2494,Pod,MODIFIED,eval-sanitize-20-r0-051-88qrg,phase=Succeeded node=kind-worker
65.251,Job,MODIFIED,eval-sanitize-20-r0-051,
65.3118,Event,MODIFIED,eval-sanitize-20-r0-065-pjdh6.18d41a678792ff18,"reason=FailedScheduling count=None msg=0/6 nodes are available: 1 c_wall violated: 3 conflicting context pair(s) with node memory, 5 node(s) had untolerated taint(s). no new claims to deallocate, preemption: 0/6 nodes are available: 1 No preemption victims found for incoming pod, 5 Preemption is not helpful for scheduling."
65.8626,Job,MODIFIED,eval-sanitize-20-r0-052,
65.8652,Job,MODIFIED,eval-sanitize-20-r0-050,
65.8747,Job,MODIFIED,eval-sanitize-20-r0-050,
65.876,Job,MODIFIED,eval-sanitize-20-r0-052,
65.8799,Event,ADDED,eval-sanitize-20-r0-050.18d41a67b8ab1169,reason=Completed count=1 msg=Job completed
65.8866,Job,MODIFIED,eval-sanitize-20-r0-050,
65.8927,TaskRequest,MODIFIED,eval-sanitize-20-r0-050,phase=Complete job=None
65.9042,Job,MODIFIED,eval-sanitize-20-r0-050,
66.0081,TaskRequest,ADDED,eval-sanitize-20-r0-066,phase=None job=None
66.0118,Pod,MODIFIED,eval-sanitize-20-r0-052-4zhkt,phase=Succeeded node=kind-worker5
66.0123,TaskRequest,MODIFIED,eval-sanitize-20-r0-066,phase=Pending job=None
66.0331,Job,ADDED,eval-sanitize-20-r0-066,
66.0417,Pod,ADDED,eval-sanitize-20-r0-066-45hlb,phase=Pending node=None
66.0427,TaskRequest,MODIFIED,eval-sanitize-20-r0-066,phase=Scheduled job=None
66.0437,Job,MODIFIED,eval-sanitize-20-r0-065,
66.0452,Job,MODIFIED,eval-sanitize-20-r0-066,
66.0467,Event,ADDED,eval-sanitize-20-r0-066.18d41a67c2a8f5ff,reason=SuccessfulCreate count=1 msg=Created pod: eval-sanitize-20-r0-066-45hlb
66.0519,TaskRequest,MODIFIED,eval-sanitize-20-r0-066,phase=Scheduled job=None
66.055,Job,MODIFIED,eval-sanitize-20-r0-065,
66.0648,Job,MODIFIED,eval-sanitize-20-r0-064,
66.0739,Job,MODIFIED,eval-sanitize-20-r0-064,
66.1136,Pod,MODIFIED,eval-sanitize-20-r0-066-45hlb,phase=Pending node=None
66.1152,Event,ADDED,eval-sanitize-20-r0-066-45hlb.18d41a67c6a4d22b,"reason=FailedScheduling count=None msg=0/6 nodes are available: 1 c_wall violated: 2 conflicting context pair(s) with node memory, 5 node(s) had untolerated taint(s). no new claims to deallocate, preemption: 0/6 nodes are available: 1 No preemption victims found for incoming pod, 5 Preemption is not helpful for scheduling."
66.1239,Event,ADDED,eval-sanitize-20-r0-066-45hlb.18d41a67c750d9f5,"reason=FailedScheduling count=None msg=0/6 nodes are available: 1 c_wall violated: 2 conflicting context pair(s) with node memory, 5 node(s) had untolerated taint(s). no new claims to deallocate, preemption: 0/6 nodes are available: 1 No preemption victims found for incoming pod, 5 Preemption is not helpful for scheduling."
66.2335,Pod,MODIFIED,eval-sanitize-20-r0-054-qhjlr,phase=Running node=kind-worker
66.2345,Job,MODIFIED,eval-sanitize-20-r0-053,
66.2447,Job,MODIFIED,eval-sanitize-20-r0-053,
66.2493,Job,MODIFIED,eval-sanitize-20-r0-051,
66.2552,Job,MODIFIED,eval-sanitize-20-r0-051,
66.2595,Event,ADDED,eval-sanitize-20-r0-051.18d41a67cf61a08d,reason=Completed count=1 msg=Job completed
66.2658,Job,MODIFIED,eval-sanitize-20-r0-051,
66.2704,TaskRequest,MODIFIED,eval-sanitize-20-r0-051,phase=Complete job=None
66.2795,Job,MODIFIED,eval-sanitize-20-r0-051,
66.3479,Event,MODIFIED,eval-sanitize-20-r0-066-45hlb.18d41a67c750d9f5,"reason=FailedScheduling count=None msg=0/6 nodes are available: 1 c_wall violated: 2 conflicting context pair(s) with node memory, 5 node(s) had untolerated taint(s). no new claims to deallocate, preemption: 0/6 nodes are available: 1 No preemption victims found for incoming pod, 5 Preemption is not helpful for scheduling."
66.3629,Pod,MODIFIED,eval-sanitize-20-r0-053-9pj9s,phase=Succeeded node=kind-worker
66.8706,Job,MODIFIED,eval-sanitize-20-r0-052,
66.8785,Pod,MODIFIED,eval-sanitize-20-r0-052-4zhkt,phase=Succeeded node=kind-worker5
66.8798,Job,MODIFIED,eval-sanitize-20-r0-052,
67.0074,TaskRequest,ADDED,eval-sanitize-20-r0-067,phase=None job=None
67.0126,TaskRequest,MODIFIED,eval-sanitize-20-r0-067,phase=Pending job=None
67.0302,Job,ADDED,eval-sanitize-20-r0-067,
67.036,Pod,ADDED,eval-sanitize-20-r0-067-vqk69,phase=Pending node=None
67.0365,TaskRequest,MODIFIED,eval-sanitize-20-r0-067,phase=Scheduled job=None
67.0388,Job,MODIFIED,eval-sanitize-20-r0-067,
67.0402,Event,ADDED,eval-sanitize-20-r0-067.18d41a67fdd16ce1,reason=SuccessfulCreate count=1 msg=Created pod: eval-sanitize-20-r0-067-vqk69
67.0448,Pod,MODIFIED,eval-sanitize-20-r0-067-vqk69,phase=Pending node=None
67.0462,Event,ADDED,eval-sanitize-20-r0-067-vqk69.18d41a67fe1323b0,"reason=FailedScheduling count=None msg=0/6 nodes are available: 1 c_wall violated: 3 conflicting context pair(s) with node memory, 5 node(s) had untolerated taint(s). no new claims to deallocate, preemption: 0/6 nodes are available: 1 No preemption victims found for incoming pod, 5 Preemption is not helpful for scheduling."
67.0463,TaskRequest,MODIFIED,eval-sanitize-20-r0-067,phase=Scheduled job=None
67.0472,Job,MODIFIED,eval-sanitize-20-r0-066,
67.048,Job,MODIFIED,eval-sanitize-20-r0-067,
67.0526,Event,ADDED,eval-sanitize-20-r0-067-vqk69.18d41a67fe9a8603,"reason=FailedScheduling count=None msg=0/6 nodes are available: 1 c_wall violated: 3 conflicting context pair(s) with node memory, 5 node(s) had untolerated taint(s). no new claims to deallocate, preemption: 0/6 nodes are available: 1 No preemption victims found for incoming pod, 5 Preemption is not helpful for scheduling."
67.0579,Job,MODIFIED,eval-sanitize-20-r0-066,
67.0598,Job,MODIFIED,eval-sanitize-20-r0-067,
67.2426,Job,MODIFIED,eval-sanitize-20-r0-054,
67.2448,Job,MODIFIED,eval-sanitize-20-r0-053,
67.2536,Job,MODIFIED,eval-sanitize-20-r0-054,
67.2564,Job,MODIFIED,eval-sanitize-20-r0-053,
67.258,Pod,MODIFIED,eval-sanitize-20-r0-053-9pj9s,phase=Succeeded node=kind-worker
67.3313,Pod,MODIFIED,eval-sanitize-20-r0-054-qhjlr,phase=Succeeded node=kind-worker
67.4432,Event,MODIFIED,eval-sanitize-20-r0-067-vqk69.18d41a67fe9a8603,"reason=FailedScheduling count=None msg=0/6 nodes are available: 1 c_wall violated: 3 conflicting context pair(s) with node memory, 5 node(s) had untolerated taint(s). no new claims to deallocate, preemption: 0/6 nodes are available: 1 No preemption victims found for incoming pod, 5 Preemption is not helpful for scheduling."
67.8777,Job,MODIFIED,eval-sanitize-20-r0-052,
67.8815,Job,MODIFIED,eval-sanitize-20-r0-052,
67.8856,Event,ADDED,eval-sanitize-20-r0-052.18d41a68303ee179,reason=Completed count=1 msg=Job completed
67.8917,Job,MODIFIED,eval-sanitize-20-r0-052,
67.8961,TaskRequest,MODIFIED,eval-sanitize-20-r0-052,phase=Complete job=None
67.9049,Job,MODIFIED,eval-sanitize-20-r0-052,
68.0084,TaskRequest,ADDED,eval-sanitize-20-r0-068,phase=None job=None
68.014,TaskRequest,MODIFIED,eval-sanitize-20-r0-068,phase=Pending job=None
68.0303,Job,ADDED,eval-sanitize-20-r0-068,
68.0376,Pod,ADDED,eval-sanitize-20-r0-068-4cgl6,phase=Pending node=None
68.0377,TaskRequest,MODIFIED,eval-sanitize-20-r0-068,phase=Scheduled job=None
68.0424,Job,MODIFIED,eval-sanitize-20-r0-068,
68.0436,Event,ADDED,eval-sanitize-20-r0-068.18d41a6839845fd6,reason=SuccessfulCreate count=1 msg=Created pod: eval-sanitize-20-r0-068-4cgl6
68.0472,Pod,MODIFIED,eval-sanitize-20-r0-068-4cgl6,phase=Pending node=None
68.0476,Event,ADDED,eval-sanitize-20-r0-068-4cgl6.18d41a6839cbcbbe,"reason=FailedScheduling count=None msg=0/6 nodes are available: 1 c_wall violated: 1 conflicting context pair(s) with node memory, 5 node(s) had untolerated taint(s). no new claims to deallocate, preemption: 0/6 nodes are available: 1 No preemption victims found for incoming pod, 5 Preemption is not helpful for scheduling."
68.0477,TaskRequest,MODIFIED,eval-sanitize-20-r0-068,phase=Scheduled job=None
68.0561,Event,ADDED,eval-sanitize-20-r0-068-4cgl6.18d41a683a507359,"reason=FailedScheduling count=None msg=0/6 nodes are available: 1 c_wall violated: 1 conflicting context pair(s) with node memory, 5 node(s) had untolerated taint(s). no new claims to deallocate, preemption: 0/6 nodes are available: 1 No preemption victims found for incoming pod, 5 Preemption is not helpful for scheduling."
68.2465,Job,MODIFIED,eval-sanitize-20-r0-054,
68.2501,Job,MODIFIED,eval-sanitize-20-r0-053,
68.2541,Job,MODIFIED,eval-sanitize-20-r0-053,
68.2566,Job,MODIFIED,eval-sanitize-20-r0-054,
68.2581,Pod,MODIFIED,eval-sanitize-20-r0-054-qhjlr,phase=Succeeded node=kind-worker
68.2607,Event,ADDED,eval-sanitize-20-r0-053.18d41a68467620b1,reason=Completed count=1 msg=Job completed
68.268,Job,MODIFIED,eval-sanitize-20-r0-053,
68.2724,TaskRequest,MODIFIED,eval-sanitize-20-r0-053,phase=Complete job=None
68.2819,Job,MODIFIED,eval-sanitize-20-r0-053,
69.0146,TaskRequest,ADDED,eval-sanitize-20-r0-069,phase=None job=None
69.0205,TaskRequest,MODIFIED,eval-sanitize-20-r0-069,phase=Pending job=None
69.0367,Job,ADDED,eval-sanitize-20-r0-069,
69.0428,Job,MODIFIED,eval-sanitize-20-r0-068,
69.0444,TaskRequest,MODIFIED,eval-sanitize-20-r0-069,phase=Scheduled job=None
69.0456,Pod,ADDED,eval-sanitize-20-r0-069-sggsm,phase=Pending node=None
69.0478,Job,MODIFIED,eval-sanitize-20-r0-069,
69.0513,Event,ADDED,eval-sanitize-20-r0-069.18d41a68759d9d57,reason=SuccessfulCreate count=1 msg=Created pod: eval-sanitize-20-r0-069-sggsm
69.0531,TaskRequest,MODIFIED,eval-sanitize-20-r0-069,phase=Scheduled job=None
69.0556,Event,ADDED,eval-sanitize-20-r0-069-sggsm.18d41a6875e8278a,"reason=FailedScheduling count=None msg=0/6 nodes are available: 1 c_wall violated: 3 conflicting context pair(s) with node memory, 5 node(s) had untolerated taint(s). no new claims to deallocate, preemption: 0/6 nodes are available: 1 No preemption victims found for incoming pod, 5 Preemption is not helpful for scheduling."
69.0565,Pod,MODIFIED,eval-sanitize-20-r0-069-sggsm,phase=Pending node=None
69.0572,Job,MODIFIED,eval-sanitize-20-r0-068,
69.0636,Event,ADDED,eval-sanitize-20-r0-069-sggsm.18d41a68767f4b4d,"reason=FailedScheduling count=None msg=0/6 nodes are available: 1 c_wall violated: 3 conflicting context pair(s) with node memory, 5 node(s) had untolerated taint(s). no new claims to deallocate, preemption: 0/6 nodes are available: 1 No preemption victims found for incoming pod, 5 Preemption is not helpful for scheduling."
69.2525,Job,MODIFIED,eval-sanitize-20-r0-054,
69.2579,Job,MODIFIED,eval-sanitize-20-r0-054,
69.2622,Event,ADDED,eval-sanitize-20-r0-054.18d41a688243579d,reason=Completed count=1 msg=Job completed
69.2697,Job,MODIFIED,eval-sanitize-20-r0-054,
69.2753,TaskRequest,MODIFIED,eval-sanitize-20-r0-054,phase=Complete job=None
69.2852,Job,MODIFIED,eval-sanitize-20-r0-054,
70.0104,TaskRequest,ADDED,eval-sanitize-20-r0-070,phase=None job=None
70.0147,TaskRequest,MODIFIED,eval-sanitize-20-r0-070,phase=Pending job=None
70.0307,Job,ADDED,eval-sanitize-20-r0-070,
70.0381,Pod,ADDED,eval-sanitize-20-r0-070-wshfr,phase=Pending node=None
70.0383,TaskRequest,MODIFIED,eval-sanitize-20-r0-070,phase=Scheduled job=None
70.0414,Job,MODIFIED,eval-sanitize-20-r0-070,
70.0431,Event,ADDED,eval-sanitize-20-r0-070.18d41a68b0cbb16b,reason=SuccessfulCreate count=1 msg=Created pod: eval-sanitize-20-r0-070-wshfr
70.0458,TaskRequest,MODIFIED,eval-sanitize-20-r0-070,phase=Scheduled job=None
70.0468,Pod,MODIFIED,eval-sanitize-20-r0-070-wshfr,phase=Pending node=kind-worker
70.0498,Job,MODIFIED,eval-sanitize-20-r0-069,
70.0502,Event,ADDED,eval-sanitize-20-r0-070-wshfr.18d41a68b14c52c1,reason=Scheduled count=None msg=Successfully assigned compute/eval-sanitize-20-r0-070-wshfr to kind-worker
70.0592,Pod,MODIFIED,eval-sanitize-20-r0-070-wshfr,phase=Pending node=kind-worker
70.0607,Job,MODIFIED,eval-sanitize-20-r0-069,
70.1564,Event,MODIFIED,eval-sanitize-20-r0-068-4cgl6.18d41a683a507359,"reason=FailedScheduling count=None msg=0/6 nodes are available: 1 c_wall violated: 1 conflicting context pair(s) with node memory, 5 node(s) had untolerated taint(s). no new claims to deallocate, preemption: 0/6 nodes are available: 1 No preemption victims found for incoming pod, 5 Preemption is not helpful for scheduling."
70.1571,Event,MODIFIED,eval-sanitize-20-r0-069-sggsm.18d41a68767f4b4d,"reason=FailedScheduling count=None msg=0/6 nodes are available: 1 c_wall violated: 3 conflicting context pair(s) with node memory, 5 node(s) had untolerated taint(s). no new claims to deallocate, preemption: 0/6 nodes are available: 1 No preemption victims found for incoming pod, 5 Preemption is not helpful for scheduling."
70.4635,Event,ADDED,eval-sanitize-20-r0-070-wshfr.18d41a68c9e9046b,"reason=Pulled count=1 msg=Container image ""busybox:musl"" already present on machine"
70.4843,Event,ADDED,eval-sanitize-20-r0-070-wshfr.18d41a68cb019cf2,reason=Created count=1 msg=Created container: task
70.5148,Event,ADDED,eval-sanitize-20-r0-070-wshfr.18d41a68ccf986b4,reason=Started count=1 msg=Started container task
71.0097,TaskRequest,ADDED,eval-sanitize-20-r0-071,phase=None job=None
71.0141,TaskRequest,MODIFIED,eval-sanitize-20-r0-071,phase=Pending job=None
71.0304,Job,ADDED,eval-sanitize-20-r0-071,
71.0363,Pod,ADDED,eval-sanitize-20-r0-071-zqn8v,phase=Pending node=None
71.0375,TaskRequest,MODIFIED,eval-sanitize-20-r0-071,phase=Scheduled job=None
71.0409,Job,MODIFIED,eval-sanitize-20-r0-071,
71.0414,Event,ADDED,eval-sanitize-20-r0-071.18d41a68ec479cf2,reason=SuccessfulCreate count=1 msg=Created pod: eval-sanitize-20-r0-071-zqn8v
71.0436,Job,MODIFIED,eval-sanitize-20-r0-070,
71.0457,Pod,MODIFIED,eval-sanitize-20-r0-071-zqn8v,phase=Pending node=kind-worker
71.0465,TaskRequest,MODIFIED,eval-sanitize-20-r0-071,phase=Scheduled job=None
71.0498,Event,ADDED,eval-sanitize-20-r0-071-zqn8v.18d41a68ecdacbeb,reason=Scheduled count=None msg=Successfully assigned compute/eval-sanitize-20-r0-071-zqn8v to kind-worker
71.0562,Job,MODIFIED,eval-sanitize-20-r0-070,
71.0615,Pod,MODIFIED,eval-sanitize-20-r0-071-zqn8v,phase=Pending node=kind-worker
71.2519,Pod,MODIFIED,eval-sanitize-20-r0-070-wshfr,phase=Running node=kind-worker
71.4575,Event,ADDED,eval-sanitize-20-r0-071-zqn8v.18d41a69051cb325,"reason=Pulled count=1 msg=Container image ""busybox:musl"" already present on machine"
71.4759,Event,ADDED,eval-sanitize-20-r0-071-zqn8v.18d41a69063e4b98,reason=Created count=1 msg=Created container: task
71.5151,Event,ADDED,eval-sanitize-20-r0-071-zqn8v.18d41a690875d022,reason=Started count=1 msg=Started container task
71.9977,Node,MODIFIED,kind-worker,taints=1
72.0032,Pod,MODIFIED,eval-sanitize-20-r0-063-92bx6,phase=Pending node=None
72.0084,Pod,MODIFIED,eval-sanitize-20-r0-066-45hlb,phase=Pending node=None
72.0093,TaskRequest,ADDED,eval-sanitize-20-r0-072,phase=None job=None
72.0142,Node,MODIFIED,kind-worker,taints=1
72.0155,Pod,MODIFIED,eval-sanitize-20-r0-067-vqk69,phase=Pending node=None
72.0173,TaskRequest,MODIFIED,eval-sanitize-20-r0-072,phase=Pending job=None
72.0211,Pod,MODIFIED,eval-sanitize-20-r0-068-4cgl6,phase=Pending node=None
72.0255,Pod,MODIFIED,eval-sanitize-20-r0-069-sggsm,phase=Pending node=None
72.0353,Pod,MODIFIED,eval-sanitize-20-r0-060-b7mgm,phase=Pending node=None
72.0359,Job,ADDED,eval-sanitize-20-r0-072,
72.0402,Pod,MODIFIED,eval-sanitize-20-r0-061-g2xd9,phase=Pending node=None
72.0417,Job,MODIFIED,eval-sanitize-20-r0-071,
72.044,Pod,ADDED,eval-sanitize-20-r0-072-jnqzb,phase=Pending node=None
72.0441,TaskRequest,MODIFIED,eval-sanitize-20-r0-072,phase=Scheduled job=None
72.0485,Job,MODIFIED,eval-sanitize-20-r0-072,
72.05,Pod,MODIFIED,eval-sanitize-20-r0-055-2z5sr,phase=Pending node=None
72.0504,Event,ADDED,eval-sanitize-20-r0-072.18d41a69285ce7fe,reason=SuccessfulCreate count=1 msg=Created pod: eval-sanitize-20-r0-072-jnqzb
72.0513,Job,MODIFIED,eval-sanitize-20-r0-070,
72.0532,Pod,MODIFIED,eval-sanitize-20-r0-072-jnqzb,phase=Pending node=None
72.0545,Event,ADDED,eval-sanitize-20-r0-072-jnqzb.18d41a69289feba9,"reason=FailedScheduling count=None msg=0/6 nodes are available: 6 node(s) had untolerated taint(s). no new claims to deallocate, preemption: 0/6 nodes are available: 6 Preemption is not helpful for scheduling."
72.0546,TaskRequest,MODIFIED,eval-sanitize-20-r0-072,phase=Scheduled job=None
72.0555,Job,MODIFIED,eval-sanitize-20-r0-071,
72.0584,Pod,MODIFIED,eval-sanitize-20-r0-056-6bgct,phase=Pending node=None
72.0605,Job,MODIFIED,eval-sanitize-20-r0-070,
72.0634,Pod,MODIFIED,eval-sanitize-20-r0-057-st55d,phase=Pending node=None
72.068,Pod,MODIFIED,eval-sanitize-20-r0-058-9b88s,phase=Pending node=None
72.0727,Pod,MODIFIED,eval-sanitize-20-r0-065-pjdh6,phase=Pending node=None
72.0772,Pod,MODIFIED,eval-sanitize-20-r0-059-zqwtk,phase=Pending node=None
72.2523,Pod,MODIFIED,eval-sanitize-20-r0-071-zqn8v,phase=Running node=kind-worker
73.0151,TaskRequest,ADDED,eval-sanitize-20-r0-073,phase=None job=None
73.0224,TaskRequest,MODIFIED,eval-sanitize-20-r0-073,phase=Pending job=None
73.04,Job,ADDED,eval-sanitize-20-r0-073,
73.0467,Pod,ADDED,eval-sanitize-20-r0-073-66xbk,phase=Pending node=None
73.0477,TaskRequest,MODIFIED,eval-sanitize-20-r0-073,phase=Scheduled job=None
73.0487,Job,MODIFIED,eval-sanitize-20-r0-071,
73.0532,Job,MODIFIED,eval-sanitize-20-r0-072,
73.0553,Event,ADDED,eval-sanitize-20-r0-073.18d41a69641965b4,reason=SuccessfulCreate count=1 msg=Created pod: eval-sanitize-20-r0-073-66xbk
73.0555,Event,ADDED,eval-sanitize-20-r0-073-66xbk.18d41a6964249862,"reason=FailedScheduling count=None msg=0/6 nodes are available: 6 node(s) had untolerated taint(s). no new claims to deallocate, preemption: 0/6 nodes are available: 6 Preemption is not helpful for scheduling."
73.0563,Job,MODIFIED,eval-sanitize-20-r0-073,
73.0572,Pod,MODIFIED,eval-sanitize-20-r0-073-66xbk,phase=Pending node=None
73.0582,TaskRequest,MODIFIED,eval-sanitize-20-r0-073,phase=Scheduled job=None
73.061,Job,MODIFIED,eval-sanitize-20-r0-071,
73.0627,Job,MODIFIED,eval-sanitize-20-r0-073,
73.0636,Job,MODIFIED,eval-sanitize-20-r0-072,
73.0739,Job,MODIFIED,eval-sanitize-20-r0-073,
73.2577,Pod,MODIFIED,eval-sanitize-20-r0-062-ddt2f,phase=Running node=kind-worker
73.4944,Node,MODIFIED,kind-worker4,taints=1
73.5073,Node,MODIFIED,kind-worker4,taints=0
73.5129,Pod,MODIFIED,eval-sanitize-20-r0-063-92bx6,phase=Pending node=kind-worker4
73.5161,Pod,MODIFIED,eval-sanitize-20-r0-066-45hlb,phase=Pending node=kind-worker4
73.5198,Event,ADDED,eval-sanitize-20-r0-063-92bx6.18d41a697fe2b3b6,reason=Scheduled count=None msg=Successfully assigned compute/eval-sanitize-20-r0-063-92bx6 to kind-worker4
73.5213,Node,MODIFIED,kind-worker4,taints=0
73.5232,Event,ADDED,eval-sanitize-20-r0-067-vqk69.18d41a697ffeaf2c,"reason=FailedScheduling count=None msg=0/6 nodes are available: 1 c_wall violated: 1 conflicting context pair(s) with node memory, 5 node(s) had untolerated taint(s). no new claims to deallocate, preemption: 0/6 nodes are available: 1 No preemption victims found for incoming pod, 5 Preemption is not helpful for scheduling."
73.5235,Event,ADDED,eval-sanitize-20-r0-066-45hlb.18d41a698019bc5c,reason=Scheduled count=None msg=Successfully assigned compute/eval-sanitize-20-r0-066-45hlb to kind-worker4
73.5244,Pod,MODIFIED,eval-sanitize-20-r0-067-vqk69,phase=Pending node=None
73.5289,Pod,MODIFIED,eval-sanitize-20-r0-063-92bx6,phase=Pending node=kind-worker4
73.532,Pod,MODIFIED,eval-sanitize-20-r0-068-4cgl6,phase=Pending node=None
73.5336,Event,ADDED,eval-sanitize-20-r0-068-4cgl6.18d41a6980ccd83f,"reason=FailedScheduling count=None msg=0/6 nodes are available: 1 c_wall violated: 2 conflicting context pair(s) with node memory, 5 node(s) had untolerated taint(s). no new claims to deallocate, preemption: 0/6 nodes are available: 1 No preemption victims found for incoming pod, 5 Preemption is not helpful for scheduling."
73.5373,Pod,MODIFIED,eval-sanitize-20-r0-066-45hlb,phase=Pending node=kind-worker4
73.5412,Pod,MODIFIED,eval-sanitize-20-r0-069-sggsm,phase=Pending node=kind-worker4
73.5442,Pod,MODIFIED,eval-sanitize-20-r0-060-b7mgm,phase=Pending node=None
73.5488,Event,ADDED,eval-sanitize-20-r0-060-b7mgm.18d41a698181f2e1,"reason=FailedScheduling count=None msg=0/6 nodes are available: 1 c_wall violated: 2 conflicting context pair(s) with node memory, 5 node(s) had untolerated taint(s). no new claims to deallocate, preemption: 0/6 nodes are available: 1 No preemption victims found for incoming pod, 5 Preemption is not helpful for scheduling."
73.5491,Event,ADDED,eval-sanitize-20-r0-069-sggsm.18d41a698197a6d4,reason=Scheduled count=None msg=Successfully assigned compute/eval-sanitize-20-r0-069-sggsm to kind-worker4
73.5506,Node,MODIFIED,kind-worker4,taints=0
73.5562,Pod,MODIFIED,eval-sanitize-20-r0-069-sggsm,phase=Pending node=kind-worker4
73.569,Pod,MODIFIED,eval-sanitize-20-r0-061-g2xd9,phase=Pending node=None
73.5701,Event,ADDED,eval-sanitize-20-r0-061-g2xd9.18d41a69830512d3,"reason=FailedScheduling count=None msg=0/6 nodes are available: 1 c_wall violated: 2 conflicting context pair(s) with node memory, 5 node(s) had untolerated taint(s). no new claims to deallocate, preemption: 0/6 nodes are available: 1 No preemption victims found for incoming pod, 5 Preemption is not helpful for scheduling."
73.5854,Node,MODIFIED,kind-worker4,taints=0
73.5957,Node,MODIFIED,kind-worker4,taints=0
73.6252,Pod,MODIFIED,eval-sanitize-20-r0-055-2z5sr,phase=Pending node=kind-worker4
73.6268,Event,ADDED,eval-sanitize-20-r0-072-jnqzb.18d41a698601ef7c,"reason=FailedScheduling count=None msg=0/6 nodes are available: 1 c_wall violated: 2 conflicting context pair(s) with node memory, 5 node(s) had untolerated taint(s). no new claims to deallocate, preemption: 0/6 nodes are available: 1 No preemption victims found for incoming pod, 5 Preemption is not helpful for scheduling."
73.6279,Pod,MODIFIED,eval-sanitize-20-r0-072-jnqzb,phase=Pending node=None
73.6292,Event,ADDED,eval-sanitize-20-r0-055-2z5sr.18d41a6986971629,reason=Scheduled count=None msg=Successfully assigned compute/eval-sanitize-20-r0-055-2z5sr to kind-worker4
73.6347,Node,MODIFIED,kind-worker4,taints=0
73.6372,Pod,MODIFIED,eval-sanitize-20-r0-055-2z5sr,phase=Pending node=kind-worker4
73.645,Node,MODIFIED,kind-worker4,taints=0
73.7224,Pod,MODIFIED,eval-sanitize-20-r0-056-6bgct,phase=Pending node=None
73.7234,Event,ADDED,eval-sanitize-20-r0-056-6bgct.18d41a698bffdbed,"reason=FailedScheduling count=None msg=0/6 nodes are available: 1 c_wall violated: 2 conflicting context pair(s) with node memory, 5 node(s) had untolerated taint(s). no new claims to deallocate, preemption: 0/6 nodes are available: 1 No preemption victims found for incoming pod, 5 Preemption is not helpful for scheduling."
73.725,Node,MODIFIED,kind-worker4,taints=0
73.732,Pod,MODIFIED,eval-sanitize-20-r0-057-st55d,phase=Pending node=None
73.7323,Event,ADDED,eval-sanitize-20-r0-057-st55d.18d41a698ca2c571,"reason=FailedScheduling count=None msg=0/6 nodes are available: 1 c_wall violated: 3 conflicting context pair(s) with node memory, 5 node(s) had untolerated taint(s). no new claims to deallocate, preemption: 0/6 nodes are available: 1 No preemption victims found for incoming pod, 5 Preemption is not helpful for scheduling."
73.7355,Node,MODIFIED,kind-worker4,taints=0
73.775,Pod,MODIFIED,eval-sanitize-20-r0-058-9b88s,phase=Pending node=kind-worker4
73.7754,Event,ADDED,eval-sanitize-20-r0-065-pjdh6.18d41a698f212453,"reason=FailedScheduling count=None msg=0/6 nodes are available: 1 c_wall violated: 1 conflicting context pair(s) with node memory, 5 node(s) had untolerated taint(s). no new claims to deallocate, preemption: 0/6 nodes are available: 1 No preemption victims found for incoming pod, 5 Preemption is not helpful for scheduling."
73.7767,Pod,MODIFIED,eval-sanitize-20-r0-065-pjdh6,phase=Pending node=None
73.7786,Event,ADDED,eval-sanitize-20-r0-058-9b88s.18d41a698f7e9bbb,reason=Scheduled count=None msg=Successfully assigned compute/eval-sanitize-20-r0-058-9b88s to kind-worker4
73.7845,Pod,MODIFIED,eval-sanitize-20-r0-059-zqwtk,phase=Pending node=None
73.7858,Event,ADDED,eval-sanitize-20-r0-059-zqwtk.18d41a698fcf2dbf,"reason=FailedScheduling count=None msg=0/6 nodes are available: 1 c_wall violated: 3 conflicting context pair(s) with node memory, 5 node(s) had untolerated taint(s). no new claims to deallocate, preemption: 0/6 nodes are available: 1 No preemption victims found for incoming pod, 5 Preemption is not helpful for scheduling."
73.7875,Pod,MODIFIED,eval-sanitize-20-r0-058-9b88s,phase=Pending node=kind-worker4
73.8195,Pod,MODIFIED,eval-sanitize-20-r0-073-66xbk,phase=Pending node=None
73.8198,Event,ADDED,eval-sanitize-20-r0-073-66xbk.18d41a6991bace0f,"reason=FailedScheduling count=None msg=0/6 nodes are available: 1 c_wall violated: 2 conflicting context pair(s) with node memory, 5 node(s) had untolerated taint(s). no new claims to deallocate, preemption: 0/6 nodes are available: 1 No preemption victims found for incoming pod, 5 Preemption is not helpful for scheduling."
73.8269,Event,ADDED,eval-sanitize-20-r0-067-vqk69.18d41a699266457e,"reason=FailedScheduling count=None msg=0/6 nodes are available: 1 c_wall violated: 1 conflicting context pair(s) with node memory, 5 node(s) had untolerated taint(s). no new claims to deallocate, preemption: 0/6 nodes are available: 1 No preemption victims found for incoming pod, 5 Preemption is not helpful for scheduling."
73.8311,Event,ADDED,eval-sanitize-20-r0-068-4cgl6.18d41a6992932b86,"reason=FailedScheduling count=None msg=0/6 nodes are available: 1 c_wall violated: 2 conflicting context pair(s) with node memory, 5 node(s) had untolerated taint(s). no new claims to deallocate, preemption: 0/6 nodes are available: 1 No preemption victims found for incoming pod, 5 Preemption is not helpful for scheduling."
73.8323,Event,ADDED,eval-sanitize-20-r0-060-b7mgm.18d41a6992c0cb73,"reason=FailedScheduling count=None msg=0/6 nodes are available: 1 c_wall violated: 2 conflicting context pair(s) with node memory, 5 node(s) had untolerated taint(s). no new claims to deallocate, preemption: 0/6 nodes are available: 1 No preemption victims found for incoming pod, 5 Preemption is not helpful for scheduling."
73.8354,Event,ADDED,eval-sanitize-20-r0-061-g2xd9.18d41a6992ed5882,"reason=FailedScheduling count=None msg=0/6 nodes are available: 1 c_wall violated: 2 conflicting context pair(s) with node memory, 5 node(s) had untolerated taint(s). no new claims to deallocate, preemption: 0/6 nodes are available: 1 No preemption victims found for incoming pod, 5 Preemption is not helpful for scheduling."
73.844,Event,ADDED,eval-sanitize-20-r0-072-jnqzb.18d41a69934d0267,"reason=FailedScheduling count=None msg=0/6 nodes are available: 1 c_wall violated: 2 conflicting context pair(s) with node memory, 5 node(s) had untolerated taint(s). no new claims to deallocate, preemption: 0/6 nodes are available: 1 No preemption victims found for incoming pod, 5 Preemption is not helpful for scheduling."
73.8477,Event,ADDED,eval-sanitize-20-r0-056-6bgct.18d41a69938e26c3,"reason=FailedScheduling count=None msg=0/6 nodes are available: 1 c_wall violated: 2 conflicting context pair(s) with node memory, 5 node(s) had untolerated taint(s). no new claims to deallocate, preemption: 0/6 nodes are available: 1 No preemption victims found for incoming pod, 5 Preemption is not helpful for scheduling."
73.9098,Event,ADDED,eval-sanitize-20-r0-057-st55d.18d41a699755d747,"reason=FailedScheduling count=None msg=0/6 nodes are available: 1 c_wall violated: 3 conflicting context pair(s) with node memory, 5 node(s) had untolerated taint(s). no new claims to deallocate, preemption: 0/6 nodes are available: 1 No preemption victims found for incoming pod, 5 Preemption is not helpful for scheduling."
73.9207,Event,ADDED,eval-sanitize-20-r0-065-pjdh6.18d41a69978b0704,"reason=FailedScheduling count=None msg=0/6 nodes are available: 1 c_wall violated: 1 conflicting context pair(s) with node memory, 5 node(s) had untolerated taint(s). no new claims to deallocate, preemption: 0/6 nodes are available: 1 No preemption victims found for incoming pod, 5 Preemption is not helpful for scheduling."
73.9233,Event,ADDED,eval-sanitize-20-r0-059-zqwtk.18d41a6997baf7cb,"reason=FailedScheduling count=None msg=0/6 nodes are available: 1 c_wall violated: 3 conflicting context pair(s) with node memory, 5 node(s) had untolerated taint(s). no new claims to deallocate, preemption: 0/6 nodes are available: 1 No preemption victims found for incoming pod, 5 Preemption is not helpful for scheduling."
73.9235,Event,ADDED,eval-sanitize-20-r0-073-66xbk.18d41a6997e8f6e1,"reason=FailedScheduling count=None msg=0/6 nodes are available: 1 c_wall violated: 2 conflicting context pair(s) with node memory, 5 node(s) had untolerated taint(s). no new claims to deallocate, preemption: 0/6 nodes are available: 1 No preemption victims found for incoming pod, 5 Preemption is not helpful for scheduling."
73.9604,Event,ADDED,eval-sanitize-20-r0-063-92bx6.18d41a699a4a27c9,"reason=Pulled count=1 msg=Container image ""busybox:musl"" already present on machine"
73.9649,Event,ADDED,eval-sanitize-20-r0-066-45hlb.18d41a699a6fde0b,"reason=Pulled count=1 msg=Container image ""busybox:musl"" already present on machine"
73.9813,Event,ADDED,eval-sanitize-20-r0-069-sggsm.18d41a699b3e1f97,"reason=Pulled count=1 msg=Container image ""busybox:musl"" already present on machine"
73.9988,Event,ADDED,eval-sanitize-20-r0-063-92bx6.18d41a699c9fe497,reason=Created count=1 msg=Created container: task
74.0057,Event,ADDED,eval-sanitize-20-r0-066-45hlb.18d41a699d09e19a,reason=Created count=1 msg=Created container: task
74.0064,TaskRequest,ADDED,eval-sanitize-20-r0-074,phase=None job=None
74.0116,TaskRequest,MODIFIED,eval-sanitize-20-r0-074,phase=Pending job=None
74.013,Event,ADDED,eval-sanitize-20-r0-069-sggsm.18d41a699d6549ff,reason=Created count=1 msg=Created container: task
74.0285,Job,ADDED,eval-sanitize-20-r0-074,
74.0345,Pod,ADDED,eval-sanitize-20-r0-074-fm9hq,phase=Pending node=None
74.0355,TaskRequest,MODIFIED,eval-sanitize-20-r0-074,phase=Scheduled job=None
74.0385,Job,MODIFIED,eval-sanitize-20-r0-074,
74.0405,Event,ADDED,eval-sanitize-20-r0-074.18d41a699efd6cbb,reason=SuccessfulCreate count=1 msg=Created pod: eval-sanitize-20-r0-074-fm9hq
74.0452,Pod,MODIFIED,eval-sanitize-20-r0-074-fm9hq,phase=Pending node=None
74.0456,Event,ADDED,eval-sanitize-20-r0-074-fm9hq.18d41a699f46b78f,"reason=FailedScheduling count=None msg=0/6 nodes are available: 1 c_wall violated: 1 conflicting context pair(s) with node memory, 5 node(s) had untolerated taint(s). no new claims to deallocate, preemption: 0/6 nodes are available: 1 No preemption victims found for incoming pod, 5 Preemption is not helpful for scheduling."
74.0466,TaskRequest,MODIFIED,eval-sanitize-20-r0-074,phase=Scheduled job=None
74.0532,Event,ADDED,eval-sanitize-20-r0-074-fm9hq.18d41a699fdff57a,"reason=FailedScheduling count=None msg=0/6 nodes are available: 1 c_wall violated: 1 conflicting context pair(s) with node memory, 5 node(s) had untolerated taint(s). no new claims to deallocate, preemption: 0/6 nodes are available: 1 No preemption victims found for incoming pod, 5 Preemption is not helpful for scheduling."
74.0784,Event,ADDED,eval-sanitize-20-r0-055-2z5sr.18d41a69a14b9545,"reason=Pulled count=1 msg=Container image ""busybox:musl"" already present on machine"
74.0862,Event,ADDED,eval-sanitize-20-r0-063-92bx6.18d41a69a1c90b54,reason=Started count=1 msg=Started container task
74.092,Event,ADDED,eval-sanitize-20-r0-066-45hlb.18d41a69a1f7f8f2,reason=Started count=1 msg=Started container task
74.0959,Event,ADDED,eval-sanitize-20-r0-069-sggsm.18d41a69a1fafe88,reason=Started count=1 msg=Started container task
74.1038,Event,ADDED,eval-sanitize-20-r0-055-2z5sr.18d41a69a2e6f998,reason=Created count=1 msg=Created container: task
74.181,Event,ADDED,eval-sanitize-20-r0-055-2z5sr.18d41a69a77607a5,reason=Started count=1 msg=Started container task
74.1889,Event,ADDED,eval-sanitize-20-r0-058-9b88s.18d41a69a7f6e735,"reason=Pulled count=1 msg=Container image ""busybox:musl"" already present on machine"
74.2093,Event,ADDED,eval-sanitize-20-r0-058-9b88s.18d41a69a918dda2,reason=Created count=1 msg=Created container: task
74.2705,Job,MODIFIED,eval-sanitize-20-r0-062,
74.2824,Job,MODIFIED,eval-sanitize-20-r0-062,
74.2922,Node,MODIFIED,kind-worker3,taints=1
74.2926,Event,ADDED,eval-sanitize-20-r0-058-9b88s.18d41a69ae1266f6,reason=Started count=1 msg=Started container task
74.3018,Event,MODIFIED,eval-sanitize-20-r0-067-vqk69.18d41a699266457e,"reason=FailedScheduling count=None msg=0/6 nodes are available: 1 c_wall violated: 1 conflicting context pair(s) with node memory, 5 node(s) had untolerated taint(s). no new claims to deallocate, preemption: 0/6 nodes are available: 1 No preemption victims found for incoming pod, 5 Preemption is not helpful for scheduling."
74.3059,Node,MODIFIED,kind-worker3,taints=1
74.3089,Event,MODIFIED,eval-sanitize-20-r0-068-4cgl6.18d41a6992932b86,"reason=FailedScheduling count=None msg=0/6 nodes are available: 1 c_wall violated: 2 conflicting context pair(s) with node memory, 5 node(s) had untolerated taint(s). no new claims to deallocate, preemption: 0/6 nodes are available: 1 No preemption victims found for incoming pod, 5 Preemption is not helpful for scheduling."
74.3093,Event,MODIFIED,eval-sanitize-20-r0-060-b7mgm.18d41a6992c0cb73,"reason=FailedScheduling count=None msg=0/6 nodes are available: 1 c_wall violated: 2 conflicting context pair(s) with node memory, 5 node(s) had untolerated taint(s). no new claims to deallocate, preemption: 0/6 nodes are available: 1 No preemption victims found for incoming pod, 5 Preemption is not helpful for scheduling."
74.3104,Event,MODIFIED,eval-sanitize-20-r0-061-g2xd9.18d41a6992ed5882,"reason=FailedScheduling count=None msg=0/6 nodes are available: 1 c_wall violated: 2 conflicting context pair(s) with node memory, 5 node(s) had untolerated taint(s). no new claims to deallocate, preemption: 0/6 nodes are available: 1 No preemption victims found for incoming pod, 5 Preemption is not helpful for scheduling."
74.3154,Node,MODIFIED,kind-worker3,taints=0
74.3157,Event,MODIFIED,eval-sanitize-20-r0-072-jnqzb.18d41a69934d0267,"reason=FailedScheduling count=None msg=0/6 nodes are available: 1 c_wall violated: 2 conflicting context pair(s) with node memory, 5 node(s) had untolerated taint(s). no new claims to deallocate, preemption: 0/6 nodes are available: 1 No preemption victims found for incoming pod, 5 Preemption is not helpful for scheduling."
74.3181,Event,MODIFIED,eval-sanitize-20-r0-056-6bgct.18d41a69938e26c3,"reason=FailedScheduling count=None msg=0/6 nodes are available: 1 c_wall violated: 2 conflicting context pair(s) with node memory, 5 node(s) had untolerated taint(s). no new claims to deallocate, preemption: 0/6 nodes are available: 1 No preemption victims found for incoming pod, 5 Preemption is not helpful for scheduling."
74.3478,Event,MODIFIED,eval-sanitize-20-r0-057-st55d.18d41a699755d747,"reason=FailedScheduling count=None msg=0/6 nodes are available: 1 c_wall violated: 3 conflicting context pair(s) with node memory, 5 node(s) had untolerated taint(s). no new claims to deallocate, preemption: 0/6 nodes are available: 1 No preemption victims found for incoming pod, 5 Preemption is not helpful for scheduling."
74.3513,Pod,MODIFIED,eval-sanitize-20-r0-065-pjdh6,phase=Pending node=kind-worker3
74.3543,Event,ADDED,eval-sanitize-20-r0-065-pjdh6.18d41a69b1d7a629,reason=Scheduled count=None msg=Successfully assigned compute/eval-sanitize-20-r0-065-pjdh6 to kind-worker3
74.362,Pod,MODIFIED,eval-sanitize-20-r0-065-pjdh6,phase=Pending node=kind-worker3
74.3748,Node,MODIFIED,kind-worker3,taints=0
74.3856,Node,MODIFIED,kind-worker3,taints=0
74.3961,Node,MODIFIED,kind-worker3,taints=0
74.4116,Pod,MODIFIED,eval-sanitize-20-r0-059-zqwtk,phase=Pending node=kind-worker3
74.414,Pod,MODIFIED,eval-sanitize-20-r0-062-ddt2f,phase=Succeeded node=kind-worker
74.4193,Pod,MODIFIED,eval-sanitize-20-r0-073-66xbk,phase=Pending node=None
74.4212,Event,ADDED,eval-sanitize-20-r0-059-zqwtk.18d41a69b5727579,reason=Scheduled count=None msg=Successfully assigned compute/eval-sanitize-20-r0-059-zqwtk to kind-worker3
74.4215,Event,MODIFIED,eval-sanitize-20-r0-073-66xbk.18d41a6997e8f6e1,"reason=FailedScheduling count=None msg=0/6 nodes are available: 1 c_wall violated: 2 conflicting context pair(s) with node memory, 5 node(s) had untolerated taint(s). no new claims to deallocate, preemption: 0/6 nodes are available: 1 No preemption victims found for incoming pod, 5 Preemption is not helpful for scheduling."
74.4247,Node,MODIFIED,kind-worker3,taints=0
74.4265,Pod,MODIFIED,eval-sanitize-20-r0-059-zqwtk,phase=Pending node=kind-worker3
74.4356,Node,MODIFIED,kind-worker3,taints=0
74.4431,Pod,MODIFIED,eval-sanitize-20-r0-074-fm9hq,phase=Pending node=kind-worker3
74.4473,Pod,MODIFIED,eval-sanitize-20-r0-067-vqk69,phase=Pending node=kind-worker3
74.4489,Event,ADDED,eval-sanitize-20-r0-074-fm9hq.18d41a69b75ece5d,reason=Scheduled count=None msg=Successfully assigned compute/eval-sanitize-20-r0-074-fm9hq to kind-worker3
74.4509,Event,ADDED,eval-sanitize-20-r0-067-vqk69.18d41a69b79c22d1,reason=Scheduled count=None msg=Successfully assigned compute/eval-sanitize-20-r0-067-vqk69 to kind-worker3
74.4548,Pod,MODIFIED,eval-sanitize-20-r0-074-fm9hq,phase=Pending node=kind-worker3
74.4609,Pod,MODIFIED,eval-sanitize-20-r0-067-vqk69,phase=Pending node=kind-worker3
74.5149,Pod,MODIFIED,eval-sanitize-20-r0-068-4cgl6,phase=Pending node=None
74.5607,Pod,MODIFIED,eval-sanitize-20-r0-060-b7mgm,phase=Pending node=kind-worker3
74.5628,Pod,MODIFIED,eval-sanitize-20-r0-061-g2xd9,phase=Pending node=kind-worker3
74.5644,Event,ADDED,eval-sanitize-20-r0-060-b7mgm.18d41a69be5a376e,reason=Scheduled count=None msg=Successfully assigned compute/eval-sanitize-20-r0-060-b7mgm to kind-worker3
74.5663,Event,ADDED,eval-sanitize-20-r0-061-g2xd9.18d41a69be817f78,reason=Scheduled count=None msg=Successfully assigned compute/eval-sanitize-20-r0-061-g2xd9 to kind-worker3
74.5707,Pod,MODIFIED,eval-sanitize-20-r0-060-b7mgm,phase=Pending node=kind-worker3
74.5735,Node,MODIFIED,kind-worker3,taints=0
74.5776,Pod,MODIFIED,eval-sanitize-20-r0-061-g2xd9,phase=Pending node=kind-worker3
74.5834,Node,MODIFIED,kind-worker3,taints=0
74.6143,Pod,MODIFIED,eval-sanitize-20-r0-072-jnqzb,phase=Pending node=None
74.6578,Pod,MODIFIED,eval-sanitize-20-r0-056-6bgct,phase=Pending node=None
74.7106,Pod,MODIFIED,eval-sanitize-20-r0-057-st55d,phase=Pending node=kind-worker3
74.7155,Event,ADDED,eval-sanitize-20-r0-057-st55d.18d41a69c74281ec,reason=Scheduled count=None msg=Successfully assigned compute/eval-sanitize-20-r0-057-st55d to kind-worker3
74.7161,Event,ADDED,eval-sanitize-20-r0-073-66xbk.18d41a69c75601e6,"reason=FailedScheduling count=None msg=0/6 nodes are available: 1 c_wall violated: 1 conflicting context pair(s) with node memory, 1 c_wall violated: 2 conflicting context pair(s) with node memory, 4 node(s) had untolerated taint(s). no new claims to deallocate, preemption: 0/6 nodes are available: 2 No preemption victims found for incoming pod, 4 Preemption is not helpful for scheduling."
74.7222,Pod,MODIFIED,eval-sanitize-20-r0-063-92bx6,phase=Running node=kind-worker4
74.7247,Pod,MODIFIED,eval-sanitize-20-r0-057-st55d,phase=Pending node=kind-worker3
74.7312,Pod,MODIFIED,eval-sanitize-20-r0-058-9b88s,phase=Running node=kind-worker4
74.7387,Pod,MODIFIED,eval-sanitize-20-r0-055-2z5sr,phase=Running node=kind-worker4
74.7478,Pod,MODIFIED,eval-sanitize-20-r0-069-sggsm,phase=Running node=kind-worker4
74.7481,Event,ADDED,eval-sanitize-20-r0-068-4cgl6.18d41a69c91f1702,"reason=FailedScheduling count=None msg=0/6 nodes are available: 1 c_wall violated: 1 conflicting context pair(s) with node memory, 1 c_wall violated: 2 conflicting context pair(s) with node memory, 4 node(s) had untolerated taint(s). no new claims to deallocate, preemption: 0/6 nodes are available: 2 No preemption victims found for incoming pod, 4 Preemption is not helpful for scheduling."
74.7557,Pod,MODIFIED,eval-sanitize-20-r0-066-45hlb,phase=Running node=kind-worker4
74.7835,Job,MODIFIED,eval-sanitize-20-r0-058,
74.7853,Event,ADDED,eval-sanitize-20-r0-065-pjdh6.18d41a69cb2c5016,"reason=Pulled count=1 msg=Container image ""busybox:musl"" already present on machine"
74.7943,Job,MODIFIED,eval-sanitize-20-r0-058,
74.813,Event,ADDED,eval-sanitize-20-r0-072-jnqzb.18d41a69cd2b5796,"reason=FailedScheduling count=None msg=0/6 nodes are available: 2 c_wall violated: 2 conflicting context pair(s) with node memory, 4 node(s) had untolerated taint(s). no new claims to deallocate, preemption: 0/6 nodes are available: 2 No preemption victims found for incoming pod, 4 Preemption is not helpful for scheduling."
74.8298,Event,ADDED,eval-sanitize-20-r0-065-pjdh6.18d41a69cdedbaa5,reason=Created count=1 msg=Created container: task
74.845,Event,ADDED,eval-sanitize-20-r0-056-6bgct.18d41a69cefc6749,"reason=FailedScheduling count=None msg=0/6 nodes are available: 1 c_wall violated: 1 conflicting context pair(s) with node memory, 1 c_wall violated: 2 conflicting context pair(s) with node memory, 4 node(s) had untolerated taint(s). no new claims to deallocate, preemption: 0/6 nodes are available: 2 No preemption victims found for incoming pod, 4 Preemption is not helpful for scheduling."
74.8605,Event,ADDED,eval-sanitize-20-r0-059-zqwtk.18d41a69cff108bc,"reason=Pulled count=1 msg=Container image ""busybox:musl"" already present on machine"
74.8828,Event,ADDED,eval-sanitize-20-r0-065-pjdh6.18d41a69d0ff0da2,reason=Started count=1 msg=Started container task
74.8892,Event,ADDED,eval-sanitize-20-r0-059-zqwtk.18d41a69d174d603,reason=Created count=1 msg=Created container: task
74.8943,Event,ADDED,eval-sanitize-20-r0-074-fm9hq.18d41a69d1c0f8f6,"reason=Pulled count=1 msg=Container image ""busybox:musl"" already present on machine"
74.8995,Event,ADDED,eval-sanitize-20-r0-067-vqk69.18d41a69d1ff2843,"reason=Pulled count=1 msg=Container image ""busybox:musl"" already present on machine"
74.9158,Event,MODIFIED,eval-sanitize-20-r0-073-66xbk.18d41a69c75601e6,"reason=FailedScheduling count=None msg=0/6 nodes are available: 1 c_wall violated: 1 conflicting context pair(s) with node memory, 1 c_wall violated: 2 conflicting context pair(s) with node memory, 4 node(s) had untolerated taint(s). no new claims to deallocate, preemption: 0/6 nodes are available: 2 No preemption victims found for incoming pod, 4 Preemption is not helpful for scheduling."
74.924,Event,ADDED,eval-sanitize-20-r0-067-vqk69.18d41a69d3b9ff46,reason=Created count=1 msg=Created container: task
74.93,Event,ADDED,eval-sanitize-20-r0-074-fm9hq.18d41a69d3efd5a3,reason=Created count=1 msg=Created container: task
74.9513,Event,MODIFIED,eval-sanitize-20-r0-068-4cgl6.18d41a69c91f1702,"reason=FailedScheduling count=None msg=0/6 nodes are available: 1 c_wall violated: 1 conflicting context pair(s) with node memory, 1 c_wall violated: 2 conflicting context pair(s) with node memory, 4 node(s) had untolerated taint(s). no new claims to deallocate, preemption: 0/6 nodes are available: 2 No preemption victims found for incoming pod, 4 Preemption is not helpful for scheduling."
74.9635,Event,ADDED,eval-sanitize-20-r0-059-zqwtk.18d41a69d60fbad4,reason=Started count=1 msg=Started container task
74.9782,Event,ADDED,eval-sanitize-20-r0-067-vqk69.18d41a69d6f3672e,reason=Started count=1 msg=Started container task
74.9836,Event,ADDED,eval-sanitize-20-r0-074-fm9hq.18d41a69d6f4461f,reason=Started count=1 msg=Started container task
75.0134,TaskRequest,ADDED,eval-sanitize-20-r0-075,phase=None job=None
75.0193,Event,MODIFIED,eval-sanitize-20-r0-072-jnqzb.18d41a69cd2b5796,"reason=FailedScheduling count=None msg=0/6 nodes are available: 2 c_wall violated: 2 conflicting context pair(s) with node memory, 4 node(s) had untolerated taint(s). no new claims to deallocate, preemption: 0/6 nodes are available: 2 No preemption victims found for incoming pod, 4 Preemption is not helpful for scheduling."
75.0199,TaskRequest,MODIFIED,eval-sanitize-20-r0-075,phase=Pending job=None
75.0407,Job,ADDED,eval-sanitize-20-r0-075,
75.0423,Job,MODIFIED,eval-sanitize-20-r0-074,
75.0487,Pod,ADDED,eval-sanitize-20-r0-075-6vkpb,phase=Pending node=None
75.0489,TaskRequest,MODIFIED,eval-sanitize-20-r0-075,phase=Scheduled job=None
75.0527,Job,MODIFIED,eval-sanitize-20-r0-075,
75.0606,Event,ADDED,eval-sanitize-20-r0-075.18d41a69db76c8d3,reason=SuccessfulCreate count=1 msg=Created pod: eval-sanitize-20-r0-075-6vkpb
75.0607,TaskRequest,MODIFIED,eval-sanitize-20-r0-075,phase=Scheduled job=None
75.0643,Job,MODIFIED,eval-sanitize-20-r0-074,
75.0691,Event,ADDED,eval-sanitize-20-r0-060-b7mgm.18d41a69dc11c411,"reason=Pulled count=1 msg=Container image ""busybox:musl"" already present on machine"
75.0709,Pod,MODIFIED,eval-sanitize-20-r0-075-6vkpb,phase=Pending node=kind-worker3
75.0783,Event,ADDED,eval-sanitize-20-r0-061-g2xd9.18d41a69dc78b59d,"reason=Pulled count=1 msg=Container image ""busybox:musl"" already present on machine"
75.0796,Event,ADDED,eval-sanitize-20-r0-075-6vkpb.18d41a69dcb9b67b,reason=Scheduled count=None msg=Successfully assigned compute/eval-sanitize-20-r0-075-6vkpb to kind-worker3
75.0862,Pod,MODIFIED,eval-sanitize-20-r0-075-6vkpb,phase=Pending node=kind-worker3
75.0936,Event,ADDED,eval-sanitize-20-r0-060-b7mgm.18d41a69dde2a4f4,reason=Created count=1 msg=Created container: task
75.1059,Event,ADDED,eval-sanitize-20-r0-061-g2xd9.18d41a69de826413,reason=Created count=1 msg=Created container: task
75.1457,Event,MODIFIED,eval-sanitize-20-r0-056-6bgct.18d41a69cefc6749,"reason=FailedScheduling count=None msg=0/6 nodes are available: 1 c_wall violated: 1 conflicting context pair(s) with node memory, 1 c_wall violated: 2 conflicting context pair(s) with node memory, 4 node(s) had untolerated taint(s). no new claims to deallocate, preemption: 0/6 nodes are available: 2 No preemption victims found for incoming pod, 4 Preemption is not helpful for scheduling."
75.1524,Event,ADDED,eval-sanitize-20-r0-060-b7mgm.18d41a69e166d9e7,reason=Started count=1 msg=Started container task
75.1586,Event,ADDED,eval-sanitize-20-r0-061-g2xd9.18d41a69e1ca88b0,reason=Started count=1 msg=Started container task
75.1685,Event,ADDED,eval-sanitize-20-r0-057-st55d.18d41a69e260b7c7,"reason=Pulled count=1 msg=Container image ""busybox:musl"" already present on machine"
75.1911,Event,ADDED,eval-sanitize-20-r0-057-st55d.18d41a69e38be9e1,reason=Created count=1 msg=Created container: task
75.2546,Event,ADDED,eval-sanitize-20-r0-057-st55d.18d41a69e76f89a5,reason=Started count=1 msg=Started container task
75.261,Pod,MODIFIED,eval-sanitize-20-r0-064-sj2r4,phase=Running node=kind-worker
75.2771,Job,MODIFIED,eval-sanitize-20-r0-062,
75.2897,Pod,MODIFIED,eval-sanitize-20-r0-062-ddt2f,phase=Succeeded node=kind-worker
75.291,Job,MODIFIED,eval-sanitize-20-r0-062,
75.3039,Pod,MODIFIED,eval-sanitize-20-r0-061-g2xd9,phase=Running node=kind-worker3
75.3112,Pod,MODIFIED,eval-sanitize-20-r0-057-st55d,phase=Running node=kind-worker3
75.3182,Pod,MODIFIED,eval-sanitize-20-r0-059-zqwtk,phase=Running node=kind-worker3
75.3258,Pod,MODIFIED,eval-sanitize-20-r0-065-pjdh6,phase=Running node=kind-worker3
75.3324,Pod,MODIFIED,eval-sanitize-20-r0-074-fm9hq,phase=Running node=kind-worker3
75.3391,Pod,MODIFIED,eval-sanitize-20-r0-067-vqk69,phase=Running node=kind-worker3
75.3463,Pod,MODIFIED,eval-sanitize-20-r0-060-b7mgm,phase=Running node=kind-worker3
75.5044,Node,MODIFIED,kind-worker2,taints=1
75.5082,Node,MODIFIED,kind-worker5,taints=1
75.5086,Event,ADDED,eval-sanitize-20-r0-075-6vkpb.18d41a69f687a980,"reason=Pulled count=1 msg=Container image ""busybox:musl"" already present on machine"
75.5298,Event,ADDED,eval-sanitize-20-r0-075-6vkpb.18d41a69f7db080a,reason=Created count=1 msg=Created container: task
75.5673,Job,MODIFIED,eval-sanitize-20-r0-060,
75.5786,Job,MODIFIED,eval-sanitize-20-r0-060,
75.584,Job,MODIFIED,eval-sanitize-20-r0-061,
75.592,Node,MODIFIED,kind-worker2,taints=0
75.5953,Node,MODIFIED,kind-worker5,taints=0
75.5971,Job,MODIFIED,eval-sanitize-20-r0-061,
75.6061,Node,MODIFIED,kind-worker2,taints=0
75.6087,Node,MODIFIED,kind-worker5,taints=0
75.6092,Event,ADDED,eval-sanitize-20-r0-075-6vkpb.18d41a69fc8c4d4f,reason=Started count=1 msg=Started container task
75.6687,Pod,MODIFIED,eval-sanitize-20-r0-068-4cgl6,phase=Pending node=kind-worker5
75.6847,Event,ADDED,eval-sanitize-20-r0-068-4cgl6.18d41a6a00645dd9,reason=Scheduled count=None msg=Successfully assigned compute/eval-sanitize-20-r0-068-4cgl6 to kind-worker5
75.6965,Node,MODIFIED,kind-worker5,taints=0
75.6982,Node,MODIFIED,kind-worker2,taints=0
75.6994,Pod,MODIFIED,eval-sanitize-20-r0-068-4cgl6,phase=Pending node=kind-worker5
75.7067,Node,MODIFIED,kind-worker5,taints=0
75.7183,Node,MODIFIED,kind-worker5,taints=0
75.7278,Job,MODIFIED,eval-sanitize-20-r0-063,
75.7391,Job,MODIFIED,eval-sanitize-20-r0-063,
75.7432,Job,MODIFIED,eval-sanitize-20-r0-055,
75.7466,Pod,MODIFIED,eval-sanitize-20-r0-072-jnqzb,phase=Pending node=kind-worker5
75.7538,Job,MODIFIED,eval-sanitize-20-r0-069,
75.756,Event,ADDED,eval-sanitize-20-r0-072-jnqzb.18d41a6a050deb43,reason=Scheduled count=None msg=Successfully assigned compute/eval-sanitize-20-r0-072-jnqzb to kind-worker5
75.7568,Job,MODIFIED,eval-sanitize-20-r0-055,
75.7602,Pod,MODIFIED,eval-sanitize-20-r0-072-jnqzb,phase=Pending node=kind-worker5
75.7619,Node,MODIFIED,kind-worker5,taints=0
75.7627,Job,MODIFIED,eval-sanitize-20-r0-066,
75.7634,Job,MODIFIED,eval-sanitize-20-r0-069,
75.7706,Job,MODIFIED,eval-sanitize-20-r0-066,
75.7826,Node,MODIFIED,kind-worker5,taints=0
75.8295,Pod,MODIFIED,eval-sanitize-20-r0-056-6bgct,phase=Pending node=kind-worker2
75.833,Event,ADDED,eval-sanitize-20-r0-056-6bgct.18d41a6a09f62ff6,reason=Scheduled count=None msg=Successfully assigned compute/eval-sanitize-20-r0-056-6bgct to kind-worker2
75.8431,Node,MODIFIED,kind-worker2,taints=0
75.8446,Pod,MODIFIED,eval-sanitize-20-r0-056-6bgct,phase=Pending node=kind-worker2
75.8539,Node,MODIFIED,kind-worker2,taints=0
75.9141,Pod,MODIFIED,eval-sanitize-20-r0-073-66xbk,phase=Pending node=kind-worker5
75.9187,Event,ADDED,eval-sanitize-20-r0-073-66xbk.18d41a6a0ef891d6,reason=Scheduled count=None msg=Successfully assigned compute/eval-sanitize-20-r0-073-66xbk to kind-worker5
75.9252,Pod,MODIFIED,eval-sanitize-20-r0-073-66xbk,phase=Pending node=kind-worker5
76.0138,TaskRequest,ADDED,eval-sanitize-20-r0-076,phase=None job=None
76.019,TaskRequest,MODIFIED,eval-sanitize-20-r0-076,phase=Pending job=None
76.0375,Job,ADDED,eval-sanitize-20-r0-076,
76.047,Pod,ADDED,eval-sanitize-20-r0-076-v7znd,phase=Pending node=None
76.049,TaskRequest,MODIFIED,eval-sanitize-20-r0-076,phase=Scheduled job=None
76.05,Job,MODIFIED,eval-sanitize-20-r0-074,
76.0514,Job,MODIFIED,eval-sanitize-20-r0-076,
76.0537,Event,ADDED,eval-sanitize-20-r0-076.18d41a6a16e65c2a,reason=SuccessfulCreate count=1 msg=Created pod: eval-sanitize-20-r0-076-v7znd
76.0545,Job,MODIFIED,eval-sanitize-20-r0-075,
76.0597,TaskRequest,MODIFIED,eval-sanitize-20-r0-076,phase=Scheduled job=None
76.0645,Job,MODIFIED,eval-sanitize-20-r0-074,
76.0666,Job,MODIFIED,eval-sanitize-20-r0-075,
76.1085,Event,ADDED,eval-sanitize-20-r0-068-4cgl6.18d41a6a1a465318,"reason=Pulled count=1 msg=Container image ""busybox:musl"" already present on machine"
76.1258,Event,ADDED,eval-sanitize-20-r0-068-4cgl6.18d41a6a1b6785e1,reason=Created count=1 msg=Created container: task
76.145,Pod,MODIFIED,eval-sanitize-20-r0-076-v7znd,phase=Pending node=None
76.1454,Event,ADDED,eval-sanitize-20-r0-076-v7znd.18d41a6a1c5a82b5,"reason=FailedScheduling count=None msg=0/6 nodes are available: 1 c_wall violated: 2 conflicting context pair(s) with node memory, 1 c_wall violated: 3 conflicting context pair(s) with node memory, 2 c_wall violated: 1 conflicting context pair(s) with node memory, 2 node(s) had untolerated taint(s). no new claims to deallocate, preemption: 0/6 nodes are available: 2 Preemption is not helpful for scheduling, 4 No preemption victims found for incoming pod."
76.1458,Event,ADDED,eval-sanitize-20-r0-072-jnqzb.18d41a6a1c9646ec,"reason=Pulled count=1 msg=Container image ""busybox:musl"" already present on machine"
76.1682,Event,ADDED,eval-sanitize-20-r0-068-4cgl6.18d41a6a1dd32516,reason=Started count=1 msg=Started container task
76.1733,Event,ADDED,eval-sanitize-20-r0-072-jnqzb.18d41a6a1e17e0d8,reason=Created count=1 msg=Created container: task
76.244,Event,ADDED,eval-sanitize-20-r0-076-v7znd.18d41a6a2261645a,"reason=FailedScheduling count=None msg=0/6 nodes are available: 1 c_wall violated: 2 conflicting context pair(s) with node memory, 1 c_wall violated: 3 conflicting context pair(s) with node memory, 2 c_wall violated: 1 conflicting context pair(s) with node memory, 2 node(s) had untolerated taint(s). no new claims to deallocate, preemption: 0/6 nodes are available: 2 Preemption is not helpful for scheduling, 4 No preemption victims found for incoming pod."
76.2543,Event,ADDED,eval-sanitize-20-r0-072-jnqzb.18d41a6a231431ab,reason=Started count=1 msg=Started container task
76.2682,Job,MODIFIED,eval-sanitize-20-r0-064,
76.2746,Event,ADDED,eval-sanitize-20-r0-056-6bgct.18d41a6a2446e0b1,"reason=Pulled count=1 msg=Container image ""busybox:musl"" already present on machine"
76.2812,Job,MODIFIED,eval-sanitize-20-r0-064,
76.2863,Job,MODIFIED,eval-sanitize-20-r0-062,
76.2935,Job,MODIFIED,eval-sanitize-20-r0-062,
76.2972,Event,ADDED,eval-sanitize-20-r0-062.18d41a6a25a0ee63,reason=Completed count=1 msg=Job completed
76.3038,Event,ADDED,eval-sanitize-20-r0-056-6bgct.18d41a6a25f34e06,reason=Created count=1 msg=Created container: task
76.3142,Pod,MODIFIED,eval-sanitize-20-r0-075-6vkpb,phase=Running node=kind-worker3
76.3181,Job,MODIFIED,eval-sanitize-20-r0-057,
76.3225,Job,MODIFIED,eval-sanitize-20-r0-059,
76.3319,Job,MODIFIED,eval-sanitize-20-r0-065,
76.3447,Job,MODIFIED,eval-sanitize-20-r0-067,
76.3456,Event,MODIFIED,eval-sanitize-20-r0-076-v7znd.18d41a6a2261645a,"reason=FailedScheduling count=None msg=0/6 nodes are available: 1 c_wall violated: 2 conflicting context pair(s) with node memory, 1 c_wall violated: 3 conflicting context pair(s) with node memory, 2 c_wall violated: 1 conflicting context pair(s) with node memory, 2 node(s) had untolerated taint(s). no new claims to deallocate, preemption: 0/6 nodes are available: 2 Preemption is not helpful for scheduling, 4 No preemption victims found for incoming pod."
76.4098,Job,MODIFIED,eval-sanitize-20-r0-062,
76.4117,Event,ADDED,eval-sanitize-20-r0-056-6bgct.18d41a6a2c7e3535,reason=Started count=1 msg=Started container task
76.4213,Event,ADDED,eval-sanitize-20-r0-073-66xbk.18d41a6a2d03c3c7,"reason=Pulled count=1 msg=Container image ""busybox:musl"" already present on machine"
76.4287,Job,MODIFIED,eval-sanitize-20-r0-057,
76.432,Job,MODIFIED,eval-sanitize-20-r0-059,
76.4326,Job,MODIFIED,eval-sanitize-20-r0-065,
76.4333,Job,MODIFIED,eval-sanitize-20-r0-067,
76.4404,Event,ADDED,eval-sanitize-20-r0-073-66xbk.18d41a6a2e38ec86,reason=Created count=1 msg=Created container: task
76.4499,Pod,MODIFIED,eval-sanitize-20-r0-064-sj2r4,phase=Succeeded node=kind-worker
76.497,TaskRequest,MODIFIED,eval-sanitize-20-r0-062,phase=Complete job=None
76.5047,Event,ADDED,eval-sanitize-20-r0-073-66xbk.18d41a6a31fb3d98,reason=Started count=1 msg=Started container task
76.5072,Job,MODIFIED,eval-sanitize-20-r0-062,
76.888,Pod,MODIFIED,eval-sanitize-20-r0-068-4cgl6,phase=Running node=kind-worker5
76.9006,Pod,MODIFIED,eval-sanitize-20-r0-072-jnqzb,phase=Running node=kind-worker5
76.9027,Pod,MODIFIED,eval-sanitize-20-r0-056-6bgct,phase=Running node=kind-worker2
76.9089,Pod,MODIFIED,eval-sanitize-20-r0-073-66xbk,phase=Running node=kind-worker5
76.9194,Job,MODIFIED,eval-sanitize-20-r0-073,
76.9287,Job,MODIFIED,eval-sanitize-20-r0-073,
77.0139,TaskRequest,ADDED,eval-sanitize-20-r0-077,phase=None job=None
77.02,TaskRequest,MODIFIED,eval-sanitize-20-r0-077,phase=Pending job=None
77.0372,Job,ADDED,eval-sanitize-20-r0-077,
77.0451,Pod,ADDED,eval-sanitize-20-r0-077-qnsfc,phase=Pending node=None
77.0453,TaskRequest,MODIFIED,eval-sanitize-20-r0-077,phase=Scheduled job=None
77.048,Job,MODIFIED,eval-sanitize-20-r0-077,
77.0512,Event,ADDED,eval-sanitize-20-r0-077.18d41a6a52717fd7,reason=SuccessfulCreate count=1 msg=Created pod: eval-sanitize-20-r0-077-qnsfc
77.0521,Job,MODIFIED,eval-sanitize-20-r0-076,
77.0523,TaskRequest,MODIFIED,eval-sanitize-20-r0-077,phase=Scheduled job=None
77.0592,Job,MODIFIED,eval-sanitize-20-r0-075,
77.0611,Job,MODIFIED,eval-sanitize-20-r0-076,
77.0684,Job,MODIFIED,eval-sanitize-20-r0-075,
77.1527,Pod,MODIFIED,eval-sanitize-20-r0-077-qnsfc,phase=Pending node=kind-worker5
77.1566,Event,ADDED,eval-sanitize-20-r0-077-qnsfc.18d41a6a58cb951b,reason=Scheduled count=None msg=Successfully assigned compute/eval-sanitize-20-r0-077-qnsfc to kind-worker5
77.1632,Pod,MODIFIED,eval-sanitize-20-r0-077-qnsfc,phase=Pending node=kind-worker5
77.2849,Job,MODIFIED,eval-sanitize-20-r0-064,
77.2931,Pod,MODIFIED,eval-sanitize-20-r0-064-sj2r4,phase=Succeeded node=kind-worker
77.2945,Job,MODIFIED,eval-sanitize-20-r0-064,
77.5783,Event,ADDED,eval-sanitize-20-r0-077-qnsfc.18d41a6a71fde1df,"reason=Pulled count=1 msg=Container image ""busybox:musl"" already present on machine"
77.5963,Event,ADDED,eval-sanitize-20-r0-077-qnsfc.18d41a6a730fb865,reason=Created count=1 msg=Created container: task
77.6309,Event,ADDED,eval-sanitize-20-r0-077-qnsfc.18d41a6a75259f16,reason=Started count=1 msg=Started container task
77.8982,Pod,MODIFIED,eval-sanitize-20-r0-077-qnsfc,phase=Running node=kind-worker5
77.8996,Job,MODIFIED,eval-sanitize-20-r0-068,
77.9085,Job,MODIFIED,eval-sanitize-20-r0-072,
77.9119,Job,MODIFIED,eval-sanitize-20-r0-056,
77.9132,Job,MODIFIED,eval-sanitize-20-r0-068,
77.9203,Job,MODIFIED,eval-sanitize-20-r0-072,
77.9232,Job,MODIFIED,eval-sanitize-20-r0-056,
78.0323,TaskRequest,ADDED,eval-sanitize-20-r0-078,phase=None job=None
78.0369,TaskRequest,MODIFIED,eval-sanitize-20-r0-078,phase=Pending job=None
78.0511,Job,MODIFIED,eval-sanitize-20-r0-077,
78.0544,Job,ADDED,eval-sanitize-20-r0-078,
78.0613,Pod,ADDED,eval-sanitize-20-r0-078-8kldj,phase=Pending node=None
78.0614,TaskRequest,MODIFIED,eval-sanitize-20-r0-078,phase=Scheduled job=None
78.0652,Job,MODIFIED,eval-sanitize-20-r0-078,
78.0675,Event,ADDED,eval-sanitize-20-r0-078.18d41a6a8f075f0d,reason=SuccessfulCreate count=1 msg=Created pod: eval-sanitize-20-r0-078-8kldj
78.0712,TaskRequest,MODIFIED,eval-sanitize-20-r0-078,phase=Scheduled job=None
78.0747,Job,MODIFIED,eval-sanitize-20-r0-077,
78.1137,Pod,MODIFIED,eval-sanitize-20-r0-078-8kldj,phase=Pending node=kind-worker2
78.1177,Event,ADDED,eval-sanitize-20-r0-078-8kldj.18d41a6a9225fa69,reason=Scheduled count=None msg=Successfully assigned compute/eval-sanitize-20-r0-078-8kldj to kind-worker2
78.1244,Node,MODIFIED,kind-worker2,taints=0
78.127,Pod,MODIFIED,eval-sanitize-20-r0-078-8kldj,phase=Pending node=kind-worker2
78.135,Node,MODIFIED,kind-worker2,taints=0
78.2945,Job,MODIFIED,eval-sanitize-20-r0-064,
78.3001,Job,MODIFIED,eval-sanitize-20-r0-064,
78.3039,Event,ADDED,eval-sanitize-20-r0-064.18d41a6a9d457eec,reason=Completed count=1 msg=Job completed
78.3109,Job,MODIFIED,eval-sanitize-20-r0-064,
78.3157,TaskRequest,MODIFIED,eval-sanitize-20-r0-064,phase=Complete job=None
78.3254,Job,MODIFIED,eval-sanitize-20-r0-064,
78.5532,Event,ADDED,eval-sanitize-20-r0-078-8kldj.18d41a6aac1c5dc6,"reason=Pulled count=1 msg=Container image ""busybox:musl"" already present on machine"
78.5718,Event,ADDED,eval-sanitize-20-r0-078-8kldj.18d41a6aad35b2ab,reason=Created count=1 msg=Created container: task
78.647,Event,ADDED,eval-sanitize-20-r0-078-8kldj.18d41a6ab1a49e7f,reason=Started count=1 msg=Started container task
78.9037,Pod,MODIFIED,eval-sanitize-20-r0-078-8kldj,phase=Running node=kind-worker2
79.0087,TaskRequest,ADDED,eval-sanitize-20-r0-079,phase=None job=None
79.0151,TaskRequest,MODIFIED,eval-sanitize-20-r0-079,phase=Pending job=None
79.0305,Job,ADDED,eval-sanitize-20-r0-079,
79.0387,Pod,ADDED,eval-sanitize-20-r0-079-rj2gc,phase=Pending node=None
79.0388,TaskRequest,MODIFIED,eval-sanitize-20-r0-079,phase=Scheduled job=None
79.0412,Job,MODIFIED,eval-sanitize-20-r0-079,
79.0436,Event,ADDED,eval-sanitize-20-r0-079.18d41a6ac93fcf21,reason=SuccessfulCreate count=1 msg=Created pod: eval-sanitize-20-r0-079-rj2gc
79.0461,TaskRequest,MODIFIED,eval-sanitize-20-r0-079,phase=Scheduled job=None
79.06,Pod,MODIFIED,eval-sanitize-20-r0-079-rj2gc,phase=Pending node=kind-worker5
79.066,Job,MODIFIED,eval-sanitize-20-r0-078,
79.0677,Event,ADDED,eval-sanitize-20-r0-079-rj2gc.18d41a6aca90b784,reason=Scheduled count=None msg=Successfully assigned compute/eval-sanitize-20-r0-079-rj2gc to kind-worker5
79.0722,Node,MODIFIED,kind-worker5,taints=0
79.0737,Pod,MODIFIED,eval-sanitize-20-r0-079-rj2gc,phase=Pending node=kind-worker5
79.0765,Job,MODIFIED,eval-sanitize-20-r0-078,
79.0819,Node,MODIFIED,kind-worker5,taints=0
79.5002,Event,ADDED,eval-sanitize-20-r0-079-rj2gc.18d41a6ae48843eb,"reason=Pulled count=1 msg=Container image ""busybox:musl"" already present on machine"
79.5187,Event,ADDED,eval-sanitize-20-r0-079-rj2gc.18d41a6ae5a4c365,reason=Created count=1 msg=Created container: task
79.5872,Event,ADDED,eval-sanitize-20-r0-079-rj2gc.18d41a6ae9bd8045,reason=Started count=1 msg=Started container task
79.897,Pod,MODIFIED,eval-sanitize-20-r0-079-rj2gc,phase=Running node=kind-worker5
80.0083,TaskRequest,ADDED,eval-sanitize-20-r0-080,phase=None job=None
80.0128,TaskRequest,MODIFIED,eval-sanitize-20-r0-080,phase=Pending job=None
80.0311,Job,ADDED,eval-sanitize-20-r0-080,
80.0361,TaskRequest,MODIFIED,eval-sanitize-20-r0-080,phase=Scheduled job=None
80.0394,Pod,ADDED,eval-sanitize-20-r0-080-lzhjn,phase=Pending node=None
80.0425,Job,MODIFIED,eval-sanitize-20-r0-080,
80.0446,Job,MODIFIED,eval-sanitize-20-r0-079,
80.0463,Event,ADDED,eval-sanitize-20-r0-080.18d41a6b04eef3fb,reason=SuccessfulCreate count=1 msg=Created pod: eval-sanitize-20-r0-080-lzhjn
80.0464,TaskRequest,MODIFIED,eval-sanitize-20-r0-080,phase=Scheduled job=None
80.0555,Job,MODIFIED,eval-sanitize-20-r0-079,
80.1424,Pod,MODIFIED,eval-sanitize-20-r0-080-lzhjn,phase=Pending node=kind-worker4
80.146,Event,ADDED,eval-sanitize-20-r0-080-lzhjn.18d41a6b0b0700cc,reason=Scheduled count=None msg=Successfully assigned compute/eval-sanitize-20-r0-080-lzhjn to kind-worker4
80.1534,Pod,MODIFIED,eval-sanitize-20-r0-080-lzhjn,phase=Pending node=kind-worker4
80.6527,Event,ADDED,eval-sanitize-20-r0-080-lzhjn.18d41a6b29400e85,"reason=Pulled count=1 msg=Container image ""busybox:musl"" already present on machine"
80.6716,Event,ADDED,eval-sanitize-20-r0-080-lzhjn.18d41a6b2a608a94,reason=Created count=1 msg=Created container: task
80.7487,Event,ADDED,eval-sanitize-20-r0-080-lzhjn.18d41a6b2efacc47,reason=Started count=1 msg=Started container task
81.0096,TaskRequest,ADDED,eval-sanitize-20-r0-081,phase=None job=None
81.0139,TaskRequest,MODIFIED,eval-sanitize-20-r0-081,phase=Pending job=None
81.031,Job,ADDED,eval-sanitize-20-r0-081,
81.036,TaskRequest,MODIFIED,eval-sanitize-20-r0-081,phase=Scheduled job=None
81.0399,Pod,ADDED,eval-sanitize-20-r0-081-bpjhg,phase=Pending node=None
81.0416,Job,MODIFIED,eval-sanitize-20-r0-081,
81.0457,Event,ADDED,eval-sanitize-20-r0-081.18d41a6b408acfa7,reason=SuccessfulCreate count=1 msg=Created pod: eval-sanitize-20-r0-081-bpjhg
81.047,Job,MODIFIED,eval-sanitize-20-r0-080,
81.0471,TaskRequest,MODIFIED,eval-sanitize-20-r0-081,phase=Scheduled job=None
81.0581,Job,MODIFIED,eval-sanitize-20-r0-080,
81.0605,Pod,MODIFIED,eval-sanitize-20-r0-081-bpjhg,phase=Pending node=kind-worker4
81.0645,Event,ADDED,eval-sanitize-20-r0-081-bpjhg.18d41a6b41ce01c6,reason=Scheduled count=None msg=Successfully assigned compute/eval-sanitize-20-r0-081-bpjhg to kind-worker4
81.072,Pod,MODIFIED,eval-sanitize-20-r0-081-bpjhg,phase=Pending node=kind-worker4
81.2777,Pod,MODIFIED,eval-sanitize-20-r0-070-wshfr,phase=Running node=kind-worker
81.4875,Event,ADDED,eval-sanitize-20-r0-081-bpjhg.18d41a6b5afd8201,"reason=Pulled count=1 msg=Container image ""busybox:musl"" already present on machine"
81.5069,Event,ADDED,eval-sanitize-20-r0-081-bpjhg.18d41a6b5c187a7b,reason=Created count=1 msg=Created container: task
81.5412,Event,ADDED,eval-sanitize-20-r0-081-bpjhg.18d41a6b5e3742be,reason=Started count=1 msg=Started container task
81.7466,Pod,MODIFIED,eval-sanitize-20-r0-080-lzhjn,phase=Running node=kind-worker4
81.7528,Pod,MODIFIED,eval-sanitize-20-r0-081-bpjhg,phase=Running node=kind-worker4
82.0141,TaskRequest,ADDED,eval-sanitize-20-r0-082,phase=None job=None
82.0196,TaskRequest,MODIFIED,eval-sanitize-20-r0-082,phase=Pending job=None
82.0422,Job,ADDED,eval-sanitize-20-r0-082,
82.048,Job,MODIFIED,eval-sanitize-20-r0-081,
82.0515,Pod,ADDED,eval-sanitize-20-r0-082-75tr7,phase=Pending node=None
82.0517,TaskRequest,MODIFIED,eval-sanitize-20-r0-082,phase=Scheduled job=None
82.0547,Job,MODIFIED,eval-sanitize-20-r0-080,
82.0579,Job,MODIFIED,eval-sanitize-20-r0-082,
82.0583,Event,ADDED,eval-sanitize-20-r0-082.18d41a6b7cd49f64,reason=SuccessfulCreate count=1 msg=Created pod: eval-sanitize-20-r0-082-75tr7
82.0592,TaskRequest,MODIFIED,eval-sanitize-20-r0-082,phase=Scheduled job=None
82.0621,Job,MODIFIED,eval-sanitize-20-r0-081,
82.064,Job,MODIFIED,eval-sanitize-20-r0-080,
82.075,Pod,MODIFIED,eval-sanitize-20-r0-082-75tr7,phase=Pending node=None
82.0755,Event,ADDED,eval-sanitize-20-r0-082-75tr7.18d41a6b7deb42d2,"reason=FailedScheduling count=None msg=0/6 nodes are available: 1 c_wall violated: 2 conflicting context pair(s) with node memory, 1 c_wall violated: 3 conflicting context pair(s) with node memory, 2 c_wall violated: 1 conflicting context pair(s) with node memory, 2 node(s) had untolerated taint(s). no new claims to deallocate, preemption: 0/6 nodes are available: 2 Preemption is not helpful for scheduling, 4 No preemption victims found for incoming pod."
82.1565,Event,ADDED,eval-sanitize-20-r0-082-75tr7.18d41a6b82c2842f,"reason=FailedScheduling count=None msg=0/6 nodes are available: 1 c_wall violated: 2 conflicting context pair(s) with node memory, 1 c_wall violated: 3 conflicting context pair(s) with node memory, 2 c_wall violated: 1 conflicting context pair(s) with node memory, 2 node(s) had untolerated taint(s). no new claims to deallocate, preemption: 0/6 nodes are available: 2 Preemption is not helpful for scheduling, 4 No preemption victims found for incoming pod."
82.282,Pod,MODIFIED,eval-sanitize-20-r0-071-zqn8v,phase=Running node=kind-worker
82.2843,Job,MODIFIED,eval-sanitize-20-r0-070,
82.2961,Job,MODIFIED,eval-sanitize-20-r0-070,
82.3589,Event,MODIFIED,eval-sanitize-20-r0-082-75tr7.18d41a6b82c2842f,"reason=FailedScheduling count=None msg=0/6 nodes are available: 1 c_wall violated: 2 conflicting context pair(s) with node memory, 1 c_wall violated: 3 conflicting context pair(s) with node memory, 2 c_wall violated: 1 conflicting context pair(s) with node memory, 2 node(s) had untolerated taint(s). no new claims to deallocate, preemption: 0/6 nodes are available: 2 Preemption is not helpful for scheduling, 4 No preemption victims found for incoming pod."
82.3822,Pod,MODIFIED,eval-sanitize-20-r0-070-wshfr,phase=Succeeded node=kind-worker
83.0082,TaskRequest,ADDED,eval-sanitize-20-r0-083,phase=None job=None
83.012,TaskRequest,MODIFIED,eval-sanitize-20-r0-083,phase=Pending job=None
83.0308,Job,ADDED,eval-sanitize-20-r0-083,
83.0384,Pod,ADDED,eval-sanitize-20-r0-083-99zmw,phase=Pending node=None
83.0395,TaskRequest,MODIFIED,eval-sanitize-20-r0-083,phase=Scheduled job=None
83.0403,Job,MODIFIED,eval-sanitize-20-r0-083,
83.044,Event,ADDED,eval-sanitize-20-r0-083.18d41a6bb7a703be,reason=SuccessfulCreate count=1 msg=Created pod: eval-sanitize-20-r0-083-99zmw
83.0564,Job,MODIFIED,eval-sanitize-20-r0-082,
83.0654,Job,MODIFIED,eval-sanitize-20-r0-082,
83.1076,TaskRequest,MODIFIED,eval-sanitize-20-r0-083,phase=Scheduled job=None
83.1528,Pod,MODIFIED,eval-sanitize-20-r0-083-99zmw,phase=Pending node=kind-worker2
83.157,Event,ADDED,eval-sanitize-20-r0-083-99zmw.18d41a6bbe7bf087,reason=Scheduled count=None msg=Successfully assigned compute/eval-sanitize-20-r0-083-99zmw to kind-worker2
83.1652,Pod,MODIFIED,eval-sanitize-20-r0-083-99zmw,phase=Pending node=kind-worker2
83.2874,Job,MODIFIED,eval-sanitize-20-r0-071,
83.2891,Job,MODIFIED,eval-sanitize-20-r0-070,
83.2968,Job,MODIFIED,eval-sanitize-20-r0-071,
83.299,Job,MODIFIED,eval-sanitize-20-r0-070,
83.3005,Pod,MODIFIED,eval-sanitize-20-r0-070-wshfr,phase=Succeeded node=kind-worker
83.4751,Pod,MODIFIED,eval-sanitize-20-r0-071-zqn8v,phase=Succeeded node=kind-worker
83.5957,Event,ADDED,eval-sanitize-20-r0-083-99zmw.18d41a6bd891df33,"reason=Pulled count=1 msg=Container image ""busybox:musl"" already present on machine"
83.6124,Event,ADDED,eval-sanitize-20-r0-083-99zmw.18d41a6bd9af99b9,reason=Created count=1 msg=Created container: task
83.647,Event,ADDED,eval-sanitize-20-r0-083-99zmw.18d41a6bdbb1769b,reason=Started count=1 msg=Started container task
83.9177,Pod,MODIFIED,eval-sanitize-20-r0-083-99zmw,phase=Running node=kind-worker2
84.0411,TaskRequest,ADDED,eval-sanitize-20-r0-084,phase=None job=None
84.0442,Job,MODIFIED,eval-sanitize-20-r0-083,
84.045,TaskRequest,MODIFIED,eval-sanitize-20-r0-084,phase=Pending job=None
84.0613,Job,ADDED,eval-sanitize-20-r0-084,
84.0656,TaskRequest,MODIFIED,eval-sanitize-20-r0-084,phase=Scheduled job=None
84.0688,Pod,ADDED,eval-sanitize-20-r0-084-zv84b,phase=Pending node=None
84.072,Job,MODIFIED,eval-sanitize-20-r0-084,
84.076,Event,ADDED,eval-sanitize-20-r0-084.18d41a6bf520238e,reason=SuccessfulCreate count=1 msg=Created pod: eval-sanitize-20-r0-084-zv84b
84.0762,TaskRequest,MODIFIED,eval-sanitize-20-r0-084,phase=Scheduled job=None
84.077,Job,MODIFIED,eval-sanitize-20-r0-083,
84.1167,Pod,MODIFIED,eval-sanitize-20-r0-084-zv84b,phase=Pending node=kind-worker4
84.1196,Event,ADDED,eval-sanitize-20-r0-084-zv84b.18d41a6bf7ecfdb4,reason=Scheduled count=None msg=Successfully assigned compute/eval-sanitize-20-r0-084-zv84b to kind-worker4
84.1263,Pod,MODIFIED,eval-sanitize-20-r0-084-zv84b,phase=Pending node=kind-worker4
84.2944,Job,MODIFIED,eval-sanitize-20-r0-071,
84.2986,Job,MODIFIED,eval-sanitize-20-r0-070,
84.3038,Pod,MODIFIED,eval-sanitize-20-r0-071-zqn8v,phase=Succeeded node=kind-worker
84.3051,Job,MODIFIED,eval-sanitize-20-r0-070,
84.3061,Job,MODIFIED,eval-sanitize-20-r0-071,
84.3148,Event,ADDED,eval-sanitize-20-r0-070.18d41a6c0338f834,reason=Completed count=1 msg=Job completed
84.3232,Job,MODIFIED,eval-sanitize-20-r0-070,
84.3276,TaskRequest,MODIFIED,eval-sanitize-20-r0-070,phase=Complete job=None
84.3377,Job,MODIFIED,eval-sanitize-20-r0-070,
84.5559,Event,ADDED,eval-sanitize-20-r0-084-zv84b.18d41a6c11e677b6,"reason=Pulled count=1 msg=Container image ""busybox:musl"" already present on machine"
84.5743,Event,ADDED,eval-sanitize-20-r0-084-zv84b.18d41a6c1302cb48,reason=Created count=1 msg=Created container: task
84.6123,Event,ADDED,eval-sanitize-20-r0-084-zv84b.18d41a6c151bfe8a,reason=Started count=1 msg=Started container task
84.7893,Pod,MODIFIED,eval-sanitize-20-r0-058-9b88s,phase=Running node=kind-worker4
84.7966,Pod,MODIFIED,eval-sanitize-20-r0-055-2z5sr,phase=Running node=kind-worker4
84.8038,Pod,MODIFIED,eval-sanitize-20-r0-084-zv84b,phase=Running node=kind-worker4
84.8109,Pod,MODIFIED,eval-sanitize-20-r0-069-sggsm,phase=Running node=kind-worker4
84.8173,Pod,MODIFIED,eval-sanitize-20-r0-066-45hlb,phase=Running node=kind-worker4
84.8231,Pod,MODIFIED,eval-sanitize-20-r0-063-92bx6,phase=Running node=kind-worker4
85.0987,TaskRequest,ADDED,eval-sanitize-20-r0-085,phase=None job=None
85.1017,Job,MODIFIED,eval-sanitize-20-r0-084,
85.1029,TaskRequest,MODIFIED,eval-sanitize-20-r0-085,phase=Pending job=None
85.1191,Job,ADDED,eval-sanitize-20-r0-085,
85.1264,Pod,ADDED,eval-sanitize-20-r0-085-4x5bt,phase=Pending node=None
85.1264,TaskRequest,MODIFIED,eval-sanitize-20-r0-085,phase=Scheduled job=None
85.1289,Job,MODIFIED,eval-sanitize-20-r0-085,
85.1317,Event,ADDED,eval-sanitize-20-r0-085.18d41a6c34257e3d,reason=SuccessfulCreate count=1 msg=Created pod: eval-sanitize-20-r0-085-4x5bt
85.1353,TaskRequest,MODIFIED,eval-sanitize-20-r0-085,phase=Scheduled job=None
85.1377,Job,MODIFIED,eval-sanitize-20-r0-084,
85.2474,Pod,MODIFIED,eval-sanitize-20-r0-085-4x5bt,phase=Pending node=kind-worker5
85.2519,Event,ADDED,eval-sanitize-20-r0-085-4x5bt.18d41a6c3b5ba7ab,reason=Scheduled count=None msg=Successfully assigned compute/eval-sanitize-20-r0-085-4x5bt to kind-worker5
85.2596,Pod,MODIFIED,eval-sanitize-20-r0-085-4x5bt,phase=Pending node=kind-worker5
85.3461,Job,MODIFIED,eval-sanitize-20-r0-071,
85.3512,Job,MODIFIED,eval-sanitize-20-r0-071,
85.3538,Pod,MODIFIED,eval-sanitize-20-r0-060-b7mgm,phase=Running node=kind-worker3
85.3576,Event,ADDED,eval-sanitize-20-r0-071.18d41a6c419016bf,reason=Completed count=1 msg=Job completed
85.3637,Pod,MODIFIED,eval-sanitize-20-r0-059-zqwtk,phase=Running node=kind-worker3
85.3665,Job,MODIFIED,eval-sanitize-20-r0-071,
85.3729,Pod,MODIFIED,eval-sanitize-20-r0-065-pjdh6,phase=Running node=kind-worker3
85.373,TaskRequest,MODIFIED,eval-sanitize-20-r0-071,phase=Complete job=None
85.3803,Pod,MODIFIED,eval-sanitize-20-r0-074-fm9hq,phase=Running node=kind-worker3
85.3836,Job,MODIFIED,eval-sanitize-20-r0-071,
85.3864,Pod,MODIFIED,eval-sanitize-20-r0-061-g2xd9,phase=Running node=kind-worker3
85.8123,Job,MODIFIED,eval-sanitize-20-r0-058,
85.8164,Job,MODIFIED,eval-sanitize-20-r0-055,
85.8189,Event,ADDED,eval-sanitize-20-r0-085-4x5bt.18d41a6c5ce9c89c,"reason=Pulled count=1 msg=Container image ""busybox:musl"" already present on machine"
85.8198,Job,MODIFIED,eval-sanitize-20-r0-069,
85.8223,Job,MODIFIED,eval-sanitize-20-r0-058,
85.8246,Job,MODIFIED,eval-sanitize-20-r0-066,
85.8276,Job,MODIFIED,eval-sanitize-20-r0-055,
85.8338,Job,MODIFIED,eval-sanitize-20-r0-063,
85.8348,Job,MODIFIED,eval-sanitize-20-r0-069,
85.8373,Job,MODIFIED,eval-sanitize-20-r0-066,
85.8394,Event,ADDED,eval-sanitize-20-r0-085-4x5bt.18d41a6c5e70922c,reason=Created count=1 msg=Created container: task
85.843,Job,MODIFIED,eval-sanitize-20-r0-063,
85.9818,Event,ADDED,eval-sanitize-20-r0-085-4x5bt.18d41a6c66dc82b9,reason=Started count=1 msg=Started container task
85.9856,Pod,MODIFIED,eval-sanitize-20-r0-055-2z5sr,phase=Succeeded node=kind-worker4
85.9932,Pod,MODIFIED,eval-sanitize-20-r0-058-9b88s,phase=Succeeded node=kind-worker4
86.0037,Pod,MODIFIED,eval-sanitize-20-r0-069-sggsm,phase=Succeeded node=kind-worker4
86.0101,Pod,MODIFIED,eval-sanitize-20-r0-066-45hlb,phase=Succeeded node=kind-worker4
86.0102,TaskRequest,ADDED,eval-sanitize-20-r0-086,phase=None job=None
86.0139,TaskRequest,MODIFIED,eval-sanitize-20-r0-086,phase=Pending job=None
86.0189,Pod,MODIFIED,eval-sanitize-20-r0-063-92bx6,phase=Succeeded node=kind-worker4
86.0325,Job,ADDED,eval-sanitize-20-r0-086,
86.0394,TaskRequest,MODIFIED,eval-sanitize-20-r0-086,phase=Scheduled job=None
86.0414,Pod,ADDED,eval-sanitize-20-r0-086-968c9,phase=Pending node=None
86.0432,Job,MODIFIED,eval-sanitize-20-r0-086,
86.0461,Event,ADDED,eval-sanitize-20-r0-086.18d41a6c6ab1030d,reason=SuccessfulCreate count=1 msg=Created pod: eval-sanitize-20-r0-086-968c9
86.1852,Job,MODIFIED,eval-sanitize-20-r0-085,
86.1854,TaskRequest,MODIFIED,eval-sanitize-20-r0-086,phase=Scheduled job=None
86.1952,Job,MODIFIED,eval-sanitize-20-r0-085,
86.3302,Pod,MODIFIED,eval-sanitize-20-r0-086-968c9,phase=Pending node=kind-worker2
86.3348,Event,ADDED,eval-sanitize-20-r0-086-968c9.18d41a6c7be59576,reason=Scheduled count=None msg=Successfully assigned compute/eval-sanitize-20-r0-086-968c9 to kind-worker2
86.3452,Pod,MODIFIED,eval-sanitize-20-r0-086-968c9,phase=Pending node=kind-worker2
86.3475,Node,MODIFIED,kind-worker2,taints=0
86.3489,Pod,MODIFIED,eval-sanitize-20-r0-057-st55d,phase=Running node=kind-worker3
86.3558,Pod,MODIFIED,eval-sanitize-20-r0-067-vqk69,phase=Running node=kind-worker3
86.358,Node,MODIFIED,kind-worker2,taints=0
86.3592,Job,MODIFIED,eval-sanitize-20-r0-060,
86.3633,Pod,MODIFIED,eval-sanitize-20-r0-075-6vkpb,phase=Running node=kind-worker3
86.3683,Job,MODIFIED,eval-sanitize-20-r0-059,
86.3697,Job,MODIFIED,eval-sanitize-20-r0-060,
86.3776,Job,MODIFIED,eval-sanitize-20-r0-065,
86.38,Job,MODIFIED,eval-sanitize-20-r0-059,
86.3871,Job,MODIFIED,eval-sanitize-20-r0-074,
86.3891,Job,MODIFIED,eval-sanitize-20-r0-065,
86.3912,Job,MODIFIED,eval-sanitize-20-r0-061,
86.3969,Job,MODIFIED,eval-sanitize-20-r0-074,
86.4013,Job,MODIFIED,eval-sanitize-20-r0-061,
86.5894,Pod,MODIFIED,eval-sanitize-20-r0-060-b7mgm,phase=Succeeded node=kind-worker3
86.7057,Pod,MODIFIED,eval-sanitize-20-r0-059-zqwtk,phase=Succeeded node=kind-worker3
86.7131,Pod,MODIFIED,eval-sanitize-20-r0-074-fm9hq,phase=Succeeded node=kind-worker3
86.7198,Pod,MODIFIED,eval-sanitize-20-r0-061-g2xd9,phase=Succeeded node=kind-worker3
86.7325,Pod,MODIFIED,eval-sanitize-20-r0-065-pjdh6,phase=Succeeded node=kind-worker3
86.7522,Event,ADDED,eval-sanitize-20-r0-086-968c9.18d41a6c94cef2c4,"reason=Pulled count=1 msg=Container image ""busybox:musl"" already present on machine"
86.7715,Event,ADDED,eval-sanitize-20-r0-086-968c9.18d41a6c95ea5392,reason=Created count=1 msg=Created container: task
86.8835,Job,MODIFIED,eval-sanitize-20-r0-058,
86.8867,Job,MODIFIED,eval-sanitize-20-r0-055,
86.8886,Job,MODIFIED,eval-sanitize-20-r0-069,
86.8896,Job,MODIFIED,eval-sanitize-20-r0-066,
86.8905,Job,MODIFIED,eval-sanitize-20-r0-063,
86.895,Pod,MODIFIED,eval-sanitize-20-r0-058-9b88s,phase=Succeeded node=kind-worker4
86.9001,Pod,MODIFIED,eval-sanitize-20-r0-066-45hlb,phase=Succeeded node=kind-worker4
86.9013,Job,MODIFIED,eval-sanitize-20-r0-058,
86.9028,Pod,MODIFIED,eval-sanitize-20-r0-063-92bx6,phase=Succeeded node=kind-worker4
86.9049,Pod,MODIFIED,eval-sanitize-20-r0-055-2z5sr,phase=Succeeded node=kind-worker4
86.906,Job,MODIFIED,eval-sanitize-20-r0-055,
86.9064,Event,ADDED,eval-sanitize-20-r0-086-968c9.18d41a6c9db10ad5,reason=Started count=1 msg=Started container task
86.9079,Pod,MODIFIED,eval-sanitize-20-r0-069-sggsm,phase=Succeeded node=kind-worker4
86.9087,Job,MODIFIED,eval-sanitize-20-r0-066,
86.9097,Job,MODIFIED,eval-sanitize-20-r0-063,
86.9101,Event,ADDED,eval-sanitize-20-r0-063.18d41a6c9e3f2089,reason=Completed count=1 msg=Job completed
86.9108,Job,MODIFIED,eval-sanitize-20-r0-069,
86.9136,Pod,MODIFIED,eval-sanitize-20-r0-073-66xbk,phase=Running node=kind-worker5
86.9157,Job,MODIFIED,eval-sanitize-20-r0-063,
86.9161,Event,ADDED,eval-sanitize-20-r0-066.18d41a6c9e427ad6,reason=Completed count=1 msg=Job completed
86.9171,Job,MODIFIED,eval-sanitize-20-r0-066,
86.9217,Pod,MODIFIED,eval-sanitize-20-r0-068-4cgl6,phase=Running node=kind-worker5
86.9241,Pod,MODIFIED,eval-sanitize-20-r0-056-6bgct,phase=Running node=kind-worker2
86.925,TaskRequest,MODIFIED,eval-sanitize-20-r0-063,phase=Complete job=None
86.9293,Pod,MODIFIED,eval-sanitize-20-r0-085-4x5bt,phase=Running node=kind-worker5
86.9323,Pod,MODIFIED,eval-sanitize-20-r0-086-968c9,phase=Running node=kind-worker2
86.933,TaskRequest,MODIFIED,eval-sanitize-20-r0-066,phase=Complete job=None
86.936,Job,MODIFIED,eval-sanitize-20-r0-063,
86.9393,Pod,MODIFIED,eval-sanitize-20-r0-072-jnqzb,phase=Running node=kind-worker5
86.9966,Job,MODIFIED,eval-sanitize-20-r0-066,
87.1026,Job,MODIFIED,eval-sanitize-20-r0-086,
87.1066,TaskRequest,ADDED,eval-sanitize-20-r0-087,phase=None job=None
87.1124,TaskRequest,MODIFIED,eval-sanitize-20-r0-087,phase=Pending job=None
87.1155,Job,MODIFIED,eval-sanitize-20-r0-086,
87.1286,Job,ADDED,eval-sanitize-20-r0-087,
87.1345,Pod,ADDED,eval-sanitize-20-r0-087-dsfdc,phase=Pending node=None
87.1347,TaskRequest,MODIFIED,eval-sanitize-20-r0-087,phase=Scheduled job=None
87.139,Job,MODIFIED,eval-sanitize-20-r0-087,
87.1405,Event,ADDED,eval-sanitize-20-r0-087.18d41a6cabe14f28,reason=SuccessfulCreate count=1 msg=Created pod: eval-sanitize-20-r0-087-dsfdc
87.1426,TaskRequest,MODIFIED,eval-sanitize-20-r0-087,phase=Scheduled job=None
87.1476,Job,MODIFIED,eval-sanitize-20-r0-087,
87.1561,Job,MODIFIED,eval-sanitize-20-r0-087,
87.1912,Job,MODIFIED,eval-sanitize-20-r0-085,
87.201,Job,MODIFIED,eval-sanitize-20-r0-085,
87.3442,Pod,MODIFIED,eval-sanitize-20-r0-087-dsfdc,phase=Pending node=kind-worker4
87.3489,Event,ADDED,eval-sanitize-20-r0-087-dsfdc.18d41a6cb84fb2ac,reason=Scheduled count=None msg=Successfully assigned compute/eval-sanitize-20-r0-087-dsfdc to kind-worker4
87.3556,Job,MODIFIED,eval-sanitize-20-r0-057,
87.3606,Pod,MODIFIED,eval-sanitize-20-r0-087-dsfdc,phase=Pending node=kind-worker4
87.3637,Job,MODIFIED,eval-sanitize-20-r0-067,
87.3665,Job,MODIFIED,eval-sanitize-20-r0-060,
87.3683,Job,MODIFIED,eval-sanitize-20-r0-075,
87.3712,Job,MODIFIED,eval-sanitize-20-r0-057,
87.3736,Job,MODIFIED,eval-sanitize-20-r0-067,
87.3769,Job,MODIFIED,eval-sanitize-20-r0-059,
87.3796,Pod,MODIFIED,eval-sanitize-20-r0-060-b7mgm,phase=Succeeded node=kind-worker3
87.3804,Job,MODIFIED,eval-sanitize-20-r0-060,
87.3812,Job,MODIFIED,eval-sanitize-20-r0-075,
87.382,Job,MODIFIED,eval-sanitize-20-r0-065,
87.3862,Pod,MODIFIED,eval-sanitize-20-r0-059-zqwtk,phase=Succeeded node=kind-worker3
87.3881,Job,MODIFIED,eval-sanitize-20-r0-059,
87.3911,Pod,MODIFIED,eval-sanitize-20-r0-065-pjdh6,phase=Succeeded node=kind-worker3
87.3921,Job,MODIFIED,eval-sanitize-20-r0-074,
87.395,Job,MODIFIED,eval-sanitize-20-r0-065,
87.3976,Job,MODIFIED,eval-sanitize-20-r0-061,
87.3984,Event,ADDED,eval-sanitize-20-r0-065.18d41a6cbb631a6d,reason=Completed count=1 msg=Job completed
87.4025,Pod,MODIFIED,eval-sanitize-20-r0-074-fm9hq,phase=Succeeded node=kind-worker3
87.4105,Job,MODIFIED,eval-sanitize-20-r0-074,
87.4123,Pod,MODIFIED,eval-sanitize-20-r0-061-g2xd9,phase=Succeeded node=kind-worker3
87.4143,Job,MODIFIED,eval-sanitize-20-r0-061,
87.4189,Event,ADDED,eval-sanitize-20-r0-074.18d41a6cbc3aecdd,reason=Completed count=1 msg=Job completed
87.4301,Job,MODIFIED,eval-sanitize-20-r0-065,
87.4325,Job,MODIFIED,eval-sanitize-20-r0-074,
87.4345,Job,MODIFIED,eval-sanitize-20-r0-061,
87.4361,TaskRequest,MODIFIED,eval-sanitize-20-r0-065,phase=Complete job=None
87.4419,TaskRequest,MODIFIED,eval-sanitize-20-r0-074,phase=Complete job=None
87.4511,TaskRequest,MODIFIED,eval-sanitize-20-r0-061,phase=Complete job=None
87.4526,Job,MODIFIED,eval-sanitize-20-r0-065,
87.4538,Job,MODIFIED,eval-sanitize-20-r0-074,
87.4682,Event,ADDED,eval-sanitize-20-r0-061.18d41a6cbc8a1d8b,reason=Completed count=1 msg=Job completed
87.4899,Pod,MODIFIED,eval-sanitize-20-r0-057-st55d,phase=Succeeded node=kind-worker3
87.6793,Job,MODIFIED,eval-sanitize-20-r0-061,
87.6874,Pod,MODIFIED,eval-sanitize-20-r0-075-6vkpb,phase=Succeeded node=kind-worker3
87.6948,Pod,MODIFIED,eval-sanitize-20-r0-067-vqk69,phase=Succeeded node=kind-worker3
87.8017,Event,ADDED,eval-sanitize-20-r0-087-dsfdc.18d41a6cd34b5e83,"reason=Pulled count=1 msg=Container image ""busybox:musl"" already present on machine"
87.822,Event,ADDED,eval-sanitize-20-r0-087-dsfdc.18d41a6cd498895a,reason=Created count=1 msg=Created container: task
87.9306,Job,MODIFIED,eval-sanitize-20-r0-058,
87.9326,Job,MODIFIED,eval-sanitize-20-r0-069,
87.9337,Job,MODIFIED,eval-sanitize-20-r0-055,
87.9345,Job,MODIFIED,eval-sanitize-20-r0-073,
87.9352,Job,MODIFIED,eval-sanitize-20-r0-068,
87.9361,Job,MODIFIED,eval-sanitize-20-r0-058,
87.9375,Event,ADDED,eval-sanitize-20-r0-087-dsfdc.18d41a6cdb4922dc,reason=Started count=1 msg=Started container task
87.9407,Pod,MODIFIED,eval-sanitize-20-r0-077-qnsfc,phase=Running node=kind-worker5
87.9423,Job,MODIFIED,eval-sanitize-20-r0-069,
87.9434,Job,MODIFIED,eval-sanitize-20-r0-055,
87.9444,Job,MODIFIED,eval-sanitize-20-r0-056,
87.952,Job,MODIFIED,eval-sanitize-20-r0-058,
87.9531,Job,MODIFIED,eval-sanitize-20-r0-069,
87.9546,Job,MODIFIED,eval-sanitize-20-r0-055,
87.9561,Job,MODIFIED,eval-sanitize-20-r0-073,
87.9569,Job,MODIFIED,eval-sanitize-20-r0-068,
87.9592,Job,MODIFIED,eval-sanitize-20-r0-056,
87.9671,Event,ADDED,eval-sanitize-20-r0-058.18d41a6cdb9df5dc,reason=Completed count=1 msg=Job completed
88.0752,TaskRequest,ADDED,eval-sanitize-20-r0-088,phase=None job=None
88.0776,Event,ADDED,eval-sanitize-20-r0-055.18d41a6cdbcd19af,reason=Completed count=1 msg=Job completed
88.0777,TaskRequest,MODIFIED,eval-sanitize-20-r0-058,phase=Complete job=None
88.0786,Job,MODIFIED,eval-sanitize-20-r0-072,
88.0842,Pod,MODIFIED,eval-sanitize-20-r0-073-66xbk,phase=Succeeded node=kind-worker5
88.0848,TaskRequest,MODIFIED,eval-sanitize-20-r0-069,phase=Complete job=None
88.0897,Job,MODIFIED,eval-sanitize-20-r0-058,
88.0907,TaskRequest,MODIFIED,eval-sanitize-20-r0-055,phase=Complete job=None
88.095,Job,MODIFIED,eval-sanitize-20-r0-069,
88.0951,TaskRequest,MODIFIED,eval-sanitize-20-r0-088,phase=Pending job=None
88.1145,Pod,MODIFIED,eval-sanitize-20-r0-056-6bgct,phase=Succeeded node=kind-worker2
88.1162,Pod,MODIFIED,eval-sanitize-20-r0-072-jnqzb,phase=Succeeded node=kind-worker5
88.1169,Event,ADDED,eval-sanitize-20-r0-069.18d41a6cdbcf31f9,reason=Completed count=1 msg=Job completed
88.123,Pod,MODIFIED,eval-sanitize-20-r0-068-4cgl6,phase=Succeeded node=kind-worker5
88.1299,Job,MODIFIED,eval-sanitize-20-r0-055,
88.1351,Job,ADDED,eval-sanitize-20-r0-088,
88.1405,TaskRequest,MODIFIED,eval-sanitize-20-r0-088,phase=Scheduled job=None
88.1453,Job,MODIFIED,eval-sanitize-20-r0-088,
88.1501,TaskRequest,MODIFIED,eval-sanitize-20-r0-088,phase=Scheduled job=None
88.1526,Job,MODIFIED,eval-sanitize-20-r0-072,
88.1703,Pod,ADDED,eval-sanitize-20-r0-088-thh9f,phase=Pending node=None
88.2185,Event,ADDED,eval-sanitize-20-r0-088.18d41a6ce99a86f3,reason=SuccessfulCreate count=1 msg=Created pod: eval-sanitize-20-r0-088-thh9f
88.3953,Pod,MODIFIED,eval-sanitize-20-r0-088-thh9f,phase=Pending node=kind-worker5
88.3981,Job,MODIFIED,eval-sanitize-20-r0-057,
88.3997,Job,MODIFIED,eval-sanitize-20-r0-067,
88.4005,Event,ADDED,eval-sanitize-20-r0-088-thh9f.18d41a6cf6f7e1d8,reason=Scheduled count=None msg=Successfully assigned compute/eval-sanitize-20-r0-088-thh9f to kind-worker5
88.4078,Pod,MODIFIED,eval-sanitize-20-r0-088-thh9f,phase=Pending node=kind-worker5
88.4106,Job,MODIFIED,eval-sanitize-20-r0-057,
88.4125,Job,MODIFIED,eval-sanitize-20-r0-067,
88.4178,Job,MODIFIED,eval-sanitize-20-r0-060,
88.4268,Job,MODIFIED,eval-sanitize-20-r0-060,
88.4703,Job,MODIFIED,eval-sanitize-20-r0-075,
88.4799,Job,MODIFIED,eval-sanitize-20-r0-075,
88.6004,Job,MODIFIED,eval-sanitize-20-r0-059,
88.6029,Pod,MODIFIED,eval-sanitize-20-r0-057-st55d,phase=Succeeded node=kind-worker3
88.6109,Job,MODIFIED,eval-sanitize-20-r0-059,
88.6237,Pod,MODIFIED,eval-sanitize-20-r0-067-vqk69,phase=Succeeded node=kind-worker3
88.7243,Pod,MODIFIED,eval-sanitize-20-r0-075-6vkpb,phase=Succeeded node=kind-worker3
88.8513,Pod,MODIFIED,eval-sanitize-20-r0-087-dsfdc,phase=Running node=kind-worker4
88.8549,Event,ADDED,eval-sanitize-20-r0-088-thh9f.18d41a6d1223bb83,"reason=Pulled count=1 msg=Container image ""busybox:musl"" already present on machine"
88.8751,Event,ADDED,eval-sanitize-20-r0-088-thh9f.18d41a6d135ed17e,reason=Created count=1 msg=Created container: task
89.0137,Event,ADDED,eval-sanitize-20-r0-088-thh9f.18d41a6d1b822fee,reason=Started count=1 msg=Started container task
89.0142,TaskRequest,ADDED,eval-sanitize-20-r0-089,phase=None job=None
89.0153,Job,MODIFIED,eval-sanitize-20-r0-073,
89.0202,Pod,MODIFIED,eval-sanitize-20-r0-078-8kldj,phase=Running node=kind-worker2
89.0215,Job,MODIFIED,eval-sanitize-20-r0-068,
89.0216,TaskRequest,MODIFIED,eval-sanitize-20-r0-089,phase=Pending job=None
89.0285,Job,MODIFIED,eval-sanitize-20-r0-073,
89.0407,Job,ADDED,eval-sanitize-20-r0-089,
89.0454,TaskRequest,MODIFIED,eval-sanitize-20-r0-089,phase=Scheduled job=None
89.0507,Job,MODIFIED,eval-sanitize-20-r0-089,
89.0546,TaskRequest,MODIFIED,eval-sanitize-20-r0-089,phase=Scheduled job=None
89.0574,Job,MODIFIED,eval-sanitize-20-r0-068,
89.0678,Job,MODIFIED,eval-sanitize-20-r0-077,
89.0831,Pod,MODIFIED,eval-sanitize-20-r0-077-qnsfc,phase=Succeeded node=kind-worker5
89.1186,Job,MODIFIED,eval-sanitize-20-r0-056,
89.1288,Job,MODIFIED,eval-sanitize-20-r0-077,
89.1296,Job,MODIFIED,eval-sanitize-20-r0-056,
89.2365,Pod,MODIFIED,eval-sanitize-20-r0-073-66xbk,phase=Succeeded node=kind-worker5
89.2389,Pod,MODIFIED,eval-sanitize-20-r0-068-4cgl6,phase=Succeeded node=kind-worker5
89.2719,Pod,ADDED,eval-sanitize-20-r0-089-ktmjl,phase=Pending node=None
89.3196,Job,MODIFIED,eval-sanitize-20-r0-072,
89.3301,Job,MODIFIED,eval-sanitize-20-r0-072,
89.4447,Pod,MODIFIED,eval-sanitize-20-r0-056-6bgct,phase=Succeeded node=kind-worker2
89.4475,Pod,MODIFIED,eval-sanitize-20-r0-089-ktmjl,phase=Pending node=kind-worker3
89.4514,Event,ADDED,eval-sanitize-20-r0-089-ktmjl.18d41a6d35bc36ef,reason=Scheduled count=None msg=Successfully assigned compute/eval-sanitize-20-r0-089-ktmjl to kind-worker3
89.4578,Pod,MODIFIED,eval-sanitize-20-r0-089-ktmjl,phase=Pending node=kind-worker3
89.5689,Event,ADDED,eval-sanitize-20-r0-089.18d41a6d2b471e50,reason=SuccessfulCreate count=1 msg=Created pod: eval-sanitize-20-r0-089-ktmjl
89.6241,Pod,MODIFIED,eval-sanitize-20-r0-072-jnqzb,phase=Succeeded node=kind-worker5
89.7523,Job,MODIFIED,eval-sanitize-20-r0-088,
89.7632,Job,MODIFIED,eval-sanitize-20-r0-088,
89.7681,Job,MODIFIED,eval-sanitize-20-r0-057,
89.7784,Job,MODIFIED,eval-sanitize-20-r0-057,
89.9029,Job,MODIFIED,eval-sanitize-20-r0-067,
89.9084,Event,ADDED,eval-sanitize-20-r0-089-ktmjl.18d41a6d50f25e74,"reason=Pulled count=1 msg=Container image ""busybox:musl"" already present on machine"
89.9128,Job,MODIFIED,eval-sanitize-20-r0-067,
89.9195,Job,MODIFIED,eval-sanitize-20-r0-060,
89.9256,TaskRequest,MODIFIED,eval-sanitize-20-r0-060,phase=Complete job=None
89.9351,Event,ADDED,eval-sanitize-20-r0-089-ktmjl.18d41a6d5288856e,reason=Created count=1 msg=Created container: task
89.9401,Job,MODIFIED,eval-sanitize-20-r0-060,
89.9416,Pod,MODIFIED,eval-sanitize-20-r0-079-rj2gc,phase=Running node=kind-worker5
89.9499,Pod,MODIFIED,eval-sanitize-20-r0-088-thh9f,phase=Running node=kind-worker5
89.9694,Job,MODIFIED,eval-sanitize-20-r0-075,
89.9794,Job,MODIFIED,eval-sanitize-20-r0-075,
90.115,TaskRequest,ADDED,eval-sanitize-20-r0-090,phase=None job=None
90.1217,Job,MODIFIED,eval-sanitize-20-r0-059,
90.1218,TaskRequest,MODIFIED,eval-sanitize-20-r0-090,phase=Pending job=None
90.1259,Event,ADDED,eval-sanitize-20-r0-089-ktmjl.18d41a6d5de167d3,reason=Started count=1 msg=Started container task
90.14,Job,ADDED,eval-sanitize-20-r0-090,
90.1453,TaskRequest,MODIFIED,eval-sanitize-20-r0-090,phase=Scheduled job=None
90.1508,Job,MODIFIED,eval-sanitize-20-r0-090,
90.1523,TaskRequest,MODIFIED,eval-sanitize-20-r0-059,phase=Complete job=None
90.153,TaskRequest,MODIFIED,eval-sanitize-20-r0-090,phase=Scheduled job=None
90.1621,Job,MODIFIED,eval-sanitize-20-r0-059,
90.1685,Job,MODIFIED,eval-sanitize-20-r0-087,
90.1779,Job,MODIFIED,eval-sanitize-20-r0-087,
90.2036,Pod,MODIFIED,eval-sanitize-20-r0-078-8kldj,phase=Succeeded node=kind-worker2
90.2169,Event,ADDED,eval-sanitize-20-r0-060.18d41a6d51dd1a0c,reason=Completed count=1 msg=Job completed
90.3939,Job,MODIFIED,eval-sanitize-20-r0-073,
90.3956,Job,MODIFIED,eval-sanitize-20-r0-078,
90.4006,Pod,MODIFIED,eval-sanitize-20-r0-089-ktmjl,phase=Running node=kind-worker3
90.4038,Job,MODIFIED,eval-sanitize-20-r0-073,
90.4057,Job,MODIFIED,eval-sanitize-20-r0-078,
90.4184,Job,MODIFIED,eval-sanitize-20-r0-068,
90.4291,Job,MODIFIED,eval-sanitize-20-r0-068,
90.4713,Job,MODIFIED,eval-sanitize-20-r0-089,
90.4818,Job,MODIFIED,eval-sanitize-20-r0-089,
90.52,Event,ADDED,eval-sanitize-20-r0-059.18d41a6d5ddb1e4d,reason=Completed count=1 msg=Job completed
90.6279,Job,MODIFIED,eval-sanitize-20-r0-077,
90.637,Job,MODIFIED,eval-sanitize-20-r0-077,
90.6693,Job,MODIFIED,eval-sanitize-20-r0-056,
90.6803,Job,MODIFIED,eval-sanitize-20-r0-056,
90.7705,Pod,ADDED,eval-sanitize-20-r0-090-lp8h4,phase=Pending node=None
90.7846,Pod,MODIFIED,eval-sanitize-20-r0-080-lzhjn,phase=Running node=kind-worker4
90.7909,Pod,MODIFIED,eval-sanitize-20-r0-090-lp8h4,phase=Pending node=kind-worker4
90.7956,Event,ADDED,eval-sanitize-20-r0-090-lp8h4.18d41a6d85e2ec05,reason=Scheduled count=None msg=Successfully assigned compute/eval-sanitize-20-r0-090-lp8h4 to kind-worker4
90.8011,Pod,MODIFIED,eval-sanitize-20-r0-090-lp8h4,phase=Pending node=kind-worker4
90.8224,Pod,MODIFIED,eval-sanitize-20-r0-077-qnsfc,phase=Succeeded node=kind-worker5
90.9423,Job,MODIFIED,eval-sanitize-20-r0-072,
90.9539,Job,MODIFIED,eval-sanitize-20-r0-072,
90.9692,Job,MODIFIED,eval-sanitize-20-r0-088,
90.979,Job,MODIFIED,eval-sanitize-20-r0-088,
91.0854,TaskRequest,ADDED,eval-sanitize-20-r0-091,phase=None job=None
91.0877,Event,ADDED,eval-sanitize-20-r0-090.18d41a6d84985360,reason=SuccessfulCreate count=1 msg=Created pod: eval-sanitize-20-r0-090-lp8h4
91.0888,Job,MODIFIED,eval-sanitize-20-r0-090,
91.0897,TaskRequest,MODIFIED,eval-sanitize-20-r0-091,phase=Pending job=None
91.0943,Pod,MODIFIED,eval-sanitize-20-r0-079-rj2gc,phase=Succeeded node=kind-worker5
91.108,Job,ADDED,eval-sanitize-20-r0-091,
91.113,TaskRequest,MODIFIED,eval-sanitize-20-r0-091,phase=Scheduled job=None
91.1177,Job,MODIFIED,eval-sanitize-20-r0-091,
91.1231,Job,MODIFIED,eval-sanitize-20-r0-090,
91.1233,TaskRequest,MODIFIED,eval-sanitize-20-r0-091,phase=Scheduled job=None
91.2125,Event,ADDED,eval-sanitize-20-r0-090-lp8h4.18d41a6d9eaec5a8,"reason=Pulled count=1 msg=Container image ""busybox:musl"" already present on machine"
91.219,Job,MODIFIED,eval-sanitize-20-r0-057,
91.2225,TaskRequest,MODIFIED,eval-sanitize-20-r0-057,phase=Complete job=None
91.2337,Job,MODIFIED,eval-sanitize-20-r0-057,
91.234,Event,ADDED,eval-sanitize-20-r0-090-lp8h4.18d41a6d9fe6e8c4,reason=Created count=1 msg=Created container: task
91.3416,Job,MODIFIED,eval-sanitize-20-r0-067,
91.343,Job,MODIFIED,eval-sanitize-20-r0-079,
91.3452,TaskRequest,MODIFIED,eval-sanitize-20-r0-067,phase=Complete job=None
91.3474,Event,ADDED,eval-sanitize-20-r0-090-lp8h4.18d41a6da6a2f25e,reason=Started count=1 msg=Started container task
91.3551,Job,MODIFIED,eval-sanitize-20-r0-067,
91.3568,Job,MODIFIED,eval-sanitize-20-r0-079,
91.3682,Job,MODIFIED,eval-sanitize-20-r0-075,
91.3725,TaskRequest,MODIFIED,eval-sanitize-20-r0-075,phase=Complete job=None
91.3819,Job,MODIFIED,eval-sanitize-20-r0-075,
91.4237,Pod,ADDED,eval-sanitize-20-r0-091-hzp7z,phase=Pending node=None
91.4455,Pod,MODIFIED,eval-sanitize-20-r0-091-hzp7z,phase=Pending node=None
91.4459,Event,ADDED,eval-sanitize-20-r0-091-hzp7z.18d41a6dac6c5e73,"reason=FailedScheduling count=None msg=0/6 nodes are available: 1 c_wall violated: 2 conflicting context pair(s) with node memory, 1 c_wall violated: 3 conflicting context pair(s) with node memory, 2 c_wall violated: 1 conflicting context pair(s) with node memory, 2 node(s) had untolerated taint(s). no new claims to deallocate, preemption: 0/6 nodes are available: 2 Preemption is not helpful for scheduling, 4 No preemption victims found for incoming pod."
91.4684,Job,MODIFIED,eval-sanitize-20-r0-078,
91.478,Job,MODIFIED,eval-sanitize-20-r0-078,
91.5876,Event,ADDED,eval-sanitize-20-r0-057.18d41a6d9f51f390,reason=Completed count=1 msg=Job completed
91.5907,Job,MODIFIED,eval-sanitize-20-r0-073,
91.5912,Event,ADDED,eval-sanitize-20-r0-091-hzp7z.18d41a6db239ae1f,"reason=FailedScheduling count=None msg=0/6 nodes are available: 1 c_wall violated: 2 conflicting context pair(s) with node memory, 1 c_wall violated: 3 conflicting context pair(s) with node memory, 2 c_wall violated: 1 conflicting context pair(s) with node memory, 2 node(s) had untolerated taint(s). no new claims to deallocate, preemption: 0/6 nodes are available: 2 Preemption is not helpful for scheduling, 4 No preemption victims found for incoming pod."
91.5956,TaskRequest,MODIFIED,eval-sanitize-20-r0-073,phase=Complete job=None
91.6056,Job,MODIFIED,eval-sanitize-20-r0-073,
91.6184,Job,MODIFIED,eval-sanitize-20-r0-089,
91.6269,Job,MODIFIED,eval-sanitize-20-r0-089,
91.745,Job,MODIFIED,eval-sanitize-20-r0-068,
91.7457,Job,MODIFIED,eval-sanitize-20-r0-091,
91.7504,TaskRequest,MODIFIED,eval-sanitize-20-r0-068,phase=Complete job=None
91.7598,Job,MODIFIED,eval-sanitize-20-r0-091,
91.7626,Job,MODIFIED,eval-sanitize-20-r0-068,
91.7716,Pod,MODIFIED,eval-sanitize-20-r0-078-8kldj,phase=Succeeded node=kind-worker2
91.7917,Pod,MODIFIED,eval-sanitize-20-r0-081-bpjhg,phase=Running node=kind-worker4
91.7986,Pod,MODIFIED,eval-sanitize-20-r0-090-lp8h4,phase=Running node=kind-worker4
91.8178,Event,ADDED,eval-sanitize-20-r0-067.18d41a6da6a0937c,reason=Completed count=1 msg=Job completed
91.9263,Job,MODIFIED,eval-sanitize-20-r0-077,
91.9311,Job,MODIFIED,eval-sanitize-20-r0-056,
91.94,Pod,MODIFIED,eval-sanitize-20-r0-080-lzhjn,phase=Succeeded node=kind-worker4
91.9402,TaskRequest,MODIFIED,eval-sanitize-20-r0-056,phase=Complete job=None
91.9411,Job,MODIFIED,eval-sanitize-20-r0-077,
91.9526,Job,MODIFIED,eval-sanitize-20-r0-056,
92.0083,TaskRequest,ADDED,eval-sanitize-20-r0-092,phase=None job=None
92.0134,Event,MODIFIED,eval-sanitize-20-r0-091-hzp7z.18d41a6db239ae1f,"reason=FailedScheduling count=None msg=0/6 nodes are available: 1 c_wall violated: 2 conflicting context pair(s) with node memory, 1 c_wall violated: 3 conflicting context pair(s) with node memory, 2 c_wall violated: 1 conflicting context pair(s) with node memory, 2 node(s) had untolerated taint(s). no new claims to deallocate, preemption: 0/6 nodes are available: 2 Preemption is not helpful for scheduling, 4 No preemption victims found for incoming pod."
92.0153,TaskRequest,MODIFIED,eval-sanitize-20-r0-092,phase=Pending job=None
92.0205,Job,MODIFIED,eval-sanitize-20-r0-080,
92.0376,Job,ADDED,eval-sanitize-20-r0-092,
92.0423,TaskRequest,MODIFIED,eval-sanitize-20-r0-092,phase=Scheduled job=None
92.0475,Job,MODIFIED,eval-sanitize-20-r0-092,
92.0513,TaskRequest,MODIFIED,eval-sanitize-20-r0-092,phase=Scheduled job=None
92.0536,Job,MODIFIED,eval-sanitize-20-r0-080,
92.0699,Event,ADDED,eval-sanitize-20-r0-075.18d41a6da83730f4,reason=Completed count=1 msg=Job completed
92.214,Job,MODIFIED,eval-sanitize-20-r0-072,
92.2177,TaskRequest,MODIFIED,eval-sanitize-20-r0-072,phase=Complete job=None
92.2203,Pod,ADDED,eval-sanitize-20-r0-092-wfwmz,phase=Pending node=None
92.2273,Job,MODIFIED,eval-sanitize-20-r0-072,
92.2689,Event,ADDED,eval-sanitize-20-r0-091.18d41a6dab822668,reason=SuccessfulCreate count=1 msg=Created pod: eval-sanitize-20-r0-091-hzp7z
92.3205,Job,MODIFIED,eval-sanitize-20-r0-079,
92.3307,Job,MODIFIED,eval-sanitize-20-r0-079,
92.4371,Node,MODIFIED,kind-worker,taints=1
92.4377,Event,ADDED,eval-sanitize-20-r0-073.18d41a6db57da206,reason=Completed count=1 msg=Job completed
92.4422,Pod,MODIFIED,eval-sanitize-20-r0-092-wfwmz,phase=Pending node=kind-worker4
92.4462,Event,ADDED,eval-sanitize-20-r0-092-wfwmz.18d41a6de83338b0,reason=Scheduled count=None msg=Successfully assigned compute/eval-sanitize-20-r0-092-wfwmz to kind-worker4
92.4541,Pod,MODIFIED,eval-sanitize-20-r0-092-wfwmz,phase=Pending node=kind-worker4
92.4727,Pod,MODIFIED,eval-sanitize-20-r0-079-rj2gc,phase=Succeeded node=kind-worker5
92.4812,Node,MODIFIED,kind-worker,taints=1
92.4899,Node,MODIFIED,kind-worker,taints=0
92.5035,Node,MODIFIED,kind-worker,taints=0
92.5195,Event,ADDED,eval-sanitize-20-r0-068.18d41a6dbeaa677a,reason=Completed count=1 msg=Job completed
92.5693,Job,MODIFIED,eval-sanitize-20-r0-078,
92.5801,Job,MODIFIED,eval-sanitize-20-r0-078,
92.6145,Pod,MODIFIED,eval-sanitize-20-r0-076-v7znd,phase=Pending node=kind-worker
92.6197,Event,ADDED,eval-sanitize-20-r0-076-v7znd.18d41a6df27393a3,reason=Scheduled count=None msg=Successfully assigned compute/eval-sanitize-20-r0-076-v7znd to kind-worker
92.6267,Node,MODIFIED,kind-worker,taints=0
92.6287,Pod,MODIFIED,eval-sanitize-20-r0-076-v7znd,phase=Pending node=kind-worker
92.6384,Node,MODIFIED,kind-worker,taints=0
92.746,Event,ADDED,eval-sanitize-20-r0-056.18d41a6dc9c718ff,reason=Completed count=1 msg=Job completed
92.7473,Pod,MODIFIED,eval-sanitize-20-r0-091-hzp7z,phase=Pending node=kind-worker
92.754,Event,ADDED,eval-sanitize-20-r0-091-hzp7z.18d41a6dfa7024d4,reason=Scheduled count=None msg=Successfully assigned compute/eval-sanitize-20-r0-091-hzp7z to kind-worker
92.7609,Pod,MODIFIED,eval-sanitize-20-r0-091-hzp7z,phase=Pending node=kind-worker
92.7676,Event,ADDED,eval-sanitize-20-r0-072.18d41a6ddaa3d2b5,reason=Completed count=1 msg=Job completed
92.8178,Event,ADDED,eval-sanitize-20-r0-092.18d41a6ddb07a7ce,reason=SuccessfulCreate count=1 msg=Created pod: eval-sanitize-20-r0-092-wfwmz
92.93,Pod,MODIFIED,eval-sanitize-20-r0-082-75tr7,phase=Pending node=kind-worker
92.9312,Job,MODIFIED,eval-sanitize-20-r0-081,
92.9321,Job,MODIFIED,eval-sanitize-20-r0-090,
92.933,Event,ADDED,eval-sanitize-20-r0-082-75tr7.18d41a6e05372fe4,reason=Scheduled count=None msg=Successfully assigned compute/eval-sanitize-20-r0-082-75tr7 to kind-worker
92.9337,Event,ADDED,eval-sanitize-20-r0-092-wfwmz.18d41a6e052daac6,"reason=Pulled count=1 msg=Container image ""busybox:musl"" already present on machine"
92.9411,Pod,MODIFIED,eval-sanitize-20-r0-082-75tr7,phase=Pending node=kind-worker
92.9437,Job,MODIFIED,eval-sanitize-20-r0-081,
92.9469,Job,MODIFIED,eval-sanitize-20-r0-090,
92.9598,Event,ADDED,eval-sanitize-20-r0-092-wfwmz.18d41a6e06ba525a,reason=Created count=1 msg=Created container: task
92.9637,Pod,MODIFIED,eval-sanitize-20-r0-081-bpjhg,phase=Succeeded node=kind-worker4
92.9678,Job,MODIFIED,eval-sanitize-20-r0-077,
92.9723,TaskRequest,MODIFIED,eval-sanitize-20-r0-077,phase=Complete job=None
92.9815,Job,MODIFIED,eval-sanitize-20-r0-077,
93.0095,TaskRequest,ADDED,eval-sanitize-20-r0-093,phase=None job=None
93.0139,TaskRequest,MODIFIED,eval-sanitize-20-r0-093,phase=Pending job=None
93.021,Job,MODIFIED,eval-sanitize-20-r0-080,
93.0329,Job,ADDED,eval-sanitize-20-r0-093,
93.038,TaskRequest,MODIFIED,eval-sanitize-20-r0-093,phase=Scheduled job=None
93.0453,Job,MODIFIED,eval-sanitize-20-r0-093,
93.0458,TaskRequest,MODIFIED,eval-sanitize-20-r0-093,phase=Scheduled job=None
93.0487,Job,MODIFIED,eval-sanitize-20-r0-080,
93.0492,Event,ADDED,eval-sanitize-20-r0-092-wfwmz.18d41a6e0c1c0783,reason=Started count=1 msg=Started container task
93.0671,Event,ADDED,eval-sanitize-20-r0-077.18d41a6e07904360,reason=Completed count=1 msg=Job completed
93.2036,Pod,MODIFIED,eval-sanitize-20-r0-080-lzhjn,phase=Succeeded node=kind-worker4
93.2046,Pod,ADDED,eval-sanitize-20-r0-093-pf6tm,phase=Pending node=None
93.2065,Event,ADDED,eval-sanitize-20-r0-091-hzp7z.18d41a6e15844a1e,"reason=Pulled count=1 msg=Container image ""busybox:musl"" already present on machine"
93.2196,Job,MODIFIED,eval-sanitize-20-r0-092,
93.2408,Job,MODIFIED,eval-sanitize-20-r0-092,
93.2413,Event,ADDED,eval-sanitize-20-r0-091-hzp7z.18d41a6e16fadbfe,reason=Created count=1 msg=Created container: task
93.3723,Event,ADDED,eval-sanitize-20-r0-093.18d41a6e15a80236,reason=SuccessfulCreate count=1 msg=Created pod: eval-sanitize-20-r0-093-pf6tm
93.3733,Pod,MODIFIED,eval-sanitize-20-r0-093-pf6tm,phase=Pending node=kind-worker5
93.3799,Event,ADDED,eval-sanitize-20-r0-091-hzp7z.18d41a6e1fae72a4,reason=Started count=1 msg=Started container task
93.3806,Event,ADDED,eval-sanitize-20-r0-093-pf6tm.18d41a6e1fa8f022,reason=Scheduled count=None msg=Successfully assigned compute/eval-sanitize-20-r0-093-pf6tm to kind-worker5
93.3879,Pod,MODIFIED,eval-sanitize-20-r0-093-pf6tm,phase=Pending node=kind-worker5
93.4193,Job,MODIFIED,eval-sanitize-20-r0-079,
93.4301,Job,MODIFIED,eval-sanitize-20-r0-079,
93.4917,Event,ADDED,eval-sanitize-20-r0-076-v7znd.18d41a6e267fc847,"reason=Pulled count=1 msg=Container image ""busybox:musl"" already present on machine"
93.4977,Event,ADDED,eval-sanitize-20-r0-082-75tr7.18d41a6e26e67f38,"reason=Pulled count=1 msg=Container image ""busybox:musl"" already present on machine"
93.5181,Event,ADDED,eval-sanitize-20-r0-076-v7znd.18d41a6e27f3c01b,reason=Created count=1 msg=Created container: task
93.523,Event,ADDED,eval-sanitize-20-r0-082-75tr7.18d41a6e284ad81a,reason=Created count=1 msg=Created container: task
93.631,Job,MODIFIED,eval-sanitize-20-r0-078,
93.6363,Event,ADDED,eval-sanitize-20-r0-078.18d41a6e2f17676c,reason=Completed count=1 msg=Job completed
93.6368,Event,ADDED,eval-sanitize-20-r0-076-v7znd.18d41a6e2f350dea,reason=Started count=1 msg=Started container task
93.6371,TaskRequest,MODIFIED,eval-sanitize-20-r0-078,phase=Complete job=None
93.6429,Event,ADDED,eval-sanitize-20-r0-082-75tr7.18d41a6e2f361d50,reason=Started count=1 msg=Started container task
93.647,Node,MODIFIED,kind-worker4,taints=1
93.6539,Job,MODIFIED,eval-sanitize-20-r0-078,
93.6623,Node,MODIFIED,kind-worker4,taints=1
93.8448,Pod,MODIFIED,eval-sanitize-20-r0-092-wfwmz,phase=Running node=kind-worker4
93.8474,Event,ADDED,eval-sanitize-20-r0-093-pf6tm.18d41a6e3bbcb93b,"reason=Pulled count=1 msg=Container image ""busybox:musl"" already present on machine"
93.8667,Event,ADDED,eval-sanitize-20-r0-093-pf6tm.18d41a6e3cdf0656,reason=Created count=1 msg=Created container: task
93.9766,Job,MODIFIED,eval-sanitize-20-r0-081,
93.9826,Pod,MODIFIED,eval-sanitize-20-r0-083-99zmw,phase=Running node=kind-worker2
93.9831,Event,ADDED,eval-sanitize-20-r0-093-pf6tm.18d41a6e43b78266,reason=Started count=1 msg=Started container task
93.9854,Pod,MODIFIED,eval-sanitize-20-r0-081-bpjhg,phase=Succeeded node=kind-worker4
93.9874,Job,MODIFIED,eval-sanitize-20-r0-081,
94.0068,TaskRequest,ADDED,eval-sanitize-20-r0-094,phase=None job=None
94.012,TaskRequest,MODIFIED,eval-sanitize-20-r0-094,phase=Pending job=None
94.0277,Job,MODIFIED,eval-sanitize-20-r0-080,
94.0312,Job,ADDED,eval-sanitize-20-r0-094,
94.0338,Job,MODIFIED,eval-sanitize-20-r0-080,
94.0366,TaskRequest,MODIFIED,eval-sanitize-20-r0-094,phase=Scheduled job=None
94.0394,Event,ADDED,eval-sanitize-20-r0-080.18d41a6e471fc3ab,reason=Completed count=1 msg=Job completed
94.0414,Pod,ADDED,eval-sanitize-20-r0-094-5vbzf,phase=Pending node=None
94.0423,Job,MODIFIED,eval-sanitize-20-r0-094,
94.0457,Event,ADDED,eval-sanitize-20-r0-094.18d41a6e477c75a6,reason=SuccessfulCreate count=1 msg=Created pod: eval-sanitize-20-r0-094-5vbzf
94.0488,TaskRequest,MODIFIED,eval-sanitize-20-r0-094,phase=Scheduled job=None
94.0518,Job,MODIFIED,eval-sanitize-20-r0-080,
94.0558,TaskRequest,MODIFIED,eval-sanitize-20-r0-080,phase=Complete job=None
94.0672,Job,MODIFIED,eval-sanitize-20-r0-093,
94.1134,Pod,MODIFIED,eval-sanitize-20-r0-094-5vbzf,phase=Pending node=kind-worker5
94.117,Event,ADDED,eval-sanitize-20-r0-094-5vbzf.18d41a6e4bd81faf,reason=Scheduled count=None msg=Successfully assigned compute/eval-sanitize-20-r0-094-5vbzf to kind-worker5
94.1233,Pod,MODIFIED,eval-sanitize-20-r0-094-5vbzf,phase=Pending node=kind-worker5
94.1272,Job,MODIFIED,eval-sanitize-20-r0-093,
94.1294,Job,MODIFIED,eval-sanitize-20-r0-080,
94.2802,Job,MODIFIED,eval-sanitize-20-r0-092,
94.3065,Job,MODIFIED,eval-sanitize-20-r0-092,
94.386,Pod,MODIFIED,eval-sanitize-20-r0-082-75tr7,phase=Running node=kind-worker
94.3906,Node,MODIFIED,kind-worker3,taints=1
94.3954,Pod,MODIFIED,eval-sanitize-20-r0-076-v7znd,phase=Running node=kind-worker
94.4016,Pod,MODIFIED,eval-sanitize-20-r0-091-hzp7z,phase=Running node=kind-worker
94.4041,Node,MODIFIED,kind-worker3,taints=1
94.4243,Job,MODIFIED,eval-sanitize-20-r0-079,
94.4292,Event,ADDED,eval-sanitize-20-r0-079.18d41a6e5e5e9dd0,reason=Completed count=1 msg=Job completed
94.4301,TaskRequest,MODIFIED,eval-sanitize-20-r0-079,phase=Complete job=None
94.4408,Job,MODIFIED,eval-sanitize-20-r0-079,
94.5974,Event,ADDED,eval-sanitize-20-r0-094-5vbzf.18d41a6e68703a57,"reason=Pulled count=1 msg=Container image ""busybox:musl"" already present on machine"
94.6172,Event,ADDED,eval-sanitize-20-r0-094-5vbzf.18d41a6e69999d22,reason=Created count=1 msg=Created container: task
94.7545,Event,ADDED,eval-sanitize-20-r0-094-5vbzf.18d41a6e71d6c906,reason=Started count=1 msg=Started container task
94.8023,Pod,MODIFIED,eval-sanitize-20-r0-084-zv84b,phase=Running node=kind-worker4
94.9835,Job,MODIFIED,eval-sanitize-20-r0-081,
94.9879,Job,MODIFIED,eval-sanitize-20-r0-081,
94.9895,Job,MODIFIED,eval-sanitize-20-r0-083,
94.9913,Pod,MODIFIED,eval-sanitize-20-r0-093-pf6tm,phase=Running node=kind-worker5
94.9927,Event,ADDED,eval-sanitize-20-r0-081.18d41a6e7ffa0f2f,reason=Completed count=1 msg=Job completed
94.9978,Pod,MODIFIED,eval-sanitize-20-r0-094-5vbzf,phase=Running node=kind-worker5
94.9991,Job,MODIFIED,eval-sanitize-20-r0-083,
94.9999,Job,MODIFIED,eval-sanitize-20-r0-081,
95.0071,TaskRequest,MODIFIED,eval-sanitize-20-r0-081,phase=Complete job=None
95.0072,TaskRequest,ADDED,eval-sanitize-20-r0-095,phase=None job=None
95.0118,TaskRequest,MODIFIED,eval-sanitize-20-r0-095,phase=Pending job=None
95.015,Job,MODIFIED,eval-sanitize-20-r0-081,
95.0285,Job,ADDED,eval-sanitize-20-r0-095,
95.0366,Pod,ADDED,eval-sanitize-20-r0-095-44zln,phase=Pending node=None
95.0368,TaskRequest,MODIFIED,eval-sanitize-20-r0-095,phase=Scheduled job=None
95.0398,Job,MODIFIED,eval-sanitize-20-r0-095,
95.0413,Event,ADDED,eval-sanitize-20-r0-095.18d41a6e82d7f2eb,reason=SuccessfulCreate count=1 msg=Created pod: eval-sanitize-20-r0-095-44zln
95.0441,Job,MODIFIED,eval-sanitize-20-r0-094,
95.0471,Pod,MODIFIED,eval-sanitize-20-r0-083-99zmw,phase=Succeeded node=kind-worker2
95.0472,TaskRequest,MODIFIED,eval-sanitize-20-r0-095,phase=Scheduled job=None
95.0567,Pod,MODIFIED,eval-sanitize-20-r0-095-44zln,phase=Pending node=kind-worker2
95.0601,Event,ADDED,eval-sanitize-20-r0-095-44zln.18d41a6e8416fcfd,reason=Scheduled count=None msg=Successfully assigned compute/eval-sanitize-20-r0-095-44zln to kind-worker2
95.066,Pod,MODIFIED,eval-sanitize-20-r0-095-44zln,phase=Pending node=kind-worker2
95.072,Job,MODIFIED,eval-sanitize-20-r0-093,
95.1004,Job,MODIFIED,eval-sanitize-20-r0-094,
95.1025,Job,MODIFIED,eval-sanitize-20-r0-093,
95.3917,Job,MODIFIED,eval-sanitize-20-r0-082,
95.4,Job,MODIFIED,eval-sanitize-20-r0-076,
95.4022,Job,MODIFIED,eval-sanitize-20-r0-082,
95.4064,Job,MODIFIED,eval-sanitize-20-r0-091,
95.4107,Job,MODIFIED,eval-sanitize-20-r0-076,
95.416,Job,MODIFIED,eval-sanitize-20-r0-091,
95.5717,Event,ADDED,eval-sanitize-20-r0-095-44zln.18d41a6ea2882f23,"reason=Pulled count=1 msg=Container image ""busybox:musl"" already present on machine"
95.592,Event,ADDED,eval-sanitize-20-r0-095-44zln.18d41a6ea3a7cf08,reason=Created count=1 msg=Created container: task
95.6123,Node,MODIFIED,kind-worker2,taints=1
95.6241,Node,MODIFIED,kind-worker2,taints=1
95.6633,Event,ADDED,eval-sanitize-20-r0-095-44zln.18d41a6ea8028f05,reason=Started count=1 msg=Started container task
95.889,Job,MODIFIED,eval-sanitize-20-r0-084,
95.8993,Job,MODIFIED,eval-sanitize-20-r0-084,
95.9563,Pod,MODIFIED,eval-sanitize-20-r0-095-44zln,phase=Running node=kind-worker2
95.9759,Pod,MODIFIED,eval-sanitize-20-r0-084-zv84b,phase=Succeeded node=kind-worker4
95.9824,Node,MODIFIED,kind-worker5,taints=1
95.9942,Pod,MODIFIED,eval-sanitize-20-r0-085-4x5bt,phase=Running node=kind-worker5
95.9961,Job,MODIFIED,eval-sanitize-20-r0-083,
95.9974,Node,MODIFIED,kind-worker5,taints=1
96.0045,Pod,MODIFIED,eval-sanitize-20-r0-083-99zmw,phase=Succeeded node=kind-worker2
96.0062,Job,MODIFIED,eval-sanitize-20-r0-083,
96.0208,TaskRequest,ADDED,eval-sanitize-20-r0-096,phase=None job=None
96.0261,TaskRequest,MODIFIED,eval-sanitize-20-r0-096,phase=Pending job=None
96.0422,Job,MODIFIED,eval-sanitize-20-r0-095,
96.0433,Job,ADDED,eval-sanitize-20-r0-096,
96.0488,Pod,ADDED,eval-sanitize-20-r0-096-ksqpv,phase=Pending node=None
96.0509,TaskRequest,MODIFIED,eval-sanitize-20-r0-096,phase=Scheduled job=None
96.0543,Job,MODIFIED,eval-sanitize-20-r0-096,
96.0547,Event,ADDED,eval-sanitize-20-r0-096.18d41a6ebf3ae6c1,reason=SuccessfulCreate count=1 msg=Created pod: eval-sanitize-20-r0-096-ksqpv
96.0577,Pod,MODIFIED,eval-sanitize-20-r0-096-ksqpv,phase=Pending node=kind-worker
96.0583,TaskRequest,MODIFIED,eval-sanitize-20-r0-096,phase=Scheduled job=None
96.0614,Job,MODIFIED,eval-sanitize-20-r0-095,
96.0618,Event,ADDED,eval-sanitize-20-r0-096-ksqpv.18d41a6ebfc2404a,reason=Scheduled count=None msg=Successfully assigned compute/eval-sanitize-20-r0-096-ksqpv to kind-worker
96.0693,Pod,MODIFIED,eval-sanitize-20-r0-096-ksqpv,phase=Pending node=kind-worker
96.501,Event,ADDED,eval-sanitize-20-r0-096-ksqpv.18d41a6ed9eba548,"reason=Pulled count=1 msg=Container image ""busybox:musl"" already present on machine"
96.528,Event,ADDED,eval-sanitize-20-r0-096-ksqpv.18d41a6edb7631dd,reason=Created count=1 msg=Created container: task
96.5597,Event,ADDED,eval-sanitize-20-r0-096-ksqpv.18d41a6edd6daf30,reason=Started count=1 msg=Started container task
96.8961,Job,MODIFIED,eval-sanitize-20-r0-084,
96.9063,Pod,MODIFIED,eval-sanitize-20-r0-084-zv84b,phase=Succeeded node=kind-worker4
96.9072,Job,MODIFIED,eval-sanitize-20-r0-084,
97.0477,TaskRequest,ADDED,eval-sanitize-20-r0-097,phase=None job=None
97.0487,Job,MODIFIED,eval-sanitize-20-r0-085,
97.0498,Job,MODIFIED,eval-sanitize-20-r0-083,
97.0532,Job,MODIFIED,eval-sanitize-20-r0-083,
97.0545,Job,MODIFIED,eval-sanitize-20-r0-096,
97.0558,TaskRequest,MODIFIED,eval-sanitize-20-r0-097,phase=Pending job=None
97.0566,Event,ADDED,eval-sanitize-20-r0-083.18d41a6efb00c1ac,reason=Completed count=1 msg=Job completed
97.0713,Job,ADDED,eval-sanitize-20-r0-097,
97.077,Pod,ADDED,eval-sanitize-20-r0-097-lnjnk,phase=Pending node=None
97.0781,TaskRequest,MODIFIED,eval-sanitize-20-r0-097,phase=Scheduled job=None
97.0809,Job,MODIFIED,eval-sanitize-20-r0-097,
97.0827,Event,ADDED,eval-sanitize-20-r0-097.18d41a6efc6b1098,reason=SuccessfulCreate count=1 msg=Created pod: eval-sanitize-20-r0-097-lnjnk
97.0874,Pod,MODIFIED,eval-sanitize-20-r0-097-lnjnk,phase=Pending node=kind-worker
97.0875,TaskRequest,MODIFIED,eval-sanitize-20-r0-097,phase=Scheduled job=None
97.092,Job,MODIFIED,eval-sanitize-20-r0-085,
97.0943,Event,ADDED,eval-sanitize-20-r0-097-lnjnk.18d41a6efd022ec3,reason=Scheduled count=None msg=Successfully assigned compute/eval-sanitize-20-r0-097-lnjnk to kind-worker
97.0951,Job,MODIFIED,eval-sanitize-20-r0-096,
97.0959,Job,MODIFIED,eval-sanitize-20-r0-083,
97.0993,Node,MODIFIED,kind-worker,taints=0
97.1012,Pod,MODIFIED,eval-sanitize-20-r0-097-lnjnk,phase=Pending node=kind-worker
97.1014,TaskRequest,MODIFIED,eval-sanitize-20-r0-083,phase=Complete job=None
97.1121,Node,MODIFIED,kind-worker,taints=0
97.1291,Job,MODIFIED,eval-sanitize-20-r0-083,
97.1453,Pod,MODIFIED,eval-sanitize-20-r0-085-4x5bt,phase=Succeeded node=kind-worker5
97.4489,Pod,MODIFIED,eval-sanitize-20-r0-096-ksqpv,phase=Running node=kind-worker
97.5953,Event,ADDED,eval-sanitize-20-r0-097-lnjnk.18d41a6f1b0ee000,"reason=Pulled count=1 msg=Container image ""busybox:musl"" already present on machine"
97.6143,Event,ADDED,eval-sanitize-20-r0-097-lnjnk.18d41a6f1c1fb5a6,reason=Created count=1 msg=Created container: task
97.7252,Event,ADDED,eval-sanitize-20-r0-097-lnjnk.18d41a6f22cfecea,reason=Started count=1 msg=Started container task
97.9827,Job,MODIFIED,eval-sanitize-20-r0-084,
97.9873,Job,MODIFIED,eval-sanitize-20-r0-084,
97.9904,Pod,MODIFIED,eval-sanitize-20-r0-086-968c9,phase=Running node=kind-worker2
97.9908,Event,ADDED,eval-sanitize-20-r0-084.18d41a6f32afdd93,reason=Completed count=1 msg=Job completed
98.0,Job,MODIFIED,eval-sanitize-20-r0-084,
98.0056,TaskRequest,MODIFIED,eval-sanitize-20-r0-084,phase=Complete job=None
98.0064,TaskRequest,ADDED,eval-sanitize-20-r0-098,phase=None job=None
98.0112,TaskRequest,MODIFIED,eval-sanitize-20-r0-098,phase=Pending job=None
98.0176,Job,MODIFIED,eval-sanitize-20-r0-084,
98.0288,Job,ADDED,eval-sanitize-20-r0-098,
98.0347,TaskRequest,MODIFIED,eval-sanitize-20-r0-098,phase=Scheduled job=None
98.0367,Pod,ADDED,eval-sanitize-20-r0-098-f2cgd,phase=Pending node=None
98.0384,Job,MODIFIED,eval-sanitize-20-r0-098,
98.041,Event,ADDED,eval-sanitize-20-r0-098.18d41a6f359c999f,reason=SuccessfulCreate count=1 msg=Created pod: eval-sanitize-20-r0-098-f2cgd
98.0429,TaskRequest,MODIFIED,eval-sanitize-20-r0-098,phase=Scheduled job=None
98.0462,Pod,MODIFIED,eval-sanitize-20-r0-098-f2cgd,phase=Pending node=kind-worker
98.0504,Event,ADDED,eval-sanitize-20-r0-098-f2cgd.18d41a6f362ec808,reason=Scheduled count=None msg=Successfully assigned compute/eval-sanitize-20-r0-098-f2cgd to kind-worker
98.0543,Job,MODIFIED,eval-sanitize-20-r0-085,
98.0592,Pod,MODIFIED,eval-sanitize-20-r0-098-f2cgd,phase=Pending node=kind-worker
98.0606,Job,MODIFIED,eval-sanitize-20-r0-096,
98.0632,Pod,MODIFIED,eval-sanitize-20-r0-085-4x5bt,phase=Succeeded node=kind-worker5
98.0667,Job,MODIFIED,eval-sanitize-20-r0-085,
98.0701,Event,ADDED,eval-sanitize-20-r0-085.18d41a6f376f6929,reason=Completed count=1 msg=Job completed
98.0811,Job,MODIFIED,eval-sanitize-20-r0-097,
98.098,Job,MODIFIED,eval-sanitize-20-r0-085,
98.0998,Job,MODIFIED,eval-sanitize-20-r0-096,
98.1004,Job,MODIFIED,eval-sanitize-20-r0-097,
98.1026,TaskRequest,MODIFIED,eval-sanitize-20-r0-085,phase=Complete job=None
98.1118,Job,MODIFIED,eval-sanitize-20-r0-085,
98.3971,Pod,MODIFIED,eval-sanitize-20-r0-097-lnjnk,phase=Running node=kind-worker
98.4676,Event,ADDED,eval-sanitize-20-r0-098-f2cgd.18d41a6f4f0c7b8b,"reason=Pulled count=1 msg=Container image ""busybox:musl"" already present on machine"
98.488,Event,ADDED,eval-sanitize-20-r0-098-f2cgd.18d41a6f502c6589,reason=Created count=1 msg=Created container: task
98.5948,Event,ADDED,eval-sanitize-20-r0-098-f2cgd.18d41a6f556dc4a6,reason=Started count=1 msg=Started container task
98.8346,Pod,MODIFIED,eval-sanitize-20-r0-087-dsfdc,phase=Running node=kind-worker4
99.0112,Job,MODIFIED,eval-sanitize-20-r0-086,
99.0137,TaskRequest,ADDED,eval-sanitize-20-r0-099,phase=None job=None
99.0176,TaskRequest,MODIFIED,eval-sanitize-20-r0-099,phase=Pending job=None
99.0218,Job,MODIFIED,eval-sanitize-20-r0-086,
99.0363,Job,ADDED,eval-sanitize-20-r0-099,
99.0408,Job,MODIFIED,eval-sanitize-20-r0-098,
99.0423,TaskRequest,MODIFIED,eval-sanitize-20-r0-099,phase=Scheduled job=None
99.0433,Pod,ADDED,eval-sanitize-20-r0-099-p8b77,phase=Pending node=None
99.0448,Job,MODIFIED,eval-sanitize-20-r0-099,
99.0483,Event,ADDED,eval-sanitize-20-r0-099.18d41a6f71a1b5cd,reason=SuccessfulCreate count=1 msg=Created pod: eval-sanitize-20-r0-099-p8b77
99.0498,TaskRequest,MODIFIED,eval-sanitize-20-r0-099,phase=Scheduled job=None
99.0531,Job,MODIFIED,eval-sanitize-20-r0-098,
99.0535,Event,ADDED,eval-sanitize-20-r0-099-p8b77.18d41a6f71e93c58,"reason=FailedScheduling count=None msg=0/6 nodes are available: 1 c_wall violated: 2 conflicting context pair(s) with node memory, 5 node(s) had untolerated taint(s). no new claims to deallocate, preemption: 0/6 nodes are available: 1 No preemption victims found for incoming pod, 5 Preemption is not helpful for scheduling."
99.0544,Pod,MODIFIED,eval-sanitize-20-r0-099-p8b77,phase=Pending node=None
99.0602,Event,ADDED,eval-sanitize-20-r0-099-p8b77.18d41a6f72704201,"reason=FailedScheduling count=None msg=0/6 nodes are available: 1 c_wall violated: 2 conflicting context pair(s) with node memory, 5 node(s) had untolerated taint(s). no new claims to deallocate, preemption: 0/6 nodes are available: 1 No preemption victims found for incoming pod, 5 Preemption is not helpful for scheduling."
99.0876,Job,MODIFIED,eval-sanitize-20-r0-097,
99.0964,Job,MODIFIED,eval-sanitize-20-r0-097,
99.1328,Pod,MODIFIED,eval-sanitize-20-r0-086-968c9,phase=Succeeded node=kind-worker2
99.1424,Event,MODIFIED,eval-sanitize-20-r0-099-p8b77.18d41a6f72704201,"reason=FailedScheduling count=None msg=0/6 nodes are available: 1 c_wall violated: 2 conflicting context pair(s) with node memory, 5 node(s) had untolerated taint(s). no new claims to deallocate, preemption: 0/6 nodes are available: 1 No preemption victims found for incoming pod, 5 Preemption is not helpful for scheduling."
99.4008,Pod,MODIFIED,eval-sanitize-20-r0-098-f2cgd,phase=Running node=kind-worker
99.9103,Job,MODIFIED,eval-sanitize-20-r0-087,
99.9199,Job,MODIFIED,eval-sanitize-20-r0-087,
99.9903,Pod,MODIFIED,eval-sanitize-20-r0-087-dsfdc,phase=Succeeded node=kind-worker4
100.0056,Pod,MODIFIED,eval-sanitize-20-r0-088-thh9f,phase=Running node=kind-worker5
100.0175,Job,MODIFIED,eval-sanitize-20-r0-086,
100.027,Pod,MODIFIED,eval-sanitize-20-r0-086-968c9,phase=Succeeded node=kind-worker2
100.0287,Job,MODIFIED,eval-sanitize-20-r0-086,
100.0468,Job,MODIFIED,eval-sanitize-20-r0-098,
100.0493,Job,MODIFIED,eval-sanitize-20-r0-099,
100.0558,Job,MODIFIED,eval-sanitize-20-r0-098,
100.0584,Job,MODIFIED,eval-sanitize-20-r0-099,
100.3972,Pod,MODIFIED,eval-sanitize-20-r0-089-ktmjl,phase=Running node=kind-worker3
100.9162,Job,MODIFIED,eval-sanitize-20-r0-087,
100.9256,Pod,MODIFIED,eval-sanitize-20-r0-087-dsfdc,phase=Succeeded node=kind-worker4
100.9266,Job,MODIFIED,eval-sanitize-20-r0-087,
101.0135,Job,MODIFIED,eval-sanitize-20-r0-088,
101.0251,Job,MODIFIED,eval-sanitize-20-r0-086,
101.0298,Job,MODIFIED,eval-sanitize-20-r0-088,
101.0317,Job,MODIFIED,eval-sanitize-20-r0-086,
101.0378,Event,ADDED,eval-sanitize-20-r0-086.18d41a6fe823a14b,reason=Completed count=1 msg=Job completed
101.0458,Job,MODIFIED,eval-sanitize-20-r0-086,
101.0512,TaskRequest,MODIFIED,eval-sanitize-20-r0-086,phase=Complete job=None
101.0614,Job,MODIFIED,eval-sanitize-20-r0-086,
101.2725,Pod,MODIFIED,eval-sanitize-20-r0-088-thh9f,phase=Succeeded node=kind-worker5
101.4034,Job,MODIFIED,eval-sanitize-20-r0-089,
101.4132,Job,MODIFIED,eval-sanitize-20-r0-089,
101.5717,Pod,MODIFIED,eval-sanitize-20-r0-089-ktmjl,phase=Succeeded node=kind-worker3
101.823,Pod,MODIFIED,eval-sanitize-20-r0-090-lp8h4,phase=Running node=kind-worker4
101.9279,Job,MODIFIED,eval-sanitize-20-r0-087,
101.9335,Job,MODIFIED,eval-sanitize-20-r0-087,
101.9371,Event,ADDED,eval-sanitize-20-r0-087.18d41a701de7296c,reason=Completed count=1 msg=Job completed
101.9441,Job,MODIFIED,eval-sanitize-20-r0-087,
101.9488,TaskRequest,MODIFIED,eval-sanitize-20-r0-087,phase=Complete job=None
101.9583,Job,MODIFIED,eval-sanitize-20-r0-087,
102.0197,Job,MODIFIED,eval-sanitize-20-r0-088,
102.0307,Pod,MODIFIED,eval-sanitize-20-r0-088-thh9f,phase=Succeeded node=kind-worker5
102.0325,Job,MODIFIED,eval-sanitize-20-r0-088,
102.4094,Job,MODIFIED,eval-sanitize-20-r0-089,
102.4172,Pod,MODIFIED,eval-sanitize-20-r0-089-ktmjl,phase=Succeeded node=kind-worker3
102.4188,Job,MODIFIED,eval-sanitize-20-r0-089,
102.8293,Job,MODIFIED,eval-sanitize-20-r0-090,
102.8396,Job,MODIFIED,eval-sanitize-20-r0-090,
102.9927,Pod,MODIFIED,eval-sanitize-20-r0-090-lp8h4,phase=Succeeded node=kind-worker4
103.0264,Job,MODIFIED,eval-sanitize-20-r0-088,
103.0311,Job,MODIFIED,eval-sanitize-20-r0-088,
103.0362,Event,ADDED,eval-sanitize-20-r0-088.18d41a705f576008,reason=Completed count=1 msg=Job completed
103.0432,Job,MODIFIED,eval-sanitize-20-r0-088,
103.0482,TaskRequest,MODIFIED,eval-sanitize-20-r0-088,phase=Complete job=None
