t_recv,kind,type,name,detail
0.0246,Node,ADDED,kind-control-plane,taints=1
0.0263,Node,ADDED,kind-worker,taints=0
0.0265,TaskRequest,ADDED,eval-conflicts-rho030-r8-000,phase=None job=None
0.0279,Node,ADDED,kind-worker2,taints=0
0.029,Node,ADDED,kind-worker3,taints=0
0.0303,Node,ADDED,kind-worker4,taints=0
0.0314,Node,ADDED,kind-worker5,taints=0
0.0319,TaskRequest,MODIFIED,eval-conflicts-rho030-r8-000,phase=Pending job=None
0.0467,Job,ADDED,eval-conflicts-rho030-r8-000,
0.0539,TaskRequest,MODIFIED,eval-conflicts-rho030-r8-000,phase=Scheduled job=None
0.0569,Event,ADDED,eval-conflicts-rho010-r0-019-vrx7r.18d4663df244c894,"reason=FailedScheduling count=None msg=0/6 nodes are available: 1 c_wall violated: 2 conflicting context pair(s) with node memory, 5 node(s) had untolerated taint(s). no new claims to deallocate, preemption: 0/6 nodes are available: 1 No preemption victims found for incoming pod, 5 Preemption is not helpful for scheduling."
0.0577,Event,ADDED,eval-conflicts-rho010-r0-020-hzzxp.18d4663df28945da,"reason=FailedScheduling count=None msg=0/6 nodes are available: 1 c_wall violated: 1 conflicting context pair(s) with node memory, 5 node(s) had untolerated taint(s). no new claims to deallocate, preemption: 0/6 nodes are available: 1 No preemption victims found for incoming pod, 5 Preemption is not helpful for scheduling."
0.0581,Event,ADDED,eval-conflicts-rho010-r0-020-hzzxp.18d4663ed97f452c,"reason=FailedScheduling count=None msg=0/6 nodes are available: 2 c_wall violated: 1 conflicting context pair(s) with node memory, 4 node(s) had untolerated taint(s). no new claims to deallocate, preemption: 0/6 nodes are available: 2 No preemption victims found for incoming pod, 4 Preemption is not helpful for scheduling."
0.0587,Event,ADDED,eval-conflicts-rho010-r0-023-ksjvl.18d4663e32a1ea4c,"reason=FailedScheduling count=None msg=0/6 nodes are available: 1 c_wall violated: 2 conflicting context pair(s) with node memory, 5 node(s) had untolerated taint(s). no new claims to deallocate, preemption: 0/6 nodes are available: 1 No preemption victims found for incoming pod, 5 Preemption is not helpful for scheduling."
0.06,Pod,ADDED,eval-conflicts-rho030-r8-000-bvzj9,phase=Pending node=None
0.0606,Event,ADDED,eval-conflicts-rho010-r0-028-gfz56.18d4663f5d38f64b,"reason=FailedScheduling count=None msg=0/6 nodes are available: 2 c_wall violated: 1 conflicting context pair(s) with node memory, 4 node(s) had untolerated taint(s). no new claims to deallocate, preemption: 0/6 nodes are available: 2 No preemption victims found for incoming pod, 4 Preemption is not helpful for scheduling."
0.0609,Event,ADDED,eval-conflicts-rho010-r0-032-6zslz.18d466404b77ca0d,"reason=FailedScheduling count=None msg=0/6 nodes are available: 2 c_wall violated: 1 conflicting context pair(s) with node memory, 4 node(s) had untolerated taint(s). no new claims to deallocate, preemption: 0/6 nodes are available: 2 No preemption victims found for incoming pod, 4 Preemption is not helpful for scheduling."
0.0615,Event,ADDED,eval-conflicts-rho010-r0-050-mhqmc.18d466447c820208,"reason=FailedScheduling count=None msg=0/6 nodes are available: 1 c_wall violated: 1 conflicting context pair(s) with node memory, 1 c_wall violated: 2 conflicting context pair(s) with node memory, 4 node(s) had untolerated taint(s). no new claims to deallocate, preemption: 0/6 nodes are available: 2 No preemption victims found for incoming pod, 4 Preemption is not helpful for scheduling."
0.0617,Event,ADDED,eval-conflicts-rho010-r0-050-mhqmc.18d46644ff0a0aa0,"reason=FailedScheduling count=None msg=0/6 nodes are available: 1 c_wall violated: 2 conflicting context pair(s) with node memory, 5 node(s) had untolerated taint(s). no new claims to deallocate, preemption: 0/6 nodes are available: 1 No preemption victims found for incoming pod, 5 Preemption is not helpful for scheduling."
0.062,Event,ADDED,eval-conflicts-rho010-r0-057-5rfpp.18d4664625e55eaa,"reason=FailedScheduling count=None msg=0/6 nodes are available: 1 c_wall violated: 1 conflicting context pair(s) with node memory, 5 node(s) had untolerated taint(s). no new claims to deallocate, preemption: 0/6 nodes are available: 1 No preemption victims found for incoming pod, 5 Preemption is not helpful for scheduling."
0.0626,Job,MODIFIED,eval-conflicts-rho030-r8-000,
0.0629,Event,ADDED,eval-conflicts-rho010-r0-059-rd4p2.18d4664694def1d0,"reason=FailedScheduling count=None msg=0/6 nodes are available: 1 c_wall violated: 1 conflicting context pair(s) with node memory, 5 node(s) had untolerated taint(s). no new claims to deallocate, preemption: 0/6 nodes are available: 1 No preemption victims found for incoming pod, 5 Preemption is not helpful for scheduling."
0.0631,Event,ADDED,eval-conflicts-rho010-r0-068-28f66.18d46648addf7dbb,"reason=FailedScheduling count=None msg=0/6 nodes are available: 2 c_wall violated: 1 conflicting context pair(s) with node memory, 4 node(s) had untolerated taint(s). no new claims to deallocate, preemption: 0/6 nodes are available: 2 No preemption victims found for incoming pod, 4 Preemption is not helpful for scheduling."
0.0633,Event,ADDED,eval-conflicts-rho010-r0-068-28f66.18d46649aa2e1b13,"reason=FailedScheduling count=None msg=0/6 nodes are available: 1 c_wall violated: 1 conflicting context pair(s) with node memory, 5 node(s) had untolerated taint(s). no new claims to deallocate, preemption: 0/6 nodes are available: 1 No preemption victims found for incoming pod, 5 Preemption is not helpful for scheduling."
0.0638,Event,ADDED,eval-conflicts-rho010-r0-088-kqdcz.18d4664d555c0ea5,"reason=FailedScheduling count=None msg=0/6 nodes are available: 1 c_wall violated: 1 conflicting context pair(s) with node memory, 5 node(s) had untolerated taint(s). no new claims to deallocate, preemption: 0/6 nodes are available: 1 No preemption victims found for incoming pod, 5 Preemption is not helpful for scheduling."
0.064,Event,ADDED,eval-conflicts-rho010-r0-091-wj8jk.18d4664e07d44fad,"reason=FailedScheduling count=None msg=0/6 nodes are available: 1 c_wall violated: 1 conflicting context pair(s) with node memory, 5 node(s) had untolerated taint(s). no new claims to deallocate, preemption: 0/6 nodes are available: 1 No preemption victims found for incoming pod, 5 Preemption is not helpful for scheduling."
0.0642,Event,ADDED,eval-conflicts-rho010-r0-091-wj8jk.18d4664e78d6da61,"reason=FailedScheduling count=None msg=0/6 nodes are available: 2 c_wall violated: 1 conflicting context pair(s) with node memory, 4 node(s) had untolerated taint(s). no new claims to deallocate, preemption: 0/6 nodes are available: 2 No preemption victims found for incoming pod, 4 Preemption is not helpful for scheduling."
0.0644,TaskRequest,MODIFIED,eval-conflicts-rho030-r8-000,phase=Scheduled job=None
0.0647,Event,ADDED,eval-conflicts-rho010-r0-091-wj8jk.18d4664e8d63901f,"reason=FailedScheduling count=None msg=0/6 nodes are available: 1 c_wall violated: 1 conflicting context pair(s) with node memory, 5 node(s) had untolerated taint(s). no new claims to deallocate, preemption: 0/6 nodes are available: 1 No preemption victims found for incoming pod, 5 Preemption is not helpful for scheduling."
0.0649,Event,ADDED,eval-conflicts-rho010-r0-099-kxkzl.18d4664fe52ac8a1,"reason=FailedScheduling count=None msg=0/6 nodes are available: 2 c_wall violated: 1 conflicting context pair(s) with node memory, 4 node(s) had untolerated taint(s). no new claims to deallocate, preemption: 0/6 nodes are available: 2 No preemption victims found for incoming pod, 4 Preemption is not helpful for scheduling."
0.0651,Event,ADDED,eval-conflicts-rho010-r0-099-kxkzl.18d46650c96df63f,"reason=FailedScheduling count=None msg=0/6 nodes are available: 1 c_wall violated: 1 conflicting context pair(s) with node memory, 5 node(s) had untolerated taint(s). no new claims to deallocate, preemption: 0/6 nodes are available: 1 No preemption victims found for incoming pod, 5 Preemption is not helpful for scheduling."
0.0656,Event,ADDED,eval-conflicts-rho010-r1-015-nzvvk.18d4665efcf65c4c,"reason=FailedScheduling count=None msg=0/6 nodes are available: 1 c_wall violated: 1 conflicting context pair(s) with node memory, 5 node(s) had untolerated taint(s). no new claims to deallocate, preemption: 0/6 nodes are available: 1 No preemption victims found for incoming pod, 5 Preemption is not helpful for scheduling."
0.0658,Event,ADDED,eval-conflicts-rho010-r1-015-nzvvk.18d4665f4e275e90,"reason=FailedScheduling count=None msg=0/6 nodes are available: 2 c_wall violated: 1 conflicting context pair(s) with node memory, 4 node(s) had untolerated taint(s). no new claims to deallocate, preemption: 0/6 nodes are available: 2 No preemption victims found for incoming pod, 4 Preemption is not helpful for scheduling."
0.0663,Event,ADDED,eval-conflicts-rho010-r1-021-npl92.18d4665efd20df7f,"reason=FailedScheduling count=None msg=0/6 nodes are available: 1 c_wall violated: 1 conflicting context pair(s) with node memory, 5 node(s) had untolerated taint(s). no new claims to deallocate, preemption: 0/6 nodes are available: 1 No preemption victims found for incoming pod, 5 Preemption is not helpful for scheduling."
0.0665,Event,ADDED,eval-conflicts-rho010-r1-023-n8cpf.18d4665f08d24cd6,"reason=FailedScheduling count=None msg=0/6 nodes are available: 1 c_wall violated: 1 conflicting context pair(s) with node memory, 5 node(s) had untolerated taint(s). no new claims to deallocate, preemption: 0/6 nodes are available: 1 No preemption victims found for incoming pod, 5 Preemption is not helpful for scheduling."
0.0667,Event,ADDED,eval-conflicts-rho010-r1-023-n8cpf.18d4665f4e7c4cad,"reason=FailedScheduling count=None msg=0/6 nodes are available: 2 c_wall violated: 1 conflicting context pair(s) with node memory, 4 node(s) had untolerated taint(s). no new claims to deallocate, preemption: 0/6 nodes are available: 2 No preemption victims found for incoming pod, 4 Preemption is not helpful for scheduling."
0.0671,Event,ADDED,eval-conflicts-rho010-r1-046-4ccdd.18d466645f4fe358,"reason=FailedScheduling count=None msg=0/6 nodes are available: 1 c_wall violated: 1 conflicting context pair(s) with node memory, 5 node(s) had untolerated taint(s). no new claims to deallocate, preemption: 0/6 nodes are available: 1 No preemption victims found for incoming pod, 5 Preemption is not helpful for scheduling."
0.0673,Event,ADDED,eval-conflicts-rho010-r1-082-5247m.18d4666cc1e72a3b,"reason=FailedScheduling count=None msg=0/6 nodes are available: 1 c_wall violated: 1 conflicting context pair(s) with node memory, 1 c_wall violated: 2 conflicting context pair(s) with node memory, 4 node(s) had untolerated taint(s). no new claims to deallocate, preemption: 0/6 nodes are available: 2 No preemption victims found for incoming pod, 4 Preemption is not helpful for scheduling."
0.0675,Event,ADDED,eval-conflicts-rho010-r1-082-5247m.18d4666d1d42e46d,"reason=FailedScheduling count=None msg=0/6 nodes are available: 1 c_wall violated: 1 conflicting context pair(s) with node memory, 5 node(s) had untolerated taint(s). no new claims to deallocate, preemption: 0/6 nodes are available: 1 No preemption victims found for incoming pod, 5 Preemption is not helpful for scheduling."
0.0678,Event,ADDED,eval-conflicts-rho010-r1-085-tdjwc.18d4666d76f07b1a,"reason=FailedScheduling count=None msg=0/6 nodes are available: 1 c_wall violated: 1 conflicting context pair(s) with node memory, 5 node(s) had untolerated taint(s). no new claims to deallocate, preemption: 0/6 nodes are available: 1 No preemption victims found for incoming pod, 5 Preemption is not helpful for scheduling."
0.068,Event,ADDED,eval-conflicts-rho010-r2-000-2cmcc.18d466793833b8a6,reason=Scheduled count=None msg=Successfully assigned compute/eval-conflicts-rho010-r2-000-2cmcc to kind-worker
0.0682,Event,ADDED,eval-conflicts-rho010-r2-000-2cmcc.18d4667951872c7b,"reason=Pulled count=1 msg=Container image ""busybox:musl"" already present on machine"
0.0684,Event,ADDED,eval-conflicts-rho010-r2-000-2cmcc.18d4667952adb0e1,reason=Created count=1 msg=Created container: task
0.0687,Event,ADDED,eval-conflicts-rho010-r2-000-2cmcc.18d46679568118bc,reason=Started count=1 msg=Started container task
0.0689,Event,ADDED,eval-conflicts-rho010-r2-000.18d46679375eb763,reason=SuccessfulCreate count=1 msg=Created pod: eval-conflicts-rho010-r2-000-2cmcc
0.0691,Event,ADDED,eval-conflicts-rho010-r2-000.18d4667c9a45ccd6,reason=Completed count=1 msg=Job completed
0.0694,Event,ADDED,eval-conflicts-rho010-r2-001-8cf4q.18d466797233f039,reason=Scheduled count=None msg=Successfully assigned compute/eval-conflicts-rho010-r2-001-8cf4q to kind-worker5
0.0695,Event,ADDED,eval-conflicts-rho010-r2-001-8cf4q.18d466798d3f5e0b,"reason=Pulled count=1 msg=Container image ""busybox:musl"" already present on machine"
0.0697,Event,ADDED,eval-conflicts-rho010-r2-001-8cf4q.18d466798e4bfae3,reason=Created count=1 msg=Created container: task
0.07,Event,ADDED,eval-conflicts-rho010-r2-001-8cf4q.18d466799153e89d,reason=Started count=1 msg=Started container task
0.0705,Event,ADDED,eval-conflicts-rho010-r2-001.18d46679711c7ee3,reason=SuccessfulCreate count=1 msg=Created pod: eval-conflicts-rho010-r2-001-8cf4q
0.071,Event,ADDED,eval-conflicts-rho010-r2-001.18d4667ca9d441be,reason=Completed count=1 msg=Job completed
0.0713,Event,ADDED,eval-conflicts-rho010-r2-002-z8jpk.18d46679ad352735,reason=Scheduled count=None msg=Successfully assigned compute/eval-conflicts-rho010-r2-002-z8jpk to kind-worker5
0.0717,Event,ADDED,eval-conflicts-rho010-r2-002-z8jpk.18d46679cb3b0215,"reason=Pulled count=1 msg=Container image ""busybox:musl"" already present on machine"
0.072,Event,ADDED,eval-conflicts-rho010-r2-002-z8jpk.18d46679cc851058,reason=Created count=1 msg=Created container: task
0.0722,Event,ADDED,eval-conflicts-rho010-r2-002-z8jpk.18d46679d2f978f0,reason=Started count=1 msg=Started container task
0.0725,Event,ADDED,eval-conflicts-rho010-r2-002.18d46679ac00d4c9,reason=SuccessfulCreate count=1 msg=Created pod: eval-conflicts-rho010-r2-002-z8jpk
0.0734,Pod,MODIFIED,eval-conflicts-rho030-r8-000-bvzj9,phase=Pending node=kind-worker
0.0739,Event,ADDED,eval-conflicts-rho010-r2-002.18d4667ce5ae286c,reason=Completed count=1 msg=Job completed
0.0741,Event,ADDED,eval-conflicts-rho010-r2-003-8vm9l.18d46679e90c033e,reason=Scheduled count=None msg=Successfully assigned compute/eval-conflicts-rho010-r2-003-8vm9l to kind-worker
0.0743,Event,ADDED,eval-conflicts-rho010-r2-003-8vm9l.18d4667a04d38cc8,"reason=Pulled count=1 msg=Container image ""busybox:musl"" already present on machine"
0.0747,Event,ADDED,eval-conflicts-rho010-r2-003-8vm9l.18d4667a05e7b991,reason=Created count=1 msg=Created container: task
0.0749,Event,ADDED,eval-conflicts-rho010-r2-003-8vm9l.18d4667a07f51924,reason=Started count=1 msg=Started container task
0.0752,Event,ADDED,eval-conflicts-rho010-r2-003.18d46679e819fb3f,reason=SuccessfulCreate count=1 msg=Created pod: eval-conflicts-rho010-r2-003-8vm9l
0.0754,Event,ADDED,eval-conflicts-rho010-r2-003.18d4667d4d4a934f,reason=Completed count=1 msg=Job completed
0.0757,Event,ADDED,eval-conflicts-rho010-r2-004-8hg2q.18d4667a23cddb53,reason=Scheduled count=None msg=Successfully assigned compute/eval-conflicts-rho010-r2-004-8hg2q to kind-worker2
0.0759,Event,ADDED,eval-conflicts-rho010-r2-004-8hg2q.18d4667a3d49c675,"reason=Pulled count=1 msg=Container image ""busybox:musl"" already present on machine"
0.0768,Event,ADDED,eval-conflicts-rho010-r2-004-8hg2q.18d4667a3ef2e3f4,reason=Created count=1 msg=Created container: task
0.077,Event,ADDED,eval-conflicts-rho010-r2-004-8hg2q.18d4667a443d6755,reason=Started count=1 msg=Started container task
0.0774,Event,ADDED,eval-conflicts-rho010-r2-004.18d4667a23248376,reason=SuccessfulCreate count=1 msg=Created pod: eval-conflicts-rho010-r2-004-8hg2q
0.0781,Event,ADDED,eval-conflicts-rho010-r2-004.18d4667d61383bd3,reason=Completed count=1 msg=Job completed
0.0783,Event,ADDED,eval-conflicts-rho010-r2-005-wv2jl.18d4667a60092644,reason=Scheduled count=None msg=Successfully assigned compute/eval-conflicts-rho010-r2-005-wv2jl to kind-worker2
0.0786,Event,ADDED,eval-conflicts-rho010-r2-005-wv2jl.18d4667a7bdb2b05,"reason=Pulled count=1 msg=Container image ""busybox:musl"" already present on machine"
0.0788,Event,ADDED,eval-conflicts-rho010-r2-005-wv2jl.18d4667a7cf09798,reason=Created count=1 msg=Created container: task
0.079,Event,ADDED,eval-conflicts-rho010-r2-005-wv2jl.18d4667a7ed2f401,reason=Started count=1 msg=Started container task
0.0791,Event,ADDED,eval-conflicts-rho010-r2-005.18d4667a5f00b9f4,reason=SuccessfulCreate count=1 msg=Created pod: eval-conflicts-rho010-r2-005-wv2jl
0.0795,Event,ADDED,eval-conflicts-rho010-r2-005.18d4667d9db98599,reason=Completed count=1 msg=Job completed
0.0797,Event,ADDED,eval-conflicts-rho010-r2-006-z92tk.18d4667a9e958c1b,reason=Scheduled count=None msg=Successfully assigned compute/eval-conflicts-rho010-r2-006-z92tk to kind-worker
0.0798,Event,ADDED,eval-conflicts-rho010-r2-006-z92tk.18d4667ab722cc55,"reason=Pulled count=1 msg=Container image ""busybox:musl"" already present on machine"
0.08,Event,ADDED,eval-conflicts-rho010-r2-006-z92tk.18d4667ab82fddb4,reason=Created count=1 msg=Created container: task
0.0807,Event,ADDED,eval-conflicts-rho010-r2-006-z92tk.18d4667aba61ba01,reason=Started count=1 msg=Started container task
0.081,Event,ADDED,eval-conflicts-rho010-r2-006.18d4667a9a623259,reason=SuccessfulCreate count=1 msg=Created pod: eval-conflicts-rho010-r2-006-z92tk
0.0814,Event,ADDED,eval-conflicts-rho010-r2-006.18d4667dc7994d5a,reason=Completed count=1 msg=Job completed
0.0817,Event,ADDED,eval-conflicts-rho010-r2-007-htrsq.18d4667ad6a8775f,reason=Scheduled count=None msg=Successfully assigned compute/eval-conflicts-rho010-r2-007-htrsq to kind-worker
0.0819,Event,ADDED,eval-conflicts-rho010-r2-007-htrsq.18d4667aeef4b406,"reason=Pulled count=1 msg=Container image ""busybox:musl"" already present on machine"
0.0821,Event,ADDED,eval-conflicts-rho010-r2-007-htrsq.18d4667aeff91314,reason=Created count=1 msg=Created container: task
0.0822,Event,ADDED,eval-conflicts-rho010-r2-007-htrsq.18d4667af461ef64,reason=Started count=1 msg=Started container task
0.0837,Pod,MODIFIED,eval-conflicts-rho030-r8-000-bvzj9,phase=Pending node=kind-worker
0.0839,Event,ADDED,eval-conflicts-rho010-r2-007.18d4667ad5cb4c7b,reason=SuccessfulCreate count=1 msg=Created pod: eval-conflicts-rho010-r2-007-htrsq
0.0841,Event,ADDED,eval-conflicts-rho010-r2-007.18d4667e037e7894,reason=Completed count=1 msg=Job completed
0.0843,Event,ADDED,eval-conflicts-rho010-r2-008-p6x8j.18d4667b12c66eaf,reason=Scheduled count=None msg=Successfully assigned compute/eval-conflicts-rho010-r2-008-p6x8j to kind-worker4
0.0847,Event,ADDED,eval-conflicts-rho010-r2-008-p6x8j.18d4667b2be88c87,"reason=Pulled count=1 msg=Container image ""busybox:musl"" already present on machine"
0.0849,Event,ADDED,eval-conflicts-rho010-r2-008-p6x8j.18d4667b2cf35b14,reason=Created count=1 msg=Created container: task
0.0851,Event,ADDED,eval-conflicts-rho010-r2-008-p6x8j.18d4667b311189ac,reason=Started count=1 msg=Started container task
0.0853,Event,ADDED,eval-conflicts-rho010-r2-008.18d4667b11f91169,reason=SuccessfulCreate count=1 msg=Created pod: eval-conflicts-rho010-r2-008-p6x8j
0.0857,Event,ADDED,eval-conflicts-rho010-r2-008.18d4667e564c5615,reason=Completed count=1 msg=Job completed
0.0861,Event,ADDED,eval-conflicts-rho010-r2-009-jd7xh.18d4667b4f899833,reason=Scheduled count=None msg=Successfully assigned compute/eval-conflicts-rho010-r2-009-jd7xh to kind-worker3
0.0863,Event,ADDED,eval-conflicts-rho010-r2-009-jd7xh.18d4667b6a9cd7cc,"reason=Pulled count=1 msg=Container image ""busybox:musl"" already present on machine"
0.0865,Event,ADDED,eval-conflicts-rho010-r2-009-jd7xh.18d4667b6bd90dc8,reason=Created count=1 msg=Created container: task
0.0878,Node,MODIFIED,kind-worker,taints=0
0.0881,Event,ADDED,eval-conflicts-rho010-r2-009-jd7xh.18d4667b6f784eb0,reason=Started count=1 msg=Started container task
0.0883,Event,ADDED,eval-conflicts-rho010-r2-009.18d4667b4e87c630,reason=SuccessfulCreate count=1 msg=Created pod: eval-conflicts-rho010-r2-009-jd7xh
0.0885,Event,ADDED,eval-conflicts-rho010-r2-009.18d4667eb6e753a7,reason=Completed count=1 msg=Job completed
0.0888,Event,ADDED,eval-conflicts-rho010-r2-010-g4gkq.18d4667b8a1694d2,reason=Scheduled count=None msg=Successfully assigned compute/eval-conflicts-rho010-r2-010-g4gkq to kind-worker4
0.089,Event,ADDED,eval-conflicts-rho010-r2-010-g4gkq.18d4667ba32a9ace,"reason=Pulled count=1 msg=Container image ""busybox:musl"" already present on machine"
0.0892,Event,ADDED,eval-conflicts-rho010-r2-010-g4gkq.18d4667ba4553ca4,reason=Created count=1 msg=Created container: task
0.0894,Event,ADDED,eval-conflicts-rho010-r2-010-g4gkq.18d4667ba934e72d,reason=Started count=1 msg=Started container task
0.0897,Event,ADDED,eval-conflicts-rho010-r2-010.18d4667b8984189f,reason=SuccessfulCreate count=1 msg=Created pod: eval-conflicts-rho010-r2-010-g4gkq
0.0899,Event,ADDED,eval-conflicts-rho010-r2-010.18d4667ecdd50d4a,reason=Completed count=1 msg=Job completed
0.0901,Event,ADDED,eval-conflicts-rho010-r2-011-p8jbw.18d4667bc86fa1bd,"reason=FailedScheduling count=None msg=0/6 nodes are available: 6 node(s) had untolerated taint(s). no new claims to deallocate, preemption: 0/6 nodes are available: 6 Preemption is not helpful for scheduling."
0.0902,Event,ADDED,eval-conflicts-rho010-r2-011-p8jbw.18d4667db600fd20,reason=Scheduled count=None msg=Successfully assigned compute/eval-conflicts-rho010-r2-011-p8jbw to kind-worker
0.0905,Event,ADDED,eval-conflicts-rho010-r2-011-p8jbw.18d4667dd0e2ef51,"reason=Pulled count=1 msg=Container image ""busybox:musl"" already present on machine"
0.0907,Event,ADDED,eval-conflicts-rho010-r2-011-p8jbw.18d4667dd4327601,reason=Created count=1 msg=Created container: task
0.0909,Event,ADDED,eval-conflicts-rho010-r2-011-p8jbw.18d4667dd687f65a,reason=Started count=1 msg=Started container task
0.0912,Event,ADDED,eval-conflicts-rho010-r2-011.18d4667bc864be95,reason=SuccessfulCreate count=1 msg=Created pod: eval-conflicts-rho010-r2-011-p8jbw
0.0913,Event,ADDED,eval-conflicts-rho010-r2-011.18d466810b261fa1,reason=Completed count=1 msg=Job completed
0.0915,Event,ADDED,eval-conflicts-rho010-r2-012-hnh5n.18d4667c00206b4a,"reason=FailedScheduling count=None msg=0/6 nodes are available: 6 node(s) had untolerated taint(s). no new claims to deallocate, preemption: 0/6 nodes are available: 6 Preemption is not helpful for scheduling."
0.0916,Event,ADDED,eval-conflicts-rho010-r2-012-hnh5n.18d4667db6861f03,reason=Scheduled count=None msg=Successfully assigned compute/eval-conflicts-rho010-r2-012-hnh5n to kind-worker
0.0918,Event,ADDED,eval-conflicts-rho010-r2-012-hnh5n.18d4667dd2aa9a64,"reason=Pulled count=1 msg=Container image ""busybox:musl"" already present on machine"
0.092,Event,ADDED,eval-conflicts-rho010-r2-012-hnh5n.18d4667dd6a7554f,reason=Created count=1 msg=Created container: task
0.0922,Event,ADDED,eval-conflicts-rho010-r2-012-hnh5n.18d4667dd8e956b5,reason=Started count=1 msg=Started container task
0.0926,Event,ADDED,eval-conflicts-rho010-r2-012.18d4667c0013815f,reason=SuccessfulCreate count=1 msg=Created pod: eval-conflicts-rho010-r2-012-hnh5n
0.0928,Event,ADDED,eval-conflicts-rho010-r2-012.18d46680cff731c3,reason=Completed count=1 msg=Job completed
0.0929,Event,ADDED,eval-conflicts-rho010-r2-013-6j5q7.18d4667c3ce5011f,"reason=FailedScheduling count=None msg=0/6 nodes are available: 6 node(s) had untolerated taint(s). no new claims to deallocate, preemption: 0/6 nodes are available: 6 Preemption is not helpful for scheduling."
0.0931,Event,ADDED,eval-conflicts-rho010-r2-013-6j5q7.18d4667db6e39669,reason=Scheduled count=None msg=Successfully assigned compute/eval-conflicts-rho010-r2-013-6j5q7 to kind-worker
0.0934,Event,ADDED,eval-conflicts-rho010-r2-013-6j5q7.18d4667dd422b03d,"reason=Pulled count=1 msg=Container image ""busybox:musl"" already present on machine"
0.0936,Event,ADDED,eval-conflicts-rho010-r2-013-6j5q7.18d4667dd8e956a1,reason=Created count=1 msg=Created container: task
0.0938,Event,ADDED,eval-conflicts-rho010-r2-013-6j5q7.18d4667ddbeec738,reason=Started count=1 msg=Started container task
0.0941,Event,ADDED,eval-conflicts-rho010-r2-013.18d4667c3cdbb598,reason=SuccessfulCreate count=1 msg=Created pod: eval-conflicts-rho010-r2-013-6j5q7
0.0942,Event,ADDED,eval-conflicts-rho010-r2-013.18d466810b50072d,reason=Completed count=1 msg=Job completed
0.0944,Event,ADDED,eval-conflicts-rho010-r2-014-zv9d5.18d4667c77133b8c,"reason=FailedScheduling count=None msg=0/6 nodes are available: 6 node(s) had untolerated taint(s). no new claims to deallocate, preemption: 0/6 nodes are available: 6 Preemption is not helpful for scheduling."
0.0946,Event,ADDED,eval-conflicts-rho010-r2-014-zv9d5.18d4667db70b06d7,reason=Scheduled count=None msg=Successfully assigned compute/eval-conflicts-rho010-r2-014-zv9d5 to kind-worker
0.0948,Event,ADDED,eval-conflicts-rho010-r2-014-zv9d5.18d4667dd322ed2b,"reason=Pulled count=1 msg=Container image ""busybox:musl"" already present on machine"
0.0953,Event,ADDED,eval-conflicts-rho010-r2-014-zv9d5.18d4667dd78a8a96,reason=Created count=1 msg=Created container: task
0.0955,Event,ADDED,eval-conflicts-rho010-r2-014-zv9d5.18d4667dd9d42968,reason=Started count=1 msg=Started container task
0.0957,Event,ADDED,eval-conflicts-rho010-r2-014.18d4667c7709644a,reason=SuccessfulCreate count=1 msg=Created pod: eval-conflicts-rho010-r2-014-zv9d5
0.096,Event,ADDED,eval-conflicts-rho010-r2-014.18d466814944b6d1,reason=Completed count=1 msg=Job completed
0.0962,Event,ADDED,eval-conflicts-rho010-r2-015-6jnsj.18d4667cb2b53258,"reason=FailedScheduling count=None msg=0/6 nodes are available: 6 node(s) had untolerated taint(s). no new claims to deallocate, preemption: 0/6 nodes are available: 6 Preemption is not helpful for scheduling."
0.0963,Event,ADDED,eval-conflicts-rho010-r2-015-6jnsj.18d4667db737a349,reason=Scheduled count=None msg=Successfully assigned compute/eval-conflicts-rho010-r2-015-6jnsj to kind-worker
0.0966,Event,ADDED,eval-conflicts-rho010-r2-015-6jnsj.18d4667dd34a5a7a,"reason=Pulled count=1 msg=Container image ""busybox:musl"" already present on machine"
0.0968,Event,ADDED,eval-conflicts-rho010-r2-015-6jnsj.18d4667dd7fc60a6,reason=Created count=1 msg=Created container: task
0.097,Event,ADDED,eval-conflicts-rho010-r2-015-6jnsj.18d4667dda57cd91,reason=Started count=1 msg=Started container task
0.0972,Event,ADDED,eval-conflicts-rho010-r2-015.18d4667cb2ab9c75,reason=SuccessfulCreate count=1 msg=Created pod: eval-conflicts-rho010-r2-015-6jnsj
0.0984,Node,MODIFIED,kind-worker,taints=0
0.0987,Event,ADDED,eval-conflicts-rho010-r2-015.18d466810ae08195,reason=Completed count=1 msg=Job completed
0.0989,Event,ADDED,eval-conflicts-rho010-r2-016-5wvrw.18d4667cee7b75d9,"reason=FailedScheduling count=None msg=0/6 nodes are available: 6 node(s) had untolerated taint(s). no new claims to deallocate, preemption: 0/6 nodes are available: 6 Preemption is not helpful for scheduling."
0.099,Event,ADDED,eval-conflicts-rho010-r2-016-5wvrw.18d4667db76bccb4,reason=Scheduled count=None msg=Successfully assigned compute/eval-conflicts-rho010-r2-016-5wvrw to kind-worker
0.0993,Event,ADDED,eval-conflicts-rho010-r2-016-5wvrw.18d4667dd443ac6f,"reason=Pulled count=1 msg=Container image ""busybox:musl"" already present on machine"
0.0995,Event,ADDED,eval-conflicts-rho010-r2-016-5wvrw.18d4667dd9107b42,reason=Created count=1 msg=Created container: task
0.0997,Event,ADDED,eval-conflicts-rho010-r2-016-5wvrw.18d4667ddc17eb34,reason=Started count=1 msg=Started container task
0.0998,Event,ADDED,eval-conflicts-rho010-r2-016.18d4667cee715266,reason=SuccessfulCreate count=1 msg=Created pod: eval-conflicts-rho010-r2-016-5wvrw
0.1001,Event,ADDED,eval-conflicts-rho010-r2-016.18d46680d1632d36,reason=Completed count=1 msg=Job completed
0.1002,Event,ADDED,eval-conflicts-rho010-r2-017-kxhcw.18d4667d2a1059f4,"reason=FailedScheduling count=None msg=0/6 nodes are available: 6 node(s) had untolerated taint(s). no new claims to deallocate, preemption: 0/6 nodes are available: 6 Preemption is not helpful for scheduling."
0.1004,Event,ADDED,eval-conflicts-rho010-r2-017-kxhcw.18d4667db732cb51,"reason=FailedScheduling count=None msg=0/6 nodes are available: 1 c_wall violated: 1 conflicting context pair(s) with node memory, 5 node(s) had untolerated taint(s). no new claims to deallocate, preemption: 0/6 nodes are available: 1 No preemption victims found for incoming pod, 5 Preemption is not helpful for scheduling."
0.1007,Event,ADDED,eval-conflicts-rho010-r2-017-kxhcw.18d4667dbc55d293,"reason=FailedScheduling count=None msg=0/6 nodes are available: 1 c_wall violated: 1 conflicting context pair(s) with node memory, 5 node(s) had untolerated taint(s). no new claims to deallocate, preemption: 0/6 nodes are available: 1 No preemption victims found for incoming pod, 5 Preemption is not helpful for scheduling."
0.1009,Event,ADDED,eval-conflicts-rho010-r2-017-kxhcw.18d4667dc627c8ce,reason=Scheduled count=None msg=Successfully assigned compute/eval-conflicts-rho010-r2-017-kxhcw to kind-worker2
0.1011,Event,ADDED,eval-conflicts-rho010-r2-017-kxhcw.18d4667dde722227,"reason=Pulled count=1 msg=Container image ""busybox:musl"" already present on machine"
0.1012,Event,ADDED,eval-conflicts-rho010-r2-017-kxhcw.18d4667ddfcbc99b,reason=Created count=1 msg=Created container: task
0.1015,Event,ADDED,eval-conflicts-rho010-r2-017-kxhcw.18d4667de4a8ae15,reason=Started count=1 msg=Started container task
0.1016,Event,ADDED,eval-conflicts-rho010-r2-017.18d4667d2a01d556,reason=SuccessfulCreate count=1 msg=Created pod: eval-conflicts-rho010-r2-017-kxhcw
0.1018,Event,ADDED,eval-conflicts-rho010-r2-017.18d466815d69a55d,reason=Completed count=1 msg=Job completed
0.1021,Event,ADDED,eval-conflicts-rho010-r2-018-xkgj8.18d4667d655c3027,"reason=FailedScheduling count=None msg=0/6 nodes are available: 6 node(s) had untolerated taint(s). no new claims to deallocate, preemption: 0/6 nodes are available: 6 Preemption is not helpful for scheduling."
0.1023,Event,ADDED,eval-conflicts-rho010-r2-018-xkgj8.18d4667dbc3b3a96,reason=Scheduled count=None msg=Successfully assigned compute/eval-conflicts-rho010-r2-018-xkgj8 to kind-worker
0.1024,Event,ADDED,eval-conflicts-rho010-r2-018-xkgj8.18d4667dd5c44ce5,"reason=Pulled count=1 msg=Container image ""busybox:musl"" already present on machine"
0.1026,Event,ADDED,eval-conflicts-rho010-r2-018-xkgj8.18d4667dd9853b34,reason=Created count=1 msg=Created container: task
0.1029,Event,ADDED,eval-conflicts-rho010-r2-018-xkgj8.18d4667ddc8aeca6,reason=Started count=1 msg=Started container task
0.1031,Event,ADDED,eval-conflicts-rho010-r2-018.18d4667d65557d56,reason=SuccessfulCreate count=1 msg=Created pod: eval-conflicts-rho010-r2-018-xkgj8
0.1033,Event,ADDED,eval-conflicts-rho010-r2-018.18d46680d1018496,reason=Completed count=1 msg=Job completed
0.1036,Event,ADDED,eval-conflicts-rho010-r2-019-h8jh9.18d4667da1d67dff,"reason=FailedScheduling count=None msg=0/6 nodes are available: 6 node(s) had untolerated taint(s). no new claims to deallocate, preemption: 0/6 nodes are available: 6 Preemption is not helpful for scheduling."
0.1037,Event,ADDED,eval-conflicts-rho010-r2-019-h8jh9.18d4667dbc80ac3f,reason=Scheduled count=None msg=Successfully assigned compute/eval-conflicts-rho010-r2-019-h8jh9 to kind-worker
0.1039,Event,ADDED,eval-conflicts-rho010-r2-019-h8jh9.18d4667dd693656c,"reason=Pulled count=1 msg=Container image ""busybox:musl"" already present on machine"
0.1044,Event,ADDED,eval-conflicts-rho010-r2-019-h8jh9.18d4667dd9ce92e6,reason=Created count=1 msg=Created container: task
0.1048,Event,ADDED,eval-conflicts-rho010-r2-019-h8jh9.18d4667ddd08bbda,reason=Started count=1 msg=Started container task
0.105,Event,ADDED,eval-conflicts-rho010-r2-019.18d4667da1cb6e7c,reason=SuccessfulCreate count=1 msg=Created pod: eval-conflicts-rho010-r2-019-h8jh9
0.1051,Event,ADDED,eval-conflicts-rho010-r2-019.18d466810afe0b4c,reason=Completed count=1 msg=Job completed
0.1053,Event,ADDED,eval-conflicts-rho010-r2-020-pms92.18d4667ddeaed2e8,reason=Scheduled count=None msg=Successfully assigned compute/eval-conflicts-rho010-r2-020-pms92 to kind-worker2
0.1055,Event,ADDED,eval-conflicts-rho010-r2-020-pms92.18d4667df902f2ee,"reason=Pulled count=1 msg=Container image ""busybox:musl"" already present on machine"
0.1057,Event,ADDED,eval-conflicts-rho010-r2-020-pms92.18d4667dfa0eec1a,reason=Created count=1 msg=Created container: task
0.1059,Event,ADDED,eval-conflicts-rho010-r2-020-pms92.18d4667e00730888,reason=Started count=1 msg=Started container task
0.106,Event,ADDED,eval-conflicts-rho010-r2-020.18d4667ddce6160a,reason=SuccessfulCreate count=1 msg=Created pod: eval-conflicts-rho010-r2-020-pms92
0.1063,Event,ADDED,eval-conflicts-rho010-r2-020.18d466815923a16b,reason=Completed count=1 msg=Job completed
0.1065,Event,ADDED,eval-conflicts-rho010-r2-021-mhhv5.18d4667e190b4351,reason=Scheduled count=None msg=Successfully assigned compute/eval-conflicts-rho010-r2-021-mhhv5 to kind-worker2
0.1067,Event,ADDED,eval-conflicts-rho010-r2-021-mhhv5.18d4667e328665c0,"reason=Pulled count=1 msg=Container image ""busybox:musl"" already present on machine"
0.107,Event,ADDED,eval-conflicts-rho010-r2-021-mhhv5.18d4667e33a0cfc4,reason=Created count=1 msg=Created container: task
0.1072,Event,ADDED,eval-conflicts-rho010-r2-021-mhhv5.18d4667e3a044cd5,reason=Started count=1 msg=Started container task
0.1074,Event,ADDED,eval-conflicts-rho010-r2-021.18d4667e18380036,reason=SuccessfulCreate count=1 msg=Created pod: eval-conflicts-rho010-r2-021-mhhv5
0.1076,Event,ADDED,eval-conflicts-rho010-r2-021.18d46681596cc3de,reason=Completed count=1 msg=Job completed
0.1079,Event,ADDED,eval-conflicts-rho010-r2-022-btntv.18d4667e556bce3d,reason=Scheduled count=None msg=Successfully assigned compute/eval-conflicts-rho010-r2-022-btntv to kind-worker2
0.1081,Event,ADDED,eval-conflicts-rho010-r2-022-btntv.18d4667e6eb1d812,"reason=Pulled count=1 msg=Container image ""busybox:musl"" already present on machine"
0.1083,Event,ADDED,eval-conflicts-rho010-r2-022-btntv.18d4667e6fbb41c0,reason=Created count=1 msg=Created container: task
0.1086,Event,ADDED,eval-conflicts-rho010-r2-022-btntv.18d4667e76658488,reason=Started count=1 msg=Started container task
0.1088,Event,ADDED,eval-conflicts-rho010-r2-022.18d4667e549c01fb,reason=SuccessfulCreate count=1 msg=Created pod: eval-conflicts-rho010-r2-022-btntv
0.1089,Event,ADDED,eval-conflicts-rho010-r2-022.18d466815a6a4dcc,reason=Completed count=1 msg=Job completed
0.1091,Event,ADDED,eval-conflicts-rho010-r2-023-6cw56.18d4667e904bbbb7,reason=Scheduled count=None msg=Successfully assigned compute/eval-conflicts-rho010-r2-023-6cw56 to kind-worker2
0.1097,Event,ADDED,eval-conflicts-rho010-r2-023-6cw56.18d4667ea9b162d8,"reason=Pulled count=1 msg=Container image ""busybox:musl"" already present on machine"
0.1099,Event,ADDED,eval-conflicts-rho010-r2-023-6cw56.18d4667eaacc992c,reason=Created count=1 msg=Created container: task
0.11,Event,ADDED,eval-conflicts-rho010-r2-023-6cw56.18d4667eacb9e539,reason=Started count=1 msg=Started container task
0.1104,Event,ADDED,eval-conflicts-rho010-r2-023.18d4667e8f7ad31b,reason=SuccessfulCreate count=1 msg=Created pod: eval-conflicts-rho010-r2-023-6cw56
0.1105,Event,ADDED,eval-conflicts-rho010-r2-023.18d46681d731fb1d,reason=Completed count=1 msg=Job completed
0.1107,Event,ADDED,eval-conflicts-rho010-r2-024-c6jk5.18d4667ecc1537ad,reason=Scheduled count=None msg=Successfully assigned compute/eval-conflicts-rho010-r2-024-c6jk5 to kind-worker5
0.1109,Event,ADDED,eval-conflicts-rho010-r2-024-c6jk5.18d4667ee7327fa5,"reason=Pulled count=1 msg=Container image ""busybox:musl"" already present on machine"
0.1111,Event,ADDED,eval-conflicts-rho010-r2-024-c6jk5.18d4667ee84fa267,reason=Created count=1 msg=Created container: task
0.1113,Event,ADDED,eval-conflicts-rho010-r2-024-c6jk5.18d4667eea4d9f2c,reason=Started count=1 msg=Started container task
0.1114,Event,ADDED,eval-conflicts-rho010-r2-024.18d4667ecb151e12,reason=SuccessfulCreate count=1 msg=Created pod: eval-conflicts-rho010-r2-024-c6jk5
0.1116,Event,ADDED,eval-conflicts-rho010-r2-024.18d4668207833cd7,reason=Completed count=1 msg=Job completed
0.1118,Event,ADDED,eval-conflicts-rho010-r2-025-dpqlk.18d4667f0a17708c,reason=Scheduled count=None msg=Successfully assigned compute/eval-conflicts-rho010-r2-025-dpqlk to kind-worker5
0.112,Event,ADDED,eval-conflicts-rho010-r2-025-dpqlk.18d4667f23d9f89a,"reason=Pulled count=1 msg=Container image ""busybox:musl"" already present on machine"
0.1121,Event,ADDED,eval-conflicts-rho010-r2-025-dpqlk.18d4667f24fd34b0,reason=Created count=1 msg=Created container: task
0.1123,Event,ADDED,eval-conflicts-rho010-r2-025-dpqlk.18d4667f26fb2bfa,reason=Started count=1 msg=Started container task
0.1125,Event,ADDED,eval-conflicts-rho010-r2-025.18d4667f08ecd323,reason=SuccessfulCreate count=1 msg=Created pod: eval-conflicts-rho010-r2-025-dpqlk
0.1127,Event,ADDED,eval-conflicts-rho010-r2-025.18d4668243c448c2,reason=Completed count=1 msg=Job completed
0.1128,Event,ADDED,eval-conflicts-rho010-r2-026-j5622.18d4667f43f70f75,reason=Scheduled count=None msg=Successfully assigned compute/eval-conflicts-rho010-r2-026-j5622 to kind-worker5
0.113,Event,ADDED,eval-conflicts-rho010-r2-026-j5622.18d4667f5d25445b,"reason=Pulled count=1 msg=Container image ""busybox:musl"" already present on machine"
0.1132,Event,ADDED,eval-conflicts-rho010-r2-026-j5622.18d4667f5e4e549d,reason=Created count=1 msg=Created container: task
0.1134,Event,ADDED,eval-conflicts-rho010-r2-026-j5622.18d4667f603ec12d,reason=Started count=1 msg=Started container task
0.1136,Event,ADDED,eval-conflicts-rho010-r2-026.18d4667f42bd110a,reason=SuccessfulCreate count=1 msg=Created pod: eval-conflicts-rho010-r2-026-j5622
0.1139,Event,ADDED,eval-conflicts-rho010-r2-026.18d4668279fe020b,reason=Completed count=1 msg=Job completed
0.114,Event,ADDED,eval-conflicts-rho010-r2-027-q9kzn.18d4667f80bb3185,reason=Scheduled count=None msg=Successfully assigned compute/eval-conflicts-rho010-r2-027-q9kzn to kind-worker5
0.1142,Event,ADDED,eval-conflicts-rho010-r2-027-q9kzn.18d4667f9cb9d16d,"reason=Pulled count=1 msg=Container image ""busybox:musl"" already present on machine"
0.1144,Event,ADDED,eval-conflicts-rho010-r2-027-q9kzn.18d4667f9de1fe5e,reason=Created count=1 msg=Created container: task
0.1145,Event,ADDED,eval-conflicts-rho010-r2-027-q9kzn.18d4667fa4ea3a57,reason=Started count=1 msg=Started container task
0.1147,Event,ADDED,eval-conflicts-rho010-r2-027.18d4667f7f913b95,reason=SuccessfulCreate count=1 msg=Created pod: eval-conflicts-rho010-r2-027-q9kzn
0.1149,Event,ADDED,eval-conflicts-rho010-r2-027.18d46682b7ef877f,reason=Completed count=1 msg=Job completed
0.115,Event,ADDED,eval-conflicts-rho010-r2-028-djcp6.18d4667fba6a0c40,"reason=FailedScheduling count=None msg=0/6 nodes are available: 3 c_wall violated: 2 conflicting context pair(s) with node memory, 3 node(s) had untolerated taint(s). no new claims to deallocate, preemption: 0/6 nodes are available: 3 No preemption victims found for incoming pod, 3 Preemption is not helpful for scheduling."
0.1153,Event,ADDED,eval-conflicts-rho010-r2-028-djcp6.18d4667fbcc3f716,"reason=FailedScheduling count=None msg=0/6 nodes are available: 3 c_wall violated: 2 conflicting context pair(s) with node memory, 3 node(s) had untolerated taint(s). no new claims to deallocate, preemption: 0/6 nodes are available: 3 No preemption victims found for incoming pod, 3 Preemption is not helpful for scheduling."
0.1155,Event,ADDED,eval-conflicts-rho010-r2-028-djcp6.18d466800c35eaf2,"reason=FailedScheduling count=None msg=0/6 nodes are available: 2 c_wall violated: 2 conflicting context pair(s) with node memory, 4 node(s) had untolerated taint(s). no new claims to deallocate, preemption: 0/6 nodes are available: 2 No preemption victims found for incoming pod, 4 Preemption is not helpful for scheduling."
0.116,Event,ADDED,eval-conflicts-rho010-r2-028-djcp6.18d466801bd0ada6,"reason=FailedScheduling count=None msg=0/6 nodes are available: 1 c_wall violated: 2 conflicting context pair(s) with node memory, 5 node(s) had untolerated taint(s). no new claims to deallocate, preemption: 0/6 nodes are available: 1 No preemption victims found for incoming pod, 5 Preemption is not helpful for scheduling."
0.1162,Event,ADDED,eval-conflicts-rho010-r2-028-djcp6.18d4668027dac925,reason=Scheduled count=None msg=Successfully assigned compute/eval-conflicts-rho010-r2-028-djcp6 to kind-worker3
0.1164,Event,ADDED,eval-conflicts-rho010-r2-028-djcp6.18d46680415c58ce,"reason=Pulled count=1 msg=Container image ""busybox:musl"" already present on machine"
0.1166,Event,ADDED,eval-conflicts-rho010-r2-028-djcp6.18d46680425eecfb,reason=Created count=1 msg=Created container: task
0.1168,Event,ADDED,eval-conflicts-rho010-r2-028-djcp6.18d46680452a6b5c,reason=Started count=1 msg=Started container task
0.117,Event,ADDED,eval-conflicts-rho010-r2-028.18d4667fb9a1417a,reason=SuccessfulCreate count=1 msg=Created pod: eval-conflicts-rho010-r2-028-djcp6
0.1171,Event,ADDED,eval-conflicts-rho010-r2-028.18d4668362e3537a,reason=Completed count=1 msg=Job completed
0.1173,Event,ADDED,eval-conflicts-rho010-r2-029-77jt9.18d4667ffa5c5f91,reason=Scheduled count=None msg=Successfully assigned compute/eval-conflicts-rho010-r2-029-77jt9 to kind-worker5
0.1175,Event,ADDED,eval-conflicts-rho010-r2-029-77jt9.18d4668013a23bd9,"reason=Pulled count=1 msg=Container image ""busybox:musl"" already present on machine"
0.1177,Event,ADDED,eval-conflicts-rho010-r2-029-77jt9.18d4668014d167d6,reason=Created count=1 msg=Created container: task
0.1179,Event,ADDED,eval-conflicts-rho010-r2-029-77jt9.18d466801713181c,reason=Started count=1 msg=Started container task
0.118,Event,ADDED,eval-conflicts-rho010-r2-029.18d4667ff5656715,reason=SuccessfulCreate count=1 msg=Created pod: eval-conflicts-rho010-r2-029-77jt9
0.1182,Event,ADDED,eval-conflicts-rho010-r2-029.18d4668337236749,reason=Completed count=1 msg=Job completed
0.1183,Event,ADDED,eval-conflicts-rho010-r2-030-lshkr.18d466803233da99,reason=Scheduled count=None msg=Successfully assigned compute/eval-conflicts-rho010-r2-030-lshkr to kind-worker5
0.1185,Event,ADDED,eval-conflicts-rho010-r2-030-lshkr.18d466804c31db7e,"reason=Pulled count=1 msg=Container image ""busybox:musl"" already present on machine"
0.1187,Event,ADDED,eval-conflicts-rho010-r2-030-lshkr.18d466804d436757,reason=Created count=1 msg=Created container: task
0.1189,Event,ADDED,eval-conflicts-rho010-r2-030-lshkr.18d466804f1decaf,reason=Started count=1 msg=Started container task
0.119,Event,ADDED,eval-conflicts-rho010-r2-030.18d46680316a9335,reason=SuccessfulCreate count=1 msg=Created pod: eval-conflicts-rho010-r2-030-lshkr
0.1192,Event,ADDED,eval-conflicts-rho010-r2-030.18d46683732732bb,reason=Completed count=1 msg=Job completed
0.1194,Event,ADDED,eval-conflicts-rho010-r2-031-rgzzg.18d466806d74f00e,reason=Scheduled count=None msg=Successfully assigned compute/eval-conflicts-rho010-r2-031-rgzzg to kind-worker4
0.1195,Event,ADDED,eval-conflicts-rho010-r2-031-rgzzg.18d46680871bcefa,"reason=Pulled count=1 msg=Container image ""busybox:musl"" already present on machine"
0.1197,Event,ADDED,eval-conflicts-rho010-r2-031-rgzzg.18d466808828d1f5,reason=Created count=1 msg=Created container: task
0.1199,Event,ADDED,eval-conflicts-rho010-r2-031-rgzzg.18d46680925eba57,reason=Started count=1 msg=Started container task
0.12,Event,ADDED,eval-conflicts-rho010-r2-031.18d466806c896aeb,reason=SuccessfulCreate count=1 msg=Created pod: eval-conflicts-rho010-r2-031-rgzzg
0.1202,Event,ADDED,eval-conflicts-rho010-r2-031.18d46683bc6b6a8a,reason=Completed count=1 msg=Job completed
0.1204,Event,ADDED,eval-conflicts-rho010-r2-032-lst5d.18d46680a92bfbea,reason=Scheduled count=None msg=Successfully assigned compute/eval-conflicts-rho010-r2-032-lst5d to kind-worker4
0.1205,Event,ADDED,eval-conflicts-rho010-r2-032-lst5d.18d46680c30dec7b,"reason=Pulled count=1 msg=Container image ""busybox:musl"" already present on machine"
0.1207,Event,ADDED,eval-conflicts-rho010-r2-032-lst5d.18d46680c41718f4,reason=Created count=1 msg=Created container: task
0.1209,Event,ADDED,eval-conflicts-rho010-r2-032-lst5d.18d46680c929d546,reason=Started count=1 msg=Started container task
0.121,Event,ADDED,eval-conflicts-rho010-r2-032.18d46680a8085e75,reason=SuccessfulCreate count=1 msg=Created pod: eval-conflicts-rho010-r2-032-lst5d
0.1213,Event,ADDED,eval-conflicts-rho010-r2-032.18d46683f1c97042,reason=Completed count=1 msg=Job completed
0.1217,Event,ADDED,eval-conflicts-rho010-r2-033-9ttsm.18d46680e58dd356,reason=Scheduled count=None msg=Successfully assigned compute/eval-conflicts-rho010-r2-033-9ttsm to kind-worker4
0.122,Event,ADDED,eval-conflicts-rho010-r2-033-9ttsm.18d46681001246a1,"reason=Pulled count=1 msg=Container image ""busybox:musl"" already present on machine"
0.1222,Event,ADDED,eval-conflicts-rho010-r2-033-9ttsm.18d46681012b279b,reason=Created count=1 msg=Created container: task
0.1225,Event,ADDED,eval-conflicts-rho010-r2-033-9ttsm.18d46681097a9946,reason=Started count=1 msg=Started container task
0.1226,Event,ADDED,eval-conflicts-rho010-r2-033.18d46680e459c9e2,reason=SuccessfulCreate count=1 msg=Created pod: eval-conflicts-rho010-r2-033-9ttsm
0.1229,Event,ADDED,eval-conflicts-rho010-r2-033.18d466842d832344,reason=Completed count=1 msg=Job completed
0.1231,Event,ADDED,eval-conflicts-rho010-r2-034-8cwzl.18d466812cfbf2e3,reason=Scheduled count=None msg=Successfully assigned compute/eval-conflicts-rho010-r2-034-8cwzl to kind-worker3
0.1232,Event,ADDED,eval-conflicts-rho010-r2-034-8cwzl.18d46681495d2fba,"reason=Pulled count=1 msg=Container image ""busybox:musl"" already present on machine"
0.1234,Event,ADDED,eval-conflicts-rho010-r2-034-8cwzl.18d466814a7f5f4e,reason=Created count=1 msg=Created container: task
0.1236,Event,ADDED,eval-conflicts-rho010-r2-034-8cwzl.18d466814e6aca3a,reason=Started count=1 msg=Started container task
0.1238,Event,ADDED,eval-conflicts-rho010-r2-034.18d466812c355ebf,reason=SuccessfulCreate count=1 msg=Created pod: eval-conflicts-rho010-r2-034-8cwzl
0.1239,Event,ADDED,eval-conflicts-rho010-r2-034.18d466848bff4ad8,reason=Completed count=1 msg=Job completed
0.1241,Event,ADDED,eval-conflicts-rho010-r2-035-7hvk6.18d4668168f9e770,reason=Scheduled count=None msg=Successfully assigned compute/eval-conflicts-rho010-r2-035-7hvk6 to kind-worker3
0.1243,Event,ADDED,eval-conflicts-rho010-r2-035-7hvk6.18d466818cd29725,"reason=Pulled count=1 msg=Container image ""busybox:musl"" already present on machine"
0.1244,Event,ADDED,eval-conflicts-rho010-r2-035-7hvk6.18d466818e22dd5a,reason=Created count=1 msg=Created container: task
0.1248,Event,ADDED,eval-conflicts-rho010-r2-035-7hvk6.18d46681924f93e4,reason=Started count=1 msg=Started container task
0.1249,Event,ADDED,eval-conflicts-rho010-r2-035.18d46681685787d8,reason=SuccessfulCreate count=1 msg=Created pod: eval-conflicts-rho010-r2-035-7hvk6
0.1251,Event,ADDED,eval-conflicts-rho010-r2-035.18d46684c7c79e8b,reason=Completed count=1 msg=Job completed
0.1253,Event,ADDED,eval-conflicts-rho010-r2-036-rj5qr.18d466819d020fce,reason=Scheduled count=None msg=Successfully assigned compute/eval-conflicts-rho010-r2-036-rj5qr to kind-worker4
0.1255,Event,ADDED,eval-conflicts-rho010-r2-036-rj5qr.18d46681b62331d3,"reason=Pulled count=1 msg=Container image ""busybox:musl"" already present on machine"
0.1257,Event,ADDED,eval-conflicts-rho010-r2-036-rj5qr.18d46681b738a66a,reason=Created count=1 msg=Created container: task
0.1259,Event,ADDED,eval-conflicts-rho010-r2-036-rj5qr.18d46681baf8ff53,reason=Started count=1 msg=Started container task
0.1261,Event,ADDED,eval-conflicts-rho010-r2-036.18d466819c419004,reason=SuccessfulCreate count=1 msg=Created pod: eval-conflicts-rho010-r2-036-rj5qr
0.1263,Event,ADDED,eval-conflicts-rho010-r2-036.18d46684e1cc86fa,reason=Completed count=1 msg=Job completed
0.1264,Event,ADDED,eval-conflicts-rho010-r2-037-8hdbd.18d46681d2ec2af4,reason=Scheduled count=None msg=Successfully assigned compute/eval-conflicts-rho010-r2-037-8hdbd to kind-worker4
0.1266,Event,ADDED,eval-conflicts-rho010-r2-037-8hdbd.18d46681ec4038c0,"reason=Pulled count=1 msg=Container image ""busybox:musl"" already present on machine"
0.1269,Event,ADDED,eval-conflicts-rho010-r2-037-8hdbd.18d46681ed4b63b1,reason=Created count=1 msg=Created container: task
0.1271,Event,ADDED,eval-conflicts-rho010-r2-037-8hdbd.18d46681f0c2fbdf,reason=Started count=1 msg=Started container task
0.1273,Event,ADDED,eval-conflicts-rho010-r2-037.18d46681d2199751,reason=SuccessfulCreate count=1 msg=Created pod: eval-conflicts-rho010-r2-037-8hdbd
0.1275,Event,ADDED,eval-conflicts-rho010-r2-037.18d466851dd9f39d,reason=Completed count=1 msg=Job completed
0.1276,Event,ADDED,eval-conflicts-rho010-r2-038-5592f.18d4668210695614,reason=Scheduled count=None msg=Successfully assigned compute/eval-conflicts-rho010-r2-038-5592f to kind-worker3
0.1278,Event,ADDED,eval-conflicts-rho010-r2-038-5592f.18d466822b37cb8a,"reason=Pulled count=1 msg=Container image ""busybox:musl"" already present on machine"
0.128,Event,ADDED,eval-conflicts-rho010-r2-038-5592f.18d466822c3fad19,reason=Created count=1 msg=Created container: task
0.1281,Event,ADDED,eval-conflicts-rho010-r2-038-5592f.18d46682317fa9ac,reason=Started count=1 msg=Started container task
0.1283,Event,ADDED,eval-conflicts-rho010-r2-038.18d466820fbdb641,reason=SuccessfulCreate count=1 msg=Created pod: eval-conflicts-rho010-r2-038-5592f
0.1285,Event,ADDED,eval-conflicts-rho010-r2-038.18d466853f0b9193,reason=Completed count=1 msg=Job completed
0.1286,Event,ADDED,eval-conflicts-rho010-r2-039-vkr9x.18d466824ce91a97,reason=Scheduled count=None msg=Successfully assigned compute/eval-conflicts-rho010-r2-039-vkr9x to kind-worker3
0.1288,Event,ADDED,eval-conflicts-rho010-r2-039-vkr9x.18d4668266ae559f,"reason=Pulled count=1 msg=Container image ""busybox:musl"" already present on machine"
0.129,Event,ADDED,eval-conflicts-rho010-r2-039-vkr9x.18d4668267b0339e,reason=Created count=1 msg=Created container: task
0.1291,Event,ADDED,eval-conflicts-rho010-r2-039-vkr9x.18d4668269abf4b4,reason=Started count=1 msg=Started container task
0.1293,Event,ADDED,eval-conflicts-rho010-r2-039.18d466824c1e5928,reason=SuccessfulCreate count=1 msg=Created pod: eval-conflicts-rho010-r2-039-vkr9x
0.1294,Event,ADDED,eval-conflicts-rho010-r2-039.18d466857b3b094a,reason=Completed count=1 msg=Job completed
0.1296,Event,ADDED,eval-conflicts-rho010-r2-040-l4d7z.18d46682859aefad,reason=Scheduled count=None msg=Successfully assigned compute/eval-conflicts-rho010-r2-040-l4d7z to kind-worker
0.1298,Event,ADDED,eval-conflicts-rho010-r2-040-l4d7z.18d46682a07d258d,"reason=Pulled count=1 msg=Container image ""busybox:musl"" already present on machine"
0.1301,Event,ADDED,eval-conflicts-rho010-r2-040-l4d7z.18d46682a18bab94,reason=Created count=1 msg=Created container: task
0.1303,Event,ADDED,eval-conflicts-rho010-r2-040-l4d7z.18d46682a5fe58f8,reason=Started count=1 msg=Started container task
0.1305,Event,ADDED,eval-conflicts-rho010-r2-040.18d4668284d216b6,reason=SuccessfulCreate count=1 msg=Created pod: eval-conflicts-rho010-r2-040-l4d7z
0.1307,Event,ADDED,eval-conflicts-rho010-r2-040.18d46685b6fbefe4,reason=Completed count=1 msg=Job completed
0.131,Event,ADDED,eval-conflicts-rho010-r2-041-srbc9.18d46682c11dc59b,reason=Scheduled count=None msg=Successfully assigned compute/eval-conflicts-rho010-r2-041-srbc9 to kind-worker2
0.1312,Event,ADDED,eval-conflicts-rho010-r2-041-srbc9.18d46682d9f6e56d,"reason=Pulled count=1 msg=Container image ""busybox:musl"" already present on machine"
0.1314,Event,ADDED,eval-conflicts-rho010-r2-041-srbc9.18d46682db114337,reason=Created count=1 msg=Created container: task
0.1316,Event,ADDED,eval-conflicts-rho010-r2-041-srbc9.18d46682e1fac4f8,reason=Started count=1 msg=Started container task
0.1319,Event,ADDED,eval-conflicts-rho010-r2-041.18d46682c07341ec,reason=SuccessfulCreate count=1 msg=Created pod: eval-conflicts-rho010-r2-041-srbc9
0.1321,Event,ADDED,eval-conflicts-rho010-r2-041.18d46685ffb5cee3,reason=Completed count=1 msg=Job completed
0.1323,Event,ADDED,eval-conflicts-rho010-r2-042-fstv9.18d46682fcbc3a2f,reason=Scheduled count=None msg=Successfully assigned compute/eval-conflicts-rho010-r2-042-fstv9 to kind-worker
0.1327,Event,ADDED,eval-conflicts-rho010-r2-042-fstv9.18d46683214db2df,"reason=Pulled count=1 msg=Container image ""busybox:musl"" already present on machine"
0.1328,Event,ADDED,eval-conflicts-rho010-r2-042-fstv9.18d4668322e38214,reason=Created count=1 msg=Created container: task
0.133,Event,ADDED,eval-conflicts-rho010-r2-042-fstv9.18d4668326c810e1,reason=Started count=1 msg=Started container task
0.1332,Event,ADDED,eval-conflicts-rho010-r2-042.18d46682fbe3ac32,reason=SuccessfulCreate count=1 msg=Created pod: eval-conflicts-rho010-r2-042-fstv9
0.1335,Event,ADDED,eval-conflicts-rho010-r2-042.18d466866aad0ae9,reason=Completed count=1 msg=Job completed
0.1337,Event,ADDED,eval-conflicts-rho010-r2-043-v2c7p.18d4668339e248e9,reason=Scheduled count=None msg=Successfully assigned compute/eval-conflicts-rho010-r2-043-v2c7p to kind-worker2
0.1338,Event,ADDED,eval-conflicts-rho010-r2-043-v2c7p.18d4668353024f17,"reason=Pulled count=1 msg=Container image ""busybox:musl"" already present on machine"
0.134,Event,ADDED,eval-conflicts-rho010-r2-043-v2c7p.18d46683544b5de9,reason=Created count=1 msg=Created container: task
0.1343,Event,ADDED,eval-conflicts-rho010-r2-043-v2c7p.18d46683564dd0f2,reason=Started count=1 msg=Started container task
0.1345,Event,ADDED,eval-conflicts-rho010-r2-043.18d4668338cd7204,reason=SuccessfulCreate count=1 msg=Created pod: eval-conflicts-rho010-r2-043-v2c7p
0.1347,Event,ADDED,eval-conflicts-rho010-r2-043.18d46686774e8c86,reason=Completed count=1 msg=Job completed
0.135,Event,ADDED,eval-conflicts-rho010-r2-044-tljjm.18d46683743365a9,reason=Scheduled count=None msg=Successfully assigned compute/eval-conflicts-rho010-r2-044-tljjm to kind-worker5
0.1352,Event,ADDED,eval-conflicts-rho010-r2-044-tljjm.18d466838ee2f026,"reason=Pulled count=1 msg=Container image ""busybox:musl"" already present on machine"
0.1353,Event,ADDED,eval-conflicts-rho010-r2-044-tljjm.18d466838ffea7db,reason=Created count=1 msg=Created container: task
0.1355,Event,ADDED,eval-conflicts-rho010-r2-044-tljjm.18d4668393acf14e,reason=Started count=1 msg=Started container task
0.1358,Event,ADDED,eval-conflicts-rho010-r2-044.18d466837348f240,reason=SuccessfulCreate count=1 msg=Created pod: eval-conflicts-rho010-r2-044-tljjm
0.136,Event,ADDED,eval-conflicts-rho010-r2-044.18d46686ae5b2128,reason=Completed count=1 msg=Job completed
0.1362,Event,ADDED,eval-conflicts-rho010-r2-045-jm542.18d46683afec0e34,reason=Scheduled count=None msg=Successfully assigned compute/eval-conflicts-rho010-r2-045-jm542 to kind-worker5
0.1365,Event,ADDED,eval-conflicts-rho010-r2-045-jm542.18d46683cb64c98f,"reason=Pulled count=1 msg=Container image ""busybox:musl"" already present on machine"
0.1367,Event,ADDED,eval-conflicts-rho010-r2-045-jm542.18d46683ccb39816,reason=Created count=1 msg=Created container: task
0.1368,Event,ADDED,eval-conflicts-rho010-r2-045-jm542.18d46683d29ee02c,reason=Started count=1 msg=Started container task
0.137,Event,ADDED,eval-conflicts-rho010-r2-045.18d46683aed04492,reason=SuccessfulCreate count=1 msg=Created pod: eval-conflicts-rho010-r2-045-jm542
0.1372,Event,ADDED,eval-conflicts-rho010-r2-045.18d46686ea35ecf8,reason=Completed count=1 msg=Job completed
0.1374,Event,ADDED,eval-conflicts-rho010-r2-046-946cl.18d46683eba1848a,reason=Scheduled count=None msg=Successfully assigned compute/eval-conflicts-rho010-r2-046-946cl to kind-worker5
0.1377,Event,ADDED,eval-conflicts-rho010-r2-046-946cl.18d4668405f8cba5,"reason=Pulled count=1 msg=Container image ""busybox:musl"" already present on machine"
0.1379,Event,ADDED,eval-conflicts-rho010-r2-046-946cl.18d46684074817e4,reason=Created count=1 msg=Created container: task
0.1382,Event,ADDED,eval-conflicts-rho010-r2-046-946cl.18d466840c186ede,reason=Started count=1 msg=Started container task
0.1383,Event,ADDED,eval-conflicts-rho010-r2-046.18d46683ea8b4c71,reason=SuccessfulCreate count=1 msg=Created pod: eval-conflicts-rho010-r2-046-946cl
0.1385,Event,ADDED,eval-conflicts-rho010-r2-046.18d466872601264e,reason=Completed count=1 msg=Job completed
0.1387,Event,ADDED,eval-conflicts-rho010-r2-047-8jgqt.18d4668427787ea2,reason=Scheduled count=None msg=Successfully assigned compute/eval-conflicts-rho010-r2-047-8jgqt to kind-worker2
0.1389,Event,ADDED,eval-conflicts-rho010-r2-047-8jgqt.18d4668442184a90,"reason=Pulled count=1 msg=Container image ""busybox:musl"" already present on machine"
0.1391,Event,ADDED,eval-conflicts-rho010-r2-047-8jgqt.18d4668443235cd3,reason=Created count=1 msg=Created container: task
0.1392,Event,ADDED,eval-conflicts-rho010-r2-047-8jgqt.18d46684470065ce,reason=Started count=1 msg=Started container task
0.1394,Event,ADDED,eval-conflicts-rho010-r2-047.18d46684265a24d6,reason=SuccessfulCreate count=1 msg=Created pod: eval-conflicts-rho010-r2-047-8jgqt
0.1396,Event,ADDED,eval-conflicts-rho010-r2-047.18d4668767960cf8,reason=Completed count=1 msg=Job completed
0.1397,Event,ADDED,eval-conflicts-rho010-r2-048-c86v4.18d4668462929554,reason=Scheduled count=None msg=Successfully assigned compute/eval-conflicts-rho010-r2-048-c86v4 to kind-worker5
0.1399,Event,ADDED,eval-conflicts-rho010-r2-048-c86v4.18d466847c03a733,"reason=Pulled count=1 msg=Container image ""busybox:musl"" already present on machine"
0.1401,Event,ADDED,eval-conflicts-rho010-r2-048-c86v4.18d466847d1613a9,reason=Created count=1 msg=Created container: task
0.1402,Event,ADDED,eval-conflicts-rho010-r2-048-c86v4.18d4668480d7d768,reason=Started count=1 msg=Started container task
0.1404,Event,ADDED,eval-conflicts-rho010-r2-048.18d4668461787baa,reason=SuccessfulCreate count=1 msg=Created pod: eval-conflicts-rho010-r2-048-c86v4
0.1406,Event,ADDED,eval-conflicts-rho010-r2-048.18d466879dab2f33,reason=Completed count=1 msg=Job completed
0.1407,Event,ADDED,eval-conflicts-rho010-r2-049-tpnj7.18d466849ecf35c6,reason=Scheduled count=None msg=Successfully assigned compute/eval-conflicts-rho010-r2-049-tpnj7 to kind-worker
0.1409,Event,ADDED,eval-conflicts-rho010-r2-049-tpnj7.18d46684b84c3b6c,"reason=Pulled count=1 msg=Container image ""busybox:musl"" already present on machine"
0.1411,Event,ADDED,eval-conflicts-rho010-r2-049-tpnj7.18d46684b9563c31,reason=Created count=1 msg=Created container: task
0.1412,Event,ADDED,eval-conflicts-rho010-r2-049-tpnj7.18d46684bb796c27,reason=Started count=1 msg=Started container task
0.1414,Event,ADDED,eval-conflicts-rho010-r2-049.18d466849d9fdcc8,reason=SuccessfulCreate count=1 msg=Created pod: eval-conflicts-rho010-r2-049-tpnj7
0.1416,Event,ADDED,eval-conflicts-rho010-r2-049.18d46687cff39eb7,reason=Completed count=1 msg=Job completed
0.1417,Event,ADDED,eval-conflicts-rho010-r2-050-9gcx4.18d46684d92630e5,reason=Scheduled count=None msg=Successfully assigned compute/eval-conflicts-rho010-r2-050-9gcx4 to kind-worker5
0.1419,Event,ADDED,eval-conflicts-rho010-r2-050-9gcx4.18d46684f2b4b6cd,"reason=Pulled count=1 msg=Container image ""busybox:musl"" already present on machine"
0.142,Event,ADDED,eval-conflicts-rho010-r2-050-9gcx4.18d46684f3c33c49,reason=Created count=1 msg=Created container: task
0.1422,Event,ADDED,eval-conflicts-rho010-r2-050-9gcx4.18d46684f58d141d,reason=Started count=1 msg=Started container task
0.1424,Event,ADDED,eval-conflicts-rho010-r2-050.18d46684d8a492e1,reason=SuccessfulCreate count=1 msg=Created pod: eval-conflicts-rho010-r2-050-9gcx4
0.1425,Event,ADDED,eval-conflicts-rho010-r2-050.18d46688158e0276,reason=Completed count=1 msg=Job completed
0.1427,Event,ADDED,eval-conflicts-rho010-r2-051-7488z.18d4668515f2d613,reason=Scheduled count=None msg=Successfully assigned compute/eval-conflicts-rho010-r2-051-7488z to kind-worker4
0.1428,Event,ADDED,eval-conflicts-rho010-r2-051-7488z.18d466852fedf398,"reason=Pulled count=1 msg=Container image ""busybox:musl"" already present on machine"
0.143,Event,ADDED,eval-conflicts-rho010-r2-051-7488z.18d46685310193f6,reason=Created count=1 msg=Created container: task
0.1432,Event,ADDED,eval-conflicts-rho010-r2-051-7488z.18d466853b14ac42,reason=Started count=1 msg=Started container task
0.1433,Event,ADDED,eval-conflicts-rho010-r2-051.18d466851551706c,reason=SuccessfulCreate count=1 msg=Created pod: eval-conflicts-rho010-r2-051-7488z
0.1435,Event,ADDED,eval-conflicts-rho010-r2-051.18d46688647bc5fe,reason=Completed count=1 msg=Job completed
0.1437,Event,ADDED,eval-conflicts-rho010-r2-052-th7kn.18d4668550d5fa38,reason=Scheduled count=None msg=Successfully assigned compute/eval-conflicts-rho010-r2-052-th7kn to kind-worker4
0.1438,Event,ADDED,eval-conflicts-rho010-r2-052-th7kn.18d466856aee5a42,"reason=Pulled count=1 msg=Container image ""busybox:musl"" already present on machine"
0.144,Event,ADDED,eval-conflicts-rho010-r2-052-th7kn.18d466856bfda7d6,reason=Created count=1 msg=Created container: task
0.1442,Event,ADDED,eval-conflicts-rho010-r2-052-th7kn.18d466856dd94bab,reason=Started count=1 msg=Started container task
0.1443,Event,ADDED,eval-conflicts-rho010-r2-052.18d46685500a0118,reason=SuccessfulCreate count=1 msg=Created pod: eval-conflicts-rho010-r2-052-th7kn
0.1445,Event,ADDED,eval-conflicts-rho010-r2-052.18d46688a0501782,reason=Completed count=1 msg=Job completed
0.1446,Event,ADDED,eval-conflicts-rho010-r2-053-565pd.18d466858cacad80,reason=Scheduled count=None msg=Successfully assigned compute/eval-conflicts-rho010-r2-053-565pd to kind-worker4
0.1448,Event,ADDED,eval-conflicts-rho010-r2-053-565pd.18d46685a6568204,"reason=Pulled count=1 msg=Container image ""busybox:musl"" already present on machine"
0.145,Event,ADDED,eval-conflicts-rho010-r2-053-565pd.18d46685a76ab797,reason=Created count=1 msg=Created container: task
0.1452,Event,ADDED,eval-conflicts-rho010-r2-053-565pd.18d46685a981ff85,reason=Started count=1 msg=Started container task
0.1454,Event,ADDED,eval-conflicts-rho010-r2-053.18d466858ba34657,reason=SuccessfulCreate count=1 msg=Created pod: eval-conflicts-rho010-r2-053-565pd
0.1455,Event,ADDED,eval-conflicts-rho010-r2-053.18d46688d965261c,reason=Completed count=1 msg=Job completed
0.1457,Event,ADDED,eval-conflicts-rho010-r2-054-zjs57.18d46685c7c42a2c,reason=Scheduled count=None msg=Successfully assigned compute/eval-conflicts-rho010-r2-054-zjs57 to kind-worker4
0.1459,Event,ADDED,eval-conflicts-rho010-r2-054-zjs57.18d46685e1a99a98,"reason=Pulled count=1 msg=Container image ""busybox:musl"" already present on machine"
0.146,Event,ADDED,eval-conflicts-rho010-r2-054-zjs57.18d46685e2b92fc7,reason=Created count=1 msg=Created container: task
0.1462,Event,ADDED,eval-conflicts-rho010-r2-054-zjs57.18d46685e6bd1457,reason=Started count=1 msg=Started container task
0.1464,Event,ADDED,eval-conflicts-rho010-r2-054.18d46685c7288401,reason=SuccessfulCreate count=1 msg=Created pod: eval-conflicts-rho010-r2-054-zjs57
0.1465,Event,ADDED,eval-conflicts-rho010-r2-054.18d46689184e536d,reason=Completed count=1 msg=Job completed
0.1467,Event,ADDED,eval-conflicts-rho010-r2-055-smsc2.18d466860361fdff,reason=Scheduled count=None msg=Successfully assigned compute/eval-conflicts-rho010-r2-055-smsc2 to kind-worker4
0.1468,Event,ADDED,eval-conflicts-rho010-r2-055-smsc2.18d466861cd682ce,"reason=Pulled count=1 msg=Container image ""busybox:musl"" already present on machine"
0.147,Event,ADDED,eval-conflicts-rho010-r2-055-smsc2.18d466861defac79,reason=Created count=1 msg=Created container: task
0.1472,Event,ADDED,eval-conflicts-rho010-r2-055-smsc2.18d466861fd6d87e,reason=Started count=1 msg=Started container task
0.1473,Event,ADDED,eval-conflicts-rho010-r2-055.18d4668602d73f66,reason=SuccessfulCreate count=1 msg=Created pod: eval-conflicts-rho010-r2-055-smsc2
0.1475,Event,ADDED,eval-conflicts-rho010-r2-055.18d4668918d22c39,reason=Completed count=1 msg=Job completed
0.1476,Event,ADDED,eval-conflicts-rho010-r2-056-4xgkn.18d466863ee74561,reason=Scheduled count=None msg=Successfully assigned compute/eval-conflicts-rho010-r2-056-4xgkn to kind-worker4
0.1478,Event,ADDED,eval-conflicts-rho010-r2-056-4xgkn.18d466865841a1a4,"reason=Pulled count=1 msg=Container image ""busybox:musl"" already present on machine"
0.148,Event,ADDED,eval-conflicts-rho010-r2-056-4xgkn.18d466865946209d,reason=Created count=1 msg=Created container: task
0.1481,Event,ADDED,eval-conflicts-rho010-r2-056-4xgkn.18d466865b2d3c2a,reason=Started count=1 msg=Started container task
0.1488,Event,ADDED,eval-conflicts-rho010-r2-056.18d466863e5e6716,reason=SuccessfulCreate count=1 msg=Created pod: eval-conflicts-rho010-r2-056-4xgkn
0.149,Event,ADDED,eval-conflicts-rho010-r2-056.18d466899412b505,reason=Completed count=1 msg=Job completed
0.1492,Event,ADDED,eval-conflicts-rho010-r2-057-7wvtn.18d466867a76b4d0,reason=Scheduled count=None msg=Successfully assigned compute/eval-conflicts-rho010-r2-057-7wvtn to kind-worker4
0.1494,Event,ADDED,eval-conflicts-rho010-r2-057-7wvtn.18d4668692c9c09d,"reason=Pulled count=1 msg=Container image ""busybox:musl"" already present on machine"
0.1497,Event,ADDED,eval-conflicts-rho010-r2-057-7wvtn.18d4668693dd5ad5,reason=Created count=1 msg=Created container: task
0.1499,Event,ADDED,eval-conflicts-rho010-r2-057-7wvtn.18d4668695f1ed4e,reason=Started count=1 msg=Started container task
0.1501,Event,ADDED,eval-conflicts-rho010-r2-057.18d4668679eabe7d,reason=SuccessfulCreate count=1 msg=Created pod: eval-conflicts-rho010-r2-057-7wvtn
0.1503,Event,ADDED,eval-conflicts-rho010-r2-057.18d46689d0dacf5f,reason=Completed count=1 msg=Job completed
0.1506,Event,ADDED,eval-conflicts-rho010-r2-058-2p2bb.18d46686b68245d7,reason=Scheduled count=None msg=Successfully assigned compute/eval-conflicts-rho010-r2-058-2p2bb to kind-worker4
0.1507,Event,ADDED,eval-conflicts-rho010-r2-058-2p2bb.18d46686cfe7d1c2,"reason=Pulled count=1 msg=Container image ""busybox:musl"" already present on machine"
0.1509,Event,ADDED,eval-conflicts-rho010-r2-058-2p2bb.18d46686d1009ce5,reason=Created count=1 msg=Created container: task
0.1512,Event,ADDED,eval-conflicts-rho010-r2-058-2p2bb.18d46686d2f890af,reason=Started count=1 msg=Started container task
0.1514,Event,ADDED,eval-conflicts-rho010-r2-058.18d46686b5f63899,reason=SuccessfulCreate count=1 msg=Created pod: eval-conflicts-rho010-r2-058-2p2bb
0.1516,Event,ADDED,eval-conflicts-rho010-r2-058.18d4668a0544de14,reason=Completed count=1 msg=Job completed
0.1518,Event,ADDED,eval-conflicts-rho010-r2-059-g22w7.18d46686f1eb53b6,reason=Scheduled count=None msg=Successfully assigned compute/eval-conflicts-rho010-r2-059-g22w7 to kind-worker4
0.152,Event,ADDED,eval-conflicts-rho010-r2-059-g22w7.18d466870b9824c6,"reason=Pulled count=1 msg=Container image ""busybox:musl"" already present on machine"
0.1522,Event,ADDED,eval-conflicts-rho010-r2-059-g22w7.18d466870ca12358,reason=Created count=1 msg=Created container: task
0.1524,Event,ADDED,eval-conflicts-rho010-r2-059-g22w7.18d466870e8f2007,reason=Started count=1 msg=Started container task
0.1527,Event,ADDED,eval-conflicts-rho010-r2-059.18d46686f1490724,reason=SuccessfulCreate count=1 msg=Created pod: eval-conflicts-rho010-r2-059-g22w7
0.1529,Event,ADDED,eval-conflicts-rho010-r2-059.18d4668a41c0f87b,reason=Completed count=1 msg=Job completed
0.153,Event,ADDED,eval-conflicts-rho010-r2-060-k59qf.18d466872e1c8226,reason=Scheduled count=None msg=Successfully assigned compute/eval-conflicts-rho010-r2-060-k59qf to kind-worker4
0.1532,Event,ADDED,eval-conflicts-rho010-r2-060-k59qf.18d4668747cbc6ef,"reason=Pulled count=1 msg=Container image ""busybox:musl"" already present on machine"
0.1535,Event,ADDED,eval-conflicts-rho010-r2-060-k59qf.18d466874920ab13,reason=Created count=1 msg=Created container: task
0.1536,Event,ADDED,eval-conflicts-rho010-r2-060-k59qf.18d466874e020263,reason=Started count=1 msg=Started container task
0.1538,Event,ADDED,eval-conflicts-rho010-r2-060.18d466872d5eb31c,reason=SuccessfulCreate count=1 msg=Created pod: eval-conflicts-rho010-r2-060-k59qf
0.154,Event,ADDED,eval-conflicts-rho010-r2-060.18d4668a7f78ecd0,reason=Completed count=1 msg=Job completed
0.1541,Event,ADDED,eval-conflicts-rho010-r2-061-sdssd.18d4668769959d52,reason=Scheduled count=None msg=Successfully assigned compute/eval-conflicts-rho010-r2-061-sdssd to kind-worker2
0.1543,Event,ADDED,eval-conflicts-rho010-r2-061-sdssd.18d46687839c76a4,"reason=Pulled count=1 msg=Container image ""busybox:musl"" already present on machine"
0.1545,Event,ADDED,eval-conflicts-rho010-r2-061-sdssd.18d4668784a50087,reason=Created count=1 msg=Created container: task
0.1547,Event,ADDED,eval-conflicts-rho010-r2-061-sdssd.18d4668787fc1013,reason=Started count=1 msg=Started container task
0.1549,Event,ADDED,eval-conflicts-rho010-r2-061.18d4668768ba7184,reason=SuccessfulCreate count=1 msg=Created pod: eval-conflicts-rho010-r2-061-sdssd
0.155,Event,ADDED,eval-conflicts-rho010-r2-061.18d4668a6fcd0300,reason=Completed count=1 msg=Job completed
0.1552,Event,ADDED,eval-conflicts-rho010-r2-062-9ht75.18d46687a865db6c,reason=Scheduled count=None msg=Successfully assigned compute/eval-conflicts-rho010-r2-062-9ht75 to kind-worker2
0.1554,Event,ADDED,eval-conflicts-rho010-r2-062-9ht75.18d46687c27aa763,"reason=Pulled count=1 msg=Container image ""busybox:musl"" already present on machine"
0.1555,Event,ADDED,eval-conflicts-rho010-r2-062-9ht75.18d46687c3b67f9c,reason=Created count=1 msg=Created container: task
0.1557,Event,ADDED,eval-conflicts-rho010-r2-062-9ht75.18d46687cb51fe3a,reason=Started count=1 msg=Started container task
0.1559,Event,ADDED,eval-conflicts-rho010-r2-062.18d46687a7a3c134,reason=SuccessfulCreate count=1 msg=Created pod: eval-conflicts-rho010-r2-062-9ht75
0.156,Event,ADDED,eval-conflicts-rho010-r2-062.18d4668aae54d8b7,reason=Completed count=1 msg=Job completed
0.1562,Event,ADDED,eval-conflicts-rho010-r2-063-kbp4z.18d46687e1e5d5e8,reason=Scheduled count=None msg=Successfully assigned compute/eval-conflicts-rho010-r2-063-kbp4z to kind-worker2
0.1563,Event,ADDED,eval-conflicts-rho010-r2-063-kbp4z.18d46687faeff061,"reason=Pulled count=1 msg=Container image ""busybox:musl"" already present on machine"
0.1565,Event,ADDED,eval-conflicts-rho010-r2-063-kbp4z.18d46687fc0165a6,reason=Created count=1 msg=Created container: task
0.1567,Event,ADDED,eval-conflicts-rho010-r2-063-kbp4z.18d466880237d42f,reason=Started count=1 msg=Started container task
0.1568,Event,ADDED,eval-conflicts-rho010-r2-063.18d46687e1271359,reason=SuccessfulCreate count=1 msg=Created pod: eval-conflicts-rho010-r2-063-kbp4z
0.157,Event,ADDED,eval-conflicts-rho010-r2-063.18d4668b25a053fe,reason=Completed count=1 msg=Job completed
0.1573,Event,ADDED,eval-conflicts-rho010-r2-064-zmbw6.18d466881c501575,reason=Scheduled count=None msg=Successfully assigned compute/eval-conflicts-rho010-r2-064-zmbw6 to kind-worker5
0.1575,Event,ADDED,eval-conflicts-rho010-r2-064-zmbw6.18d4668839ee6722,"reason=Pulled count=1 msg=Container image ""busybox:musl"" already present on machine"
0.1576,Event,ADDED,eval-conflicts-rho010-r2-064-zmbw6.18d466883b0a3f37,reason=Created count=1 msg=Created container: task
0.158,Event,ADDED,eval-conflicts-rho010-r2-064-zmbw6.18d46688427ec1cc,reason=Started count=1 msg=Started container task
0.1582,Event,ADDED,eval-conflicts-rho010-r2-064.18d466881ba533cb,reason=SuccessfulCreate count=1 msg=Created pod: eval-conflicts-rho010-r2-064-zmbw6
0.1584,Event,ADDED,eval-conflicts-rho010-r2-064.18d4668b5aa0e5e6,reason=Completed count=1 msg=Job completed
0.1586,Event,ADDED,eval-conflicts-rho010-r2-065-2gvpg.18d46688590280a1,reason=Scheduled count=None msg=Successfully assigned compute/eval-conflicts-rho010-r2-065-2gvpg to kind-worker3
0.1588,Event,ADDED,eval-conflicts-rho010-r2-065-2gvpg.18d4668872d6c77c,"reason=Pulled count=1 msg=Container image ""busybox:musl"" already present on machine"
0.159,Event,ADDED,eval-conflicts-rho010-r2-065-2gvpg.18d4668873f195d9,reason=Created count=1 msg=Created container: task
0.1592,Event,ADDED,eval-conflicts-rho010-r2-065-2gvpg.18d46688760aeb49,reason=Started count=1 msg=Started container task
0.1593,Event,ADDED,eval-conflicts-rho010-r2-065.18d4668858349c78,reason=SuccessfulCreate count=1 msg=Created pod: eval-conflicts-rho010-r2-065-2gvpg
0.1595,Event,ADDED,eval-conflicts-rho010-r2-065.18d4668b8bd6fb3d,reason=Completed count=1 msg=Job completed
0.1596,Event,ADDED,eval-conflicts-rho010-r2-066-qk5n4.18d4668893998c3a,reason=Scheduled count=None msg=Successfully assigned compute/eval-conflicts-rho010-r2-066-qk5n4 to kind-worker5
0.1598,Event,ADDED,eval-conflicts-rho010-r2-066-qk5n4.18d46688b1bdb1a8,"reason=Pulled count=1 msg=Container image ""busybox:musl"" already present on machine"
0.1602,Event,ADDED,eval-conflicts-rho010-r2-066-qk5n4.18d46688b2e1c32b,reason=Created count=1 msg=Created container: task
0.1604,Event,ADDED,eval-conflicts-rho010-r2-066-qk5n4.18d46688b5fa14eb,reason=Started count=1 msg=Started container task
0.1606,Event,ADDED,eval-conflicts-rho010-r2-066.18d46688928915f9,reason=SuccessfulCreate count=1 msg=Created pod: eval-conflicts-rho010-r2-066-qk5n4
0.1607,Event,ADDED,eval-conflicts-rho010-r2-066.18d4668bd17d2847,reason=Completed count=1 msg=Job completed
0.1609,Event,ADDED,eval-conflicts-rho010-r2-067-phm5q.18d46688cf594591,reason=Scheduled count=None msg=Successfully assigned compute/eval-conflicts-rho010-r2-067-phm5q to kind-worker5
0.1611,Event,ADDED,eval-conflicts-rho010-r2-067-phm5q.18d46688e887a976,"reason=Pulled count=1 msg=Container image ""busybox:musl"" already present on machine"
0.1613,Event,ADDED,eval-conflicts-rho010-r2-067-phm5q.18d46688e98dfcf8,reason=Created count=1 msg=Created container: task
0.1615,Event,ADDED,eval-conflicts-rho010-r2-067-phm5q.18d46688eba170be,reason=Started count=1 msg=Started container task
0.1616,Event,ADDED,eval-conflicts-rho010-r2-067.18d46688ce35be1b,reason=SuccessfulCreate count=1 msg=Created pod: eval-conflicts-rho010-r2-067-phm5q
0.1618,Event,ADDED,eval-conflicts-rho010-r2-067.18d4668c0da19d7f,reason=Completed count=1 msg=Job completed
0.1619,Event,ADDED,eval-conflicts-rho010-r2-068-s4w5x.18d466890abeff1b,reason=Scheduled count=None msg=Successfully assigned compute/eval-conflicts-rho010-r2-068-s4w5x to kind-worker5
0.1621,Event,ADDED,eval-conflicts-rho010-r2-068-s4w5x.18d466892658f002,"reason=Pulled count=1 msg=Container image ""busybox:musl"" already present on machine"
0.1623,Event,ADDED,eval-conflicts-rho010-r2-068-s4w5x.18d46689276ebb7e,reason=Created count=1 msg=Created container: task
0.1625,Event,ADDED,eval-conflicts-rho010-r2-068-s4w5x.18d466892e1e784b,reason=Started count=1 msg=Started container task
0.1627,Event,ADDED,eval-conflicts-rho010-r2-068.18d46689098babc8,reason=SuccessfulCreate count=1 msg=Created pod: eval-conflicts-rho010-r2-068-s4w5x
0.1628,Event,ADDED,eval-conflicts-rho010-r2-068.18d4668c4985ad06,reason=Completed count=1 msg=Job completed
0.163,Event,ADDED,eval-conflicts-rho010-r2-069-r77c9.18d4668946741390,reason=Scheduled count=None msg=Successfully assigned compute/eval-conflicts-rho010-r2-069-r77c9 to kind-worker5
0.1632,Event,ADDED,eval-conflicts-rho010-r2-069-r77c9.18d46689608ec48c,"reason=Pulled count=1 msg=Container image ""busybox:musl"" already present on machine"
0.1634,Event,ADDED,eval-conflicts-rho010-r2-069-r77c9.18d46689619e7ab9,reason=Created count=1 msg=Created container: task
0.1636,Event,ADDED,eval-conflicts-rho010-r2-069-r77c9.18d4668966071b2a,reason=Started count=1 msg=Started container task
0.1638,Event,ADDED,eval-conflicts-rho010-r2-069.18d46689456150a5,reason=SuccessfulCreate count=1 msg=Created pod: eval-conflicts-rho010-r2-069-r77c9
0.164,Event,ADDED,eval-conflicts-rho010-r2-069.18d4668c855d12b2,reason=Completed count=1 msg=Job completed
0.1641,Event,ADDED,eval-conflicts-rho010-r2-070-5mz9c.18d4668981e6632d,reason=Scheduled count=None msg=Successfully assigned compute/eval-conflicts-rho010-r2-070-5mz9c to kind-worker2
0.1643,Event,ADDED,eval-conflicts-rho010-r2-070-5mz9c.18d466899b9b1975,"reason=Pulled count=1 msg=Container image ""busybox:musl"" already present on machine"
0.1645,Event,ADDED,eval-conflicts-rho010-r2-070-5mz9c.18d466899ccd6a1d,reason=Created count=1 msg=Created container: task
0.1646,Event,ADDED,eval-conflicts-rho010-r2-070-5mz9c.18d46689a3bab941,reason=Started count=1 msg=Started container task
0.1648,Event,ADDED,eval-conflicts-rho010-r2-070.18d4668980becac1,reason=SuccessfulCreate count=1 msg=Created pod: eval-conflicts-rho010-r2-070-5mz9c
0.165,Event,ADDED,eval-conflicts-rho010-r2-070.18d4668c888cb061,reason=Completed count=1 msg=Job completed
0.1651,Event,ADDED,eval-conflicts-rho010-r2-071-vb7sq.18d46689c2136c33,reason=Scheduled count=None msg=Successfully assigned compute/eval-conflicts-rho010-r2-071-vb7sq to kind-worker
0.1653,Event,ADDED,eval-conflicts-rho010-r2-071-vb7sq.18d46689dd85d3ae,"reason=Pulled count=1 msg=Container image ""busybox:musl"" already present on machine"
0.1654,Event,ADDED,eval-conflicts-rho010-r2-071-vb7sq.18d46689de9e50aa,reason=Created count=1 msg=Created container: task
0.1656,Event,ADDED,eval-conflicts-rho010-r2-071-vb7sq.18d46689e66f307b,reason=Started count=1 msg=Started container task
0.1658,Event,ADDED,eval-conflicts-rho010-r2-071.18d46689c156687e,reason=SuccessfulCreate count=1 msg=Created pod: eval-conflicts-rho010-r2-071-vb7sq
0.1659,Event,ADDED,eval-conflicts-rho010-r2-071.18d4668cf29e9dde,reason=Completed count=1 msg=Job completed
0.1661,Event,ADDED,eval-conflicts-rho010-r2-072-ck5zg.18d46689f91ae1b3,reason=Scheduled count=None msg=Successfully assigned compute/eval-conflicts-rho010-r2-072-ck5zg to kind-worker
0.1663,Event,ADDED,eval-conflicts-rho010-r2-072-ck5zg.18d4668a156ca316,"reason=Pulled count=1 msg=Container image ""busybox:musl"" already present on machine"
0.1664,Event,ADDED,eval-conflicts-rho010-r2-072-ck5zg.18d4668a167d5945,reason=Created count=1 msg=Created container: task
0.1666,Event,ADDED,eval-conflicts-rho010-r2-072-ck5zg.18d4668a18738cd3,reason=Started count=1 msg=Started container task
0.1668,Event,ADDED,eval-conflicts-rho010-r2-072.18d46689f84dffcc,reason=SuccessfulCreate count=1 msg=Created pod: eval-conflicts-rho010-r2-072-ck5zg
0.1669,Event,ADDED,eval-conflicts-rho010-r2-072.18d4668d2eaa9c3a,reason=Completed count=1 msg=Job completed
0.1671,Event,ADDED,eval-conflicts-rho010-r2-073-vm2wh.18d4668a34ba3fef,reason=Scheduled count=None msg=Successfully assigned compute/eval-conflicts-rho010-r2-073-vm2wh to kind-worker
0.1673,Event,ADDED,eval-conflicts-rho010-r2-073-vm2wh.18d4668a60254a83,"reason=Pulled count=1 msg=Container image ""busybox:musl"" already present on machine"
0.1674,Event,ADDED,eval-conflicts-rho010-r2-073-vm2wh.18d4668a6134f73c,reason=Created count=1 msg=Created container: task
0.1676,Event,ADDED,eval-conflicts-rho010-r2-073-vm2wh.18d4668a63557f49,reason=Started count=1 msg=Started container task
0.1678,Event,ADDED,eval-conflicts-rho010-r2-073.18d4668a33db0e31,reason=SuccessfulCreate count=1 msg=Created pod: eval-conflicts-rho010-r2-073-vm2wh
0.1679,Event,ADDED,eval-conflicts-rho010-r2-073.18d4668da762d528,reason=Completed count=1 msg=Job completed
0.1681,Event,ADDED,eval-conflicts-rho010-r2-074-wmg4k.18d4668a70dc5349,reason=Scheduled count=None msg=Successfully assigned compute/eval-conflicts-rho010-r2-074-wmg4k to kind-worker
0.1683,Event,ADDED,eval-conflicts-rho010-r2-074-wmg4k.18d4668a8cc4180b,"reason=Pulled count=1 msg=Container image ""busybox:musl"" already present on machine"
0.1684,Event,ADDED,eval-conflicts-rho010-r2-074-wmg4k.18d4668a8dd7f0be,reason=Created count=1 msg=Created container: task
0.1686,Event,ADDED,eval-conflicts-rho010-r2-074-wmg4k.18d4668a94427d68,reason=Started count=1 msg=Started container task
0.1687,Event,ADDED,eval-conflicts-rho010-r2-074.18d4668a702df7d6,reason=SuccessfulCreate count=1 msg=Created pod: eval-conflicts-rho010-r2-074-wmg4k
0.1689,Event,ADDED,eval-conflicts-rho010-r2-074.18d4668da765dadd,reason=Completed count=1 msg=Job completed
0.1691,Event,ADDED,eval-conflicts-rho010-r2-075-th99l.18d4668aafc671f3,reason=Scheduled count=None msg=Successfully assigned compute/eval-conflicts-rho010-r2-075-th99l to kind-worker
0.1692,Event,ADDED,eval-conflicts-rho010-r2-075-th99l.18d4668aced67cd8,"reason=Pulled count=1 msg=Container image ""busybox:musl"" already present on machine"
0.1694,Event,ADDED,eval-conflicts-rho010-r2-075-th99l.18d4668ad0164826,reason=Created count=1 msg=Created container: task
0.1696,Event,ADDED,eval-conflicts-rho010-r2-075-th99l.18d4668ad4f4c3f7,reason=Started count=1 msg=Started container task
0.1698,Event,ADDED,eval-conflicts-rho010-r2-075.18d4668aaf22c106,reason=SuccessfulCreate count=1 msg=Created pod: eval-conflicts-rho010-r2-075-th99l
0.17,Event,ADDED,eval-conflicts-rho010-r2-075.18d4668de2b1ef10,reason=Completed count=1 msg=Job completed
0.1704,Event,ADDED,eval-conflicts-rho010-r2-076-gx225.18d4668ae72d2cbb,reason=Scheduled count=None msg=Successfully assigned compute/eval-conflicts-rho010-r2-076-gx225 to kind-worker
0.1705,Event,ADDED,eval-conflicts-rho010-r2-076-gx225.18d4668b00760c77,"reason=Pulled count=1 msg=Container image ""busybox:musl"" already present on machine"
0.1707,Event,ADDED,eval-conflicts-rho010-r2-076-gx225.18d4668b0182be63,reason=Created count=1 msg=Created container: task
0.1709,Event,ADDED,eval-conflicts-rho010-r2-076-gx225.18d4668b03879087,reason=Started count=1 msg=Started container task
0.1712,Event,ADDED,eval-conflicts-rho010-r2-076.18d4668ae69d2ed7,reason=SuccessfulCreate count=1 msg=Created pod: eval-conflicts-rho010-r2-076-gx225
0.1713,Event,ADDED,eval-conflicts-rho010-r2-076.18d4668e1e5de038,reason=Completed count=1 msg=Job completed
0.1715,Event,ADDED,eval-conflicts-rho010-r2-077-wgd77.18d4668b22e34f8a,reason=Scheduled count=None msg=Successfully assigned compute/eval-conflicts-rho010-r2-077-wgd77 to kind-worker
0.1717,Event,ADDED,eval-conflicts-rho010-r2-077-wgd77.18d4668b3bed7456,"reason=Pulled count=1 msg=Container image ""busybox:musl"" already present on machine"
0.172,Event,ADDED,eval-conflicts-rho010-r2-077-wgd77.18d4668b3d3167bc,reason=Created count=1 msg=Created container: task
0.1722,Event,ADDED,eval-conflicts-rho010-r2-077-wgd77.18d4668b3f463ea6,reason=Started count=1 msg=Started container task
0.1724,Event,ADDED,eval-conflicts-rho010-r2-077.18d4668b225ecedf,reason=SuccessfulCreate count=1 msg=Created pod: eval-conflicts-rho010-r2-077-wgd77
0.1727,Event,ADDED,eval-conflicts-rho010-r2-077.18d4668e59f434ab,reason=Completed count=1 msg=Job completed
0.173,Event,ADDED,eval-conflicts-rho010-r2-078-dtlbb.18d4668b5eb1f756,"reason=FailedScheduling count=None msg=0/6 nodes are available: 1 c_wall violated: 1 conflicting context pair(s) with node memory, 5 node(s) had untolerated taint(s). no new claims to deallocate, preemption: 0/6 nodes are available: 1 No preemption victims found for incoming pod, 5 Preemption is not helpful for scheduling."
0.1732,Event,ADDED,eval-conflicts-rho010-r2-078-dtlbb.18d4668b5f857183,"reason=FailedScheduling count=None msg=0/6 nodes are available: 1 c_wall violated: 1 conflicting context pair(s) with node memory, 5 node(s) had untolerated taint(s). no new claims to deallocate, preemption: 0/6 nodes are available: 1 No preemption victims found for incoming pod, 5 Preemption is not helpful for scheduling."
0.1735,Event,ADDED,eval-conflicts-rho010-r2-078-dtlbb.18d4668c0c16342b,reason=Scheduled count=None msg=Successfully assigned compute/eval-conflicts-rho010-r2-078-dtlbb to kind-worker3
0.1737,Event,ADDED,eval-conflicts-rho010-r2-078-dtlbb.18d4668c265dbb87,"reason=Pulled count=1 msg=Container image ""busybox:musl"" already present on machine"
0.1739,Event,ADDED,eval-conflicts-rho010-r2-078-dtlbb.18d4668c28269d73,reason=Created count=1 msg=Created container: task
0.1742,Event,ADDED,eval-conflicts-rho010-r2-078-dtlbb.18d4668c2a62488e,reason=Started count=1 msg=Started container task
0.1745,Event,ADDED,eval-conflicts-rho010-r2-078.18d4668b5e681bc1,reason=SuccessfulCreate count=1 msg=Created pod: eval-conflicts-rho010-r2-078-dtlbb
0.1747,Event,ADDED,eval-conflicts-rho010-r2-078.18d4668f47ae030d,reason=Completed count=1 msg=Job completed
0.1749,Event,ADDED,eval-conflicts-rho010-r2-079-79xcd.18d4668b99a79cb2,"reason=FailedScheduling count=None msg=0/6 nodes are available: 1 c_wall violated: 1 conflicting context pair(s) with node memory, 5 node(s) had untolerated taint(s). no new claims to deallocate, preemption: 0/6 nodes are available: 1 No preemption victims found for incoming pod, 5 Preemption is not helpful for scheduling."
0.1751,Event,ADDED,eval-conflicts-rho010-r2-079-79xcd.18d4668b9a46ca82,"reason=FailedScheduling count=None msg=0/6 nodes are available: 1 c_wall violated: 1 conflicting context pair(s) with node memory, 5 node(s) had untolerated taint(s). no new claims to deallocate, preemption: 0/6 nodes are available: 1 No preemption victims found for incoming pod, 5 Preemption is not helpful for scheduling."
0.1752,Event,ADDED,eval-conflicts-rho010-r2-079-79xcd.18d4668c0c6f5947,reason=Scheduled count=None msg=Successfully assigned compute/eval-conflicts-rho010-r2-079-79xcd to kind-worker3
0.1754,Event,ADDED,eval-conflicts-rho010-r2-079-79xcd.18d4668c269fea6c,"reason=Pulled count=1 msg=Container image ""busybox:musl"" already present on machine"
0.1756,Event,ADDED,eval-conflicts-rho010-r2-079-79xcd.18d4668c2864b8cd,reason=Created count=1 msg=Created container: task
0.1758,Event,ADDED,eval-conflicts-rho010-r2-079-79xcd.18d4668c2a62a335,reason=Started count=1 msg=Started container task
0.1759,Event,ADDED,eval-conflicts-rho010-r2-079.18d4668b996a4e95,reason=SuccessfulCreate count=1 msg=Created pod: eval-conflicts-rho010-r2-079-79xcd
0.1761,Event,ADDED,eval-conflicts-rho010-r2-079.18d4668f484b4b8b,reason=Completed count=1 msg=Job completed
0.1763,Event,ADDED,eval-conflicts-rho010-r2-080-npv2r.18d4668bd6fc9a86,reason=Scheduled count=None msg=Successfully assigned compute/eval-conflicts-rho010-r2-080-npv2r to kind-worker
0.1764,Event,ADDED,eval-conflicts-rho010-r2-080-npv2r.18d4668bef938346,"reason=Pulled count=1 msg=Container image ""busybox:musl"" already present on machine"
0.1766,Event,ADDED,eval-conflicts-rho010-r2-080-npv2r.18d4668bf0a1c200,reason=Created count=1 msg=Created container: task
0.1768,Event,ADDED,eval-conflicts-rho010-r2-080-npv2r.18d4668bf2743165,reason=Started count=1 msg=Started container task
0.1769,Event,ADDED,eval-conflicts-rho010-r2-080.18d4668bd670d2a3,reason=SuccessfulCreate count=1 msg=Created pod: eval-conflicts-rho010-r2-080-npv2r
0.1771,Event,ADDED,eval-conflicts-rho010-r2-080.18d4668f0d475e44,reason=Completed count=1 msg=Job completed
0.1772,Event,ADDED,eval-conflicts-rho010-r2-081-49nrx.18d4668c14605f65,reason=Scheduled count=None msg=Successfully assigned compute/eval-conflicts-rho010-r2-081-49nrx to kind-worker3
0.1774,Event,ADDED,eval-conflicts-rho010-r2-081-49nrx.18d4668c2be49b6c,"reason=Pulled count=1 msg=Container image ""busybox:musl"" already present on machine"
0.1776,Event,ADDED,eval-conflicts-rho010-r2-081-49nrx.18d4668c2d0d7093,reason=Created count=1 msg=Created container: task
0.1778,Event,ADDED,eval-conflicts-rho010-r2-081-49nrx.18d4668c2ef3a5b3,reason=Started count=1 msg=Started container task
0.1779,Event,ADDED,eval-conflicts-rho010-r2-081.18d4668c13d0f4ec,reason=SuccessfulCreate count=1 msg=Created pod: eval-conflicts-rho010-r2-081-49nrx
0.1781,Event,ADDED,eval-conflicts-rho010-r2-081.18d4668f47d50f2b,reason=Completed count=1 msg=Job completed
0.1782,Event,ADDED,eval-conflicts-rho010-r2-082-9l5zn.18d4668c4d58b807,reason=Scheduled count=None msg=Successfully assigned compute/eval-conflicts-rho010-r2-082-9l5zn to kind-worker4
0.1784,Event,ADDED,eval-conflicts-rho010-r2-082-9l5zn.18d4668c665cb39c,"reason=Pulled count=1 msg=Container image ""busybox:musl"" already present on machine"
0.1786,Event,ADDED,eval-conflicts-rho010-r2-082-9l5zn.18d4668c67654317,reason=Created count=1 msg=Created container: task
0.1788,Event,ADDED,eval-conflicts-rho010-r2-082-9l5zn.18d4668c69b04676,reason=Started count=1 msg=Started container task
0.1789,Event,ADDED,eval-conflicts-rho010-r2-082.18d4668c4c4556b9,reason=SuccessfulCreate count=1 msg=Created pod: eval-conflicts-rho010-r2-082-9l5zn
0.1791,Event,ADDED,eval-conflicts-rho010-r2-082.18d4668f9e15f882,reason=Completed count=1 msg=Job completed
0.1792,Event,ADDED,eval-conflicts-rho010-r2-083-g898l.18d4668c89120e48,reason=Scheduled count=None msg=Successfully assigned compute/eval-conflicts-rho010-r2-083-g898l to kind-worker4
0.1794,Event,ADDED,eval-conflicts-rho010-r2-083-g898l.18d4668ca27df032,"reason=Pulled count=1 msg=Container image ""busybox:musl"" already present on machine"
0.1796,Event,ADDED,eval-conflicts-rho010-r2-083-g898l.18d4668ca38e125b,reason=Created count=1 msg=Created container: task
0.1798,Event,ADDED,eval-conflicts-rho010-r2-083-g898l.18d4668ca5746b07,reason=Started count=1 msg=Started container task
0.18,Event,ADDED,eval-conflicts-rho010-r2-083.18d4668c87fcc2e7,reason=SuccessfulCreate count=1 msg=Created pod: eval-conflicts-rho010-r2-083-g898l
0.1801,Event,ADDED,eval-conflicts-rho010-r2-083.18d4668fda04e4e4,reason=Completed count=1 msg=Job completed
0.1804,Event,ADDED,eval-conflicts-rho010-r2-084-l4z7b.18d4668cc41e23c2,reason=Scheduled count=None msg=Successfully assigned compute/eval-conflicts-rho010-r2-084-l4z7b to kind-worker5
0.1806,Event,ADDED,eval-conflicts-rho010-r2-084-l4z7b.18d4668cdd9e2603,"reason=Pulled count=1 msg=Container image ""busybox:musl"" already present on machine"
0.1807,Event,ADDED,eval-conflicts-rho010-r2-084-l4z7b.18d4668cdeb16d9e,reason=Created count=1 msg=Created container: task
0.1809,Event,ADDED,eval-conflicts-rho010-r2-084-l4z7b.18d4668ce0b82bd6,reason=Started count=1 msg=Started container task
0.1811,Event,ADDED,eval-conflicts-rho010-r2-084.18d4668cc334860b,reason=SuccessfulCreate count=1 msg=Created pod: eval-conflicts-rho010-r2-084-l4z7b
0.1812,Event,ADDED,eval-conflicts-rho010-r2-084.18d4668fcb310502,reason=Completed count=1 msg=Job completed
0.1814,Event,ADDED,eval-conflicts-rho010-r2-085-k89rh.18d4668d00076260,reason=Scheduled count=None msg=Successfully assigned compute/eval-conflicts-rho010-r2-085-k89rh to kind-worker5
0.1816,Event,ADDED,eval-conflicts-rho010-r2-085-k89rh.18d4668d1983b49d,"reason=Pulled count=1 msg=Container image ""busybox:musl"" already present on machine"
0.1817,Event,ADDED,eval-conflicts-rho010-r2-085-k89rh.18d4668d1a9d5b92,reason=Created count=1 msg=Created container: task
0.1819,Event,ADDED,eval-conflicts-rho010-r2-085-k89rh.18d4668d1c8baad1,reason=Started count=1 msg=Started container task
0.1821,Event,ADDED,eval-conflicts-rho010-r2-085.18d4668cfef704f5,reason=SuccessfulCreate count=1 msg=Created pod: eval-conflicts-rho010-r2-085-k89rh
0.1822,Event,ADDED,eval-conflicts-rho010-r2-085.18d4669006aa5a6a,reason=Completed count=1 msg=Job completed
0.1825,Event,ADDED,eval-conflicts-rho010-r2-086-sd5k4.18d4668d3b9d8260,reason=Scheduled count=None msg=Successfully assigned compute/eval-conflicts-rho010-r2-086-sd5k4 to kind-worker5
0.1826,Event,ADDED,eval-conflicts-rho010-r2-086-sd5k4.18d4668d54fa3fb6,"reason=Pulled count=1 msg=Container image ""busybox:musl"" already present on machine"
0.1829,Event,ADDED,eval-conflicts-rho010-r2-086-sd5k4.18d4668d55fceeb8,reason=Created count=1 msg=Created container: task
0.183,Event,ADDED,eval-conflicts-rho010-r2-086-sd5k4.18d4668d57ed4c53,reason=Started count=1 msg=Started container task
0.1832,Event,ADDED,eval-conflicts-rho010-r2-086.18d4668d3a92cc3c,reason=SuccessfulCreate count=1 msg=Created pod: eval-conflicts-rho010-r2-086-sd5k4
0.1834,Event,ADDED,eval-conflicts-rho010-r2-086.18d466907dbf7147,reason=Completed count=1 msg=Job completed
0.1835,Event,ADDED,eval-conflicts-rho010-r2-087-n7sd2.18d4668d7717fa68,reason=Scheduled count=None msg=Successfully assigned compute/eval-conflicts-rho010-r2-087-n7sd2 to kind-worker4
0.1837,Event,ADDED,eval-conflicts-rho010-r2-087-n7sd2.18d4668d915b4f83,"reason=Pulled count=1 msg=Container image ""busybox:musl"" already present on machine"
0.1839,Event,ADDED,eval-conflicts-rho010-r2-087-n7sd2.18d4668d927b5e80,reason=Created count=1 msg=Created container: task
0.184,Event,ADDED,eval-conflicts-rho010-r2-087-n7sd2.18d4668d95f0794e,reason=Started count=1 msg=Started container task
0.1842,Event,ADDED,eval-conflicts-rho010-r2-087.18d4668d761fd0d4,reason=SuccessfulCreate count=1 msg=Created pod: eval-conflicts-rho010-r2-087-n7sd2
0.1844,Event,ADDED,eval-conflicts-rho010-r2-087.18d46690c99214c6,reason=Completed count=1 msg=Job completed
0.1845,Event,ADDED,eval-conflicts-rho010-r2-088-vtqgk.18d4668db38e66ef,reason=Scheduled count=None msg=Successfully assigned compute/eval-conflicts-rho010-r2-088-vtqgk to kind-worker5
0.1847,Event,ADDED,eval-conflicts-rho010-r2-088-vtqgk.18d4668dcc229b24,"reason=Pulled count=1 msg=Container image ""busybox:musl"" already present on machine"
0.1848,Event,ADDED,eval-conflicts-rho010-r2-088-vtqgk.18d4668dcd400cb1,reason=Created count=1 msg=Created container: task
0.185,Event,ADDED,eval-conflicts-rho010-r2-088-vtqgk.18d4668dcf6d5b02,reason=Started count=1 msg=Started container task
0.1852,Event,ADDED,eval-conflicts-rho010-r2-088.18d4668db2670cc0,reason=SuccessfulCreate count=1 msg=Created pod: eval-conflicts-rho010-r2-088-vtqgk
0.1853,Event,ADDED,eval-conflicts-rho010-r2-088.18d46690f5f8054d,reason=Completed count=1 msg=Job completed
0.1855,Event,ADDED,eval-conflicts-rho010-r2-089-9gdh7.18d4668def09275b,reason=Scheduled count=None msg=Successfully assigned compute/eval-conflicts-rho010-r2-089-9gdh7 to kind-worker5
0.1856,Event,ADDED,eval-conflicts-rho010-r2-089-9gdh7.18d4668e092af86a,"reason=Pulled count=1 msg=Container image ""busybox:musl"" already present on machine"
0.1858,Event,ADDED,eval-conflicts-rho010-r2-089-9gdh7.18d4668e0a37f1f8,reason=Created count=1 msg=Created container: task
0.186,Event,ADDED,eval-conflicts-rho010-r2-089-9gdh7.18d4668e0e03c29b,reason=Started count=1 msg=Started container task
0.1861,Event,ADDED,eval-conflicts-rho010-r2-089.18d4668dedd15f31,reason=SuccessfulCreate count=1 msg=Created pod: eval-conflicts-rho010-r2-089-9gdh7
0.1863,Event,ADDED,eval-conflicts-rho010-r2-089.18d466913260f81e,reason=Completed count=1 msg=Job completed
0.1865,Event,ADDED,eval-conflicts-rho010-r2-090-v6dns.18d4668e2a5c001e,reason=Scheduled count=None msg=Successfully assigned compute/eval-conflicts-rho010-r2-090-v6dns to kind-worker5
0.1866,Event,ADDED,eval-conflicts-rho010-r2-090-v6dns.18d4668e442afae8,"reason=Pulled count=1 msg=Container image ""busybox:musl"" already present on machine"
0.1868,Event,ADDED,eval-conflicts-rho010-r2-090-v6dns.18d4668e453cbcce,reason=Created count=1 msg=Created container: task
0.187,Event,ADDED,eval-conflicts-rho010-r2-090-v6dns.18d4668e49249ce0,reason=Started count=1 msg=Started container task
0.1871,Event,ADDED,eval-conflicts-rho010-r2-090.18d4668e294acd8d,reason=SuccessfulCreate count=1 msg=Created pod: eval-conflicts-rho010-r2-090-v6dns
0.1873,Event,ADDED,eval-conflicts-rho010-r2-090.18d466916f08aabf,reason=Completed count=1 msg=Job completed
0.1874,Event,ADDED,eval-conflicts-rho010-r2-091-nxw5v.18d4668e65b34ccb,reason=Scheduled count=None msg=Successfully assigned compute/eval-conflicts-rho010-r2-091-nxw5v to kind-worker4
0.1876,Event,ADDED,eval-conflicts-rho010-r2-091-nxw5v.18d4668e7f70ad0c,"reason=Pulled count=1 msg=Container image ""busybox:musl"" already present on machine"
0.1878,Event,ADDED,eval-conflicts-rho010-r2-091-nxw5v.18d4668e80bca191,reason=Created count=1 msg=Created container: task
0.1879,Event,ADDED,eval-conflicts-rho010-r2-091-nxw5v.18d4668e8419f7d1,reason=Started count=1 msg=Started container task
0.1881,Event,ADDED,eval-conflicts-rho010-r2-091.18d4668e64ac545e,reason=SuccessfulCreate count=1 msg=Created pod: eval-conflicts-rho010-r2-091-nxw5v
0.1883,Event,ADDED,eval-conflicts-rho010-r2-091.18d46691b9212258,reason=Completed count=1 msg=Job completed
0.1884,Event,ADDED,eval-conflicts-rho010-r2-092-blw87.18d4668ea17e48ef,reason=Scheduled count=None msg=Successfully assigned compute/eval-conflicts-rho010-r2-092-blw87 to kind-worker2
0.1886,Event,ADDED,eval-conflicts-rho010-r2-092-blw87.18d4668ebae2fb25,"reason=Pulled count=1 msg=Container image ""busybox:musl"" already present on machine"
0.1887,Event,ADDED,eval-conflicts-rho010-r2-092-blw87.18d4668ebc169db7,reason=Created count=1 msg=Created container: task
0.1889,Event,ADDED,eval-conflicts-rho010-r2-092-blw87.18d4668ebfe005f0,reason=Started count=1 msg=Started container task
0.1891,Event,ADDED,eval-conflicts-rho010-r2-092.18d4668ea0d09022,reason=SuccessfulCreate count=1 msg=Created pod: eval-conflicts-rho010-r2-092-blw87
0.1915,Event,ADDED,eval-conflicts-rho010-r2-092.18d46691e72d0234,reason=Completed count=1 msg=Job completed
0.192,Event,ADDED,eval-conflicts-rho010-r2-093-g5hsm.18d4668edcddaaac,reason=Scheduled count=None msg=Successfully assigned compute/eval-conflicts-rho010-r2-093-g5hsm to kind-worker2
0.1924,Event,ADDED,eval-conflicts-rho010-r2-093-g5hsm.18d4668ef6b6cce4,"reason=Pulled count=1 msg=Container image ""busybox:musl"" already present on machine"
0.1927,Event,ADDED,eval-conflicts-rho010-r2-093-g5hsm.18d4668ef7d9d3e5,reason=Created count=1 msg=Created container: task
0.1929,Event,ADDED,eval-conflicts-rho010-r2-093-g5hsm.18d4668f00a4df20,reason=Started count=1 msg=Started container task
0.1932,Event,ADDED,eval-conflicts-rho010-r2-093.18d4668edbe66b45,reason=SuccessfulCreate count=1 msg=Created pod: eval-conflicts-rho010-r2-093-g5hsm
0.1935,Event,ADDED,eval-conflicts-rho010-r2-093.18d46692232b279a,reason=Completed count=1 msg=Job completed
0.1938,Event,ADDED,eval-conflicts-rho010-r2-094-l5wnc.18d4668f18501c1a,reason=Scheduled count=None msg=Successfully assigned compute/eval-conflicts-rho010-r2-094-l5wnc to kind-worker5
0.1941,Event,ADDED,eval-conflicts-rho010-r2-094-l5wnc.18d4668f3157ddac,"reason=Pulled count=1 msg=Container image ""busybox:musl"" already present on machine"
0.1943,Event,ADDED,eval-conflicts-rho010-r2-094-l5wnc.18d4668f326eb523,reason=Created count=1 msg=Created container: task
0.1945,Event,ADDED,eval-conflicts-rho010-r2-094-l5wnc.18d4668f3636bc7d,reason=Started count=1 msg=Started container task
0.1946,Event,ADDED,eval-conflicts-rho010-r2-094.18d4668f1790bbb9,reason=SuccessfulCreate count=1 msg=Created pod: eval-conflicts-rho010-r2-094-l5wnc
0.1949,Event,ADDED,eval-conflicts-rho010-r2-094.18d466925d373ce9,reason=Completed count=1 msg=Job completed
0.195,Event,ADDED,eval-conflicts-rho010-r2-095-8wjd5.18d4668f53ec05ca,reason=Scheduled count=None msg=Successfully assigned compute/eval-conflicts-rho010-r2-095-8wjd5 to kind-worker2
0.1952,Event,ADDED,eval-conflicts-rho010-r2-095-8wjd5.18d4668f6d28adcd,"reason=Pulled count=1 msg=Container image ""busybox:musl"" already present on machine"
0.1954,Event,ADDED,eval-conflicts-rho010-r2-095-8wjd5.18d4668f6e4529f7,reason=Created count=1 msg=Created container: task
0.1956,Event,ADDED,eval-conflicts-rho010-r2-095-8wjd5.18d4668f7042bb66,reason=Started count=1 msg=Started container task
0.1957,Event,ADDED,eval-conflicts-rho010-r2-095.18d4668f5354c048,reason=SuccessfulCreate count=1 msg=Created pod: eval-conflicts-rho010-r2-095-8wjd5
0.1959,Event,ADDED,eval-conflicts-rho010-r2-095.18d466929adc181a,reason=Completed count=1 msg=Job completed
0.196,Event,ADDED,eval-conflicts-rho010-r2-096-8t8f4.18d4668f8f85244b,reason=Scheduled count=None msg=Successfully assigned compute/eval-conflicts-rho010-r2-096-8t8f4 to kind-worker2
0.1962,Event,ADDED,eval-conflicts-rho010-r2-096-8t8f4.18d4668fa85c544d,"reason=Pulled count=1 msg=Container image ""busybox:musl"" already present on machine"
0.1964,Event,ADDED,eval-conflicts-rho010-r2-096-8t8f4.18d4668fa9861b4f,reason=Created count=1 msg=Created container: task
0.1965,Event,ADDED,eval-conflicts-rho010-r2-096-8t8f4.18d4668fad8ab88d,reason=Started count=1 msg=Started container task
0.1967,Event,ADDED,eval-conflicts-rho010-r2-096.18d4668f8ee9b10c,reason=SuccessfulCreate count=1 msg=Created pod: eval-conflicts-rho010-r2-096-8t8f4
0.1969,Event,ADDED,eval-conflicts-rho010-r2-096.18d46692d6f229b9,reason=Completed count=1 msg=Job completed
0.197,Event,ADDED,eval-conflicts-rho010-r2-097-m54b7.18d4668fcb4c3b65,"reason=FailedScheduling count=None msg=0/6 nodes are available: 1 c_wall violated: 1 conflicting context pair(s) with node memory, 5 node(s) had untolerated taint(s). no new claims to deallocate, preemption: 0/6 nodes are available: 1 No preemption victims found for incoming pod, 5 Preemption is not helpful for scheduling."
0.1972,Event,ADDED,eval-conflicts-rho010-r2-097-m54b7.18d4668fcbe1b942,"reason=FailedScheduling count=None msg=0/6 nodes are available: 1 c_wall violated: 1 conflicting context pair(s) with node memory, 5 node(s) had untolerated taint(s). no new claims to deallocate, preemption: 0/6 nodes are available: 1 No preemption victims found for incoming pod, 5 Preemption is not helpful for scheduling."
0.1974,Event,ADDED,eval-conflicts-rho010-r2-097-m54b7.18d46690aa8502f1,reason=Scheduled count=None msg=Successfully assigned compute/eval-conflicts-rho010-r2-097-m54b7 to kind-worker
0.1976,Event,ADDED,eval-conflicts-rho010-r2-097-m54b7.18d46690c46e5ff6,"reason=Pulled count=1 msg=Container image ""busybox:musl"" already present on machine"
0.1977,Event,ADDED,eval-conflicts-rho010-r2-097-m54b7.18d46690c5e0b837,reason=Created count=1 msg=Created container: task
0.1979,Event,ADDED,eval-conflicts-rho010-r2-097-m54b7.18d46690ca35be27,reason=Started count=1 msg=Started container task
0.1981,Event,ADDED,eval-conflicts-rho010-r2-097.18d4668fcb0fe6bf,reason=SuccessfulCreate count=1 msg=Created pod: eval-conflicts-rho010-r2-097-m54b7
0.1982,Event,ADDED,eval-conflicts-rho010-r2-097.18d46693f4a08e6e,reason=Completed count=1 msg=Job completed
0.1984,Event,ADDED,eval-conflicts-rho010-r2-098-fjj9p.18d4669007800043,"reason=FailedScheduling count=None msg=0/6 nodes are available: 1 c_wall violated: 1 conflicting context pair(s) with node memory, 5 node(s) had untolerated taint(s). no new claims to deallocate, preemption: 0/6 nodes are available: 1 No preemption victims found for incoming pod, 5 Preemption is not helpful for scheduling."
0.1986,Event,ADDED,eval-conflicts-rho010-r2-098-fjj9p.18d466900812e9e7,"reason=FailedScheduling count=None msg=0/6 nodes are available: 1 c_wall violated: 1 conflicting context pair(s) with node memory, 5 node(s) had untolerated taint(s). no new claims to deallocate, preemption: 0/6 nodes are available: 1 No preemption victims found for incoming pod, 5 Preemption is not helpful for scheduling."
0.1988,Event,ADDED,eval-conflicts-rho010-r2-098-fjj9p.18d46690afef1170,"reason=FailedScheduling count=None msg=0/6 nodes are available: 2 c_wall violated: 1 conflicting context pair(s) with node memory, 4 node(s) had untolerated taint(s). no new claims to deallocate, preemption: 0/6 nodes are available: 2 No preemption victims found for incoming pod, 4 Preemption is not helpful for scheduling."
0.199,Event,ADDED,eval-conflicts-rho010-r2-098-fjj9p.18d46690c7cf43b4,"reason=FailedScheduling count=None msg=0/6 nodes are available: 1 c_wall violated: 1 conflicting context pair(s) with node memory, 5 node(s) had untolerated taint(s). no new claims to deallocate, preemption: 0/6 nodes are available: 1 No preemption victims found for incoming pod, 5 Preemption is not helpful for scheduling."
0.1991,Event,ADDED,eval-conflicts-rho010-r2-098-fjj9p.18d46690e54072d4,reason=Scheduled count=None msg=Successfully assigned compute/eval-conflicts-rho010-r2-098-fjj9p to kind-worker3
0.1993,Event,ADDED,eval-conflicts-rho010-r2-098-fjj9p.18d4669101de29b6,"reason=Pulled count=1 msg=Container image ""busybox:musl"" already present on machine"
0.1994,Event,ADDED,eval-conflicts-rho010-r2-098-fjj9p.18d46691030804a3,reason=Created count=1 msg=Created container: task
0.1996,Event,ADDED,eval-conflicts-rho010-r2-098-fjj9p.18d4669105d00d67,reason=Started count=1 msg=Started container task
0.1998,Event,ADDED,eval-conflicts-rho010-r2-098.18d46690073b8e2b,reason=SuccessfulCreate count=1 msg=Created pod: eval-conflicts-rho010-r2-098-fjj9p
0.1999,Event,ADDED,eval-conflicts-rho010-r2-098.18d466942e490d57,reason=Completed count=1 msg=Job completed
0.2001,Event,ADDED,eval-conflicts-rho010-r2-099-hbfqc.18d466904208aae6,"reason=FailedScheduling count=None msg=0/6 nodes are available: 1 c_wall violated: 1 conflicting context pair(s) with node memory, 5 node(s) had untolerated taint(s). no new claims to deallocate, preemption: 0/6 nodes are available: 1 No preemption victims found for incoming pod, 5 Preemption is not helpful for scheduling."
0.2003,Event,ADDED,eval-conflicts-rho010-r2-099-hbfqc.18d4669042a5e6f2,"reason=FailedScheduling count=None msg=0/6 nodes are available: 1 c_wall violated: 1 conflicting context pair(s) with node memory, 5 node(s) had untolerated taint(s). no new claims to deallocate, preemption: 0/6 nodes are available: 1 No preemption victims found for incoming pod, 5 Preemption is not helpful for scheduling."
0.2004,Event,ADDED,eval-conflicts-rho010-r2-099-hbfqc.18d46690afdd963a,reason=Scheduled count=None msg=Successfully assigned compute/eval-conflicts-rho010-r2-099-hbfqc to kind-worker
0.2007,Event,ADDED,eval-conflicts-rho010-r2-099-hbfqc.18d46690cabae6d5,"reason=Pulled count=1 msg=Container image ""busybox:musl"" already present on machine"
0.2008,Event,ADDED,eval-conflicts-rho010-r2-099-hbfqc.18d46690cc0b63ca,reason=Created count=1 msg=Created container: task
0.201,Event,ADDED,eval-conflicts-rho010-r2-099-hbfqc.18d46690ce676c98,reason=Started count=1 msg=Started container task
0.2011,Event,ADDED,eval-conflicts-rho010-r2-099.18d4669041991d94,reason=SuccessfulCreate count=1 msg=Created pod: eval-conflicts-rho010-r2-099-hbfqc
0.2013,Event,ADDED,eval-conflicts-rho010-r2-099.18d46693f4bf4c33,reason=Completed count=1 msg=Job completed
0.2015,Event,ADDED,eval-conflicts-rho010-r3-000-kzrhp.18d46698d8b2baf8,reason=Scheduled count=None msg=Successfully assigned compute/eval-conflicts-rho010-r3-000-kzrhp to kind-worker
0.2016,Event,ADDED,eval-conflicts-rho010-r3-000-kzrhp.18d46698f241a62e,"reason=Pulled count=1 msg=Container image ""busybox:musl"" already present on machine"
0.2018,Event,ADDED,eval-conflicts-rho010-r3-000-kzrhp.18d46698f3587087,reason=Created count=1 msg=Created container: task
0.202,Event,ADDED,eval-conflicts-rho010-r3-000-kzrhp.18d46698f843233d,reason=Started count=1 msg=Started container task
0.2021,Event,ADDED,eval-conflicts-rho010-r3-000.18d46698d7cf2177,reason=SuccessfulCreate count=1 msg=Created pod: eval-conflicts-rho010-r3-000-kzrhp
0.2023,Event,ADDED,eval-conflicts-rho010-r3-000.18d4669c2055c1e3,reason=Completed count=1 msg=Job completed
0.2024,Event,ADDED,eval-conflicts-rho010-r3-001-f8zf7.18d466991385df86,reason=Scheduled count=None msg=Successfully assigned compute/eval-conflicts-rho010-r3-001-f8zf7 to kind-worker5
0.2026,Event,ADDED,eval-conflicts-rho010-r3-001-f8zf7.18d466992c054700,"reason=Pulled count=1 msg=Container image ""busybox:musl"" already present on machine"
0.2028,Event,ADDED,eval-conflicts-rho010-r3-001-f8zf7.18d466992d4fbada,reason=Created count=1 msg=Created container: task
0.2029,Event,ADDED,eval-conflicts-rho010-r3-001-f8zf7.18d466992f46db41,reason=Started count=1 msg=Started container task
0.2032,Event,ADDED,eval-conflicts-rho010-r3-001.18d4669912620cdd,reason=SuccessfulCreate count=1 msg=Created pod: eval-conflicts-rho010-r3-001-f8zf7
0.2034,Event,ADDED,eval-conflicts-rho010-r3-001.18d4669c6598fcfc,reason=Completed count=1 msg=Job completed
0.2035,Event,ADDED,eval-conflicts-rho010-r3-002-bwz82.18d466994df47e45,reason=Scheduled count=None msg=Successfully assigned compute/eval-conflicts-rho010-r3-002-bwz82 to kind-worker2
0.204,Event,ADDED,eval-conflicts-rho010-r3-002-bwz82.18d46699674d7c78,"reason=Pulled count=1 msg=Container image ""busybox:musl"" already present on machine"
0.2044,Event,ADDED,eval-conflicts-rho010-r3-002-bwz82.18d4669968626240,reason=Created count=1 msg=Created container: task
0.2047,Event,ADDED,eval-conflicts-rho010-r3-002-bwz82.18d466996a7e992e,reason=Started count=1 msg=Started container task
0.2049,Event,ADDED,eval-conflicts-rho010-r3-002.18d466994cfc1403,reason=SuccessfulCreate count=1 msg=Created pod: eval-conflicts-rho010-r3-002-bwz82
0.2053,Event,ADDED,eval-conflicts-rho010-r3-002.18d4669ca2fe662d,reason=Completed count=1 msg=Job completed
0.2055,Event,ADDED,eval-conflicts-rho010-r3-003-gv7tx.18d4669989ab6e45,reason=Scheduled count=None msg=Successfully assigned compute/eval-conflicts-rho010-r3-003-gv7tx to kind-worker5
0.2056,Event,ADDED,eval-conflicts-rho010-r3-003-gv7tx.18d46699a322199a,"reason=Pulled count=1 msg=Container image ""busybox:musl"" already present on machine"
0.2058,Event,ADDED,eval-conflicts-rho010-r3-003-gv7tx.18d46699a435dd3f,reason=Created count=1 msg=Created container: task
0.2061,Event,ADDED,eval-conflicts-rho010-r3-003-gv7tx.18d46699a64c0361,reason=Started count=1 msg=Started container task
0.2063,Event,ADDED,eval-conflicts-rho010-r3-003.18d46699888f5ad9,reason=SuccessfulCreate count=1 msg=Created pod: eval-conflicts-rho010-r3-003-gv7tx
0.2065,Event,ADDED,eval-conflicts-rho010-r3-003.18d4669cdd356f0c,reason=Completed count=1 msg=Job completed
0.2068,Event,ADDED,eval-conflicts-rho010-r3-004-npkrv.18d46699c51ad480,reason=Scheduled count=None msg=Successfully assigned compute/eval-conflicts-rho010-r3-004-npkrv to kind-worker2
0.2069,Event,ADDED,eval-conflicts-rho010-r3-004-npkrv.18d46699dd4fb794,"reason=Pulled count=1 msg=Container image ""busybox:musl"" already present on machine"
0.2071,Event,ADDED,eval-conflicts-rho010-r3-004-npkrv.18d46699de60b6dc,reason=Created count=1 msg=Created container: task
0.2073,Event,ADDED,eval-conflicts-rho010-r3-004-npkrv.18d46699e04fa957,reason=Started count=1 msg=Started container task
0.2075,Event,ADDED,eval-conflicts-rho010-r3-004.18d46699c3f76431,reason=SuccessfulCreate count=1 msg=Created pod: eval-conflicts-rho010-r3-004-npkrv
0.2077,Event,ADDED,eval-conflicts-rho010-r3-004.18d4669d1ab2733c,reason=Completed count=1 msg=Job completed
0.2078,Event,ADDED,eval-conflicts-rho010-r3-005-dg4s6.18d4669a00b1cac6,reason=Scheduled count=None msg=Successfully assigned compute/eval-conflicts-rho010-r3-005-dg4s6 to kind-worker
0.208,Event,ADDED,eval-conflicts-rho010-r3-005-dg4s6.18d4669a196198f6,"reason=Pulled count=1 msg=Container image ""busybox:musl"" already present on machine"
0.2082,Event,ADDED,eval-conflicts-rho010-r3-005-dg4s6.18d4669a1a6ab7b8,reason=Created count=1 msg=Created container: task
0.2083,Event,ADDED,eval-conflicts-rho010-r3-005-dg4s6.18d4669a1c7628c6,reason=Started count=1 msg=Started container task
0.2085,Event,ADDED,eval-conflicts-rho010-r3-005.18d46699ffacfee6,reason=SuccessfulCreate count=1 msg=Created pod: eval-conflicts-rho010-r3-005-dg4s6
0.2087,Event,ADDED,eval-conflicts-rho010-r3-005.18d4669d4c5fdb36,reason=Completed count=1 msg=Job completed
0.2088,Event,ADDED,eval-conflicts-rho010-r3-006-dz8pf.18d4669a3c61eb7f,reason=Scheduled count=None msg=Successfully assigned compute/eval-conflicts-rho010-r3-006-dz8pf to kind-worker4
0.209,Event,ADDED,eval-conflicts-rho010-r3-006-dz8pf.18d4669a554d4ad2,"reason=Pulled count=1 msg=Container image ""busybox:musl"" already present on machine"
0.2093,Event,ADDED,eval-conflicts-rho010-r3-006-dz8pf.18d4669a5680e6a3,reason=Created count=1 msg=Created container: task
0.2095,Event,ADDED,eval-conflicts-rho010-r3-006-dz8pf.18d4669a58c57725,reason=Started count=1 msg=Started container task
0.2097,Event,ADDED,eval-conflicts-rho010-r3-006.18d4669a3b808cc4,reason=SuccessfulCreate count=1 msg=Created pod: eval-conflicts-rho010-r3-006-dz8pf
0.2099,Event,ADDED,eval-conflicts-rho010-r3-006.18d4669d9f0ce22d,reason=Completed count=1 msg=Job completed
0.2101,Event,ADDED,eval-conflicts-rho010-r3-007-nj2nk.18d4669a7755b8f8,reason=Scheduled count=None msg=Successfully assigned compute/eval-conflicts-rho010-r3-007-nj2nk to kind-worker3
0.2103,Event,ADDED,eval-conflicts-rho010-r3-007-nj2nk.18d4669a8fc59a28,"reason=Pulled count=1 msg=Container image ""busybox:musl"" already present on machine"
0.2105,Event,ADDED,eval-conflicts-rho010-r3-007-nj2nk.18d4669a90cb47ab,reason=Created count=1 msg=Created container: task
0.2107,Event,ADDED,eval-conflicts-rho010-r3-007-nj2nk.18d4669a95325508,reason=Started count=1 msg=Started container task
0.211,Event,ADDED,eval-conflicts-rho010-r3-007.18d4669a76d08002,reason=SuccessfulCreate count=1 msg=Created pod: eval-conflicts-rho010-r3-007-nj2nk
0.2112,Event,ADDED,eval-conflicts-rho010-r3-007.18d4669dbfe4c25c,reason=Completed count=1 msg=Job completed
0.2115,Event,ADDED,eval-conflicts-rho010-r3-008-lkbq4.18d4669ab37f216a,reason=Scheduled count=None msg=Successfully assigned compute/eval-conflicts-rho010-r3-008-lkbq4 to kind-worker5
0.2117,Event,ADDED,eval-conflicts-rho010-r3-008-lkbq4.18d4669acdacc861,"reason=Pulled count=1 msg=Container image ""busybox:musl"" already present on machine"
0.212,Event,ADDED,eval-conflicts-rho010-r3-008-lkbq4.18d4669acec4d1c4,reason=Created count=1 msg=Created container: task
0.2122,Event,ADDED,eval-conflicts-rho010-r3-008-lkbq4.18d4669ad208d225,reason=Started count=1 msg=Started container task
0.2124,Event,ADDED,eval-conflicts-rho010-r3-008.18d4669ab2889980,reason=SuccessfulCreate count=1 msg=Created pod: eval-conflicts-rho010-r3-008-lkbq4
0.2127,Event,ADDED,eval-conflicts-rho010-r3-008.18d4669e07c17c45,reason=Completed count=1 msg=Job completed
0.2128,Event,ADDED,eval-conflicts-rho010-r3-009-2jzch.18d4669aeeacac5d,reason=Scheduled count=None msg=Successfully assigned compute/eval-conflicts-rho010-r3-009-2jzch to kind-worker3
0.213,Event,ADDED,eval-conflicts-rho010-r3-009-2jzch.18d4669b06fcb740,"reason=Pulled count=1 msg=Container image ""busybox:musl"" already present on machine"
0.2132,Event,ADDED,eval-conflicts-rho010-r3-009-2jzch.18d4669b0807886e,reason=Created count=1 msg=Created container: task
0.2135,Event,ADDED,eval-conflicts-rho010-r3-009-2jzch.18d4669b09e073bd,reason=Started count=1 msg=Started container task
0.2136,Event,ADDED,eval-conflicts-rho010-r3-009.18d4669aee07bf49,reason=SuccessfulCreate count=1 msg=Created pod: eval-conflicts-rho010-r3-009-2jzch
0.2138,Event,ADDED,eval-conflicts-rho010-r3-009.18d4669e37b2abbb,reason=Completed count=1 msg=Job completed
0.214,Event,ADDED,eval-conflicts-rho010-r3-010-rchzl.18d4669b2b3e97a7,reason=Scheduled count=None msg=Successfully assigned compute/eval-conflicts-rho010-r3-010-rchzl to kind-worker3
0.2142,Event,ADDED,eval-conflicts-rho010-r3-010-rchzl.18d4669b461fe644,"reason=Pulled count=1 msg=Container image ""busybox:musl"" already present on machine"
0.2144,Event,ADDED,eval-conflicts-rho010-r3-010-rchzl.18d4669b475253c0,reason=Created count=1 msg=Created container: task
0.2145,Event,ADDED,eval-conflicts-rho010-r3-010-rchzl.18d4669b4ad99f64,reason=Started count=1 msg=Started container task
0.2147,Event,ADDED,eval-conflicts-rho010-r3-010.18d4669b2ab54c83,reason=SuccessfulCreate count=1 msg=Created pod: eval-conflicts-rho010-r3-010-rchzl
0.2149,Event,ADDED,eval-conflicts-rho010-r3-010.18d4669e7365be57,reason=Completed count=1 msg=Job completed
0.215,Event,ADDED,eval-conflicts-rho010-r3-011-s9jnk.18d4669b65a90048,"reason=FailedScheduling count=None msg=0/6 nodes are available: 1 c_wall violated: 1 conflicting context pair(s) with node memory, 5 node(s) had untolerated taint(s). no new claims to deallocate, preemption: 0/6 nodes are available: 1 No preemption victims found for incoming pod, 5 Preemption is not helpful for scheduling."
0.216,Event,ADDED,eval-conflicts-rho010-r3-011-s9jnk.18d4669b6643fc1e,"reason=FailedScheduling count=None msg=0/6 nodes are available: 1 c_wall violated: 1 conflicting context pair(s) with node memory, 5 node(s) had untolerated taint(s). no new claims to deallocate, preemption: 0/6 nodes are available: 1 No preemption victims found for incoming pod, 5 Preemption is not helpful for scheduling."
0.2162,Event,ADDED,eval-conflicts-rho010-r3-011-s9jnk.18d4669cd5c1bbe8,reason=Scheduled count=None msg=Successfully assigned compute/eval-conflicts-rho010-r3-011-s9jnk to kind-worker2
0.2164,Event,ADDED,eval-conflicts-rho010-r3-011-s9jnk.18d4669cf023e16f,"reason=Pulled count=1 msg=Container image ""busybox:musl"" already present on machine"
0.2165,Event,ADDED,eval-conflicts-rho010-r3-011-s9jnk.18d4669cf1f05521,reason=Created count=1 msg=Created container: task
0.2167,Event,ADDED,eval-conflicts-rho010-r3-011-s9jnk.18d4669cf598a120,reason=Started count=1 msg=Started container task
0.2169,Event,ADDED,eval-conflicts-rho010-r3-011.18d4669b6560f099,reason=SuccessfulCreate count=1 msg=Created pod: eval-conflicts-rho010-r3-011-s9jnk
0.2171,Event,ADDED,eval-conflicts-rho010-r3-011.18d466a024caf17a,reason=Completed count=1 msg=Job completed
0.2172,Event,ADDED,eval-conflicts-rho010-r3-012-ngxcr.18d4669ba1d994d6,reason=Scheduled count=None msg=Successfully assigned compute/eval-conflicts-rho010-r3-012-ngxcr to kind-worker3
0.2175,Event,ADDED,eval-conflicts-rho010-r3-012-ngxcr.18d4669bbc89b57b,"reason=Pulled count=1 msg=Container image ""busybox:musl"" already present on machine"
0.2177,Event,ADDED,eval-conflicts-rho010-r3-012-ngxcr.18d4669bbdcaa35d,reason=Created count=1 msg=Created container: task
0.2179,Event,ADDED,eval-conflicts-rho010-r3-012-ngxcr.18d4669bbfe66d2b,reason=Started count=1 msg=Started container task
0.2182,Event,ADDED,eval-conflicts-rho010-r3-012.18d4669ba147aaa7,reason=SuccessfulCreate count=1 msg=Created pod: eval-conflicts-rho010-r3-012-ngxcr
0.2184,Event,ADDED,eval-conflicts-rho010-r3-012.18d4669eeba18c23,reason=Completed count=1 msg=Job completed
0.2185,Event,ADDED,eval-conflicts-rho010-r3-013-qzs78.18d4669bdd541612,"reason=FailedScheduling count=None msg=0/6 nodes are available: 1 c_wall violated: 1 conflicting context pair(s) with node memory, 5 node(s) had untolerated taint(s). no new claims to deallocate, preemption: 0/6 nodes are available: 1 No preemption victims found for incoming pod, 5 Preemption is not helpful for scheduling."
0.2188,Event,ADDED,eval-conflicts-rho010-r3-013-qzs78.18d4669bddda5089,"reason=FailedScheduling count=None msg=0/6 nodes are available: 1 c_wall violated: 1 conflicting context pair(s) with node memory, 5 node(s) had untolerated taint(s). no new claims to deallocate, preemption: 0/6 nodes are available: 1 No preemption victims found for incoming pod, 5 Preemption is not helpful for scheduling."
0.2189,Event,ADDED,eval-conflicts-rho010-r3-013-qzs78.18d4669cd59078af,reason=Scheduled count=None msg=Successfully assigned compute/eval-conflicts-rho010-r3-013-qzs78 to kind-worker2
0.2191,Event,ADDED,eval-conflicts-rho010-r3-013-qzs78.18d4669cefbef8fd,"reason=Pulled count=1 msg=Container image ""busybox:musl"" already present on machine"
0.2193,Event,ADDED,eval-conflicts-rho010-r3-013-qzs78.18d4669cf15e6597,reason=Created count=1 msg=Created container: task
0.2195,Event,ADDED,eval-conflicts-rho010-r3-013-qzs78.18d4669cf53726f1,reason=Started count=1 msg=Started container task
0.2197,Event,ADDED,eval-conflicts-rho010-r3-013.18d4669bdd0bdca0,reason=SuccessfulCreate count=1 msg=Created pod: eval-conflicts-rho010-r3-013-qzs78
0.2199,Event,ADDED,eval-conflicts-rho010-r3-013.18d466a0246d9cf6,reason=Completed count=1 msg=Job completed
0.22,Event,ADDED,eval-conflicts-rho010-r3-014-m7k2d.18d4669c18ddfd1e,reason=Scheduled count=None msg=Successfully assigned compute/eval-conflicts-rho010-r3-014-m7k2d to kind-worker3
0.2203,Event,ADDED,eval-conflicts-rho010-r3-014-m7k2d.18d4669c31c23f13,"reason=Pulled count=1 msg=Container image ""busybox:musl"" already present on machine"
0.2205,Event,ADDED,eval-conflicts-rho010-r3-014-m7k2d.18d4669c32d288cf,reason=Created count=1 msg=Created container: task
0.2207,Event,ADDED,eval-conflicts-rho010-r3-014-m7k2d.18d4669c34cc25e2,reason=Started count=1 msg=Started container task
0.2209,Event,ADDED,eval-conflicts-rho010-r3-014.18d4669c182f7770,reason=SuccessfulCreate count=1 msg=Created pod: eval-conflicts-rho010-r3-014-m7k2d
0.2211,Event,ADDED,eval-conflicts-rho010-r3-014.18d4669f63adf0b0,reason=Completed count=1 msg=Job completed
0.2213,Event,ADDED,eval-conflicts-rho010-r3-015-9r4mv.18d4669c54d7be43,reason=Scheduled count=None msg=Successfully assigned compute/eval-conflicts-rho010-r3-015-9r4mv to kind-worker3
0.2215,Event,ADDED,eval-conflicts-rho010-r3-015-9r4mv.18d4669c6eb39961,"reason=Pulled count=1 msg=Container image ""busybox:musl"" already present on machine"
0.2218,Event,ADDED,eval-conflicts-rho010-r3-015-9r4mv.18d4669c6fc5230a,reason=Created count=1 msg=Created container: task
0.2219,Event,ADDED,eval-conflicts-rho010-r3-015-9r4mv.18d4669c71f5f7ee,reason=Started count=1 msg=Started container task
0.2221,Event,ADDED,eval-conflicts-rho010-r3-015.18d4669c5437e624,reason=SuccessfulCreate count=1 msg=Created pod: eval-conflicts-rho010-r3-015-9r4mv
0.2223,Event,ADDED,eval-conflicts-rho010-r3-015.18d4669f9fd8b767,reason=Completed count=1 msg=Job completed
0.2225,Event,ADDED,eval-conflicts-rho010-r3-016-jd2cf.18d4669c90e4d131,reason=Scheduled count=None msg=Successfully assigned compute/eval-conflicts-rho010-r3-016-jd2cf to kind-worker3
0.2227,Event,ADDED,eval-conflicts-rho010-r3-016-jd2cf.18d4669caa12d84a,"reason=Pulled count=1 msg=Container image ""busybox:musl"" already present on machine"
0.2229,Event,ADDED,eval-conflicts-rho010-r3-016-jd2cf.18d4669cab25bc1b,reason=Created count=1 msg=Created container: task
0.2232,Event,ADDED,eval-conflicts-rho010-r3-016-jd2cf.18d4669caf5936be,reason=Started count=1 msg=Started container task
0.2233,Event,ADDED,eval-conflicts-rho010-r3-016.18d4669c9050c787,reason=SuccessfulCreate count=1 msg=Created pod: eval-conflicts-rho010-r3-016-jd2cf
0.2235,Event,ADDED,eval-conflicts-rho010-r3-016.18d4669fdcbef3a1,reason=Completed count=1 msg=Job completed
0.2237,Event,ADDED,eval-conflicts-rho010-r3-017-cv6n2.18d4669ccaf7356b,"reason=FailedScheduling count=None msg=0/6 nodes are available: 6 node(s) had untolerated taint(s). no new claims to deallocate, preemption: 0/6 nodes are available: 6 Preemption is not helpful for scheduling."
0.2239,Event,ADDED,eval-conflicts-rho010-r3-017-cv6n2.18d4669cd60706ea,reason=Scheduled count=None msg=Successfully assigned compute/eval-conflicts-rho010-r3-017-cv6n2 to kind-worker2
0.224,Event,ADDED,eval-conflicts-rho010-r3-017-cv6n2.18d4669cf0601def,"reason=Pulled count=1 msg=Container image ""busybox:musl"" already present on machine"
0.2242,Event,ADDED,eval-conflicts-rho010-r3-017-cv6n2.18d4669cf258edef,reason=Created count=1 msg=Created container: task
0.2245,Event,ADDED,eval-conflicts-rho010-r3-017-cv6n2.18d4669cf598cd13,reason=Started count=1 msg=Started container task
0.2247,Event,ADDED,eval-conflicts-rho010-r3-017.18d4669ccaede1c0,reason=SuccessfulCreate count=1 msg=Created pod: eval-conflicts-rho010-r3-017-cv6n2
0.2248,Event,ADDED,eval-conflicts-rho010-r3-017.18d466a0265aef4e,reason=Completed count=1 msg=Job completed
0.225,Event,ADDED,eval-conflicts-rho010-r3-018-cwtxb.18d4669d07d2daff,"reason=FailedScheduling count=None msg=0/6 nodes are available: 1 c_wall violated: 1 conflicting context pair(s) with node memory, 5 node(s) had untolerated taint(s). no new claims to deallocate, preemption: 0/6 nodes are available: 1 No preemption victims found for incoming pod, 5 Preemption is not helpful for scheduling."
0.2252,Event,ADDED,eval-conflicts-rho010-r3-018-cwtxb.18d4669d08597ab1,"reason=FailedScheduling count=None msg=0/6 nodes are available: 1 c_wall violated: 1 conflicting context pair(s) with node memory, 5 node(s) had untolerated taint(s). no new claims to deallocate, preemption: 0/6 nodes are available: 1 No preemption victims found for incoming pod, 5 Preemption is not helpful for scheduling."
0.2254,Event,ADDED,eval-conflicts-rho010-r3-018-cwtxb.18d4669ed55a6d4f,reason=Scheduled count=None msg=Successfully assigned compute/eval-conflicts-rho010-r3-018-cwtxb to kind-worker
0.2255,Event,ADDED,eval-conflicts-rho010-r3-018-cwtxb.18d4669eece1d8ce,"reason=Pulled count=1 msg=Container image ""busybox:musl"" already present on machine"
0.2257,Event,ADDED,eval-conflicts-rho010-r3-018-cwtxb.18d4669eef090ad7,reason=Created count=1 msg=Created container: task
0.2259,Event,ADDED,eval-conflicts-rho010-r3-018-cwtxb.18d4669ef39fbaf5,reason=Started count=1 msg=Started container task
0.2261,Event,ADDED,eval-conflicts-rho010-r3-018.18d4669d078def12,reason=SuccessfulCreate count=1 msg=Created pod: eval-conflicts-rho010-r3-018-cwtxb
0.2262,Event,ADDED,eval-conflicts-rho010-r3-018.18d466a233374a5c,reason=Completed count=1 msg=Job completed
0.2264,Event,ADDED,eval-conflicts-rho010-r3-019-mftww.18d4669d43558550,reason=Scheduled count=None msg=Successfully assigned compute/eval-conflicts-rho010-r3-019-mftww to kind-worker2
0.2265,Event,ADDED,eval-conflicts-rho010-r3-019-mftww.18d4669d5c991f26,"reason=Pulled count=1 msg=Container image ""busybox:musl"" already present on machine"
0.2267,Event,ADDED,eval-conflicts-rho010-r3-019-mftww.18d4669d5daae190,reason=Created count=1 msg=Created container: task
0.2271,Event,ADDED,eval-conflicts-rho010-r3-019-mftww.18d4669d6440237f,reason=Started count=1 msg=Started container task
0.2273,Event,ADDED,eval-conflicts-rho010-r3-019.18d4669d42d39955,reason=SuccessfulCreate count=1 msg=Created pod: eval-conflicts-rho010-r3-019-mftww
0.2275,Event,ADDED,eval-conflicts-rho010-r3-019.18d466a09bf2d74e,reason=Completed count=1 msg=Job completed
0.2277,Event,ADDED,eval-conflicts-rho010-r3-020-b94m7.18d4669d7f201b01,reason=Scheduled count=None msg=Successfully assigned compute/eval-conflicts-rho010-r3-020-b94m7 to kind-worker2
0.228,Event,ADDED,eval-conflicts-rho010-r3-020-b94m7.18d4669d975d7891,"reason=Pulled count=1 msg=Container image ""busybox:musl"" already present on machine"
0.2281,Event,ADDED,eval-conflicts-rho010-r3-020-b94m7.18d4669d987eae13,reason=Created count=1 msg=Created container: task
0.2283,Event,ADDED,eval-conflicts-rho010-r3-020-b94m7.18d4669d9ab3bb6b,reason=Started count=1 msg=Started container task
0.2285,Event,ADDED,eval-conflicts-rho010-r3-020.18d4669d7e7eb535,reason=SuccessfulCreate count=1 msg=Created pod: eval-conflicts-rho010-r3-020-b94m7
0.2288,Event,ADDED,eval-conflicts-rho010-r3-020.18d466a0d7d81c61,reason=Completed count=1 msg=Job completed
0.2289,Event,ADDED,eval-conflicts-rho010-r3-021-p86bx.18d4669db9ab7b6c,"reason=FailedScheduling count=None msg=0/6 nodes are available: 1 c_wall violated: 1 conflicting context pair(s) with node memory, 5 node(s) had untolerated taint(s). no new claims to deallocate, preemption: 0/6 nodes are available: 1 No preemption victims found for incoming pod, 5 Preemption is not helpful for scheduling."
0.2293,Event,ADDED,eval-conflicts-rho010-r3-021-p86bx.18d4669dba36f2ad,"reason=FailedScheduling count=None msg=0/6 nodes are available: 1 c_wall violated: 1 conflicting context pair(s) with node memory, 5 node(s) had untolerated taint(s). no new claims to deallocate, preemption: 0/6 nodes are available: 1 No preemption victims found for incoming pod, 5 Preemption is not helpful for scheduling."
0.2297,Event,ADDED,eval-conflicts-rho010-r3-021-p86bx.18d4669edbae0c10,"reason=FailedScheduling count=None msg=0/6 nodes are available: 2 c_wall violated: 1 conflicting context pair(s) with node memory, 4 node(s) had untolerated taint(s). no new claims to deallocate, preemption: 0/6 nodes are available: 2 No preemption victims found for incoming pod, 4 Preemption is not helpful for scheduling."
0.2299,Event,ADDED,eval-conflicts-rho010-r3-021-p86bx.18d4669f32743af2,"reason=FailedScheduling count=None msg=0/6 nodes are available: 1 c_wall violated: 1 conflicting context pair(s) with node memory, 5 node(s) had untolerated taint(s). no new claims to deallocate, preemption: 0/6 nodes are available: 1 No preemption victims found for incoming pod, 5 Preemption is not helpful for scheduling."
0.2301,Event,ADDED,eval-conflicts-rho010-r3-021-p86bx.18d4669f4829c80e,reason=Scheduled count=None msg=Successfully assigned compute/eval-conflicts-rho010-r3-021-p86bx to kind-worker4
0.2304,Event,ADDED,eval-conflicts-rho010-r3-021-p86bx.18d4669f62d5df18,"reason=Pulled count=1 msg=Container image ""busybox:musl"" already present on machine"
0.2306,Event,ADDED,eval-conflicts-rho010-r3-021-p86bx.18d4669f6537487b,reason=Created count=1 msg=Created container: task
0.2308,Event,ADDED,eval-conflicts-rho010-r3-021-p86bx.18d4669f6942d030,reason=Started count=1 msg=Started container task
0.2311,Event,ADDED,eval-conflicts-rho010-r3-021.18d4669db967b1fb,reason=SuccessfulCreate count=1 msg=Created pod: eval-conflicts-rho010-r3-021-p86bx
0.2313,Event,ADDED,eval-conflicts-rho010-r3-021.18d466a2863ed683,reason=Completed count=1 msg=Job completed
0.2315,Event,ADDED,eval-conflicts-rho010-r3-022-g4swg.18d4669df5cd4571,reason=Scheduled count=None msg=Successfully assigned compute/eval-conflicts-rho010-r3-022-g4swg to kind-worker2
0.2316,Event,ADDED,eval-conflicts-rho010-r3-022-g4swg.18d4669e0fd9b433,"reason=Pulled count=1 msg=Container image ""busybox:musl"" already present on machine"
0.2319,Event,ADDED,eval-conflicts-rho010-r3-022-g4swg.18d4669e10eb68cf,reason=Created count=1 msg=Created container: task
0.232,Event,ADDED,eval-conflicts-rho010-r3-022-g4swg.18d4669e149b1796,reason=Started count=1 msg=Started container task
0.2322,Event,ADDED,eval-conflicts-rho010-r3-022.18d4669df5432789,reason=SuccessfulCreate count=1 msg=Created pod: eval-conflicts-rho010-r3-022-g4swg
0.2324,Event,ADDED,eval-conflicts-rho010-r3-022.18d466a14fca06b1,reason=Completed count=1 msg=Job completed
0.2325,Event,ADDED,eval-conflicts-rho010-r3-023-gxwbw.18d4669e31f0f3d5,"reason=FailedScheduling count=None msg=0/6 nodes are available: 1 c_wall violated: 1 conflicting context pair(s) with node memory, 5 node(s) had untolerated taint(s). no new claims to deallocate, preemption: 0/6 nodes are available: 1 No preemption victims found for incoming pod, 5 Preemption is not helpful for scheduling."
0.2327,Event,ADDED,eval-conflicts-rho010-r3-023-gxwbw.18d4669e3272d941,"reason=FailedScheduling count=None msg=0/6 nodes are available: 1 c_wall violated: 1 conflicting context pair(s) with node memory, 5 node(s) had untolerated taint(s). no new claims to deallocate, preemption: 0/6 nodes are available: 1 No preemption victims found for incoming pod, 5 Preemption is not helpful for scheduling."
0.2329,Event,ADDED,eval-conflicts-rho010-r3-023-gxwbw.18d4669edb9f93f4,reason=Scheduled count=None msg=Successfully assigned compute/eval-conflicts-rho010-r3-023-gxwbw to kind-worker
0.2331,Event,ADDED,eval-conflicts-rho010-r3-023-gxwbw.18d4669ef5cfcceb,"reason=Pulled count=1 msg=Container image ""busybox:musl"" already present on machine"
0.2332,Event,ADDED,eval-conflicts-rho010-r3-023-gxwbw.18d4669ef6fa2637,reason=Created count=1 msg=Created container: task
0.2334,Event,ADDED,eval-conflicts-rho010-r3-023-gxwbw.18d4669efa25011b,reason=Started count=1 msg=Started container task
0.2336,Event,ADDED,eval-conflicts-rho010-r3-023.18d4669e31ac5e7a,reason=SuccessfulCreate count=1 msg=Created pod: eval-conflicts-rho010-r3-023-gxwbw
0.2337,Event,ADDED,eval-conflicts-rho010-r3-023.18d466a23363fd29,reason=Completed count=1 msg=Job completed
0.2339,Event,ADDED,eval-conflicts-rho010-r3-024-c4bpr.18d4669e6cbadfae,reason=Scheduled count=None msg=Successfully assigned compute/eval-conflicts-rho010-r3-024-c4bpr to kind-worker2
0.2341,Event,ADDED,eval-conflicts-rho010-r3-024-c4bpr.18d4669e86553cbd,"reason=Pulled count=1 msg=Container image ""busybox:musl"" already present on machine"
0.2342,Event,ADDED,eval-conflicts-rho010-r3-024-c4bpr.18d4669e876d5a18,reason=Created count=1 msg=Created container: task
0.2344,Event,ADDED,eval-conflicts-rho010-r3-024-c4bpr.18d4669e8985cf8a,reason=Started count=1 msg=Started container task
0.2346,Event,ADDED,eval-conflicts-rho010-r3-024.18d4669e6c2e0c0f,reason=SuccessfulCreate count=1 msg=Created pod: eval-conflicts-rho010-r3-024-c4bpr
0.2347,Event,ADDED,eval-conflicts-rho010-r3-024.18d466a1c8403084,reason=Completed count=1 msg=Job completed
0.2349,Event,ADDED,eval-conflicts-rho010-r3-025-vsnb7.18d4669ea880426a,"reason=FailedScheduling count=None msg=0/6 nodes are available: 1 c_wall violated: 1 conflicting context pair(s) with node memory, 5 node(s) had untolerated taint(s). no new claims to deallocate, preemption: 0/6 nodes are available: 1 No preemption victims found for incoming pod, 5 Preemption is not helpful for scheduling."
0.2351,Event,ADDED,eval-conflicts-rho010-r3-025-vsnb7.18d4669ea90898b1,"reason=FailedScheduling count=None msg=0/6 nodes are available: 1 c_wall violated: 1 conflicting context pair(s) with node memory, 5 node(s) had untolerated taint(s). no new claims to deallocate, preemption: 0/6 nodes are available: 1 No preemption victims found for incoming pod, 5 Preemption is not helpful for scheduling."
0.2352,Event,ADDED,eval-conflicts-rho010-r3-025-vsnb7.18d4669ed1b40b49,reason=Scheduled count=None msg=Successfully assigned compute/eval-conflicts-rho010-r3-025-vsnb7 to kind-worker
0.2354,Event,ADDED,eval-conflicts-rho010-r3-025-vsnb7.18d4669eecb31ed3,"reason=Pulled count=1 msg=Container image ""busybox:musl"" already present on machine"
0.2356,Event,ADDED,eval-conflicts-rho010-r3-025-vsnb7.18d4669eeebeb1a6,reason=Created count=1 msg=Created container: task
0.2358,Event,ADDED,eval-conflicts-rho010-r3-025-vsnb7.18d4669ef35a70b9,reason=Started count=1 msg=Started container task
0.2359,Event,ADDED,eval-conflicts-rho010-r3-025.18d4669ea83f3c21,reason=SuccessfulCreate count=1 msg=Created pod: eval-conflicts-rho010-r3-025-vsnb7
0.2361,Event,ADDED,eval-conflicts-rho010-r3-025.18d466a23365f2eb,reason=Completed count=1 msg=Job completed
0.2362,Event,ADDED,eval-conflicts-rho010-r3-026-cpnh9.18d4669ee45c8a71,reason=Scheduled count=None msg=Successfully assigned compute/eval-conflicts-rho010-r3-026-cpnh9 to kind-worker
0.2364,Event,ADDED,eval-conflicts-rho010-r3-026-cpnh9.18d4669eff3c43ea,"reason=Pulled count=1 msg=Container image ""busybox:musl"" already present on machine"
0.2366,Event,ADDED,eval-conflicts-rho010-r3-026-cpnh9.18d4669f005916d7,reason=Created count=1 msg=Created container: task
0.2368,Event,ADDED,eval-conflicts-rho010-r3-026-cpnh9.18d4669f035e298f,reason=Started count=1 msg=Started container task
0.2369,Event,ADDED,eval-conflicts-rho010-r3-026.18d4669ee35a1614,reason=SuccessfulCreate count=1 msg=Created pod: eval-conflicts-rho010-r3-026-cpnh9
0.2371,Event,ADDED,eval-conflicts-rho010-r3-026.18d466a23365766b,reason=Completed count=1 msg=Job completed
0.2373,Event,ADDED,eval-conflicts-rho010-r3-027-h9v2k.18d4669f20bdfdca,"reason=FailedScheduling count=None msg=0/6 nodes are available: 2 c_wall violated: 1 conflicting context pair(s) with node memory, 4 node(s) had untolerated taint(s). no new claims to deallocate, preemption: 0/6 nodes are available: 2 No preemption victims found for incoming pod, 4 Preemption is not helpful for scheduling."
0.2374,Event,ADDED,eval-conflicts-rho010-r3-027-h9v2k.18d4669f220c844d,"reason=FailedScheduling count=None msg=0/6 nodes are available: 2 c_wall violated: 1 conflicting context pair(s) with node memory, 4 node(s) had untolerated taint(s). no new claims to deallocate, preemption: 0/6 nodes are available: 2 No preemption victims found for incoming pod, 4 Preemption is not helpful for scheduling."
0.2379,Event,ADDED,eval-conflicts-rho010-r3-027-h9v2k.18d4669f329cf9e1,"reason=FailedScheduling count=None msg=0/6 nodes are available: 1 c_wall violated: 1 conflicting context pair(s) with node memory, 5 node(s) had untolerated taint(s). no new claims to deallocate, preemption: 0/6 nodes are available: 1 No preemption victims found for incoming pod, 5 Preemption is not helpful for scheduling."
0.2381,Event,ADDED,eval-conflicts-rho010-r3-027-h9v2k.18d4669f48990b80,reason=Scheduled count=None msg=Successfully assigned compute/eval-conflicts-rho010-r3-027-h9v2k to kind-worker4
0.2383,Event,ADDED,eval-conflicts-rho010-r3-027-h9v2k.18d4669f62f31b90,"reason=Pulled count=1 msg=Container image ""busybox:musl"" already present on machine"
0.2385,Event,ADDED,eval-conflicts-rho010-r3-027-h9v2k.18d4669f655306a9,reason=Created count=1 msg=Created container: task
0.2388,Event,ADDED,eval-conflicts-rho010-r3-027-h9v2k.18d4669f69463539,reason=Started count=1 msg=Started container task
0.239,Event,ADDED,eval-conflicts-rho010-r3-027.18d4669f204dd03e,reason=SuccessfulCreate count=1 msg=Created pod: eval-conflicts-rho010-r3-027-h9v2k
0.2391,Event,ADDED,eval-conflicts-rho010-r3-027.18d466a2866c3e3d,reason=Completed count=1 msg=Job completed
0.2393,Event,ADDED,eval-conflicts-rho010-r3-028-x4gn6.18d4669f5d21f307,reason=Scheduled count=None msg=Successfully assigned compute/eval-conflicts-rho010-r3-028-x4gn6 to kind-worker4
0.2395,Event,ADDED,eval-conflicts-rho010-r3-028-x4gn6.18d4669f76babfd1,"reason=Pulled count=1 msg=Container image ""busybox:musl"" already present on machine"
0.2398,Event,ADDED,eval-conflicts-rho010-r3-028-x4gn6.18d4669f77f96e8f,reason=Created count=1 msg=Created container: task
0.24,Event,ADDED,eval-conflicts-rho010-r3-028-x4gn6.18d4669f7a216f3b,reason=Started count=1 msg=Started container task
0.2402,Event,ADDED,eval-conflicts-rho010-r3-028.18d4669f5b8bf610,reason=SuccessfulCreate count=1 msg=Created pod: eval-conflicts-rho010-r3-028-x4gn6
0.2405,Event,ADDED,eval-conflicts-rho010-r3-028.18d466a2c1f136be,reason=Completed count=1 msg=Job completed
0.2407,Event,ADDED,eval-conflicts-rho010-r3-029-gbc55.18d4669f97452179,reason=Scheduled count=None msg=Successfully assigned compute/eval-conflicts-rho010-r3-029-gbc55 to kind-worker5
0.2408,Event,ADDED,eval-conflicts-rho010-r3-029-gbc55.18d4669fb152222b,"reason=Pulled count=1 msg=Container image ""busybox:musl"" already present on machine"
0.2411,Event,ADDED,eval-conflicts-rho010-r3-029-gbc55.18d4669fb296b8ea,reason=Created count=1 msg=Created container: task
0.2412,Event,ADDED,eval-conflicts-rho010-r3-029-gbc55.18d4669fb7ad126a,reason=Started count=1 msg=Started container task
0.2414,Event,ADDED,eval-conflicts-rho010-r3-029.18d4669f966eb861,reason=SuccessfulCreate count=1 msg=Created pod: eval-conflicts-rho010-r3-029-gbc55
0.2416,Event,ADDED,eval-conflicts-rho010-r3-029.18d466a2eebfa78d,reason=Completed count=1 msg=Job completed
0.2417,Event,ADDED,eval-conflicts-rho010-r3-030-qhxnn.18d4669fd36ee286,reason=Scheduled count=None msg=Successfully assigned compute/eval-conflicts-rho010-r3-030-qhxnn to kind-worker5
0.2419,Event,ADDED,eval-conflicts-rho010-r3-030-qhxnn.18d4669febd13422,"reason=Pulled count=1 msg=Container image ""busybox:musl"" already present on machine"
0.2421,Event,ADDED,eval-conflicts-rho010-r3-030-qhxnn.18d4669fece82582,reason=Created count=1 msg=Created container: task
0.2423,Event,ADDED,eval-conflicts-rho010-r3-030-qhxnn.18d4669ff192a9b9,reason=Started count=1 msg=Started container task
0.2424,Event,ADDED,eval-conflicts-rho010-r3-030.18d4669fd262a8e8,reason=SuccessfulCreate count=1 msg=Created pod: eval-conflicts-rho010-r3-030-qhxnn
0.2426,Event,ADDED,eval-conflicts-rho010-r3-030.18d466a32a5e09dc,reason=Completed count=1 msg=Job completed
0.2427,Event,ADDED,eval-conflicts-rho010-r3-031-47kv6.18d466a00e4b4615,reason=Scheduled count=None msg=Successfully assigned compute/eval-conflicts-rho010-r3-031-47kv6 to kind-worker
0.2429,Event,ADDED,eval-conflicts-rho010-r3-031-47kv6.18d466a02e0ee8d7,"reason=Pulled count=1 msg=Container image ""busybox:musl"" already present on machine"
0.2431,Event,ADDED,eval-conflicts-rho010-r3-031-47kv6.18d466a02f2124e0,reason=Created count=1 msg=Created container: task
0.2432,Event,ADDED,eval-conflicts-rho010-r3-031-47kv6.18d466a032eb0613,reason=Started count=1 msg=Started container task
0.2434,Event,ADDED,eval-conflicts-rho010-r3-031.18d466a00d3b5eb8,reason=SuccessfulCreate count=1 msg=Created pod: eval-conflicts-rho010-r3-031-47kv6
0.2436,Event,ADDED,eval-conflicts-rho010-r3-031.18d466a35da48dfa,reason=Completed count=1 msg=Job completed
0.2437,Event,ADDED,eval-conflicts-rho010-r3-032-86fdk.18d466a04a3cce13,reason=Scheduled count=None msg=Successfully assigned compute/eval-conflicts-rho010-r3-032-86fdk to kind-worker5
0.2439,Event,ADDED,eval-conflicts-rho010-r3-032-86fdk.18d466a0670c0a97,"reason=Pulled count=1 msg=Container image ""busybox:musl"" already present on machine"
0.2441,Event,ADDED,eval-conflicts-rho010-r3-032-86fdk.18d466a06817e298,reason=Created count=1 msg=Created container: task
0.2442,Event,ADDED,eval-conflicts-rho010-r3-032-86fdk.18d466a0715f7e46,reason=Started count=1 msg=Started container task
0.2444,Event,ADDED,eval-conflicts-rho010-r3-032.18d466a0490c1e2f,reason=SuccessfulCreate count=1 msg=Created pod: eval-conflicts-rho010-r3-032-86fdk
0.2445,Event,ADDED,eval-conflicts-rho010-r3-032.18d466a3a1de85c3,reason=Completed count=1 msg=Job completed
0.2447,Event,ADDED,eval-conflicts-rho010-r3-033-cn24m.18d466a085efa35b,reason=Scheduled count=None msg=Successfully assigned compute/eval-conflicts-rho010-r3-033-cn24m to kind-worker
0.2449,Event,ADDED,eval-conflicts-rho010-r3-033-cn24m.18d466a0a10fe9b6,"reason=Pulled count=1 msg=Container image ""busybox:musl"" already present on machine"
0.245,Event,ADDED,eval-conflicts-rho010-r3-033-cn24m.18d466a0a22f32a2,reason=Created count=1 msg=Created container: task
0.2452,Event,ADDED,eval-conflicts-rho010-r3-033-cn24m.18d466a0a594fcaa,reason=Started count=1 msg=Started container task
0.2454,Event,ADDED,eval-conflicts-rho010-r3-033.18d466a084974150,reason=SuccessfulCreate count=1 msg=Created pod: eval-conflicts-rho010-r3-033-cn24m
0.2455,Event,ADDED,eval-conflicts-rho010-r3-033.18d466a3d530042a,reason=Completed count=1 msg=Job completed
0.2457,Event,ADDED,eval-conflicts-rho010-r3-034-z9zfk.18d466a0c26a54ea,reason=Scheduled count=None msg=Successfully assigned compute/eval-conflicts-rho010-r3-034-z9zfk to kind-worker5
0.2458,Event,ADDED,eval-conflicts-rho010-r3-034-z9zfk.18d466a0dfa7a269,"reason=Pulled count=1 msg=Container image ""busybox:musl"" already present on machine"
0.246,Event,ADDED,eval-conflicts-rho010-r3-034-z9zfk.18d466a0e0be7e4f,reason=Created count=1 msg=Created container: task
0.2462,Event,ADDED,eval-conflicts-rho010-r3-034-z9zfk.18d466a0e45241ee,reason=Started count=1 msg=Started container task
0.2463,Event,ADDED,eval-conflicts-rho010-r3-034.18d466a0c10c7e75,reason=SuccessfulCreate count=1 msg=Created pod: eval-conflicts-rho010-r3-034-z9zfk
0.2465,Event,ADDED,eval-conflicts-rho010-r3-034.18d466a41995c85a,reason=Completed count=1 msg=Job completed
0.2467,Event,ADDED,eval-conflicts-rho010-r3-035-4bvpr.18d466a0fd03aad4,reason=Scheduled count=None msg=Successfully assigned compute/eval-conflicts-rho010-r3-035-4bvpr to kind-worker4
0.2468,Event,ADDED,eval-conflicts-rho010-r3-035-4bvpr.18d466a116259da7,"reason=Pulled count=1 msg=Container image ""busybox:musl"" already present on machine"
0.247,Event,ADDED,eval-conflicts-rho010-r3-035-4bvpr.18d466a11762e52f,reason=Created count=1 msg=Created container: task
0.2472,Event,ADDED,eval-conflicts-rho010-r3-035-4bvpr.18d466a1194922a1,reason=Started count=1 msg=Started container task
0.2473,Event,ADDED,eval-conflicts-rho010-r3-035.18d466a0fbcce01c,reason=SuccessfulCreate count=1 msg=Created pod: eval-conflicts-rho010-r3-035-4bvpr
0.2475,Event,ADDED,eval-conflicts-rho010-r3-035.18d466a428bf99f9,reason=Completed count=1 msg=Job completed
0.2477,Event,ADDED,eval-conflicts-rho010-r3-036-jrzlb.18d466a1383db7e2,reason=Scheduled count=None msg=Successfully assigned compute/eval-conflicts-rho010-r3-036-jrzlb to kind-worker5
0.2479,Event,ADDED,eval-conflicts-rho010-r3-036-jrzlb.18d466a157456ed4,"reason=Pulled count=1 msg=Container image ""busybox:musl"" already present on machine"
0.248,Event,ADDED,eval-conflicts-rho010-r3-036-jrzlb.18d466a1587501bc,reason=Created count=1 msg=Created container: task
0.2488,Event,ADDED,eval-conflicts-rho010-r3-036-jrzlb.18d466a15bdb6ded,reason=Started count=1 msg=Started container task
0.2489,Event,ADDED,eval-conflicts-rho010-r3-036.18d466a1377677c3,reason=SuccessfulCreate count=1 msg=Created pod: eval-conflicts-rho010-r3-036-jrzlb
0.2491,Event,ADDED,eval-conflicts-rho010-r3-036.18d466a491dcd78d,reason=Completed count=1 msg=Job completed
0.2493,Event,ADDED,eval-conflicts-rho010-r3-037-q4lgv.18d466a173d9054e,reason=Scheduled count=None msg=Successfully assigned compute/eval-conflicts-rho010-r3-037-q4lgv to kind-worker5
0.2496,Event,ADDED,eval-conflicts-rho010-r3-037-q4lgv.18d466a19222720f,"reason=Pulled count=1 msg=Container image ""busybox:musl"" already present on machine"
0.2498,Event,ADDED,eval-conflicts-rho010-r3-037-q4lgv.18d466a19343f687,reason=Created count=1 msg=Created container: task
0.2499,Event,ADDED,eval-conflicts-rho010-r3-037-q4lgv.18d466a1971e6d98,reason=Started count=1 msg=Started container task
0.2501,Event,ADDED,eval-conflicts-rho010-r3-037.18d466a173304600,reason=SuccessfulCreate count=1 msg=Created pod: eval-conflicts-rho010-r3-037-q4lgv
0.2503,Event,ADDED,eval-conflicts-rho010-r3-037.18d466a4cddad53e,reason=Completed count=1 msg=Job completed
0.2505,Event,ADDED,eval-conflicts-rho010-r3-038-44xcl.18d466a1b005501a,reason=Scheduled count=None msg=Successfully assigned compute/eval-conflicts-rho010-r3-038-44xcl to kind-worker2
0.2507,Event,ADDED,eval-conflicts-rho010-r3-038-44xcl.18d466a1c912e19e,"reason=Pulled count=1 msg=Container image ""busybox:musl"" already present on machine"
0.2508,Event,ADDED,eval-conflicts-rho010-r3-038-44xcl.18d466a1ca404e33,reason=Created count=1 msg=Created container: task
0.251,Event,ADDED,eval-conflicts-rho010-r3-038-44xcl.18d466a1cecd44b1,reason=Started count=1 msg=Started container task
0.2512,Event,ADDED,eval-conflicts-rho010-r3-038.18d466a1af5159f0,reason=SuccessfulCreate count=1 msg=Created pod: eval-conflicts-rho010-r3-038-44xcl
0.2513,Event,ADDED,eval-conflicts-rho010-r3-038.18d466a50da1e66e,reason=Completed count=1 msg=Job completed
0.2515,Event,ADDED,eval-conflicts-rho010-r3-039-tn8b2.18d466a1eaa93fff,reason=Scheduled count=None msg=Successfully assigned compute/eval-conflicts-rho010-r3-039-tn8b2 to kind-worker2
0.2517,Event,ADDED,eval-conflicts-rho010-r3-039-tn8b2.18d466a2041b40e3,"reason=Pulled count=1 msg=Container image ""busybox:musl"" already present on machine"
0.2518,Event,ADDED,eval-conflicts-rho010-r3-039-tn8b2.18d466a2055bdab5,reason=Created count=1 msg=Created container: task
0.2521,Event,ADDED,eval-conflicts-rho010-r3-039-tn8b2.18d466a20753e8b3,reason=Started count=1 msg=Started container task
0.2524,Event,ADDED,eval-conflicts-rho010-r3-039.18d466a1e9f4d5a2,reason=SuccessfulCreate count=1 msg=Created pod: eval-conflicts-rho010-r3-039-tn8b2
0.2526,Event,ADDED,eval-conflicts-rho010-r3-039.18d466a548c7b194,reason=Completed count=1 msg=Job completed
0.2527,Event,ADDED,eval-conflicts-rho010-r3-040-clgcg.18d466a226ec925c,reason=Scheduled count=None msg=Successfully assigned compute/eval-conflicts-rho010-r3-040-clgcg to kind-worker2
0.253,Event,ADDED,eval-conflicts-rho010-r3-040-clgcg.18d466a2413d8f8b,"reason=Pulled count=1 msg=Container image ""busybox:musl"" already present on machine"
0.2532,Event,ADDED,eval-conflicts-rho010-r3-040-clgcg.18d466a24256d1d3,reason=Created count=1 msg=Created container: task
0.2533,Event,ADDED,eval-conflicts-rho010-r3-040-clgcg.18d466a2446ffd62,reason=Started count=1 msg=Started container task
0.2535,Event,ADDED,eval-conflicts-rho010-r3-040.18d466a2261c2431,reason=SuccessfulCreate count=1 msg=Created pod: eval-conflicts-rho010-r3-040-clgcg
0.2537,Event,ADDED,eval-conflicts-rho010-r3-040.18d466a585390db4,reason=Completed count=1 msg=Job completed
0.2538,Event,ADDED,eval-conflicts-rho010-r3-041-4fv76.18d466a261d256d3,reason=Scheduled count=None msg=Successfully assigned compute/eval-conflicts-rho010-r3-041-4fv76 to kind-worker3
0.254,Event,ADDED,eval-conflicts-rho010-r3-041-4fv76.18d466a27ccbde31,"reason=Pulled count=1 msg=Container image ""busybox:musl"" already present on machine"
0.2542,Event,ADDED,eval-conflicts-rho010-r3-041-4fv76.18d466a27ddface4,reason=Created count=1 msg=Created container: task
0.2543,Event,ADDED,eval-conflicts-rho010-r3-041-4fv76.18d466a280eddfc0,reason=Started count=1 msg=Started container task
0.2545,Event,ADDED,eval-conflicts-rho010-r3-041.18d466a261411e28,reason=SuccessfulCreate count=1 msg=Created pod: eval-conflicts-rho010-r3-041-4fv76
0.2548,Event,ADDED,eval-conflicts-rho010-r3-041.18d466a5b048bd48,reason=Completed count=1 msg=Job completed
0.2551,Event,ADDED,eval-conflicts-rho010-r3-042-jcg89.18d466a29dbaf166,reason=Scheduled count=None msg=Successfully assigned compute/eval-conflicts-rho010-r3-042-jcg89 to kind-worker2
0.2552,Event,ADDED,eval-conflicts-rho010-r3-042-jcg89.18d466a2b8638011,"reason=Pulled count=1 msg=Container image ""busybox:musl"" already present on machine"
0.2554,Event,ADDED,eval-conflicts-rho010-r3-042-jcg89.18d466a2b97ef0eb,reason=Created count=1 msg=Created container: task
0.2556,Event,ADDED,eval-conflicts-rho010-r3-042-jcg89.18d466a2bdff058e,reason=Started count=1 msg=Started container task
0.256,Event,ADDED,eval-conflicts-rho010-r3-042.18d466a29d15cd28,reason=SuccessfulCreate count=1 msg=Created pod: eval-conflicts-rho010-r3-042-jcg89
0.2562,Event,ADDED,eval-conflicts-rho010-r3-042.18d466a5fcc039a8,reason=Completed count=1 msg=Job completed
0.2563,Event,ADDED,eval-conflicts-rho010-r3-043-mjzv9.18d466a2d95b0b94,reason=Scheduled count=None msg=Successfully assigned compute/eval-conflicts-rho010-r3-043-mjzv9 to kind-worker2
0.2575,Event,ADDED,eval-conflicts-rho010-r3-043-mjzv9.18d466a2f412e1e4,"reason=Pulled count=1 msg=Container image ""busybox:musl"" already present on machine"
0.2577,Event,ADDED,eval-conflicts-rho010-r3-043-mjzv9.18d466a2f545beae,reason=Created count=1 msg=Created container: task
0.2578,Event,ADDED,eval-conflicts-rho010-r3-043-mjzv9.18d466a2f9f41c11,reason=Started count=1 msg=Started container task
0.258,Event,ADDED,eval-conflicts-rho010-r3-043.18d466a2d88fa752,reason=SuccessfulCreate count=1 msg=Created pod: eval-conflicts-rho010-r3-043-mjzv9
0.2582,Event,ADDED,eval-conflicts-rho010-r3-043.18d466a638332152,reason=Completed count=1 msg=Job completed
0.2584,Event,ADDED,eval-conflicts-rho010-r3-044-qvjxn.18d466a3154ae228,reason=Scheduled count=None msg=Successfully assigned compute/eval-conflicts-rho010-r3-044-qvjxn to kind-worker2
0.2585,Event,ADDED,eval-conflicts-rho010-r3-044-qvjxn.18d466a32e943125,"reason=Pulled count=1 msg=Container image ""busybox:musl"" already present on machine"
0.2587,Event,ADDED,eval-conflicts-rho010-r3-044-qvjxn.18d466a32f9785fd,reason=Created count=1 msg=Created container: task
0.2589,Event,ADDED,eval-conflicts-rho010-r3-044-qvjxn.18d466a3321e4cd6,reason=Started count=1 msg=Started container task
0.2591,Event,ADDED,eval-conflicts-rho010-r3-044.18d466a314415296,reason=SuccessfulCreate count=1 msg=Created pod: eval-conflicts-rho010-r3-044-qvjxn
0.2592,Event,ADDED,eval-conflicts-rho010-r3-044.18d466a674151802,reason=Completed count=1 msg=Job completed
0.2594,Event,ADDED,eval-conflicts-rho010-r3-045-l2fxj.18d466a350a21b3a,reason=Scheduled count=None msg=Successfully assigned compute/eval-conflicts-rho010-r3-045-l2fxj to kind-worker3
0.2595,Event,ADDED,eval-conflicts-rho010-r3-045-l2fxj.18d466a36bc0a899,"reason=Pulled count=1 msg=Container image ""busybox:musl"" already present on machine"
0.2597,Event,ADDED,eval-conflicts-rho010-r3-045-l2fxj.18d466a36cc708e4,reason=Created count=1 msg=Created container: task
0.2599,Event,ADDED,eval-conflicts-rho010-r3-045-l2fxj.18d466a370051e3e,reason=Started count=1 msg=Started container task
0.2602,Event,ADDED,eval-conflicts-rho010-r3-045.18d466a34fd46427,reason=SuccessfulCreate count=1 msg=Created pod: eval-conflicts-rho010-r3-045-l2fxj
0.2604,Event,ADDED,eval-conflicts-rho010-r3-045.18d466a69ee85bdc,reason=Completed count=1 msg=Job completed
0.2605,Event,ADDED,eval-conflicts-rho010-r3-046-h7d8x.18d466a38beb670f,reason=Scheduled count=None msg=Successfully assigned compute/eval-conflicts-rho010-r3-046-h7d8x to kind-worker
0.2609,Event,ADDED,eval-conflicts-rho010-r3-046-h7d8x.18d466a3aa46e134,"reason=Pulled count=1 msg=Container image ""busybox:musl"" already present on machine"
0.2611,Event,ADDED,eval-conflicts-rho010-r3-046-h7d8x.18d466a3ab4e2279,reason=Created count=1 msg=Created container: task
0.2613,Event,ADDED,eval-conflicts-rho010-r3-046-h7d8x.18d466a3af17faec,reason=Started count=1 msg=Started container task
0.2614,Event,ADDED,eval-conflicts-rho010-r3-046.18d466a38b4e02f5,reason=SuccessfulCreate count=1 msg=Created pod: eval-conflicts-rho010-r3-046-h7d8x
0.2618,Event,ADDED,eval-conflicts-rho010-r3-046.18d466a6dddf2b62,reason=Completed count=1 msg=Job completed
0.2619,Event,ADDED,eval-conflicts-rho010-r3-047-wm7ns.18d466a3c83bcaed,reason=Scheduled count=None msg=Successfully assigned compute/eval-conflicts-rho010-r3-047-wm7ns to kind-worker
0.2621,Event,ADDED,eval-conflicts-rho010-r3-047-wm7ns.18d466a3e2d7c7c4,"reason=Pulled count=1 msg=Container image ""busybox:musl"" already present on machine"
0.2623,Event,ADDED,eval-conflicts-rho010-r3-047-wm7ns.18d466a3e42a12ae,reason=Created count=1 msg=Created container: task
0.2625,Event,ADDED,eval-conflicts-rho010-r3-047-wm7ns.18d466a3e83d89cd,reason=Started count=1 msg=Started container task
0.2626,Event,ADDED,eval-conflicts-rho010-r3-047.18d466a3c7019c12,reason=SuccessfulCreate count=1 msg=Created pod: eval-conflicts-rho010-r3-047-wm7ns
0.2628,Event,ADDED,eval-conflicts-rho010-r3-047.18d466a719ca0291,reason=Completed count=1 msg=Job completed
0.263,Event,ADDED,eval-conflicts-rho010-r3-048-j6zc7.18d466a403143d65,reason=Scheduled count=None msg=Successfully assigned compute/eval-conflicts-rho010-r3-048-j6zc7 to kind-worker4
0.2631,Event,ADDED,eval-conflicts-rho010-r3-048-j6zc7.18d466a41c90f7ae,"reason=Pulled count=1 msg=Container image ""busybox:musl"" already present on machine"
0.2633,Event,ADDED,eval-conflicts-rho010-r3-048-j6zc7.18d466a41da664cd,reason=Created count=1 msg=Created container: task
0.2634,Event,ADDED,eval-conflicts-rho010-r3-048-j6zc7.18d466a422633af3,reason=Started count=1 msg=Started container task
0.2636,Event,ADDED,eval-conflicts-rho010-r3-048.18d466a402954e67,reason=SuccessfulCreate count=1 msg=Created pod: eval-conflicts-rho010-r3-048-j6zc7
0.2638,Event,ADDED,eval-conflicts-rho010-r3-048.18d466a73176c3c8,reason=Completed count=1 msg=Job completed
0.2639,Event,ADDED,eval-conflicts-rho010-r3-049-zn9kh.18d466a43f1e521c,reason=Scheduled count=None msg=Successfully assigned compute/eval-conflicts-rho010-r3-049-zn9kh to kind-worker
0.2641,Event,ADDED,eval-conflicts-rho010-r3-049-zn9kh.18d466a45b558018,"reason=Pulled count=1 msg=Container image ""busybox:musl"" already present on machine"
0.2644,Event,ADDED,eval-conflicts-rho010-r3-049-zn9kh.18d466a45c7707e2,reason=Created count=1 msg=Created container: task
0.2646,Event,ADDED,eval-conflicts-rho010-r3-049-zn9kh.18d466a462c89f98,reason=Started count=1 msg=Started container task
0.2651,Event,ADDED,eval-conflicts-rho010-r3-049.18d466a43e242428,reason=SuccessfulCreate count=1 msg=Created pod: eval-conflicts-rho010-r3-049-zn9kh
0.2653,Event,ADDED,eval-conflicts-rho010-r3-049.18d466a791eecf8f,reason=Completed count=1 msg=Job completed
0.2655,Event,ADDED,eval-conflicts-rho010-r3-050-xpdpl.18d466a47aff1c4c,reason=Scheduled count=None msg=Successfully assigned compute/eval-conflicts-rho010-r3-050-xpdpl to kind-worker
0.2656,Event,ADDED,eval-conflicts-rho010-r3-050-xpdpl.18d466a49398f512,"reason=Pulled count=1 msg=Container image ""busybox:musl"" already present on machine"
0.2658,Event,ADDED,eval-conflicts-rho010-r3-050-xpdpl.18d466a494ce03f1,reason=Created count=1 msg=Created container: task
0.266,Event,ADDED,eval-conflicts-rho010-r3-050-xpdpl.18d466a49cd74cad,reason=Started count=1 msg=Started container task
0.2662,Event,ADDED,eval-conflicts-rho010-r3-050.18d466a479f3bccc,reason=SuccessfulCreate count=1 msg=Created pod: eval-conflicts-rho010-r3-050-xpdpl
0.2663,Event,ADDED,eval-conflicts-rho010-r3-050.18d466a7ce0b9bfc,reason=Completed count=1 msg=Job completed
0.2665,Event,ADDED,eval-conflicts-rho010-r3-051-6ddms.18d466a4b66e244c,reason=Scheduled count=None msg=Successfully assigned compute/eval-conflicts-rho010-r3-051-6ddms to kind-worker
0.2667,Event,ADDED,eval-conflicts-rho010-r3-051-6ddms.18d466a4d0411f8a,"reason=Pulled count=1 msg=Container image ""busybox:musl"" already present on machine"
0.267,Event,ADDED,eval-conflicts-rho010-r3-051-6ddms.18d466a4d21b0cb4,reason=Created count=1 msg=Created container: task
0.2673,Event,ADDED,eval-conflicts-rho010-r3-051-6ddms.18d466a4d65ada43,reason=Started count=1 msg=Started container task
0.2675,Event,ADDED,eval-conflicts-rho010-r3-051.18d466a4b595d784,reason=SuccessfulCreate count=1 msg=Created pod: eval-conflicts-rho010-r3-051-6ddms
0.2677,Event,ADDED,eval-conflicts-rho010-r3-051.18d466a809e13b9d,reason=Completed count=1 msg=Job completed
0.2679,Event,ADDED,eval-conflicts-rho010-r3-052-zlszf.18d466a4f23b4561,reason=Scheduled count=None msg=Successfully assigned compute/eval-conflicts-rho010-r3-052-zlszf to kind-worker4
0.268,Event,ADDED,eval-conflicts-rho010-r3-052-zlszf.18d466a50b5979ad,"reason=Pulled count=1 msg=Container image ""busybox:musl"" already present on machine"
0.2683,Event,ADDED,eval-conflicts-rho010-r3-052-zlszf.18d466a50cb984ad,reason=Created count=1 msg=Created container: task
0.2685,Event,ADDED,eval-conflicts-rho010-r3-052-zlszf.18d466a51ac3b024,reason=Started count=1 msg=Started container task
0.2686,Event,ADDED,eval-conflicts-rho010-r3-052.18d466a4f1350759,reason=SuccessfulCreate count=1 msg=Created pod: eval-conflicts-rho010-r3-052-zlszf
0.2688,Event,ADDED,eval-conflicts-rho010-r3-052.18d466a85ca9f455,reason=Completed count=1 msg=Job completed
0.269,Event,ADDED,eval-conflicts-rho010-r3-053-5ngpv.18d466a52d651b6f,"reason=FailedScheduling count=None msg=0/6 nodes are available: 2 c_wall violated: 1 conflicting context pair(s) with node memory, 4 node(s) had untolerated taint(s). no new claims to deallocate, preemption: 0/6 nodes are available: 2 No preemption victims found for incoming pod, 4 Preemption is not helpful for scheduling."
0.2692,Event,ADDED,eval-conflicts-rho010-r3-053-5ngpv.18d466a52e2c4e42,"reason=FailedScheduling count=None msg=0/6 nodes are available: 2 c_wall violated: 1 conflicting context pair(s) with node memory, 4 node(s) had untolerated taint(s). no new claims to deallocate, preemption: 0/6 nodes are available: 2 No preemption victims found for incoming pod, 4 Preemption is not helpful for scheduling."
0.2694,Event,ADDED,eval-conflicts-rho010-r3-053-5ngpv.18d466a5def6384f,"reason=FailedScheduling count=None msg=0/6 nodes are available: 1 c_wall violated: 1 conflicting context pair(s) with node memory, 5 node(s) had untolerated taint(s). no new claims to deallocate, preemption: 0/6 nodes are available: 1 No preemption victims found for incoming pod, 5 Preemption is not helpful for scheduling."
0.2695,Event,ADDED,eval-conflicts-rho010-r3-053-5ngpv.18d466a648a1769a,reason=Scheduled count=None msg=Successfully assigned compute/eval-conflicts-rho010-r3-053-5ngpv to kind-worker2
0.2697,Event,ADDED,eval-conflicts-rho010-r3-053-5ngpv.18d466a65f0c8613,"reason=Pulled count=1 msg=Container image ""busybox:musl"" already present on machine"
0.2699,Event,ADDED,eval-conflicts-rho010-r3-053-5ngpv.18d466a6605868a0,reason=Created count=1 msg=Created container: task
0.27,Event,ADDED,eval-conflicts-rho010-r3-053-5ngpv.18d466a665aae72f,reason=Started count=1 msg=Started container task
0.2702,Event,ADDED,eval-conflicts-rho010-r3-053.18d466a52ceac261,reason=SuccessfulCreate count=1 msg=Created pod: eval-conflicts-rho010-r3-053-5ngpv
0.2704,Event,ADDED,eval-conflicts-rho010-r3-053.18d466a97d9c2d4a,reason=Completed count=1 msg=Job completed
0.2706,Event,ADDED,eval-conflicts-rho010-r3-054-66qhb.18d466a56904f9c3,reason=Scheduled count=None msg=Successfully assigned compute/eval-conflicts-rho010-r3-054-66qhb to kind-worker
0.2707,Event,ADDED,eval-conflicts-rho010-r3-054-66qhb.18d466a581f4a490,"reason=Pulled count=1 msg=Container image ""busybox:musl"" already present on machine"
0.2709,Event,ADDED,eval-conflicts-rho010-r3-054-66qhb.18d466a58304ad9d,reason=Created count=1 msg=Created container: task
0.2711,Event,ADDED,eval-conflicts-rho010-r3-054-66qhb.18d466a587d328f7,reason=Started count=1 msg=Started container task
0.2713,Event,ADDED,eval-conflicts-rho010-r3-054.18d466a56847c240,reason=SuccessfulCreate count=1 msg=Created pod: eval-conflicts-rho010-r3-054-66qhb
0.2715,Event,ADDED,eval-conflicts-rho010-r3-054.18d466a8bcddd1ae,reason=Completed count=1 msg=Job completed
0.2716,Event,ADDED,eval-conflicts-rho010-r3-055-j66g6.18d466a5a4f53bf9,reason=Scheduled count=None msg=Successfully assigned compute/eval-conflicts-rho010-r3-055-j66g6 to kind-worker4
0.2718,Event,ADDED,eval-conflicts-rho010-r3-055-j66g6.18d466a5be9984d5,"reason=Pulled count=1 msg=Container image ""busybox:musl"" already present on machine"
0.272,Event,ADDED,eval-conflicts-rho010-r3-055-j66g6.18d466a5bff0ab0a,reason=Created count=1 msg=Created container: task
0.2723,Event,ADDED,eval-conflicts-rho010-r3-055-j66g6.18d466a5c4b2753a,reason=Started count=1 msg=Started container task
0.2725,Event,ADDED,eval-conflicts-rho010-r3-055.18d466a5a3e8e299,reason=SuccessfulCreate count=1 msg=Created pod: eval-conflicts-rho010-r3-055-j66g6
0.2727,Event,ADDED,eval-conflicts-rho010-r3-055.18d466a8d44f4c55,reason=Completed count=1 msg=Job completed
0.2728,Event,ADDED,eval-conflicts-rho010-r3-056-j5wdn.18d466a5dfefdbc2,"reason=FailedScheduling count=None msg=0/6 nodes are available: 1 c_wall violated: 1 conflicting context pair(s) with node memory, 5 node(s) had untolerated taint(s). no new claims to deallocate, preemption: 0/6 nodes are available: 1 No preemption victims found for incoming pod, 5 Preemption is not helpful for scheduling."
0.273,Event,ADDED,eval-conflicts-rho010-r3-056-j5wdn.18d466a5e09435df,"reason=FailedScheduling count=None msg=0/6 nodes are available: 1 c_wall violated: 1 conflicting context pair(s) with node memory, 5 node(s) had untolerated taint(s). no new claims to deallocate, preemption: 0/6 nodes are available: 1 No preemption victims found for incoming pod, 5 Preemption is not helpful for scheduling."
0.2733,Event,ADDED,eval-conflicts-rho010-r3-056-j5wdn.18d466a64a498ba5,"reason=FailedScheduling count=None msg=0/6 nodes are available: 2 c_wall violated: 1 conflicting context pair(s) with node memory, 4 node(s) had untolerated taint(s). no new claims to deallocate, preemption: 0/6 nodes are available: 2 No preemption victims found for incoming pod, 4 Preemption is not helpful for scheduling."
0.2736,Event,ADDED,eval-conflicts-rho010-r3-056-j5wdn.18d466a651c2f09f,"reason=FailedScheduling count=None msg=0/6 nodes are available: 1 c_wall violated: 1 conflicting context pair(s) with node memory, 5 node(s) had untolerated taint(s). no new claims to deallocate, preemption: 0/6 nodes are available: 1 No preemption victims found for incoming pod, 5 Preemption is not helpful for scheduling."
0.2738,Event,ADDED,eval-conflicts-rho010-r3-056-j5wdn.18d466a6af629302,"reason=FailedScheduling count=None msg=0/6 nodes are available: 2 c_wall violated: 1 conflicting context pair(s) with node memory, 4 node(s) had untolerated taint(s). no new claims to deallocate, preemption: 0/6 nodes are available: 2 No preemption victims found for incoming pod, 4 Preemption is not helpful for scheduling."
0.2741,Event,ADDED,eval-conflicts-rho010-r3-056-j5wdn.18d466a88d4e7a8b,reason=Scheduled count=None msg=Successfully assigned compute/eval-conflicts-rho010-r3-056-j5wdn to kind-worker3
0.2742,Event,ADDED,eval-conflicts-rho010-r3-056-j5wdn.18d466a8a735ebaa,"reason=Pulled count=1 msg=Container image ""busybox:musl"" already present on machine"
0.2744,Event,ADDED,eval-conflicts-rho010-r3-056-j5wdn.18d466a8a85421d8,reason=Created count=1 msg=Created container: task
0.2746,Event,ADDED,eval-conflicts-rho010-r3-056-j5wdn.18d466a8aac6fc0b,reason=Started count=1 msg=Started container task
0.2749,Event,ADDED,eval-conflicts-rho010-r3-056.18d466a5dfb45524,reason=SuccessfulCreate count=1 msg=Created pod: eval-conflicts-rho010-r3-056-j5wdn
0.275,Event,ADDED,eval-conflicts-rho010-r3-056.18d466abc15e523a,reason=Completed count=1 msg=Job completed
0.2752,Event,ADDED,eval-conflicts-rho010-r3-057-nxw9s.18d466a61b8ccfdf,"reason=FailedScheduling count=None msg=0/6 nodes are available: 1 c_wall violated: 1 conflicting context pair(s) with node memory, 5 node(s) had untolerated taint(s). no new claims to deallocate, preemption: 0/6 nodes are available: 1 No preemption victims found for incoming pod, 5 Preemption is not helpful for scheduling."
0.2755,Event,ADDED,eval-conflicts-rho010-r3-057-nxw9s.18d466a61c2d9a7b,"reason=FailedScheduling count=None msg=0/6 nodes are available: 1 c_wall violated: 1 conflicting context pair(s) with node memory, 5 node(s) had untolerated taint(s). no new claims to deallocate, preemption: 0/6 nodes are available: 1 No preemption victims found for incoming pod, 5 Preemption is not helpful for scheduling."
0.2756,Event,ADDED,eval-conflicts-rho010-r3-057-nxw9s.18d466a64a31dc6e,reason=Scheduled count=None msg=Successfully assigned compute/eval-conflicts-rho010-r3-057-nxw9s to kind-worker2
0.2758,Event,ADDED,eval-conflicts-rho010-r3-057-nxw9s.18d466a665b108be,"reason=Pulled count=1 msg=Container image ""busybox:musl"" already present on machine"
0.2759,Event,ADDED,eval-conflicts-rho010-r3-057-nxw9s.18d466a667246f13,reason=Created count=1 msg=Created container: task
0.2761,Event,ADDED,eval-conflicts-rho010-r3-057-nxw9s.18d466a66acf692d,reason=Started count=1 msg=Started container task
0.2763,Event,ADDED,eval-conflicts-rho010-r3-057.18d466a61b48c6e7,reason=SuccessfulCreate count=1 msg=Created pod: eval-conflicts-rho010-r3-057-nxw9s
0.2765,Event,ADDED,eval-conflicts-rho010-r3-057.18d466a97d726932,reason=Completed count=1 msg=Job completed
0.2766,Event,ADDED,eval-conflicts-rho010-r3-058-vw2gd.18d466a656ecd7d7,"reason=FailedScheduling count=None msg=0/6 nodes are available: 1 c_wall violated: 1 conflicting context pair(s) with node memory, 5 node(s) had untolerated taint(s). no new claims to deallocate, preemption: 0/6 nodes are available: 1 No preemption victims found for incoming pod, 5 Preemption is not helpful for scheduling."
0.2768,Event,ADDED,eval-conflicts-rho010-r3-058-vw2gd.18d466a65763615b,"reason=FailedScheduling count=None msg=0/6 nodes are available: 1 c_wall violated: 1 conflicting context pair(s) with node memory, 5 node(s) had untolerated taint(s). no new claims to deallocate, preemption: 0/6 nodes are available: 1 No preemption victims found for incoming pod, 5 Preemption is not helpful for scheduling."
0.2769,Event,ADDED,eval-conflicts-rho010-r3-058-vw2gd.18d466a6aa3a5a8c,reason=Scheduled count=None msg=Successfully assigned compute/eval-conflicts-rho010-r3-058-vw2gd to kind-worker5
0.2772,Event,ADDED,eval-conflicts-rho010-r3-058-vw2gd.18d466a6c3796c0d,"reason=Pulled count=1 msg=Container image ""busybox:musl"" already present on machine"
0.2774,Event,ADDED,eval-conflicts-rho010-r3-058-vw2gd.18d466a6c4ae2102,reason=Created count=1 msg=Created container: task
0.2777,Event,ADDED,eval-conflicts-rho010-r3-058-vw2gd.18d466a6c925f801,reason=Started count=1 msg=Started container task
0.2778,Event,ADDED,eval-conflicts-rho010-r3-058.18d466a656afcb3c,reason=SuccessfulCreate count=1 msg=Created pod: eval-conflicts-rho010-r3-058-vw2gd
0.2781,Event,ADDED,eval-conflicts-rho010-r3-058.18d466a9f03d92dc,reason=Completed count=1 msg=Job completed
0.2783,Event,ADDED,eval-conflicts-rho010-r3-059-rmwmh.18d466a693052e9e,reason=Scheduled count=None msg=Successfully assigned compute/eval-conflicts-rho010-r3-059-rmwmh to kind-worker2
0.2786,Event,ADDED,eval-conflicts-rho010-r3-059-rmwmh.18d466a6ae15a40f,"reason=Pulled count=1 msg=Container image ""busybox:musl"" already present on machine"
0.2788,Event,ADDED,eval-conflicts-rho010-r3-059-rmwmh.18d466a6af3cf4da,reason=Created count=1 msg=Created container: task
0.279,Event,ADDED,eval-conflicts-rho010-r3-059-rmwmh.18d466a6b32fb81b,reason=Started count=1 msg=Started container task
0.2792,Event,ADDED,eval-conflicts-rho010-r3-059.18d466a69284a571,reason=SuccessfulCreate count=1 msg=Created pod: eval-conflicts-rho010-r3-059-rmwmh
0.2794,Event,ADDED,eval-conflicts-rho010-r3-059.18d466a9f532595c,reason=Completed count=1 msg=Job completed
0.2795,Event,ADDED,eval-conflicts-rho010-r3-060-hslc4.18d466a6ceee8d9e,reason=Scheduled count=None msg=Successfully assigned compute/eval-conflicts-rho010-r3-060-hslc4 to kind-worker2
0.2797,Event,ADDED,eval-conflicts-rho010-r3-060-hslc4.18d466a6e8604c72,"reason=Pulled count=1 msg=Container image ""busybox:musl"" already present on machine"
0.2799,Event,ADDED,eval-conflicts-rho010-r3-060-hslc4.18d466a6e96cbf37,reason=Created count=1 msg=Created container: task
0.28,Event,ADDED,eval-conflicts-rho010-r3-060-hslc4.18d466a6eda0c0da,reason=Started count=1 msg=Started container task
0.2802,Event,ADDED,eval-conflicts-rho010-r3-060.18d466a6ce2e2b25,reason=SuccessfulCreate count=1 msg=Created pod: eval-conflicts-rho010-r3-060-hslc4
0.2804,Event,ADDED,eval-conflicts-rho010-r3-060.18d466aa3125fe5d,reason=Completed count=1 msg=Job completed
0.2805,Event,ADDED,eval-conflicts-rho010-r3-061-8xccw.18d466a70b0610f9,reason=Scheduled count=None msg=Successfully assigned compute/eval-conflicts-rho010-r3-061-8xccw to kind-worker5
0.2807,Event,ADDED,eval-conflicts-rho010-r3-061-8xccw.18d466a724649d09,"reason=Pulled count=1 msg=Container image ""busybox:musl"" already present on machine"
0.2808,Event,ADDED,eval-conflicts-rho010-r3-061-8xccw.18d466a72581c5c9,reason=Created count=1 msg=Created container: task
0.281,Event,ADDED,eval-conflicts-rho010-r3-061-8xccw.18d466a727a9d14f,reason=Started count=1 msg=Started container task
0.2812,Event,ADDED,eval-conflicts-rho010-r3-061.18d466a709e13c03,reason=SuccessfulCreate count=1 msg=Created pod: eval-conflicts-rho010-r3-061-8xccw
0.2814,Event,ADDED,eval-conflicts-rho010-r3-061.18d466aa682236ff,reason=Completed count=1 msg=Job completed
0.2815,Event,ADDED,eval-conflicts-rho010-r3-062-szc75.18d466a7461bfdc3,reason=Scheduled count=None msg=Successfully assigned compute/eval-conflicts-rho010-r3-062-szc75 to kind-worker5
0.2823,Event,ADDED,eval-conflicts-rho010-r3-062-szc75.18d466a75fdfadcd,"reason=Pulled count=1 msg=Container image ""busybox:musl"" already present on machine"
0.2825,Event,ADDED,eval-conflicts-rho010-r3-062-szc75.18d466a760fcaa68,reason=Created count=1 msg=Created container: task
0.2827,Event,ADDED,eval-conflicts-rho010-r3-062-szc75.18d466a766703432,reason=Started count=1 msg=Started container task
0.2828,Event,ADDED,eval-conflicts-rho010-r3-062.18d466a7455776a6,reason=SuccessfulCreate count=1 msg=Created pod: eval-conflicts-rho010-r3-062-szc75
0.283,Event,ADDED,eval-conflicts-rho010-r3-062.18d466aaa449de33,reason=Completed count=1 msg=Job completed
0.2832,Event,ADDED,eval-conflicts-rho010-r3-063-fmjj6.18d466a7825ea153,reason=Scheduled count=None msg=Successfully assigned compute/eval-conflicts-rho010-r3-063-fmjj6 to kind-worker5
0.2834,Event,ADDED,eval-conflicts-rho010-r3-063-fmjj6.18d466a79b1cc340,"reason=Pulled count=1 msg=Container image ""busybox:musl"" already present on machine"
0.2836,Event,ADDED,eval-conflicts-rho010-r3-063-fmjj6.18d466a79c2ebafc,reason=Created count=1 msg=Created container: task
0.2838,Event,ADDED,eval-conflicts-rho010-r3-063-fmjj6.18d466a7a054a2bb,reason=Started count=1 msg=Started container task
0.2841,Event,ADDED,eval-conflicts-rho010-r3-063.18d466a7815f2be5,reason=SuccessfulCreate count=1 msg=Created pod: eval-conflicts-rho010-r3-063-fmjj6
0.2842,Event,ADDED,eval-conflicts-rho010-r3-063.18d466aae042122b,reason=Completed count=1 msg=Job completed
0.2848,Event,ADDED,eval-conflicts-rho010-r3-064-n2pzm.18d466a7bd8139c3,reason=Scheduled count=None msg=Successfully assigned compute/eval-conflicts-rho010-r3-064-n2pzm to kind-worker5
0.2849,Event,ADDED,eval-conflicts-rho010-r3-064-n2pzm.18d466a7d722cc3e,"reason=Pulled count=1 msg=Container image ""busybox:musl"" already present on machine"
0.2851,Event,ADDED,eval-conflicts-rho010-r3-064-n2pzm.18d466a7d836dbbc,reason=Created count=1 msg=Created container: task
0.2854,Event,ADDED,eval-conflicts-rho010-r3-064-n2pzm.18d466a7da880eff,reason=Started count=1 msg=Started container task
0.2856,Event,ADDED,eval-conflicts-rho010-r3-064.18d466a7bcc9ae65,reason=SuccessfulCreate count=1 msg=Created pod: eval-conflicts-rho010-r3-064-n2pzm
0.2858,Event,ADDED,eval-conflicts-rho010-r3-064.18d466ab1c22e826,reason=Completed count=1 msg=Job completed
0.2859,Event,ADDED,eval-conflicts-rho010-r3-065-5skks.18d466a7f985e011,reason=Scheduled count=None msg=Successfully assigned compute/eval-conflicts-rho010-r3-065-5skks to kind-worker5
0.2863,Event,ADDED,eval-conflicts-rho010-r3-065-5skks.18d466a812b0e230,"reason=Pulled count=1 msg=Container image ""busybox:musl"" already present on machine"
0.2864,Event,ADDED,eval-conflicts-rho010-r3-065-5skks.18d466a813c667c3,reason=Created count=1 msg=Created container: task
0.2866,Event,ADDED,eval-conflicts-rho010-r3-065-5skks.18d466a8178555cd,reason=Started count=1 msg=Started container task
0.2868,Event,ADDED,eval-conflicts-rho010-r3-065.18d466a7f8c93f11,reason=SuccessfulCreate count=1 msg=Created pod: eval-conflicts-rho010-r3-065-5skks
0.2871,Event,ADDED,eval-conflicts-rho010-r3-065.18d466ab570f54db,reason=Completed count=1 msg=Job completed
0.2873,Event,ADDED,eval-conflicts-rho010-r3-066-f6hgd.18d466a8340fb498,reason=Scheduled count=None msg=Successfully assigned compute/eval-conflicts-rho010-r3-066-f6hgd to kind-worker5
0.2875,Event,ADDED,eval-conflicts-rho010-r3-066-f6hgd.18d466a84da257dc,"reason=Pulled count=1 msg=Container image ""busybox:musl"" already present on machine"
0.2879,Event,ADDED,eval-conflicts-rho010-r3-066-f6hgd.18d466a84ec6899f,reason=Created count=1 msg=Created container: task
0.288,Event,ADDED,eval-conflicts-rho010-r3-066-f6hgd.18d466a853218978,reason=Started count=1 msg=Started container task
0.2882,Event,ADDED,eval-conflicts-rho010-r3-066.18d466a833701b64,reason=SuccessfulCreate count=1 msg=Created pod: eval-conflicts-rho010-r3-066-f6hgd
0.2884,Event,ADDED,eval-conflicts-rho010-r3-066.18d466ab92bdb6e9,reason=Completed count=1 msg=Job completed
0.2887,Event,ADDED,eval-conflicts-rho010-r3-067-mxfm5.18d466a86fb26f8e,reason=Scheduled count=None msg=Successfully assigned compute/eval-conflicts-rho010-r3-067-mxfm5 to kind-worker5
0.2889,Event,ADDED,eval-conflicts-rho010-r3-067-mxfm5.18d466a888bb685e,"reason=Pulled count=1 msg=Container image ""busybox:musl"" already present on machine"
0.289,Event,ADDED,eval-conflicts-rho010-r3-067-mxfm5.18d466a889cca634,reason=Created count=1 msg=Created container: task
0.2892,Event,ADDED,eval-conflicts-rho010-r3-067-mxfm5.18d466a88f2cf597,reason=Started count=1 msg=Started container task
0.2894,Event,ADDED,eval-conflicts-rho010-r3-067.18d466a86f0b4409,reason=SuccessfulCreate count=1 msg=Created pod: eval-conflicts-rho010-r3-067-mxfm5
0.2896,Event,ADDED,eval-conflicts-rho010-r3-067.18d466abce739137,reason=Completed count=1 msg=Job completed
0.2898,Event,ADDED,eval-conflicts-rho010-r3-068-2h8r8.18d466a8abfe2d9a,reason=Scheduled count=None msg=Successfully assigned compute/eval-conflicts-rho010-r3-068-2h8r8 to kind-worker3
0.2899,Event,ADDED,eval-conflicts-rho010-r3-068-2h8r8.18d466a8c554bf47,"reason=Pulled count=1 msg=Container image ""busybox:musl"" already present on machine"
0.2901,Event,ADDED,eval-conflicts-rho010-r3-068-2h8r8.18d466a8c65f17c4,reason=Created count=1 msg=Created container: task
0.2903,Event,ADDED,eval-conflicts-rho010-r3-068-2h8r8.18d466a8c8847205,reason=Started count=1 msg=Started container task
0.2904,Event,ADDED,eval-conflicts-rho010-r3-068.18d466a8ab11f2b9,reason=SuccessfulCreate count=1 msg=Created pod: eval-conflicts-rho010-r3-068-2h8r8
0.2906,Event,ADDED,eval-conflicts-rho010-r3-068.18d466abfdef036c,reason=Completed count=1 msg=Job completed
0.2908,Event,ADDED,eval-conflicts-rho010-r3-069-cfvsb.18d466a8e7431865,reason=Scheduled count=None msg=Successfully assigned compute/eval-conflicts-rho010-r3-069-cfvsb to kind-worker4
0.2909,Event,ADDED,eval-conflicts-rho010-r3-069-cfvsb.18d466a900fb9bdd,"reason=Pulled count=1 msg=Container image ""busybox:musl"" already present on machine"
0.2911,Event,ADDED,eval-conflicts-rho010-r3-069-cfvsb.18d466a90212b542,reason=Created count=1 msg=Created container: task
0.2913,Event,ADDED,eval-conflicts-rho010-r3-069-cfvsb.18d466a9062d5915,reason=Started count=1 msg=Started container task
0.2915,Event,ADDED,eval-conflicts-rho010-r3-069.18d466a8e6554c96,reason=SuccessfulCreate count=1 msg=Created pod: eval-conflicts-rho010-r3-069-cfvsb
0.2916,Event,ADDED,eval-conflicts-rho010-r3-069.18d466ac18ffef95,reason=Completed count=1 msg=Job completed
0.2918,Event,ADDED,eval-conflicts-rho010-r3-070-q4wr7.18d466a92298a6ea,reason=Scheduled count=None msg=Successfully assigned compute/eval-conflicts-rho010-r3-070-q4wr7 to kind-worker4
0.292,Event,ADDED,eval-conflicts-rho010-r3-070-q4wr7.18d466a93c1ff775,"reason=Pulled count=1 msg=Container image ""busybox:musl"" already present on machine"
0.2921,Event,ADDED,eval-conflicts-rho010-r3-070-q4wr7.18d466a93d3c4205,reason=Created count=1 msg=Created container: task
0.2923,Event,ADDED,eval-conflicts-rho010-r3-070-q4wr7.18d466a93f3a43fa,reason=Started count=1 msg=Started container task
0.2925,Event,ADDED,eval-conflicts-rho010-r3-070.18d466a921e98b02,reason=SuccessfulCreate count=1 msg=Created pod: eval-conflicts-rho010-r3-070-q4wr7
0.2926,Event,ADDED,eval-conflicts-rho010-r3-070.18d466ac54d016c8,reason=Completed count=1 msg=Job completed
0.2928,Event,ADDED,eval-conflicts-rho010-r3-071-jmvzv.18d466a95e9221c4,reason=Scheduled count=None msg=Successfully assigned compute/eval-conflicts-rho010-r3-071-jmvzv to kind-worker4
0.2929,Event,ADDED,eval-conflicts-rho010-r3-071-jmvzv.18d466a979798051,"reason=Pulled count=1 msg=Container image ""busybox:musl"" already present on machine"
0.2931,Event,ADDED,eval-conflicts-rho010-r3-071-jmvzv.18d466a97a8a65fd,reason=Created count=1 msg=Created container: task
0.2933,Event,ADDED,eval-conflicts-rho010-r3-071-jmvzv.18d466a97f0e2878,reason=Started count=1 msg=Started container task
0.2934,Event,ADDED,eval-conflicts-rho010-r3-071.18d466a95d994ace,reason=SuccessfulCreate count=1 msg=Created pod: eval-conflicts-rho010-r3-071-jmvzv
0.2939,Event,ADDED,eval-conflicts-rho010-r3-071.18d466ac91061125,reason=Completed count=1 msg=Job completed
0.294,Event,ADDED,eval-conflicts-rho010-r3-072-27h97.18d466a99ab77010,reason=Scheduled count=None msg=Successfully assigned compute/eval-conflicts-rho010-r3-072-27h97 to kind-worker4
0.2942,Event,ADDED,eval-conflicts-rho010-r3-072-27h97.18d466a9b3d7fc00,"reason=Pulled count=1 msg=Container image ""busybox:musl"" already present on machine"
0.2943,Event,ADDED,eval-conflicts-rho010-r3-072-27h97.18d466a9b521540f,reason=Created count=1 msg=Created container: task
0.2945,Event,ADDED,eval-conflicts-rho010-r3-072-27h97.18d466a9ba61d5f8,reason=Started count=1 msg=Started container task
0.2947,Event,ADDED,eval-conflicts-rho010-r3-072.18d466a999ec5b22,reason=SuccessfulCreate count=1 msg=Created pod: eval-conflicts-rho010-r3-072-27h97
0.2948,Event,ADDED,eval-conflicts-rho010-r3-072.18d466accd17eb0e,reason=Completed count=1 msg=Job completed
0.295,Event,ADDED,eval-conflicts-rho010-r3-073-zk8j5.18d466a9d60b8cd0,reason=Scheduled count=None msg=Successfully assigned compute/eval-conflicts-rho010-r3-073-zk8j5 to kind-worker4
0.2952,Event,ADDED,eval-conflicts-rho010-r3-073-zk8j5.18d466a9ef6605eb,"reason=Pulled count=1 msg=Container image ""busybox:musl"" already present on machine"
0.2953,Event,ADDED,eval-conflicts-rho010-r3-073-zk8j5.18d466a9f0f81193,reason=Created count=1 msg=Created container: task
0.2955,Event,ADDED,eval-conflicts-rho010-r3-073-zk8j5.18d466a9f4596311,reason=Started count=1 msg=Started container task
0.2957,Event,ADDED,eval-conflicts-rho010-r3-073.18d466a9d5395e39,reason=SuccessfulCreate count=1 msg=Created pod: eval-conflicts-rho010-r3-073-zk8j5
0.2959,Event,ADDED,eval-conflicts-rho010-r3-073.18d466ad08f6cc41,reason=Completed count=1 msg=Job completed
0.296,Event,ADDED,eval-conflicts-rho010-r3-074-p497j.18d466aa114c9375,reason=Scheduled count=None msg=Successfully assigned compute/eval-conflicts-rho010-r3-074-p497j to kind-worker3
0.2962,Event,ADDED,eval-conflicts-rho010-r3-074-p497j.18d466aa2b6d0e80,"reason=Pulled count=1 msg=Container image ""busybox:musl"" already present on machine"
0.2964,Event,ADDED,eval-conflicts-rho010-r3-074-p497j.18d466aa2ce13ff0,reason=Created count=1 msg=Created container: task
0.2965,Event,ADDED,eval-conflicts-rho010-r3-074-p497j.18d466aa30aa3b17,reason=Started count=1 msg=Started container task
0.2967,Event,ADDED,eval-conflicts-rho010-r3-074.18d466aa1073812e,reason=SuccessfulCreate count=1 msg=Created pod: eval-conflicts-rho010-r3-074-p497j
0.2969,Event,ADDED,eval-conflicts-rho010-r3-074.18d466ad641ef89b,reason=Completed count=1 msg=Job completed
0.297,Event,ADDED,eval-conflicts-rho010-r3-075-stnp9.18d466aa4dca7300,reason=Scheduled count=None msg=Successfully assigned compute/eval-conflicts-rho010-r3-075-stnp9 to kind-worker3
0.2972,Event,ADDED,eval-conflicts-rho010-r3-075-stnp9.18d466aa672bd476,"reason=Pulled count=1 msg=Container image ""busybox:musl"" already present on machine"
0.2973,Event,ADDED,eval-conflicts-rho010-r3-075-stnp9.18d466aa68b50da6,reason=Created count=1 msg=Created container: task
0.2975,Event,ADDED,eval-conflicts-rho010-r3-075-stnp9.18d466aa6d5f4673,reason=Started count=1 msg=Started container task
0.2979,Event,ADDED,eval-conflicts-rho010-r3-075.18d466aa4ca4682c,reason=SuccessfulCreate count=1 msg=Created pod: eval-conflicts-rho010-r3-075-stnp9
0.2981,Event,ADDED,eval-conflicts-rho010-r3-075.18d466ad9fef33b3,reason=Completed count=1 msg=Job completed
0.2983,Event,ADDED,eval-conflicts-rho010-r3-076-99fpd.18d466aa88804e29,"reason=FailedScheduling count=None msg=0/6 nodes are available: 2 c_wall violated: 1 conflicting context pair(s) with node memory, 4 node(s) had untolerated taint(s). no new claims to deallocate, preemption: 0/6 nodes are available: 2 No preemption victims found for incoming pod, 4 Preemption is not helpful for scheduling."
0.2984,Event,ADDED,eval-conflicts-rho010-r3-076-99fpd.18d466aa8917bfb7,"reason=FailedScheduling count=None msg=0/6 nodes are available: 2 c_wall violated: 1 conflicting context pair(s) with node memory, 4 node(s) had untolerated taint(s). no new claims to deallocate, preemption: 0/6 nodes are available: 2 No preemption victims found for incoming pod, 4 Preemption is not helpful for scheduling."
0.2986,Event,ADDED,eval-conflicts-rho010-r3-076-99fpd.18d466aa9b134588,reason=Scheduled count=None msg=Successfully assigned compute/eval-conflicts-rho010-r3-076-99fpd to kind-worker
0.2988,Event,ADDED,eval-conflicts-rho010-r3-076-99fpd.18d466aab3b8ff9c,"reason=Pulled count=1 msg=Container image ""busybox:musl"" already present on machine"
0.2989,Event,ADDED,eval-conflicts-rho010-r3-076-99fpd.18d466aab4d37b32,reason=Created count=1 msg=Created container: task
0.2991,Event,ADDED,eval-conflicts-rho010-r3-076-99fpd.18d466aab6eecec7,reason=Started count=1 msg=Started container task
0.2993,Event,ADDED,eval-conflicts-rho010-r3-076.18d466aa880acd9c,reason=SuccessfulCreate count=1 msg=Created pod: eval-conflicts-rho010-r3-076-99fpd
0.2994,Event,ADDED,eval-conflicts-rho010-r3-076.18d466addeed524f,reason=Completed count=1 msg=Job completed
0.2996,Event,ADDED,eval-conflicts-rho010-r3-077-snpmx.18d466aac4111fac,reason=Scheduled count=None msg=Successfully assigned compute/eval-conflicts-rho010-r3-077-snpmx to kind-worker4
0.2997,Event,ADDED,eval-conflicts-rho010-r3-077-snpmx.18d466aadd27e0e3,"reason=Pulled count=1 msg=Container image ""busybox:musl"" already present on machine"
0.2999,Event,ADDED,eval-conflicts-rho010-r3-077-snpmx.18d466aade595d06,reason=Created count=1 msg=Created container: task
0.3001,Event,ADDED,eval-conflicts-rho010-r3-077-snpmx.18d466aae86121ea,reason=Started count=1 msg=Started container task
0.3002,Event,ADDED,eval-conflicts-rho010-r3-077.18d466aac321e433,reason=SuccessfulCreate count=1 msg=Created pod: eval-conflicts-rho010-r3-077-snpmx
0.3004,Event,ADDED,eval-conflicts-rho010-r3-077.18d466adf7c50051,reason=Completed count=1 msg=Job completed
0.3006,Event,ADDED,eval-conflicts-rho010-r3-078-slb9t.18d466aaffac954e,reason=Scheduled count=None msg=Successfully assigned compute/eval-conflicts-rho010-r3-078-slb9t to kind-worker4
0.3007,Event,ADDED,eval-conflicts-rho010-r3-078-slb9t.18d466ab19169e64,"reason=Pulled count=1 msg=Container image ""busybox:musl"" already present on machine"
0.3009,Event,ADDED,eval-conflicts-rho010-r3-078-slb9t.18d466ab1a3b2241,reason=Created count=1 msg=Created container: task
0.3011,Event,ADDED,eval-conflicts-rho010-r3-078-slb9t.18d466ab216a51f9,reason=Started count=1 msg=Started container task
0.3012,Event,ADDED,eval-conflicts-rho010-r3-078.18d466aafeef7d4f,reason=SuccessfulCreate count=1 msg=Created pod: eval-conflicts-rho010-r3-078-slb9t
0.3014,Event,ADDED,eval-conflicts-rho010-r3-078.18d466ae33de1796,reason=Completed count=1 msg=Job completed
0.3015,Event,ADDED,eval-conflicts-rho010-r3-079-4pm7n.18d466ab3b49fa36,reason=Scheduled count=None msg=Successfully assigned compute/eval-conflicts-rho010-r3-079-4pm7n to kind-worker2
0.3017,Event,ADDED,eval-conflicts-rho010-r3-079-4pm7n.18d466ab5485237a,"reason=Pulled count=1 msg=Container image ""busybox:musl"" already present on machine"
0.3019,Event,ADDED,eval-conflicts-rho010-r3-079-4pm7n.18d466ab55998ee5,reason=Created count=1 msg=Created container: task
0.3021,Event,ADDED,eval-conflicts-rho010-r3-079-4pm7n.18d466ab5adfe53c,reason=Started count=1 msg=Started container task
0.3022,Event,ADDED,eval-conflicts-rho010-r3-079.18d466ab3acb4774,reason=SuccessfulCreate count=1 msg=Created pod: eval-conflicts-rho010-r3-079-4pm7n
0.3027,Event,ADDED,eval-conflicts-rho010-r3-079.18d466aea0a557a8,reason=Completed count=1 msg=Job completed
0.3029,Event,ADDED,eval-conflicts-rho010-r3-080-9gkgk.18d466ab77140b4f,reason=Scheduled count=None msg=Successfully assigned compute/eval-conflicts-rho010-r3-080-9gkgk to kind-worker5
0.3031,Event,ADDED,eval-conflicts-rho010-r3-080-9gkgk.18d466ab8fa558e4,"reason=Pulled count=1 msg=Container image ""busybox:musl"" already present on machine"
0.3032,Event,ADDED,eval-conflicts-rho010-r3-080-9gkgk.18d466ab90d25e81,reason=Created count=1 msg=Created container: task
0.3034,Event,ADDED,eval-conflicts-rho010-r3-080-9gkgk.18d466ab92ff4126,reason=Started count=1 msg=Started container task
0.3035,Event,ADDED,eval-conflicts-rho010-r3-080.18d466ab75d8ace7,reason=SuccessfulCreate count=1 msg=Created pod: eval-conflicts-rho010-r3-080-9gkgk
0.3037,Event,ADDED,eval-conflicts-rho010-r3-080.18d466aeda4880c7,reason=Completed count=1 msg=Job completed
0.3039,Event,ADDED,eval-conflicts-rho010-r3-081-frdsl.18d466abb2d9e88d,reason=Scheduled count=None msg=Successfully assigned compute/eval-conflicts-rho010-r3-081-frdsl to kind-worker
0.3041,Event,ADDED,eval-conflicts-rho010-r3-081-frdsl.18d466abcbc61fbc,"reason=Pulled count=1 msg=Container image ""busybox:musl"" already present on machine"
0.3043,Event,ADDED,eval-conflicts-rho010-r3-081-frdsl.18d466abcce3c08e,reason=Created count=1 msg=Created container: task
0.3045,Event,ADDED,eval-conflicts-rho010-r3-081-frdsl.18d466abcef3e875,reason=Started count=1 msg=Started container task
0.3048,Event,ADDED,eval-conflicts-rho010-r3-081.18d466abb1b9c95e,reason=SuccessfulCreate count=1 msg=Created pod: eval-conflicts-rho010-r3-081-frdsl
0.3049,Event,ADDED,eval-conflicts-rho010-r3-081.18d466af0994dbe3,reason=Completed count=1 msg=Job completed
0.3051,Event,ADDED,eval-conflicts-rho010-r3-082-8fxpc.18d466abee33a620,reason=Scheduled count=None msg=Successfully assigned compute/eval-conflicts-rho010-r3-082-8fxpc to kind-worker2
0.3053,Event,ADDED,eval-conflicts-rho010-r3-082-8fxpc.18d466ac06f6fb30,"reason=Pulled count=1 msg=Container image ""busybox:musl"" already present on machine"
0.3056,Event,ADDED,eval-conflicts-rho010-r3-082-8fxpc.18d466ac0811dff7,reason=Created count=1 msg=Created container: task
0.3057,Event,ADDED,eval-conflicts-rho010-r3-082-8fxpc.18d466ac0b03163e,reason=Started count=1 msg=Started container task
0.3059,Event,ADDED,eval-conflicts-rho010-r3-082.18d466abed4ae386,reason=SuccessfulCreate count=1 msg=Created pod: eval-conflicts-rho010-r3-082-8fxpc
0.3061,Event,ADDED,eval-conflicts-rho010-r3-082.18d466af185142ed,reason=Completed count=1 msg=Job completed
0.3063,Event,ADDED,eval-conflicts-rho010-r3-083-qwmxl.18d466ac2a1845cb,reason=Scheduled count=None msg=Successfully assigned compute/eval-conflicts-rho010-r3-083-qwmxl to kind-worker5
0.3064,Event,ADDED,eval-conflicts-rho010-r3-083-qwmxl.18d466ac44a857cf,"reason=Pulled count=1 msg=Container image ""busybox:musl"" already present on machine"
0.3066,Event,ADDED,eval-conflicts-rho010-r3-083-qwmxl.18d466ac45cb267f,reason=Created count=1 msg=Created container: task
0.3071,Event,ADDED,eval-conflicts-rho010-r3-083-qwmxl.18d466ac496f0785,reason=Started count=1 msg=Started container task
0.3072,Event,ADDED,eval-conflicts-rho010-r3-083.18d466ac28dcec9b,reason=SuccessfulCreate count=1 msg=Created pod: eval-conflicts-rho010-r3-083-qwmxl
0.3074,Event,ADDED,eval-conflicts-rho010-r3-083.18d466af8c0d16ae,reason=Completed count=1 msg=Job completed
0.3075,Event,ADDED,eval-conflicts-rho010-r3-084-klnc7.18d466ac660197b0,reason=Scheduled count=None msg=Successfully assigned compute/eval-conflicts-rho010-r3-084-klnc7 to kind-worker5
0.3077,Event,ADDED,eval-conflicts-rho010-r3-084-klnc7.18d466ac7e89496f,"reason=Pulled count=1 msg=Container image ""busybox:musl"" already present on machine"
0.3079,Event,ADDED,eval-conflicts-rho010-r3-084-klnc7.18d466ac7f8ede65,reason=Created count=1 msg=Created container: task
0.308,Event,ADDED,eval-conflicts-rho010-r3-084-klnc7.18d466ac83a31107,reason=Started count=1 msg=Started container task
0.3082,Event,ADDED,eval-conflicts-rho010-r3-084.18d466ac64a731f7,reason=SuccessfulCreate count=1 msg=Created pod: eval-conflicts-rho010-r3-084-klnc7
0.3084,Event,ADDED,eval-conflicts-rho010-r3-084.18d466afc7fe8bc0,reason=Completed count=1 msg=Job completed
0.3085,Event,ADDED,eval-conflicts-rho010-r3-085-h8sn2.18d466aca212c0b4,reason=Scheduled count=None msg=Successfully assigned compute/eval-conflicts-rho010-r3-085-h8sn2 to kind-worker2
0.3087,Event,ADDED,eval-conflicts-rho010-r3-085-h8sn2.18d466acbc3a2e47,"reason=Pulled count=1 msg=Container image ""busybox:musl"" already present on machine"
0.3088,Event,ADDED,eval-conflicts-rho010-r3-085-h8sn2.18d466acbd71ba71,reason=Created count=1 msg=Created container: task
0.309,Event,ADDED,eval-conflicts-rho010-r3-085-h8sn2.18d466acc1f0e805,reason=Started count=1 msg=Started container task
0.3092,Event,ADDED,eval-conflicts-rho010-r3-085.18d466aca0da34f7,reason=SuccessfulCreate count=1 msg=Created pod: eval-conflicts-rho010-r3-085-h8sn2
0.3093,Event,ADDED,eval-conflicts-rho010-r3-085.18d466b0077a8448,reason=Completed count=1 msg=Job completed
0.3095,Event,ADDED,eval-conflicts-rho010-r3-086-dh67j.18d466acdcfd31b2,reason=Scheduled count=None msg=Successfully assigned compute/eval-conflicts-rho010-r3-086-dh67j to kind-worker5
0.3096,Event,ADDED,eval-conflicts-rho010-r3-086-dh67j.18d466acf5f98d08,"reason=Pulled count=1 msg=Container image ""busybox:musl"" already present on machine"
0.3098,Event,ADDED,eval-conflicts-rho010-r3-086-dh67j.18d466acf72a68b5,reason=Created count=1 msg=Created container: task
0.31,Event,ADDED,eval-conflicts-rho010-r3-086-dh67j.18d466acfaf8e995,reason=Started count=1 msg=Started container task
0.3101,Event,ADDED,eval-conflicts-rho010-r3-086.18d466acdbc9d920,reason=SuccessfulCreate count=1 msg=Created pod: eval-conflicts-rho010-r3-086-dh67j
0.3103,Event,ADDED,eval-conflicts-rho010-r3-086.18d466b03f09a85a,reason=Completed count=1 msg=Job completed
0.3104,Event,ADDED,eval-conflicts-rho010-r3-087-d6qkc.18d466ad18dd8c41,reason=Scheduled count=None msg=Successfully assigned compute/eval-conflicts-rho010-r3-087-d6qkc to kind-worker5
0.3106,Event,ADDED,eval-conflicts-rho010-r3-087-d6qkc.18d466ad319c1a76,"reason=Pulled count=1 msg=Container image ""busybox:musl"" already present on machine"
0.3108,Event,ADDED,eval-conflicts-rho010-r3-087-d6qkc.18d466ad32c7c633,reason=Created count=1 msg=Created container: task
0.3109,Event,ADDED,eval-conflicts-rho010-r3-087-d6qkc.18d466ad3734e419,reason=Started count=1 msg=Started container task
0.3112,Event,ADDED,eval-conflicts-rho010-r3-087.18d466ad1838e49e,reason=SuccessfulCreate count=1 msg=Created pod: eval-conflicts-rho010-r3-087-d6qkc
0.3114,Event,ADDED,eval-conflicts-rho010-r3-087.18d466b07b0a9c24,reason=Completed count=1 msg=Job completed
0.3116,Event,ADDED,eval-conflicts-rho010-r3-088-gxpd6.18d466ad54037243,reason=Scheduled count=None msg=Successfully assigned compute/eval-conflicts-rho010-r3-088-gxpd6 to kind-worker2
0.3117,Event,ADDED,eval-conflicts-rho010-r3-088-gxpd6.18d466ad6e596112,"reason=Pulled count=1 msg=Container image ""busybox:musl"" already present on machine"
0.312,Event,ADDED,eval-conflicts-rho010-r3-088-gxpd6.18d466ad702996d7,reason=Created count=1 msg=Created container: task
0.3121,Event,ADDED,eval-conflicts-rho010-r3-088-gxpd6.18d466ad7548aab1,reason=Started count=1 msg=Started container task
0.3123,Event,ADDED,eval-conflicts-rho010-r3-088.18d466ad531b53ff,reason=SuccessfulCreate count=1 msg=Created pod: eval-conflicts-rho010-r3-088-gxpd6
0.3124,Event,ADDED,eval-conflicts-rho010-r3-088.18d466b0baddc715,reason=Completed count=1 msg=Job completed
0.3126,Event,ADDED,eval-conflicts-rho010-r3-089-r4smx.18d466ad8f4bb159,reason=Scheduled count=None msg=Successfully assigned compute/eval-conflicts-rho010-r3-089-r4smx to kind-worker5
0.3128,Event,ADDED,eval-conflicts-rho010-r3-089-r4smx.18d466adac167bf2,"reason=Pulled count=1 msg=Container image ""busybox:musl"" already present on machine"
0.3129,Event,ADDED,eval-conflicts-rho010-r3-089-r4smx.18d466adad389375,reason=Created count=1 msg=Created container: task
0.3131,Event,ADDED,eval-conflicts-rho010-r3-089-r4smx.18d466adb400aa46,reason=Started count=1 msg=Started container task
0.3133,Event,ADDED,eval-conflicts-rho010-r3-089.18d466ad8e4a56a7,reason=SuccessfulCreate count=1 msg=Created pod: eval-conflicts-rho010-r3-089-r4smx
0.3135,Event,ADDED,eval-conflicts-rho010-r3-089.18d466b0f2ed0c11,reason=Completed count=1 msg=Job completed
0.3136,Event,ADDED,eval-conflicts-rho010-r3-090-7l9ch.18d466adcad04c52,reason=Scheduled count=None msg=Successfully assigned compute/eval-conflicts-rho010-r3-090-7l9ch to kind-worker3
0.3139,Event,ADDED,eval-conflicts-rho010-r3-090-7l9ch.18d466ade534197c,"reason=Pulled count=1 msg=Container image ""busybox:musl"" already present on machine"
0.314,Event,ADDED,eval-conflicts-rho010-r3-090-7l9ch.18d466ade65823e5,reason=Created count=1 msg=Created container: task
0.3142,Event,ADDED,eval-conflicts-rho010-r3-090-7l9ch.18d466adec240a22,reason=Started count=1 msg=Started container task
0.3147,Event,ADDED,eval-conflicts-rho010-r3-090.18d466adca635335,reason=SuccessfulCreate count=1 msg=Created pod: eval-conflicts-rho010-r3-090-7l9ch
0.3149,Event,ADDED,eval-conflicts-rho010-r3-090.18d466b0e5236190,reason=Completed count=1 msg=Job completed
0.3151,Event,ADDED,eval-conflicts-rho010-r3-091-9nmcb.18d466ae082ac906,reason=Scheduled count=None msg=Successfully assigned compute/eval-conflicts-rho010-r3-091-9nmcb to kind-worker3
0.3152,Event,ADDED,eval-conflicts-rho010-r3-091-9nmcb.18d466ae20e1e838,"reason=Pulled count=1 msg=Container image ""busybox:musl"" already present on machine"
0.3155,Event,ADDED,eval-conflicts-rho010-r3-091-9nmcb.18d466ae21e6ebe9,reason=Created count=1 msg=Created container: task
0.3157,Event,ADDED,eval-conflicts-rho010-r3-091-9nmcb.18d466ae25d2578a,reason=Started count=1 msg=Started container task
0.3159,Event,ADDED,eval-conflicts-rho010-r3-091.18d466ae07baf554,reason=SuccessfulCreate count=1 msg=Created pod: eval-conflicts-rho010-r3-091-9nmcb
0.3161,Event,ADDED,eval-conflicts-rho010-r3-091.18d466b15ca5115d,reason=Completed count=1 msg=Job completed
0.3163,Event,ADDED,eval-conflicts-rho010-r3-092-k74l6.18d466ae418c462b,reason=Scheduled count=None msg=Successfully assigned compute/eval-conflicts-rho010-r3-092-k74l6 to kind-worker3
0.3166,Event,ADDED,eval-conflicts-rho010-r3-092-k74l6.18d466ae5a2b0b59,"reason=Pulled count=1 msg=Container image ""busybox:musl"" already present on machine"
0.3168,Event,ADDED,eval-conflicts-rho010-r3-092-k74l6.18d466ae5b473827,reason=Created count=1 msg=Created container: task
0.3171,Event,ADDED,eval-conflicts-rho010-r3-092-k74l6.18d466ae5fb96d0b,reason=Started count=1 msg=Started container task
0.3173,Event,ADDED,eval-conflicts-rho010-r3-092.18d466ae412194a9,reason=SuccessfulCreate count=1 msg=Created pod: eval-conflicts-rho010-r3-092-k74l6
0.3174,Event,ADDED,eval-conflicts-rho010-r3-092.18d466b198a6d4ef,reason=Completed count=1 msg=Job completed
0.3176,Event,ADDED,eval-conflicts-rho010-r3-093-vfftc.18d466ae7d75c56a,reason=Scheduled count=None msg=Successfully assigned compute/eval-conflicts-rho010-r3-093-vfftc to kind-worker3
0.3179,Event,ADDED,eval-conflicts-rho010-r3-093-vfftc.18d466ae96575481,"reason=Pulled count=1 msg=Container image ""busybox:musl"" already present on machine"
0.3181,Event,ADDED,eval-conflicts-rho010-r3-093-vfftc.18d466ae976dbc5f,reason=Created count=1 msg=Created container: task
0.3183,Event,ADDED,eval-conflicts-rho010-r3-093-vfftc.18d466ae995dcc10,reason=Started count=1 msg=Started container task
0.3184,Event,ADDED,eval-conflicts-rho010-r3-093.18d466ae7ceb1349,reason=SuccessfulCreate count=1 msg=Created pod: eval-conflicts-rho010-r3-093-vfftc
0.3187,Event,ADDED,eval-conflicts-rho010-r3-093.18d466b1d4532a38,reason=Completed count=1 msg=Job completed
0.3189,Event,ADDED,eval-conflicts-rho010-r3-094-9rvwr.18d466aeb91d7c33,reason=Scheduled count=None msg=Successfully assigned compute/eval-conflicts-rho010-r3-094-9rvwr to kind-worker3
0.319,Event,ADDED,eval-conflicts-rho010-r3-094-9rvwr.18d466aed1c00f5a,"reason=Pulled count=1 msg=Container image ""busybox:musl"" already present on machine"
0.3193,Event,ADDED,eval-conflicts-rho010-r3-094-9rvwr.18d466aed2d632db,reason=Created count=1 msg=Created container: task
0.3195,Event,ADDED,eval-conflicts-rho010-r3-094-9rvwr.18d466aed4ce7ddf,reason=Started count=1 msg=Started container task
0.3197,Event,ADDED,eval-conflicts-rho010-r3-094.18d466aeb86b1095,reason=SuccessfulCreate count=1 msg=Created pod: eval-conflicts-rho010-r3-094-9rvwr
0.3198,Event,ADDED,eval-conflicts-rho010-r3-094.18d466b2108180c7,reason=Completed count=1 msg=Job completed
0.3201,Event,ADDED,eval-conflicts-rho010-r3-095-x9qt2.18d466aef4a2c36e,reason=Scheduled count=None msg=Successfully assigned compute/eval-conflicts-rho010-r3-095-x9qt2 to kind-worker3
0.3203,Event,ADDED,eval-conflicts-rho010-r3-095-x9qt2.18d466af0de886b5,"reason=Pulled count=1 msg=Container image ""busybox:musl"" already present on machine"
0.3205,Event,ADDED,eval-conflicts-rho010-r3-095-x9qt2.18d466af0ef5f8b7,reason=Created count=1 msg=Created container: task
0.3208,Event,ADDED,eval-conflicts-rho010-r3-095-x9qt2.18d466af1111d05a,reason=Started count=1 msg=Started container task
0.321,Event,ADDED,eval-conflicts-rho010-r3-095.18d466aef417f662,reason=SuccessfulCreate count=1 msg=Created pod: eval-conflicts-rho010-r3-095-x9qt2
0.3211,Event,ADDED,eval-conflicts-rho010-r3-095.18d466b24c3b8dba,reason=Completed count=1 msg=Job completed
0.3213,Event,ADDED,eval-conflicts-rho010-r3-096-25tc5.18d466af3073e5bb,reason=Scheduled count=None msg=Successfully assigned compute/eval-conflicts-rho010-r3-096-25tc5 to kind-worker3
0.3215,Event,ADDED,eval-conflicts-rho010-r3-096-25tc5.18d466af499df652,"reason=Pulled count=1 msg=Container image ""busybox:musl"" already present on machine"
0.3217,Event,ADDED,eval-conflicts-rho010-r3-096-25tc5.18d466af4abe6bb7,reason=Created count=1 msg=Created container: task
0.3218,Event,ADDED,eval-conflicts-rho010-r3-096-25tc5.18d466af4d0fed10,reason=Started count=1 msg=Started container task
0.322,Event,ADDED,eval-conflicts-rho010-r3-096.18d466af2fd721db,reason=SuccessfulCreate count=1 msg=Created pod: eval-conflicts-rho010-r3-096-25tc5
0.3222,Event,ADDED,eval-conflicts-rho010-r3-096.18d466b2884df5c4,reason=Completed count=1 msg=Job completed
0.3224,Event,ADDED,eval-conflicts-rho010-r3-097-zxg7v.18d466af6ce69000,reason=Scheduled count=None msg=Successfully assigned compute/eval-conflicts-rho010-r3-097-zxg7v to kind-worker
0.3225,Event,ADDED,eval-conflicts-rho010-r3-097-zxg7v.18d466af853c2c61,"reason=Pulled count=1 msg=Container image ""busybox:musl"" already present on machine"
0.3227,Event,ADDED,eval-conflicts-rho010-r3-097-zxg7v.18d466af864c67a4,reason=Created count=1 msg=Created container: task
0.3229,Event,ADDED,eval-conflicts-rho010-r3-097-zxg7v.18d466af8835bf5c,reason=Started count=1 msg=Started container task
0.3231,Event,ADDED,eval-conflicts-rho010-r3-097.18d466af6be4ad0c,reason=SuccessfulCreate count=1 msg=Created pod: eval-conflicts-rho010-r3-097-zxg7v
0.3232,Event,ADDED,eval-conflicts-rho010-r3-097.18d466b28a859ede,reason=Completed count=1 msg=Job completed
0.3234,Event,ADDED,eval-conflicts-rho010-r3-098-8zs7d.18d466afa737e7c0,reason=Scheduled count=None msg=Successfully assigned compute/eval-conflicts-rho010-r3-098-8zs7d to kind-worker
0.3236,Event,ADDED,eval-conflicts-rho010-r3-098-8zs7d.18d466afc06a419b,"reason=Pulled count=1 msg=Container image ""busybox:musl"" already present on machine"
0.3238,Event,ADDED,eval-conflicts-rho010-r3-098-8zs7d.18d466afc176f75d,reason=Created count=1 msg=Created container: task
0.3239,Event,ADDED,eval-conflicts-rho010-r3-098-8zs7d.18d466afc355897c,reason=Started count=1 msg=Started container task
0.3241,Event,ADDED,eval-conflicts-rho010-r3-098.18d466afa6be835b,reason=SuccessfulCreate count=1 msg=Created pod: eval-conflicts-rho010-r3-098-8zs7d
0.3242,Event,ADDED,eval-conflicts-rho010-r3-098.18d466b301dd838c,reason=Completed count=1 msg=Job completed
0.3244,Event,ADDED,eval-conflicts-rho010-r3-099-l9lvt.18d466afe305f493,reason=Scheduled count=None msg=Successfully assigned compute/eval-conflicts-rho010-r3-099-l9lvt to kind-worker
0.3246,Event,ADDED,eval-conflicts-rho010-r3-099-l9lvt.18d466affc07fc67,"reason=Pulled count=1 msg=Container image ""busybox:musl"" already present on machine"
0.3247,Event,ADDED,eval-conflicts-rho010-r3-099-l9lvt.18d466affd208e38,reason=Created count=1 msg=Created container: task
0.3249,Event,ADDED,eval-conflicts-rho010-r3-099-l9lvt.18d466b001350b66,reason=Started count=1 msg=Started container task
0.325,Event,ADDED,eval-conflicts-rho010-r3-099.18d466afe24fc834,reason=SuccessfulCreate count=1 msg=Created pod: eval-conflicts-rho010-r3-099-l9lvt
0.3253,Event,ADDED,eval-conflicts-rho010-r3-099.18d466b33db6ef45,reason=Completed count=1 msg=Job completed
0.3254,Event,ADDED,eval-conflicts-rho010-r4-000-vcpkp.18d466b865177534,reason=Scheduled count=None msg=Successfully assigned compute/eval-conflicts-rho010-r4-000-vcpkp to kind-worker2
0.3256,Event,ADDED,eval-conflicts-rho010-r4-000-vcpkp.18d466b87e34f133,"reason=Pulled count=1 msg=Container image ""busybox:musl"" already present on machine"
0.3258,Event,ADDED,eval-conflicts-rho010-r4-000-vcpkp.18d466b87f47c928,reason=Created count=1 msg=Created container: task
0.3259,Event,ADDED,eval-conflicts-rho010-r4-000-vcpkp.18d466b8819192c8,reason=Started count=1 msg=Started container task
0.3261,Event,ADDED,eval-conflicts-rho010-r4-000.18d466b864345855,reason=SuccessfulCreate count=1 msg=Created pod: eval-conflicts-rho010-r4-000-vcpkp
0.3263,Event,ADDED,eval-conflicts-rho010-r4-000.18d466bbb32a2f4e,reason=Completed count=1 msg=Job completed
0.3265,Event,ADDED,eval-conflicts-rho010-r4-001-rtggb.18d466b89f3b69fe,reason=Scheduled count=None msg=Successfully assigned compute/eval-conflicts-rho010-r4-001-rtggb to kind-worker
0.3268,Event,ADDED,eval-conflicts-rho010-r4-001-rtggb.18d466b8b7aabd7a,"reason=Pulled count=1 msg=Container image ""busybox:musl"" already present on machine"
0.327,Event,ADDED,eval-conflicts-rho010-r4-001-rtggb.18d466b8b8caaf01,reason=Created count=1 msg=Created container: task
0.3272,Event,ADDED,eval-conflicts-rho010-r4-001-rtggb.18d466b8bc86792a,reason=Started count=1 msg=Started container task
0.3274,Event,ADDED,eval-conflicts-rho010-r4-001.18d466b89e30688b,reason=SuccessfulCreate count=1 msg=Created pod: eval-conflicts-rho010-r4-001-rtggb
0.3276,Event,ADDED,eval-conflicts-rho010-r4-001.18d466bba47c889f,reason=Completed count=1 msg=Job completed
0.3278,Event,ADDED,eval-conflicts-rho010-r4-002-7z68v.18d466b8db4293b0,reason=Scheduled count=None msg=Successfully assigned compute/eval-conflicts-rho010-r4-002-7z68v to kind-worker5
0.3281,Event,ADDED,eval-conflicts-rho010-r4-002-7z68v.18d466b8f45cb681,"reason=Pulled count=1 msg=Container image ""busybox:musl"" already present on machine"
0.3282,Event,ADDED,eval-conflicts-rho010-r4-002-7z68v.18d466b8f56c7d60,reason=Created count=1 msg=Created container: task
0.3284,Event,ADDED,eval-conflicts-rho010-r4-002-7z68v.18d466b8f8b17746,reason=Started count=1 msg=Started container task
0.3286,Event,ADDED,eval-conflicts-rho010-r4-002.18d466b8da9a1e38,reason=SuccessfulCreate count=1 msg=Created pod: eval-conflicts-rho010-r4-002-7z68v
0.3288,Event,ADDED,eval-conflicts-rho010-r4-002.18d466bc27728ec3,reason=Completed count=1 msg=Job completed
0.3289,Event,ADDED,eval-conflicts-rho010-r4-003-vg5zs.18d466b916671192,reason=Scheduled count=None msg=Successfully assigned compute/eval-conflicts-rho010-r4-003-vg5zs to kind-worker5
0.3291,Event,ADDED,eval-conflicts-rho010-r4-003-vg5zs.18d466b930288230,"reason=Pulled count=1 msg=Container image ""busybox:musl"" already present on machine"
0.3293,Event,ADDED,eval-conflicts-rho010-r4-003-vg5zs.18d466b93149a9e9,reason=Created count=1 msg=Created container: task
0.3295,Event,ADDED,eval-conflicts-rho010-r4-003-vg5zs.18d466b93361d8c6,reason=Started count=1 msg=Started container task
0.3296,Event,ADDED,eval-conflicts-rho010-r4-003.18d466b91572320b,reason=SuccessfulCreate count=1 msg=Created pod: eval-conflicts-rho010-r4-003-vg5zs
0.3298,Event,ADDED,eval-conflicts-rho010-r4-003.18d466bc62eb864c,reason=Completed count=1 msg=Job completed
0.3299,Event,ADDED,eval-conflicts-rho010-r4-004-xrs9h.18d466b951d5fe99,reason=Scheduled count=None msg=Successfully assigned compute/eval-conflicts-rho010-r4-004-xrs9h to kind-worker5
0.3301,Event,ADDED,eval-conflicts-rho010-r4-004-xrs9h.18d466b96a442579,"reason=Pulled count=1 msg=Container image ""busybox:musl"" already present on machine"
0.3303,Event,ADDED,eval-conflicts-rho010-r4-004-xrs9h.18d466b96b4bda73,reason=Created count=1 msg=Created container: task
0.3304,Event,ADDED,eval-conflicts-rho010-r4-004-xrs9h.18d466b96ec6c7f1,reason=Started count=1 msg=Started container task
0.3306,Event,ADDED,eval-conflicts-rho010-r4-004.18d466b95121503e,reason=SuccessfulCreate count=1 msg=Created pod: eval-conflicts-rho010-r4-004-xrs9h
0.3308,Event,ADDED,eval-conflicts-rho010-r4-004.18d466bc9ea2ba19,reason=Completed count=1 msg=Job completed
0.3309,Event,ADDED,eval-conflicts-rho010-r4-005-wvlxt.18d466b98dbf0df0,reason=Scheduled count=None msg=Successfully assigned compute/eval-conflicts-rho010-r4-005-wvlxt to kind-worker5
0.3311,Event,ADDED,eval-conflicts-rho010-r4-005-wvlxt.18d466b9a603d0bf,"reason=Pulled count=1 msg=Container image ""busybox:musl"" already present on machine"
0.3313,Event,ADDED,eval-conflicts-rho010-r4-005-wvlxt.18d466b9a70f9707,reason=Created count=1 msg=Created container: task
0.3314,Event,ADDED,eval-conflicts-rho010-r4-005-wvlxt.18d466b9a92318e6,reason=Started count=1 msg=Started container task
0.3316,Event,ADDED,eval-conflicts-rho010-r4-005.18d466b98cfcfbe4,reason=SuccessfulCreate count=1 msg=Created pod: eval-conflicts-rho010-r4-005-wvlxt
0.3318,Event,ADDED,eval-conflicts-rho010-r4-005.18d466bcda78670b,reason=Completed count=1 msg=Job completed
0.332,Event,ADDED,eval-conflicts-rho010-r4-006-sdjdk.18d466b9c88ca5a0,reason=Scheduled count=None msg=Successfully assigned compute/eval-conflicts-rho010-r4-006-sdjdk to kind-worker4
0.3322,Event,ADDED,eval-conflicts-rho010-r4-006-sdjdk.18d466b9e23e8b66,"reason=Pulled count=1 msg=Container image ""busybox:musl"" already present on machine"
0.3324,Event,ADDED,eval-conflicts-rho010-r4-006-sdjdk.18d466b9e3c20c33,reason=Created count=1 msg=Created container: task
0.3326,Event,ADDED,eval-conflicts-rho010-r4-006-sdjdk.18d466b9e5c787c5,reason=Started count=1 msg=Started container task
0.3328,Event,ADDED,eval-conflicts-rho010-r4-006.18d466b9c7f1776a,reason=SuccessfulCreate count=1 msg=Created pod: eval-conflicts-rho010-r4-006-sdjdk
0.3329,Event,ADDED,eval-conflicts-rho010-r4-006.18d466bd22a3c231,reason=Completed count=1 msg=Job completed
0.3331,Event,ADDED,eval-conflicts-rho010-r4-007-ndf8w.18d466ba045eb897,reason=Scheduled count=None msg=Successfully assigned compute/eval-conflicts-rho010-r4-007-ndf8w to kind-worker4
0.3333,Event,ADDED,eval-conflicts-rho010-r4-007-ndf8w.18d466ba1df65adb,"reason=Pulled count=1 msg=Container image ""busybox:musl"" already present on machine"
0.3334,Event,ADDED,eval-conflicts-rho010-r4-007-ndf8w.18d466ba1f1bf409,reason=Created count=1 msg=Created container: task
0.3336,Event,ADDED,eval-conflicts-rho010-r4-007-ndf8w.18d466ba214734b1,reason=Started count=1 msg=Started container task
0.3338,Event,ADDED,eval-conflicts-rho010-r4-007.18d466ba038c2a1e,reason=SuccessfulCreate count=1 msg=Created pod: eval-conflicts-rho010-r4-007-ndf8w
0.3339,Event,ADDED,eval-conflicts-rho010-r4-007.18d466bd5ea1dc8b,reason=Completed count=1 msg=Job completed
0.3341,Event,ADDED,eval-conflicts-rho010-r4-008-h9bnn.18d466ba3fa5bd81,reason=Scheduled count=None msg=Successfully assigned compute/eval-conflicts-rho010-r4-008-h9bnn to kind-worker3
0.3342,Event,ADDED,eval-conflicts-rho010-r4-008-h9bnn.18d466ba58e2a1c0,"reason=Pulled count=1 msg=Container image ""busybox:musl"" already present on machine"
0.3344,Event,ADDED,eval-conflicts-rho010-r4-008-h9bnn.18d466ba5a15b4db,reason=Created count=1 msg=Created container: task
0.3346,Event,ADDED,eval-conflicts-rho010-r4-008-h9bnn.18d466ba5dc3145b,reason=Started count=1 msg=Started container task
0.3347,Event,ADDED,eval-conflicts-rho010-r4-008.18d466ba3f024a81,reason=SuccessfulCreate count=1 msg=Created pod: eval-conflicts-rho010-r4-008-h9bnn
0.3349,Event,ADDED,eval-conflicts-rho010-r4-008.18d466bd7f865ca9,reason=Completed count=1 msg=Job completed
0.335,Event,ADDED,eval-conflicts-rho010-r4-009-rsgsr.18d466ba7b8baa45,reason=Scheduled count=None msg=Successfully assigned compute/eval-conflicts-rho010-r4-009-rsgsr to kind-worker4
0.3353,Event,ADDED,eval-conflicts-rho010-r4-009-rsgsr.18d466ba94598788,"reason=Pulled count=1 msg=Container image ""busybox:musl"" already present on machine"
0.3354,Event,ADDED,eval-conflicts-rho010-r4-009-rsgsr.18d466ba9575f120,reason=Created count=1 msg=Created container: task
0.3359,Event,ADDED,eval-conflicts-rho010-r4-009-rsgsr.18d466ba97f3ae52,reason=Started count=1 msg=Started container task
0.3361,Event,ADDED,eval-conflicts-rho010-r4-009.18d466ba7a95b91f,reason=SuccessfulCreate count=1 msg=Created pod: eval-conflicts-rho010-r4-009-rsgsr
0.3364,Event,ADDED,eval-conflicts-rho010-r4-009.18d466bdd5e49c07,reason=Completed count=1 msg=Job completed
0.3367,Event,ADDED,eval-conflicts-rho010-r4-010-k9tnq.18d466bab6eb6370,reason=Scheduled count=None msg=Successfully assigned compute/eval-conflicts-rho010-r4-010-k9tnq to kind-worker3
0.3373,Event,ADDED,eval-conflicts-rho010-r4-010-k9tnq.18d466bacfc898db,"reason=Pulled count=1 msg=Container image ""busybox:musl"" already present on machine"
0.3375,Event,ADDED,eval-conflicts-rho010-r4-010-k9tnq.18d466bad0e68a12,reason=Created count=1 msg=Created container: task
0.3377,Event,ADDED,eval-conflicts-rho010-r4-010-k9tnq.18d466bad36f65cd,reason=Started count=1 msg=Started container task
0.338,Event,ADDED,eval-conflicts-rho010-r4-010.18d466bab640de8e,reason=SuccessfulCreate count=1 msg=Created pod: eval-conflicts-rho010-r4-010-k9tnq
0.3382,Event,ADDED,eval-conflicts-rho010-r4-010.18d466bdf77f4cbc,reason=Completed count=1 msg=Job completed
0.3384,Event,ADDED,eval-conflicts-rho010-r4-011-55cqs.18d466baf37e4e13,reason=Scheduled count=None msg=Successfully assigned compute/eval-conflicts-rho010-r4-011-55cqs to kind-worker4
0.3385,Event,ADDED,eval-conflicts-rho010-r4-011-55cqs.18d466bb0c80b97e,"reason=Pulled count=1 msg=Container image ""busybox:musl"" already present on machine"
0.3389,Event,ADDED,eval-conflicts-rho010-r4-011-55cqs.18d466bb0d9978d2,reason=Created count=1 msg=Created container: task
0.339,Event,ADDED,eval-conflicts-rho010-r4-011-55cqs.18d466bb0fdaaeaf,reason=Started count=1 msg=Started container task
0.3392,Event,ADDED,eval-conflicts-rho010-r4-011.18d466baf28bfc87,reason=SuccessfulCreate count=1 msg=Created pod: eval-conflicts-rho010-r4-011-55cqs
0.3395,Event,ADDED,eval-conflicts-rho010-r4-011.18d466be4dfa1bb7,reason=Completed count=1 msg=Job completed
0.3397,Event,ADDED,eval-conflicts-rho010-r4-012-gbm46.18d466bb2e5b5912,reason=Scheduled count=None msg=Successfully assigned compute/eval-conflicts-rho010-r4-012-gbm46 to kind-worker4
0.3398,Event,ADDED,eval-conflicts-rho010-r4-012-gbm46.18d466bb472c419f,"reason=Pulled count=1 msg=Container image ""busybox:musl"" already present on machine"
0.34,Event,ADDED,eval-conflicts-rho010-r4-012-gbm46.18d466bb484c1ca0,reason=Created count=1 msg=Created container: task
0.3402,Event,ADDED,eval-conflicts-rho010-r4-012-gbm46.18d466bb4a46853d,reason=Started count=1 msg=Started container task
0.3404,Event,ADDED,eval-conflicts-rho010-r4-012.18d466bb2d7acc2a,reason=SuccessfulCreate count=1 msg=Created pod: eval-conflicts-rho010-r4-012-gbm46
0.3405,Event,ADDED,eval-conflicts-rho010-r4-012.18d466be89cabc72,reason=Completed count=1 msg=Job completed
0.3407,Event,ADDED,eval-conflicts-rho010-r4-013-nhzjr.18d466bb6ae1d17d,reason=Scheduled count=None msg=Successfully assigned compute/eval-conflicts-rho010-r4-013-nhzjr to kind-worker4
0.3409,Event,ADDED,eval-conflicts-rho010-r4-013-nhzjr.18d466bb866a9457,"reason=Pulled count=1 msg=Container image ""busybox:musl"" already present on machine"
0.341,Event,ADDED,eval-conflicts-rho010-r4-013-nhzjr.18d466bb87b1af2f,reason=Created count=1 msg=Created container: task
0.3412,Event,ADDED,eval-conflicts-rho010-r4-013-nhzjr.18d466bb8efd06a6,reason=Started count=1 msg=Started container task
0.3414,Event,ADDED,eval-conflicts-rho010-r4-013.18d466bb6a2e9a4f,reason=SuccessfulCreate count=1 msg=Created pod: eval-conflicts-rho010-r4-013-nhzjr
0.3415,Event,ADDED,eval-conflicts-rho010-r4-013.18d466bec5da8219,reason=Completed count=1 msg=Job completed
0.3417,Event,ADDED,eval-conflicts-rho010-r4-014-cmgz9.18d466bba530ab26,reason=Scheduled count=None msg=Successfully assigned compute/eval-conflicts-rho010-r4-014-cmgz9 to kind-worker2
0.3418,Event,ADDED,eval-conflicts-rho010-r4-014-cmgz9.18d466bbc30994a6,"reason=Pulled count=1 msg=Container image ""busybox:musl"" already present on machine"
0.342,Event,ADDED,eval-conflicts-rho010-r4-014-cmgz9.18d466bbc49649ec,reason=Created count=1 msg=Created container: task
0.3422,Event,ADDED,eval-conflicts-rho010-r4-014-cmgz9.18d466bbc9e59992,reason=Started count=1 msg=Started container task
0.3423,Event,ADDED,eval-conflicts-rho010-r4-014.18d466bba4c06ea5,reason=SuccessfulCreate count=1 msg=Created pod: eval-conflicts-rho010-r4-014-cmgz9
0.3425,Event,ADDED,eval-conflicts-rho010-r4-014.18d466bef7d12640,reason=Completed count=1 msg=Job completed
0.3426,Event,ADDED,eval-conflicts-rho010-r4-015-nbj5d.18d466bbe25f121c,reason=Scheduled count=None msg=Successfully assigned compute/eval-conflicts-rho010-r4-015-nbj5d to kind-worker2
0.3428,Event,ADDED,eval-conflicts-rho010-r4-015-nbj5d.18d466bbfb241dc5,"reason=Pulled count=1 msg=Container image ""busybox:musl"" already present on machine"
0.343,Event,ADDED,eval-conflicts-rho010-r4-015-nbj5d.18d466bbfc33f643,reason=Created count=1 msg=Created container: task
0.3431,Event,ADDED,eval-conflicts-rho010-r4-015-nbj5d.18d466bbfe8f680e,reason=Started count=1 msg=Started container task
0.3433,Event,ADDED,eval-conflicts-rho010-r4-015.18d466bbe196e194,reason=SuccessfulCreate count=1 msg=Created pod: eval-conflicts-rho010-r4-015-nbj5d
0.3435,Event,ADDED,eval-conflicts-rho010-r4-015.18d466bf33d51260,reason=Completed count=1 msg=Job completed
0.3436,Event,ADDED,eval-conflicts-rho010-r4-016-59wmd.18d466bc1c539177,reason=Scheduled count=None msg=Successfully assigned compute/eval-conflicts-rho010-r4-016-59wmd to kind-worker2
0.3438,Event,ADDED,eval-conflicts-rho010-r4-016-59wmd.18d466bc35e5b09b,"reason=Pulled count=1 msg=Container image ""busybox:musl"" already present on machine"
0.344,Event,ADDED,eval-conflicts-rho010-r4-016-59wmd.18d466bc370c1de6,reason=Created count=1 msg=Created container: task
0.3441,Event,ADDED,eval-conflicts-rho010-r4-016-59wmd.18d466bc3a80ec39,reason=Started count=1 msg=Started container task
0.3443,Event,ADDED,eval-conflicts-rho010-r4-016.18d466bc1bd7dfc0,reason=SuccessfulCreate count=1 msg=Created pod: eval-conflicts-rho010-r4-016-59wmd
0.3445,Event,ADDED,eval-conflicts-rho010-r4-016.18d466bf6fe68046,reason=Completed count=1 msg=Job completed
0.3446,Event,ADDED,eval-conflicts-rho010-r4-017-zsvqq.18d466bc582acdc7,reason=Scheduled count=None msg=Successfully assigned compute/eval-conflicts-rho010-r4-017-zsvqq to kind-worker2
0.3448,Event,ADDED,eval-conflicts-rho010-r4-017-zsvqq.18d466bc713b2501,"reason=Pulled count=1 msg=Container image ""busybox:musl"" already present on machine"
0.349,Event,ADDED,eval-conflicts-rho010-r4-017-zsvqq.18d466bc7255a45b,reason=Created count=1 msg=Created container: task
0.3492,Event,ADDED,eval-conflicts-rho010-r4-017-zsvqq.18d466bc747e0a9e,reason=Started count=1 msg=Started container task
0.3494,Event,ADDED,eval-conflicts-rho010-r4-017.18d466bc579d59e9,reason=SuccessfulCreate count=1 msg=Created pod: eval-conflicts-rho010-r4-017-zsvqq
0.3495,Event,ADDED,eval-conflicts-rho010-r4-017.18d466bf704d151b,reason=Completed count=1 msg=Job completed
0.3497,Event,ADDED,eval-conflicts-rho010-r4-018-dv4cp.18d466bc93e2364c,reason=Scheduled count=None msg=Successfully assigned compute/eval-conflicts-rho010-r4-018-dv4cp to kind-worker2
0.3499,Event,ADDED,eval-conflicts-rho010-r4-018-dv4cp.18d466bcacf1fe30,"reason=Pulled count=1 msg=Container image ""busybox:musl"" already present on machine"
0.35,Event,ADDED,eval-conflicts-rho010-r4-018-dv4cp.18d466bcae2ea383,reason=Created count=1 msg=Created container: task
0.3504,Event,ADDED,eval-conflicts-rho010-r4-018-dv4cp.18d466bcb027f5ee,reason=Started count=1 msg=Started container task
0.3505,Event,ADDED,eval-conflicts-rho010-r4-018.18d466bc935b3ac5,reason=SuccessfulCreate count=1 msg=Created pod: eval-conflicts-rho010-r4-018-dv4cp
0.3507,Event,ADDED,eval-conflicts-rho010-r4-018.18d466bfe88780b9,reason=Completed count=1 msg=Job completed
0.3509,Event,ADDED,eval-conflicts-rho010-r4-019-pzxrw.18d466bccf0fa09b,reason=Scheduled count=None msg=Successfully assigned compute/eval-conflicts-rho010-r4-019-pzxrw to kind-worker2
0.3514,Event,ADDED,eval-conflicts-rho010-r4-019-pzxrw.18d466bceea0dde0,"reason=Pulled count=1 msg=Container image ""busybox:musl"" already present on machine"
0.3515,Event,ADDED,eval-conflicts-rho010-r4-019-pzxrw.18d466bcefc6c540,reason=Created count=1 msg=Created container: task
0.3517,Event,ADDED,eval-conflicts-rho010-r4-019-pzxrw.18d466bcf38d013c,reason=Started count=1 msg=Started container task
0.352,Event,ADDED,eval-conflicts-rho010-r4-019.18d466bcce9e435a,reason=SuccessfulCreate count=1 msg=Created pod: eval-conflicts-rho010-r4-019-pzxrw
0.3521,Event,ADDED,eval-conflicts-rho010-r4-019.18d466c02499680a,reason=Completed count=1 msg=Job completed
0.3523,Event,ADDED,eval-conflicts-rho010-r4-020-sb77t.18d466bd0ac7c7a0,reason=Scheduled count=None msg=Successfully assigned compute/eval-conflicts-rho010-r4-020-sb77t to kind-worker2
0.3525,Event,ADDED,eval-conflicts-rho010-r4-020-sb77t.18d466bd2589444d,"reason=Pulled count=1 msg=Container image ""busybox:musl"" already present on machine"
0.3527,Event,ADDED,eval-conflicts-rho010-r4-020-sb77t.18d466bd2700a086,reason=Created count=1 msg=Created container: task
0.3528,Event,ADDED,eval-conflicts-rho010-r4-020-sb77t.18d466bd2fe72c33,reason=Started count=1 msg=Started container task
0.353,Event,ADDED,eval-conflicts-rho010-r4-020.18d466bd0a1c1d8c,reason=SuccessfulCreate count=1 msg=Created pod: eval-conflicts-rho010-r4-020-sb77t
0.3532,Event,ADDED,eval-conflicts-rho010-r4-020.18d466c0603b7e98,reason=Completed count=1 msg=Job completed
0.3533,Event,ADDED,eval-conflicts-rho010-r4-021-xqpsn.18d466bd463a761e,"reason=FailedScheduling count=None msg=0/6 nodes are available: 1 c_wall violated: 1 conflicting context pair(s) with node memory, 5 node(s) had untolerated taint(s). no new claims to deallocate, preemption: 0/6 nodes are available: 1 No preemption victims found for incoming pod, 5 Preemption is not helpful for scheduling."
0.3536,Event,ADDED,eval-conflicts-rho010-r4-021-xqpsn.18d466bd46d8ddcc,"reason=FailedScheduling count=None msg=0/6 nodes are available: 1 c_wall violated: 1 conflicting context pair(s) with node memory, 5 node(s) had untolerated taint(s). no new claims to deallocate, preemption: 0/6 nodes are available: 1 No preemption victims found for incoming pod, 5 Preemption is not helpful for scheduling."
0.3538,Event,ADDED,eval-conflicts-rho010-r4-021-xqpsn.18d466bd7a4ddb16,reason=Scheduled count=None msg=Successfully assigned compute/eval-conflicts-rho010-r4-021-xqpsn to kind-worker
0.354,Event,ADDED,eval-conflicts-rho010-r4-021-xqpsn.18d466bd9309a4af,"reason=Pulled count=1 msg=Container image ""busybox:musl"" already present on machine"
0.3542,Event,ADDED,eval-conflicts-rho010-r4-021-xqpsn.18d466bd9414b2f5,reason=Created count=1 msg=Created container: task
0.3544,Event,ADDED,eval-conflicts-rho010-r4-021-xqpsn.18d466bd95e5a67e,reason=Started count=1 msg=Started container task
0.3545,Event,ADDED,eval-conflicts-rho010-r4-021.18d466bd45f8dc9b,reason=SuccessfulCreate count=1 msg=Created pod: eval-conflicts-rho010-r4-021-xqpsn
0.3547,Event,ADDED,eval-conflicts-rho010-r4-021.18d466c08c36b388,reason=Completed count=1 msg=Job completed
0.3549,Event,ADDED,eval-conflicts-rho010-r4-022-clmdt.18d466bd82ee6d3e,reason=Scheduled count=None msg=Successfully assigned compute/eval-conflicts-rho010-r4-022-clmdt to kind-worker
0.355,Event,ADDED,eval-conflicts-rho010-r4-022-clmdt.18d466bd9c49f7cf,"reason=Pulled count=1 msg=Container image ""busybox:musl"" already present on machine"
0.3552,Event,ADDED,eval-conflicts-rho010-r4-022-clmdt.18d466bd9d68b6c4,reason=Created count=1 msg=Created container: task
0.3554,Event,ADDED,eval-conflicts-rho010-r4-022-clmdt.18d466bda0a35bcf,reason=Started count=1 msg=Started container task
0.3555,Event,ADDED,eval-conflicts-rho010-r4-022.18d466bd821fe92e,reason=SuccessfulCreate count=1 msg=Created pod: eval-conflicts-rho010-r4-022-clmdt
0.3557,Event,ADDED,eval-conflicts-rho010-r4-022.18d466c08c546332,reason=Completed count=1 msg=Job completed
0.3559,Event,ADDED,eval-conflicts-rho010-r4-023-zr2zf.18d466bdbe3d09eb,reason=Scheduled count=None msg=Successfully assigned compute/eval-conflicts-rho010-r4-023-zr2zf to kind-worker
0.356,Event,ADDED,eval-conflicts-rho010-r4-023-zr2zf.18d466bdd79f413a,"reason=Pulled count=1 msg=Container image ""busybox:musl"" already present on machine"
0.3562,Event,ADDED,eval-conflicts-rho010-r4-023-zr2zf.18d466bdd8b429cc,reason=Created count=1 msg=Created container: task
0.3564,Event,ADDED,eval-conflicts-rho010-r4-023-zr2zf.18d466bddbf70760,reason=Started count=1 msg=Started container task
0.3565,Event,ADDED,eval-conflicts-rho010-r4-023.18d466bdbcf6be43,reason=SuccessfulCreate count=1 msg=Created pod: eval-conflicts-rho010-r4-023-zr2zf
0.3567,Event,ADDED,eval-conflicts-rho010-r4-023.18d466c0c771acbc,reason=Completed count=1 msg=Job completed
0.3568,Event,ADDED,eval-conflicts-rho010-r4-024-ghmj9.18d466bdf91563f3,reason=Scheduled count=None msg=Successfully assigned compute/eval-conflicts-rho010-r4-024-ghmj9 to kind-worker3
0.3571,Event,ADDED,eval-conflicts-rho010-r4-024-ghmj9.18d466be135a6d49,"reason=Pulled count=1 msg=Container image ""busybox:musl"" already present on machine"
0.3572,Event,ADDED,eval-conflicts-rho010-r4-024-ghmj9.18d466be14640a59,reason=Created count=1 msg=Created container: task
0.3574,Event,ADDED,eval-conflicts-rho010-r4-024-ghmj9.18d466be1bafebed,reason=Started count=1 msg=Started container task
0.3576,Event,ADDED,eval-conflicts-rho010-r4-024.18d466bdf896f1f5,reason=SuccessfulCreate count=1 msg=Created pod: eval-conflicts-rho010-r4-024-ghmj9
0.3578,Event,ADDED,eval-conflicts-rho010-r4-024.18d466c100255b2f,reason=Completed count=1 msg=Job completed
0.3579,Event,ADDED,eval-conflicts-rho010-r4-025-gcbdp.18d466be34f264d7,reason=Scheduled count=None msg=Successfully assigned compute/eval-conflicts-rho010-r4-025-gcbdp to kind-worker
0.3581,Event,ADDED,eval-conflicts-rho010-r4-025-gcbdp.18d466be4f32cf63,"reason=Pulled count=1 msg=Container image ""busybox:musl"" already present on machine"
0.3583,Event,ADDED,eval-conflicts-rho010-r4-025-gcbdp.18d466be505eb6ac,reason=Created count=1 msg=Created container: task
0.3584,Event,ADDED,eval-conflicts-rho010-r4-025-gcbdp.18d466be5390bc36,reason=Started count=1 msg=Started container task
0.3586,Event,ADDED,eval-conflicts-rho010-r4-025.18d466be341c8e38,reason=SuccessfulCreate count=1 msg=Created pod: eval-conflicts-rho010-r4-025-gcbdp
0.3588,Event,ADDED,eval-conflicts-rho010-r4-025.18d466c17a7d0176,reason=Completed count=1 msg=Job completed
0.3589,Event,ADDED,eval-conflicts-rho010-r4-026-dq6n6.18d466be711559b5,reason=Scheduled count=None msg=Successfully assigned compute/eval-conflicts-rho010-r4-026-dq6n6 to kind-worker5
0.3591,Event,ADDED,eval-conflicts-rho010-r4-026-dq6n6.18d466be8d7745cd,"reason=Pulled count=1 msg=Container image ""busybox:musl"" already present on machine"
0.3593,Event,ADDED,eval-conflicts-rho010-r4-026-dq6n6.18d466be8e8983c0,reason=Created count=1 msg=Created container: task
0.3595,Event,ADDED,eval-conflicts-rho010-r4-026-dq6n6.18d466be94ba5186,reason=Started count=1 msg=Started container task
0.3597,Event,ADDED,eval-conflicts-rho010-r4-026.18d466be70280f7c,reason=SuccessfulCreate count=1 msg=Created pod: eval-conflicts-rho010-r4-026-dq6n6
0.3598,Event,ADDED,eval-conflicts-rho010-r4-026.18d466c1c988a7b8,reason=Completed count=1 msg=Job completed
0.36,Event,ADDED,eval-conflicts-rho010-r4-027-wtwr4.18d466beacc7ba5e,reason=Scheduled count=None msg=Successfully assigned compute/eval-conflicts-rho010-r4-027-wtwr4 to kind-worker5
0.3601,Event,ADDED,eval-conflicts-rho010-r4-027-wtwr4.18d466bec585f8fe,"reason=Pulled count=1 msg=Container image ""busybox:musl"" already present on machine"
0.3603,Event,ADDED,eval-conflicts-rho010-r4-027-wtwr4.18d466bec6bbf710,reason=Created count=1 msg=Created container: task
0.3605,Event,ADDED,eval-conflicts-rho010-r4-027-wtwr4.18d466beca9d49a3,reason=Started count=1 msg=Started container task
0.3606,Event,ADDED,eval-conflicts-rho010-r4-027.18d466beab858c72,reason=SuccessfulCreate count=1 msg=Created pod: eval-conflicts-rho010-r4-027-wtwr4
0.3608,Event,ADDED,eval-conflicts-rho010-r4-027.18d466c206a4b067,reason=Completed count=1 msg=Job completed
0.3609,Event,ADDED,eval-conflicts-rho010-r4-028-48hk2.18d466bee82cd8f0,reason=Scheduled count=None msg=Successfully assigned compute/eval-conflicts-rho010-r4-028-48hk2 to kind-worker5
0.3611,Event,ADDED,eval-conflicts-rho010-r4-028-48hk2.18d466bf019ab282,"reason=Pulled count=1 msg=Container image ""busybox:musl"" already present on machine"
0.3617,Event,ADDED,eval-conflicts-rho010-r4-028-48hk2.18d466bf02b07f73,reason=Created count=1 msg=Created container: task
0.3618,Event,ADDED,eval-conflicts-rho010-r4-028-48hk2.18d466bf070ba4aa,reason=Started count=1 msg=Started container task
0.362,Event,ADDED,eval-conflicts-rho010-r4-028.18d466bee7051e29,reason=SuccessfulCreate count=1 msg=Created pod: eval-conflicts-rho010-r4-028-48hk2
0.3622,Event,ADDED,eval-conflicts-rho010-r4-028.18d466c23b340ba7,reason=Completed count=1 msg=Job completed
0.3623,Event,ADDED,eval-conflicts-rho010-r4-029-swghr.18d466bf247e6cdd,reason=Scheduled count=None msg=Successfully assigned compute/eval-conflicts-rho010-r4-029-swghr to kind-worker5
0.3625,Event,ADDED,eval-conflicts-rho010-r4-029-swghr.18d466bf3eb95112,"reason=Pulled count=1 msg=Container image ""busybox:musl"" already present on machine"
0.3626,Event,ADDED,eval-conflicts-rho010-r4-029-swghr.18d466bf3fcc53fb,reason=Created count=1 msg=Created container: task
0.3628,Event,ADDED,eval-conflicts-rho010-r4-029-swghr.18d466bf41eb46f3,reason=Started count=1 msg=Started container task
0.363,Event,ADDED,eval-conflicts-rho010-r4-029.18d466bf23454dae,reason=SuccessfulCreate count=1 msg=Created pod: eval-conflicts-rho010-r4-029-swghr
0.3631,Event,ADDED,eval-conflicts-rho010-r4-029.18d466c2789414e2,reason=Completed count=1 msg=Job completed
0.3633,Event,ADDED,eval-conflicts-rho010-r4-030-498hd.18d466bf5f7b0c19,reason=Scheduled count=None msg=Successfully assigned compute/eval-conflicts-rho010-r4-030-498hd to kind-worker
0.3638,Event,ADDED,eval-conflicts-rho010-r4-030-498hd.18d466bf787f34c2,"reason=Pulled count=1 msg=Container image ""busybox:musl"" already present on machine"
0.364,Event,ADDED,eval-conflicts-rho010-r4-030-498hd.18d466bf7991d1f5,reason=Created count=1 msg=Created container: task
0.3642,Event,ADDED,eval-conflicts-rho010-r4-030-498hd.18d466bf7c61182e,reason=Started count=1 msg=Started container task
0.3643,Event,ADDED,eval-conflicts-rho010-r4-030.18d466bf5e5a5327,reason=SuccessfulCreate count=1 msg=Created pod: eval-conflicts-rho010-r4-030-498hd
0.3646,Event,ADDED,eval-conflicts-rho010-r4-030.18d466c2aa6ad5d1,reason=Completed count=1 msg=Job completed
0.3647,Event,ADDED,eval-conflicts-rho010-r4-031-knxj7.18d466bf9c6c398d,reason=Scheduled count=None msg=Successfully assigned compute/eval-conflicts-rho010-r4-031-knxj7 to kind-worker5
0.3649,Event,ADDED,eval-conflicts-rho010-r4-031-knxj7.18d466bfb65eba9f,"reason=Pulled count=1 msg=Container image ""busybox:musl"" already present on machine"
0.3651,Event,ADDED,eval-conflicts-rho010-r4-031-knxj7.18d466bfb77b4148,reason=Created count=1 msg=Created container: task
0.3652,Event,ADDED,eval-conflicts-rho010-r4-031-knxj7.18d466bfba777af0,reason=Started count=1 msg=Started container task
0.3654,Event,ADDED,eval-conflicts-rho010-r4-031.18d466bf9b3a1e96,reason=SuccessfulCreate count=1 msg=Created pod: eval-conflicts-rho010-r4-031-knxj7
0.3656,Event,ADDED,eval-conflicts-rho010-r4-031.18d466c2f09d011b,reason=Completed count=1 msg=Job completed
0.3657,Event,ADDED,eval-conflicts-rho010-r4-032-wrfgl.18d466bfd62366df,reason=Scheduled count=None msg=Successfully assigned compute/eval-conflicts-rho010-r4-032-wrfgl to kind-worker3
0.3659,Event,ADDED,eval-conflicts-rho010-r4-032-wrfgl.18d466bff01a6e23,"reason=Pulled count=1 msg=Container image ""busybox:musl"" already present on machine"
0.3661,Event,ADDED,eval-conflicts-rho010-r4-032-wrfgl.18d466bff1335730,reason=Created count=1 msg=Created container: task
0.3662,Event,ADDED,eval-conflicts-rho010-r4-032-wrfgl.18d466bff3299820,reason=Started count=1 msg=Started container task
0.3664,Event,ADDED,eval-conflicts-rho010-r4-032.18d466bfd555d179,reason=SuccessfulCreate count=1 msg=Created pod: eval-conflicts-rho010-r4-032-wrfgl
0.3666,Event,ADDED,eval-conflicts-rho010-r4-032.18d466c31988be66,reason=Completed count=1 msg=Job completed
0.3667,Event,ADDED,eval-conflicts-rho010-r4-033-nss6m.18d466c0121ca05b,reason=Scheduled count=None msg=Successfully assigned compute/eval-conflicts-rho010-r4-033-nss6m to kind-worker5
0.3669,Event,ADDED,eval-conflicts-rho010-r4-033-nss6m.18d466c02a81757c,"reason=Pulled count=1 msg=Container image ""busybox:musl"" already present on machine"
0.3671,Event,ADDED,eval-conflicts-rho010-r4-033-nss6m.18d466c02b8c8ac4,reason=Created count=1 msg=Created container: task
0.3672,Event,ADDED,eval-conflicts-rho010-r4-033-nss6m.18d466c02d893311,reason=Started count=1 msg=Started container task
0.3674,Event,ADDED,eval-conflicts-rho010-r4-033.18d466c0111ed070,reason=SuccessfulCreate count=1 msg=Created pod: eval-conflicts-rho010-r4-033-nss6m
0.3676,Event,ADDED,eval-conflicts-rho010-r4-033.18d466c366e40510,reason=Completed count=1 msg=Job completed
0.3677,Event,ADDED,eval-conflicts-rho010-r4-034-8cqls.18d466c04d6221ea,reason=Scheduled count=None msg=Successfully assigned compute/eval-conflicts-rho010-r4-034-8cqls to kind-worker4
0.3679,Event,ADDED,eval-conflicts-rho010-r4-034-8cqls.18d466c065ef085d,"reason=Pulled count=1 msg=Container image ""busybox:musl"" already present on machine"
0.368,Event,ADDED,eval-conflicts-rho010-r4-034-8cqls.18d466c06742bc0b,reason=Created count=1 msg=Created container: task
0.3682,Event,ADDED,eval-conflicts-rho010-r4-034-8cqls.18d466c0697cf84a,reason=Started count=1 msg=Started container task
0.3684,Event,ADDED,eval-conflicts-rho010-r4-034.18d466c04ca05e23,reason=SuccessfulCreate count=1 msg=Created pod: eval-conflicts-rho010-r4-034-8cqls
0.3685,Event,ADDED,eval-conflicts-rho010-r4-034.18d466c3b2c79dd0,reason=Completed count=1 msg=Job completed
0.3687,Event,ADDED,eval-conflicts-rho010-r4-035-sh9vm.18d466c089aa7edd,reason=Scheduled count=None msg=Successfully assigned compute/eval-conflicts-rho010-r4-035-sh9vm to kind-worker2
0.3689,Event,ADDED,eval-conflicts-rho010-r4-035-sh9vm.18d466c0a1eeafdf,"reason=Pulled count=1 msg=Container image ""busybox:musl"" already present on machine"
0.369,Event,ADDED,eval-conflicts-rho010-r4-035-sh9vm.18d466c0a31d43b8,reason=Created count=1 msg=Created container: task
0.3693,Event,ADDED,eval-conflicts-rho010-r4-035-sh9vm.18d466c0a6f4b752,reason=Started count=1 msg=Started container task
0.3694,Event,ADDED,eval-conflicts-rho010-r4-035.18d466c088b9f078,reason=SuccessfulCreate count=1 msg=Created pod: eval-conflicts-rho010-r4-035-sh9vm
0.3696,Event,ADDED,eval-conflicts-rho010-r4-035.18d466c3e4b4aba1,reason=Completed count=1 msg=Job completed
0.3697,Event,ADDED,eval-conflicts-rho010-r4-036-fc292.18d466c0c5830935,reason=Scheduled count=None msg=Successfully assigned compute/eval-conflicts-rho010-r4-036-fc292 to kind-worker2
0.3699,Event,ADDED,eval-conflicts-rho010-r4-036-fc292.18d466c0df37bdb3,"reason=Pulled count=1 msg=Container image ""busybox:musl"" already present on machine"
0.3701,Event,ADDED,eval-conflicts-rho010-r4-036-fc292.18d466c0e04690a9,reason=Created count=1 msg=Created container: task
0.3702,Event,ADDED,eval-conflicts-rho010-r4-036-fc292.18d466c0e41554b0,reason=Started count=1 msg=Started container task
0.3704,Event,ADDED,eval-conflicts-rho010-r4-036.18d466c0c4c04516,reason=SuccessfulCreate count=1 msg=Created pod: eval-conflicts-rho010-r4-036-fc292
0.3706,Event,ADDED,eval-conflicts-rho010-r4-036.18d466c424976ed6,reason=Completed count=1 msg=Job completed
0.3707,Event,ADDED,eval-conflicts-rho010-r4-037-5tgss.18d466c100ccacc6,reason=Scheduled count=None msg=Successfully assigned compute/eval-conflicts-rho010-r4-037-5tgss to kind-worker2
0.3709,Event,ADDED,eval-conflicts-rho010-r4-037-5tgss.18d466c119a64316,"reason=Pulled count=1 msg=Container image ""busybox:musl"" already present on machine"
0.371,Event,ADDED,eval-conflicts-rho010-r4-037-5tgss.18d466c11ac11650,reason=Created count=1 msg=Created container: task
0.3712,Event,ADDED,eval-conflicts-rho010-r4-037-5tgss.18d466c11cda16ca,reason=Started count=1 msg=Started container task
0.3714,Event,ADDED,eval-conflicts-rho010-r4-037.18d466c0ff9e91d5,reason=SuccessfulCreate count=1 msg=Created pod: eval-conflicts-rho010-r4-037-5tgss
0.3715,Event,ADDED,eval-conflicts-rho010-r4-037.18d466c460c7ad4a,reason=Completed count=1 msg=Job completed
0.3722,Event,ADDED,eval-conflicts-rho010-r4-038-mms8t.18d466c13cdbd217,reason=Scheduled count=None msg=Successfully assigned compute/eval-conflicts-rho010-r4-038-mms8t to kind-worker2
0.3725,Event,ADDED,eval-conflicts-rho010-r4-038-mms8t.18d466c1574dcefc,"reason=Pulled count=1 msg=Container image ""busybox:musl"" already present on machine"
0.3728,Event,ADDED,eval-conflicts-rho010-r4-038-mms8t.18d466c15877a5f2,reason=Created count=1 msg=Created container: task
0.373,Event,ADDED,eval-conflicts-rho010-r4-038-mms8t.18d466c160abb1e5,reason=Started count=1 msg=Started container task
0.3734,Event,ADDED,eval-conflicts-rho010-r4-038.18d466c13c01f751,reason=SuccessfulCreate count=1 msg=Created pod: eval-conflicts-rho010-r4-038-mms8t
0.3735,Event,ADDED,eval-conflicts-rho010-r4-038.18d466c49c818823,reason=Completed count=1 msg=Job completed
0.3737,Event,ADDED,eval-conflicts-rho010-r4-039-7rl9l.18d466c178b876ab,reason=Scheduled count=None msg=Successfully assigned compute/eval-conflicts-rho010-r4-039-7rl9l to kind-worker4
0.3739,Event,ADDED,eval-conflicts-rho010-r4-039-7rl9l.18d466c193b825bc,"reason=Pulled count=1 msg=Container image ""busybox:musl"" already present on machine"
0.3742,Event,ADDED,eval-conflicts-rho010-r4-039-7rl9l.18d466c194c39f89,reason=Created count=1 msg=Created container: task
0.3744,Event,ADDED,eval-conflicts-rho010-r4-039-7rl9l.18d466c19b72ef09,reason=Started count=1 msg=Started container task
0.3746,Event,ADDED,eval-conflicts-rho010-r4-039.18d466c177c75251,reason=SuccessfulCreate count=1 msg=Created pod: eval-conflicts-rho010-r4-039-7rl9l
0.3748,Event,ADDED,eval-conflicts-rho010-r4-039.18d466c4da0234fd,reason=Completed count=1 msg=Job completed
0.3749,Event,ADDED,eval-conflicts-rho010-r4-040-bwzg4.18d466c1b31cee2c,reason=Scheduled count=None msg=Successfully assigned compute/eval-conflicts-rho010-r4-040-bwzg4 to kind-worker2
0.3751,Event,ADDED,eval-conflicts-rho010-r4-040-bwzg4.18d466c1d18791cf,"reason=Pulled count=1 msg=Container image ""busybox:musl"" already present on machine"
0.3753,Event,ADDED,eval-conflicts-rho010-r4-040-bwzg4.18d466c1d2b13d4a,reason=Created count=1 msg=Created container: task
0.3754,Event,ADDED,eval-conflicts-rho010-r4-040-bwzg4.18d466c1d9bd89d2,reason=Started count=1 msg=Started container task
0.3756,Event,ADDED,eval-conflicts-rho010-r4-040.18d466c1b2336f9b,reason=SuccessfulCreate count=1 msg=Created pod: eval-conflicts-rho010-r4-040-bwzg4
0.3758,Event,ADDED,eval-conflicts-rho010-r4-040.18d466c50c0e69a8,reason=Completed count=1 msg=Job completed
0.3759,Event,ADDED,eval-conflicts-rho010-r4-041-47gwj.18d466c1eef6f070,reason=Scheduled count=None msg=Successfully assigned compute/eval-conflicts-rho010-r4-041-47gwj to kind-worker4
0.3761,Event,ADDED,eval-conflicts-rho010-r4-041-47gwj.18d466c20cec58bb,"reason=Pulled count=1 msg=Container image ""busybox:musl"" already present on machine"
0.3763,Event,ADDED,eval-conflicts-rho010-r4-041-47gwj.18d466c20e06a6f2,reason=Created count=1 msg=Created container: task
0.3764,Event,ADDED,eval-conflicts-rho010-r4-041-47gwj.18d466c21580b084,reason=Started count=1 msg=Started container task
0.3766,Event,ADDED,eval-conflicts-rho010-r4-041.18d466c1ee07718b,reason=SuccessfulCreate count=1 msg=Created pod: eval-conflicts-rho010-r4-041-47gwj
0.3768,Event,ADDED,eval-conflicts-rho010-r4-041.18d466c557f64024,reason=Completed count=1 msg=Job completed
0.3769,Event,ADDED,eval-conflicts-rho010-r4-042-s5tzc.18d466c22a6d31f2,reason=Scheduled count=None msg=Successfully assigned compute/eval-conflicts-rho010-r4-042-s5tzc to kind-worker4
0.3771,Event,ADDED,eval-conflicts-rho010-r4-042-s5tzc.18d466c24886920b,"reason=Pulled count=1 msg=Container image ""busybox:musl"" already present on machine"
0.3772,Event,ADDED,eval-conflicts-rho010-r4-042-s5tzc.18d466c249bc9d8a,reason=Created count=1 msg=Created container: task
0.3774,Event,ADDED,eval-conflicts-rho010-r4-042-s5tzc.18d466c24caafa22,reason=Started count=1 msg=Started container task
0.3776,Event,ADDED,eval-conflicts-rho010-r4-042.18d466c2298d0307,reason=SuccessfulCreate count=1 msg=Created pod: eval-conflicts-rho010-r4-042-s5tzc
0.3777,Event,ADDED,eval-conflicts-rho010-r4-042.18d466c593eda8f6,reason=Completed count=1 msg=Job completed
0.3779,Event,ADDED,eval-conflicts-rho010-r4-043-f8trd.18d466c26647cc18,reason=Scheduled count=None msg=Successfully assigned compute/eval-conflicts-rho010-r4-043-f8trd to kind-worker2
0.378,Event,ADDED,eval-conflicts-rho010-r4-043-f8trd.18d466c282f74378,"reason=Pulled count=1 msg=Container image ""busybox:musl"" already present on machine"
0.3782,Event,ADDED,eval-conflicts-rho010-r4-043-f8trd.18d466c2842d92fb,reason=Created count=1 msg=Created container: task
0.3784,Event,ADDED,eval-conflicts-rho010-r4-043-f8trd.18d466c287b96f18,reason=Started count=1 msg=Started container task
0.3786,Event,ADDED,eval-conflicts-rho010-r4-043.18d466c2656067c4,reason=SuccessfulCreate count=1 msg=Created pod: eval-conflicts-rho010-r4-043-f8trd
0.3788,Event,ADDED,eval-conflicts-rho010-r4-043.18d466c5c02aeaed,reason=Completed count=1 msg=Job completed
0.379,Event,ADDED,eval-conflicts-rho010-r4-044-w9d85.18d466c2a1043d4e,"reason=FailedScheduling count=None msg=0/6 nodes are available: 1 c_wall violated: 1 conflicting context pair(s) with node memory, 5 node(s) had untolerated taint(s). no new claims to deallocate, preemption: 0/6 nodes are available: 1 No preemption victims found for incoming pod, 5 Preemption is not helpful for scheduling."
0.3793,Event,ADDED,eval-conflicts-rho010-r4-044-w9d85.18d466c2a187c574,"reason=FailedScheduling count=None msg=0/6 nodes are available: 1 c_wall violated: 1 conflicting context pair(s) with node memory, 5 node(s) had untolerated taint(s). no new claims to deallocate, preemption: 0/6 nodes are available: 1 No preemption victims found for incoming pod, 5 Preemption is not helpful for scheduling."
0.3795,Event,ADDED,eval-conflicts-rho010-r4-044-w9d85.18d466c3053440ed,reason=Scheduled count=None msg=Successfully assigned compute/eval-conflicts-rho010-r4-044-w9d85 to kind-worker5
0.3797,Event,ADDED,eval-conflicts-rho010-r4-044-w9d85.18d466c3222b9bf4,"reason=Pulled count=1 msg=Container image ""busybox:musl"" already present on machine"
0.3799,Event,ADDED,eval-conflicts-rho010-r4-044-w9d85.18d466c3239b689f,reason=Created count=1 msg=Created container: task
0.3801,Event,ADDED,eval-conflicts-rho010-r4-044-w9d85.18d466c32a92f715,reason=Started count=1 msg=Started container task
0.3803,Event,ADDED,eval-conflicts-rho010-r4-044.18d466c2a0c61a82,reason=SuccessfulCreate count=1 msg=Created pod: eval-conflicts-rho010-r4-044-w9d85
0.3805,Event,ADDED,eval-conflicts-rho010-r4-044.18d466c637fd72cc,reason=Completed count=1 msg=Job completed
0.3807,Event,ADDED,eval-conflicts-rho010-r4-045-ml7lt.18d466c2dcbf0cfe,"reason=FailedScheduling count=None msg=0/6 nodes are available: 6 node(s) had untolerated taint(s). no new claims to deallocate, preemption: 0/6 nodes are available: 6 Preemption is not helpful for scheduling."
0.3808,Event,ADDED,eval-conflicts-rho010-r4-045-ml7lt.18d466c305509613,reason=Scheduled count=None msg=Successfully assigned compute/eval-conflicts-rho010-r4-045-ml7lt to kind-worker5
0.381,Event,ADDED,eval-conflicts-rho010-r4-045-ml7lt.18d466c3224ec692,"reason=Pulled count=1 msg=Container image ""busybox:musl"" already present on machine"
0.3812,Event,ADDED,eval-conflicts-rho010-r4-045-ml7lt.18d466c323f0825c,reason=Created count=1 msg=Created container: task
0.3814,Event,ADDED,eval-conflicts-rho010-r4-045-ml7lt.18d466c32a8eacd9,reason=Started count=1 msg=Started container task
0.3816,Event,ADDED,eval-conflicts-rho010-r4-045.18d466c2dcb5a9e0,reason=SuccessfulCreate count=1 msg=Created pod: eval-conflicts-rho010-r4-045-ml7lt
0.3817,Event,ADDED,eval-conflicts-rho010-r4-045.18d466c6388c0b5a,reason=Completed count=1 msg=Job completed
0.3819,Event,ADDED,eval-conflicts-rho010-r4-046-f4lcp.18d466c318564c20,reason=Scheduled count=None msg=Successfully assigned compute/eval-conflicts-rho010-r4-046-f4lcp to kind-worker5
0.3821,Event,ADDED,eval-conflicts-rho010-r4-046-f4lcp.18d466c331ad1fd6,"reason=Pulled count=1 msg=Container image ""busybox:musl"" already present on machine"
0.3822,Event,ADDED,eval-conflicts-rho010-r4-046-f4lcp.18d466c332ba30d5,reason=Created count=1 msg=Created container: task
0.3824,Event,ADDED,eval-conflicts-rho010-r4-046-f4lcp.18d466c334b54eaf,reason=Started count=1 msg=Started container task
0.3826,Event,ADDED,eval-conflicts-rho010-r4-046.18d466c317a59c8f,reason=SuccessfulCreate count=1 msg=Created pod: eval-conflicts-rho010-r4-046-f4lcp
0.3832,Event,ADDED,eval-conflicts-rho010-r4-046.18d466c6739de303,reason=Completed count=1 msg=Job completed
0.3835,Event,ADDED,eval-conflicts-rho010-r4-047-rgsrt.18d466c353d56f78,"reason=FailedScheduling count=None msg=0/6 nodes are available: 1 c_wall violated: 1 conflicting context pair(s) with node memory, 5 node(s) had untolerated taint(s). no new claims to deallocate, preemption: 0/6 nodes are available: 1 No preemption victims found for incoming pod, 5 Preemption is not helpful for scheduling."
0.3838,Event,ADDED,eval-conflicts-rho010-r4-047-rgsrt.18d466c354585c49,"reason=FailedScheduling count=None msg=0/6 nodes are available: 1 c_wall violated: 1 conflicting context pair(s) with node memory, 5 node(s) had untolerated taint(s). no new claims to deallocate, preemption: 0/6 nodes are available: 1 No preemption victims found for incoming pod, 5 Preemption is not helpful for scheduling."
0.3842,Event,ADDED,eval-conflicts-rho010-r4-047-rgsrt.18d466c49240a17e,"reason=FailedScheduling count=None msg=0/6 nodes are available: 2 c_wall violated: 1 conflicting context pair(s) with node memory, 4 node(s) had untolerated taint(s). no new claims to deallocate, preemption: 0/6 nodes are available: 2 No preemption victims found for incoming pod, 4 Preemption is not helpful for scheduling."
0.3844,Event,ADDED,eval-conflicts-rho010-r4-047-rgsrt.18d466c4dd35bc2e,reason=Scheduled count=None msg=Successfully assigned compute/eval-conflicts-rho010-r4-047-rgsrt to kind-worker3
0.3845,Event,ADDED,eval-conflicts-rho010-r4-047-rgsrt.18d466c4f8524c93,"reason=Pulled count=1 msg=Container image ""busybox:musl"" already present on machine"
0.3849,Event,ADDED,eval-conflicts-rho010-r4-047-rgsrt.18d466c4f977f6c8,reason=Created count=1 msg=Created container: task
0.3851,Event,ADDED,eval-conflicts-rho010-r4-047-rgsrt.18d466c5026da981,reason=Started count=1 msg=Started container task
0.3852,Event,ADDED,eval-conflicts-rho010-r4-047.18d466c35398bca0,reason=SuccessfulCreate count=1 msg=Created pod: eval-conflicts-rho010-r4-047-rgsrt
0.3854,Event,ADDED,eval-conflicts-rho010-r4-047.18d466c843c0251d,reason=Completed count=1 msg=Job completed
0.3857,Event,ADDED,eval-conflicts-rho010-r4-048-5xbn2.18d466c390a97202,reason=Scheduled count=None msg=Successfully assigned compute/eval-conflicts-rho010-r4-048-5xbn2 to kind-worker5
0.3858,Event,ADDED,eval-conflicts-rho010-r4-048-5xbn2.18d466c3b18b0cea,"reason=Pulled count=1 msg=Container image ""busybox:musl"" already present on machine"
0.386,Event,ADDED,eval-conflicts-rho010-r4-048-5xbn2.18d466c3b2fff587,reason=Created count=1 msg=Created container: task
0.3862,Event,ADDED,eval-conflicts-rho010-r4-048-5xbn2.18d466c3b9fc5c57,reason=Started count=1 msg=Started container task
0.3864,Event,ADDED,eval-conflicts-rho010-r4-048.18d466c3901843bb,reason=SuccessfulCreate count=1 msg=Created pod: eval-conflicts-rho010-r4-048-5xbn2
0.3865,Event,ADDED,eval-conflicts-rho010-r4-048.18d466c6eb75758a,reason=Completed count=1 msg=Job completed
0.3867,Event,ADDED,eval-conflicts-rho010-r4-049-l2gdc.18d466c3cb3192d5,reason=Scheduled count=None msg=Successfully assigned compute/eval-conflicts-rho010-r4-049-l2gdc to kind-worker5
0.3868,Event,ADDED,eval-conflicts-rho010-r4-049-l2gdc.18d466c3ef4ddf5d,"reason=Pulled count=1 msg=Container image ""busybox:musl"" already present on machine"
0.387,Event,ADDED,eval-conflicts-rho010-r4-049-l2gdc.18d466c3f089d484,reason=Created count=1 msg=Created container: task
0.3872,Event,ADDED,eval-conflicts-rho010-r4-049-l2gdc.18d466c3f464671f,reason=Started count=1 msg=Started container task
0.3873,Event,ADDED,eval-conflicts-rho010-r4-049.18d466c3caafb0bf,reason=SuccessfulCreate count=1 msg=Created pod: eval-conflicts-rho010-r4-049-l2gdc
0.3875,Event,ADDED,eval-conflicts-rho010-r4-049.18d466c72936dc91,reason=Completed count=1 msg=Job completed
0.3877,Event,ADDED,eval-conflicts-rho010-r4-050-z2jkk.18d466c406e04eb3,"reason=FailedScheduling count=None msg=0/6 nodes are available: 1 c_wall violated: 1 conflicting context pair(s) with node memory, 5 node(s) had untolerated taint(s). no new claims to deallocate, preemption: 0/6 nodes are available: 1 No preemption victims found for incoming pod, 5 Preemption is not helpful for scheduling."
0.3879,Event,ADDED,eval-conflicts-rho010-r4-050-z2jkk.18d466c407631159,"reason=FailedScheduling count=None msg=0/6 nodes are available: 1 c_wall violated: 1 conflicting context pair(s) with node memory, 5 node(s) had untolerated taint(s). no new claims to deallocate, preemption: 0/6 nodes are available: 1 No preemption victims found for incoming pod, 5 Preemption is not helpful for scheduling."
0.388,Event,ADDED,eval-conflicts-rho010-r4-050-z2jkk.18d466c48a49a756,reason=Scheduled count=None msg=Successfully assigned compute/eval-conflicts-rho010-r4-050-z2jkk to kind-worker
0.3882,Event,ADDED,eval-conflicts-rho010-r4-050-z2jkk.18d466c4a2dd3d53,"reason=Pulled count=1 msg=Container image ""busybox:musl"" already present on machine"
0.3884,Event,ADDED,eval-conflicts-rho010-r4-050-z2jkk.18d466c4a3ecb3ea,reason=Created count=1 msg=Created container: task
0.3885,Event,ADDED,eval-conflicts-rho010-r4-050-z2jkk.18d466c4aa8e9f83,reason=Started count=1 msg=Started container task
0.3887,Event,ADDED,eval-conflicts-rho010-r4-050.18d466c406999be3,reason=SuccessfulCreate count=1 msg=Created pod: eval-conflicts-rho010-r4-050-z2jkk
0.389,Event,ADDED,eval-conflicts-rho010-r4-050.18d466c7c9184b98,reason=Completed count=1 msg=Job completed
0.3891,Event,ADDED,eval-conflicts-rho010-r4-051-cp9j7.18d466c442936e54,"reason=FailedScheduling count=None msg=0/6 nodes are available: 1 c_wall violated: 1 conflicting context pair(s) with node memory, 5 node(s) had untolerated taint(s). no new claims to deallocate, preemption: 0/6 nodes are available: 1 No preemption victims found for incoming pod, 5 Preemption is not helpful for scheduling."
0.3893,Event,ADDED,eval-conflicts-rho010-r4-051-cp9j7.18d466c443252862,"reason=FailedScheduling count=None msg=0/6 nodes are available: 1 c_wall violated: 1 conflicting context pair(s) with node memory, 5 node(s) had untolerated taint(s). no new claims to deallocate, preemption: 0/6 nodes are available: 1 No preemption victims found for incoming pod, 5 Preemption is not helpful for scheduling."
0.3895,Event,ADDED,eval-conflicts-rho010-r4-051-cp9j7.18d466c4928e62a7,"reason=FailedScheduling count=None msg=0/6 nodes are available: 2 c_wall violated: 1 conflicting context pair(s) with node memory, 4 node(s) had untolerated taint(s). no new claims to deallocate, preemption: 0/6 nodes are available: 2 No preemption victims found for incoming pod, 4 Preemption is not helpful for scheduling."
0.3896,Event,ADDED,eval-conflicts-rho010-r4-051-cp9j7.18d466c4e587c2a8,reason=Scheduled count=None msg=Successfully assigned compute/eval-conflicts-rho010-r4-051-cp9j7 to kind-worker3
0.3898,Event,ADDED,eval-conflicts-rho010-r4-051-cp9j7.18d466c502793d71,"reason=Pulled count=1 msg=Container image ""busybox:musl"" already present on machine"
0.39,Event,ADDED,eval-conflicts-rho010-r4-051-cp9j7.18d466c5039e2181,reason=Created count=1 msg=Created container: task
0.3901,Event,ADDED,eval-conflicts-rho010-r4-051-cp9j7.18d466c50836f7ed,reason=Started count=1 msg=Started container task
0.3903,Event,ADDED,eval-conflicts-rho010-r4-051.18d466c442500ea5,reason=SuccessfulCreate count=1 msg=Created pod: eval-conflicts-rho010-r4-051-cp9j7
0.3905,Event,ADDED,eval-conflicts-rho010-r4-051.18d466c843944de5,reason=Completed count=1 msg=Job completed
0.3906,Event,ADDED,eval-conflicts-rho010-r4-052-ltl58.18d466c47e70cb20,reason=Scheduled count=None msg=Successfully assigned compute/eval-conflicts-rho010-r4-052-ltl58 to kind-worker5
0.3908,Event,ADDED,eval-conflicts-rho010-r4-052-ltl58.18d466c49cb9e849,"reason=Pulled count=1 msg=Container image ""busybox:musl"" already present on machine"
0.391,Event,ADDED,eval-conflicts-rho010-r4-052-ltl58.18d466c49e293453,reason=Created count=1 msg=Created container: task
0.3911,Event,ADDED,eval-conflicts-rho010-r4-052-ltl58.18d466c4a21b21c7,reason=Started count=1 msg=Started container task
0.3914,Event,ADDED,eval-conflicts-rho010-r4-052.18d466c47de158cb,reason=SuccessfulCreate count=1 msg=Created pod: eval-conflicts-rho010-r4-052-ltl58
0.3916,Event,ADDED,eval-conflicts-rho010-r4-052.18d466c7e20449ab,reason=Completed count=1 msg=Job completed
0.3919,Event,ADDED,eval-conflicts-rho010-r4-053-85b24.18d466c4badc31a4,reason=Scheduled count=None msg=Successfully assigned compute/eval-conflicts-rho010-r4-053-85b24 to kind-worker
0.3921,Event,ADDED,eval-conflicts-rho010-r4-053-85b24.18d466c4d92d1546,"reason=Pulled count=1 msg=Container image ""busybox:musl"" already present on machine"
0.3923,Event,ADDED,eval-conflicts-rho010-r4-053-85b24.18d466c4da9e66cf,reason=Created count=1 msg=Created container: task
0.3926,Event,ADDED,eval-conflicts-rho010-r4-053-85b24.18d466c4de34836b,reason=Started count=1 msg=Started container task
0.3931,Event,ADDED,eval-conflicts-rho010-r4-053.18d466c4b9af5bf5,reason=SuccessfulCreate count=1 msg=Created pod: eval-conflicts-rho010-r4-053-85b24
0.3933,Event,ADDED,eval-conflicts-rho010-r4-053.18d466c807377188,reason=Completed count=1 msg=Job completed
0.3935,Event,ADDED,eval-conflicts-rho010-r4-054-k4sxr.18d466c4f695350c,reason=Scheduled count=None msg=Successfully assigned compute/eval-conflicts-rho010-r4-054-k4sxr to kind-worker3
0.3938,Event,ADDED,eval-conflicts-rho010-r4-054-k4sxr.18d466c50fe63611,"reason=Pulled count=1 msg=Container image ""busybox:musl"" already present on machine"
0.394,Event,ADDED,eval-conflicts-rho010-r4-054-k4sxr.18d466c511007aef,reason=Created count=1 msg=Created container: task
0.3941,Event,ADDED,eval-conflicts-rho010-r4-054-k4sxr.18d466c518d934ca,reason=Started count=1 msg=Started container task
0.3943,Event,ADDED,eval-conflicts-rho010-r4-054.18d466c4f59115a3,reason=SuccessfulCreate count=1 msg=Created pod: eval-conflicts-rho010-r4-054-k4sxr
0.3946,Event,ADDED,eval-conflicts-rho010-r4-054.18d466c84367a8dd,reason=Completed count=1 msg=Job completed
0.3947,Event,ADDED,eval-conflicts-rho010-r4-055-f4hhp.18d466c531058a40,reason=Scheduled count=None msg=Successfully assigned compute/eval-conflicts-rho010-r4-055-f4hhp to kind-worker
0.3949,Event,ADDED,eval-conflicts-rho010-r4-055-f4hhp.18d466c54fdd14e2,"reason=Pulled count=1 msg=Container image ""busybox:musl"" already present on machine"
0.395,Event,ADDED,eval-conflicts-rho010-r4-055-f4hhp.18d466c551057640,reason=Created count=1 msg=Created container: task
0.3954,Event,ADDED,eval-conflicts-rho010-r4-055-f4hhp.18d466c557b0fccb,reason=Started count=1 msg=Started container task
0.3956,Event,ADDED,eval-conflicts-rho010-r4-055.18d466c53030d747,reason=SuccessfulCreate count=1 msg=Created pod: eval-conflicts-rho010-r4-055-f4hhp
0.3958,Event,ADDED,eval-conflicts-rho010-r4-055.18d466c84442dba2,reason=Completed count=1 msg=Job completed
0.3961,Event,ADDED,eval-conflicts-rho010-r4-056-4bpg2.18d466c57196804c,reason=Scheduled count=None msg=Successfully assigned compute/eval-conflicts-rho010-r4-056-4bpg2 to kind-worker
0.3963,Event,ADDED,eval-conflicts-rho010-r4-056-4bpg2.18d466c58d833f14,"reason=Pulled count=1 msg=Container image ""busybox:musl"" already present on machine"
0.3965,Event,ADDED,eval-conflicts-rho010-r4-056-4bpg2.18d466c58ebe225e,reason=Created count=1 msg=Created container: task
0.3966,Event,ADDED,eval-conflicts-rho010-r4-056-4bpg2.18d466c592d7f191,reason=Started count=1 msg=Started container task
0.397,Event,ADDED,eval-conflicts-rho010-r4-056.18d466c5709819d4,reason=SuccessfulCreate count=1 msg=Created pod: eval-conflicts-rho010-r4-056-4bpg2
0.3971,Event,ADDED,eval-conflicts-rho010-r4-056.18d466c8bbf7aac8,reason=Completed count=1 msg=Job completed
0.3973,Event,ADDED,eval-conflicts-rho010-r4-057-2fxpb.18d466c5a85e67dc,reason=Scheduled count=None msg=Successfully assigned compute/eval-conflicts-rho010-r4-057-2fxpb to kind-worker
0.3976,Event,ADDED,eval-conflicts-rho010-r4-057-2fxpb.18d466c5cb0474fa,"reason=Pulled count=1 msg=Container image ""busybox:musl"" already present on machine"
0.3979,Event,ADDED,eval-conflicts-rho010-r4-057-2fxpb.18d466c5cc53c209,reason=Created count=1 msg=Created container: task
0.3981,Event,ADDED,eval-conflicts-rho010-r4-057-2fxpb.18d466c5d0a99601,reason=Started count=1 msg=Started container task
0.3983,Event,ADDED,eval-conflicts-rho010-r4-057.18d466c5a7c81547,reason=SuccessfulCreate count=1 msg=Created pod: eval-conflicts-rho010-r4-057-2fxpb
0.3992,Event,ADDED,eval-conflicts-rho010-r4-057.18d466c8f75e7d82,reason=Completed count=1 msg=Job completed
0.3993,Event,ADDED,eval-conflicts-rho010-r4-058-8xqrj.18d466c5e8e259cc,reason=Scheduled count=None msg=Successfully assigned compute/eval-conflicts-rho010-r4-058-8xqrj to kind-worker
0.3995,Event,ADDED,eval-conflicts-rho010-r4-058-8xqrj.18d466c603e18853,"reason=Pulled count=1 msg=Container image ""busybox:musl"" already present on machine"
0.3997,Event,ADDED,eval-conflicts-rho010-r4-058-8xqrj.18d466c604fd4491,reason=Created count=1 msg=Created container: task
0.4002,Event,ADDED,eval-conflicts-rho010-r4-058-8xqrj.18d466c608a4386f,reason=Started count=1 msg=Started container task
0.4007,Event,ADDED,eval-conflicts-rho010-r4-058.18d466c5e7eaf853,reason=SuccessfulCreate count=1 msg=Created pod: eval-conflicts-rho010-r4-058-8xqrj
0.4009,Event,ADDED,eval-conflicts-rho010-r4-058.18d466c9343f7f52,reason=Completed count=1 msg=Job completed
0.4011,Event,ADDED,eval-conflicts-rho010-r4-059-5kg5w.18d466c61fbb6955,reason=Scheduled count=None msg=Successfully assigned compute/eval-conflicts-rho010-r4-059-5kg5w to kind-worker
0.4012,Event,ADDED,eval-conflicts-rho010-r4-059-5kg5w.18d466c640c141f8,"reason=Pulled count=1 msg=Container image ""busybox:musl"" already present on machine"
0.4016,Event,ADDED,eval-conflicts-rho010-r4-059-5kg5w.18d466c641dfcd1b,reason=Created count=1 msg=Created container: task
0.4018,Event,ADDED,eval-conflicts-rho010-r4-059-5kg5w.18d466c6487d2443,reason=Started count=1 msg=Started container task
0.402,Event,ADDED,eval-conflicts-rho010-r4-059.18d466c61ee693e2,reason=SuccessfulCreate count=1 msg=Created pod: eval-conflicts-rho010-r4-059-5kg5w
0.4022,Event,ADDED,eval-conflicts-rho010-r4-059.18d466c970415e50,reason=Completed count=1 msg=Job completed
0.4023,Event,ADDED,eval-conflicts-rho010-r4-060-4h7zd.18d466c65b77a4dc,reason=Scheduled count=None msg=Successfully assigned compute/eval-conflicts-rho010-r4-060-4h7zd to kind-worker
0.4025,Event,ADDED,eval-conflicts-rho010-r4-060-4h7zd.18d466c67bb0fa1c,"reason=Pulled count=1 msg=Container image ""busybox:musl"" already present on machine"
0.4028,Event,ADDED,eval-conflicts-rho010-r4-060-4h7zd.18d466c67d0077d8,reason=Created count=1 msg=Created container: task
0.403,Event,ADDED,eval-conflicts-rho010-r4-060-4h7zd.18d466c683ab795c,reason=Started count=1 msg=Started container task
0.4031,Event,ADDED,eval-conflicts-rho010-r4-060.18d466c65a8bd616,reason=SuccessfulCreate count=1 msg=Created pod: eval-conflicts-rho010-r4-060-4h7zd
0.4034,Event,ADDED,eval-conflicts-rho010-r4-060.18d466c9a882a8f7,reason=Completed count=1 msg=Job completed
0.4035,Event,ADDED,eval-conflicts-rho010-r4-061-52n5n.18d466c6995bb3ed,reason=Scheduled count=None msg=Successfully assigned compute/eval-conflicts-rho010-r4-061-52n5n to kind-worker
0.4037,Event,ADDED,eval-conflicts-rho010-r4-061-52n5n.18d466c6bc9c6ec6,"reason=Pulled count=1 msg=Container image ""busybox:musl"" already present on machine"
0.4038,Event,ADDED,eval-conflicts-rho010-r4-061-52n5n.18d466c6bdc6565f,reason=Created count=1 msg=Created container: task
0.404,Event,ADDED,eval-conflicts-rho010-r4-061-52n5n.18d466c6c6ee0e53,reason=Started count=1 msg=Started container task
0.4043,Event,ADDED,eval-conflicts-rho010-r4-061.18d466c698a6c54e,reason=SuccessfulCreate count=1 msg=Created pod: eval-conflicts-rho010-r4-061-52n5n
0.4044,Event,ADDED,eval-conflicts-rho010-r4-061.18d466c9e443910c,reason=Completed count=1 msg=Job completed
0.4046,Event,ADDED,eval-conflicts-rho010-r4-062-dhmrx.18d466c6d25d7983,reason=Scheduled count=None msg=Successfully assigned compute/eval-conflicts-rho010-r4-062-dhmrx to kind-worker
0.4049,Event,ADDED,eval-conflicts-rho010-r4-062-dhmrx.18d466c6fd1cbca2,"reason=Pulled count=1 msg=Container image ""busybox:musl"" already present on machine"
0.405,Event,ADDED,eval-conflicts-rho010-r4-062-dhmrx.18d466c6fe3da03e,reason=Created count=1 msg=Created container: task
0.4052,Event,ADDED,eval-conflicts-rho010-r4-062-dhmrx.18d466c705a49429,reason=Started count=1 msg=Started container task
0.4055,Event,ADDED,eval-conflicts-rho010-r4-062.18d466c6d1af1e75,reason=SuccessfulCreate count=1 msg=Created pod: eval-conflicts-rho010-r4-062-dhmrx
0.4057,Event,ADDED,eval-conflicts-rho010-r4-062.18d466ca20aa787a,reason=Completed count=1 msg=Job completed
0.4058,Event,ADDED,eval-conflicts-rho010-r4-063-9fzpp.18d466c7153aa232,reason=Scheduled count=None msg=Successfully assigned compute/eval-conflicts-rho010-r4-063-9fzpp to kind-worker3
0.406,Event,ADDED,eval-conflicts-rho010-r4-063-9fzpp.18d466c74f9a09c3,"reason=Pulled count=1 msg=Container image ""busybox:musl"" already present on machine"
0.4062,Event,ADDED,eval-conflicts-rho010-r4-063-9fzpp.18d466c750fda9d8,reason=Created count=1 msg=Created container: task
0.4064,Event,ADDED,eval-conflicts-rho010-r4-063-9fzpp.18d466c75a184ac8,reason=Started count=1 msg=Started container task
0.4065,Event,ADDED,eval-conflicts-rho010-r4-063.18d466c714c93081,reason=SuccessfulCreate count=1 msg=Created pod: eval-conflicts-rho010-r4-063-9fzpp
0.407,Event,ADDED,eval-conflicts-rho010-r4-063.18d466ca927fd3db,reason=Completed count=1 msg=Job completed
0.4071,Event,ADDED,eval-conflicts-rho010-r4-064-75fts.18d466c748eabd02,"reason=FailedScheduling count=None msg=0/6 nodes are available: 6 node(s) had untolerated taint(s). no new claims to deallocate, preemption: 0/6 nodes are available: 6 Preemption is not helpful for scheduling."
0.4073,Event,ADDED,eval-conflicts-rho010-r4-064-75fts.18d466c75950c069,reason=Scheduled count=None msg=Successfully assigned compute/eval-conflicts-rho010-r4-064-75fts to kind-worker4
0.4074,Event,ADDED,eval-conflicts-rho010-r4-064-75fts.18d466c77988823b,"reason=Pulled count=1 msg=Container image ""busybox:musl"" already present on machine"
0.4078,Event,ADDED,eval-conflicts-rho010-r4-064-75fts.18d466c77abca989,reason=Created count=1 msg=Created container: task
0.4081,Event,ADDED,eval-conflicts-rho010-r4-064-75fts.18d466c77f82b9b4,reason=Started count=1 msg=Started container task
0.4083,Event,ADDED,eval-conflicts-rho010-r4-064.18d466c748de55c3,reason=SuccessfulCreate count=1 msg=Created pod: eval-conflicts-rho010-r4-064-75fts
0.4084,Event,ADDED,eval-conflicts-rho010-r4-064.18d466caae25e07e,reason=Completed count=1 msg=Job completed
0.4087,Event,ADDED,eval-conflicts-rho010-r4-065-b2t4l.18d466c78abd2053,reason=Scheduled count=None msg=Successfully assigned compute/eval-conflicts-rho010-r4-065-b2t4l to kind-worker2
0.4088,Event,ADDED,eval-conflicts-rho010-r4-065-b2t4l.18d466c7ab9fac6c,"reason=Pulled count=1 msg=Container image ""busybox:musl"" already present on machine"
0.409,Event,ADDED,eval-conflicts-rho010-r4-065-b2t4l.18d466c7acdcca88,reason=Created count=1 msg=Created container: task
0.4092,Event,ADDED,eval-conflicts-rho010-r4-065-b2t4l.18d466c7b5e1e800,reason=Started count=1 msg=Started container task
0.4094,Event,ADDED,eval-conflicts-rho010-r4-065.18d466c789c65504,reason=SuccessfulCreate count=1 msg=Created pod: eval-conflicts-rho010-r4-065-b2t4l
0.4097,Event,ADDED,eval-conflicts-rho010-r4-065.18d466cae1dca204,reason=Completed count=1 msg=Job completed
0.4098,Event,ADDED,eval-conflicts-rho010-r4-066-5j998.18d466c7c0b16468,reason=Scheduled count=None msg=Successfully assigned compute/eval-conflicts-rho010-r4-066-5j998 to kind-worker5
0.4101,Event,ADDED,eval-conflicts-rho010-r4-066-5j998.18d466c7da3a5669,"reason=Pulled count=1 msg=Container image ""busybox:musl"" already present on machine"
0.4103,Event,ADDED,eval-conflicts-rho010-r4-066-5j998.18d466c7db49222d,reason=Created count=1 msg=Created container: task
0.4105,Event,ADDED,eval-conflicts-rho010-r4-066-5j998.18d466c7e281e2c6,reason=Started count=1 msg=Started container task
0.4108,Event,ADDED,eval-conflicts-rho010-r4-066.18d466c7bfddadcb,reason=SuccessfulCreate count=1 msg=Created pod: eval-conflicts-rho010-r4-066-5j998
0.411,Event,ADDED,eval-conflicts-rho010-r4-066.18d466cb1d73e431,reason=Completed count=1 msg=Job completed
0.4112,Event,ADDED,eval-conflicts-rho010-r4-067-8jn26.18d466c7fd2a2d52,reason=Scheduled count=None msg=Successfully assigned compute/eval-conflicts-rho010-r4-067-8jn26 to kind-worker5
0.4113,Event,ADDED,eval-conflicts-rho010-r4-067-8jn26.18d466c81c3070dd,"reason=Pulled count=1 msg=Container image ""busybox:musl"" already present on machine"
0.4116,Event,ADDED,eval-conflicts-rho010-r4-067-8jn26.18d466c81d480aa5,reason=Created count=1 msg=Created container: task
0.4118,Event,ADDED,eval-conflicts-rho010-r4-067-8jn26.18d466c824e6baee,reason=Started count=1 msg=Started container task
0.412,Event,ADDED,eval-conflicts-rho010-r4-067.18d466c7fc1c0623,reason=SuccessfulCreate count=1 msg=Created pod: eval-conflicts-rho010-r4-067-8jn26
0.4121,Event,ADDED,eval-conflicts-rho010-r4-067.18d466cb59017d74,reason=Completed count=1 msg=Job completed
0.4124,Event,ADDED,eval-conflicts-rho010-r4-068-7592l.18d466c83fd8a5e2,reason=Scheduled count=None msg=Successfully assigned compute/eval-conflicts-rho010-r4-068-7592l to kind-worker5
0.4125,Event,ADDED,eval-conflicts-rho010-r4-068-7592l.18d466c85c1a8414,"reason=Pulled count=1 msg=Container image ""busybox:musl"" already present on machine"
0.4127,Event,ADDED,eval-conflicts-rho010-r4-068-7592l.18d466c85d422838,reason=Created count=1 msg=Created container: task
0.4129,Event,ADDED,eval-conflicts-rho010-r4-068-7592l.18d466c8676ee2ca,reason=Started count=1 msg=Started container task
0.413,Event,ADDED,eval-conflicts-rho010-r4-068.18d466c83e978e06,reason=SuccessfulCreate count=1 msg=Created pod: eval-conflicts-rho010-r4-068-7592l
0.4132,Event,ADDED,eval-conflicts-rho010-r4-068.18d466cb94e65d42,reason=Completed count=1 msg=Job completed
0.4134,Event,ADDED,eval-conflicts-rho010-r4-069-n9wpr.18d466c8748f07c9,reason=Scheduled count=None msg=Successfully assigned compute/eval-conflicts-rho010-r4-069-n9wpr to kind-worker2
0.4137,Event,ADDED,eval-conflicts-rho010-r4-069-n9wpr.18d466c8a58c8d9d,"reason=Pulled count=1 msg=Container image ""busybox:musl"" already present on machine"
0.4141,Event,ADDED,eval-conflicts-rho010-r4-069-n9wpr.18d466c8a6ac681f,reason=Created count=1 msg=Created container: task
0.4143,Event,ADDED,eval-conflicts-rho010-r4-069-n9wpr.18d466c8ab363552,reason=Started count=1 msg=Started container task
0.4145,Event,ADDED,eval-conflicts-rho010-r4-069.18d466c873503a15,reason=SuccessfulCreate count=1 msg=Created pod: eval-conflicts-rho010-r4-069-n9wpr
0.4148,Event,ADDED,eval-conflicts-rho010-r4-069.18d466cbd146e55d,reason=Completed count=1 msg=Job completed
0.415,Event,ADDED,eval-conflicts-rho010-r4-070-2xcl4.18d466c8b00dba2c,reason=Scheduled count=None msg=Successfully assigned compute/eval-conflicts-rho010-r4-070-2xcl4 to kind-worker5
0.4151,Event,ADDED,eval-conflicts-rho010-r4-070-2xcl4.18d466c8cee7d592,"reason=Pulled count=1 msg=Container image ""busybox:musl"" already present on machine"
0.4155,Event,ADDED,eval-conflicts-rho010-r4-070-2xcl4.18d466c8d02934e4,reason=Created count=1 msg=Created container: task
0.4157,Event,ADDED,eval-conflicts-rho010-r4-070-2xcl4.18d466c8d5b26bb9,reason=Started count=1 msg=Started container task
0.4159,Event,ADDED,eval-conflicts-rho010-r4-070.18d466c8aee9ff71,reason=SuccessfulCreate count=1 msg=Created pod: eval-conflicts-rho010-r4-070-2xcl4
0.4161,Event,ADDED,eval-conflicts-rho010-r4-070.18d466cc0ca7a4ce,reason=Completed count=1 msg=Job completed
0.4164,Event,ADDED,eval-conflicts-rho010-r4-071-7kbbg.18d466c8eb906b04,reason=Scheduled count=None msg=Successfully assigned compute/eval-conflicts-rho010-r4-071-7kbbg to kind-worker2
0.4166,Event,ADDED,eval-conflicts-rho010-r4-071-7kbbg.18d466c906647a31,"reason=Pulled count=1 msg=Container image ""busybox:musl"" already present on machine"
0.4167,Event,ADDED,eval-conflicts-rho010-r4-071-7kbbg.18d466c9078fff48,reason=Created count=1 msg=Created container: task
0.417,Event,ADDED,eval-conflicts-rho010-r4-071-7kbbg.18d466c90ae6a45a,reason=Started count=1 msg=Started container task
0.4172,Event,ADDED,eval-conflicts-rho010-r4-071.18d466c8ea57a9bc,reason=SuccessfulCreate count=1 msg=Created pod: eval-conflicts-rho010-r4-071-7kbbg
0.4174,Event,ADDED,eval-conflicts-rho010-r4-071.18d466cc489c7c50,reason=Completed count=1 msg=Job completed
0.4176,Event,ADDED,eval-conflicts-rho010-r4-072-mfc4b.18d466c927621257,reason=Scheduled count=None msg=Successfully assigned compute/eval-conflicts-rho010-r4-072-mfc4b to kind-worker5
0.4178,Event,ADDED,eval-conflicts-rho010-r4-072-mfc4b.18d466c940460bfd,"reason=Pulled count=1 msg=Container image ""busybox:musl"" already present on machine"
0.418,Event,ADDED,eval-conflicts-rho010-r4-072-mfc4b.18d466c9417485ee,reason=Created count=1 msg=Created container: task
0.4181,Event,ADDED,eval-conflicts-rho010-r4-072-mfc4b.18d466c943ec8339,reason=Started count=1 msg=Started container task
0.4183,Event,ADDED,eval-conflicts-rho010-r4-072.18d466c9261c2424,reason=SuccessfulCreate count=1 msg=Created pod: eval-conflicts-rho010-r4-072-mfc4b
0.4185,Event,ADDED,eval-conflicts-rho010-r4-072.18d466cc847683ca,reason=Completed count=1 msg=Job completed
0.4186,Event,ADDED,eval-conflicts-rho010-r4-073-b4ngc.18d466c9627a4e76,reason=Scheduled count=None msg=Successfully assigned compute/eval-conflicts-rho010-r4-073-b4ngc to kind-worker2
0.4188,Event,ADDED,eval-conflicts-rho010-r4-073-b4ngc.18d466c97b95323f,"reason=Pulled count=1 msg=Container image ""busybox:musl"" already present on machine"
0.419,Event,ADDED,eval-conflicts-rho010-r4-073-b4ngc.18d466c97cd06e1a,reason=Created count=1 msg=Created container: task
0.4192,Event,ADDED,eval-conflicts-rho010-r4-073-b4ngc.18d466c9816568b5,reason=Started count=1 msg=Started container task
0.4194,Event,ADDED,eval-conflicts-rho010-r4-073.18d466c96132bfdf,reason=SuccessfulCreate count=1 msg=Created pod: eval-conflicts-rho010-r4-073-b4ngc
0.4195,Event,ADDED,eval-conflicts-rho010-r4-073.18d466ccc05df3cc,reason=Completed count=1 msg=Job completed
0.4197,Event,ADDED,eval-conflicts-rho010-r4-074-wdlvj.18d466c99e586bee,reason=Scheduled count=None msg=Successfully assigned compute/eval-conflicts-rho010-r4-074-wdlvj to kind-worker2
0.4199,Event,ADDED,eval-conflicts-rho010-r4-074-wdlvj.18d466c9b9833e64,"reason=Pulled count=1 msg=Container image ""busybox:musl"" already present on machine"
0.42,Event,ADDED,eval-conflicts-rho010-r4-074-wdlvj.18d466c9bac5a3ff,reason=Created count=1 msg=Created container: task
0.4202,Event,ADDED,eval-conflicts-rho010-r4-074-wdlvj.18d466c9bd2969e2,reason=Started count=1 msg=Started container task
0.4204,Event,ADDED,eval-conflicts-rho010-r4-074.18d466c99d28b3a8,reason=SuccessfulCreate count=1 msg=Created pod: eval-conflicts-rho010-r4-074-wdlvj
0.4205,Event,ADDED,eval-conflicts-rho010-r4-074.18d466ccfc2c5668,reason=Completed count=1 msg=Job completed
0.4207,Event,ADDED,eval-conflicts-rho010-r4-075-97tpz.18d466c9d9c46cbd,reason=Scheduled count=None msg=Successfully assigned compute/eval-conflicts-rho010-r4-075-97tpz to kind-worker5
0.4209,Event,ADDED,eval-conflicts-rho010-r4-075-97tpz.18d466c9f49f56e1,"reason=Pulled count=1 msg=Container image ""busybox:musl"" already present on machine"
0.421,Event,ADDED,eval-conflicts-rho010-r4-075-97tpz.18d466c9f5bdfb01,reason=Created count=1 msg=Created container: task
0.4212,Event,ADDED,eval-conflicts-rho010-r4-075-97tpz.18d466c9f7c92976,reason=Started count=1 msg=Started container task
0.4213,Event,ADDED,eval-conflicts-rho010-r4-075.18d466c9d936cbda,reason=SuccessfulCreate count=1 msg=Created pod: eval-conflicts-rho010-r4-075-97tpz
0.4217,Event,ADDED,eval-conflicts-rho010-r4-075.18d466cd3843f22f,reason=Completed count=1 msg=Job completed
0.4218,Event,ADDED,eval-conflicts-rho010-r4-076-pv75k.18d466ca147e1a16,"reason=FailedScheduling count=None msg=0/6 nodes are available: 6 node(s) had untolerated taint(s). no new claims to deallocate, preemption: 0/6 nodes are available: 6 Preemption is not helpful for scheduling."
0.422,Event,ADDED,eval-conflicts-rho010-r4-076-pv75k.18d466cba8572f1c,reason=Scheduled count=None msg=Successfully assigned compute/eval-conflicts-rho010-r4-076-pv75k to kind-worker
0.4223,Event,ADDED,eval-conflicts-rho010-r4-076-pv75k.18d466cbc2aa3986,"reason=Pulled count=1 msg=Container image ""busybox:musl"" already present on machine"
0.4225,Event,ADDED,eval-conflicts-rho010-r4-076-pv75k.18d466cbc4a41576,reason=Created count=1 msg=Created container: task
0.4227,Event,ADDED,eval-conflicts-rho010-r4-076-pv75k.18d466cbc6aeab1b,reason=Started count=1 msg=Started container task
0.4228,Event,ADDED,eval-conflicts-rho010-r4-076.18d466ca1475bad4,reason=SuccessfulCreate count=1 msg=Created pod: eval-conflicts-rho010-r4-076-pv75k
0.423,Event,ADDED,eval-conflicts-rho010-r4-076.18d466cf0812d732,reason=Completed count=1 msg=Job completed
0.4232,Event,ADDED,eval-conflicts-rho010-r4-077-9h742.18d466ca50b89864,"reason=FailedScheduling count=None msg=0/6 nodes are available: 6 node(s) had untolerated taint(s). no new claims to deallocate, preemption: 0/6 nodes are available: 6 Preemption is not helpful for scheduling."
0.4233,Event,ADDED,eval-conflicts-rho010-r4-077-9h742.18d466cba88b7fd0,"reason=FailedScheduling count=None msg=0/6 nodes are available: 1 c_wall violated: 1 conflicting context pair(s) with node memory, 5 node(s) had untolerated taint(s). no new claims to deallocate, preemption: 0/6 nodes are available: 1 No preemption victims found for incoming pod, 5 Preemption is not helpful for scheduling."
0.4235,Event,ADDED,eval-conflicts-rho010-r4-077-9h742.18d466cbb2bc7cdd,"reason=FailedScheduling count=None msg=0/6 nodes are available: 1 c_wall violated: 1 conflicting context pair(s) with node memory, 5 node(s) had untolerated taint(s). no new claims to deallocate, preemption: 0/6 nodes are available: 1 No preemption victims found for incoming pod, 5 Preemption is not helpful for scheduling."
0.4238,Event,ADDED,eval-conflicts-rho010-r4-077-9h742.18d466cbeaf2dfc9,reason=Scheduled count=None msg=Successfully assigned compute/eval-conflicts-rho010-r4-077-9h742 to kind-worker3
0.424,Event,ADDED,eval-conflicts-rho010-r4-077-9h742.18d466cc041798a4,"reason=Pulled count=1 msg=Container image ""busybox:musl"" already present on machine"
0.4241,Event,ADDED,eval-conflicts-rho010-r4-077-9h742.18d466cc05772ff8,reason=Created count=1 msg=Created container: task
0.4243,Event,ADDED,eval-conflicts-rho010-r4-077-9h742.18d466cc07650700,reason=Started count=1 msg=Started container task
0.4245,Event,ADDED,eval-conflicts-rho010-r4-077.18d466ca50b00fc1,reason=SuccessfulCreate count=1 msg=Created pod: eval-conflicts-rho010-r4-077-9h742
0.4246,Event,ADDED,eval-conflicts-rho010-r4-077.18d466cf3c5a0d00,reason=Completed count=1 msg=Job completed
0.4248,Event,ADDED,eval-conflicts-rho010-r4-078-mwhvj.18d466ca8bb834ae,"reason=FailedScheduling count=None msg=0/6 nodes are available: 6 node(s) had untolerated taint(s). no new claims to deallocate, preemption: 0/6 nodes are available: 6 Preemption is not helpful for scheduling."
0.4249,Event,ADDED,eval-conflicts-rho010-r4-078-mwhvj.18d466cba9757595,reason=Scheduled count=None msg=Successfully assigned compute/eval-conflicts-rho010-r4-078-mwhvj to kind-worker
0.4251,Event,ADDED,eval-conflicts-rho010-r4-078-mwhvj.18d466cbc3ef400b,"reason=Pulled count=1 msg=Container image ""busybox:musl"" already present on machine"
0.4253,Event,ADDED,eval-conflicts-rho010-r4-078-mwhvj.18d466cbc73b27c6,reason=Created count=1 msg=Created container: task
0.4255,Event,ADDED,eval-conflicts-rho010-r4-078-mwhvj.18d466cbc9ed4b3d,reason=Started count=1 msg=Started container task
0.4257,Event,ADDED,eval-conflicts-rho010-r4-078.18d466ca8baa225a,reason=SuccessfulCreate count=1 msg=Created pod: eval-conflicts-rho010-r4-078-mwhvj
0.426,Event,ADDED,eval-conflicts-rho010-r4-078.18d466cf07ab09b3,reason=Completed count=1 msg=Job completed
0.4266,Event,ADDED,eval-conflicts-rho010-r4-079-6wtsn.18d466cac755225f,"reason=FailedScheduling count=None msg=0/6 nodes are available: 6 node(s) had untolerated taint(s). no new claims to deallocate, preemption: 0/6 nodes are available: 6 Preemption is not helpful for scheduling."
0.4268,Event,ADDED,eval-conflicts-rho010-r4-079-6wtsn.18d466cba99e873f,reason=Scheduled count=None msg=Successfully assigned compute/eval-conflicts-rho010-r4-079-6wtsn to kind-worker
0.427,Event,ADDED,eval-conflicts-rho010-r4-079-6wtsn.18d466cbc4102b27,"reason=Pulled count=1 msg=Container image ""busybox:musl"" already present on machine"
0.4272,Event,ADDED,eval-conflicts-rho010-r4-079-6wtsn.18d466cbc7c94fb2,reason=Created count=1 msg=Created container: task
0.4275,Event,ADDED,eval-conflicts-rho010-r4-079-6wtsn.18d466cbca7443a2,reason=Started count=1 msg=Started container task
0.4277,Event,ADDED,eval-conflicts-rho010-r4-079.18d466cac74bf939,reason=SuccessfulCreate count=1 msg=Created pod: eval-conflicts-rho010-r4-079-6wtsn
0.4279,Event,ADDED,eval-conflicts-rho010-r4-079.18d466cf088626a6,reason=Completed count=1 msg=Job completed
0.4281,Event,ADDED,eval-conflicts-rho010-r4-080-77kmd.18d466cb029ff80c,"reason=FailedScheduling count=None msg=0/6 nodes are available: 6 node(s) had untolerated taint(s). no new claims to deallocate, preemption: 0/6 nodes are available: 6 Preemption is not helpful for scheduling."
0.4284,Event,ADDED,eval-conflicts-rho010-r4-080-77kmd.18d466cbacccd813,reason=Scheduled count=None msg=Successfully assigned compute/eval-conflicts-rho010-r4-080-77kmd to kind-worker
0.4286,Event,ADDED,eval-conflicts-rho010-r4-080-77kmd.18d466cbc4acfacc,"reason=Pulled count=1 msg=Container image ""busybox:musl"" already present on machine"
0.4288,Event,ADDED,eval-conflicts-rho010-r4-080-77kmd.18d466cbc787ef2b,reason=Created count=1 msg=Created container: task
0.4292,Event,ADDED,eval-conflicts-rho010-r4-080-77kmd.18d466cbc9ed89ec,reason=Started count=1 msg=Started container task
0.4294,Event,ADDED,eval-conflicts-rho010-r4-080.18d466cb0296f912,reason=SuccessfulCreate count=1 msg=Created pod: eval-conflicts-rho010-r4-080-77kmd
0.4296,Event,ADDED,eval-conflicts-rho010-r4-080.18d466cf0781a264,reason=Completed count=1 msg=Job completed
0.4297,Event,ADDED,eval-conflicts-rho010-r4-081-b5xbp.18d466cb3e408d9b,"reason=FailedScheduling count=None msg=0/6 nodes are available: 6 node(s) had untolerated taint(s). no new claims to deallocate, preemption: 0/6 nodes are available: 6 Preemption is not helpful for scheduling."
0.4301,Event,ADDED,eval-conflicts-rho010-r4-081-b5xbp.18d466cbacd7d63d,reason=Scheduled count=None msg=Successfully assigned compute/eval-conflicts-rho010-r4-081-b5xbp to kind-worker
0.4303,Event,ADDED,eval-conflicts-rho010-r4-081-b5xbp.18d466cbc4c9b100,"reason=Pulled count=1 msg=Container image ""busybox:musl"" already present on machine"
0.4305,Event,ADDED,eval-conflicts-rho010-r4-081-b5xbp.18d466cbc859d4df,reason=Created count=1 msg=Created container: task
0.4308,Event,ADDED,eval-conflicts-rho010-r4-081-b5xbp.18d466cbcb475b9a,reason=Started count=1 msg=Started container task
0.431,Event,ADDED,eval-conflicts-rho010-r4-081.18d466cb3e336403,reason=SuccessfulCreate count=1 msg=Created pod: eval-conflicts-rho010-r4-081-b5xbp
0.4311,Event,ADDED,eval-conflicts-rho010-r4-081.18d466cf08ebea8c,reason=Completed count=1 msg=Job completed
0.4313,Event,ADDED,eval-conflicts-rho010-r4-082-2svnh.18d466cb79e597a3,"reason=FailedScheduling count=None msg=0/6 nodes are available: 6 node(s) had untolerated taint(s). no new claims to deallocate, preemption: 0/6 nodes are available: 6 Preemption is not helpful for scheduling."
0.4315,Event,ADDED,eval-conflicts-rho010-r4-082-2svnh.18d466cbad1c2b49,reason=Scheduled count=None msg=Successfully assigned compute/eval-conflicts-rho010-r4-082-2svnh to kind-worker
0.4316,Event,ADDED,eval-conflicts-rho010-r4-082-2svnh.18d466cbc5e0623b,"reason=Pulled count=1 msg=Container image ""busybox:musl"" already present on machine"
0.4318,Event,ADDED,eval-conflicts-rho010-r4-082-2svnh.18d466cbc89c534f,reason=Created count=1 msg=Created container: task
0.432,Event,ADDED,eval-conflicts-rho010-r4-082-2svnh.18d466cbcb475b90,reason=Started count=1 msg=Started container task
0.4321,Event,ADDED,eval-conflicts-rho010-r4-082.18d466cb79db14bd,reason=SuccessfulCreate count=1 msg=Created pod: eval-conflicts-rho010-r4-082-2svnh
0.4323,Event,ADDED,eval-conflicts-rho010-r4-082.18d466cecdeec81b,reason=Completed count=1 msg=Job completed
0.4325,Event,ADDED,eval-conflicts-rho010-r4-083-8txvg.18d466cbb68a0ba4,reason=Scheduled count=None msg=Successfully assigned compute/eval-conflicts-rho010-r4-083-8txvg to kind-worker
0.4326,Event,ADDED,eval-conflicts-rho010-r4-083-8txvg.18d466cbd0179ce1,"reason=Pulled count=1 msg=Container image ""busybox:musl"" already present on machine"
0.4328,Event,ADDED,eval-conflicts-rho010-r4-083-8txvg.18d466cbd1b5aa0a,reason=Created count=1 msg=Created container: task
0.433,Event,ADDED,eval-conflicts-rho010-r4-083-8txvg.18d466cbd5e4c96e,reason=Started count=1 msg=Started container task
0.4331,Event,ADDED,eval-conflicts-rho010-r4-083.18d466cbb6077d21,reason=SuccessfulCreate count=1 msg=Created pod: eval-conflicts-rho010-r4-083-8txvg
0.4333,Event,ADDED,eval-conflicts-rho010-r4-083.18d466cf07c7a222,reason=Completed count=1 msg=Job completed
0.4335,Event,ADDED,eval-conflicts-rho010-r4-084-z9zq2.18d466cbf16be6ee,reason=Scheduled count=None msg=Successfully assigned compute/eval-conflicts-rho010-r4-084-z9zq2 to kind-worker3
0.4338,Event,ADDED,eval-conflicts-rho010-r4-084-z9zq2.18d466cc0899e714,"reason=Pulled count=1 msg=Container image ""busybox:musl"" already present on machine"
0.4341,Event,ADDED,eval-conflicts-rho010-r4-084-z9zq2.18d466cc09a1f76b,reason=Created count=1 msg=Created container: task
0.4342,Event,ADDED,eval-conflicts-rho010-r4-084-z9zq2.18d466cc0d3d3a0e,reason=Started count=1 msg=Started container task
0.4344,Event,ADDED,eval-conflicts-rho010-r4-084.18d466cbf0aab96f,reason=SuccessfulCreate count=1 msg=Created pod: eval-conflicts-rho010-r4-084-z9zq2
0.4346,Event,ADDED,eval-conflicts-rho010-r4-084.18d466cf3c36c6a7,reason=Completed count=1 msg=Job completed
0.4347,Event,ADDED,eval-conflicts-rho010-r4-085-vglh2.18d466cc2e3c7ee2,reason=Scheduled count=None msg=Successfully assigned compute/eval-conflicts-rho010-r4-085-vglh2 to kind-worker4
0.4349,Event,ADDED,eval-conflicts-rho010-r4-085-vglh2.18d466cc472cd3a4,"reason=Pulled count=1 msg=Container image ""busybox:musl"" already present on machine"
0.4351,Event,ADDED,eval-conflicts-rho010-r4-085-vglh2.18d466cc48bdce7e,reason=Created count=1 msg=Created container: task
0.4352,Event,ADDED,eval-conflicts-rho010-r4-085-vglh2.18d466cc4cd5cc17,reason=Started count=1 msg=Started container task
0.4354,Event,ADDED,eval-conflicts-rho010-r4-085.18d466cc2cf7e55f,reason=SuccessfulCreate count=1 msg=Created pod: eval-conflicts-rho010-r4-085-vglh2
0.4355,Event,ADDED,eval-conflicts-rho010-r4-085.18d466cf931769cf,reason=Completed count=1 msg=Job completed
0.4357,Event,ADDED,eval-conflicts-rho010-r4-086-b9xrt.18d466cc695bbf2e,reason=Scheduled count=None msg=Successfully assigned compute/eval-conflicts-rho010-r4-086-b9xrt to kind-worker4
0.4359,Event,ADDED,eval-conflicts-rho010-r4-086-b9xrt.18d466cc827dfe63,"reason=Pulled count=1 msg=Container image ""busybox:musl"" already present on machine"
0.436,Event,ADDED,eval-conflicts-rho010-r4-086-b9xrt.18d466cc83ceed36,reason=Created count=1 msg=Created container: task
0.4362,Event,ADDED,eval-conflicts-rho010-r4-086-b9xrt.18d466cc8bf01612,reason=Started count=1 msg=Started container task
0.4363,Event,ADDED,eval-conflicts-rho010-r4-086.18d466cc68320f37,reason=SuccessfulCreate count=1 msg=Created pod: eval-conflicts-rho010-r4-086-b9xrt
0.4365,Event,ADDED,eval-conflicts-rho010-r4-086.18d466cfcf30fc18,reason=Completed count=1 msg=Job completed
0.4367,Event,ADDED,eval-conflicts-rho010-r4-087-trdn4.18d466cca590fc57,reason=Scheduled count=None msg=Successfully assigned compute/eval-conflicts-rho010-r4-087-trdn4 to kind-worker3
0.4368,Event,ADDED,eval-conflicts-rho010-r4-087-trdn4.18d466ccbec1f17f,"reason=Pulled count=1 msg=Container image ""busybox:musl"" already present on machine"
0.437,Event,ADDED,eval-conflicts-rho010-r4-087-trdn4.18d466ccc0c18004,reason=Created count=1 msg=Created container: task
0.4372,Event,ADDED,eval-conflicts-rho010-r4-087-trdn4.18d466ccc7167a3a,reason=Started count=1 msg=Started container task
0.4373,Event,ADDED,eval-conflicts-rho010-r4-087.18d466cca4b2b434,reason=SuccessfulCreate count=1 msg=Created pod: eval-conflicts-rho010-r4-087-trdn4
0.4376,Event,ADDED,eval-conflicts-rho010-r4-087.18d466cfefc860ff,reason=Completed count=1 msg=Job completed
0.4378,Event,ADDED,eval-conflicts-rho010-r4-088-44xkz.18d466cce08dccec,reason=Scheduled count=None msg=Successfully assigned compute/eval-conflicts-rho010-r4-088-44xkz to kind-worker4
0.438,Event,ADDED,eval-conflicts-rho010-r4-088-44xkz.18d466ccfa1081f2,"reason=Pulled count=1 msg=Container image ""busybox:musl"" already present on machine"
0.4382,Event,ADDED,eval-conflicts-rho010-r4-088-44xkz.18d466ccfb40bc21,reason=Created count=1 msg=Created container: task
0.4384,Event,ADDED,eval-conflicts-rho010-r4-088-44xkz.18d466cd014e8a8b,reason=Started count=1 msg=Started container task
0.4387,Event,ADDED,eval-conflicts-rho010-r4-088.18d466ccdf67a617,reason=SuccessfulCreate count=1 msg=Created pod: eval-conflicts-rho010-r4-088-44xkz
0.4389,Event,ADDED,eval-conflicts-rho010-r4-088.18d466d046f5ad52,reason=Completed count=1 msg=Job completed
0.439,Event,ADDED,eval-conflicts-rho010-r4-089-599rf.18d466cd1c81a313,reason=Scheduled count=None msg=Successfully assigned compute/eval-conflicts-rho010-r4-089-599rf to kind-worker4
0.4393,Event,ADDED,eval-conflicts-rho010-r4-089-599rf.18d466cd3631e82f,"reason=Pulled count=1 msg=Container image ""busybox:musl"" already present on machine"
0.4395,Event,ADDED,eval-conflicts-rho010-r4-089-599rf.18d466cd374117f5,reason=Created count=1 msg=Created container: task
0.4396,Event,ADDED,eval-conflicts-rho010-r4-089-599rf.18d466cd3940c591,reason=Started count=1 msg=Started container task
0.4398,Event,ADDED,eval-conflicts-rho010-r4-089.18d466cd1b1863b6,reason=SuccessfulCreate count=1 msg=Created pod: eval-conflicts-rho010-r4-089-599rf
0.44,Event,ADDED,eval-conflicts-rho010-r4-089.18d466d047bb47e9,reason=Completed count=1 msg=Job completed
0.4401,Event,ADDED,eval-conflicts-rho010-r4-090-x84fj.18d466cd5811d859,reason=Scheduled count=None msg=Successfully assigned compute/eval-conflicts-rho010-r4-090-x84fj to kind-worker4
0.4403,Event,ADDED,eval-conflicts-rho010-r4-090-x84fj.18d466cd70661bb9,"reason=Pulled count=1 msg=Container image ""busybox:musl"" already present on machine"
0.4405,Event,ADDED,eval-conflicts-rho010-r4-090-x84fj.18d466cd7184a92e,reason=Created count=1 msg=Created container: task
0.4407,Event,ADDED,eval-conflicts-rho010-r4-090-x84fj.18d466cd739131ce,reason=Started count=1 msg=Started container task
0.4408,Event,ADDED,eval-conflicts-rho010-r4-090.18d466cd56a0cb2d,reason=SuccessfulCreate count=1 msg=Created pod: eval-conflicts-rho010-r4-090-x84fj
0.441,Event,ADDED,eval-conflicts-rho010-r4-090.18d466d0835ba4c8,reason=Completed count=1 msg=Job completed
0.4412,Event,ADDED,eval-conflicts-rho010-r4-091-vc9t7.18d466cd93a1e9b4,reason=Scheduled count=None msg=Successfully assigned compute/eval-conflicts-rho010-r4-091-vc9t7 to kind-worker
0.4415,Event,ADDED,eval-conflicts-rho010-r4-091-vc9t7.18d466cdadb5cea0,"reason=Pulled count=1 msg=Container image ""busybox:musl"" already present on machine"
0.4418,Event,ADDED,eval-conflicts-rho010-r4-091-vc9t7.18d466cdaedded28,reason=Created count=1 msg=Created container: task
0.442,Event,ADDED,eval-conflicts-rho010-r4-091-vc9t7.18d466cdb0e37e89,reason=Started count=1 msg=Started container task
0.4423,Event,ADDED,eval-conflicts-rho010-r4-091.18d466cd925cf0a2,reason=SuccessfulCreate count=1 msg=Created pod: eval-conflicts-rho010-r4-091-vc9t7
0.4424,Event,ADDED,eval-conflicts-rho010-r4-091.18d466d0e5c5d308,reason=Completed count=1 msg=Job completed
0.4426,Event,ADDED,eval-conflicts-rho010-r4-092-j7mvc.18d466cdcf320946,reason=Scheduled count=None msg=Successfully assigned compute/eval-conflicts-rho010-r4-092-j7mvc to kind-worker4
0.4431,Event,ADDED,eval-conflicts-rho010-r4-092-j7mvc.18d466cde947bbe7,"reason=Pulled count=1 msg=Container image ""busybox:musl"" already present on machine"
0.4434,Event,ADDED,eval-conflicts-rho010-r4-092-j7mvc.18d466cdea75ef5d,reason=Created count=1 msg=Created container: task
0.4435,Event,ADDED,eval-conflicts-rho010-r4-092-j7mvc.18d466cdecfad227,reason=Started count=1 msg=Started container task
0.4437,Event,ADDED,eval-conflicts-rho010-r4-092.18d466cdcde36572,reason=SuccessfulCreate count=1 msg=Created pod: eval-conflicts-rho010-r4-092-j7mvc
0.444,Event,ADDED,eval-conflicts-rho010-r4-092.18d466d0faa86bc8,reason=Completed count=1 msg=Job completed
0.4442,Event,ADDED,eval-conflicts-rho010-r4-093-cxvvz.18d466ce09fb392e,"reason=FailedScheduling count=None msg=0/6 nodes are available: 2 c_wall violated: 1 conflicting context pair(s) with node memory, 4 node(s) had untolerated taint(s). no new claims to deallocate, preemption: 0/6 nodes are available: 2 No preemption victims found for incoming pod, 4 Preemption is not helpful for scheduling."
0.4444,Event,ADDED,eval-conflicts-rho010-r4-093-cxvvz.18d466ce0aba81bf,"reason=FailedScheduling count=None msg=0/6 nodes are available: 2 c_wall violated: 1 conflicting context pair(s) with node memory, 4 node(s) had untolerated taint(s). no new claims to deallocate, preemption: 0/6 nodes are available: 2 No preemption victims found for incoming pod, 4 Preemption is not helpful for scheduling."
0.4446,Event,ADDED,eval-conflicts-rho010-r4-093-cxvvz.18d466ce4066f960,"reason=FailedScheduling count=None msg=0/6 nodes are available: 1 c_wall violated: 1 conflicting context pair(s) with node memory, 5 node(s) had untolerated taint(s). no new claims to deallocate, preemption: 0/6 nodes are available: 1 No preemption victims found for incoming pod, 5 Preemption is not helpful for scheduling."
0.4448,Event,ADDED,eval-conflicts-rho010-r4-093-cxvvz.18d466ce8b7362a5,reason=Scheduled count=None msg=Successfully assigned compute/eval-conflicts-rho010-r4-093-cxvvz to kind-worker2
0.4449,Event,ADDED,eval-conflicts-rho010-r4-093-cxvvz.18d466cea40d3195,"reason=Pulled count=1 msg=Container image ""busybox:musl"" already present on machine"
0.4451,Event,ADDED,eval-conflicts-rho010-r4-093-cxvvz.18d466cea534cb99,reason=Created count=1 msg=Created container: task
0.4453,Event,ADDED,eval-conflicts-rho010-r4-093-cxvvz.18d466cea8d2e6c5,reason=Started count=1 msg=Started container task
0.4454,Event,ADDED,eval-conflicts-rho010-r4-093.18d466ce098f9b60,reason=SuccessfulCreate count=1 msg=Created pod: eval-conflicts-rho010-r4-093-cxvvz
0.4456,Event,ADDED,eval-conflicts-rho010-r4-093.18d466d1e2c4c624,reason=Completed count=1 msg=Job completed
0.4458,Event,ADDED,eval-conflicts-rho010-r4-094-dcn45.18d466ce45c826df,reason=Scheduled count=None msg=Successfully assigned compute/eval-conflicts-rho010-r4-094-dcn45 to kind-worker4
0.4459,Event,ADDED,eval-conflicts-rho010-r4-094-dcn45.18d466ce5f80cf26,"reason=Pulled count=1 msg=Container image ""busybox:musl"" already present on machine"
0.4461,Event,ADDED,eval-conflicts-rho010-r4-094-dcn45.18d466ce60983861,reason=Created count=1 msg=Created container: task
0.4463,Event,ADDED,eval-conflicts-rho010-r4-094-dcn45.18d466ce62854bd3,reason=Started count=1 msg=Started container task
0.4464,Event,ADDED,eval-conflicts-rho010-r4-094.18d466ce4554027a,reason=SuccessfulCreate count=1 msg=Created pod: eval-conflicts-rho010-r4-094-dcn45
0.4466,Event,ADDED,eval-conflicts-rho010-r4-094.18d466d1725817c5,reason=Completed count=1 msg=Job completed
0.4468,Event,ADDED,eval-conflicts-rho010-r4-095-xhspn.18d466ce80999bd9,"reason=FailedScheduling count=None msg=0/6 nodes are available: 6 node(s) had untolerated taint(s). no new claims to deallocate, preemption: 0/6 nodes are available: 6 Preemption is not helpful for scheduling."
0.4469,Event,ADDED,eval-conflicts-rho010-r4-095-xhspn.18d466ce8b57d332,"reason=FailedScheduling count=None msg=0/6 nodes are available: 1 c_wall violated: 1 conflicting context pair(s) with node memory, 5 node(s) had untolerated taint(s). no new claims to deallocate, preemption: 0/6 nodes are available: 1 No preemption victims found for incoming pod, 5 Preemption is not helpful for scheduling."
0.4471,Event,ADDED,eval-conflicts-rho010-r4-095-xhspn.18d466ce8c3fdb3e,"reason=FailedScheduling count=None msg=0/6 nodes are available: 1 c_wall violated: 1 conflicting context pair(s) with node memory, 5 node(s) had untolerated taint(s). no new claims to deallocate, preemption: 0/6 nodes are available: 1 No preemption victims found for incoming pod, 5 Preemption is not helpful for scheduling."
0.4473,Event,ADDED,eval-conflicts-rho010-r4-095-xhspn.18d466ced9cb2820,reason=Scheduled count=None msg=Successfully assigned compute/eval-conflicts-rho010-r4-095-xhspn to kind-worker5
0.4474,Event,ADDED,eval-conflicts-rho010-r4-095-xhspn.18d466cef26b5d54,"reason=Pulled count=1 msg=Container image ""busybox:musl"" already present on machine"
0.4476,Event,ADDED,eval-conflicts-rho010-r4-095-xhspn.18d466cef3a086d1,reason=Created count=1 msg=Created container: task
0.4478,Event,ADDED,eval-conflicts-rho010-r4-095-xhspn.18d466cef8131ebd,reason=Started count=1 msg=Started container task
0.4479,Event,ADDED,eval-conflicts-rho010-r4-095.18d466ce808dbe45,reason=SuccessfulCreate count=1 msg=Created pod: eval-conflicts-rho010-r4-095-xhspn
0.4481,Event,ADDED,eval-conflicts-rho010-r4-095.18d466d21eecdc35,reason=Completed count=1 msg=Job completed
0.4483,Event,ADDED,eval-conflicts-rho010-r4-096-p8kpq.18d466cebcab9f30,reason=Scheduled count=None msg=Successfully assigned compute/eval-conflicts-rho010-r4-096-p8kpq to kind-worker2
0.4484,Event,ADDED,eval-conflicts-rho010-r4-096-p8kpq.18d466ced564bfe2,"reason=Pulled count=1 msg=Container image ""busybox:musl"" already present on machine"
0.4486,Event,ADDED,eval-conflicts-rho010-r4-096-p8kpq.18d466ced6cecee8,reason=Created count=1 msg=Created container: task
0.4488,Event,ADDED,eval-conflicts-rho010-r4-096-p8kpq.18d466cedd7b2c15,reason=Started count=1 msg=Started container task
0.4489,Event,ADDED,eval-conflicts-rho010-r4-096.18d466cebc1f5707,reason=SuccessfulCreate count=1 msg=Created pod: eval-conflicts-rho010-r4-096-p8kpq
0.4491,Event,ADDED,eval-conflicts-rho010-r4-096.18d466d21ec8d192,reason=Completed count=1 msg=Job completed
0.4492,Event,ADDED,eval-conflicts-rho010-r4-097-7g6j8.18d466cef858f3c1,"reason=FailedScheduling count=None msg=0/6 nodes are available: 2 c_wall violated: 1 conflicting context pair(s) with node memory, 4 node(s) had untolerated taint(s). no new claims to deallocate, preemption: 0/6 nodes are available: 2 No preemption victims found for incoming pod, 4 Preemption is not helpful for scheduling."
0.4495,Event,ADDED,eval-conflicts-rho010-r4-097-7g6j8.18d466cef901fa24,"reason=FailedScheduling count=None msg=0/6 nodes are available: 2 c_wall violated: 1 conflicting context pair(s) with node memory, 4 node(s) had untolerated taint(s). no new claims to deallocate, preemption: 0/6 nodes are available: 2 No preemption victims found for incoming pod, 4 Preemption is not helpful for scheduling."
0.4497,Event,ADDED,eval-conflicts-rho010-r4-097-7g6j8.18d466d0a5889699,reason=Scheduled count=None msg=Successfully assigned compute/eval-conflicts-rho010-r4-097-7g6j8 to kind-worker3
0.4499,Event,ADDED,eval-conflicts-rho010-r4-097-7g6j8.18d466d0be0858e4,"reason=Pulled count=1 msg=Container image ""busybox:musl"" already present on machine"
0.4501,Event,ADDED,eval-conflicts-rho010-r4-097-7g6j8.18d466d0bf594a61,reason=Created count=1 msg=Created container: task
0.4503,Event,ADDED,eval-conflicts-rho010-r4-097-7g6j8.18d466d0c14275da,reason=Started count=1 msg=Started container task
0.4504,Event,ADDED,eval-conflicts-rho010-r4-097.18d466cef7ef2eca,reason=SuccessfulCreate count=1 msg=Created pod: eval-conflicts-rho010-r4-097-7g6j8
0.4506,Event,ADDED,eval-conflicts-rho010-r4-097.18d466d3e74a38c5,reason=Completed count=1 msg=Job completed
0.4508,Event,ADDED,eval-conflicts-rho010-r4-098-484d2.18d466cf34fec2fb,reason=Scheduled count=None msg=Successfully assigned compute/eval-conflicts-rho010-r4-098-484d2 to kind-worker5
0.451,Event,ADDED,eval-conflicts-rho010-r4-098-484d2.18d466cf4d974bbd,"reason=Pulled count=1 msg=Container image ""busybox:musl"" already present on machine"
0.4511,Event,ADDED,eval-conflicts-rho010-r4-098-484d2.18d466cf4ec2ae80,reason=Created count=1 msg=Created container: task
0.4513,Event,ADDED,eval-conflicts-rho010-r4-098-484d2.18d466cf53c1e16d,reason=Started count=1 msg=Started container task
0.4515,Event,ADDED,eval-conflicts-rho010-r4-098.18d466cf33c28674,reason=SuccessfulCreate count=1 msg=Created pod: eval-conflicts-rho010-r4-098-484d2
0.4516,Event,ADDED,eval-conflicts-rho010-r4-098.18d466d29631915a,reason=Completed count=1 msg=Job completed
0.4519,Event,ADDED,eval-conflicts-rho010-r4-099-r9tph.18d466cf6fd35972,reason=Scheduled count=None msg=Successfully assigned compute/eval-conflicts-rho010-r4-099-r9tph to kind-worker5
0.4521,Event,ADDED,eval-conflicts-rho010-r4-099-r9tph.18d466cf88b96476,"reason=Pulled count=1 msg=Container image ""busybox:musl"" already present on machine"
0.4522,Event,ADDED,eval-conflicts-rho010-r4-099-r9tph.18d466cf89e10f87,reason=Created count=1 msg=Created container: task
0.4524,Event,ADDED,eval-conflicts-rho010-r4-099-r9tph.18d466cf8c64c286,reason=Started count=1 msg=Started container task
0.4526,Event,ADDED,eval-conflicts-rho010-r4-099.18d466cf6efc7622,reason=SuccessfulCreate count=1 msg=Created pod: eval-conflicts-rho010-r4-099-r9tph
0.4527,Event,ADDED,eval-conflicts-rho010-r4-099.18d466d2d20236b4,reason=Completed count=1 msg=Job completed
0.4529,Event,ADDED,eval-conflicts-rho010-r5-000-pl8k2.18d466d9326363e7,reason=Scheduled count=None msg=Successfully assigned compute/eval-conflicts-rho010-r5-000-pl8k2 to kind-worker2
0.4531,Event,ADDED,eval-conflicts-rho010-r5-000-pl8k2.18d466d94b9e12b3,"reason=Pulled count=1 msg=Container image ""busybox:musl"" already present on machine"
0.4532,Event,ADDED,eval-conflicts-rho010-r5-000-pl8k2.18d466d94cdb475c,reason=Created count=1 msg=Created container: task
0.4534,Event,ADDED,eval-conflicts-rho010-r5-000-pl8k2.18d466d94fdf8d09,reason=Started count=1 msg=Started container task
0.4536,Event,ADDED,eval-conflicts-rho010-r5-000.18d466d9315d784d,reason=SuccessfulCreate count=1 msg=Created pod: eval-conflicts-rho010-r5-000-pl8k2
0.4537,Event,ADDED,eval-conflicts-rho010-r5-000.18d466dc62c66c9f,reason=Completed count=1 msg=Job completed
0.4539,Event,ADDED,eval-conflicts-rho010-r5-001-rxrgl.18d466d96d5e0583,reason=Scheduled count=None msg=Successfully assigned compute/eval-conflicts-rho010-r5-001-rxrgl to kind-worker5
0.454,Event,ADDED,eval-conflicts-rho010-r5-001-rxrgl.18d466d9866cb2c4,"reason=Pulled count=1 msg=Container image ""busybox:musl"" already present on machine"
0.4542,Event,ADDED,eval-conflicts-rho010-r5-001-rxrgl.18d466d9878427e1,reason=Created count=1 msg=Created container: task
0.4544,Event,ADDED,eval-conflicts-rho010-r5-001-rxrgl.18d466d9898d48c7,reason=Started count=1 msg=Started container task
0.4545,Event,ADDED,eval-conflicts-rho010-r5-001.18d466d96c54a0de,reason=SuccessfulCreate count=1 msg=Created pod: eval-conflicts-rho010-r5-001-rxrgl
0.4547,Event,ADDED,eval-conflicts-rho010-r5-001.18d466dc9f78d7b3,reason=Completed count=1 msg=Job completed
0.4548,Event,ADDED,eval-conflicts-rho010-r5-002-tfvg2.18d466d9a9b9685f,reason=Scheduled count=None msg=Successfully assigned compute/eval-conflicts-rho010-r5-002-tfvg2 to kind-worker
0.455,Event,ADDED,eval-conflicts-rho010-r5-002-tfvg2.18d466d9c31816de,"reason=Pulled count=1 msg=Container image ""busybox:musl"" already present on machine"
0.4552,Event,ADDED,eval-conflicts-rho010-r5-002-tfvg2.18d466d9c429c0bf,reason=Created count=1 msg=Created container: task
0.4553,Event,ADDED,eval-conflicts-rho010-r5-002-tfvg2.18d466d9c7ed69c9,reason=Started count=1 msg=Started container task
0.4555,Event,ADDED,eval-conflicts-rho010-r5-002.18d466d9a8ac399b,reason=SuccessfulCreate count=1 msg=Created pod: eval-conflicts-rho010-r5-002-tfvg2
0.4557,Event,ADDED,eval-conflicts-rho010-r5-002.18d466dd090d77f6,reason=Completed count=1 msg=Job completed
0.4558,Event,ADDED,eval-conflicts-rho010-r5-003-8j7hc.18d466d9e44acf16,reason=Scheduled count=None msg=Successfully assigned compute/eval-conflicts-rho010-r5-003-8j7hc to kind-worker5
0.456,Event,ADDED,eval-conflicts-rho010-r5-003-8j7hc.18d466d9fd618d84,"reason=Pulled count=1 msg=Container image ""busybox:musl"" already present on machine"
0.4562,Event,ADDED,eval-conflicts-rho010-r5-003-8j7hc.18d466d9fe9acb6e,reason=Created count=1 msg=Created container: task
0.4563,Event,ADDED,eval-conflicts-rho010-r5-003-8j7hc.18d466da00bfdb65,reason=Started count=1 msg=Started container task
0.4565,Event,ADDED,eval-conflicts-rho010-r5-003.18d466d9e35df7df,reason=SuccessfulCreate count=1 msg=Created pod: eval-conflicts-rho010-r5-003-8j7hc
0.4566,Event,ADDED,eval-conflicts-rho010-r5-003.18d466dd1761cb1b,reason=Completed count=1 msg=Job completed
0.4568,Event,ADDED,eval-conflicts-rho010-r5-004-s5nst.18d466da1f9feb66,reason=Scheduled count=None msg=Successfully assigned compute/eval-conflicts-rho010-r5-004-s5nst to kind-worker2
0.457,Event,ADDED,eval-conflicts-rho010-r5-004-s5nst.18d466da37d52343,"reason=Pulled count=1 msg=Container image ""busybox:musl"" already present on machine"
0.4573,Event,ADDED,eval-conflicts-rho010-r5-004-s5nst.18d466da38f1136a,reason=Created count=1 msg=Created container: task
0.4579,Event,ADDED,eval-conflicts-rho010-r5-004-s5nst.18d466da3aebbdb3,reason=Started count=1 msg=Started container task
0.4581,Event,ADDED,eval-conflicts-rho010-r5-004.18d466da1eba70be,reason=SuccessfulCreate count=1 msg=Created pod: eval-conflicts-rho010-r5-004-s5nst
0.4582,Event,ADDED,eval-conflicts-rho010-r5-004.18d466dd526fb948,reason=Completed count=1 msg=Job completed
0.4584,Event,ADDED,eval-conflicts-rho010-r5-005-rqk55.18d466da5b0c34eb,reason=Scheduled count=None msg=Successfully assigned compute/eval-conflicts-rho010-r5-005-rqk55 to kind-worker5
0.4588,Event,ADDED,eval-conflicts-rho010-r5-005-rqk55.18d466da741d503f,"reason=Pulled count=1 msg=Container image ""busybox:musl"" already present on machine"
0.459,Event,ADDED,eval-conflicts-rho010-r5-005-rqk55.18d466da7525341d,reason=Created count=1 msg=Created container: task
0.4593,Event,ADDED,eval-conflicts-rho010-r5-005-rqk55.18d466da7715d7ad,reason=Started count=1 msg=Started container task
0.4599,Event,ADDED,eval-conflicts-rho010-r5-005.18d466da5a3ffbcf,reason=SuccessfulCreate count=1 msg=Created pod: eval-conflicts-rho010-r5-005-rqk55
0.4602,Event,ADDED,eval-conflicts-rho010-r5-005.18d466dd8f0c7f2d,reason=Completed count=1 msg=Job completed
0.4604,Event,ADDED,eval-conflicts-rho010-r5-006-7j56n.18d466da96ebcd94,reason=Scheduled count=None msg=Successfully assigned compute/eval-conflicts-rho010-r5-006-7j56n to kind-worker4
0.4606,Event,ADDED,eval-conflicts-rho010-r5-006-7j56n.18d466dab0424229,"reason=Pulled count=1 msg=Container image ""busybox:musl"" already present on machine"
0.4609,Event,ADDED,eval-conflicts-rho010-r5-006-7j56n.18d466dab15c7e2f,reason=Created count=1 msg=Created container: task
0.4611,Event,ADDED,eval-conflicts-rho010-r5-006-7j56n.18d466dab3903fc0,reason=Started count=1 msg=Started container task
0.4612,Event,ADDED,eval-conflicts-rho010-r5-006.18d466da9621d3d2,reason=SuccessfulCreate count=1 msg=Created pod: eval-conflicts-rho010-r5-006-7j56n
0.4615,Event,ADDED,eval-conflicts-rho010-r5-006.18d466ddd0b32fc1,reason=Completed count=1 msg=Job completed
0.4625,Event,ADDED,eval-conflicts-rho010-r5-007-mrcnp.18d466dad2519277,reason=Scheduled count=None msg=Successfully assigned compute/eval-conflicts-rho010-r5-007-mrcnp to kind-worker4
0.4627,Event,ADDED,eval-conflicts-rho010-r5-007-mrcnp.18d466daeb39f6de,"reason=Pulled count=1 msg=Container image ""busybox:musl"" already present on machine"
0.4628,Event,ADDED,eval-conflicts-rho010-r5-007-mrcnp.18d466daec5a14b3,reason=Created count=1 msg=Created container: task
0.4631,Event,ADDED,eval-conflicts-rho010-r5-007-mrcnp.18d466daefeb274e,reason=Started count=1 msg=Started container task
0.4633,Event,ADDED,eval-conflicts-rho010-r5-007.18d466dad18e3385,reason=SuccessfulCreate count=1 msg=Created pod: eval-conflicts-rho010-r5-007-mrcnp
0.4635,Event,ADDED,eval-conflicts-rho010-r5-007.18d466de0c9c7fe2,reason=Completed count=1 msg=Job completed
0.4636,Event,ADDED,eval-conflicts-rho010-r5-008-45jpp.18d466db0dfff10f,reason=Scheduled count=None msg=Successfully assigned compute/eval-conflicts-rho010-r5-008-45jpp to kind-worker4
0.4639,Event,ADDED,eval-conflicts-rho010-r5-008-45jpp.18d466db269b1f3f,"reason=Pulled count=1 msg=Container image ""busybox:musl"" already present on machine"
0.4641,Event,ADDED,eval-conflicts-rho010-r5-008-45jpp.18d466db27be58ff,reason=Created count=1 msg=Created container: task
0.4642,Event,ADDED,eval-conflicts-rho010-r5-008-45jpp.18d466db2c3e0e79,reason=Started count=1 msg=Started container task
0.4647,Event,ADDED,eval-conflicts-rho010-r5-008.18d466db0d35cfa8,reason=SuccessfulCreate count=1 msg=Created pod: eval-conflicts-rho010-r5-008-45jpp
0.465,Event,ADDED,eval-conflicts-rho010-r5-008.18d466de47f85c53,reason=Completed count=1 msg=Job completed
0.4652,Event,ADDED,eval-conflicts-rho010-r5-009-jf85t.18d466db4b267d96,reason=Scheduled count=None msg=Successfully assigned compute/eval-conflicts-rho010-r5-009-jf85t to kind-worker4
0.4655,Event,ADDED,eval-conflicts-rho010-r5-009-jf85t.18d466db64571633,"reason=Pulled count=1 msg=Container image ""busybox:musl"" already present on machine"
0.4658,Event,ADDED,eval-conflicts-rho010-r5-009-jf85t.18d466db6589b764,reason=Created count=1 msg=Created container: task
0.466,Event,ADDED,eval-conflicts-rho010-r5-009-jf85t.18d466db67aa382b,reason=Started count=1 msg=Started container task
0.4662,Event,ADDED,eval-conflicts-rho010-r5-009.18d466db498e6085,reason=SuccessfulCreate count=1 msg=Created pod: eval-conflicts-rho010-r5-009-jf85t
0.4664,Event,ADDED,eval-conflicts-rho010-r5-009.18d466de83e0f13c,reason=Completed count=1 msg=Job completed
0.4666,Event,ADDED,eval-conflicts-rho010-r5-010-n7m4m.18d466db8552adf3,reason=Scheduled count=None msg=Successfully assigned compute/eval-conflicts-rho010-r5-010-n7m4m to kind-worker3
0.4668,Event,ADDED,eval-conflicts-rho010-r5-010-n7m4m.18d466db9e0e0af2,"reason=Pulled count=1 msg=Container image ""busybox:musl"" already present on machine"
0.467,Event,ADDED,eval-conflicts-rho010-r5-010-n7m4m.18d466db9f794190,reason=Created count=1 msg=Created container: task
0.4672,Event,ADDED,eval-conflicts-rho010-r5-010-n7m4m.18d466dba41a5fe2,reason=Started count=1 msg=Started container task
0.4674,Event,ADDED,eval-conflicts-rho010-r5-010.18d466db849984ff,reason=SuccessfulCreate count=1 msg=Created pod: eval-conflicts-rho010-r5-010-n7m4m
0.4678,Event,ADDED,eval-conflicts-rho010-r5-010.18d466dede4049e6,reason=Completed count=1 msg=Job completed
0.468,Event,ADDED,eval-conflicts-rho010-r5-011-bpzt6.18d466dbc17c904c,reason=Scheduled count=None msg=Successfully assigned compute/eval-conflicts-rho010-r5-011-bpzt6 to kind-worker3
0.4682,Event,ADDED,eval-conflicts-rho010-r5-011-bpzt6.18d466dbdb331e17,"reason=Pulled count=1 msg=Container image ""busybox:musl"" already present on machine"
0.4683,Event,ADDED,eval-conflicts-rho010-r5-011-bpzt6.18d466dbdc56c358,reason=Created count=1 msg=Created container: task
0.4685,Event,ADDED,eval-conflicts-rho010-r5-011-bpzt6.18d466dbe111a084,reason=Started count=1 msg=Started container task
0.4687,Event,ADDED,eval-conflicts-rho010-r5-011.18d466dbc06a74c5,reason=SuccessfulCreate count=1 msg=Created pod: eval-conflicts-rho010-r5-011-bpzt6
0.4689,Event,ADDED,eval-conflicts-rho010-r5-011.18d466df1a2b7bbc,reason=Completed count=1 msg=Job completed
0.4691,Event,ADDED,eval-conflicts-rho010-r5-012-nwrqd.18d466dbfc8c7c8b,reason=Scheduled count=None msg=Successfully assigned compute/eval-conflicts-rho010-r5-012-nwrqd to kind-worker3
0.4693,Event,ADDED,eval-conflicts-rho010-r5-012-nwrqd.18d466dc155ad5fd,"reason=Pulled count=1 msg=Container image ""busybox:musl"" already present on machine"
0.4696,Event,ADDED,eval-conflicts-rho010-r5-012-nwrqd.18d466dc16b6635c,reason=Created count=1 msg=Created container: task
0.4698,Event,ADDED,eval-conflicts-rho010-r5-012-nwrqd.18d466dc1b911af1,reason=Started count=1 msg=Started container task
0.47,Event,ADDED,eval-conflicts-rho010-r5-012.18d466dbfb91a5be,reason=SuccessfulCreate count=1 msg=Created pod: eval-conflicts-rho010-r5-012-nwrqd
0.4702,Event,ADDED,eval-conflicts-rho010-r5-012.18d466df55facd99,reason=Completed count=1 msg=Job completed
0.4705,Event,ADDED,eval-conflicts-rho010-r5-013-szwpk.18d466dc38894668,reason=Scheduled count=None msg=Successfully assigned compute/eval-conflicts-rho010-r5-013-szwpk to kind-worker3
0.4707,Event,ADDED,eval-conflicts-rho010-r5-013-szwpk.18d466dc517c7c1a,"reason=Pulled count=1 msg=Container image ""busybox:musl"" already present on machine"
0.4708,Event,ADDED,eval-conflicts-rho010-r5-013-szwpk.18d466dc528525b7,reason=Created count=1 msg=Created container: task
0.471,Event,ADDED,eval-conflicts-rho010-r5-013-szwpk.18d466dc546ead59,reason=Started count=1 msg=Started container task
0.4712,Event,ADDED,eval-conflicts-rho010-r5-013.18d466dc37c38dd8,reason=SuccessfulCreate count=1 msg=Created pod: eval-conflicts-rho010-r5-013-szwpk
0.4714,Event,ADDED,eval-conflicts-rho010-r5-013.18d466df91e13746,reason=Completed count=1 msg=Job completed
0.4715,Event,ADDED,eval-conflicts-rho010-r5-014-skrqs.18d466dc733ebe0c,reason=Scheduled count=None msg=Successfully assigned compute/eval-conflicts-rho010-r5-014-skrqs to kind-worker4
0.4717,Event,ADDED,eval-conflicts-rho010-r5-014-skrqs.18d466dc8cec3fbb,"reason=Pulled count=1 msg=Container image ""busybox:musl"" already present on machine"
0.4719,Event,ADDED,eval-conflicts-rho010-r5-014-skrqs.18d466dc8e1c048c,reason=Created count=1 msg=Created container: task
0.472,Event,ADDED,eval-conflicts-rho010-r5-014-skrqs.18d466dc917b9dab,reason=Started count=1 msg=Started container task
0.4722,Event,ADDED,eval-conflicts-rho010-r5-014.18d466dc72b04676,reason=SuccessfulCreate count=1 msg=Created pod: eval-conflicts-rho010-r5-014-skrqs
0.4724,Event,ADDED,eval-conflicts-rho010-r5-014.18d466dfaee658ea,reason=Completed count=1 msg=Job completed
0.4725,Event,ADDED,eval-conflicts-rho010-r5-015-7fnkt.18d466dcaf0de65c,"reason=FailedScheduling count=None msg=0/6 nodes are available: 6 node(s) had untolerated taint(s). no new claims to deallocate, preemption: 0/6 nodes are available: 6 Preemption is not helpful for scheduling."
0.4727,Event,ADDED,eval-conflicts-rho010-r5-015-7fnkt.18d466de7df220a4,reason=Scheduled count=None msg=Successfully assigned compute/eval-conflicts-rho010-r5-015-7fnkt to kind-worker
0.4729,Event,ADDED,eval-conflicts-rho010-r5-015-7fnkt.18d466de9700b933,"reason=Pulled count=1 msg=Container image ""busybox:musl"" already present on machine"
0.473,Event,ADDED,eval-conflicts-rho010-r5-015-7fnkt.18d466de986d49f8,reason=Created count=1 msg=Created container: task
0.4733,Event,ADDED,eval-conflicts-rho010-r5-015-7fnkt.18d466de9d1e2ce2,reason=Started count=1 msg=Started container task
0.4735,Event,ADDED,eval-conflicts-rho010-r5-015.18d466dcaeff54d0,reason=SuccessfulCreate count=1 msg=Created pod: eval-conflicts-rho010-r5-015-7fnkt
0.4737,Event,ADDED,eval-conflicts-rho010-r5-015.18d466e1b81531c9,reason=Completed count=1 msg=Job completed
0.4739,Event,ADDED,eval-conflicts-rho010-r5-016-n99rg.18d466dcea2f707c,"reason=FailedScheduling count=None msg=0/6 nodes are available: 6 node(s) had untolerated taint(s). no new claims to deallocate, preemption: 0/6 nodes are available: 6 Preemption is not helpful for scheduling."
0.474,Event,ADDED,eval-conflicts-rho010-r5-016-n99rg.18d466de7ea29842,reason=Scheduled count=None msg=Successfully assigned compute/eval-conflicts-rho010-r5-016-n99rg to kind-worker
0.4744,Event,ADDED,eval-conflicts-rho010-r5-016-n99rg.18d466de9825faf9,"reason=Pulled count=1 msg=Container image ""busybox:musl"" already present on machine"
0.4745,Event,ADDED,eval-conflicts-rho010-r5-016-n99rg.18d466de99ca1890,reason=Created count=1 msg=Created container: task
0.4747,Event,ADDED,eval-conflicts-rho010-r5-016-n99rg.18d466de9dc7680d,reason=Started count=1 msg=Started container task
0.4749,Event,ADDED,eval-conflicts-rho010-r5-016.18d466dcea246465,reason=SuccessfulCreate count=1 msg=Created pod: eval-conflicts-rho010-r5-016-n99rg
0.475,Event,ADDED,eval-conflicts-rho010-r5-016.18d466e1b813849e,reason=Completed count=1 msg=Job completed
0.4752,Event,ADDED,eval-conflicts-rho010-r5-017-nzkqc.18d466dd25e6f590,"reason=FailedScheduling count=None msg=0/6 nodes are available: 6 node(s) had untolerated taint(s). no new claims to deallocate, preemption: 0/6 nodes are available: 6 Preemption is not helpful for scheduling."
0.4753,Event,ADDED,eval-conflicts-rho010-r5-017-nzkqc.18d466de7ec77045,reason=Scheduled count=None msg=Successfully assigned compute/eval-conflicts-rho010-r5-017-nzkqc to kind-worker
0.4755,Event,ADDED,eval-conflicts-rho010-r5-017-nzkqc.18d466de980d7452,"reason=Pulled count=1 msg=Container image ""busybox:musl"" already present on machine"
0.4757,Event,ADDED,eval-conflicts-rho010-r5-017-nzkqc.18d466de99977725,reason=Created count=1 msg=Created container: task
0.4759,Event,ADDED,eval-conflicts-rho010-r5-017-nzkqc.18d466de9dc65261,reason=Started count=1 msg=Started container task
0.4761,Event,ADDED,eval-conflicts-rho010-r5-017.18d466dd25d908e0,reason=SuccessfulCreate count=1 msg=Created pod: eval-conflicts-rho010-r5-017-nzkqc
0.4764,Event,ADDED,eval-conflicts-rho010-r5-017.18d466e1b81711be,reason=Completed count=1 msg=Job completed
0.4766,Event,ADDED,eval-conflicts-rho010-r5-018-rs8fj.18d466dd6137bf73,"reason=FailedScheduling count=None msg=0/6 nodes are available: 6 node(s) had untolerated taint(s). no new claims to deallocate, preemption: 0/6 nodes are available: 6 Preemption is not helpful for scheduling."
0.4768,Event,ADDED,eval-conflicts-rho010-r5-018-rs8fj.18d466de7eb0abc0,"reason=FailedScheduling count=None msg=0/6 nodes are available: 1 c_wall violated: 1 conflicting context pair(s) with node memory, 5 node(s) had untolerated taint(s). no new claims to deallocate, preemption: 0/6 nodes are available: 1 No preemption victims found for incoming pod, 5 Preemption is not helpful for scheduling."
0.477,Event,ADDED,eval-conflicts-rho010-r5-018-rs8fj.18d466de8519c19b,"reason=FailedScheduling count=None msg=0/6 nodes are available: 1 c_wall violated: 1 conflicting context pair(s) with node memory, 5 node(s) had untolerated taint(s). no new claims to deallocate, preemption: 0/6 nodes are available: 1 No preemption victims found for incoming pod, 5 Preemption is not helpful for scheduling."
0.4772,Event,ADDED,eval-conflicts-rho010-r5-018-rs8fj.18d466df0e1b4630,reason=Scheduled count=None msg=Successfully assigned compute/eval-conflicts-rho010-r5-018-rs8fj to kind-worker2
0.4774,Event,ADDED,eval-conflicts-rho010-r5-018-rs8fj.18d466df2a22320c,"reason=Pulled count=1 msg=Container image ""busybox:musl"" already present on machine"
0.4776,Event,ADDED,eval-conflicts-rho010-r5-018-rs8fj.18d466df2b8af07c,reason=Created count=1 msg=Created container: task
0.4779,Event,ADDED,eval-conflicts-rho010-r5-018-rs8fj.18d466df2dfad52e,reason=Started count=1 msg=Started container task
0.4781,Event,ADDED,eval-conflicts-rho010-r5-018.18d466dd612825de,reason=SuccessfulCreate count=1 msg=Created pod: eval-conflicts-rho010-r5-018-rs8fj
0.4782,Event,ADDED,eval-conflicts-rho010-r5-018.18d466e23d489f70,reason=Completed count=1 msg=Job completed
0.4784,Event,ADDED,eval-conflicts-rho010-r5-019-qrl5b.18d466dd9d32e12e,"reason=FailedScheduling count=None msg=0/6 nodes are available: 6 node(s) had untolerated taint(s). no new claims to deallocate, preemption: 0/6 nodes are available: 6 Preemption is not helpful for scheduling."
0.4786,Event,ADDED,eval-conflicts-rho010-r5-019-qrl5b.18d466de7f7e2176,"reason=FailedScheduling count=None msg=0/6 nodes are available: 1 c_wall violated: 1 conflicting context pair(s) with node memory, 5 node(s) had untolerated taint(s). no new claims to deallocate, preemption: 0/6 nodes are available: 1 No preemption victims found for incoming pod, 5 Preemption is not helpful for scheduling."
0.4787,Event,ADDED,eval-conflicts-rho010-r5-019-qrl5b.18d466de85429810,"reason=FailedScheduling count=None msg=0/6 nodes are available: 1 c_wall violated: 1 conflicting context pair(s) with node memory, 5 node(s) had untolerated taint(s). no new claims to deallocate, preemption: 0/6 nodes are available: 1 No preemption victims found for incoming pod, 5 Preemption is not helpful for scheduling."
0.4789,Event,ADDED,eval-conflicts-rho010-r5-019-qrl5b.18d466df020511ac,reason=Scheduled count=None msg=Successfully assigned compute/eval-conflicts-rho010-r5-019-qrl5b to kind-worker2
0.4791,Event,ADDED,eval-conflicts-rho010-r5-019-qrl5b.18d466df1bb674b0,"reason=Pulled count=1 msg=Container image ""busybox:musl"" already present on machine"
0.4792,Event,ADDED,eval-conflicts-rho010-r5-019-qrl5b.18d466df1e84b8fb,reason=Created count=1 msg=Created container: task
0.4794,Event,ADDED,eval-conflicts-rho010-r5-019-qrl5b.18d466df2142e660,reason=Started count=1 msg=Started container task
0.4796,Event,ADDED,eval-conflicts-rho010-r5-019.18d466dd9d2916c5,reason=SuccessfulCreate count=1 msg=Created pod: eval-conflicts-rho010-r5-019-qrl5b
0.4798,Event,ADDED,eval-conflicts-rho010-r5-019.18d466e23b5dbd0e,reason=Completed count=1 msg=Job completed
0.4799,Event,ADDED,eval-conflicts-rho010-r5-020-xmct7.18d466ddd89cca2a,"reason=FailedScheduling count=None msg=0/6 nodes are available: 6 node(s) had untolerated taint(s). no new claims to deallocate, preemption: 0/6 nodes are available: 6 Preemption is not helpful for scheduling."
0.4801,Event,ADDED,eval-conflicts-rho010-r5-020-xmct7.18d466de82885f33,"reason=FailedScheduling count=None msg=0/6 nodes are available: 1 c_wall violated: 1 conflicting context pair(s) with node memory, 5 node(s) had untolerated taint(s). no new claims to deallocate, preemption: 0/6 nodes are available: 1 No preemption victims found for incoming pod, 5 Preemption is not helpful for scheduling."
0.4803,Event,ADDED,eval-conflicts-rho010-r5-020-xmct7.18d466de8567d27c,"reason=FailedScheduling count=None msg=0/6 nodes are available: 1 c_wall violated: 1 conflicting context pair(s) with node memory, 5 node(s) had untolerated taint(s). no new claims to deallocate, preemption: 0/6 nodes are available: 1 No preemption victims found for incoming pod, 5 Preemption is not helpful for scheduling."
0.4805,Event,ADDED,eval-conflicts-rho010-r5-020-xmct7.18d466df0757b567,reason=Scheduled count=None msg=Successfully assigned compute/eval-conflicts-rho010-r5-020-xmct7 to kind-worker2
0.4806,Event,ADDED,eval-conflicts-rho010-r5-020-xmct7.18d466df20f2d998,"reason=Pulled count=1 msg=Container image ""busybox:musl"" already present on machine"
0.4809,Event,ADDED,eval-conflicts-rho010-r5-020-xmct7.18d466df245a77c7,reason=Created count=1 msg=Created container: task
0.4811,Event,ADDED,eval-conflicts-rho010-r5-020-xmct7.18d466df29b674de,reason=Started count=1 msg=Started container task
0.4813,Event,ADDED,eval-conflicts-rho010-r5-020.18d466ddd893eb33,reason=SuccessfulCreate count=1 msg=Created pod: eval-conflicts-rho010-r5-020-xmct7
0.4819,Event,ADDED,eval-conflicts-rho010-r5-020.18d466e277891b16,reason=Completed count=1 msg=Job completed
0.4822,Event,ADDED,eval-conflicts-rho010-r5-021-kpdpd.18d466de140da2ef,"reason=FailedScheduling count=None msg=0/6 nodes are available: 6 node(s) had untolerated taint(s). no new claims to deallocate, preemption: 0/6 nodes are available: 6 Preemption is not helpful for scheduling."
0.4824,Event,ADDED,eval-conflicts-rho010-r5-021-kpdpd.18d466de83ee6928,"reason=FailedScheduling count=None msg=0/6 nodes are available: 1 c_wall violated: 1 conflicting context pair(s) with node memory, 5 node(s) had untolerated taint(s). no new claims to deallocate, preemption: 0/6 nodes are available: 1 No preemption victims found for incoming pod, 5 Preemption is not helpful for scheduling."
0.4826,Event,ADDED,eval-conflicts-rho010-r5-021-kpdpd.18d466de859588cd,"reason=FailedScheduling count=None msg=0/6 nodes are available: 1 c_wall violated: 1 conflicting context pair(s) with node memory, 5 node(s) had untolerated taint(s). no new claims to deallocate, preemption: 0/6 nodes are available: 1 No preemption victims found for incoming pod, 5 Preemption is not helpful for scheduling."
0.4829,Event,ADDED,eval-conflicts-rho010-r5-021-kpdpd.18d466df085aa477,reason=Scheduled count=None msg=Successfully assigned compute/eval-conflicts-rho010-r5-021-kpdpd to kind-worker2
0.4831,Event,ADDED,eval-conflicts-rho010-r5-021-kpdpd.18d466df22b076b9,"reason=Pulled count=1 msg=Container image ""busybox:musl"" already present on machine"
0.4832,Event,ADDED,eval-conflicts-rho010-r5-021-kpdpd.18d466df25c4770a,reason=Created count=1 msg=Created container: task
0.4835,Event,ADDED,eval-conflicts-rho010-r5-021-kpdpd.18d466df29b6e7ba,reason=Started count=1 msg=Started container task
0.4836,Event,ADDED,eval-conflicts-rho010-r5-021.18d466de14015e4d,reason=SuccessfulCreate count=1 msg=Created pod: eval-conflicts-rho010-r5-021-kpdpd
0.4838,Event,ADDED,eval-conflicts-rho010-r5-021.18d466e2783987a4,reason=Completed count=1 msg=Job completed
0.484,Event,ADDED,eval-conflicts-rho010-r5-022-mhvbz.18d466de4fd072f0,"reason=FailedScheduling count=None msg=0/6 nodes are available: 6 node(s) had untolerated taint(s). no new claims to deallocate, preemption: 0/6 nodes are available: 6 Preemption is not helpful for scheduling."
0.4878,Event,ADDED,eval-conflicts-rho010-r5-022-mhvbz.18d466de84900322,"reason=FailedScheduling count=None msg=0/6 nodes are available: 1 c_wall violated: 1 conflicting context pair(s) with node memory, 5 node(s) had untolerated taint(s). no new claims to deallocate, preemption: 0/6 nodes are available: 1 No preemption victims found for incoming pod, 5 Preemption is not helpful for scheduling."
0.4881,Event,ADDED,eval-conflicts-rho010-r5-022-mhvbz.18d466de85bdedc7,"reason=FailedScheduling count=None msg=0/6 nodes are available: 1 c_wall violated: 1 conflicting context pair(s) with node memory, 5 node(s) had untolerated taint(s). no new claims to deallocate, preemption: 0/6 nodes are available: 1 No preemption victims found for incoming pod, 5 Preemption is not helpful for scheduling."
0.4883,Event,ADDED,eval-conflicts-rho010-r5-022-mhvbz.18d466df0d45a16d,reason=Scheduled count=None msg=Successfully assigned compute/eval-conflicts-rho010-r5-022-mhvbz to kind-worker2
0.4886,Event,ADDED,eval-conflicts-rho010-r5-022-mhvbz.18d466df28745b5e,"reason=Pulled count=1 msg=Container image ""busybox:musl"" already present on machine"
0.4887,Event,ADDED,eval-conflicts-rho010-r5-022-mhvbz.18d466df29c98989,reason=Created count=1 msg=Created container: task
0.4889,Event,ADDED,eval-conflicts-rho010-r5-022-mhvbz.18d466df2d467fea,reason=Started count=1 msg=Started container task
0.4891,Event,ADDED,eval-conflicts-rho010-r5-022.18d466de4fc5c066,reason=SuccessfulCreate count=1 msg=Created pod: eval-conflicts-rho010-r5-022-mhvbz
0.4893,Event,ADDED,eval-conflicts-rho010-r5-022.18d466e277b2e6e5,reason=Completed count=1 msg=Job completed
0.4896,Event,ADDED,eval-conflicts-rho010-r5-023-l2ksk.18d466de8b4d589b,"reason=FailedScheduling count=None msg=0/6 nodes are available: 1 c_wall violated: 1 conflicting context pair(s) with node memory, 5 node(s) had untolerated taint(s). no new claims to deallocate, preemption: 0/6 nodes are available: 1 No preemption victims found for incoming pod, 5 Preemption is not helpful for scheduling."
0.4898,Event,ADDED,eval-conflicts-rho010-r5-023-l2ksk.18d466de8bcf0b9f,"reason=FailedScheduling count=None msg=0/6 nodes are available: 1 c_wall violated: 1 conflicting context pair(s) with node memory, 5 node(s) had untolerated taint(s). no new claims to deallocate, preemption: 0/6 nodes are available: 1 No preemption victims found for incoming pod, 5 Preemption is not helpful for scheduling."
0.4901,Event,ADDED,eval-conflicts-rho010-r5-023-l2ksk.18d466df0d9379d1,reason=Scheduled count=None msg=Successfully assigned compute/eval-conflicts-rho010-r5-023-l2ksk to kind-worker2
0.4903,Event,ADDED,eval-conflicts-rho010-r5-023-l2ksk.18d466df2a40aa7c,"reason=Pulled count=1 msg=Container image ""busybox:musl"" already present on machine"
0.4904,Event,ADDED,eval-conflicts-rho010-r5-023-l2ksk.18d466df2bf48df6,reason=Created count=1 msg=Created container: task
0.4909,Event,ADDED,eval-conflicts-rho010-r5-023-l2ksk.18d466df2e539b9a,reason=Started count=1 msg=Started container task
0.4911,Event,ADDED,eval-conflicts-rho010-r5-023.18d466de8b0fc45b,reason=SuccessfulCreate count=1 msg=Created pod: eval-conflicts-rho010-r5-023-l2ksk
0.4913,Event,ADDED,eval-conflicts-rho010-r5-023.18d466e27728ce5b,reason=Completed count=1 msg=Job completed
0.4915,Event,ADDED,eval-conflicts-rho010-r5-024-rdk7z.18d466dec73fbe01,reason=Scheduled count=None msg=Successfully assigned compute/eval-conflicts-rho010-r5-024-rdk7z to kind-worker
0.492,Event,ADDED,eval-conflicts-rho010-r5-024-rdk7z.18d466dee346e5a9,"reason=Pulled count=1 msg=Container image ""busybox:musl"" already present on machine"
0.4922,Event,ADDED,eval-conflicts-rho010-r5-024-rdk7z.18d466dee450e6ce,reason=Created count=1 msg=Created container: task
0.4924,Event,ADDED,eval-conflicts-rho010-r5-024-rdk7z.18d466dee7e52a38,reason=Started count=1 msg=Started container task
0.4928,Event,ADDED,eval-conflicts-rho010-r5-024.18d466dec6bdf6d1,reason=SuccessfulCreate count=1 msg=Created pod: eval-conflicts-rho010-r5-024-rdk7z
0.4929,Event,ADDED,eval-conflicts-rho010-r5-024.18d466e22f91374f,reason=Completed count=1 msg=Job completed
0.4931,Event,ADDED,eval-conflicts-rho010-r5-025-6x6vv.18d466df0823a98b,reason=Scheduled count=None msg=Successfully assigned compute/eval-conflicts-rho010-r5-025-6x6vv to kind-worker2
0.4933,Event,ADDED,eval-conflicts-rho010-r5-025-6x6vv.18d466df2273d30c,"reason=Pulled count=1 msg=Container image ""busybox:musl"" already present on machine"
0.4937,Event,ADDED,eval-conflicts-rho010-r5-025-6x6vv.18d466df25aa7ced,reason=Created count=1 msg=Created container: task
0.4939,Event,ADDED,eval-conflicts-rho010-r5-025-6x6vv.18d466df2990693b,reason=Started count=1 msg=Started container task
0.4942,Event,ADDED,eval-conflicts-rho010-r5-025.18d466df04451f0a,reason=SuccessfulCreate count=1 msg=Created pod: eval-conflicts-rho010-r5-025-6x6vv
0.4944,Event,ADDED,eval-conflicts-rho010-r5-025.18d466e27749a9da,reason=Completed count=1 msg=Job completed
0.4946,Event,ADDED,eval-conflicts-rho010-r5-026-h24qq.18d466df3edf16c7,reason=Scheduled count=None msg=Successfully assigned compute/eval-conflicts-rho010-r5-026-h24qq to kind-worker
0.4948,Event,ADDED,eval-conflicts-rho010-r5-026-h24qq.18d466df5795cdf6,"reason=Pulled count=1 msg=Container image ""busybox:musl"" already present on machine"
0.495,Event,ADDED,eval-conflicts-rho010-r5-026-h24qq.18d466df58c4465a,reason=Created count=1 msg=Created container: task
0.4951,Event,ADDED,eval-conflicts-rho010-r5-026-h24qq.18d466df5ca4b291,reason=Started count=1 msg=Started container task
0.4953,Event,ADDED,eval-conflicts-rho010-r5-026.18d466df3e2f443c,reason=SuccessfulCreate count=1 msg=Created pod: eval-conflicts-rho010-r5-026-h24qq
0.4955,Event,ADDED,eval-conflicts-rho010-r5-026.18d466e2af9cf4ce,reason=Completed count=1 msg=Job completed
0.4957,Event,ADDED,eval-conflicts-rho010-r5-027-75vxm.18d466df7a8601d1,reason=Scheduled count=None msg=Successfully assigned compute/eval-conflicts-rho010-r5-027-75vxm to kind-worker5
0.4959,Event,ADDED,eval-conflicts-rho010-r5-027-75vxm.18d466df94021367,"reason=Pulled count=1 msg=Container image ""busybox:musl"" already present on machine"
0.4961,Event,ADDED,eval-conflicts-rho010-r5-027-75vxm.18d466df9516bd71,reason=Created count=1 msg=Created container: task
0.4964,Event,ADDED,eval-conflicts-rho010-r5-027-75vxm.18d466df97394688,reason=Started count=1 msg=Started container task
0.4966,Event,ADDED,eval-conflicts-rho010-r5-027.18d466df798b4909,reason=SuccessfulCreate count=1 msg=Created pod: eval-conflicts-rho010-r5-027-75vxm
0.4968,Event,ADDED,eval-conflicts-rho010-r5-027.18d466e2b2bad899,reason=Completed count=1 msg=Job completed
0.4971,Event,ADDED,eval-conflicts-rho010-r5-028-w7kxq.18d466dfb76d2202,reason=Scheduled count=None msg=Successfully assigned compute/eval-conflicts-rho010-r5-028-w7kxq to kind-worker5
0.4973,Event,ADDED,eval-conflicts-rho010-r5-028-w7kxq.18d466dfcfe77eb3,"reason=Pulled count=1 msg=Container image ""busybox:musl"" already present on machine"
0.4975,Event,ADDED,eval-conflicts-rho010-r5-028-w7kxq.18d466dfd0f754f3,reason=Created count=1 msg=Created container: task
0.4977,Event,ADDED,eval-conflicts-rho010-r5-028-w7kxq.18d466dfd2f3c361,reason=Started count=1 msg=Started container task
0.4982,Event,ADDED,eval-conflicts-rho010-r5-028.18d466dfb623ddcc,reason=SuccessfulCreate count=1 msg=Created pod: eval-conflicts-rho010-r5-028-w7kxq
0.4983,Event,ADDED,eval-conflicts-rho010-r5-028.18d466e2ed34fafe,reason=Completed count=1 msg=Job completed
0.4985,Event,ADDED,eval-conflicts-rho010-r5-029-txcm9.18d466dff213af7a,reason=Scheduled count=None msg=Successfully assigned compute/eval-conflicts-rho010-r5-029-txcm9 to kind-worker5
0.4987,Event,ADDED,eval-conflicts-rho010-r5-029-txcm9.18d466e00aebdf84,"reason=Pulled count=1 msg=Container image ""busybox:musl"" already present on machine"
0.4991,Event,ADDED,eval-conflicts-rho010-r5-029-txcm9.18d466e00c07216d,reason=Created count=1 msg=Created container: task
0.4994,Event,ADDED,eval-conflicts-rho010-r5-029-txcm9.18d466e01081c62f,reason=Started count=1 msg=Started container task
0.4996,Event,ADDED,eval-conflicts-rho010-r5-029.18d466dff0dc1c6b,reason=SuccessfulCreate count=1 msg=Created pod: eval-conflicts-rho010-r5-029-txcm9
0.4999,Event,ADDED,eval-conflicts-rho010-r5-029.18d466e328eda94a,reason=Completed count=1 msg=Job completed
0.5001,Event,ADDED,eval-conflicts-rho010-r5-030-jfxft.18d466e02d8ab1f2,reason=Scheduled count=None msg=Successfully assigned compute/eval-conflicts-rho010-r5-030-jfxft to kind-worker
0.5003,Event,ADDED,eval-conflicts-rho010-r5-030-jfxft.18d466e04685a868,"reason=Pulled count=1 msg=Container image ""busybox:musl"" already present on machine"
0.5005,Event,ADDED,eval-conflicts-rho010-r5-030-jfxft.18d466e047a13e7d,reason=Created count=1 msg=Created container: task
0.5008,Event,ADDED,eval-conflicts-rho010-r5-030-jfxft.18d466e04b825492,reason=Started count=1 msg=Started container task
0.501,Event,ADDED,eval-conflicts-rho010-r5-030.18d466e02c7c8a14,reason=SuccessfulCreate count=1 msg=Created pod: eval-conflicts-rho010-r5-030-jfxft
0.5012,Event,ADDED,eval-conflicts-rho010-r5-030.18d466e395541476,reason=Completed count=1 msg=Job completed
0.5013,Event,ADDED,eval-conflicts-rho010-r5-031-d6mkg.18d466e069b9210a,reason=Scheduled count=None msg=Successfully assigned compute/eval-conflicts-rho010-r5-031-d6mkg to kind-worker5
0.5017,Event,ADDED,eval-conflicts-rho010-r5-031-d6mkg.18d466e082e0e667,"reason=Pulled count=1 msg=Container image ""busybox:musl"" already present on machine"
0.5019,Event,ADDED,eval-conflicts-rho010-r5-031-d6mkg.18d466e083f47946,reason=Created count=1 msg=Created container: task
0.5022,Event,ADDED,eval-conflicts-rho010-r5-031-d6mkg.18d466e086080b15,reason=Started count=1 msg=Started container task
0.5027,Event,ADDED,eval-conflicts-rho010-r5-031.18d466e068913ef3,reason=SuccessfulCreate count=1 msg=Created pod: eval-conflicts-rho010-r5-031-d6mkg
0.5029,Event,ADDED,eval-conflicts-rho010-r5-031.18d466e3a5cbd037,reason=Completed count=1 msg=Job completed
0.503,Event,ADDED,eval-conflicts-rho010-r5-032-lsr4c.18d466e0a5bfdd17,reason=Scheduled count=None msg=Successfully assigned compute/eval-conflicts-rho010-r5-032-lsr4c to kind-worker5
0.5036,Event,ADDED,eval-conflicts-rho010-r5-032-lsr4c.18d466e0be293f54,"reason=Pulled count=1 msg=Container image ""busybox:musl"" already present on machine"
0.5042,Event,ADDED,eval-conflicts-rho010-r5-032-lsr4c.18d466e0bf4478f6,reason=Created count=1 msg=Created container: task
0.5044,Event,ADDED,eval-conflicts-rho010-r5-032-lsr4c.18d466e0c427220e,reason=Started count=1 msg=Started container task
0.5046,Event,ADDED,eval-conflicts-rho010-r5-032.18d466e0a49531ff,reason=SuccessfulCreate count=1 msg=Created pod: eval-conflicts-rho010-r5-032-lsr4c
0.5049,Event,ADDED,eval-conflicts-rho010-r5-032.18d466e3e1aa2238,reason=Completed count=1 msg=Job completed
0.5051,Event,ADDED,eval-conflicts-rho010-r5-033-w2zrx.18d466e0e072c696,reason=Scheduled count=None msg=Successfully assigned compute/eval-conflicts-rho010-r5-033-w2zrx to kind-worker5
0.5053,Event,ADDED,eval-conflicts-rho010-r5-033-w2zrx.18d466e0fc33b5a5,"reason=Pulled count=1 msg=Container image ""busybox:musl"" already present on machine"
0.5055,Event,ADDED,eval-conflicts-rho010-r5-033-w2zrx.18d466e0fd4eff60,reason=Created count=1 msg=Created container: task
0.5057,Event,ADDED,eval-conflicts-rho010-r5-033-w2zrx.18d466e1060d99ed,reason=Started count=1 msg=Started container task
0.506,Event,ADDED,eval-conflicts-rho010-r5-033.18d466e0df9547ab,reason=SuccessfulCreate count=1 msg=Created pod: eval-conflicts-rho010-r5-033-w2zrx
0.5062,Event,ADDED,eval-conflicts-rho010-r5-033.18d466e41f5e52e6,reason=Completed count=1 msg=Job completed
0.5063,Event,ADDED,eval-conflicts-rho010-r5-034-5jzfh.18d466e11bab66e1,reason=Scheduled count=None msg=Successfully assigned compute/eval-conflicts-rho010-r5-034-5jzfh to kind-worker5
0.5067,Event,ADDED,eval-conflicts-rho010-r5-034-5jzfh.18d466e133ff792f,"reason=Pulled count=1 msg=Container image ""busybox:musl"" already present on machine"
0.5069,Event,ADDED,eval-conflicts-rho010-r5-034-5jzfh.18d466e1352c8ad4,reason=Created count=1 msg=Created container: task
0.507,Event,ADDED,eval-conflicts-rho010-r5-034-5jzfh.18d466e13b6c27fd,reason=Started count=1 msg=Started container task
0.5073,Event,ADDED,eval-conflicts-rho010-r5-034.18d466e11ab2c5d7,reason=SuccessfulCreate count=1 msg=Created pod: eval-conflicts-rho010-r5-034-5jzfh
0.5075,Event,ADDED,eval-conflicts-rho010-r5-034.18d466e4547d249e,reason=Completed count=1 msg=Job completed
0.5077,Event,ADDED,eval-conflicts-rho010-r5-035-clwnl.18d466e1572862ac,reason=Scheduled count=None msg=Successfully assigned compute/eval-conflicts-rho010-r5-035-clwnl to kind-worker4
0.5079,Event,ADDED,eval-conflicts-rho010-r5-035-clwnl.18d466e1719d8c2f,"reason=Pulled count=1 msg=Container image ""busybox:musl"" already present on machine"
0.5081,Event,ADDED,eval-conflicts-rho010-r5-035-clwnl.18d466e172ac51a3,reason=Created count=1 msg=Created container: task
0.5083,Event,ADDED,eval-conflicts-rho010-r5-035-clwnl.18d466e17667ff2e,reason=Started count=1 msg=Started container task
0.5084,Event,ADDED,eval-conflicts-rho010-r5-035.18d466e1566f4e46,reason=SuccessfulCreate count=1 msg=Created pod: eval-conflicts-rho010-r5-035-clwnl
0.5086,Event,ADDED,eval-conflicts-rho010-r5-035.18d466e49ba7e907,reason=Completed count=1 msg=Job completed
0.5088,Event,ADDED,eval-conflicts-rho010-r5-036-zswxt.18d466e192ad8eac,reason=Scheduled count=None msg=Successfully assigned compute/eval-conflicts-rho010-r5-036-zswxt to kind-worker4
0.509,Event,ADDED,eval-conflicts-rho010-r5-036-zswxt.18d466e1adb39bcf,"reason=Pulled count=1 msg=Container image ""busybox:musl"" already present on machine"
0.5091,Event,ADDED,eval-conflicts-rho010-r5-036-zswxt.18d466e1aedaa2c4,reason=Created count=1 msg=Created container: task
0.5093,Event,ADDED,eval-conflicts-rho010-r5-036-zswxt.18d466e1b79c0c24,reason=Started count=1 msg=Started container task
0.5096,Event,ADDED,eval-conflicts-rho010-r5-036.18d466e191dd2246,reason=SuccessfulCreate count=1 msg=Created pod: eval-conflicts-rho010-r5-036-zswxt
0.5098,Event,ADDED,eval-conflicts-rho010-r5-036.18d466e4d752e75a,reason=Completed count=1 msg=Job completed
0.5099,Event,ADDED,eval-conflicts-rho010-r5-037-qrr52.18d466e1ce49d478,reason=Scheduled count=None msg=Successfully assigned compute/eval-conflicts-rho010-r5-037-qrr52 to kind-worker4
0.5102,Event,ADDED,eval-conflicts-rho010-r5-037-qrr52.18d466e1eb36d6b6,"reason=Pulled count=1 msg=Container image ""busybox:musl"" already present on machine"
0.5104,Event,ADDED,eval-conflicts-rho010-r5-037-qrr52.18d466e1ec72f982,reason=Created count=1 msg=Created container: task
0.5106,Event,ADDED,eval-conflicts-rho010-r5-037-qrr52.18d466e1f2bb6a38,reason=Started count=1 msg=Started container task
0.5108,Event,ADDED,eval-conflicts-rho010-r5-037.18d466e1cd7774c0,reason=SuccessfulCreate count=1 msg=Created pod: eval-conflicts-rho010-r5-037-qrr52
0.511,Event,ADDED,eval-conflicts-rho010-r5-037.18d466e50d9522b1,reason=Completed count=1 msg=Job completed
0.5112,Event,ADDED,eval-conflicts-rho010-r5-038-62t4d.18d466e20a4d4a9a,reason=Scheduled count=None msg=Successfully assigned compute/eval-conflicts-rho010-r5-038-62t4d to kind-worker4
0.5113,Event,ADDED,eval-conflicts-rho010-r5-038-62t4d.18d466e223c5e1b7,"reason=Pulled count=1 msg=Container image ""busybox:musl"" already present on machine"
0.5115,Event,ADDED,eval-conflicts-rho010-r5-038-62t4d.18d466e224ddb018,reason=Created count=1 msg=Created container: task
0.5117,Event,ADDED,eval-conflicts-rho010-r5-038-62t4d.18d466e226ad006e,reason=Started count=1 msg=Started container task
0.5119,Event,ADDED,eval-conflicts-rho010-r5-038.18d466e2097640c7,reason=SuccessfulCreate count=1 msg=Created pod: eval-conflicts-rho010-r5-038-62t4d
0.5121,Event,ADDED,eval-conflicts-rho010-r5-038.18d466e549a54fbc,reason=Completed count=1 msg=Job completed
0.5122,Event,ADDED,eval-conflicts-rho010-r5-039-q9psz.18d466e24818e5ea,reason=Scheduled count=None msg=Successfully assigned compute/eval-conflicts-rho010-r5-039-q9psz to kind-worker3
0.5124,Event,ADDED,eval-conflicts-rho010-r5-039-q9psz.18d466e263c65a07,"reason=Pulled count=1 msg=Container image ""busybox:musl"" already present on machine"
0.5125,Event,ADDED,eval-conflicts-rho010-r5-039-q9psz.18d466e264e8704c,reason=Created count=1 msg=Created container: task
0.5127,Event,ADDED,eval-conflicts-rho010-r5-039-q9psz.18d466e268c44546,reason=Started count=1 msg=Started container task
0.5129,Event,ADDED,eval-conflicts-rho010-r5-039.18d466e247676813,reason=SuccessfulCreate count=1 msg=Created pod: eval-conflicts-rho010-r5-039-q9psz
0.513,Event,ADDED,eval-conflicts-rho010-r5-039.18d466e5a3b81b8f,reason=Completed count=1 msg=Job completed
0.5132,Event,ADDED,eval-conflicts-rho010-r5-040-tdfbc.18d466e2834a7e06,reason=Scheduled count=None msg=Successfully assigned compute/eval-conflicts-rho010-r5-040-tdfbc to kind-worker3
0.5134,Event,ADDED,eval-conflicts-rho010-r5-040-tdfbc.18d466e29d2f0214,"reason=Pulled count=1 msg=Container image ""busybox:musl"" already present on machine"
0.5136,Event,ADDED,eval-conflicts-rho010-r5-040-tdfbc.18d466e29e52b3dc,reason=Created count=1 msg=Created container: task
0.5139,Event,ADDED,eval-conflicts-rho010-r5-040-tdfbc.18d466e2a49d9769,reason=Started count=1 msg=Started container task
0.5143,Event,ADDED,eval-conflicts-rho010-r5-040.18d466e2828cd48d,reason=SuccessfulCreate count=1 msg=Created pod: eval-conflicts-rho010-r5-040-tdfbc
0.5145,Event,ADDED,eval-conflicts-rho010-r5-040.18d466e5dfbaf6eb,reason=Completed count=1 msg=Job completed
0.5146,Event,ADDED,eval-conflicts-rho010-r5-041-nlptv.18d466e2bcc0f6fd,reason=Scheduled count=None msg=Successfully assigned compute/eval-conflicts-rho010-r5-041-nlptv to kind-worker4
0.5148,Event,ADDED,eval-conflicts-rho010-r5-041-nlptv.18d466e2d7ed7a38,"reason=Pulled count=1 msg=Container image ""busybox:musl"" already present on machine"
0.5152,Event,ADDED,eval-conflicts-rho010-r5-041-nlptv.18d466e2d919a348,reason=Created count=1 msg=Created container: task
0.5153,Event,ADDED,eval-conflicts-rho010-r5-041-nlptv.18d466e2de3f591c,reason=Started count=1 msg=Started container task
0.5155,Event,ADDED,eval-conflicts-rho010-r5-041.18d466e2bbe07ec0,reason=SuccessfulCreate count=1 msg=Created pod: eval-conflicts-rho010-r5-041-nlptv
0.5157,Event,ADDED,eval-conflicts-rho010-r5-041.18d466e5fd955272,reason=Completed count=1 msg=Job completed
0.516,Event,ADDED,eval-conflicts-rho010-r5-042-726fh.18d466e2f8aafe47,reason=Scheduled count=None msg=Successfully assigned compute/eval-conflicts-rho010-r5-042-726fh to kind-worker3
0.5162,Event,ADDED,eval-conflicts-rho010-r5-042-726fh.18d466e31332ddd4,"reason=Pulled count=1 msg=Container image ""busybox:musl"" already present on machine"
0.5164,Event,ADDED,eval-conflicts-rho010-r5-042-726fh.18d466e3144da923,reason=Created count=1 msg=Created container: task
0.5169,Event,ADDED,eval-conflicts-rho010-r5-042-726fh.18d466e3166b8dd8,reason=Started count=1 msg=Started container task
0.5171,Event,ADDED,eval-conflicts-rho010-r5-042.18d466e2f7de3ebd,reason=SuccessfulCreate count=1 msg=Created pod: eval-conflicts-rho010-r5-042-726fh
0.5172,Event,ADDED,eval-conflicts-rho010-r5-042.18d466e656bd9379,reason=Completed count=1 msg=Job completed
0.5174,Event,ADDED,eval-conflicts-rho010-r5-043-dc4f8.18d466e33767f935,reason=Scheduled count=None msg=Successfully assigned compute/eval-conflicts-rho010-r5-043-dc4f8 to kind-worker3
0.518,Event,ADDED,eval-conflicts-rho010-r5-043-dc4f8.18d466e35313c7e0,"reason=Pulled count=1 msg=Container image ""busybox:musl"" already present on machine"
0.5182,Event,ADDED,eval-conflicts-rho010-r5-043-dc4f8.18d466e3541e306a,reason=Created count=1 msg=Created container: task
0.5184,Event,ADDED,eval-conflicts-rho010-r5-043-dc4f8.18d466e358b33132,reason=Started count=1 msg=Started container task
0.5185,Event,ADDED,eval-conflicts-rho010-r5-043.18d466e336616137,reason=SuccessfulCreate count=1 msg=Created pod: eval-conflicts-rho010-r5-043-dc4f8
0.5188,Event,ADDED,eval-conflicts-rho010-r5-043.18d466e692926b92,reason=Completed count=1 msg=Job completed
0.519,Event,ADDED,eval-conflicts-rho010-r5-044-vj7gs.18d466e36f87ac55,reason=Scheduled count=None msg=Successfully assigned compute/eval-conflicts-rho010-r5-044-vj7gs to kind-worker
0.5192,Event,ADDED,eval-conflicts-rho010-r5-044-vj7gs.18d466e389fa806a,"reason=Pulled count=1 msg=Container image ""busybox:musl"" already present on machine"
0.5195,Event,ADDED,eval-conflicts-rho010-r5-044-vj7gs.18d466e38b133d2a,reason=Created count=1 msg=Created container: task
0.5197,Event,ADDED,eval-conflicts-rho010-r5-044-vj7gs.18d466e3926b9257,reason=Started count=1 msg=Started container task
0.5199,Event,ADDED,eval-conflicts-rho010-r5-044.18d466e36ed27f90,reason=SuccessfulCreate count=1 msg=Created pod: eval-conflicts-rho010-r5-044-vj7gs
0.52,Event,ADDED,eval-conflicts-rho010-r5-044.18d466e6d8fce104,reason=Completed count=1 msg=Job completed
0.5203,Event,ADDED,eval-conflicts-rho010-r5-045-wvfds.18d466e3ab687fd5,reason=Scheduled count=None msg=Successfully assigned compute/eval-conflicts-rho010-r5-045-wvfds to kind-worker
0.5204,Event,ADDED,eval-conflicts-rho010-r5-045-wvfds.18d466e3c57e1e3e,"reason=Pulled count=1 msg=Container image ""busybox:musl"" already present on machine"
0.5206,Event,ADDED,eval-conflicts-rho010-r5-045-wvfds.18d466e3c6b64091,reason=Created count=1 msg=Created container: task
0.5209,Event,ADDED,eval-conflicts-rho010-r5-045-wvfds.18d466e3ce582ea7,reason=Started count=1 msg=Started container task
0.5212,Event,ADDED,eval-conflicts-rho010-r5-045.18d466e3aac0fa02,reason=SuccessfulCreate count=1 msg=Created pod: eval-conflicts-rho010-r5-045-wvfds
0.5214,Event,ADDED,eval-conflicts-rho010-r5-045.18d466e6d91a28ab,reason=Completed count=1 msg=Job completed
0.5216,Event,ADDED,eval-conflicts-rho010-r5-046-gqpzq.18d466e3eb1b946f,reason=Scheduled count=None msg=Successfully assigned compute/eval-conflicts-rho010-r5-046-gqpzq to kind-worker2
0.5219,Event,ADDED,eval-conflicts-rho010-r5-046-gqpzq.18d466e40348b9a2,"reason=Pulled count=1 msg=Container image ""busybox:musl"" already present on machine"
0.5221,Event,ADDED,eval-conflicts-rho010-r5-046-gqpzq.18d466e40459f43f,reason=Created count=1 msg=Created container: task
0.5223,Event,ADDED,eval-conflicts-rho010-r5-046-gqpzq.18d466e40ab8b652,reason=Started count=1 msg=Started container task
0.5225,Event,ADDED,eval-conflicts-rho010-r5-046.18d466e3ea688acb,reason=SuccessfulCreate count=1 msg=Created pod: eval-conflicts-rho010-r5-046-gqpzq
0.5228,Event,ADDED,eval-conflicts-rho010-r5-046.18d466e7213188a0,reason=Completed count=1 msg=Job completed
0.5229,Event,ADDED,eval-conflicts-rho010-r5-047-g69mj.18d466e4228b6635,reason=Scheduled count=None msg=Successfully assigned compute/eval-conflicts-rho010-r5-047-g69mj to kind-worker5
0.5231,Event,ADDED,eval-conflicts-rho010-r5-047-g69mj.18d466e4408b20f9,"reason=Pulled count=1 msg=Container image ""busybox:musl"" already present on machine"
0.5234,Event,ADDED,eval-conflicts-rho010-r5-047-g69mj.18d466e441aa2bac,reason=Created count=1 msg=Created container: task
0.5236,Event,ADDED,eval-conflicts-rho010-r5-047-g69mj.18d466e447f79c89,reason=Started count=1 msg=Started container task
0.5238,Event,ADDED,eval-conflicts-rho010-r5-047.18d466e421931d86,reason=SuccessfulCreate count=1 msg=Created pod: eval-conflicts-rho010-r5-047-g69mj
0.5239,Event,ADDED,eval-conflicts-rho010-r5-047.18d466e75dada61b,reason=Completed count=1 msg=Job completed
0.5242,Event,ADDED,eval-conflicts-rho010-r5-048-ftm2t.18d466e45e9097e5,reason=Scheduled count=None msg=Successfully assigned compute/eval-conflicts-rho010-r5-048-ftm2t to kind-worker5
0.5244,Event,ADDED,eval-conflicts-rho010-r5-048-ftm2t.18d466e47c0777d9,"reason=Pulled count=1 msg=Container image ""busybox:musl"" already present on machine"
0.5246,Event,ADDED,eval-conflicts-rho010-r5-048-ftm2t.18d466e47d2b9499,reason=Created count=1 msg=Created container: task
0.5247,Event,ADDED,eval-conflicts-rho010-r5-048-ftm2t.18d466e484740dbf,reason=Started count=1 msg=Started container task
0.525,Event,ADDED,eval-conflicts-rho010-r5-048.18d466e45d792d36,reason=SuccessfulCreate count=1 msg=Created pod: eval-conflicts-rho010-r5-048-ftm2t
0.5252,Event,ADDED,eval-conflicts-rho010-r5-048.18d466e7992473d7,reason=Completed count=1 msg=Job completed
0.5254,Event,ADDED,eval-conflicts-rho010-r5-049-tk8dk.18d466e49ea721a1,reason=Scheduled count=None msg=Successfully assigned compute/eval-conflicts-rho010-r5-049-tk8dk to kind-worker2
0.5258,Event,ADDED,eval-conflicts-rho010-r5-049-tk8dk.18d466e4bb2b6fba,"reason=Pulled count=1 msg=Container image ""busybox:musl"" already present on machine"
0.526,Event,ADDED,eval-conflicts-rho010-r5-049-tk8dk.18d466e4bc52a165,reason=Created count=1 msg=Created container: task
0.5261,Event,ADDED,eval-conflicts-rho010-r5-049-tk8dk.18d466e4cd3809fb,reason=Started count=1 msg=Started container task
0.5263,Event,ADDED,eval-conflicts-rho010-r5-049.18d466e49d95568e,reason=SuccessfulCreate count=1 msg=Created pod: eval-conflicts-rho010-r5-049-tk8dk
0.5266,Event,ADDED,eval-conflicts-rho010-r5-049.18d466e80ffecb5f,reason=Completed count=1 msg=Job completed
0.5268,Event,ADDED,eval-conflicts-rho010-r5-050-2qh4f.18d466e4d55cb794,reason=Scheduled count=None msg=Successfully assigned compute/eval-conflicts-rho010-r5-050-2qh4f to kind-worker2
0.527,Event,ADDED,eval-conflicts-rho010-r5-050-2qh4f.18d466e4ef5928f8,"reason=Pulled count=1 msg=Container image ""busybox:musl"" already present on machine"
0.5273,Event,ADDED,eval-conflicts-rho010-r5-050-2qh4f.18d466e4f078f333,reason=Created count=1 msg=Created container: task
0.5274,Event,ADDED,eval-conflicts-rho010-r5-050-2qh4f.18d466e4f57fe679,reason=Started count=1 msg=Started container task
0.5276,Event,ADDED,eval-conflicts-rho010-r5-050.18d466e4d4590092,reason=SuccessfulCreate count=1 msg=Created pod: eval-conflicts-rho010-r5-050-2qh4f
0.5278,Event,ADDED,eval-conflicts-rho010-r5-050.18d466e80fe25c5e,reason=Completed count=1 msg=Job completed
0.5281,Event,ADDED,eval-conflicts-rho010-r5-051-s5rbt.18d466e5117a5671,reason=Scheduled count=None msg=Successfully assigned compute/eval-conflicts-rho010-r5-051-s5rbt to kind-worker5
0.5283,Event,ADDED,eval-conflicts-rho010-r5-051-s5rbt.18d466e52a628de8,"reason=Pulled count=1 msg=Container image ""busybox:musl"" already present on machine"
0.5284,Event,ADDED,eval-conflicts-rho010-r5-051-s5rbt.18d466e52bd6e43e,reason=Created count=1 msg=Created container: task
0.5286,Event,ADDED,eval-conflicts-rho010-r5-051-s5rbt.18d466e53283d8cf,reason=Started count=1 msg=Started container task
0.5288,Event,ADDED,eval-conflicts-rho010-r5-051.18d466e51051c6cb,reason=SuccessfulCreate count=1 msg=Created pod: eval-conflicts-rho010-r5-051-s5rbt
0.529,Event,ADDED,eval-conflicts-rho010-r5-051.18d466e84d70c74a,reason=Completed count=1 msg=Job completed
0.5291,Event,ADDED,eval-conflicts-rho010-r5-052-zqmbp.18d466e54c5d23b9,"reason=FailedScheduling count=None msg=0/6 nodes are available: 3 c_wall violated: 1 conflicting context pair(s) with node memory, 3 node(s) had untolerated taint(s). no new claims to deallocate, preemption: 0/6 nodes are available: 3 No preemption victims found for incoming pod, 3 Preemption is not helpful for scheduling."
0.5296,Event,ADDED,eval-conflicts-rho010-r5-052-zqmbp.18d466e5510f9ebb,"reason=FailedScheduling count=None msg=0/6 nodes are available: 3 c_wall violated: 1 conflicting context pair(s) with node memory, 3 node(s) had untolerated taint(s). no new claims to deallocate, preemption: 0/6 nodes are available: 3 No preemption victims found for incoming pod, 3 Preemption is not helpful for scheduling."
0.5298,Event,ADDED,eval-conflicts-rho010-r5-052-zqmbp.18d466e59432c6e6,"reason=FailedScheduling count=None msg=0/6 nodes are available: 2 c_wall violated: 1 conflicting context pair(s) with node memory, 4 node(s) had untolerated taint(s). no new claims to deallocate, preemption: 0/6 nodes are available: 2 No preemption victims found for incoming pod, 4 Preemption is not helpful for scheduling."
0.5299,Event,ADDED,eval-conflicts-rho010-r5-052-zqmbp.18d466e5f26f880d,reason=Scheduled count=None msg=Successfully assigned compute/eval-conflicts-rho010-r5-052-zqmbp to kind-worker4
0.5302,Event,ADDED,eval-conflicts-rho010-r5-052-zqmbp.18d466e60af4c8e1,"reason=Pulled count=1 msg=Container image ""busybox:musl"" already present on machine"
0.5303,Event,ADDED,eval-conflicts-rho010-r5-052-zqmbp.18d466e60c01721e,reason=Created count=1 msg=Created container: task
0.5305,Event,ADDED,eval-conflicts-rho010-r5-052-zqmbp.18d466e60dec9fb6,reason=Started count=1 msg=Started container task
0.5307,Event,ADDED,eval-conflicts-rho010-r5-052.18d466e54badf6b3,reason=SuccessfulCreate count=1 msg=Created pod: eval-conflicts-rho010-r5-052-zqmbp
0.531,Event,ADDED,eval-conflicts-rho010-r5-052.18d466e941b3c01d,reason=Completed count=1 msg=Job completed
0.5312,Event,ADDED,eval-conflicts-rho010-r5-053-wrcv2.18d466e58890edaf,reason=Scheduled count=None msg=Successfully assigned compute/eval-conflicts-rho010-r5-053-wrcv2 to kind-worker5
0.5313,Event,ADDED,eval-conflicts-rho010-r5-053-wrcv2.18d466e5a11ca9fa,"reason=Pulled count=1 msg=Container image ""busybox:musl"" already present on machine"
0.5316,Event,ADDED,eval-conflicts-rho010-r5-053-wrcv2.18d466e5a255a165,reason=Created count=1 msg=Created container: task
0.5318,Event,ADDED,eval-conflicts-rho010-r5-053-wrcv2.18d466e5a9fa18b2,reason=Started count=1 msg=Started container task
0.532,Event,ADDED,eval-conflicts-rho010-r5-053.18d466e5875d91f9,reason=SuccessfulCreate count=1 msg=Created pod: eval-conflicts-rho010-r5-053-wrcv2
0.5321,Event,ADDED,eval-conflicts-rho010-r5-053.18d466e8c4506a90,reason=Completed count=1 msg=Job completed
0.5323,Event,ADDED,eval-conflicts-rho010-r5-054-6fqzt.18d466e5c4074519,reason=Scheduled count=None msg=Successfully assigned compute/eval-conflicts-rho010-r5-054-6fqzt to kind-worker2
0.5325,Event,ADDED,eval-conflicts-rho010-r5-054-6fqzt.18d466e5dd8f1b42,"reason=Pulled count=1 msg=Container image ""busybox:musl"" already present on machine"
0.5327,Event,ADDED,eval-conflicts-rho010-r5-054-6fqzt.18d466e5ded18737,reason=Created count=1 msg=Created container: task
0.5328,Event,ADDED,eval-conflicts-rho010-r5-054-6fqzt.18d466e5e9815b86,reason=Started count=1 msg=Started container task
0.533,Event,ADDED,eval-conflicts-rho010-r5-054.18d466e5c3231a30,reason=SuccessfulCreate count=1 msg=Created pod: eval-conflicts-rho010-r5-054-6fqzt
0.5332,Event,ADDED,eval-conflicts-rho010-r5-054.18d466e8ff5ea3f7,reason=Completed count=1 msg=Job completed
0.5333,Event,ADDED,eval-conflicts-rho010-r5-055-8bhff.18d466e5ffb017a9,reason=Scheduled count=None msg=Successfully assigned compute/eval-conflicts-rho010-r5-055-8bhff to kind-worker4
0.5337,Event,ADDED,eval-conflicts-rho010-r5-055-8bhff.18d466e618cea4ef,"reason=Pulled count=1 msg=Container image ""busybox:musl"" already present on machine"
0.5338,Event,ADDED,eval-conflicts-rho010-r5-055-8bhff.18d466e619ea3fa6,reason=Created count=1 msg=Created container: task
0.534,Event,ADDED,eval-conflicts-rho010-r5-055-8bhff.18d466e6279e8b57,reason=Started count=1 msg=Started container task
0.5342,Event,ADDED,eval-conflicts-rho010-r5-055.18d466e5fe8e9f2a,reason=SuccessfulCreate count=1 msg=Created pod: eval-conflicts-rho010-r5-055-8bhff
0.5344,Event,ADDED,eval-conflicts-rho010-r5-055.18d466e905cc40bf,reason=Completed count=1 msg=Job completed
0.5346,Event,ADDED,eval-conflicts-rho010-r5-056-snhrg.18d466e63ae537cc,reason=Scheduled count=None msg=Successfully assigned compute/eval-conflicts-rho010-r5-056-snhrg to kind-worker5
0.5347,Event,ADDED,eval-conflicts-rho010-r5-056-snhrg.18d466e65436582c,"reason=Pulled count=1 msg=Container image ""busybox:musl"" already present on machine"
0.5349,Event,ADDED,eval-conflicts-rho010-r5-056-snhrg.18d466e6554848a1,reason=Created count=1 msg=Created container: task
0.5351,Event,ADDED,eval-conflicts-rho010-r5-056-snhrg.18d466e6575c01ec,reason=Started count=1 msg=Started container task
0.5353,Event,ADDED,eval-conflicts-rho010-r5-056.18d466e639fce970,reason=SuccessfulCreate count=1 msg=Created pod: eval-conflicts-rho010-r5-056-snhrg
0.5354,Event,ADDED,eval-conflicts-rho010-r5-056.18d466e977ba4c45,reason=Completed count=1 msg=Job completed
0.5356,Event,ADDED,eval-conflicts-rho010-r5-057-9bd5q.18d466e676259165,reason=Scheduled count=None msg=Successfully assigned compute/eval-conflicts-rho010-r5-057-9bd5q to kind-worker4
0.5358,Event,ADDED,eval-conflicts-rho010-r5-057-9bd5q.18d466e68f2775e7,"reason=Pulled count=1 msg=Container image ""busybox:musl"" already present on machine"
0.5359,Event,ADDED,eval-conflicts-rho010-r5-057-9bd5q.18d466e690355cda,reason=Created count=1 msg=Created container: task
0.5361,Event,ADDED,eval-conflicts-rho010-r5-057-9bd5q.18d466e6924dbbfd,reason=Started count=1 msg=Started container task
0.5363,Event,ADDED,eval-conflicts-rho010-r5-057.18d466e67586742a,reason=SuccessfulCreate count=1 msg=Created pod: eval-conflicts-rho010-r5-057-9bd5q
0.5364,Event,ADDED,eval-conflicts-rho010-r5-057.18d466e97da0f102,reason=Completed count=1 msg=Job completed
0.5366,Event,ADDED,eval-conflicts-rho010-r5-058-h2tb8.18d466e6b1a3cd35,reason=Scheduled count=None msg=Successfully assigned compute/eval-conflicts-rho010-r5-058-h2tb8 to kind-worker4
0.5368,Event,ADDED,eval-conflicts-rho010-r5-058-h2tb8.18d466e6cb3fe213,"reason=Pulled count=1 msg=Container image ""busybox:musl"" already present on machine"
0.537,Event,ADDED,eval-conflicts-rho010-r5-058-h2tb8.18d466e6cc56625c,reason=Created count=1 msg=Created container: task
0.5372,Event,ADDED,eval-conflicts-rho010-r5-058-h2tb8.18d466e6ce52905d,reason=Started count=1 msg=Started container task
0.5375,Event,ADDED,eval-conflicts-rho010-r5-058.18d466e6b1267f2e,reason=SuccessfulCreate count=1 msg=Created pod: eval-conflicts-rho010-r5-058-h2tb8
0.5378,Event,ADDED,eval-conflicts-rho010-r5-058.18d466e9f50864f8,reason=Completed count=1 msg=Job completed
0.5379,Event,ADDED,eval-conflicts-rho010-r5-059-wljc6.18d466e6ed5dcf98,reason=Scheduled count=None msg=Successfully assigned compute/eval-conflicts-rho010-r5-059-wljc6 to kind-worker4
0.5381,Event,ADDED,eval-conflicts-rho010-r5-059-wljc6.18d466e70681613f,"reason=Pulled count=1 msg=Container image ""busybox:musl"" already present on machine"
0.5383,Event,ADDED,eval-conflicts-rho010-r5-059-wljc6.18d466e707a101d6,reason=Created count=1 msg=Created container: task
0.5385,Event,ADDED,eval-conflicts-rho010-r5-059-wljc6.18d466e70b6b0360,reason=Started count=1 msg=Started container task
0.5387,Event,ADDED,eval-conflicts-rho010-r5-059.18d466e6ecd2554c,reason=SuccessfulCreate count=1 msg=Created pod: eval-conflicts-rho010-r5-059-wljc6
0.5389,Event,ADDED,eval-conflicts-rho010-r5-059.18d466e9f590596d,reason=Completed count=1 msg=Job completed
0.5391,Event,ADDED,eval-conflicts-rho010-r5-060-hj8dg.18d466e7294dfb26,reason=Scheduled count=None msg=Successfully assigned compute/eval-conflicts-rho010-r5-060-hj8dg to kind-worker4
0.5393,Event,ADDED,eval-conflicts-rho010-r5-060-hj8dg.18d466e742283786,"reason=Pulled count=1 msg=Container image ""busybox:musl"" already present on machine"
0.5394,Event,ADDED,eval-conflicts-rho010-r5-060-hj8dg.18d466e7433cdd96,reason=Created count=1 msg=Created container: task
0.5396,Event,ADDED,eval-conflicts-rho010-r5-060-hj8dg.18d466e74549c3a7,reason=Started count=1 msg=Started container task
0.5398,Event,ADDED,eval-conflicts-rho010-r5-060.18d466e728b3dd16,reason=SuccessfulCreate count=1 msg=Created pod: eval-conflicts-rho010-r5-060-hj8dg
0.5399,Event,ADDED,eval-conflicts-rho010-r5-060.18d466ea6cc869f4,reason=Completed count=1 msg=Job completed
0.5401,Event,ADDED,eval-conflicts-rho010-r5-061-svjzz.18d466e7648d561c,"reason=FailedScheduling count=None msg=0/6 nodes are available: 1 c_wall violated: 1 conflicting context pair(s) with node memory, 5 node(s) had untolerated taint(s). no new claims to deallocate, preemption: 0/6 nodes are available: 1 No preemption victims found for incoming pod, 5 Preemption is not helpful for scheduling."
0.5406,Event,ADDED,eval-conflicts-rho010-r5-061-svjzz.18d466e764f8138e,"reason=FailedScheduling count=None msg=0/6 nodes are available: 1 c_wall violated: 1 conflicting context pair(s) with node memory, 5 node(s) had untolerated taint(s). no new claims to deallocate, preemption: 0/6 nodes are available: 1 No preemption victims found for incoming pod, 5 Preemption is not helpful for scheduling."
0.5407,Event,ADDED,eval-conflicts-rho010-r5-061-svjzz.18d466e7ec7ad4ec,reason=Scheduled count=None msg=Successfully assigned compute/eval-conflicts-rho010-r5-061-svjzz to kind-worker
0.5409,Event,ADDED,eval-conflicts-rho010-r5-061-svjzz.18d466e805d937f5,"reason=Pulled count=1 msg=Container image ""busybox:musl"" already present on machine"
0.541,Event,ADDED,eval-conflicts-rho010-r5-061-svjzz.18d466e806fbf88f,reason=Created count=1 msg=Created container: task
0.5413,Event,ADDED,eval-conflicts-rho010-r5-061-svjzz.18d466e808e7293f,reason=Started count=1 msg=Started container task
0.5415,Event,ADDED,eval-conflicts-rho010-r5-061.18d466e7643c6de8,reason=SuccessfulCreate count=1 msg=Created pod: eval-conflicts-rho010-r5-061-svjzz
0.5417,Event,ADDED,eval-conflicts-rho010-r5-061.18d466eb49525b90,reason=Completed count=1 msg=Job completed
0.5419,Event,ADDED,eval-conflicts-rho010-r5-062-9cxpr.18d466e7a07a2d98,reason=Scheduled count=None msg=Successfully assigned compute/eval-conflicts-rho010-r5-062-9cxpr to kind-worker4
0.5421,Event,ADDED,eval-conflicts-rho010-r5-062-9cxpr.18d466e7b90e64fd,"reason=Pulled count=1 msg=Container image ""busybox:musl"" already present on machine"
0.5423,Event,ADDED,eval-conflicts-rho010-r5-062-9cxpr.18d466e7ba2077b3,reason=Created count=1 msg=Created container: task
0.5424,Event,ADDED,eval-conflicts-rho010-r5-062-9cxpr.18d466e7bc0b28af,reason=Started count=1 msg=Started container task
0.5426,Event,ADDED,eval-conflicts-rho010-r5-062.18d466e7a00630c0,reason=SuccessfulCreate count=1 msg=Created pod: eval-conflicts-rho010-r5-062-9cxpr
0.5428,Event,ADDED,eval-conflicts-rho010-r5-062.18d466eae4a4c9dd,reason=Completed count=1 msg=Job completed
0.5429,Event,ADDED,eval-conflicts-rho010-r5-063-cljs2.18d466e7dc75178a,reason=Scheduled count=None msg=Successfully assigned compute/eval-conflicts-rho010-r5-063-cljs2 to kind-worker4
0.5431,Event,ADDED,eval-conflicts-rho010-r5-063-cljs2.18d466e7f54867fc,"reason=Pulled count=1 msg=Container image ""busybox:musl"" already present on machine"
0.5434,Event,ADDED,eval-conflicts-rho010-r5-063-cljs2.18d466e7f666c1be,reason=Created count=1 msg=Created container: task
0.5436,Event,ADDED,eval-conflicts-rho010-r5-063-cljs2.18d466e7f89de5e1,reason=Started count=1 msg=Started container task
0.5437,Event,ADDED,eval-conflicts-rho010-r5-063.18d466e7dbdd7b4b,reason=SuccessfulCreate count=1 msg=Created pod: eval-conflicts-rho010-r5-063-cljs2
0.5439,Event,ADDED,eval-conflicts-rho010-r5-063.18d466eb201a3aae,reason=Completed count=1 msg=Job completed
0.544,Event,ADDED,eval-conflicts-rho010-r5-064-rpdk4.18d466e817aed28a,reason=Scheduled count=None msg=Successfully assigned compute/eval-conflicts-rho010-r5-064-rpdk4 to kind-worker
0.5442,Event,ADDED,eval-conflicts-rho010-r5-064-rpdk4.18d466e8302d0f90,"reason=Pulled count=1 msg=Container image ""busybox:musl"" already present on machine"
0.5444,Event,ADDED,eval-conflicts-rho010-r5-064-rpdk4.18d466e83133b611,reason=Created count=1 msg=Created container: task
0.5448,Event,ADDED,eval-conflicts-rho010-r5-064-rpdk4.18d466e8331d0a0b,reason=Started count=1 msg=Started container task
0.545,Event,ADDED,eval-conflicts-rho010-r5-064.18d466e816f01789,reason=SuccessfulCreate count=1 msg=Created pod: eval-conflicts-rho010-r5-064-rpdk4
0.5452,Event,ADDED,eval-conflicts-rho010-r5-064.18d466eb493314f7,reason=Completed count=1 msg=Job completed
0.5454,Event,ADDED,eval-conflicts-rho010-r5-065-d4gmr.18d466e8532d8c07,reason=Scheduled count=None msg=Successfully assigned compute/eval-conflicts-rho010-r5-065-d4gmr to kind-worker3
0.5457,Event,ADDED,eval-conflicts-rho010-r5-065-d4gmr.18d466e86bfc4d14,"reason=Pulled count=1 msg=Container image ""busybox:musl"" already present on machine"
0.5459,Event,ADDED,eval-conflicts-rho010-r5-065-d4gmr.18d466e86d0eb27e,reason=Created count=1 msg=Created container: task
0.5461,Event,ADDED,eval-conflicts-rho010-r5-065-d4gmr.18d466e86f029160,reason=Started count=1 msg=Started container task
0.5466,Event,ADDED,eval-conflicts-rho010-r5-065.18d466e8529e5579,reason=SuccessfulCreate count=1 msg=Created pod: eval-conflicts-rho010-r5-065-d4gmr
0.5468,Event,ADDED,eval-conflicts-rho010-r5-065.18d466ebb6224284,reason=Completed count=1 msg=Job completed
0.547,Event,ADDED,eval-conflicts-rho010-r5-066-j57cn.18d466e8904194c6,reason=Scheduled count=None msg=Successfully assigned compute/eval-conflicts-rho010-r5-066-j57cn to kind-worker
0.5472,Event,ADDED,eval-conflicts-rho010-r5-066-j57cn.18d466e8a9491201,"reason=Pulled count=1 msg=Container image ""busybox:musl"" already present on machine"
0.5475,Event,ADDED,eval-conflicts-rho010-r5-066-j57cn.18d466e8aa6e703f,reason=Created count=1 msg=Created container: task
0.5477,Event,ADDED,eval-conflicts-rho010-r5-066-j57cn.18d466e8ac62d050,reason=Started count=1 msg=Started container task
0.5478,Event,ADDED,eval-conflicts-rho010-r5-066.18d466e88f02cae8,reason=SuccessfulCreate count=1 msg=Created pod: eval-conflicts-rho010-r5-066-j57cn
0.5481,Event,ADDED,eval-conflicts-rho010-r5-066.18d466ebc14343fc,reason=Completed count=1 msg=Job completed
0.5483,Event,ADDED,eval-conflicts-rho010-r5-067-kz6nt.18d466e8cb11df7d,reason=Scheduled count=None msg=Successfully assigned compute/eval-conflicts-rho010-r5-067-kz6nt to kind-worker
0.5485,Event,ADDED,eval-conflicts-rho010-r5-067-kz6nt.18d466e8e3f94554,"reason=Pulled count=1 msg=Container image ""busybox:musl"" already present on machine"
0.5486,Event,ADDED,eval-conflicts-rho010-r5-067-kz6nt.18d466e8e513c41f,reason=Created count=1 msg=Created container: task
0.5489,Event,ADDED,eval-conflicts-rho010-r5-067-kz6nt.18d466e8ed28d742,reason=Started count=1 msg=Started container task
0.549,Event,ADDED,eval-conflicts-rho010-r5-067.18d466e8ca2a4484,reason=SuccessfulCreate count=1 msg=Created pod: eval-conflicts-rho010-r5-067-kz6nt
0.5492,Event,ADDED,eval-conflicts-rho010-r5-067.18d466ebfcd6de2e,reason=Completed count=1 msg=Job completed
0.5494,Event,ADDED,eval-conflicts-rho010-r5-068-vkkjw.18d466e9065ab33b,reason=Scheduled count=None msg=Successfully assigned compute/eval-conflicts-rho010-r5-068-vkkjw to kind-worker
0.5497,Event,ADDED,eval-conflicts-rho010-r5-068-vkkjw.18d466e92036a2e8,"reason=Pulled count=1 msg=Container image ""busybox:musl"" already present on machine"
0.5499,Event,ADDED,eval-conflicts-rho010-r5-068-vkkjw.18d466e9215c9831,reason=Created count=1 msg=Created container: task
0.55,Event,ADDED,eval-conflicts-rho010-r5-068-vkkjw.18d466e924b3d636,reason=Started count=1 msg=Started container task
0.5503,Event,ADDED,eval-conflicts-rho010-r5-068.18d466e90553b4b7,reason=SuccessfulCreate count=1 msg=Created pod: eval-conflicts-rho010-r5-068-vkkjw
0.5505,Event,ADDED,eval-conflicts-rho010-r5-068.18d466ec3881b86c,reason=Completed count=1 msg=Job completed
0.5507,Event,ADDED,eval-conflicts-rho010-r5-069-pk2lm.18d466e9423a5768,reason=Scheduled count=None msg=Successfully assigned compute/eval-conflicts-rho010-r5-069-pk2lm to kind-worker
0.5508,Event,ADDED,eval-conflicts-rho010-r5-069-pk2lm.18d466e95b4b6d06,"reason=Pulled count=1 msg=Container image ""busybox:musl"" already present on machine"
0.5512,Event,ADDED,eval-conflicts-rho010-r5-069-pk2lm.18d466e95c660f70,reason=Created count=1 msg=Created container: task
0.5513,Event,ADDED,eval-conflicts-rho010-r5-069-pk2lm.18d466e96453ab53,reason=Started count=1 msg=Started container task
0.5515,Event,ADDED,eval-conflicts-rho010-r5-069.18d466e941373a84,reason=SuccessfulCreate count=1 msg=Created pod: eval-conflicts-rho010-r5-069-pk2lm
0.5517,Event,ADDED,eval-conflicts-rho010-r5-069.18d466ec7410a714,reason=Completed count=1 msg=Job completed
0.5519,Event,ADDED,eval-conflicts-rho010-r5-070-vb5mc.18d466e97dedb217,reason=Scheduled count=None msg=Successfully assigned compute/eval-conflicts-rho010-r5-070-vb5mc to kind-worker3
0.5521,Event,ADDED,eval-conflicts-rho010-r5-070-vb5mc.18d466e9972be44f,"reason=Pulled count=1 msg=Container image ""busybox:musl"" already present on machine"
0.5523,Event,ADDED,eval-conflicts-rho010-r5-070-vb5mc.18d466e9983bb8f6,reason=Created count=1 msg=Created container: task
0.5527,Event,ADDED,eval-conflicts-rho010-r5-070-vb5mc.18d466e99a37688c,reason=Started count=1 msg=Started container task
0.5529,Event,ADDED,eval-conflicts-rho010-r5-070.18d466e97cd7feb8,reason=SuccessfulCreate count=1 msg=Created pod: eval-conflicts-rho010-r5-070-vb5mc
0.5531,Event,ADDED,eval-conflicts-rho010-r5-070.18d466ecdfae2718,reason=Completed count=1 msg=Job completed
0.5533,Event,ADDED,eval-conflicts-rho010-r5-071-wp4hm.18d466e9b93c519b,reason=Scheduled count=None msg=Successfully assigned compute/eval-conflicts-rho010-r5-071-wp4hm to kind-worker
0.5537,Event,ADDED,eval-conflicts-rho010-r5-071-wp4hm.18d466e9d3748de8,"reason=Pulled count=1 msg=Container image ""busybox:musl"" already present on machine"
0.5538,Event,ADDED,eval-conflicts-rho010-r5-071-wp4hm.18d466e9d496a04e,reason=Created count=1 msg=Created container: task
0.554,Event,ADDED,eval-conflicts-rho010-r5-071-wp4hm.18d466e9d92505ae,reason=Started count=1 msg=Started container task
0.5544,Event,ADDED,eval-conflicts-rho010-r5-071.18d466e9b86bbb26,reason=SuccessfulCreate count=1 msg=Created pod: eval-conflicts-rho010-r5-071-wp4hm
0.5546,Event,ADDED,eval-conflicts-rho010-r5-071.18d466ecebde298d,reason=Completed count=1 msg=Job completed
0.5548,Event,ADDED,eval-conflicts-rho010-r5-072-hbxnt.18d466e9f509a426,reason=Scheduled count=None msg=Successfully assigned compute/eval-conflicts-rho010-r5-072-hbxnt to kind-worker
0.555,Event,ADDED,eval-conflicts-rho010-r5-072-hbxnt.18d466ea0e925444,"reason=Pulled count=1 msg=Container image ""busybox:musl"" already present on machine"
0.5553,Event,ADDED,eval-conflicts-rho010-r5-072-hbxnt.18d466ea0faebc80,reason=Created count=1 msg=Created container: task
0.5555,Event,ADDED,eval-conflicts-rho010-r5-072-hbxnt.18d466ea11a163fd,reason=Started count=1 msg=Started container task
0.5557,Event,ADDED,eval-conflicts-rho010-r5-072.18d466e9f4234910,reason=SuccessfulCreate count=1 msg=Created pod: eval-conflicts-rho010-r5-072-hbxnt
0.5558,Event,ADDED,eval-conflicts-rho010-r5-072.18d466ed27b47d01,reason=Completed count=1 msg=Job completed
0.5561,Event,ADDED,eval-conflicts-rho010-r5-073-ftx5v.18d466ea3064868e,reason=Scheduled count=None msg=Successfully assigned compute/eval-conflicts-rho010-r5-073-ftx5v to kind-worker3
0.5563,Event,ADDED,eval-conflicts-rho010-r5-073-ftx5v.18d466ea48e91157,"reason=Pulled count=1 msg=Container image ""busybox:musl"" already present on machine"
0.5565,Event,ADDED,eval-conflicts-rho010-r5-073-ftx5v.18d466ea49fd26a5,reason=Created count=1 msg=Created container: task
0.5568,Event,ADDED,eval-conflicts-rho010-r5-073-ftx5v.18d466ea4be86cb8,reason=Started count=1 msg=Started container task
0.557,Event,ADDED,eval-conflicts-rho010-r5-073.18d466ea2fa1c61a,reason=SuccessfulCreate count=1 msg=Created pod: eval-conflicts-rho010-r5-073-ftx5v
0.5572,Event,ADDED,eval-conflicts-rho010-r5-073.18d466ed5778b108,reason=Completed count=1 msg=Job completed
0.5574,Event,ADDED,eval-conflicts-rho010-r5-074-w22h5.18d466ea6bd0664c,reason=Scheduled count=None msg=Successfully assigned compute/eval-conflicts-rho010-r5-074-w22h5 to kind-worker3
0.5586,Event,ADDED,eval-conflicts-rho010-r5-074-w22h5.18d466ea85b45138,"reason=Pulled count=1 msg=Container image ""busybox:musl"" already present on machine"
0.56,Event,ADDED,eval-conflicts-rho010-r5-074-w22h5.18d466ea86d30561,reason=Created count=1 msg=Created container: task
0.5602,Event,ADDED,eval-conflicts-rho010-r5-074-w22h5.18d466ea88c3d51e,reason=Started count=1 msg=Started container task
0.562,Event,ADDED,eval-conflicts-rho010-r5-074.18d466ea6b32e59a,reason=SuccessfulCreate count=1 msg=Created pod: eval-conflicts-rho010-r5-074-w22h5
0.5623,Event,ADDED,eval-conflicts-rho010-r5-074.18d466ed9340849b,reason=Completed count=1 msg=Job completed
0.5625,Event,ADDED,eval-conflicts-rho010-r5-075-c9q22.18d466eaa6a4511c,"reason=FailedScheduling count=None msg=0/6 nodes are available: 6 node(s) had untolerated taint(s). no new claims to deallocate, preemption: 0/6 nodes are available: 6 Preemption is not helpful for scheduling."
0.5627,Event,ADDED,eval-conflicts-rho010-r5-075-c9q22.18d466eac98762c3,reason=Scheduled count=None msg=Successfully assigned compute/eval-conflicts-rho010-r5-075-c9q22 to kind-worker2
0.5629,Event,ADDED,eval-conflicts-rho010-r5-075-c9q22.18d466eae262a57a,"reason=Pulled count=1 msg=Container image ""busybox:musl"" already present on machine"
0.5631,Event,ADDED,eval-conflicts-rho010-r5-075-c9q22.18d466eae3e5cb05,reason=Created count=1 msg=Created container: task
0.5632,Event,ADDED,eval-conflicts-rho010-r5-075-c9q22.18d466eae628987a,reason=Started count=1 msg=Started container task
0.5634,Event,ADDED,eval-conflicts-rho010-r5-075.18d466eaa69ad74b,reason=SuccessfulCreate count=1 msg=Created pod: eval-conflicts-rho010-r5-075-c9q22
0.5636,Event,ADDED,eval-conflicts-rho010-r5-075.18d466ee2193fb6d,reason=Completed count=1 msg=Job completed
0.5639,Event,ADDED,eval-conflicts-rho010-r5-076-g456n.18d466eae369eb06,reason=Scheduled count=None msg=Successfully assigned compute/eval-conflicts-rho010-r5-076-g456n to kind-worker2
0.5641,Event,ADDED,eval-conflicts-rho010-r5-076-g456n.18d466eafb94652a,"reason=Pulled count=1 msg=Container image ""busybox:musl"" already present on machine"
0.5643,Event,ADDED,eval-conflicts-rho010-r5-076-g456n.18d466eafca1cbe4,reason=Created count=1 msg=Created container: task
0.5645,Event,ADDED,eval-conflicts-rho010-r5-076-g456n.18d466eb005c5fa1,reason=Started count=1 msg=Started container task
0.5646,Event,ADDED,eval-conflicts-rho010-r5-076.18d466eae2cc5b12,reason=SuccessfulCreate count=1 msg=Created pod: eval-conflicts-rho010-r5-076-g456n
0.5648,Event,ADDED,eval-conflicts-rho010-r5-076.18d466ee216735de,reason=Completed count=1 msg=Job completed
0.565,Event,ADDED,eval-conflicts-rho010-r5-077-knxkq.18d466eb1ec50858,reason=Scheduled count=None msg=Successfully assigned compute/eval-conflicts-rho010-r5-077-knxkq to kind-worker5
0.5652,Event,ADDED,eval-conflicts-rho010-r5-077-knxkq.18d466eb393e1a48,"reason=Pulled count=1 msg=Container image ""busybox:musl"" already present on machine"
0.5655,Event,ADDED,eval-conflicts-rho010-r5-077-knxkq.18d466eb3a59a1a2,reason=Created count=1 msg=Created container: task
0.5657,Event,ADDED,eval-conflicts-rho010-r5-077-knxkq.18d466eb3c6b4fb2,reason=Started count=1 msg=Started container task
0.566,Event,ADDED,eval-conflicts-rho010-r5-077.18d466eb1e2cafa4,reason=SuccessfulCreate count=1 msg=Created pod: eval-conflicts-rho010-r5-077-knxkq
0.5661,Event,ADDED,eval-conflicts-rho010-r5-077.18d466ee235e2298,reason=Completed count=1 msg=Job completed
0.5663,Event,ADDED,eval-conflicts-rho010-r5-078-cc75b.18d466eb5b355f00,reason=Scheduled count=None msg=Successfully assigned compute/eval-conflicts-rho010-r5-078-cc75b to kind-worker5
0.5666,Event,ADDED,eval-conflicts-rho010-r5-078-cc75b.18d466eb7526d2ba,"reason=Pulled count=1 msg=Container image ""busybox:musl"" already present on machine"
0.5668,Event,ADDED,eval-conflicts-rho010-r5-078-cc75b.18d466eb764f02f4,reason=Created count=1 msg=Created container: task
0.5669,Event,ADDED,eval-conflicts-rho010-r5-078-cc75b.18d466eb7a24315b,reason=Started count=1 msg=Started container task
0.5671,Event,ADDED,eval-conflicts-rho010-r5-078.18d466eb59ac7159,reason=SuccessfulCreate count=1 msg=Created pod: eval-conflicts-rho010-r5-078-cc75b
0.5675,Event,ADDED,eval-conflicts-rho010-r5-078.18d466ee5fd199cc,reason=Completed count=1 msg=Job completed
0.5676,Event,ADDED,eval-conflicts-rho010-r5-079-rfblz.18d466eb963f1da4,reason=Scheduled count=None msg=Successfully assigned compute/eval-conflicts-rho010-r5-079-rfblz to kind-worker5
0.5678,Event,ADDED,eval-conflicts-rho010-r5-079-rfblz.18d466ebaff9c353,"reason=Pulled count=1 msg=Container image ""busybox:musl"" already present on machine"
0.568,Event,ADDED,eval-conflicts-rho010-r5-079-rfblz.18d466ebb1131128,reason=Created count=1 msg=Created container: task
0.5682,Event,ADDED,eval-conflicts-rho010-r5-079-rfblz.18d466ebb2fba56c,reason=Started count=1 msg=Started container task
0.5684,Event,ADDED,eval-conflicts-rho010-r5-079.18d466eb954bdeb5,reason=SuccessfulCreate count=1 msg=Created pod: eval-conflicts-rho010-r5-079-rfblz
0.5686,Event,ADDED,eval-conflicts-rho010-r5-079.18d466ee9b12ee54,reason=Completed count=1 msg=Job completed
0.5689,Event,ADDED,eval-conflicts-rho010-r5-080-dxm2g.18d466ebd12b7f29,"reason=FailedScheduling count=None msg=0/6 nodes are available: 2 c_wall violated: 1 conflicting context pair(s) with node memory, 4 node(s) had untolerated taint(s). no new claims to deallocate, preemption: 0/6 nodes are available: 2 No preemption victims found for incoming pod, 4 Preemption is not helpful for scheduling."
0.5691,Event,ADDED,eval-conflicts-rho010-r5-080-dxm2g.18d466ebd1f64d9f,"reason=FailedScheduling count=None msg=0/6 nodes are available: 2 c_wall violated: 1 conflicting context pair(s) with node memory, 4 node(s) had untolerated taint(s). no new claims to deallocate, preemption: 0/6 nodes are available: 2 No preemption victims found for incoming pod, 4 Preemption is not helpful for scheduling."
0.5693,Event,ADDED,eval-conflicts-rho010-r5-080-dxm2g.18d466ed0634b01b,reason=Scheduled count=None msg=Successfully assigned compute/eval-conflicts-rho010-r5-080-dxm2g to kind-worker4
0.5697,Event,ADDED,eval-conflicts-rho010-r5-080-dxm2g.18d466ed229ebd96,"reason=Pulled count=1 msg=Container image ""busybox:musl"" already present on machine"
0.5699,Event,ADDED,eval-conflicts-rho010-r5-080-dxm2g.18d466ed23de9dee,reason=Created count=1 msg=Created container: task
0.5701,Event,ADDED,eval-conflicts-rho010-r5-080-dxm2g.18d466ed27e371fd,reason=Started count=1 msg=Started container task
0.5702,Event,ADDED,eval-conflicts-rho010-r5-080.18d466ebd0c6d951,reason=SuccessfulCreate count=1 msg=Created pod: eval-conflicts-rho010-r5-080-dxm2g
0.5705,Event,ADDED,eval-conflicts-rho010-r5-080.18d466f0439b6b7b,reason=Completed count=1 msg=Job completed
0.5706,Event,ADDED,eval-conflicts-rho010-r5-081-knr5j.18d466ec0cffc1dc,reason=Scheduled count=None msg=Successfully assigned compute/eval-conflicts-rho010-r5-081-knr5j to kind-worker5
0.5708,Event,ADDED,eval-conflicts-rho010-r5-081-knr5j.18d466ec26458c85,"reason=Pulled count=1 msg=Container image ""busybox:musl"" already present on machine"
0.5713,Event,ADDED,eval-conflicts-rho010-r5-081-knr5j.18d466ec2776ba23,reason=Created count=1 msg=Created container: task
0.5717,Event,ADDED,eval-conflicts-rho010-r5-081-knr5j.18d466ec299617d2,reason=Started count=1 msg=Started container task
0.5719,Event,ADDED,eval-conflicts-rho010-r5-081.18d466ec0c24bc8c,reason=SuccessfulCreate count=1 msg=Created pod: eval-conflicts-rho010-r5-081-knr5j
0.5721,Event,ADDED,eval-conflicts-rho010-r5-081.18d466ef1318dc4c,reason=Completed count=1 msg=Job completed
0.5724,Event,ADDED,eval-conflicts-rho010-r5-082-4vdjl.18d466ec48540fd9,"reason=FailedScheduling count=None msg=0/6 nodes are available: 2 c_wall violated: 1 conflicting context pair(s) with node memory, 4 node(s) had untolerated taint(s). no new claims to deallocate, preemption: 0/6 nodes are available: 2 No preemption victims found for incoming pod, 4 Preemption is not helpful for scheduling."
0.5726,Event,ADDED,eval-conflicts-rho010-r5-082-4vdjl.18d466ec4904c5bc,"reason=FailedScheduling count=None msg=0/6 nodes are available: 2 c_wall violated: 1 conflicting context pair(s) with node memory, 4 node(s) had untolerated taint(s). no new claims to deallocate, preemption: 0/6 nodes are available: 2 No preemption victims found for incoming pod, 4 Preemption is not helpful for scheduling."
0.5728,Event,ADDED,eval-conflicts-rho010-r5-082-4vdjl.18d466ed0bfaaaa6,"reason=FailedScheduling count=None msg=0/6 nodes are available: 3 c_wall violated: 1 conflicting context pair(s) with node memory, 3 node(s) had untolerated taint(s). no new claims to deallocate, preemption: 0/6 nodes are available: 3 No preemption victims found for incoming pod, 3 Preemption is not helpful for scheduling."
0.573,Event,ADDED,eval-conflicts-rho010-r5-082-4vdjl.18d466ed2373ef4c,"reason=FailedScheduling count=None msg=0/6 nodes are available: 2 c_wall violated: 1 conflicting context pair(s) with node memory, 4 node(s) had untolerated taint(s). no new claims to deallocate, preemption: 0/6 nodes are available: 2 No preemption victims found for incoming pod, 4 Preemption is not helpful for scheduling."
0.5732,Event,ADDED,eval-conflicts-rho010-r5-082-4vdjl.18d466ed6a939d48,"reason=FailedScheduling count=None msg=0/6 nodes are available: 1 c_wall violated: 1 conflicting context pair(s) with node memory, 5 node(s) had untolerated taint(s). no new claims to deallocate, preemption: 0/6 nodes are available: 1 No preemption victims found for incoming pod, 5 Preemption is not helpful for scheduling."
0.5733,Event,ADDED,eval-conflicts-rho010-r5-082-4vdjl.18d466ef0bd6efb8,reason=Scheduled count=None msg=Successfully assigned compute/eval-conflicts-rho010-r5-082-4vdjl to kind-worker
0.5735,Event,ADDED,eval-conflicts-rho010-r5-082-4vdjl.18d466ef248694c4,"reason=Pulled count=1 msg=Container image ""busybox:musl"" already present on machine"
0.5737,Event,ADDED,eval-conflicts-rho010-r5-082-4vdjl.18d466ef258daf08,reason=Created count=1 msg=Created container: task
0.5739,Event,ADDED,eval-conflicts-rho010-r5-082-4vdjl.18d466ef2763a49c,reason=Started count=1 msg=Started container task
0.5741,Event,ADDED,eval-conflicts-rho010-r5-082.18d466ec47d9e331,reason=SuccessfulCreate count=1 msg=Created pod: eval-conflicts-rho010-r5-082-4vdjl
0.5743,Event,ADDED,eval-conflicts-rho010-r5-082.18d466f24ac3e7a0,reason=Completed count=1 msg=Job completed
0.5745,Event,ADDED,eval-conflicts-rho010-r5-083-bmsc8.18d466ec856c964b,reason=Scheduled count=None msg=Successfully assigned compute/eval-conflicts-rho010-r5-083-bmsc8 to kind-worker2
0.5747,Event,ADDED,eval-conflicts-rho010-r5-083-bmsc8.18d466ec9f3bb424,"reason=Pulled count=1 msg=Container image ""busybox:musl"" already present on machine"
0.5749,Event,ADDED,eval-conflicts-rho010-r5-083-bmsc8.18d466eca064fa0f,reason=Created count=1 msg=Created container: task
0.575,Event,ADDED,eval-conflicts-rho010-r5-083-bmsc8.18d466eca528cba2,reason=Started count=1 msg=Started container task
0.5752,Event,ADDED,eval-conflicts-rho010-r5-083.18d466ec8463f4f1,reason=SuccessfulCreate count=1 msg=Created pod: eval-conflicts-rho010-r5-083-bmsc8
0.5754,Event,ADDED,eval-conflicts-rho010-r5-083.18d466efc400cb82,reason=Completed count=1 msg=Job completed
0.5755,Event,ADDED,eval-conflicts-rho010-r5-084-ltswm.18d466ecc0007ba8,reason=Scheduled count=None msg=Successfully assigned compute/eval-conflicts-rho010-r5-084-ltswm to kind-worker5
0.5757,Event,ADDED,eval-conflicts-rho010-r5-084-ltswm.18d466ecd8afa371,"reason=Pulled count=1 msg=Container image ""busybox:musl"" already present on machine"
0.5759,Event,ADDED,eval-conflicts-rho010-r5-084-ltswm.18d466ecd9c5be28,reason=Created count=1 msg=Created container: task
0.576,Event,ADDED,eval-conflicts-rho010-r5-084-ltswm.18d466ecdbd45955,reason=Started count=1 msg=Started container task
0.5762,Event,ADDED,eval-conflicts-rho010-r5-084.18d466ecbf05db4e,reason=SuccessfulCreate count=1 msg=Created pod: eval-conflicts-rho010-r5-084-ltswm
0.5764,Event,ADDED,eval-conflicts-rho010-r5-084.18d466efc5f7d9fe,reason=Completed count=1 msg=Job completed
0.5765,Event,ADDED,eval-conflicts-rho010-r5-085-gc8vw.18d466ecfbb2d2ec,reason=Scheduled count=None msg=Successfully assigned compute/eval-conflicts-rho010-r5-085-gc8vw to kind-worker2
0.5767,Event,ADDED,eval-conflicts-rho010-r5-085-gc8vw.18d466ed15262147,"reason=Pulled count=1 msg=Container image ""busybox:musl"" already present on machine"
0.5769,Event,ADDED,eval-conflicts-rho010-r5-085-gc8vw.18d466ed16415f41,reason=Created count=1 msg=Created container: task
0.577,Event,ADDED,eval-conflicts-rho010-r5-085-gc8vw.18d466ed184289af,reason=Started count=1 msg=Started container task
0.5772,Event,ADDED,eval-conflicts-rho010-r5-085.18d466ecfb0bcb22,reason=SuccessfulCreate count=1 msg=Created pod: eval-conflicts-rho010-r5-085-gc8vw
0.5774,Event,ADDED,eval-conflicts-rho010-r5-085.18d466f03c0e9fb7,reason=Completed count=1 msg=Job completed
0.5775,Event,ADDED,eval-conflicts-rho010-r5-086-jtvws.18d466ed36e2a8e2,reason=Scheduled count=None msg=Successfully assigned compute/eval-conflicts-rho010-r5-086-jtvws to kind-worker4
0.5777,Event,ADDED,eval-conflicts-rho010-r5-086-jtvws.18d466ed4fd8babd,"reason=Pulled count=1 msg=Container image ""busybox:musl"" already present on machine"
0.5779,Event,ADDED,eval-conflicts-rho010-r5-086-jtvws.18d466ed50e2d30e,reason=Created count=1 msg=Created container: task
0.578,Event,ADDED,eval-conflicts-rho010-r5-086-jtvws.18d466ed5303ad4d,reason=Started count=1 msg=Started container task
0.5782,Event,ADDED,eval-conflicts-rho010-r5-086.18d466ed36285f3e,reason=SuccessfulCreate count=1 msg=Created pod: eval-conflicts-rho010-r5-086-jtvws
0.5784,Event,ADDED,eval-conflicts-rho010-r5-086.18d466f07f6a7f1f,reason=Completed count=1 msg=Job completed
0.5785,Event,ADDED,eval-conflicts-rho010-r5-087-r8l2v.18d466ed72bf5d15,reason=Scheduled count=None msg=Successfully assigned compute/eval-conflicts-rho010-r5-087-r8l2v to kind-worker4
0.5788,Event,ADDED,eval-conflicts-rho010-r5-087-r8l2v.18d466ed8b56743c,"reason=Pulled count=1 msg=Container image ""busybox:musl"" already present on machine"
0.5789,Event,ADDED,eval-conflicts-rho010-r5-087-r8l2v.18d466ed8c6f5e97,reason=Created count=1 msg=Created container: task
0.5791,Event,ADDED,eval-conflicts-rho010-r5-087-r8l2v.18d466ed8fa961b2,reason=Started count=1 msg=Started container task
0.5797,Event,ADDED,eval-conflicts-rho010-r5-087.18d466ed72316280,reason=SuccessfulCreate count=1 msg=Created pod: eval-conflicts-rho010-r5-087-r8l2v
0.5799,Event,ADDED,eval-conflicts-rho010-r5-087.18d466f0802d38a4,reason=Completed count=1 msg=Job completed
0.58,Event,ADDED,eval-conflicts-rho010-r5-088-6mmmt.18d466edae1de065,reason=Scheduled count=None msg=Successfully assigned compute/eval-conflicts-rho010-r5-088-6mmmt to kind-worker4
0.5804,Event,ADDED,eval-conflicts-rho010-r5-088-6mmmt.18d466edc7bcc3b0,"reason=Pulled count=1 msg=Container image ""busybox:musl"" already present on machine"
0.5805,Event,ADDED,eval-conflicts-rho010-r5-088-6mmmt.18d466edc8eb7782,reason=Created count=1 msg=Created container: task
0.5807,Event,ADDED,eval-conflicts-rho010-r5-088-6mmmt.18d466edcb33b54e,reason=Started count=1 msg=Started container task
0.5809,Event,ADDED,eval-conflicts-rho010-r5-088.18d466edad78d274,reason=SuccessfulCreate count=1 msg=Created pod: eval-conflicts-rho010-r5-088-6mmmt
0.5811,Event,ADDED,eval-conflicts-rho010-r5-088.18d466f0f744ccae,reason=Completed count=1 msg=Job completed
0.5813,Event,ADDED,eval-conflicts-rho010-r5-089-gdw2g.18d466ede9402d3b,reason=Scheduled count=None msg=Successfully assigned compute/eval-conflicts-rho010-r5-089-gdw2g to kind-worker4
0.5814,Event,ADDED,eval-conflicts-rho010-r5-089-gdw2g.18d466ee031ce4de,"reason=Pulled count=1 msg=Container image ""busybox:musl"" already present on machine"
0.5817,Event,ADDED,eval-conflicts-rho010-r5-089-gdw2g.18d466ee043108cc,reason=Created count=1 msg=Created container: task
0.5819,Event,ADDED,eval-conflicts-rho010-r5-089-gdw2g.18d466ee0644fcfd,reason=Started count=1 msg=Started container task
0.5821,Event,ADDED,eval-conflicts-rho010-r5-089.18d466ede8c17193,reason=SuccessfulCreate count=1 msg=Created pod: eval-conflicts-rho010-r5-089-gdw2g
0.5823,Event,ADDED,eval-conflicts-rho010-r5-089.18d466f13343a79e,reason=Completed count=1 msg=Job completed
0.5826,Event,ADDED,eval-conflicts-rho010-r5-090-dkx8s.18d466ee259fa65e,reason=Scheduled count=None msg=Successfully assigned compute/eval-conflicts-rho010-r5-090-dkx8s to kind-worker4
0.5828,Event,ADDED,eval-conflicts-rho010-r5-090-dkx8s.18d466ee4072e6d6,"reason=Pulled count=1 msg=Container image ""busybox:musl"" already present on machine"
0.583,Event,ADDED,eval-conflicts-rho010-r5-090-dkx8s.18d466ee41ba0892,reason=Created count=1 msg=Created container: task
0.5831,Event,ADDED,eval-conflicts-rho010-r5-090-dkx8s.18d466ee448dde32,reason=Started count=1 msg=Started container task
0.5835,Event,ADDED,eval-conflicts-rho010-r5-090.18d466ee2507f58a,reason=SuccessfulCreate count=1 msg=Created pod: eval-conflicts-rho010-r5-090-dkx8s
0.5836,Event,ADDED,eval-conflicts-rho010-r5-090.18d466f16f580149,reason=Completed count=1 msg=Job completed
0.5838,Event,ADDED,eval-conflicts-rho010-r5-091-vmf29.18d466ee6239e496,reason=Scheduled count=None msg=Successfully assigned compute/eval-conflicts-rho010-r5-091-vmf29 to kind-worker4
0.584,Event,ADDED,eval-conflicts-rho010-r5-091-vmf29.18d466ee7b5d1835,"reason=Pulled count=1 msg=Container image ""busybox:musl"" already present on machine"
0.5842,Event,ADDED,eval-conflicts-rho010-r5-091-vmf29.18d466ee7c6c1254,reason=Created count=1 msg=Created container: task
0.5844,Event,ADDED,eval-conflicts-rho010-r5-091-vmf29.18d466ee7ea333eb,reason=Started count=1 msg=Started container task
0.5845,Event,ADDED,eval-conflicts-rho010-r5-091.18d466ee61997c88,reason=SuccessfulCreate count=1 msg=Created pod: eval-conflicts-rho010-r5-091-vmf29
0.5847,Event,ADDED,eval-conflicts-rho010-r5-091.18d466f1ab206a72,reason=Completed count=1 msg=Job completed
0.5848,Event,ADDED,eval-conflicts-rho010-r5-092-886pk.18d466ee9c545bf1,reason=Scheduled count=None msg=Successfully assigned compute/eval-conflicts-rho010-r5-092-886pk to kind-worker4
0.585,Event,ADDED,eval-conflicts-rho010-r5-092-886pk.18d466eeb560c213,"reason=Pulled count=1 msg=Container image ""busybox:musl"" already present on machine"
0.5852,Event,ADDED,eval-conflicts-rho010-r5-092-886pk.18d466eeb65e8e9a,reason=Created count=1 msg=Created container: task
0.5853,Event,ADDED,eval-conflicts-rho010-r5-092-886pk.18d466eeb847902b,reason=Started count=1 msg=Started container task
0.5855,Event,ADDED,eval-conflicts-rho010-r5-092.18d466ee9bcd9703,reason=SuccessfulCreate count=1 msg=Created pod: eval-conflicts-rho010-r5-092-886pk
0.5857,Event,ADDED,eval-conflicts-rho010-r5-092.18d466f1e6f5499c,reason=Completed count=1 msg=Job completed
0.586,Event,ADDED,eval-conflicts-rho010-r5-093-grh8w.18d466eed835178e,"reason=FailedScheduling count=None msg=0/6 nodes are available: 1 c_wall violated: 1 conflicting context pair(s) with node memory, 5 node(s) had untolerated taint(s). no new claims to deallocate, preemption: 0/6 nodes are available: 1 No preemption victims found for incoming pod, 5 Preemption is not helpful for scheduling."
0.5862,Event,ADDED,eval-conflicts-rho010-r5-093-grh8w.18d466eed8c1e891,"reason=FailedScheduling count=None msg=0/6 nodes are available: 1 c_wall violated: 1 conflicting context pair(s) with node memory, 5 node(s) had untolerated taint(s). no new claims to deallocate, preemption: 0/6 nodes are available: 1 No preemption victims found for incoming pod, 5 Preemption is not helpful for scheduling."
0.5864,Event,ADDED,eval-conflicts-rho010-r5-093-grh8w.18d466ef0d33257d,"reason=FailedScheduling count=None msg=0/6 nodes are available: 2 c_wall violated: 1 conflicting context pair(s) with node memory, 4 node(s) had untolerated taint(s). no new claims to deallocate, preemption: 0/6 nodes are available: 2 No preemption victims found for incoming pod, 4 Preemption is not helpful for scheduling."
0.5866,Event,ADDED,eval-conflicts-rho010-r5-093-grh8w.18d466ef53e4b2e8,reason=Scheduled count=None msg=Successfully assigned compute/eval-conflicts-rho010-r5-093-grh8w to kind-worker3
0.5868,Event,ADDED,eval-conflicts-rho010-r5-093-grh8w.18d466ef6e92c463,"reason=Pulled count=1 msg=Container image ""busybox:musl"" already present on machine"
0.587,Event,ADDED,eval-conflicts-rho010-r5-093-grh8w.18d466ef6fff92b3,reason=Created count=1 msg=Created container: task
0.5872,Event,ADDED,eval-conflicts-rho010-r5-093-grh8w.18d466ef79756d7e,reason=Started count=1 msg=Started container task
0.5874,Event,ADDED,eval-conflicts-rho010-r5-093.18d466eed7f5e94b,reason=SuccessfulCreate count=1 msg=Created pod: eval-conflicts-rho010-r5-093-grh8w
0.5876,Event,ADDED,eval-conflicts-rho010-r5-093.18d466f2b55642f2,reason=Completed count=1 msg=Job completed
0.5878,Event,ADDED,eval-conflicts-rho010-r5-094-gxl8t.18d466ef141c0ea1,reason=Scheduled count=None msg=Successfully assigned compute/eval-conflicts-rho010-r5-094-gxl8t to kind-worker
0.5881,Event,ADDED,eval-conflicts-rho010-r5-094-gxl8t.18d466ef2d5a14b3,"reason=Pulled count=1 msg=Container image ""busybox:musl"" already present on machine"
0.5883,Event,ADDED,eval-conflicts-rho010-r5-094-gxl8t.18d466ef2e63ebe0,reason=Created count=1 msg=Created container: task
0.5884,Event,ADDED,eval-conflicts-rho010-r5-094-gxl8t.18d466ef303fffd1,reason=Started count=1 msg=Started container task
0.5886,Event,ADDED,eval-conflicts-rho010-r5-094.18d466ef12e7e47c,reason=SuccessfulCreate count=1 msg=Created pod: eval-conflicts-rho010-r5-094-gxl8t
0.5889,Event,ADDED,eval-conflicts-rho010-r5-094.18d466f24a77e828,reason=Completed count=1 msg=Job completed
0.5891,Event,ADDED,eval-conflicts-rho010-r5-095-9fc64.18d466ef53a9cec6,reason=Scheduled count=None msg=Successfully assigned compute/eval-conflicts-rho010-r5-095-9fc64 to kind-worker4
0.5892,Event,ADDED,eval-conflicts-rho010-r5-095-9fc64.18d466ef6e8dc114,"reason=Pulled count=1 msg=Container image ""busybox:musl"" already present on machine"
0.5894,Event,ADDED,eval-conflicts-rho010-r5-095-9fc64.18d466ef6fd54f21,reason=Created count=1 msg=Created container: task
0.5898,Event,ADDED,eval-conflicts-rho010-r5-095-9fc64.18d466ef759cc200,reason=Started count=1 msg=Started container task
0.59,Event,ADDED,eval-conflicts-rho010-r5-095.18d466ef4fc6515b,reason=SuccessfulCreate count=1 msg=Created pod: eval-conflicts-rho010-r5-095-9fc64
0.5901,Event,ADDED,eval-conflicts-rho010-r5-095.18d466f299c70c33,reason=Completed count=1 msg=Job completed
0.5905,Event,ADDED,eval-conflicts-rho010-r5-096-ttl59.18d466ef8b4ce8ce,reason=Scheduled count=None msg=Successfully assigned compute/eval-conflicts-rho010-r5-096-ttl59 to kind-worker
0.5907,Event,ADDED,eval-conflicts-rho010-r5-096-ttl59.18d466efa5c6366a,"reason=Pulled count=1 msg=Container image ""busybox:musl"" already present on machine"
0.5909,Event,ADDED,eval-conflicts-rho010-r5-096-ttl59.18d466efa6c75904,reason=Created count=1 msg=Created container: task
0.5911,Event,ADDED,eval-conflicts-rho010-r5-096-ttl59.18d466efa8a5ebe8,reason=Started count=1 msg=Started container task
0.5914,Event,ADDED,eval-conflicts-rho010-r5-096.18d466ef8aa1a60e,reason=SuccessfulCreate count=1 msg=Created pod: eval-conflicts-rho010-r5-096-ttl59
0.5916,Event,ADDED,eval-conflicts-rho010-r5-096.18d466f2c2a258a0,reason=Completed count=1 msg=Job completed
0.5917,Event,ADDED,eval-conflicts-rho010-r5-097-ts9km.18d466efc707fede,reason=Scheduled count=None msg=Successfully assigned compute/eval-conflicts-rho010-r5-097-ts9km to kind-worker3
0.5919,Event,ADDED,eval-conflicts-rho010-r5-097-ts9km.18d466efdff63dab,"reason=Pulled count=1 msg=Container image ""busybox:musl"" already present on machine"
0.5921,Event,ADDED,eval-conflicts-rho010-r5-097-ts9km.18d466efe0f5fc2c,reason=Created count=1 msg=Created container: task
0.5922,Event,ADDED,eval-conflicts-rho010-r5-097-ts9km.18d466efe2cc9dae,reason=Started count=1 msg=Started container task
0.5924,Event,ADDED,eval-conflicts-rho010-r5-097.18d466efc656c4b0,reason=SuccessfulCreate count=1 msg=Created pod: eval-conflicts-rho010-r5-097-ts9km
0.5926,Event,ADDED,eval-conflicts-rho010-r5-097.18d466f32d37b49b,reason=Completed count=1 msg=Job completed
0.5927,Event,ADDED,eval-conflicts-rho010-r5-098-h6z6j.18d466f0021018d0,reason=Scheduled count=None msg=Successfully assigned compute/eval-conflicts-rho010-r5-098-h6z6j to kind-worker5
0.5929,Event,ADDED,eval-conflicts-rho010-r5-098-h6z6j.18d466f01b60a6dd,"reason=Pulled count=1 msg=Container image ""busybox:musl"" already present on machine"
0.5931,Event,ADDED,eval-conflicts-rho010-r5-098-h6z6j.18d466f01c6b42a8,reason=Created count=1 msg=Created container: task
0.5932,Event,ADDED,eval-conflicts-rho010-r5-098-h6z6j.18d466f01e4dd07b,reason=Started count=1 msg=Started container task
0.5934,Event,ADDED,eval-conflicts-rho010-r5-098.18d466f001443c4c,reason=SuccessfulCreate count=1 msg=Created pod: eval-conflicts-rho010-r5-098-h6z6j
0.5937,Event,ADDED,eval-conflicts-rho010-r5-098.18d466f3478316f9,reason=Completed count=1 msg=Job completed
0.5939,Event,ADDED,eval-conflicts-rho010-r5-099-sbrcf.18d466f03e65d4f0,reason=Scheduled count=None msg=Successfully assigned compute/eval-conflicts-rho010-r5-099-sbrcf to kind-worker5
0.594,Event,ADDED,eval-conflicts-rho010-r5-099-sbrcf.18d466f05643b770,"reason=Pulled count=1 msg=Container image ""busybox:musl"" already present on machine"
0.5942,Event,ADDED,eval-conflicts-rho010-r5-099-sbrcf.18d466f0574d7056,reason=Created count=1 msg=Created container: task
0.5944,Event,ADDED,eval-conflicts-rho010-r5-099-sbrcf.18d466f05926d745,reason=Started count=1 msg=Started container task
0.5947,Event,ADDED,eval-conflicts-rho010-r5-099.18d466f03d4f56e2,reason=SuccessfulCreate count=1 msg=Created pod: eval-conflicts-rho010-r5-099-sbrcf
0.5949,Event,ADDED,eval-conflicts-rho010-r5-099.18d466f383f4e8c7,reason=Completed count=1 msg=Job completed
0.595,Event,ADDED,eval-conflicts-rho010-r6-000-8xxh7.18d466f8d094f0bc,reason=Scheduled count=None msg=Successfully assigned compute/eval-conflicts-rho010-r6-000-8xxh7 to kind-worker2
0.5952,Event,ADDED,eval-conflicts-rho010-r6-000-8xxh7.18d466f8eb8aad7b,"reason=Pulled count=1 msg=Container image ""busybox:musl"" already present on machine"
0.5955,Event,ADDED,eval-conflicts-rho010-r6-000-8xxh7.18d466f8ecbac792,reason=Created count=1 msg=Created container: task
0.5957,Event,ADDED,eval-conflicts-rho010-r6-000-8xxh7.18d466f8eec5e46d,reason=Started count=1 msg=Started container task
0.5958,Event,ADDED,eval-conflicts-rho010-r6-000.18d466f8cf5bdd5b,reason=SuccessfulCreate count=1 msg=Created pod: eval-conflicts-rho010-r6-000-8xxh7
0.5961,Event,ADDED,eval-conflicts-rho010-r6-000.18d466fc20903efa,reason=Completed count=1 msg=Job completed
0.5963,Event,ADDED,eval-conflicts-rho010-r6-001-bqjhx.18d466f9095bd9a4,reason=Scheduled count=None msg=Successfully assigned compute/eval-conflicts-rho010-r6-001-bqjhx to kind-worker5
0.5965,Event,ADDED,eval-conflicts-rho010-r6-001-bqjhx.18d466f921900afa,"reason=Pulled count=1 msg=Container image ""busybox:musl"" already present on machine"
0.5967,Event,ADDED,eval-conflicts-rho010-r6-001-bqjhx.18d466f922a8eb12,reason=Created count=1 msg=Created container: task
0.5969,Event,ADDED,eval-conflicts-rho010-r6-001-bqjhx.18d466f924a0f932,reason=Started count=1 msg=Started container task
0.5971,Event,ADDED,eval-conflicts-rho010-r6-001.18d466f908e4b53a,reason=SuccessfulCreate count=1 msg=Created pod: eval-conflicts-rho010-r6-001-bqjhx
0.5972,Event,ADDED,eval-conflicts-rho010-r6-001.18d466fc608d0a4f,reason=Completed count=1 msg=Job completed
0.5974,Event,ADDED,eval-conflicts-rho010-r6-002-8bz8s.18d466f9456bb69e,reason=Scheduled count=None msg=Successfully assigned compute/eval-conflicts-rho010-r6-002-8bz8s to kind-worker
0.5976,Event,ADDED,eval-conflicts-rho010-r6-002-8bz8s.18d466f95e8c6584,"reason=Pulled count=1 msg=Container image ""busybox:musl"" already present on machine"
0.5977,Event,ADDED,eval-conflicts-rho010-r6-002-8bz8s.18d466f95fa00327,reason=Created count=1 msg=Created container: task
0.5979,Event,ADDED,eval-conflicts-rho010-r6-002-8bz8s.18d466f961ac753b,reason=Started count=1 msg=Started container task
0.5981,Event,ADDED,eval-conflicts-rho010-r6-002.18d466f9443f447a,reason=SuccessfulCreate count=1 msg=Created pod: eval-conflicts-rho010-r6-002-8bz8s
0.5982,Event,ADDED,eval-conflicts-rho010-r6-002.18d466fc90fa3127,reason=Completed count=1 msg=Job completed
0.5984,Event,ADDED,eval-conflicts-rho010-r6-003-b2n7v.18d466f98090bed0,reason=Scheduled count=None msg=Successfully assigned compute/eval-conflicts-rho010-r6-003-b2n7v to kind-worker4
0.5985,Event,ADDED,eval-conflicts-rho010-r6-003-b2n7v.18d466f999e2f747,"reason=Pulled count=1 msg=Container image ""busybox:musl"" already present on machine"
0.5987,Event,ADDED,eval-conflicts-rho010-r6-003-b2n7v.18d466f99b01c8f4,reason=Created count=1 msg=Created container: task
0.5989,Event,ADDED,eval-conflicts-rho010-r6-003-b2n7v.18d466f99d2de9c0,reason=Started count=1 msg=Started container task
0.5991,Event,ADDED,eval-conflicts-rho010-r6-003.18d466f97fd589f2,reason=SuccessfulCreate count=1 msg=Created pod: eval-conflicts-rho010-r6-003-b2n7v
0.5993,Event,ADDED,eval-conflicts-rho010-r6-003.18d466fcdee3e55f,reason=Completed count=1 msg=Job completed
0.5994,Event,ADDED,eval-conflicts-rho010-r6-004-zchk5.18d466f9bbfdb584,reason=Scheduled count=None msg=Successfully assigned compute/eval-conflicts-rho010-r6-004-zchk5 to kind-worker
0.5996,Event,ADDED,eval-conflicts-rho010-r6-004-zchk5.18d466f9d4933b2b,"reason=Pulled count=1 msg=Container image ""busybox:musl"" already present on machine"
0.5997,Event,ADDED,eval-conflicts-rho010-r6-004-zchk5.18d466f9d5c8ab6d,reason=Created count=1 msg=Created container: task
0.6,Event,ADDED,eval-conflicts-rho010-r6-004-zchk5.18d466f9d7dbb485,reason=Started count=1 msg=Started container task
0.6001,Event,ADDED,eval-conflicts-rho010-r6-004.18d466f9bb0d2d7e,reason=SuccessfulCreate count=1 msg=Created pod: eval-conflicts-rho010-r6-004-zchk5
0.6003,Event,ADDED,eval-conflicts-rho010-r6-004.18d466fd0d08e9ff,reason=Completed count=1 msg=Job completed
0.6004,Event,ADDED,eval-conflicts-rho010-r6-005-6dxtg.18d466f9f802236c,reason=Scheduled count=None msg=Successfully assigned compute/eval-conflicts-rho010-r6-005-6dxtg to kind-worker4
