t_recv,kind,type,name,detail
0.0204,Node,ADDED,kind-control-plane,taints=1
0.0212,Event,ADDED,eval-sanitize-1-r0-007-8kfn5.18d41f2469875ef6,"reason=FailedScheduling count=None msg=0/6 nodes are available: 1 c_wall violated: 1 conflicting context pair(s) with node memory, 5 node(s) had untolerated taint(s). no new claims to deallocate, preemption: 0/6 nodes are available: 1 No preemption victims found for incoming pod, 5 Preemption is not helpful for scheduling."
0.0224,Node,ADDED,kind-worker,taints=0
0.0228,Event,ADDED,eval-sanitize-1-r0-007-8kfn5.18d41f24a79a6a54,"reason=FailedScheduling count=None msg=0/6 nodes are available: 1 c_wall violated: 1 conflicting context pair(s) with node memory, 1 c_wall violated: 2 conflicting context pair(s) with node memory, 4 node(s) had untolerated taint(s). no new claims to deallocate, preemption: 0/6 nodes are available: 2 No preemption victims found for incoming pod, 4 Preemption is not helpful for scheduling."
0.0231,Event,ADDED,eval-sanitize-1-r0-009-9mtfx.18d41f2469b2aada,"reason=FailedScheduling count=None msg=0/6 nodes are available: 1 c_wall violated: 3 conflicting context pair(s) with node memory, 5 node(s) had untolerated taint(s). no new claims to deallocate, preemption: 0/6 nodes are available: 1 No preemption victims found for incoming pod, 5 Preemption is not helpful for scheduling."
0.0232,Event,ADDED,eval-sanitize-1-r0-011-l58zp.18d41f2469dbc96c,"reason=FailedScheduling count=None msg=0/6 nodes are available: 1 c_wall violated: 1 conflicting context pair(s) with node memory, 5 node(s) had untolerated taint(s). no new claims to deallocate, preemption: 0/6 nodes are available: 1 No preemption victims found for incoming pod, 5 Preemption is not helpful for scheduling."
0.0237,Event,ADDED,eval-sanitize-1-r0-011-l58zp.18d41f24a1836fcb,"reason=FailedScheduling count=None msg=0/6 nodes are available: 1 c_wall violated: 1 conflicting context pair(s) with node memory, 1 c_wall violated: 2 conflicting context pair(s) with node memory, 4 node(s) had untolerated taint(s). no new claims to deallocate, preemption: 0/6 nodes are available: 2 No preemption victims found for incoming pod, 4 Preemption is not helpful for scheduling."
0.0239,Event,ADDED,eval-sanitize-1-r0-012-dscsx.18d41f246a0b0109,"reason=FailedScheduling count=None msg=0/6 nodes are available: 1 c_wall violated: 3 conflicting context pair(s) with node memory, 5 node(s) had untolerated taint(s). no new claims to deallocate, preemption: 0/6 nodes are available: 1 No preemption victims found for incoming pod, 5 Preemption is not helpful for scheduling."
0.025,Node,ADDED,kind-worker2,taints=0
0.0253,Event,ADDED,eval-sanitize-1-r0-013-gvtcp.18d41f246a30abdb,"reason=FailedScheduling count=None msg=0/6 nodes are available: 1 c_wall violated: 3 conflicting context pair(s) with node memory, 5 node(s) had untolerated taint(s). no new claims to deallocate, preemption: 0/6 nodes are available: 1 No preemption victims found for incoming pod, 5 Preemption is not helpful for scheduling."
0.0255,Event,ADDED,eval-sanitize-1-r0-014-7wkn9.18d41f2471a1a06c,"reason=FailedScheduling count=None msg=0/6 nodes are available: 1 c_wall violated: 3 conflicting context pair(s) with node memory, 5 node(s) had untolerated taint(s). no new claims to deallocate, preemption: 0/6 nodes are available: 1 No preemption victims found for incoming pod, 5 Preemption is not helpful for scheduling."
0.0258,Event,ADDED,eval-sanitize-1-r0-015-66n9t.18d41f24ad37b516,"reason=FailedScheduling count=None msg=0/6 nodes are available: 1 c_wall violated: 1 conflicting context pair(s) with node memory, 1 c_wall violated: 2 conflicting context pair(s) with node memory, 4 node(s) had untolerated taint(s). no new claims to deallocate, preemption: 0/6 nodes are available: 2 No preemption victims found for incoming pod, 4 Preemption is not helpful for scheduling."
0.027,Node,ADDED,kind-worker3,taints=0
0.0273,Event,ADDED,eval-sanitize-1-r0-016-dwbgm.18d41f24e8c6e494,"reason=FailedScheduling count=None msg=0/6 nodes are available: 1 c_wall violated: 1 conflicting context pair(s) with node memory, 5 node(s) had untolerated taint(s). no new claims to deallocate, preemption: 0/6 nodes are available: 1 No preemption victims found for incoming pod, 5 Preemption is not helpful for scheduling."
0.0275,Event,ADDED,eval-sanitize-1-r0-017-46n92.18d41f2524bd48e5,"reason=FailedScheduling count=None msg=0/6 nodes are available: 1 c_wall violated: 1 conflicting context pair(s) with node memory, 5 node(s) had untolerated taint(s). no new claims to deallocate, preemption: 0/6 nodes are available: 1 No preemption victims found for incoming pod, 5 Preemption is not helpful for scheduling."
0.0277,Event,ADDED,eval-sanitize-1-r0-018-jnpxh.18d41f278e17553a,"reason=FailedScheduling count=None msg=0/6 nodes are available: 1 c_wall violated: 3 conflicting context pair(s) with node memory, 5 node(s) had untolerated taint(s). no new claims to deallocate, preemption: 0/6 nodes are available: 1 No preemption victims found for incoming pod, 5 Preemption is not helpful for scheduling."
0.0281,Event,ADDED,eval-sanitize-1-r0-021-m5vhs.18d41f278d612610,"reason=FailedScheduling count=None msg=0/6 nodes are available: 1 c_wall violated: 2 conflicting context pair(s) with node memory, 5 node(s) had untolerated taint(s). no new claims to deallocate, preemption: 0/6 nodes are available: 1 No preemption victims found for incoming pod, 5 Preemption is not helpful for scheduling."
0.0283,Event,ADDED,eval-sanitize-1-r0-023-gdrzz.18d41f278d95d885,"reason=FailedScheduling count=None msg=0/6 nodes are available: 1 c_wall violated: 1 conflicting context pair(s) with node memory, 5 node(s) had untolerated taint(s). no new claims to deallocate, preemption: 0/6 nodes are available: 1 No preemption victims found for incoming pod, 5 Preemption is not helpful for scheduling."
0.0285,Event,ADDED,eval-sanitize-1-r0-025-srtmj.18d41f278dbf61d2,"reason=FailedScheduling count=None msg=0/6 nodes are available: 1 c_wall violated: 3 conflicting context pair(s) with node memory, 5 node(s) had untolerated taint(s). no new claims to deallocate, preemption: 0/6 nodes are available: 1 No preemption victims found for incoming pod, 5 Preemption is not helpful for scheduling."
0.0296,Node,ADDED,kind-worker4,taints=0
0.0299,Event,ADDED,eval-sanitize-1-r0-027-fjtkj.18d41f278decc228,"reason=FailedScheduling count=None msg=0/6 nodes are available: 1 c_wall violated: 3 conflicting context pair(s) with node memory, 5 node(s) had untolerated taint(s). no new claims to deallocate, preemption: 0/6 nodes are available: 1 No preemption victims found for incoming pod, 5 Preemption is not helpful for scheduling."
0.0301,Event,ADDED,eval-sanitize-1-r0-027-fjtkj.18d41f27ba511b41,"reason=FailedScheduling count=None msg=0/6 nodes are available: 1 c_wall violated: 3 conflicting context pair(s) with node memory, 2 c_wall violated: 2 conflicting context pair(s) with node memory, 3 node(s) had untolerated taint(s). no new claims to deallocate, preemption: 0/6 nodes are available: 3 No preemption victims found for incoming pod, 3 Preemption is not helpful for scheduling."
0.0303,Event,ADDED,eval-sanitize-1-r0-033-dp7bb.18d41f2aa76152f8,"reason=FailedScheduling count=None msg=0/6 nodes are available: 1 c_wall violated: 2 conflicting context pair(s) with node memory, 5 node(s) had untolerated taint(s). no new claims to deallocate, preemption: 0/6 nodes are available: 1 No preemption victims found for incoming pod, 5 Preemption is not helpful for scheduling."
0.0307,Event,ADDED,eval-sanitize-1-r0-034-nw2dw.18d41f2aa916ee11,"reason=FailedScheduling count=None msg=0/6 nodes are available: 1 c_wall violated: 3 conflicting context pair(s) with node memory, 5 node(s) had untolerated taint(s). no new claims to deallocate, preemption: 0/6 nodes are available: 1 No preemption victims found for incoming pod, 5 Preemption is not helpful for scheduling."
0.0309,Event,ADDED,eval-sanitize-1-r0-035-4tnf8.18d41f2aa6b0fc20,"reason=FailedScheduling count=None msg=0/6 nodes are available: 1 c_wall violated: 1 conflicting context pair(s) with node memory, 5 node(s) had untolerated taint(s). no new claims to deallocate, preemption: 0/6 nodes are available: 1 No preemption victims found for incoming pod, 5 Preemption is not helpful for scheduling."
0.032,Node,ADDED,kind-worker5,taints=0
0.0323,Event,ADDED,eval-sanitize-1-r0-035-4tnf8.18d41f2ac51a4990,"reason=FailedScheduling count=None msg=0/6 nodes are available: 2 c_wall violated: 1 conflicting context pair(s) with node memory, 4 node(s) had untolerated taint(s). no new claims to deallocate, preemption: 0/6 nodes are available: 2 No preemption victims found for incoming pod, 4 Preemption is not helpful for scheduling."
0.0325,Event,ADDED,eval-sanitize-1-r0-036-pmf44.18d41f2aa96ba9aa,"reason=FailedScheduling count=None msg=0/6 nodes are available: 1 c_wall violated: 3 conflicting context pair(s) with node memory, 5 node(s) had untolerated taint(s). no new claims to deallocate, preemption: 0/6 nodes are available: 1 No preemption victims found for incoming pod, 5 Preemption is not helpful for scheduling."
0.0326,Event,ADDED,eval-sanitize-1-r0-041-p92cv.18d41f2ac70eddfd,"reason=FailedScheduling count=None msg=0/6 nodes are available: 1 c_wall violated: 1 conflicting context pair(s) with node memory, 1 c_wall violated: 3 conflicting context pair(s) with node memory, 4 node(s) had untolerated taint(s). no new claims to deallocate, preemption: 0/6 nodes are available: 2 No preemption victims found for incoming pod, 4 Preemption is not helpful for scheduling."
0.033,Event,ADDED,eval-sanitize-1-r0-045-q5j2g.18d41f2db8ef6668,"reason=FailedScheduling count=None msg=0/6 nodes are available: 1 c_wall violated: 2 conflicting context pair(s) with node memory, 5 node(s) had untolerated taint(s). no new claims to deallocate, preemption: 0/6 nodes are available: 1 No preemption victims found for incoming pod, 5 Preemption is not helpful for scheduling."
0.0332,Event,ADDED,eval-sanitize-1-r0-045-q5j2g.18d41f2dd7c1f209,"reason=FailedScheduling count=None msg=0/6 nodes are available: 2 c_wall violated: 2 conflicting context pair(s) with node memory, 4 node(s) had untolerated taint(s). no new claims to deallocate, preemption: 0/6 nodes are available: 2 No preemption victims found for incoming pod, 4 Preemption is not helpful for scheduling."
0.0334,Event,ADDED,eval-sanitize-1-r0-045-q5j2g.18d41f2de9a59c78,"reason=FailedScheduling count=None msg=0/6 nodes are available: 1 c_wall violated: 2 conflicting context pair(s) with node memory, 5 node(s) had untolerated taint(s). no new claims to deallocate, preemption: 0/6 nodes are available: 1 No preemption victims found for incoming pod, 5 Preemption is not helpful for scheduling."
0.0337,Event,ADDED,eval-sanitize-1-r0-047-5cj5r.18d41f2db8429170,"reason=FailedScheduling count=None msg=0/6 nodes are available: 1 c_wall violated: 1 conflicting context pair(s) with node memory, 5 node(s) had untolerated taint(s). no new claims to deallocate, preemption: 0/6 nodes are available: 1 No preemption victims found for incoming pod, 5 Preemption is not helpful for scheduling."
0.0339,Event,ADDED,eval-sanitize-1-r0-047-5cj5r.18d41f2dd9c864e5,"reason=FailedScheduling count=None msg=0/6 nodes are available: 2 c_wall violated: 1 conflicting context pair(s) with node memory, 4 node(s) had untolerated taint(s). no new claims to deallocate, preemption: 0/6 nodes are available: 2 No preemption victims found for incoming pod, 4 Preemption is not helpful for scheduling."
0.0341,Event,ADDED,eval-sanitize-1-r0-047-5cj5r.18d41f2de97778ec,"reason=FailedScheduling count=None msg=0/6 nodes are available: 1 c_wall violated: 1 conflicting context pair(s) with node memory, 5 node(s) had untolerated taint(s). no new claims to deallocate, preemption: 0/6 nodes are available: 1 No preemption victims found for incoming pod, 5 Preemption is not helpful for scheduling."
0.0344,Event,ADDED,eval-sanitize-1-r0-048-2l2zl.18d41f2db876a84a,"reason=FailedScheduling count=None msg=0/6 nodes are available: 1 c_wall violated: 2 conflicting context pair(s) with node memory, 5 node(s) had untolerated taint(s). no new claims to deallocate, preemption: 0/6 nodes are available: 1 No preemption victims found for incoming pod, 5 Preemption is not helpful for scheduling."
0.0346,Event,ADDED,eval-sanitize-1-r0-052-kgdq7.18d41f2db8a03281,"reason=FailedScheduling count=None msg=0/6 nodes are available: 1 c_wall violated: 2 conflicting context pair(s) with node memory, 5 node(s) had untolerated taint(s). no new claims to deallocate, preemption: 0/6 nodes are available: 1 No preemption victims found for incoming pod, 5 Preemption is not helpful for scheduling."
0.0348,Event,ADDED,eval-sanitize-1-r0-053-pgppj.18d41f2db8c977f1,"reason=FailedScheduling count=None msg=0/6 nodes are available: 1 c_wall violated: 2 conflicting context pair(s) with node memory, 5 node(s) had untolerated taint(s). no new claims to deallocate, preemption: 0/6 nodes are available: 1 No preemption victims found for incoming pod, 5 Preemption is not helpful for scheduling."
0.0351,Event,ADDED,eval-sanitize-1-r0-055-djfzn.18d41f2e1cab1aa9,"reason=FailedScheduling count=None msg=0/6 nodes are available: 1 c_wall violated: 1 conflicting context pair(s) with node memory, 5 node(s) had untolerated taint(s). no new claims to deallocate, preemption: 0/6 nodes are available: 1 No preemption victims found for incoming pod, 5 Preemption is not helpful for scheduling."
0.0353,Event,ADDED,eval-sanitize-1-r0-057-gwjmb.18d41f2e93302015,"reason=FailedScheduling count=None msg=0/6 nodes are available: 1 c_wall violated: 1 conflicting context pair(s) with node memory, 5 node(s) had untolerated taint(s). no new claims to deallocate, preemption: 0/6 nodes are available: 1 No preemption victims found for incoming pod, 5 Preemption is not helpful for scheduling."
0.0357,Event,ADDED,eval-sanitize-1-r0-058-gxw45.18d41f311c1b96e6,"reason=FailedScheduling count=None msg=0/6 nodes are available: 1 c_wall violated: 1 conflicting context pair(s) with node memory, 1 c_wall violated: 2 conflicting context pair(s) with node memory, 4 node(s) had untolerated taint(s). no new claims to deallocate, preemption: 0/6 nodes are available: 2 No preemption victims found for incoming pod, 4 Preemption is not helpful for scheduling."
0.0359,Event,ADDED,eval-sanitize-1-r0-058-gxw45.18d41f3175d342fc,"reason=FailedScheduling count=None msg=0/6 nodes are available: 1 c_wall violated: 2 conflicting context pair(s) with node memory, 5 node(s) had untolerated taint(s). no new claims to deallocate, preemption: 0/6 nodes are available: 1 No preemption victims found for incoming pod, 5 Preemption is not helpful for scheduling."
0.0361,Event,ADDED,eval-sanitize-1-r0-060-fs5lb.18d41f3120101964,"reason=FailedScheduling count=None msg=0/6 nodes are available: 1 c_wall violated: 1 conflicting context pair(s) with node memory, 1 c_wall violated: 2 conflicting context pair(s) with node memory, 4 node(s) had untolerated taint(s). no new claims to deallocate, preemption: 0/6 nodes are available: 2 No preemption victims found for incoming pod, 4 Preemption is not helpful for scheduling."
0.0364,Event,ADDED,eval-sanitize-1-r0-060-fs5lb.18d41f31455e336c,"reason=FailedScheduling count=None msg=0/6 nodes are available: 1 c_wall violated: 2 conflicting context pair(s) with node memory, 5 node(s) had untolerated taint(s). no new claims to deallocate, preemption: 0/6 nodes are available: 1 No preemption victims found for incoming pod, 5 Preemption is not helpful for scheduling."
0.0366,Event,ADDED,eval-sanitize-1-r0-060-fs5lb.18d41f317605c516,"reason=FailedScheduling count=None msg=0/6 nodes are available: 1 c_wall violated: 2 conflicting context pair(s) with node memory, 5 node(s) had untolerated taint(s). no new claims to deallocate, preemption: 0/6 nodes are available: 1 No preemption victims found for incoming pod, 5 Preemption is not helpful for scheduling."
0.0368,Event,ADDED,eval-sanitize-1-r0-063-tshsq.18d41f3110139346,"reason=FailedScheduling count=None msg=0/6 nodes are available: 1 c_wall violated: 1 conflicting context pair(s) with node memory, 1 c_wall violated: 2 conflicting context pair(s) with node memory, 4 node(s) had untolerated taint(s). no new claims to deallocate, preemption: 0/6 nodes are available: 2 No preemption victims found for incoming pod, 4 Preemption is not helpful for scheduling."
0.0371,Event,ADDED,eval-sanitize-1-r0-063-tshsq.18d41f3145b471b3,"reason=FailedScheduling count=None msg=0/6 nodes are available: 1 c_wall violated: 2 conflicting context pair(s) with node memory, 5 node(s) had untolerated taint(s). no new claims to deallocate, preemption: 0/6 nodes are available: 1 No preemption victims found for incoming pod, 5 Preemption is not helpful for scheduling."
0.0373,Event,ADDED,eval-sanitize-1-r0-063-tshsq.18d41f317634735a,"reason=FailedScheduling count=None msg=0/6 nodes are available: 1 c_wall violated: 2 conflicting context pair(s) with node memory, 5 node(s) had untolerated taint(s). no new claims to deallocate, preemption: 0/6 nodes are available: 1 No preemption victims found for incoming pod, 5 Preemption is not helpful for scheduling."
0.0375,Event,ADDED,eval-sanitize-1-r0-064-ck955.18d41f311064395d,"reason=FailedScheduling count=None msg=0/6 nodes are available: 2 c_wall violated: 2 conflicting context pair(s) with node memory, 4 node(s) had untolerated taint(s). no new claims to deallocate, preemption: 0/6 nodes are available: 2 No preemption victims found for incoming pod, 4 Preemption is not helpful for scheduling."
0.0378,Event,ADDED,eval-sanitize-1-r0-064-ck955.18d41f3145e17543,"reason=FailedScheduling count=None msg=0/6 nodes are available: 1 c_wall violated: 2 conflicting context pair(s) with node memory, 5 node(s) had untolerated taint(s). no new claims to deallocate, preemption: 0/6 nodes are available: 1 No preemption victims found for incoming pod, 5 Preemption is not helpful for scheduling."
0.038,Event,ADDED,eval-sanitize-1-r0-065-6v8q6.18d41f3110b80296,"reason=FailedScheduling count=None msg=0/6 nodes are available: 2 c_wall violated: 2 conflicting context pair(s) with node memory, 4 node(s) had untolerated taint(s). no new claims to deallocate, preemption: 0/6 nodes are available: 2 No preemption victims found for incoming pod, 4 Preemption is not helpful for scheduling."
0.0382,Event,ADDED,eval-sanitize-1-r0-065-6v8q6.18d41f314611a257,"reason=FailedScheduling count=None msg=0/6 nodes are available: 1 c_wall violated: 2 conflicting context pair(s) with node memory, 5 node(s) had untolerated taint(s). no new claims to deallocate, preemption: 0/6 nodes are available: 1 No preemption victims found for incoming pod, 5 Preemption is not helpful for scheduling."
0.0386,Event,ADDED,eval-sanitize-1-r0-066-gsqwg.18d41f311633513e,"reason=FailedScheduling count=None msg=0/6 nodes are available: 1 c_wall violated: 1 conflicting context pair(s) with node memory, 1 c_wall violated: 2 conflicting context pair(s) with node memory, 4 node(s) had untolerated taint(s). no new claims to deallocate, preemption: 0/6 nodes are available: 2 No preemption victims found for incoming pod, 4 Preemption is not helpful for scheduling."
0.0388,Event,ADDED,eval-sanitize-1-r0-067-h6pnc.18d41f311a34379b,"reason=FailedScheduling count=None msg=0/6 nodes are available: 1 c_wall violated: 1 conflicting context pair(s) with node memory, 1 c_wall violated: 2 conflicting context pair(s) with node memory, 4 node(s) had untolerated taint(s). no new claims to deallocate, preemption: 0/6 nodes are available: 2 No preemption victims found for incoming pod, 4 Preemption is not helpful for scheduling."
0.0389,TaskRequest,ADDED,eval-sanitize-1-r2-000,phase=None job=None
0.0394,Event,ADDED,eval-sanitize-1-r0-068-d8nm2.18d41f3116874714,"reason=FailedScheduling count=None msg=0/6 nodes are available: 2 c_wall violated: 2 conflicting context pair(s) with node memory, 4 node(s) had untolerated taint(s). no new claims to deallocate, preemption: 0/6 nodes are available: 2 No preemption victims found for incoming pod, 4 Preemption is not helpful for scheduling."
0.0396,Event,ADDED,eval-sanitize-1-r0-069-cvks5.18d41f3175a6189d,"reason=FailedScheduling count=None msg=0/6 nodes are available: 1 c_wall violated: 1 conflicting context pair(s) with node memory, 5 node(s) had untolerated taint(s). no new claims to deallocate, preemption: 0/6 nodes are available: 1 No preemption victims found for incoming pod, 5 Preemption is not helpful for scheduling."
0.0398,Event,ADDED,eval-sanitize-1-r0-070-lhjss.18d41f317c7ce7be,"reason=FailedScheduling count=None msg=0/6 nodes are available: 1 c_wall violated: 2 conflicting context pair(s) with node memory, 5 node(s) had untolerated taint(s). no new claims to deallocate, preemption: 0/6 nodes are available: 1 No preemption victims found for incoming pod, 5 Preemption is not helpful for scheduling."
0.0401,Event,ADDED,eval-sanitize-1-r0-073-frs5s.18d41f33e431632c,"reason=FailedScheduling count=None msg=0/6 nodes are available: 1 c_wall violated: 2 conflicting context pair(s) with node memory, 5 node(s) had untolerated taint(s). no new claims to deallocate, preemption: 0/6 nodes are available: 1 No preemption victims found for incoming pod, 5 Preemption is not helpful for scheduling."
0.0403,Event,ADDED,eval-sanitize-1-r0-075-qxvn5.18d41f33dee28983,"reason=FailedScheduling count=None msg=0/6 nodes are available: 1 c_wall violated: 1 conflicting context pair(s) with node memory, 5 node(s) had untolerated taint(s). no new claims to deallocate, preemption: 0/6 nodes are available: 1 No preemption victims found for incoming pod, 5 Preemption is not helpful for scheduling."
0.0406,Event,ADDED,eval-sanitize-1-r0-075-qxvn5.18d41f3422dcab91,"reason=FailedScheduling count=None msg=0/6 nodes are available: 1 c_wall violated: 2 conflicting context pair(s) with node memory, 5 node(s) had untolerated taint(s). no new claims to deallocate, preemption: 0/6 nodes are available: 1 No preemption victims found for incoming pod, 5 Preemption is not helpful for scheduling."
0.041,Event,ADDED,eval-sanitize-1-r0-076-b6sl7.18d41f33df07d162,"reason=FailedScheduling count=None msg=0/6 nodes are available: 1 c_wall violated: 1 conflicting context pair(s) with node memory, 5 node(s) had untolerated taint(s). no new claims to deallocate, preemption: 0/6 nodes are available: 1 No preemption victims found for incoming pod, 5 Preemption is not helpful for scheduling."
0.0412,Event,ADDED,eval-sanitize-1-r0-077-rprg7.18d41f33df2f8e13,"reason=FailedScheduling count=None msg=0/6 nodes are available: 1 c_wall violated: 1 conflicting context pair(s) with node memory, 5 node(s) had untolerated taint(s). no new claims to deallocate, preemption: 0/6 nodes are available: 1 No preemption victims found for incoming pod, 5 Preemption is not helpful for scheduling."
0.0414,Event,ADDED,eval-sanitize-1-r0-078-p7p96.18d41f33e394be8d,"reason=FailedScheduling count=None msg=0/6 nodes are available: 1 c_wall violated: 2 conflicting context pair(s) with node memory, 5 node(s) had untolerated taint(s). no new claims to deallocate, preemption: 0/6 nodes are available: 1 No preemption victims found for incoming pod, 5 Preemption is not helpful for scheduling."
0.0416,Event,ADDED,eval-sanitize-1-r0-079-fgs9f.18d41f33e3d4fce0,"reason=FailedScheduling count=None msg=0/6 nodes are available: 1 c_wall violated: 1 conflicting context pair(s) with node memory, 5 node(s) had untolerated taint(s). no new claims to deallocate, preemption: 0/6 nodes are available: 1 No preemption victims found for incoming pod, 5 Preemption is not helpful for scheduling."
0.0418,Event,ADDED,eval-sanitize-1-r0-080-sbxzs.18d41f33e405bf38,"reason=FailedScheduling count=None msg=0/6 nodes are available: 1 c_wall violated: 1 conflicting context pair(s) with node memory, 5 node(s) had untolerated taint(s). no new claims to deallocate, preemption: 0/6 nodes are available: 1 No preemption victims found for incoming pod, 5 Preemption is not helpful for scheduling."
0.042,Event,ADDED,eval-sanitize-1-r0-081-78f85.18d41f340b4ed876,"reason=FailedScheduling count=None msg=0/6 nodes are available: 1 c_wall violated: 2 conflicting context pair(s) with node memory, 5 node(s) had untolerated taint(s). no new claims to deallocate, preemption: 0/6 nodes are available: 1 No preemption victims found for incoming pod, 5 Preemption is not helpful for scheduling."
0.0423,Event,ADDED,eval-sanitize-1-r0-082-9hftz.18d41f344746ab5a,"reason=FailedScheduling count=None msg=0/6 nodes are available: 1 c_wall violated: 1 conflicting context pair(s) with node memory, 5 node(s) had untolerated taint(s). no new claims to deallocate, preemption: 0/6 nodes are available: 1 No preemption victims found for incoming pod, 5 Preemption is not helpful for scheduling."
0.0425,Event,ADDED,eval-sanitize-1-r0-082-9hftz.18d41f35b3673492,"reason=FailedScheduling count=None msg=0/6 nodes are available: 1 c_wall violated: 2 conflicting context pair(s) with node memory, 5 node(s) had untolerated taint(s). no new claims to deallocate, preemption: 0/6 nodes are available: 1 No preemption victims found for incoming pod, 5 Preemption is not helpful for scheduling."
0.0429,Event,ADDED,eval-sanitize-1-r0-082-9hftz.18d41f35d028d021,"reason=FailedScheduling count=None msg=0/6 nodes are available: 1 c_wall violated: 1 conflicting context pair(s) with node memory, 1 c_wall violated: 2 conflicting context pair(s) with node memory, 4 node(s) had untolerated taint(s). no new claims to deallocate, preemption: 0/6 nodes are available: 2 No preemption victims found for incoming pod, 4 Preemption is not helpful for scheduling."
0.0431,Event,ADDED,eval-sanitize-1-r0-083-brzw2.18d41f35bb145f03,"reason=FailedScheduling count=None msg=0/6 nodes are available: 1 c_wall violated: 3 conflicting context pair(s) with node memory, 5 node(s) had untolerated taint(s). no new claims to deallocate, preemption: 0/6 nodes are available: 1 No preemption victims found for incoming pod, 5 Preemption is not helpful for scheduling."
0.0433,Event,ADDED,eval-sanitize-1-r0-086-5sfbh.18d41f35babb2dd0,"reason=FailedScheduling count=None msg=0/6 nodes are available: 1 c_wall violated: 3 conflicting context pair(s) with node memory, 5 node(s) had untolerated taint(s). no new claims to deallocate, preemption: 0/6 nodes are available: 1 No preemption victims found for incoming pod, 5 Preemption is not helpful for scheduling."
0.0436,Event,ADDED,eval-sanitize-1-r0-089-sgfqw.18d41f35e881fa87,"reason=FailedScheduling count=None msg=0/6 nodes are available: 1 c_wall violated: 1 conflicting context pair(s) with node memory, 1 c_wall violated: 2 conflicting context pair(s) with node memory, 4 node(s) had untolerated taint(s). no new claims to deallocate, preemption: 0/6 nodes are available: 2 No preemption victims found for incoming pod, 4 Preemption is not helpful for scheduling."
0.0438,Event,ADDED,eval-sanitize-1-r0-094-ldwkb.18d41f378d3f5258,"reason=FailedScheduling count=None msg=0/6 nodes are available: 1 c_wall violated: 3 conflicting context pair(s) with node memory, 5 node(s) had untolerated taint(s). no new claims to deallocate, preemption: 0/6 nodes are available: 1 No preemption victims found for incoming pod, 5 Preemption is not helpful for scheduling."
0.0453,TaskRequest,MODIFIED,eval-sanitize-1-r2-000,phase=Pending job=None
0.0624,Job,ADDED,eval-sanitize-1-r2-000,
0.0673,TaskRequest,MODIFIED,eval-sanitize-1-r2-000,phase=Scheduled job=None
0.0704,Pod,ADDED,eval-sanitize-1-r2-000-d9psq,phase=Pending node=None
0.074,Job,MODIFIED,eval-sanitize-1-r2-000,
0.0786,TaskRequest,MODIFIED,eval-sanitize-1-r2-000,phase=Scheduled job=None
0.0806,Event,ADDED,eval-sanitize-1-r2-000.18d41fb09b979839,reason=SuccessfulCreate count=1 msg=Created pod: eval-sanitize-1-r2-000-d9psq
0.0853,Pod,MODIFIED,eval-sanitize-1-r2-000-d9psq,phase=Pending node=kind-worker5
0.0921,Event,ADDED,eval-sanitize-1-r2-000-d9psq.18d41fb09c7c1b39,reason=Scheduled count=None msg=Successfully assigned compute/eval-sanitize-1-r2-000-d9psq to kind-worker5
0.0962,Pod,MODIFIED,eval-sanitize-1-r2-000-d9psq,phase=Pending node=kind-worker5
0.099,Node,MODIFIED,kind-worker5,taints=0
0.1118,Node,MODIFIED,kind-worker5,taints=0
0.5039,Event,ADDED,eval-sanitize-1-r2-000-d9psq.18d41fb0b52c66f4,"reason=Pulled count=1 msg=Container image ""busybox:musl"" already present on machine"
0.5219,Event,ADDED,eval-sanitize-1-r2-000-d9psq.18d41fb0b6472bc8,reason=Created count=1 msg=Created container: task
0.5521,Node,MODIFIED,kind-worker5,taints=1
0.555,Event,ADDED,eval-sanitize-1-r2-000-d9psq.18d41fb0b84a52ef,reason=Started count=1 msg=Started container task
0.564,Node,MODIFIED,kind-worker5,taints=1
0.892,Node,MODIFIED,kind-worker2,taints=0
1.0077,TaskRequest,ADDED,eval-sanitize-1-r2-001,phase=None job=None
1.0116,TaskRequest,MODIFIED,eval-sanitize-1-r2-001,phase=Pending job=None
1.027,Job,ADDED,eval-sanitize-1-r2-001,
1.0349,Pod,ADDED,eval-sanitize-1-r2-001-65npq,phase=Pending node=None
1.0351,TaskRequest,MODIFIED,eval-sanitize-1-r2-001,phase=Scheduled job=None
1.0381,Job,MODIFIED,eval-sanitize-1-r2-001,
1.0401,Event,ADDED,eval-sanitize-1-r2-001.18d41fb0d50f0885,reason=SuccessfulCreate count=1 msg=Created pod: eval-sanitize-1-r2-001-65npq
1.044,TaskRequest,MODIFIED,eval-sanitize-1-r2-001,phase=Scheduled job=None
1.0466,Pod,MODIFIED,eval-sanitize-1-r2-001-65npq,phase=Pending node=kind-worker3
1.0503,Event,ADDED,eval-sanitize-1-r2-001-65npq.18d41fb0d5c7a3d2,reason=Scheduled count=None msg=Successfully assigned compute/eval-sanitize-1-r2-001-65npq to kind-worker3
1.0556,Node,MODIFIED,kind-worker3,taints=0
1.0581,Pod,MODIFIED,eval-sanitize-1-r2-001-65npq,phase=Pending node=kind-worker3
1.0652,Node,MODIFIED,kind-worker3,taints=0
1.0752,Job,MODIFIED,eval-sanitize-1-r2-000,
1.0837,Job,MODIFIED,eval-sanitize-1-r2-000,
1.2813,Node,MODIFIED,kind-worker3,taints=1
1.2938,Node,MODIFIED,kind-worker3,taints=1
1.4789,Event,ADDED,eval-sanitize-1-r2-001-65npq.18d41fb0ef4f0598,"reason=Pulled count=1 msg=Container image ""busybox:musl"" already present on machine"
1.4875,Pod,MODIFIED,eval-sanitize-1-r2-000-d9psq,phase=Running node=kind-worker5
1.4999,Event,ADDED,eval-sanitize-1-r2-001-65npq.18d41fb0f07a32b1,reason=Created count=1 msg=Created container: task
1.5335,Event,ADDED,eval-sanitize-1-r2-001-65npq.18d41fb0f2961cc6,reason=Started count=1 msg=Started container task
1.9674,Pod,MODIFIED,eval-sanitize-1-r2-001-65npq,phase=Running node=kind-worker3
2.0143,TaskRequest,ADDED,eval-sanitize-1-r2-002,phase=None job=None
2.0181,TaskRequest,MODIFIED,eval-sanitize-1-r2-002,phase=Pending job=None
2.0341,Job,ADDED,eval-sanitize-1-r2-002,
2.0394,Job,MODIFIED,eval-sanitize-1-r2-001,
2.0404,TaskRequest,MODIFIED,eval-sanitize-1-r2-002,phase=Scheduled job=None
2.0414,Pod,ADDED,eval-sanitize-1-r2-002-8p5db,phase=Pending node=None
2.0439,Job,MODIFIED,eval-sanitize-1-r2-002,
2.0457,Event,ADDED,eval-sanitize-1-r2-002.18d41fb111112c57,reason=SuccessfulCreate count=1 msg=Created pod: eval-sanitize-1-r2-002-8p5db
2.0495,TaskRequest,MODIFIED,eval-sanitize-1-r2-002,phase=Scheduled job=None
2.0533,Pod,MODIFIED,eval-sanitize-1-r2-002-8p5db,phase=Pending node=kind-worker
2.0549,Job,MODIFIED,eval-sanitize-1-r2-001,
2.0569,Event,ADDED,eval-sanitize-1-r2-002-8p5db.18d41fb111c91d5a,reason=Scheduled count=None msg=Successfully assigned compute/eval-sanitize-1-r2-002-8p5db to kind-worker
2.0637,Node,MODIFIED,kind-worker,taints=0
2.0667,Pod,MODIFIED,eval-sanitize-1-r2-002-8p5db,phase=Pending node=kind-worker
2.0744,Node,MODIFIED,kind-worker,taints=0
2.0797,Job,MODIFIED,eval-sanitize-1-r2-000,
2.0896,Job,MODIFIED,eval-sanitize-1-r2-000,
2.5018,Event,ADDED,eval-sanitize-1-r2-002-8p5db.18d41fb12c493c45,"reason=Pulled count=1 msg=Container image ""busybox:musl"" already present on machine"
2.5186,Event,ADDED,eval-sanitize-1-r2-002-8p5db.18d41fb12d583da1,reason=Created count=1 msg=Created container: task
2.5539,Event,ADDED,eval-sanitize-1-r2-002-8p5db.18d41fb12f5a5231,reason=Started count=1 msg=Started container task
2.5615,Node,MODIFIED,kind-worker,taints=1
2.5724,Node,MODIFIED,kind-worker,taints=1
3.0262,TaskRequest,ADDED,eval-sanitize-1-r2-003,phase=None job=None
3.0313,TaskRequest,MODIFIED,eval-sanitize-1-r2-003,phase=Pending job=None
3.0448,Job,ADDED,eval-sanitize-1-r2-003,
3.0469,Job,MODIFIED,eval-sanitize-1-r2-002,
3.0513,Pod,ADDED,eval-sanitize-1-r2-003-9x5tt,phase=Pending node=None
3.0526,TaskRequest,MODIFIED,eval-sanitize-1-r2-003,phase=Scheduled job=None
3.0534,Job,MODIFIED,eval-sanitize-1-r2-003,
3.0554,Event,ADDED,eval-sanitize-1-r2-003.18d41fb14d492ca3,reason=SuccessfulCreate count=1 msg=Created pod: eval-sanitize-1-r2-003-9x5tt
3.0607,Pod,MODIFIED,eval-sanitize-1-r2-003-9x5tt,phase=Pending node=kind-worker4
3.0608,TaskRequest,MODIFIED,eval-sanitize-1-r2-003,phase=Scheduled job=None
3.0636,Job,MODIFIED,eval-sanitize-1-r2-002,
3.064,Event,ADDED,eval-sanitize-1-r2-003-9x5tt.18d41fb14dc4b7b8,reason=Scheduled count=None msg=Successfully assigned compute/eval-sanitize-1-r2-003-9x5tt to kind-worker4
3.0693,Pod,MODIFIED,eval-sanitize-1-r2-003-9x5tt,phase=Pending node=kind-worker4
3.0714,Node,MODIFIED,kind-worker4,taints=0
3.0833,Node,MODIFIED,kind-worker4,taints=0
3.5058,Event,ADDED,eval-sanitize-1-r2-003-9x5tt.18d41fb168210e74,"reason=Pulled count=1 msg=Container image ""busybox:musl"" already present on machine"
3.5224,Event,ADDED,eval-sanitize-1-r2-003-9x5tt.18d41fb1692a6072,reason=Created count=1 msg=Created container: task
3.5745,Pod,MODIFIED,eval-sanitize-1-r2-002-8p5db,phase=Running node=kind-worker
3.5769,Node,MODIFIED,kind-worker4,taints=1
3.5897,Node,MODIFIED,kind-worker4,taints=1
3.5901,Event,ADDED,eval-sanitize-1-r2-003-9x5tt.18d41fb16d25a810,reason=Started count=1 msg=Started container task
3.7714,Pod,MODIFIED,eval-sanitize-1-r2-003-9x5tt,phase=Running node=kind-worker4
4.0137,TaskRequest,ADDED,eval-sanitize-1-r2-004,phase=None job=None
4.0173,TaskRequest,MODIFIED,eval-sanitize-1-r2-004,phase=Pending job=None
4.0336,Job,ADDED,eval-sanitize-1-r2-004,
4.0399,Pod,ADDED,eval-sanitize-1-r2-004-bhlgt,phase=Pending node=None
4.0414,Job,MODIFIED,eval-sanitize-1-r2-004,
4.0415,TaskRequest,MODIFIED,eval-sanitize-1-r2-004,phase=Scheduled job=None
4.0454,Event,ADDED,eval-sanitize-1-r2-004.18d41fb18835a719,reason=SuccessfulCreate count=1 msg=Created pod: eval-sanitize-1-r2-004-bhlgt
4.0462,Pod,MODIFIED,eval-sanitize-1-r2-004-bhlgt,phase=Pending node=kind-worker2
4.0485,TaskRequest,MODIFIED,eval-sanitize-1-r2-004,phase=Scheduled job=None
4.051,Event,ADDED,eval-sanitize-1-r2-004-bhlgt.18d41fb188925167,reason=Scheduled count=None msg=Successfully assigned compute/eval-sanitize-1-r2-004-bhlgt to kind-worker2
4.0537,Job,MODIFIED,eval-sanitize-1-r2-002,
4.0571,Job,MODIFIED,eval-sanitize-1-r2-003,
4.0588,Node,MODIFIED,kind-worker2,taints=0
4.0625,Pod,MODIFIED,eval-sanitize-1-r2-004-bhlgt,phase=Pending node=kind-worker2
4.0637,Job,MODIFIED,eval-sanitize-1-r2-002,
4.0654,Job,MODIFIED,eval-sanitize-1-r2-003,
4.0684,Node,MODIFIED,kind-worker2,taints=0
4.2984,Node,MODIFIED,kind-worker2,taints=1
4.3105,Node,MODIFIED,kind-worker2,taints=1
4.4837,Event,ADDED,eval-sanitize-1-r2-004-bhlgt.18d41fb1a2617d6f,"reason=Pulled count=1 msg=Container image ""busybox:musl"" already present on machine"
4.5026,Event,ADDED,eval-sanitize-1-r2-004-bhlgt.18d41fb1a37d1b30,reason=Created count=1 msg=Created container: task
4.5346,Event,ADDED,eval-sanitize-1-r2-004-bhlgt.18d41fb1a578d690,reason=Started count=1 msg=Started container task
5.0081,TaskRequest,ADDED,eval-sanitize-1-r2-005,phase=None job=None
5.0116,TaskRequest,MODIFIED,eval-sanitize-1-r2-005,phase=Pending job=None
5.0276,Job,ADDED,eval-sanitize-1-r2-005,
5.034,Pod,ADDED,eval-sanitize-1-r2-005-2bx8m,phase=Pending node=None
5.0353,TaskRequest,MODIFIED,eval-sanitize-1-r2-005,phase=Scheduled job=None
5.0362,Job,MODIFIED,eval-sanitize-1-r2-005,
5.04,Event,ADDED,eval-sanitize-1-r2-005.18d41fb1c3795b2d,reason=SuccessfulCreate count=1 msg=Created pod: eval-sanitize-1-r2-005-2bx8m
5.0402,Event,ADDED,eval-sanitize-1-r2-005-2bx8m.18d41fb1c385c4e2,"reason=FailedScheduling count=None msg=0/6 nodes are available: 6 node(s) had untolerated taint(s). no new claims to deallocate, preemption: 0/6 nodes are available: 6 Preemption is not helpful for scheduling."
5.0411,Pod,MODIFIED,eval-sanitize-1-r2-005-2bx8m,phase=Pending node=None
5.0437,Job,MODIFIED,eval-sanitize-1-r2-004,
5.0476,TaskRequest,MODIFIED,eval-sanitize-1-r2-005,phase=Scheduled job=None
5.0518,Job,MODIFIED,eval-sanitize-1-r2-004,
5.1221,Pod,MODIFIED,eval-sanitize-1-r2-004-bhlgt,phase=Running node=kind-worker2
6.0078,TaskRequest,ADDED,eval-sanitize-1-r2-006,phase=None job=None
6.0117,TaskRequest,MODIFIED,eval-sanitize-1-r2-006,phase=Pending job=None
6.0275,Job,ADDED,eval-sanitize-1-r2-006,
6.0316,TaskRequest,MODIFIED,eval-sanitize-1-r2-006,phase=Scheduled job=None
6.0345,Pod,ADDED,eval-sanitize-1-r2-006-hjp5g,phase=Pending node=None
6.0371,Job,MODIFIED,eval-sanitize-1-r2-006,
6.0404,Job,MODIFIED,eval-sanitize-1-r2-005,
6.0421,Event,ADDED,eval-sanitize-1-r2-006.18d41fb1ff1be355,reason=SuccessfulCreate count=1 msg=Created pod: eval-sanitize-1-r2-006-hjp5g
6.0423,Event,ADDED,eval-sanitize-1-r2-006-hjp5g.18d41fb1ff2758ce,"reason=FailedScheduling count=None msg=0/6 nodes are available: 6 node(s) had untolerated taint(s). no new claims to deallocate, preemption: 0/6 nodes are available: 6 Preemption is not helpful for scheduling."
6.0435,Pod,MODIFIED,eval-sanitize-1-r2-006-hjp5g,phase=Pending node=None
6.0437,TaskRequest,MODIFIED,eval-sanitize-1-r2-006,phase=Scheduled job=None
6.0493,Job,MODIFIED,eval-sanitize-1-r2-004,
6.0514,Job,MODIFIED,eval-sanitize-1-r2-005,
6.0577,Job,MODIFIED,eval-sanitize-1-r2-004,
7.0095,TaskRequest,ADDED,eval-sanitize-1-r2-007,phase=None job=None
7.0133,TaskRequest,MODIFIED,eval-sanitize-1-r2-007,phase=Pending job=None
7.0291,Job,ADDED,eval-sanitize-1-r2-007,
7.036,Pod,ADDED,eval-sanitize-1-r2-007-fzlg7,phase=Pending node=None
7.0361,TaskRequest,MODIFIED,eval-sanitize-1-r2-007,phase=Scheduled job=None
7.0385,Job,MODIFIED,eval-sanitize-1-r2-007,
7.0406,Event,ADDED,eval-sanitize-1-r2-007.18d41fb23ac5eca0,reason=SuccessfulCreate count=1 msg=Created pod: eval-sanitize-1-r2-007-fzlg7
7.0415,Job,MODIFIED,eval-sanitize-1-r2-006,
7.0424,Pod,MODIFIED,eval-sanitize-1-r2-007-fzlg7,phase=Pending node=None
7.0427,Event,ADDED,eval-sanitize-1-r2-007-fzlg7.18d41fb23acd839d,"reason=FailedScheduling count=None msg=0/6 nodes are available: 6 node(s) had untolerated taint(s). no new claims to deallocate, preemption: 0/6 nodes are available: 6 Preemption is not helpful for scheduling."
7.0434,TaskRequest,MODIFIED,eval-sanitize-1-r2-007,phase=Scheduled job=None
7.0493,Job,MODIFIED,eval-sanitize-1-r2-006,
8.0126,TaskRequest,ADDED,eval-sanitize-1-r2-008,phase=None job=None
8.0161,TaskRequest,MODIFIED,eval-sanitize-1-r2-008,phase=Pending job=None
8.0315,Job,ADDED,eval-sanitize-1-r2-008,
8.0381,Pod,ADDED,eval-sanitize-1-r2-008-7hn5w,phase=Pending node=None
8.0381,TaskRequest,MODIFIED,eval-sanitize-1-r2-008,phase=Scheduled job=None
8.0408,Job,MODIFIED,eval-sanitize-1-r2-007,
8.0415,Job,MODIFIED,eval-sanitize-1-r2-008,
8.0424,Event,ADDED,eval-sanitize-1-r2-008.18d41fb276856e53,reason=SuccessfulCreate count=1 msg=Created pod: eval-sanitize-1-r2-008-7hn5w
8.0437,Pod,MODIFIED,eval-sanitize-1-r2-008-7hn5w,phase=Pending node=None
8.044,Event,ADDED,eval-sanitize-1-r2-008-7hn5w.18d41fb27690ba09,"reason=FailedScheduling count=None msg=0/6 nodes are available: 6 node(s) had untolerated taint(s). no new claims to deallocate, preemption: 0/6 nodes are available: 6 Preemption is not helpful for scheduling."
8.0445,TaskRequest,MODIFIED,eval-sanitize-1-r2-008,phase=Scheduled job=None
8.0503,Job,MODIFIED,eval-sanitize-1-r2-007,
9.0135,TaskRequest,ADDED,eval-sanitize-1-r2-009,phase=None job=None
9.0175,TaskRequest,MODIFIED,eval-sanitize-1-r2-009,phase=Pending job=None
9.034,Job,ADDED,eval-sanitize-1-r2-009,
9.038,TaskRequest,MODIFIED,eval-sanitize-1-r2-009,phase=Scheduled job=None
9.0411,Pod,ADDED,eval-sanitize-1-r2-009-4dhzg,phase=Pending node=None
9.0433,Job,MODIFIED,eval-sanitize-1-r2-008,
9.0443,Job,MODIFIED,eval-sanitize-1-r2-009,
9.0472,Event,ADDED,eval-sanitize-1-r2-009.18d41fb2b2515cd8,reason=SuccessfulCreate count=1 msg=Created pod: eval-sanitize-1-r2-009-4dhzg
9.0475,Event,ADDED,eval-sanitize-1-r2-009-4dhzg.18d41fb2b25b4ac6,"reason=FailedScheduling count=None msg=0/6 nodes are available: 6 node(s) had untolerated taint(s). no new claims to deallocate, preemption: 0/6 nodes are available: 6 Preemption is not helpful for scheduling."
9.0477,TaskRequest,MODIFIED,eval-sanitize-1-r2-009,phase=Scheduled job=None
9.0488,Pod,MODIFIED,eval-sanitize-1-r2-009-4dhzg,phase=Pending node=None
9.0538,Job,MODIFIED,eval-sanitize-1-r2-008,
10.0085,TaskRequest,ADDED,eval-sanitize-1-r2-010,phase=None job=None
10.0134,TaskRequest,MODIFIED,eval-sanitize-1-r2-010,phase=Pending job=None
10.0298,Job,ADDED,eval-sanitize-1-r2-010,
10.0341,TaskRequest,MODIFIED,eval-sanitize-1-r2-010,phase=Scheduled job=None
10.0384,Pod,ADDED,eval-sanitize-1-r2-010-wsghf,phase=Pending node=None
10.0399,Job,MODIFIED,eval-sanitize-1-r2-010,
10.0405,TaskRequest,MODIFIED,eval-sanitize-1-r2-010,phase=Scheduled job=None
10.045,Event,ADDED,eval-sanitize-1-r2-010.18d41fb2edc3b85c,reason=SuccessfulCreate count=1 msg=Created pod: eval-sanitize-1-r2-010-wsghf
10.0454,Event,ADDED,eval-sanitize-1-r2-010-wsghf.18d41fb2edd03934,"reason=FailedScheduling count=None msg=0/6 nodes are available: 6 node(s) had untolerated taint(s). no new claims to deallocate, preemption: 0/6 nodes are available: 6 Preemption is not helpful for scheduling."
10.0463,Job,MODIFIED,eval-sanitize-1-r2-009,
10.0472,Pod,MODIFIED,eval-sanitize-1-r2-010-wsghf,phase=Pending node=None
10.0541,Job,MODIFIED,eval-sanitize-1-r2-009,
11.0094,TaskRequest,ADDED,eval-sanitize-1-r2-011,phase=None job=None
11.0134,TaskRequest,MODIFIED,eval-sanitize-1-r2-011,phase=Pending job=None
11.0301,Job,ADDED,eval-sanitize-1-r2-011,
11.0358,Pod,ADDED,eval-sanitize-1-r2-011-5sw64,phase=Pending node=None
11.0369,TaskRequest,MODIFIED,eval-sanitize-1-r2-011,phase=Scheduled job=None
11.0398,Job,MODIFIED,eval-sanitize-1-r2-011,
11.0417,Event,ADDED,eval-sanitize-1-r2-011.18d41fb329299b31,reason=SuccessfulCreate count=1 msg=Created pod: eval-sanitize-1-r2-011-5sw64
11.0427,Pod,MODIFIED,eval-sanitize-1-r2-011-5sw64,phase=Pending node=None
11.0434,Event,ADDED,eval-sanitize-1-r2-011-5sw64.18d41fb3293605f4,"reason=FailedScheduling count=None msg=0/6 nodes are available: 6 node(s) had untolerated taint(s). no new claims to deallocate, preemption: 0/6 nodes are available: 6 Preemption is not helpful for scheduling."
11.0442,Job,MODIFIED,eval-sanitize-1-r2-010,
11.0453,TaskRequest,MODIFIED,eval-sanitize-1-r2-011,phase=Scheduled job=None
11.0544,Job,MODIFIED,eval-sanitize-1-r2-010,
11.5059,Pod,MODIFIED,eval-sanitize-1-r2-000-d9psq,phase=Running node=kind-worker5
11.9825,Pod,MODIFIED,eval-sanitize-1-r2-001-65npq,phase=Running node=kind-worker3
12.0127,TaskRequest,ADDED,eval-sanitize-1-r2-012,phase=None job=None
12.018,TaskRequest,MODIFIED,eval-sanitize-1-r2-012,phase=Pending job=None
12.0328,Job,ADDED,eval-sanitize-1-r2-012,
12.0387,Pod,ADDED,eval-sanitize-1-r2-012-jmcgx,phase=Pending node=None
12.0401,TaskRequest,MODIFIED,eval-sanitize-1-r2-012,phase=Scheduled job=None
12.0432,Job,MODIFIED,eval-sanitize-1-r2-011,
12.0445,Job,MODIFIED,eval-sanitize-1-r2-012,
12.0451,Event,ADDED,eval-sanitize-1-r2-012.18d41fb364eae792,reason=SuccessfulCreate count=1 msg=Created pod: eval-sanitize-1-r2-012-jmcgx
12.0454,Event,ADDED,eval-sanitize-1-r2-012-jmcgx.18d41fb364fdff2b,"reason=FailedScheduling count=None msg=0/6 nodes are available: 6 node(s) had untolerated taint(s). no new claims to deallocate, preemption: 0/6 nodes are available: 6 Preemption is not helpful for scheduling."
12.0466,Pod,MODIFIED,eval-sanitize-1-r2-012-jmcgx,phase=Pending node=None
12.0488,TaskRequest,MODIFIED,eval-sanitize-1-r2-012,phase=Scheduled job=None
12.0535,Job,MODIFIED,eval-sanitize-1-r2-011,
12.5153,Job,MODIFIED,eval-sanitize-1-r2-000,
12.5242,Job,MODIFIED,eval-sanitize-1-r2-000,
12.7015,Pod,MODIFIED,eval-sanitize-1-r2-000-d9psq,phase=Succeeded node=kind-worker5
12.989,Job,MODIFIED,eval-sanitize-1-r2-001,
12.9997,Job,MODIFIED,eval-sanitize-1-r2-001,
13.012,TaskRequest,ADDED,eval-sanitize-1-r2-013,phase=None job=None
13.017,TaskRequest,MODIFIED,eval-sanitize-1-r2-013,phase=Pending job=None
13.0311,Job,ADDED,eval-sanitize-1-r2-013,
13.0375,TaskRequest,MODIFIED,eval-sanitize-1-r2-013,phase=Scheduled job=None
13.0397,Pod,ADDED,eval-sanitize-1-r2-013-kl8tg,phase=Pending node=None
13.0406,Job,MODIFIED,eval-sanitize-1-r2-013,
13.0447,Pod,MODIFIED,eval-sanitize-1-r2-013-kl8tg,phase=Pending node=None
13.0458,Job,MODIFIED,eval-sanitize-1-r2-012,
13.0465,Event,ADDED,eval-sanitize-1-r2-013.18d41fb3a0924ea6,reason=SuccessfulCreate count=1 msg=Created pod: eval-sanitize-1-r2-013-kl8tg
13.0467,Event,ADDED,eval-sanitize-1-r2-013-kl8tg.18d41fb3a0a18dc1,"reason=FailedScheduling count=None msg=0/6 nodes are available: 6 node(s) had untolerated taint(s). no new claims to deallocate, preemption: 0/6 nodes are available: 6 Preemption is not helpful for scheduling."
13.0468,TaskRequest,MODIFIED,eval-sanitize-1-r2-013,phase=Scheduled job=None
13.0532,Job,MODIFIED,eval-sanitize-1-r2-012,
13.0755,Pod,MODIFIED,eval-sanitize-1-r2-001-65npq,phase=Succeeded node=kind-worker3
13.5222,Job,MODIFIED,eval-sanitize-1-r2-000,
13.532,Pod,MODIFIED,eval-sanitize-1-r2-000-d9psq,phase=Succeeded node=kind-worker5
13.5334,Job,MODIFIED,eval-sanitize-1-r2-000,
13.5361,Node,MODIFIED,kind-worker5,taints=1
13.5791,Pod,MODIFIED,eval-sanitize-1-r2-002-8p5db,phase=Running node=kind-worker
13.6325,Node,MODIFIED,kind-worker5,taints=1
13.6501,Node,MODIFIED,kind-worker5,taints=0
13.6557,Pod,MODIFIED,eval-sanitize-1-r2-005-2bx8m,phase=Pending node=kind-worker5
13.6616,Pod,MODIFIED,eval-sanitize-1-r2-006-hjp5g,phase=Pending node=kind-worker5
13.6625,Event,ADDED,eval-sanitize-1-r2-005-2bx8m.18d41fb3c55231a3,reason=Scheduled count=None msg=Successfully assigned compute/eval-sanitize-1-r2-005-2bx8m to kind-worker5
13.6637,Pod,MODIFIED,eval-sanitize-1-r2-007-fzlg7,phase=Pending node=kind-worker5
13.6676,Node,MODIFIED,kind-worker5,taints=0
13.6701,Event,ADDED,eval-sanitize-1-r2-008-7hn5w.18d41fb3c59e1ab2,"reason=FailedScheduling count=None msg=0/6 nodes are available: 1 c_wall violated: 2 conflicting context pair(s) with node memory, 5 node(s) had untolerated taint(s). no new claims to deallocate, preemption: 0/6 nodes are available: 1 No preemption victims found for incoming pod, 5 Preemption is not helpful for scheduling."
13.6704,Event,ADDED,eval-sanitize-1-r2-006-hjp5g.18d41fb3c5a7db80,reason=Scheduled count=None msg=Successfully assigned compute/eval-sanitize-1-r2-006-hjp5g to kind-worker5
13.6705,Event,ADDED,eval-sanitize-1-r2-007-fzlg7.18d41fb3c5cbf8a9,reason=Scheduled count=None msg=Successfully assigned compute/eval-sanitize-1-r2-007-fzlg7 to kind-worker5
13.6715,Pod,MODIFIED,eval-sanitize-1-r2-008-7hn5w,phase=Pending node=None
13.6729,Pod,MODIFIED,eval-sanitize-1-r2-005-2bx8m,phase=Pending node=kind-worker5
13.6776,Pod,MODIFIED,eval-sanitize-1-r2-007-fzlg7,phase=Pending node=kind-worker5
13.6797,Pod,MODIFIED,eval-sanitize-1-r2-009-4dhzg,phase=Pending node=kind-worker5
13.6822,Pod,MODIFIED,eval-sanitize-1-r2-010-wsghf,phase=Pending node=kind-worker5
13.6869,Pod,MODIFIED,eval-sanitize-1-r2-006-hjp5g,phase=Pending node=kind-worker5
13.6887,Event,ADDED,eval-sanitize-1-r2-009-4dhzg.18d41fb3c6c586e5,reason=Scheduled count=None msg=Successfully assigned compute/eval-sanitize-1-r2-009-4dhzg to kind-worker5
13.6889,Event,ADDED,eval-sanitize-1-r2-011-5sw64.18d41fb3c6e11c93,"reason=FailedScheduling count=None msg=0/6 nodes are available: 1 c_wall violated: 3 conflicting context pair(s) with node memory, 5 node(s) had untolerated taint(s). no new claims to deallocate, preemption: 0/6 nodes are available: 1 No preemption victims found for incoming pod, 5 Preemption is not helpful for scheduling."
13.6898,Pod,MODIFIED,eval-sanitize-1-r2-011-5sw64,phase=Pending node=None
13.691,Event,ADDED,eval-sanitize-1-r2-010-wsghf.18d41fb3c6f3b34c,reason=Scheduled count=None msg=Successfully assigned compute/eval-sanitize-1-r2-010-wsghf to kind-worker5
13.6926,Node,MODIFIED,kind-worker5,taints=0
13.6971,Pod,MODIFIED,eval-sanitize-1-r2-009-4dhzg,phase=Pending node=kind-worker5
13.7056,Pod,MODIFIED,eval-sanitize-1-r2-010-wsghf,phase=Pending node=kind-worker5
13.7383,Node,MODIFIED,kind-worker5,taints=0
13.751,Pod,MODIFIED,eval-sanitize-1-r2-012-jmcgx,phase=Pending node=None
13.7513,Event,ADDED,eval-sanitize-1-r2-012-jmcgx.18d41fb3cabe6c3e,"reason=FailedScheduling count=None msg=0/6 nodes are available: 1 c_wall violated: 1 conflicting context pair(s) with node memory, 5 node(s) had untolerated taint(s). no new claims to deallocate, preemption: 0/6 nodes are available: 1 No preemption victims found for incoming pod, 5 Preemption is not helpful for scheduling."
13.7789,Pod,MODIFIED,eval-sanitize-1-r2-003-9x5tt,phase=Running node=kind-worker4
13.7916,Pod,MODIFIED,eval-sanitize-1-r2-013-kl8tg,phase=Pending node=None
13.7919,Event,ADDED,eval-sanitize-1-r2-013-kl8tg.18d41fb3cd2c60c9,"reason=FailedScheduling count=None msg=0/6 nodes are available: 1 c_wall violated: 1 conflicting context pair(s) with node memory, 5 node(s) had untolerated taint(s). no new claims to deallocate, preemption: 0/6 nodes are available: 1 No preemption victims found for incoming pod, 5 Preemption is not helpful for scheduling."
13.7967,Node,MODIFIED,kind-worker5,taints=0
13.8009,Pod,MODIFIED,eval-sanitize-1-r2-008-7hn5w,phase=Pending node=None
13.8012,Event,ADDED,eval-sanitize-1-r2-008-7hn5w.18d41fb3cdb0a001,"reason=FailedScheduling count=None msg=0/6 nodes are available: 1 c_wall violated: 3 conflicting context pair(s) with node memory, 5 node(s) had untolerated taint(s). no new claims to deallocate, preemption: 0/6 nodes are available: 1 No preemption victims found for incoming pod, 5 Preemption is not helpful for scheduling."
13.8076,Event,ADDED,eval-sanitize-1-r2-011-5sw64.18d41fb3ce2f7ff9,"reason=FailedScheduling count=None msg=0/6 nodes are available: 1 c_wall violated: 3 conflicting context pair(s) with node memory, 5 node(s) had untolerated taint(s). no new claims to deallocate, preemption: 0/6 nodes are available: 1 No preemption victims found for incoming pod, 5 Preemption is not helpful for scheduling."
13.8116,Event,ADDED,eval-sanitize-1-r2-012-jmcgx.18d41fb3ce5e5362,"reason=FailedScheduling count=None msg=0/6 nodes are available: 1 c_wall violated: 1 conflicting context pair(s) with node memory, 5 node(s) had untolerated taint(s). no new claims to deallocate, preemption: 0/6 nodes are available: 1 No preemption victims found for incoming pod, 5 Preemption is not helpful for scheduling."
13.8137,Event,ADDED,eval-sanitize-1-r2-013-kl8tg.18d41fb3ce926220,"reason=FailedScheduling count=None msg=0/6 nodes are available: 1 c_wall violated: 1 conflicting context pair(s) with node memory, 5 node(s) had untolerated taint(s). no new claims to deallocate, preemption: 0/6 nodes are available: 1 No preemption victims found for incoming pod, 5 Preemption is not helpful for scheduling."
13.8164,Event,ADDED,eval-sanitize-1-r2-008-7hn5w.18d41fb3cec3cd7b,"reason=FailedScheduling count=None msg=0/6 nodes are available: 1 c_wall violated: 3 conflicting context pair(s) with node memory, 5 node(s) had untolerated taint(s). no new claims to deallocate, preemption: 0/6 nodes are available: 1 No preemption victims found for incoming pod, 5 Preemption is not helpful for scheduling."
13.8464,Node,MODIFIED,kind-worker3,taints=1
13.8483,Node,MODIFIED,kind-worker5,taints=0
13.8539,Event,MODIFIED,eval-sanitize-1-r2-011-5sw64.18d41fb3ce2f7ff9,"reason=FailedScheduling count=None msg=0/6 nodes are available: 1 c_wall violated: 3 conflicting context pair(s) with node memory, 5 node(s) had untolerated taint(s). no new claims to deallocate, preemption: 0/6 nodes are available: 1 No preemption victims found for incoming pod, 5 Preemption is not helpful for scheduling."
13.8969,Event,MODIFIED,eval-sanitize-1-r2-012-jmcgx.18d41fb3ce5e5362,"reason=FailedScheduling count=None msg=0/6 nodes are available: 1 c_wall violated: 1 conflicting context pair(s) with node memory, 5 node(s) had untolerated taint(s). no new claims to deallocate, preemption: 0/6 nodes are available: 1 No preemption victims found for incoming pod, 5 Preemption is not helpful for scheduling."
13.8999,Event,MODIFIED,eval-sanitize-1-r2-008-7hn5w.18d41fb3cec3cd7b,"reason=FailedScheduling count=None msg=0/6 nodes are available: 1 c_wall violated: 3 conflicting context pair(s) with node memory, 5 node(s) had untolerated taint(s). no new claims to deallocate, preemption: 0/6 nodes are available: 1 No preemption victims found for incoming pod, 5 Preemption is not helpful for scheduling."
13.9006,Event,MODIFIED,eval-sanitize-1-r2-013-kl8tg.18d41fb3ce926220,"reason=FailedScheduling count=None msg=0/6 nodes are available: 1 c_wall violated: 1 conflicting context pair(s) with node memory, 5 node(s) had untolerated taint(s). no new claims to deallocate, preemption: 0/6 nodes are available: 1 No preemption victims found for incoming pod, 5 Preemption is not helpful for scheduling."
13.9431,Node,MODIFIED,kind-worker3,taints=0
13.9515,Pod,MODIFIED,eval-sanitize-1-r2-012-jmcgx,phase=Pending node=kind-worker3
13.9551,Event,ADDED,eval-sanitize-1-r2-012-jmcgx.18d41fb3d6f95c56,reason=Scheduled count=None msg=Successfully assigned compute/eval-sanitize-1-r2-012-jmcgx to kind-worker3
13.958,Pod,MODIFIED,eval-sanitize-1-r2-013-kl8tg,phase=Pending node=None
13.9612,Node,MODIFIED,kind-worker3,taints=0
13.9633,Pod,MODIFIED,eval-sanitize-1-r2-012-jmcgx,phase=Pending node=kind-worker3
13.9701,Pod,MODIFIED,eval-sanitize-1-r2-008-7hn5w,phase=Pending node=None
13.9978,Job,MODIFIED,eval-sanitize-1-r2-001,
14.0066,Pod,MODIFIED,eval-sanitize-1-r2-001-65npq,phase=Succeeded node=kind-worker3
14.0085,Job,MODIFIED,eval-sanitize-1-r2-001,
14.013,TaskRequest,ADDED,eval-sanitize-1-r2-014,phase=None job=None
14.017,TaskRequest,MODIFIED,eval-sanitize-1-r2-014,phase=Pending job=None
14.0353,Node,MODIFIED,kind-worker5,taints=0
14.0368,Job,ADDED,eval-sanitize-1-r2-014,
14.0385,Node,MODIFIED,kind-worker3,taints=0
14.0456,Pod,ADDED,eval-sanitize-1-r2-014-k7rkd,phase=Pending node=None
14.0474,TaskRequest,MODIFIED,eval-sanitize-1-r2-014,phase=Scheduled job=None
14.0482,Job,MODIFIED,eval-sanitize-1-r2-013,
14.0487,Job,MODIFIED,eval-sanitize-1-r2-014,
14.0512,Node,MODIFIED,kind-worker3,taints=0
14.0524,Event,ADDED,eval-sanitize-1-r2-014.18d41fb3dc8e5f35,reason=SuccessfulCreate count=1 msg=Created pod: eval-sanitize-1-r2-014-k7rkd
14.0532,Pod,MODIFIED,eval-sanitize-1-r2-011-5sw64,phase=Pending node=None
14.0557,TaskRequest,MODIFIED,eval-sanitize-1-r2-014,phase=Scheduled job=None
14.0613,Job,MODIFIED,eval-sanitize-1-r2-013,
14.0737,Pod,MODIFIED,eval-sanitize-1-r2-014-k7rkd,phase=Pending node=kind-worker3
14.0804,Event,ADDED,eval-sanitize-1-r2-014-k7rkd.18d41fb3de2b57b0,reason=Scheduled count=None msg=Successfully assigned compute/eval-sanitize-1-r2-014-k7rkd to kind-worker3
14.081,Event,ADDED,eval-sanitize-1-r2-013-kl8tg.18d41fb3de5cf296,"reason=FailedScheduling count=None msg=0/6 nodes are available: 2 c_wall violated: 1 conflicting context pair(s) with node memory, 4 node(s) had untolerated taint(s). no new claims to deallocate, preemption: 0/6 nodes are available: 2 No preemption victims found for incoming pod, 4 Preemption is not helpful for scheduling."
14.0874,Node,MODIFIED,kind-worker3,taints=0
14.0891,Pod,MODIFIED,eval-sanitize-1-r2-014-k7rkd,phase=Pending node=kind-worker3
14.0984,Node,MODIFIED,kind-worker3,taints=0
14.1115,Event,ADDED,eval-sanitize-1-r2-005-2bx8m.18d41fb3e03cdc6e,"reason=Pulled count=1 msg=Container image ""busybox:musl"" already present on machine"
14.1343,Event,ADDED,eval-sanitize-1-r2-005-2bx8m.18d41fb3e19204e5,reason=Created count=1 msg=Created container: task
14.1391,Event,ADDED,eval-sanitize-1-r2-009-4dhzg.18d41fb3e1c628cc,"reason=Pulled count=1 msg=Container image ""busybox:musl"" already present on machine"
14.1457,Event,ADDED,eval-sanitize-1-r2-006-hjp5g.18d41fb3e1e0afa3,"reason=Pulled count=1 msg=Container image ""busybox:musl"" already present on machine"
14.1498,Event,ADDED,eval-sanitize-1-r2-007-fzlg7.18d41fb3e20de4bd,"reason=Pulled count=1 msg=Container image ""busybox:musl"" already present on machine"
14.1536,Pod,MODIFIED,eval-sanitize-1-r2-008-7hn5w,phase=Pending node=None
14.1541,Event,ADDED,eval-sanitize-1-r2-008-7hn5w.18d41fb3e2b4aae0,"reason=FailedScheduling count=None msg=0/6 nodes are available: 1 c_wall violated: 2 conflicting context pair(s) with node memory, 1 c_wall violated: 3 conflicting context pair(s) with node memory, 4 node(s) had untolerated taint(s). no new claims to deallocate, preemption: 0/6 nodes are available: 2 No preemption victims found for incoming pod, 4 Preemption is not helpful for scheduling."
14.1551,Event,ADDED,eval-sanitize-1-r2-010-wsghf.18d41fb3e22c09c0,"reason=Pulled count=1 msg=Container image ""busybox:musl"" already present on machine"
14.1672,Pod,MODIFIED,eval-sanitize-1-r2-011-5sw64,phase=Pending node=None
14.1688,Event,ADDED,eval-sanitize-1-r2-011-5sw64.18d41fb3e3682423,"reason=FailedScheduling count=None msg=0/6 nodes are available: 1 c_wall violated: 2 conflicting context pair(s) with node memory, 1 c_wall violated: 3 conflicting context pair(s) with node memory, 4 node(s) had untolerated taint(s). no new claims to deallocate, preemption: 0/6 nodes are available: 2 No preemption victims found for incoming pod, 4 Preemption is not helpful for scheduling."
14.17,Event,ADDED,eval-sanitize-1-r2-009-4dhzg.18d41fb3e3ab2d2f,reason=Created count=1 msg=Created container: task
14.1801,Event,MODIFIED,eval-sanitize-1-r2-013-kl8tg.18d41fb3de5cf296,"reason=FailedScheduling count=None msg=0/6 nodes are available: 2 c_wall violated: 1 conflicting context pair(s) with node memory, 4 node(s) had untolerated taint(s). no new claims to deallocate, preemption: 0/6 nodes are available: 2 No preemption victims found for incoming pod, 4 Preemption is not helpful for scheduling."
14.1852,Event,ADDED,eval-sanitize-1-r2-006-hjp5g.18d41fb3e4a2f712,reason=Created count=1 msg=Created container: task
14.1921,Event,ADDED,eval-sanitize-1-r2-007-fzlg7.18d41fb3e4c9170f,reason=Created count=1 msg=Created container: task
14.1963,Event,ADDED,eval-sanitize-1-r2-010-wsghf.18d41fb3e53e753d,reason=Created count=1 msg=Created container: task
14.2014,Event,ADDED,eval-sanitize-1-r2-005-2bx8m.18d41fb3e579a1cb,reason=Started count=1 msg=Started container task
14.2087,Event,ADDED,eval-sanitize-1-r2-009-4dhzg.18d41fb3e61795b4,reason=Started count=1 msg=Started container task
14.2276,Event,ADDED,eval-sanitize-1-r2-007-fzlg7.18d41fb3e734170e,reason=Started count=1 msg=Started container task
14.2328,Event,ADDED,eval-sanitize-1-r2-006-hjp5g.18d41fb3e7341721,reason=Started count=1 msg=Started container task
14.2367,Event,ADDED,eval-sanitize-1-r2-010-wsghf.18d41fb3e757cbf4,reason=Started count=1 msg=Started container task
14.2547,Event,ADDED,eval-sanitize-1-r2-008-7hn5w.18d41fb3e8db4316,"reason=FailedScheduling count=None msg=0/6 nodes are available: 1 c_wall violated: 2 conflicting context pair(s) with node memory, 1 c_wall violated: 3 conflicting context pair(s) with node memory, 4 node(s) had untolerated taint(s). no new claims to deallocate, preemption: 0/6 nodes are available: 2 No preemption victims found for incoming pod, 4 Preemption is not helpful for scheduling."
14.2588,Event,ADDED,eval-sanitize-1-r2-011-5sw64.18d41fb3e921c4f9,"reason=FailedScheduling count=None msg=0/6 nodes are available: 1 c_wall violated: 2 conflicting context pair(s) with node memory, 1 c_wall violated: 3 conflicting context pair(s) with node memory, 4 node(s) had untolerated taint(s). no new claims to deallocate, preemption: 0/6 nodes are available: 2 No preemption victims found for incoming pod, 4 Preemption is not helpful for scheduling."
14.376,Event,ADDED,eval-sanitize-1-r2-012-jmcgx.18d41fb3eff433e1,"reason=Pulled count=1 msg=Container image ""busybox:musl"" already present on machine"
14.3948,Event,ADDED,eval-sanitize-1-r2-012-jmcgx.18d41fb3f1286ed5,reason=Created count=1 msg=Created container: task
14.4277,Event,ADDED,eval-sanitize-1-r2-012-jmcgx.18d41fb3f31cd0b7,reason=Started count=1 msg=Started container task
14.4649,Event,ADDED,eval-sanitize-1-r2-014-k7rkd.18d41fb3f554955f,"reason=Pulled count=1 msg=Container image ""busybox:musl"" already present on machine"
14.4835,Event,ADDED,eval-sanitize-1-r2-014-k7rkd.18d41fb3f6680ca9,reason=Created count=1 msg=Created container: task
14.5131,Pod,MODIFIED,eval-sanitize-1-r2-009-4dhzg,phase=Running node=kind-worker5
14.5187,Pod,MODIFIED,eval-sanitize-1-r2-007-fzlg7,phase=Running node=kind-worker5
14.5255,Pod,MODIFIED,eval-sanitize-1-r2-010-wsghf,phase=Running node=kind-worker5
14.5293,Job,MODIFIED,eval-sanitize-1-r2-000,
14.5341,Job,MODIFIED,eval-sanitize-1-r2-000,
14.5358,Event,MODIFIED,eval-sanitize-1-r2-008-7hn5w.18d41fb3e8db4316,"reason=FailedScheduling count=None msg=0/6 nodes are available: 1 c_wall violated: 2 conflicting context pair(s) with node memory, 1 c_wall violated: 3 conflicting context pair(s) with node memory, 4 node(s) had untolerated taint(s). no new claims to deallocate, preemption: 0/6 nodes are available: 2 No preemption victims found for incoming pod, 4 Preemption is not helpful for scheduling."
14.5372,Pod,MODIFIED,eval-sanitize-1-r2-006-hjp5g,phase=Running node=kind-worker5
14.5376,Event,MODIFIED,eval-sanitize-1-r2-011-5sw64.18d41fb3e921c4f9,"reason=FailedScheduling count=None msg=0/6 nodes are available: 1 c_wall violated: 2 conflicting context pair(s) with node memory, 1 c_wall violated: 3 conflicting context pair(s) with node memory, 4 node(s) had untolerated taint(s). no new claims to deallocate, preemption: 0/6 nodes are available: 2 No preemption victims found for incoming pod, 4 Preemption is not helpful for scheduling."
14.5388,Event,ADDED,eval-sanitize-1-r2-000.18d41fb3f9b176cc,reason=Completed count=1 msg=Job completed
14.5459,Pod,MODIFIED,eval-sanitize-1-r2-005-2bx8m,phase=Running node=kind-worker5
14.5472,Job,MODIFIED,eval-sanitize-1-r2-000,
14.5521,TaskRequest,MODIFIED,eval-sanitize-1-r2-000,phase=Complete job=None
14.562,Job,MODIFIED,eval-sanitize-1-r2-000,
14.5917,Job,MODIFIED,eval-sanitize-1-r2-002,
14.6001,Job,MODIFIED,eval-sanitize-1-r2-002,
14.651,Event,ADDED,eval-sanitize-1-r2-014-k7rkd.18d41fb40067b8b6,reason=Started count=1 msg=Started container task
14.6615,Job,MODIFIED,eval-sanitize-1-r2-005,
14.6668,Job,MODIFIED,eval-sanitize-1-r2-006,
14.6683,Job,MODIFIED,eval-sanitize-1-r2-007,
14.6717,Job,MODIFIED,eval-sanitize-1-r2-005,
14.6758,Job,MODIFIED,eval-sanitize-1-r2-006,
14.6786,Job,MODIFIED,eval-sanitize-1-r2-007,
14.6837,Job,MODIFIED,eval-sanitize-1-r2-009,
14.6868,Job,MODIFIED,eval-sanitize-1-r2-010,
14.6925,Job,MODIFIED,eval-sanitize-1-r2-009,
14.6947,Job,MODIFIED,eval-sanitize-1-r2-010,
14.7302,Pod,MODIFIED,eval-sanitize-1-r2-002-8p5db,phase=Succeeded node=kind-worker
14.7539,Node,MODIFIED,kind-worker5,taints=1
14.7859,Job,MODIFIED,eval-sanitize-1-r2-003,
14.7966,Job,MODIFIED,eval-sanitize-1-r2-003,
14.8261,Pod,MODIFIED,eval-sanitize-1-r2-008-7hn5w,phase=Pending node=None
14.8339,Pod,MODIFIED,eval-sanitize-1-r2-011-5sw64,phase=Pending node=None
14.8396,Node,MODIFIED,kind-worker5,taints=1
14.8415,Pod,MODIFIED,eval-sanitize-1-r2-013-kl8tg,phase=Pending node=None
14.8486,Event,ADDED,eval-sanitize-1-r2-008-7hn5w.18d41fb40c382ef2,"reason=FailedScheduling count=None msg=0/6 nodes are available: 1 c_wall violated: 2 conflicting context pair(s) with node memory, 5 node(s) had untolerated taint(s). no new claims to deallocate, preemption: 0/6 nodes are available: 1 No preemption victims found for incoming pod, 5 Preemption is not helpful for scheduling."
14.8514,Event,ADDED,eval-sanitize-1-r2-011-5sw64.18d41fb40c61e87b,"reason=FailedScheduling count=None msg=0/6 nodes are available: 1 c_wall violated: 2 conflicting context pair(s) with node memory, 5 node(s) had untolerated taint(s). no new claims to deallocate, preemption: 0/6 nodes are available: 1 No preemption victims found for incoming pod, 5 Preemption is not helpful for scheduling."
14.8539,Event,ADDED,eval-sanitize-1-r2-013-kl8tg.18d41fb40c992774,"reason=FailedScheduling count=None msg=0/6 nodes are available: 1 c_wall violated: 1 conflicting context pair(s) with node memory, 5 node(s) had untolerated taint(s). no new claims to deallocate, preemption: 0/6 nodes are available: 1 No preemption victims found for incoming pod, 5 Preemption is not helpful for scheduling."
14.9678,Pod,MODIFIED,eval-sanitize-1-r2-003-9x5tt,phase=Succeeded node=kind-worker4
14.9763,Event,MODIFIED,eval-sanitize-1-r2-008-7hn5w.18d41fb40c382ef2,"reason=FailedScheduling count=None msg=0/6 nodes are available: 1 c_wall violated: 2 conflicting context pair(s) with node memory, 5 node(s) had untolerated taint(s). no new claims to deallocate, preemption: 0/6 nodes are available: 1 No preemption victims found for incoming pod, 5 Preemption is not helpful for scheduling."
14.9782,Event,MODIFIED,eval-sanitize-1-r2-011-5sw64.18d41fb40c61e87b,"reason=FailedScheduling count=None msg=0/6 nodes are available: 1 c_wall violated: 2 conflicting context pair(s) with node memory, 5 node(s) had untolerated taint(s). no new claims to deallocate, preemption: 0/6 nodes are available: 1 No preemption victims found for incoming pod, 5 Preemption is not helpful for scheduling."
14.9821,Event,MODIFIED,eval-sanitize-1-r2-013-kl8tg.18d41fb40c992774,"reason=FailedScheduling count=None msg=0/6 nodes are available: 1 c_wall violated: 1 conflicting context pair(s) with node memory, 5 node(s) had untolerated taint(s). no new claims to deallocate, preemption: 0/6 nodes are available: 1 No preemption victims found for incoming pod, 5 Preemption is not helpful for scheduling."
14.9883,Pod,MODIFIED,eval-sanitize-1-r2-014-k7rkd,phase=Running node=kind-worker3
14.995,Pod,MODIFIED,eval-sanitize-1-r2-012-jmcgx,phase=Running node=kind-worker3
15.0023,Job,MODIFIED,eval-sanitize-1-r2-001,
15.0068,Job,MODIFIED,eval-sanitize-1-r2-001,
15.0126,Event,ADDED,eval-sanitize-1-r2-001.18d41fb415e4044f,reason=Completed count=1 msg=Job completed
15.0182,Job,MODIFIED,eval-sanitize-1-r2-001,
15.0236,TaskRequest,MODIFIED,eval-sanitize-1-r2-001,phase=Complete job=None
15.0334,Job,MODIFIED,eval-sanitize-1-r2-001,
15.0462,Node,MODIFIED,kind-worker3,taints=1
15.0505,Job,MODIFIED,eval-sanitize-1-r2-014,
15.0528,Pod,MODIFIED,eval-sanitize-1-r2-008-7hn5w,phase=Pending node=None
15.0532,TaskRequest,ADDED,eval-sanitize-1-r2-015,phase=None job=None
15.0567,TaskRequest,MODIFIED,eval-sanitize-1-r2-015,phase=Pending job=None
15.0594,Job,MODIFIED,eval-sanitize-1-r2-014,
15.0603,Pod,MODIFIED,eval-sanitize-1-r2-011-5sw64,phase=Pending node=None
15.0644,Pod,MODIFIED,eval-sanitize-1-r2-013-kl8tg,phase=Pending node=None
15.0723,Job,ADDED,eval-sanitize-1-r2-015,
15.0765,TaskRequest,MODIFIED,eval-sanitize-1-r2-015,phase=Scheduled job=None
15.0795,Pod,ADDED,eval-sanitize-1-r2-015-tqkls,phase=Pending node=None
15.0832,Job,MODIFIED,eval-sanitize-1-r2-015,
15.085,Event,ADDED,eval-sanitize-1-r2-015.18d41fb41a3a7b95,reason=SuccessfulCreate count=1 msg=Created pod: eval-sanitize-1-r2-015-tqkls
15.0853,Event,ADDED,eval-sanitize-1-r2-015-tqkls.18d41fb41a3e9b05,"reason=FailedScheduling count=None msg=0/6 nodes are available: 6 node(s) had untolerated taint(s). no new claims to deallocate, preemption: 0/6 nodes are available: 6 Preemption is not helpful for scheduling."
15.0854,TaskRequest,MODIFIED,eval-sanitize-1-r2-015,phase=Scheduled job=None
15.0863,Pod,MODIFIED,eval-sanitize-1-r2-015-tqkls,phase=Pending node=None
15.1349,Node,MODIFIED,kind-worker4,taints=1
15.1372,Node,MODIFIED,kind-worker3,taints=1
15.1396,Pod,MODIFIED,eval-sanitize-1-r2-004-bhlgt,phase=Running node=kind-worker2
15.2314,Node,MODIFIED,kind-worker4,taints=0
15.237,Pod,MODIFIED,eval-sanitize-1-r2-008-7hn5w,phase=Pending node=kind-worker4
15.24,Pod,MODIFIED,eval-sanitize-1-r2-011-5sw64,phase=Pending node=kind-worker4
15.2423,Event,ADDED,eval-sanitize-1-r2-008-7hn5w.18d41fb42397f18c,reason=Scheduled count=None msg=Successfully assigned compute/eval-sanitize-1-r2-008-7hn5w to kind-worker4
15.2449,Event,ADDED,eval-sanitize-1-r2-013-kl8tg.18d41fb423ae7e45,"reason=FailedScheduling count=None msg=0/6 nodes are available: 1 c_wall violated: 1 conflicting context pair(s) with node memory, 5 node(s) had untolerated taint(s). no new claims to deallocate, preemption: 0/6 nodes are available: 1 No preemption victims found for incoming pod, 5 Preemption is not helpful for scheduling."
15.2459,Pod,MODIFIED,eval-sanitize-1-r2-013-kl8tg,phase=Pending node=None
15.2502,Event,ADDED,eval-sanitize-1-r2-011-5sw64.18d41fb423c7e51f,reason=Scheduled count=None msg=Successfully assigned compute/eval-sanitize-1-r2-011-5sw64 to kind-worker4
15.252,Node,MODIFIED,kind-worker4,taints=0
15.2534,Pod,MODIFIED,eval-sanitize-1-r2-008-7hn5w,phase=Pending node=kind-worker4
15.2546,Pod,MODIFIED,eval-sanitize-1-r2-015-tqkls,phase=Pending node=None
15.2549,Event,ADDED,eval-sanitize-1-r2-015-tqkls.18d41fb4245cd06e,"reason=FailedScheduling count=None msg=0/6 nodes are available: 1 c_wall violated: 2 conflicting context pair(s) with node memory, 5 node(s) had untolerated taint(s). no new claims to deallocate, preemption: 0/6 nodes are available: 1 No preemption victims found for incoming pod, 5 Preemption is not helpful for scheduling."
15.2596,Pod,MODIFIED,eval-sanitize-1-r2-011-5sw64,phase=Pending node=kind-worker4
15.2627,Event,ADDED,eval-sanitize-1-r2-013-kl8tg.18d41fb424dbe7b1,"reason=FailedScheduling count=None msg=0/6 nodes are available: 1 c_wall violated: 1 conflicting context pair(s) with node memory, 5 node(s) had untolerated taint(s). no new claims to deallocate, preemption: 0/6 nodes are available: 1 No preemption victims found for incoming pod, 5 Preemption is not helpful for scheduling."
15.266,Event,ADDED,eval-sanitize-1-r2-015-tqkls.18d41fb425204773,"reason=FailedScheduling count=None msg=0/6 nodes are available: 1 c_wall violated: 2 conflicting context pair(s) with node memory, 5 node(s) had untolerated taint(s). no new claims to deallocate, preemption: 0/6 nodes are available: 1 No preemption victims found for incoming pod, 5 Preemption is not helpful for scheduling."
15.2687,Event,MODIFIED,eval-sanitize-1-r2-013-kl8tg.18d41fb424dbe7b1,"reason=FailedScheduling count=None msg=0/6 nodes are available: 1 c_wall violated: 1 conflicting context pair(s) with node memory, 5 node(s) had untolerated taint(s). no new claims to deallocate, preemption: 0/6 nodes are available: 1 No preemption victims found for incoming pod, 5 Preemption is not helpful for scheduling."
15.2739,Node,MODIFIED,kind-worker4,taints=0
15.3198,Event,MODIFIED,eval-sanitize-1-r2-015-tqkls.18d41fb425204773,"reason=FailedScheduling count=None msg=0/6 nodes are available: 1 c_wall violated: 2 conflicting context pair(s) with node memory, 5 node(s) had untolerated taint(s). no new claims to deallocate, preemption: 0/6 nodes are available: 1 No preemption victims found for incoming pod, 5 Preemption is not helpful for scheduling."
15.3312,Node,MODIFIED,kind-worker4,taints=0
15.3412,Node,MODIFIED,kind-worker4,taints=0
15.3501,Node,MODIFIED,kind-worker4,taints=0
15.3605,Node,MODIFIED,kind-worker4,taints=0
15.4916,Node,MODIFIED,kind-worker,taints=1
15.5346,Node,MODIFIED,kind-worker,taints=1
15.5433,Node,MODIFIED,kind-worker,taints=0
15.5514,Pod,MODIFIED,eval-sanitize-1-r2-013-kl8tg,phase=Pending node=kind-worker
15.5617,Event,ADDED,eval-sanitize-1-r2-013-kl8tg.18d41fb436526afb,reason=Scheduled count=None msg=Successfully assigned compute/eval-sanitize-1-r2-013-kl8tg to kind-worker
15.5631,Node,MODIFIED,kind-worker,taints=0
15.564,Pod,MODIFIED,eval-sanitize-1-r2-015-tqkls,phase=Pending node=kind-worker
15.57,Pod,MODIFIED,eval-sanitize-1-r2-013-kl8tg,phase=Pending node=kind-worker
15.5704,Event,ADDED,eval-sanitize-1-r2-015-tqkls.18d41fb436f9486e,reason=Scheduled count=None msg=Successfully assigned compute/eval-sanitize-1-r2-015-tqkls to kind-worker
15.5734,Node,MODIFIED,kind-worker,taints=0
15.579,Pod,MODIFIED,eval-sanitize-1-r2-015-tqkls,phase=Pending node=kind-worker
15.5864,Node,MODIFIED,kind-worker,taints=0
15.5976,Job,MODIFIED,eval-sanitize-1-r2-002,
15.6066,Pod,MODIFIED,eval-sanitize-1-r2-002-8p5db,phase=Succeeded node=kind-worker
15.6081,Job,MODIFIED,eval-sanitize-1-r2-002,
15.6567,Node,MODIFIED,kind-worker,taints=0
15.6676,Node,MODIFIED,kind-worker,taints=0
15.7012,Event,ADDED,eval-sanitize-1-r2-008-7hn5w.18d41fb43ef890af,"reason=Pulled count=1 msg=Container image ""busybox:musl"" already present on machine"
15.7052,Event,ADDED,eval-sanitize-1-r2-011-5sw64.18d41fb43f197b16,"reason=Pulled count=1 msg=Container image ""busybox:musl"" already present on machine"
15.7236,Event,ADDED,eval-sanitize-1-r2-008-7hn5w.18d41fb4404de4bf,reason=Created count=1 msg=Created container: task
15.7294,Event,ADDED,eval-sanitize-1-r2-011-5sw64.18d41fb440bc848f,reason=Created count=1 msg=Created container: task
15.7935,Job,MODIFIED,eval-sanitize-1-r2-003,
15.7956,Event,ADDED,eval-sanitize-1-r2-008-7hn5w.18d41fb444a24f89,reason=Started count=1 msg=Started container task
15.8004,Event,ADDED,eval-sanitize-1-r2-011-5sw64.18d41fb444e94adb,reason=Started count=1 msg=Started container task
15.8034,Job,MODIFIED,eval-sanitize-1-r2-003,
15.8049,Pod,MODIFIED,eval-sanitize-1-r2-003-9x5tt,phase=Succeeded node=kind-worker4
15.9852,Event,ADDED,eval-sanitize-1-r2-013-kl8tg.18d41fb44fe6caf0,"reason=Pulled count=1 msg=Container image ""busybox:musl"" already present on machine"
15.9903,Event,ADDED,eval-sanitize-1-r2-015-tqkls.18d41fb4504964cb,"reason=Pulled count=1 msg=Container image ""busybox:musl"" already present on machine"
16.0,Job,MODIFIED,eval-sanitize-1-r2-012,
16.0103,Job,MODIFIED,eval-sanitize-1-r2-012,
16.0106,Event,ADDED,eval-sanitize-1-r2-013-kl8tg.18d41fb45169be5d,reason=Created count=1 msg=Created container: task
16.0167,Event,ADDED,eval-sanitize-1-r2-015-tqkls.18d41fb451d607cf,reason=Created count=1 msg=Created container: task
16.0237,TaskRequest,ADDED,eval-sanitize-1-r2-016,phase=None job=None
16.0284,TaskRequest,MODIFIED,eval-sanitize-1-r2-016,phase=Pending job=None
16.0496,Job,ADDED,eval-sanitize-1-r2-016,
16.0528,Event,ADDED,eval-sanitize-1-r2-013-kl8tg.18d41fb453e8b3c8,reason=Started count=1 msg=Started container task
16.0578,Pod,ADDED,eval-sanitize-1-r2-016-smvtd,phase=Pending node=None
16.0579,TaskRequest,MODIFIED,eval-sanitize-1-r2-016,phase=Scheduled job=None
16.0583,Event,ADDED,eval-sanitize-1-r2-015-tqkls.18d41fb4543d637e,reason=Started count=1 msg=Started container task
16.0612,Job,MODIFIED,eval-sanitize-1-r2-016,
16.0639,Event,ADDED,eval-sanitize-1-r2-016.18d41fb45474a416,reason=SuccessfulCreate count=1 msg=Created pod: eval-sanitize-1-r2-016-smvtd
16.0663,TaskRequest,MODIFIED,eval-sanitize-1-r2-016,phase=Scheduled job=None
16.0708,Pod,MODIFIED,eval-sanitize-1-r2-016-smvtd,phase=Pending node=None
16.0713,Event,ADDED,eval-sanitize-1-r2-016-smvtd.18d41fb454f62bce,"reason=FailedScheduling count=None msg=0/6 nodes are available: 2 c_wall violated: 2 conflicting context pair(s) with node memory, 4 node(s) had untolerated taint(s). no new claims to deallocate, preemption: 0/6 nodes are available: 2 No preemption victims found for incoming pod, 4 Preemption is not helpful for scheduling."
16.0858,Job,MODIFIED,eval-sanitize-1-r2-015,
16.107,Job,MODIFIED,eval-sanitize-1-r2-015,
16.118,Event,ADDED,eval-sanitize-1-r2-016-smvtd.18d41fb457eaaf6b,"reason=FailedScheduling count=None msg=0/6 nodes are available: 2 c_wall violated: 2 conflicting context pair(s) with node memory, 4 node(s) had untolerated taint(s). no new claims to deallocate, preemption: 0/6 nodes are available: 2 No preemption victims found for incoming pod, 4 Preemption is not helpful for scheduling."
16.1465,Job,MODIFIED,eval-sanitize-1-r2-004,
16.1573,Job,MODIFIED,eval-sanitize-1-r2-004,
16.2339,Pod,MODIFIED,eval-sanitize-1-r2-004-bhlgt,phase=Succeeded node=kind-worker2
16.2443,Event,MODIFIED,eval-sanitize-1-r2-016-smvtd.18d41fb457eaaf6b,"reason=FailedScheduling count=None msg=0/6 nodes are available: 2 c_wall violated: 2 conflicting context pair(s) with node memory, 4 node(s) had untolerated taint(s). no new claims to deallocate, preemption: 0/6 nodes are available: 2 No preemption victims found for incoming pod, 4 Preemption is not helpful for scheduling."
16.2575,Node,MODIFIED,kind-worker4,taints=1
16.2657,Pod,MODIFIED,eval-sanitize-1-r2-016-smvtd,phase=Pending node=None
16.2731,Event,ADDED,eval-sanitize-1-r2-016-smvtd.18d41fb4611feb9c,"reason=FailedScheduling count=None msg=0/6 nodes are available: 1 c_wall violated: 2 conflicting context pair(s) with node memory, 5 node(s) had untolerated taint(s). no new claims to deallocate, preemption: 0/6 nodes are available: 1 No preemption victims found for incoming pod, 5 Preemption is not helpful for scheduling."
16.3418,Node,MODIFIED,kind-worker4,taints=1
16.3502,Event,MODIFIED,eval-sanitize-1-r2-016-smvtd.18d41fb4611feb9c,"reason=FailedScheduling count=None msg=0/6 nodes are available: 1 c_wall violated: 2 conflicting context pair(s) with node memory, 5 node(s) had untolerated taint(s). no new claims to deallocate, preemption: 0/6 nodes are available: 1 No preemption victims found for incoming pod, 5 Preemption is not helpful for scheduling."
16.5634,Node,MODIFIED,kind-worker,taints=1
16.5682,Pod,MODIFIED,eval-sanitize-1-r2-016-smvtd,phase=Pending node=None
16.5758,Node,MODIFIED,kind-worker,taints=1
16.5886,Pod,MODIFIED,eval-sanitize-1-r2-013-kl8tg,phase=Running node=kind-worker
16.5946,Pod,MODIFIED,eval-sanitize-1-r2-015-tqkls,phase=Running node=kind-worker
16.6026,Job,MODIFIED,eval-sanitize-1-r2-002,
16.6068,Job,MODIFIED,eval-sanitize-1-r2-002,
16.6118,Event,ADDED,eval-sanitize-1-r2-002.18d41fb4753d9f68,reason=Completed count=1 msg=Job completed
16.6175,Job,MODIFIED,eval-sanitize-1-r2-002,
16.6217,TaskRequest,MODIFIED,eval-sanitize-1-r2-002,phase=Complete job=None
16.6308,Job,MODIFIED,eval-sanitize-1-r2-002,
16.7882,Pod,MODIFIED,eval-sanitize-1-r2-008-7hn5w,phase=Running node=kind-worker4
16.7953,Pod,MODIFIED,eval-sanitize-1-r2-011-5sw64,phase=Running node=kind-worker4
16.7974,Job,MODIFIED,eval-sanitize-1-r2-003,
16.8015,Job,MODIFIED,eval-sanitize-1-r2-003,
16.8041,Event,ADDED,eval-sanitize-1-r2-003.18d41fb480dc8b33,reason=Completed count=1 msg=Job completed
16.8123,Job,MODIFIED,eval-sanitize-1-r2-003,
16.8169,TaskRequest,MODIFIED,eval-sanitize-1-r2-003,phase=Complete job=None
16.825,Job,MODIFIED,eval-sanitize-1-r2-003,
16.9467,Node,MODIFIED,kind-worker2,taints=1
17.0108,TaskRequest,ADDED,eval-sanitize-1-r2-017,phase=None job=None
17.0157,TaskRequest,MODIFIED,eval-sanitize-1-r2-017,phase=Pending job=None
17.03,Job,ADDED,eval-sanitize-1-r2-017,
17.0329,Node,MODIFIED,kind-worker2,taints=0
17.0365,Pod,ADDED,eval-sanitize-1-r2-017-w6mk9,phase=Pending node=None
17.0457,TaskRequest,MODIFIED,eval-sanitize-1-r2-017,phase=Scheduled job=None
17.0471,Pod,MODIFIED,eval-sanitize-1-r2-016-smvtd,phase=Pending node=kind-worker2
17.0489,Event,ADDED,eval-sanitize-1-r2-017.18d41fb48edcc231,reason=SuccessfulCreate count=1 msg=Created pod: eval-sanitize-1-r2-017-w6mk9
17.0494,Event,ADDED,eval-sanitize-1-r2-017-w6mk9.18d41fb48f168e7e,"reason=FailedScheduling count=None msg=0/6 nodes are available: 1 c_wall violated: 1 conflicting context pair(s) with node memory, 5 node(s) had untolerated taint(s). no new claims to deallocate, preemption: 0/6 nodes are available: 1 No preemption victims found for incoming pod, 5 Preemption is not helpful for scheduling."
17.0502,Pod,MODIFIED,eval-sanitize-1-r2-017-w6mk9,phase=Pending node=None
17.051,Job,MODIFIED,eval-sanitize-1-r2-017,
17.0513,Event,ADDED,eval-sanitize-1-r2-016-smvtd.18d41fb48f6f7966,reason=Scheduled count=None msg=Successfully assigned compute/eval-sanitize-1-r2-016-smvtd to kind-worker2
17.0525,Node,MODIFIED,kind-worker2,taints=0
17.0552,TaskRequest,MODIFIED,eval-sanitize-1-r2-017,phase=Scheduled job=None
17.0591,Pod,MODIFIED,eval-sanitize-1-r2-016-smvtd,phase=Pending node=kind-worker2
17.0595,Event,ADDED,eval-sanitize-1-r2-017-w6mk9.18d41fb48fdfb5e7,"reason=FailedScheduling count=None msg=0/6 nodes are available: 1 c_wall violated: 1 conflicting context pair(s) with node memory, 5 node(s) had untolerated taint(s). no new claims to deallocate, preemption: 0/6 nodes are available: 1 No preemption victims found for incoming pod, 5 Preemption is not helpful for scheduling."
17.0611,Node,MODIFIED,kind-worker2,taints=0
17.062,Job,MODIFIED,eval-sanitize-1-r2-016,
17.0676,Event,MODIFIED,eval-sanitize-1-r2-017-w6mk9.18d41fb48fdfb5e7,"reason=FailedScheduling count=None msg=0/6 nodes are available: 1 c_wall violated: 1 conflicting context pair(s) with node memory, 5 node(s) had untolerated taint(s). no new claims to deallocate, preemption: 0/6 nodes are available: 1 No preemption victims found for incoming pod, 5 Preemption is not helpful for scheduling."
17.0705,Job,MODIFIED,eval-sanitize-1-r2-016,
17.0905,Job,MODIFIED,eval-sanitize-1-r2-015,
17.0989,Job,MODIFIED,eval-sanitize-1-r2-015,
17.1114,Node,MODIFIED,kind-worker2,taints=0
17.1603,Node,MODIFIED,kind-worker2,taints=0
17.1612,Job,MODIFIED,eval-sanitize-1-r2-004,
17.1711,Pod,MODIFIED,eval-sanitize-1-r2-004-bhlgt,phase=Succeeded node=kind-worker2
17.1724,Job,MODIFIED,eval-sanitize-1-r2-004,
17.4998,Event,ADDED,eval-sanitize-1-r2-016-smvtd.18d41fb4aa2537b4,"reason=Pulled count=1 msg=Container image ""busybox:musl"" already present on machine"
17.515,Event,ADDED,eval-sanitize-1-r2-016-smvtd.18d41fb4ab3098a6,reason=Created count=1 msg=Created container: task
17.5791,Event,ADDED,eval-sanitize-1-r2-016-smvtd.18d41fb4aef58b59,reason=Started count=1 msg=Started container task
17.5937,Job,MODIFIED,eval-sanitize-1-r2-013,
17.6025,Job,MODIFIED,eval-sanitize-1-r2-013,
17.7995,Job,MODIFIED,eval-sanitize-1-r2-008,
17.8011,Job,MODIFIED,eval-sanitize-1-r2-011,
17.8093,Job,MODIFIED,eval-sanitize-1-r2-008,
17.8108,Job,MODIFIED,eval-sanitize-1-r2-011,
18.0141,TaskRequest,ADDED,eval-sanitize-1-r2-018,phase=None job=None
18.0177,TaskRequest,MODIFIED,eval-sanitize-1-r2-018,phase=Pending job=None
18.0335,Job,ADDED,eval-sanitize-1-r2-018,
18.04,Pod,ADDED,eval-sanitize-1-r2-018-4p7vs,phase=Pending node=None
18.0415,TaskRequest,MODIFIED,eval-sanitize-1-r2-018,phase=Scheduled job=None
18.0422,Job,MODIFIED,eval-sanitize-1-r2-017,
18.0444,Job,MODIFIED,eval-sanitize-1-r2-018,
18.0493,Event,ADDED,eval-sanitize-1-r2-018.18d41fb4caac7dd3,reason=SuccessfulCreate count=1 msg=Created pod: eval-sanitize-1-r2-018-4p7vs
18.0505,Pod,MODIFIED,eval-sanitize-1-r2-018-4p7vs,phase=Pending node=kind-worker2
18.0532,Job,MODIFIED,eval-sanitize-1-r2-017,
18.0538,Event,ADDED,eval-sanitize-1-r2-018-4p7vs.18d41fb4cb44b178,reason=Scheduled count=None msg=Successfully assigned compute/eval-sanitize-1-r2-018-4p7vs to kind-worker2
18.0613,Node,MODIFIED,kind-worker2,taints=1
18.0627,TaskRequest,MODIFIED,eval-sanitize-1-r2-018,phase=Scheduled job=None
18.0643,Pod,MODIFIED,eval-sanitize-1-r2-018-4p7vs,phase=Pending node=kind-worker2
18.0654,Pod,MODIFIED,eval-sanitize-1-r2-017-w6mk9,phase=Pending node=None
18.0683,Pod,MODIFIED,eval-sanitize-1-r2-017-w6mk9,phase=Pending node=None
18.0743,Node,MODIFIED,kind-worker2,taints=1
18.0865,Node,MODIFIED,kind-worker2,taints=1
18.1611,Node,MODIFIED,kind-worker2,taints=1
18.1666,Pod,MODIFIED,eval-sanitize-1-r2-016-smvtd,phase=Running node=kind-worker2
18.1677,Job,MODIFIED,eval-sanitize-1-r2-004,
18.1725,Job,MODIFIED,eval-sanitize-1-r2-004,
18.1775,Event,ADDED,eval-sanitize-1-r2-004.18d41fb4d2962d0a,reason=Completed count=1 msg=Job completed
18.1836,Job,MODIFIED,eval-sanitize-1-r2-004,
18.1877,TaskRequest,MODIFIED,eval-sanitize-1-r2-004,phase=Complete job=None
18.1966,Job,MODIFIED,eval-sanitize-1-r2-004,
18.4934,Event,ADDED,eval-sanitize-1-r2-018-4p7vs.18d41fb4e5799038,"reason=Pulled count=1 msg=Container image ""busybox:musl"" already present on machine"
18.5117,Event,ADDED,eval-sanitize-1-r2-018-4p7vs.18d41fb4e692bada,reason=Created count=1 msg=Created container: task
18.5458,Event,ADDED,eval-sanitize-1-r2-018-4p7vs.18d41fb4e89a1436,reason=Started count=1 msg=Started container task
19.019,TaskRequest,ADDED,eval-sanitize-1-r2-019,phase=None job=None
19.0242,TaskRequest,MODIFIED,eval-sanitize-1-r2-019,phase=Pending job=None
19.0383,Job,ADDED,eval-sanitize-1-r2-019,
19.0446,Pod,ADDED,eval-sanitize-1-r2-019-7bqxs,phase=Pending node=None
19.0479,Job,MODIFIED,eval-sanitize-1-r2-018,
19.048,TaskRequest,MODIFIED,eval-sanitize-1-r2-019,phase=Scheduled job=None
19.0489,Job,MODIFIED,eval-sanitize-1-r2-019,
19.0517,Event,ADDED,eval-sanitize-1-r2-019-7bqxs.18d41fb50699c77e,"reason=FailedScheduling count=None msg=0/6 nodes are available: 6 node(s) had untolerated taint(s). no new claims to deallocate, preemption: 0/6 nodes are available: 6 Preemption is not helpful for scheduling."
19.0519,Event,ADDED,eval-sanitize-1-r2-019.18d41fb5068f1f58,reason=SuccessfulCreate count=1 msg=Created pod: eval-sanitize-1-r2-019-7bqxs
19.0528,Pod,MODIFIED,eval-sanitize-1-r2-019-7bqxs,phase=Pending node=None
19.0571,TaskRequest,MODIFIED,eval-sanitize-1-r2-019,phase=Scheduled job=None
19.0594,Job,MODIFIED,eval-sanitize-1-r2-018,
19.1581,Pod,MODIFIED,eval-sanitize-1-r2-018-4p7vs,phase=Running node=kind-worker2
19.1712,Job,MODIFIED,eval-sanitize-1-r2-016,
19.1796,Job,MODIFIED,eval-sanitize-1-r2-016,
20.0079,TaskRequest,ADDED,eval-sanitize-1-r2-020,phase=None job=None
20.0124,TaskRequest,MODIFIED,eval-sanitize-1-r2-020,phase=Pending job=None
20.0274,Job,ADDED,eval-sanitize-1-r2-020,
20.0315,TaskRequest,MODIFIED,eval-sanitize-1-r2-020,phase=Scheduled job=None
20.0343,Pod,ADDED,eval-sanitize-1-r2-020-vzhm2,phase=Pending node=None
20.0362,Job,MODIFIED,eval-sanitize-1-r2-020,
20.0407,Event,ADDED,eval-sanitize-1-r2-020.18d41fb5418c9c1e,reason=SuccessfulCreate count=1 msg=Created pod: eval-sanitize-1-r2-020-vzhm2
20.041,Event,ADDED,eval-sanitize-1-r2-020-vzhm2.18d41fb5419a706d,"reason=FailedScheduling count=None msg=0/6 nodes are available: 6 node(s) had untolerated taint(s). no new claims to deallocate, preemption: 0/6 nodes are available: 6 Preemption is not helpful for scheduling."
20.0411,TaskRequest,MODIFIED,eval-sanitize-1-r2-020,phase=Scheduled job=None
20.042,Pod,MODIFIED,eval-sanitize-1-r2-020-vzhm2,phase=Pending node=None
20.0499,Job,MODIFIED,eval-sanitize-1-r2-019,
20.0522,Job,MODIFIED,eval-sanitize-1-r2-018,
20.0595,Job,MODIFIED,eval-sanitize-1-r2-019,
20.0617,Job,MODIFIED,eval-sanitize-1-r2-018,
21.023,TaskRequest,ADDED,eval-sanitize-1-r2-021,phase=None job=None
21.0292,TaskRequest,MODIFIED,eval-sanitize-1-r2-021,phase=Pending job=None
21.0403,Job,MODIFIED,eval-sanitize-1-r2-020,
21.0447,Job,ADDED,eval-sanitize-1-r2-021,
21.0509,Pod,ADDED,eval-sanitize-1-r2-021-mkjc6,phase=Pending node=None
21.0511,TaskRequest,MODIFIED,eval-sanitize-1-r2-021,phase=Scheduled job=None
21.0546,Job,MODIFIED,eval-sanitize-1-r2-021,
21.0566,Event,ADDED,eval-sanitize-1-r2-021.18d41fb57e28bc1c,reason=SuccessfulCreate count=1 msg=Created pod: eval-sanitize-1-r2-021-mkjc6
21.0575,Pod,MODIFIED,eval-sanitize-1-r2-021-mkjc6,phase=Pending node=None
21.0578,Event,ADDED,eval-sanitize-1-r2-021-mkjc6.18d41fb57e336209,"reason=FailedScheduling count=None msg=0/6 nodes are available: 6 node(s) had untolerated taint(s). no new claims to deallocate, preemption: 0/6 nodes are available: 6 Preemption is not helpful for scheduling."
21.0593,TaskRequest,MODIFIED,eval-sanitize-1-r2-021,phase=Scheduled job=None
21.0617,Job,MODIFIED,eval-sanitize-1-r2-020,
22.0128,TaskRequest,ADDED,eval-sanitize-1-r2-022,phase=None job=None
22.0164,TaskRequest,MODIFIED,eval-sanitize-1-r2-022,phase=Pending job=None
22.0328,Job,ADDED,eval-sanitize-1-r2-022,
22.0392,Pod,ADDED,eval-sanitize-1-r2-022-p9mtd,phase=Pending node=None
22.0393,TaskRequest,MODIFIED,eval-sanitize-1-r2-022,phase=Scheduled job=None
22.0429,Job,MODIFIED,eval-sanitize-1-r2-022,
22.0447,Event,ADDED,eval-sanitize-1-r2-022.18d41fb5b90f23c2,reason=SuccessfulCreate count=1 msg=Created pod: eval-sanitize-1-r2-022-p9mtd
22.0449,Event,ADDED,eval-sanitize-1-r2-022-p9mtd.18d41fb5b916597e,"reason=FailedScheduling count=None msg=0/6 nodes are available: 6 node(s) had untolerated taint(s). no new claims to deallocate, preemption: 0/6 nodes are available: 6 Preemption is not helpful for scheduling."
22.0459,Pod,MODIFIED,eval-sanitize-1-r2-022-p9mtd,phase=Pending node=None
22.0461,TaskRequest,MODIFIED,eval-sanitize-1-r2-022,phase=Scheduled job=None
22.0556,Job,MODIFIED,eval-sanitize-1-r2-021,
22.064,Job,MODIFIED,eval-sanitize-1-r2-021,
23.0087,TaskRequest,ADDED,eval-sanitize-1-r2-023,phase=None job=None
23.0124,TaskRequest,MODIFIED,eval-sanitize-1-r2-023,phase=Pending job=None
23.03,Job,ADDED,eval-sanitize-1-r2-023,
23.0345,TaskRequest,MODIFIED,eval-sanitize-1-r2-023,phase=Scheduled job=None
23.0391,Pod,ADDED,eval-sanitize-1-r2-023-9f62p,phase=Pending node=None
23.0415,Job,MODIFIED,eval-sanitize-1-r2-023,
23.043,TaskRequest,MODIFIED,eval-sanitize-1-r2-023,phase=Scheduled job=None
23.0455,Event,ADDED,eval-sanitize-1-r2-023.18d41fb5f4a93579,reason=SuccessfulCreate count=1 msg=Created pod: eval-sanitize-1-r2-023-9f62p
23.0457,Event,ADDED,eval-sanitize-1-r2-023-9f62p.18d41fb5f4b874f7,"reason=FailedScheduling count=None msg=0/6 nodes are available: 6 node(s) had untolerated taint(s). no new claims to deallocate, preemption: 0/6 nodes are available: 6 Preemption is not helpful for scheduling."
23.0467,Pod,MODIFIED,eval-sanitize-1-r2-023-9f62p,phase=Pending node=None
23.0474,Job,MODIFIED,eval-sanitize-1-r2-022,
23.0549,Job,MODIFIED,eval-sanitize-1-r2-022,
24.0071,TaskRequest,ADDED,eval-sanitize-1-r2-024,phase=None job=None
24.0119,TaskRequest,MODIFIED,eval-sanitize-1-r2-024,phase=Pending job=None
24.0267,Job,ADDED,eval-sanitize-1-r2-024,
24.0322,TaskRequest,MODIFIED,eval-sanitize-1-r2-024,phase=Scheduled job=None
24.0353,Pod,ADDED,eval-sanitize-1-r2-024-49jtx,phase=Pending node=None
24.0377,Job,MODIFIED,eval-sanitize-1-r2-024,
24.0416,Event,ADDED,eval-sanitize-1-r2-024.18d41fb6300716f4,reason=SuccessfulCreate count=1 msg=Created pod: eval-sanitize-1-r2-024-49jtx
24.0418,Event,ADDED,eval-sanitize-1-r2-024-49jtx.18d41fb6301098c5,"reason=FailedScheduling count=None msg=0/6 nodes are available: 6 node(s) had untolerated taint(s). no new claims to deallocate, preemption: 0/6 nodes are available: 6 Preemption is not helpful for scheduling."
24.0419,TaskRequest,MODIFIED,eval-sanitize-1-r2-024,phase=Scheduled job=None
24.0428,Pod,MODIFIED,eval-sanitize-1-r2-024-49jtx,phase=Pending node=None
24.0438,Job,MODIFIED,eval-sanitize-1-r2-023,
24.0519,Job,MODIFIED,eval-sanitize-1-r2-023,
24.5354,Pod,MODIFIED,eval-sanitize-1-r2-009-4dhzg,phase=Running node=kind-worker5
24.5414,Pod,MODIFIED,eval-sanitize-1-r2-007-fzlg7,phase=Running node=kind-worker5
24.5467,Pod,MODIFIED,eval-sanitize-1-r2-010-wsghf,phase=Running node=kind-worker5
24.5528,Pod,MODIFIED,eval-sanitize-1-r2-006-hjp5g,phase=Running node=kind-worker5
24.5584,Pod,MODIFIED,eval-sanitize-1-r2-005-2bx8m,phase=Running node=kind-worker5
25.0121,Pod,MODIFIED,eval-sanitize-1-r2-014-k7rkd,phase=Running node=kind-worker3
25.0124,TaskRequest,ADDED,eval-sanitize-1-r2-025,phase=None job=None
25.0168,Pod,MODIFIED,eval-sanitize-1-r2-012-jmcgx,phase=Running node=kind-worker3
25.0169,TaskRequest,MODIFIED,eval-sanitize-1-r2-025,phase=Pending job=None
25.0315,Job,ADDED,eval-sanitize-1-r2-025,
25.0413,Pod,ADDED,eval-sanitize-1-r2-025-2lqh8,phase=Pending node=None
25.0427,TaskRequest,MODIFIED,eval-sanitize-1-r2-025,phase=Scheduled job=None
25.0521,Job,MODIFIED,eval-sanitize-1-r2-025,
25.0534,Event,ADDED,eval-sanitize-1-r2-025-2lqh8.18d41fb66bebca9f,"reason=FailedScheduling count=None msg=0/6 nodes are available: 6 node(s) had untolerated taint(s). no new claims to deallocate, preemption: 0/6 nodes are available: 6 Preemption is not helpful for scheduling."
25.0539,Event,ADDED,eval-sanitize-1-r2-025.18d41fb66bd4bb34,reason=SuccessfulCreate count=1 msg=Created pod: eval-sanitize-1-r2-025-2lqh8
25.0546,Job,MODIFIED,eval-sanitize-1-r2-024,
25.0555,Pod,MODIFIED,eval-sanitize-1-r2-025-2lqh8,phase=Pending node=None
25.0579,TaskRequest,MODIFIED,eval-sanitize-1-r2-025,phase=Scheduled job=None
25.0637,Job,MODIFIED,eval-sanitize-1-r2-024,
25.5421,Job,MODIFIED,eval-sanitize-1-r2-009,
25.5475,Job,MODIFIED,eval-sanitize-1-r2-007,
25.5539,Job,MODIFIED,eval-sanitize-1-r2-010,
25.5553,Job,MODIFIED,eval-sanitize-1-r2-009,
25.5581,Job,MODIFIED,eval-sanitize-1-r2-007,
25.5609,Job,MODIFIED,eval-sanitize-1-r2-006,
25.5633,Job,MODIFIED,eval-sanitize-1-r2-005,
25.5644,Job,MODIFIED,eval-sanitize-1-r2-010,
25.5701,Job,MODIFIED,eval-sanitize-1-r2-006,
25.573,Job,MODIFIED,eval-sanitize-1-r2-005,
25.7104,Pod,MODIFIED,eval-sanitize-1-r2-005-2bx8m,phase=Succeeded node=kind-worker5
25.7412,Pod,MODIFIED,eval-sanitize-1-r2-009-4dhzg,phase=Succeeded node=kind-worker5
25.7476,Pod,MODIFIED,eval-sanitize-1-r2-007-fzlg7,phase=Succeeded node=kind-worker5
25.754,Pod,MODIFIED,eval-sanitize-1-r2-010-wsghf,phase=Succeeded node=kind-worker5
25.7601,Pod,MODIFIED,eval-sanitize-1-r2-006-hjp5g,phase=Succeeded node=kind-worker5
26.012,TaskRequest,ADDED,eval-sanitize-1-r2-026,phase=None job=None
26.0176,Job,MODIFIED,eval-sanitize-1-r2-014,
26.0178,TaskRequest,MODIFIED,eval-sanitize-1-r2-026,phase=Pending job=None
26.0211,Job,MODIFIED,eval-sanitize-1-r2-012,
26.0331,Node,MODIFIED,kind-worker5,taints=1
26.0374,Job,ADDED,eval-sanitize-1-r2-026,
26.0462,Job,MODIFIED,eval-sanitize-1-r2-025,
26.0474,Pod,ADDED,eval-sanitize-1-r2-026-4lgk7,phase=Pending node=None
26.0475,TaskRequest,MODIFIED,eval-sanitize-1-r2-026,phase=Scheduled job=None
26.0483,Job,MODIFIED,eval-sanitize-1-r2-026,
26.0518,Event,ADDED,eval-sanitize-1-r2-026.18d41fb6a7d79078,reason=SuccessfulCreate count=1 msg=Created pod: eval-sanitize-1-r2-026-4lgk7
26.052,Event,ADDED,eval-sanitize-1-r2-026-4lgk7.18d41fb6a7df8e42,"reason=FailedScheduling count=None msg=0/6 nodes are available: 6 node(s) had untolerated taint(s). no new claims to deallocate, preemption: 0/6 nodes are available: 6 Preemption is not helpful for scheduling."
26.053,Pod,MODIFIED,eval-sanitize-1-r2-026-4lgk7,phase=Pending node=None
26.0552,TaskRequest,MODIFIED,eval-sanitize-1-r2-026,phase=Scheduled job=None
26.0577,Job,MODIFIED,eval-sanitize-1-r2-014,
26.0598,Job,MODIFIED,eval-sanitize-1-r2-012,
26.0619,Job,MODIFIED,eval-sanitize-1-r2-025,
26.0969,Pod,MODIFIED,eval-sanitize-1-r2-014-k7rkd,phase=Succeeded node=kind-worker3
26.1353,Node,MODIFIED,kind-worker5,taints=1
26.1443,Pod,MODIFIED,eval-sanitize-1-r2-012-jmcgx,phase=Succeeded node=kind-worker3
26.2452,Node,MODIFIED,kind-worker5,taints=0
26.2503,Pod,MODIFIED,eval-sanitize-1-r2-017-w6mk9,phase=Pending node=kind-worker5
26.2535,Event,ADDED,eval-sanitize-1-r2-017-w6mk9.18d41fb6b40eca09,reason=Scheduled count=None msg=Successfully assigned compute/eval-sanitize-1-r2-017-w6mk9 to kind-worker5
26.2591,Pod,MODIFIED,eval-sanitize-1-r2-019-7bqxs,phase=Pending node=kind-worker5
26.2627,Node,MODIFIED,kind-worker5,taints=0
26.264,Pod,MODIFIED,eval-sanitize-1-r2-017-w6mk9,phase=Pending node=kind-worker5
26.266,Pod,MODIFIED,eval-sanitize-1-r2-020-vzhm2,phase=Pending node=kind-worker5
26.267,Event,ADDED,eval-sanitize-1-r2-019-7bqxs.18d41fb6b495b587,reason=Scheduled count=None msg=Successfully assigned compute/eval-sanitize-1-r2-019-7bqxs to kind-worker5
26.2673,Event,ADDED,eval-sanitize-1-r2-021-mkjc6.18d41fb6b4a79538,"reason=FailedScheduling count=None msg=0/6 nodes are available: 1 c_wall violated: 1 conflicting context pair(s) with node memory, 5 node(s) had untolerated taint(s). no new claims to deallocate, preemption: 0/6 nodes are available: 1 No preemption victims found for incoming pod, 5 Preemption is not helpful for scheduling."
26.2681,Pod,MODIFIED,eval-sanitize-1-r2-021-mkjc6,phase=Pending node=None
26.2733,Pod,MODIFIED,eval-sanitize-1-r2-019-7bqxs,phase=Pending node=kind-worker5
26.2736,Event,ADDED,eval-sanitize-1-r2-020-vzhm2.18d41fb6b4f57f76,reason=Scheduled count=None msg=Successfully assigned compute/eval-sanitize-1-r2-020-vzhm2 to kind-worker5
26.2775,Pod,MODIFIED,eval-sanitize-1-r2-022-p9mtd,phase=Pending node=None
26.2788,Event,ADDED,eval-sanitize-1-r2-022-p9mtd.18d41fb6b55e637a,"reason=FailedScheduling count=None msg=0/6 nodes are available: 1 c_wall violated: 1 conflicting context pair(s) with node memory, 5 node(s) had untolerated taint(s). no new claims to deallocate, preemption: 0/6 nodes are available: 1 No preemption victims found for incoming pod, 5 Preemption is not helpful for scheduling."
26.2801,Pod,MODIFIED,eval-sanitize-1-r2-020-vzhm2,phase=Pending node=kind-worker5
26.2856,Pod,MODIFIED,eval-sanitize-1-r2-023-9f62p,phase=Pending node=None
26.286,Event,ADDED,eval-sanitize-1-r2-023-9f62p.18d41fb6b5e78104,"reason=FailedScheduling count=None msg=0/6 nodes are available: 1 c_wall violated: 2 conflicting context pair(s) with node memory, 5 node(s) had untolerated taint(s). no new claims to deallocate, preemption: 0/6 nodes are available: 1 No preemption victims found for incoming pod, 5 Preemption is not helpful for scheduling."
26.2892,Node,MODIFIED,kind-worker5,taints=0
26.2942,Pod,MODIFIED,eval-sanitize-1-r2-024-49jtx,phase=Pending node=kind-worker5
26.2976,Event,ADDED,eval-sanitize-1-r2-024-49jtx.18d41fb6b6adc380,reason=Scheduled count=None msg=Successfully assigned compute/eval-sanitize-1-r2-024-49jtx to kind-worker5
26.3049,Pod,MODIFIED,eval-sanitize-1-r2-024-49jtx,phase=Pending node=kind-worker5
26.3388,Node,MODIFIED,kind-worker5,taints=0
26.3541,Pod,MODIFIED,eval-sanitize-1-r2-025-2lqh8,phase=Pending node=kind-worker5
26.3561,Pod,MODIFIED,eval-sanitize-1-r2-026-4lgk7,phase=Pending node=None
26.3565,Event,ADDED,eval-sanitize-1-r2-026-4lgk7.18d41fb6ba1334be,"reason=FailedScheduling count=None msg=0/6 nodes are available: 1 c_wall violated: 2 conflicting context pair(s) with node memory, 5 node(s) had untolerated taint(s). no new claims to deallocate, preemption: 0/6 nodes are available: 1 No preemption victims found for incoming pod, 5 Preemption is not helpful for scheduling."
26.3593,Event,ADDED,eval-sanitize-1-r2-025-2lqh8.18d41fb6ba4023d8,reason=Scheduled count=None msg=Successfully assigned compute/eval-sanitize-1-r2-025-2lqh8 to kind-worker5
26.363,Pod,MODIFIED,eval-sanitize-1-r2-021-mkjc6,phase=Pending node=None
26.3642,Event,ADDED,eval-sanitize-1-r2-021-mkjc6.18d41fb6ba8f0879,"reason=FailedScheduling count=None msg=0/6 nodes are available: 1 c_wall violated: 2 conflicting context pair(s) with node memory, 5 node(s) had untolerated taint(s). no new claims to deallocate, preemption: 0/6 nodes are available: 1 No preemption victims found for incoming pod, 5 Preemption is not helpful for scheduling."
26.3658,Pod,MODIFIED,eval-sanitize-1-r2-025-2lqh8,phase=Pending node=kind-worker5
26.368,Node,MODIFIED,kind-worker5,taints=0
26.3703,Event,ADDED,eval-sanitize-1-r2-022-p9mtd.18d41fb6baff214a,"reason=FailedScheduling count=None msg=0/6 nodes are available: 1 c_wall violated: 1 conflicting context pair(s) with node memory, 5 node(s) had untolerated taint(s). no new claims to deallocate, preemption: 0/6 nodes are available: 1 No preemption victims found for incoming pod, 5 Preemption is not helpful for scheduling."
26.3733,Event,ADDED,eval-sanitize-1-r2-023-9f62p.18d41fb6bb32da0e,"reason=FailedScheduling count=None msg=0/6 nodes are available: 1 c_wall violated: 2 conflicting context pair(s) with node memory, 5 node(s) had untolerated taint(s). no new claims to deallocate, preemption: 0/6 nodes are available: 1 No preemption victims found for incoming pod, 5 Preemption is not helpful for scheduling."
26.3898,Event,ADDED,eval-sanitize-1-r2-026-4lgk7.18d41fb6bb6321be,"reason=FailedScheduling count=None msg=0/6 nodes are available: 1 c_wall violated: 2 conflicting context pair(s) with node memory, 5 node(s) had untolerated taint(s). no new claims to deallocate, preemption: 0/6 nodes are available: 1 No preemption victims found for incoming pod, 5 Preemption is not helpful for scheduling."
26.4362,Node,MODIFIED,kind-worker5,taints=0
26.4507,Event,ADDED,eval-sanitize-1-r2-021-mkjc6.18d41fb6bfbcccb3,"reason=FailedScheduling count=None msg=0/6 nodes are available: 1 c_wall violated: 2 conflicting context pair(s) with node memory, 5 node(s) had untolerated taint(s). no new claims to deallocate, preemption: 0/6 nodes are available: 1 No preemption victims found for incoming pod, 5 Preemption is not helpful for scheduling."
26.454,Event,MODIFIED,eval-sanitize-1-r2-022-p9mtd.18d41fb6baff214a,"reason=FailedScheduling count=None msg=0/6 nodes are available: 1 c_wall violated: 1 conflicting context pair(s) with node memory, 5 node(s) had untolerated taint(s). no new claims to deallocate, preemption: 0/6 nodes are available: 1 No preemption victims found for incoming pod, 5 Preemption is not helpful for scheduling."
26.4561,Event,MODIFIED,eval-sanitize-1-r2-023-9f62p.18d41fb6bb32da0e,"reason=FailedScheduling count=None msg=0/6 nodes are available: 1 c_wall violated: 2 conflicting context pair(s) with node memory, 5 node(s) had untolerated taint(s). no new claims to deallocate, preemption: 0/6 nodes are available: 1 No preemption victims found for incoming pod, 5 Preemption is not helpful for scheduling."
26.46,Event,MODIFIED,eval-sanitize-1-r2-026-4lgk7.18d41fb6bb6321be,"reason=FailedScheduling count=None msg=0/6 nodes are available: 1 c_wall violated: 2 conflicting context pair(s) with node memory, 5 node(s) had untolerated taint(s). no new claims to deallocate, preemption: 0/6 nodes are available: 1 No preemption victims found for incoming pod, 5 Preemption is not helpful for scheduling."
26.461,Event,MODIFIED,eval-sanitize-1-r2-021-mkjc6.18d41fb6bfbcccb3,"reason=FailedScheduling count=None msg=0/6 nodes are available: 1 c_wall violated: 2 conflicting context pair(s) with node memory, 5 node(s) had untolerated taint(s). no new claims to deallocate, preemption: 0/6 nodes are available: 1 No preemption victims found for incoming pod, 5 Preemption is not helpful for scheduling."
26.5399,Node,MODIFIED,kind-worker5,taints=0
26.5479,Job,MODIFIED,eval-sanitize-1-r2-009,
26.5532,Job,MODIFIED,eval-sanitize-1-r2-007,
26.5569,Pod,MODIFIED,eval-sanitize-1-r2-009-4dhzg,phase=Succeeded node=kind-worker5
26.5582,Job,MODIFIED,eval-sanitize-1-r2-009,
26.56,Job,MODIFIED,eval-sanitize-1-r2-010,
26.5644,Pod,MODIFIED,eval-sanitize-1-r2-007-fzlg7,phase=Succeeded node=kind-worker5
26.5652,Job,MODIFIED,eval-sanitize-1-r2-007,
26.5666,Job,MODIFIED,eval-sanitize-1-r2-006,
26.5701,Job,MODIFIED,eval-sanitize-1-r2-005,
26.5715,Pod,MODIFIED,eval-sanitize-1-r2-010-wsghf,phase=Succeeded node=kind-worker5
26.5739,Job,MODIFIED,eval-sanitize-1-r2-010,
26.5773,Job,MODIFIED,eval-sanitize-1-r2-006,
26.5785,Pod,MODIFIED,eval-sanitize-1-r2-006-hjp5g,phase=Succeeded node=kind-worker5
26.5822,Pod,MODIFIED,eval-sanitize-1-r2-005-2bx8m,phase=Succeeded node=kind-worker5
26.5845,Job,MODIFIED,eval-sanitize-1-r2-005,
26.6076,Pod,MODIFIED,eval-sanitize-1-r2-013-kl8tg,phase=Running node=kind-worker
26.615,Pod,MODIFIED,eval-sanitize-1-r2-015-tqkls,phase=Running node=kind-worker
26.706,Event,ADDED,eval-sanitize-1-r2-017-w6mk9.18d41fb6cecbfb0a,"reason=Pulled count=1 msg=Container image ""busybox:musl"" already present on machine"
26.7207,Event,ADDED,eval-sanitize-1-r2-020-vzhm2.18d41fb6cfd0e525,"reason=Pulled count=1 msg=Container image ""busybox:musl"" already present on machine"
26.7252,Event,ADDED,eval-sanitize-1-r2-019-7bqxs.18d41fb6cff0d841,"reason=Pulled count=1 msg=Container image ""busybox:musl"" already present on machine"
26.7324,Event,ADDED,eval-sanitize-1-r2-017-w6mk9.18d41fb6d08a0cb7,reason=Created count=1 msg=Created container: task
26.7434,Event,ADDED,eval-sanitize-1-r2-024-49jtx.18d41fb6d11aaa36,"reason=Pulled count=1 msg=Container image ""busybox:musl"" already present on machine"
26.7541,Event,ADDED,eval-sanitize-1-r2-019-7bqxs.18d41fb6d1c3c90f,reason=Created count=1 msg=Created container: task
26.7612,Event,ADDED,eval-sanitize-1-r2-020-vzhm2.18d41fb6d21bc480,reason=Created count=1 msg=Created container: task
26.7669,Event,ADDED,eval-sanitize-1-r2-025-2lqh8.18d41fb6d2714998,"reason=Pulled count=1 msg=Container image ""busybox:musl"" already present on machine"
26.7719,Event,ADDED,eval-sanitize-1-r2-017-w6mk9.18d41fb6d2effa9e,reason=Started count=1 msg=Started container task
26.7784,Event,ADDED,eval-sanitize-1-r2-024-49jtx.18d41fb6d31beed7,reason=Created count=1 msg=Created container: task
26.7877,Event,ADDED,eval-sanitize-1-r2-025-2lqh8.18d41fb6d3d8d6cd,reason=Created count=1 msg=Created container: task
26.8061,Pod,MODIFIED,eval-sanitize-1-r2-011-5sw64,phase=Running node=kind-worker4
26.8135,Pod,MODIFIED,eval-sanitize-1-r2-008-7hn5w,phase=Running node=kind-worker4
26.8235,Event,ADDED,eval-sanitize-1-r2-025-2lqh8.18d41fb6d5ded2ac,reason=Started count=1 msg=Started container task
26.8296,Event,ADDED,eval-sanitize-1-r2-019-7bqxs.18d41fb6d667dc1c,reason=Started count=1 msg=Started container task
26.8745,Event,ADDED,eval-sanitize-1-r2-020-vzhm2.18d41fb6d90c15ac,reason=Started count=1 msg=Started container task
26.8778,Event,ADDED,eval-sanitize-1-r2-024-49jtx.18d41fb6d90c3e0c,reason=Started count=1 msg=Started container task
27.0118,TaskRequest,ADDED,eval-sanitize-1-r2-027,phase=None job=None
27.0156,TaskRequest,MODIFIED,eval-sanitize-1-r2-027,phase=Pending job=None
27.0274,Job,MODIFIED,eval-sanitize-1-r2-014,
27.0297,Job,MODIFIED,eval-sanitize-1-r2-012,
27.0303,Job,ADDED,eval-sanitize-1-r2-027,
27.0383,Pod,MODIFIED,eval-sanitize-1-r2-014-k7rkd,phase=Succeeded node=kind-worker3
27.0385,TaskRequest,MODIFIED,eval-sanitize-1-r2-027,phase=Scheduled job=None
27.0401,Pod,ADDED,eval-sanitize-1-r2-027-9rnn5,phase=Pending node=None
27.0419,Pod,MODIFIED,eval-sanitize-1-r2-012-jmcgx,phase=Succeeded node=kind-worker3
27.0432,Job,MODIFIED,eval-sanitize-1-r2-014,
27.0454,Job,MODIFIED,eval-sanitize-1-r2-027,
27.0457,Event,ADDED,eval-sanitize-1-r2-027.18d41fb6e311f8b7,reason=SuccessfulCreate count=1 msg=Created pod: eval-sanitize-1-r2-027-9rnn5
27.0468,Job,MODIFIED,eval-sanitize-1-r2-012,
27.0491,Pod,MODIFIED,eval-sanitize-1-r2-027-9rnn5,phase=Pending node=None
27.0502,Event,ADDED,eval-sanitize-1-r2-027-9rnn5.18d41fb6e36335fd,"reason=FailedScheduling count=None msg=0/6 nodes are available: 1 c_wall violated: 2 conflicting context pair(s) with node memory, 5 node(s) had untolerated taint(s). no new claims to deallocate, preemption: 0/6 nodes are available: 1 No preemption victims found for incoming pod, 5 Preemption is not helpful for scheduling."
27.051,Job,MODIFIED,eval-sanitize-1-r2-026,
27.0513,Event,ADDED,eval-sanitize-1-r2-014.18d41fb6e3560ad4,reason=Completed count=1 msg=Job completed
27.0534,TaskRequest,MODIFIED,eval-sanitize-1-r2-027,phase=Scheduled job=None
27.0561,Event,ADDED,eval-sanitize-1-r2-012.18d41fb6e37dd886,reason=Completed count=1 msg=Job completed
27.0588,Job,MODIFIED,eval-sanitize-1-r2-014,
27.0601,Job,MODIFIED,eval-sanitize-1-r2-012,
27.0604,Event,ADDED,eval-sanitize-1-r2-027-9rnn5.18d41fb6e405ff18,"reason=FailedScheduling count=None msg=0/6 nodes are available: 1 c_wall violated: 2 conflicting context pair(s) with node memory, 5 node(s) had untolerated taint(s). no new claims to deallocate, preemption: 0/6 nodes are available: 1 No preemption victims found for incoming pod, 5 Preemption is not helpful for scheduling."
27.0612,Job,MODIFIED,eval-sanitize-1-r2-026,
27.104,TaskRequest,MODIFIED,eval-sanitize-1-r2-014,phase=Complete job=None
27.1077,TaskRequest,MODIFIED,eval-sanitize-1-r2-012,phase=Complete job=None
27.1136,Job,MODIFIED,eval-sanitize-1-r2-014,
27.1428,Job,MODIFIED,eval-sanitize-1-r2-012,
27.5547,Pod,MODIFIED,eval-sanitize-1-r2-024-49jtx,phase=Running node=kind-worker5
27.5558,Job,MODIFIED,eval-sanitize-1-r2-009,
27.5584,Job,MODIFIED,eval-sanitize-1-r2-007,
27.5614,Job,MODIFIED,eval-sanitize-1-r2-009,
27.5637,Job,MODIFIED,eval-sanitize-1-r2-007,
27.5651,Pod,MODIFIED,eval-sanitize-1-r2-025-2lqh8,phase=Running node=kind-worker5
27.5658,Job,MODIFIED,eval-sanitize-1-r2-010,
27.5668,Event,ADDED,eval-sanitize-1-r2-009.18d41fb702391256,reason=Completed count=1 msg=Job completed
27.5722,Job,MODIFIED,eval-sanitize-1-r2-010,
27.5735,Job,MODIFIED,eval-sanitize-1-r2-006,
27.5739,Event,ADDED,eval-sanitize-1-r2-007.18d41fb7025674aa,reason=Completed count=1 msg=Job completed
27.5753,Pod,MODIFIED,eval-sanitize-1-r2-019-7bqxs,phase=Running node=kind-worker5
27.5782,Job,MODIFIED,eval-sanitize-1-r2-009,
27.5797,Job,MODIFIED,eval-sanitize-1-r2-005,
27.5816,Job,MODIFIED,eval-sanitize-1-r2-007,
27.582,Event,ADDED,eval-sanitize-1-r2-010.18d41fb702e27721,reason=Completed count=1 msg=Job completed
27.5823,Event,MODIFIED,eval-sanitize-1-r2-027-9rnn5.18d41fb6e405ff18,"reason=FailedScheduling count=None msg=0/6 nodes are available: 1 c_wall violated: 2 conflicting context pair(s) with node memory, 5 node(s) had untolerated taint(s). no new claims to deallocate, preemption: 0/6 nodes are available: 1 No preemption victims found for incoming pod, 5 Preemption is not helpful for scheduling."
27.5833,Job,MODIFIED,eval-sanitize-1-r2-006,
27.5841,Job,MODIFIED,eval-sanitize-1-r2-005,
27.5854,TaskRequest,MODIFIED,eval-sanitize-1-r2-009,phase=Complete job=None
27.5864,Job,MODIFIED,eval-sanitize-1-r2-010,
27.5876,Event,ADDED,eval-sanitize-1-r2-006.18d41fb7036c018b,reason=Completed count=1 msg=Job completed
27.5894,Pod,MODIFIED,eval-sanitize-1-r2-020-vzhm2,phase=Running node=kind-worker5
27.5937,TaskRequest,MODIFIED,eval-sanitize-1-r2-007,phase=Complete job=None
27.5973,Event,ADDED,eval-sanitize-1-r2-005.18d41fb703957b82,reason=Completed count=1 msg=Job completed
27.5986,Job,MODIFIED,eval-sanitize-1-r2-006,
27.6002,Pod,MODIFIED,eval-sanitize-1-r2-017-w6mk9,phase=Running node=kind-worker5
27.6003,TaskRequest,MODIFIED,eval-sanitize-1-r2-010,phase=Complete job=None
27.6121,Job,MODIFIED,eval-sanitize-1-r2-013,
27.6195,Job,MODIFIED,eval-sanitize-1-r2-015,
27.6388,Job,MODIFIED,eval-sanitize-1-r2-009,
27.6404,TaskRequest,MODIFIED,eval-sanitize-1-r2-006,phase=Complete job=None
27.6412,Job,MODIFIED,eval-sanitize-1-r2-005,
27.6429,Job,MODIFIED,eval-sanitize-1-r2-007,
27.6448,Job,MODIFIED,eval-sanitize-1-r2-010,
27.7348,TaskRequest,MODIFIED,eval-sanitize-1-r2-005,phase=Complete job=None
27.7384,Job,MODIFIED,eval-sanitize-1-r2-006,
27.7401,Job,MODIFIED,eval-sanitize-1-r2-013,
27.7432,Job,MODIFIED,eval-sanitize-1-r2-005,
27.7449,Job,MODIFIED,eval-sanitize-1-r2-015,
27.8044,Pod,MODIFIED,eval-sanitize-1-r2-013-kl8tg,phase=Succeeded node=kind-worker
27.8116,Job,MODIFIED,eval-sanitize-1-r2-011,
27.8185,Job,MODIFIED,eval-sanitize-1-r2-008,
27.8224,Job,MODIFIED,eval-sanitize-1-r2-011,
27.8295,Job,MODIFIED,eval-sanitize-1-r2-008,
27.899,Pod,MODIFIED,eval-sanitize-1-r2-011-5sw64,phase=Succeeded node=kind-worker4
27.9424,Node,MODIFIED,kind-worker5,taints=1
27.9474,Pod,MODIFIED,eval-sanitize-1-r2-015-tqkls,phase=Succeeded node=kind-worker
27.9487,Pod,MODIFIED,eval-sanitize-1-r2-008-7hn5w,phase=Succeeded node=kind-worker4
27.9495,Pod,MODIFIED,eval-sanitize-1-r2-021-mkjc6,phase=Pending node=None
27.9524,Pod,MODIFIED,eval-sanitize-1-r2-022-p9mtd,phase=Pending node=None
27.9569,Pod,MODIFIED,eval-sanitize-1-r2-027-9rnn5,phase=Pending node=None
27.9606,Pod,MODIFIED,eval-sanitize-1-r2-023-9f62p,phase=Pending node=None
27.9652,Pod,MODIFIED,eval-sanitize-1-r2-026-4lgk7,phase=Pending node=None
28.0134,TaskRequest,ADDED,eval-sanitize-1-r2-028,phase=None job=None
28.0171,TaskRequest,MODIFIED,eval-sanitize-1-r2-028,phase=Pending job=None
28.0327,Job,ADDED,eval-sanitize-1-r2-028,
28.0369,Node,MODIFIED,kind-worker5,taints=1
28.0377,Pod,ADDED,eval-sanitize-1-r2-028-dp77l,phase=Pending node=None
28.0392,TaskRequest,MODIFIED,eval-sanitize-1-r2-028,phase=Scheduled job=None
28.0418,Job,MODIFIED,eval-sanitize-1-r2-028,
28.0437,Event,ADDED,eval-sanitize-1-r2-028.18d41fb71ea106af,reason=SuccessfulCreate count=1 msg=Created pod: eval-sanitize-1-r2-028-dp77l
28.044,Event,ADDED,eval-sanitize-1-r2-028-dp77l.18d41fb71ea73cd2,"reason=FailedScheduling count=None msg=0/6 nodes are available: 6 node(s) had untolerated taint(s). no new claims to deallocate, preemption: 0/6 nodes are available: 6 Preemption is not helpful for scheduling."
28.0447,Job,MODIFIED,eval-sanitize-1-r2-027,
28.0454,Pod,MODIFIED,eval-sanitize-1-r2-028-dp77l,phase=Pending node=None
28.0537,Job,MODIFIED,eval-sanitize-1-r2-027,
28.06,TaskRequest,MODIFIED,eval-sanitize-1-r2-028,phase=Scheduled job=None
28.1674,Pod,MODIFIED,eval-sanitize-1-r2-016-smvtd,phase=Running node=kind-worker2
28.5647,Job,MODIFIED,eval-sanitize-1-r2-024,
28.5694,Job,MODIFIED,eval-sanitize-1-r2-025,
28.5737,Job,MODIFIED,eval-sanitize-1-r2-024,
28.5776,Job,MODIFIED,eval-sanitize-1-r2-025,
28.5795,Job,MODIFIED,eval-sanitize-1-r2-019,
28.5881,Job,MODIFIED,eval-sanitize-1-r2-019,
28.593,Job,MODIFIED,eval-sanitize-1-r2-020,
28.6017,Job,MODIFIED,eval-sanitize-1-r2-020,
28.6037,Job,MODIFIED,eval-sanitize-1-r2-017,
28.6124,Job,MODIFIED,eval-sanitize-1-r2-017,
28.6168,Job,MODIFIED,eval-sanitize-1-r2-013,
28.6246,Pod,MODIFIED,eval-sanitize-1-r2-013-kl8tg,phase=Succeeded node=kind-worker
28.6262,Job,MODIFIED,eval-sanitize-1-r2-015,
28.6269,Job,MODIFIED,eval-sanitize-1-r2-013,
28.6348,Pod,MODIFIED,eval-sanitize-1-r2-015-tqkls,phase=Succeeded node=kind-worker
28.6381,Job,MODIFIED,eval-sanitize-1-r2-015,
28.6411,Event,ADDED,eval-sanitize-1-r2-015.18d41fb742670246,reason=Completed count=1 msg=Job completed
28.6468,Job,MODIFIED,eval-sanitize-1-r2-015,
28.6507,TaskRequest,MODIFIED,eval-sanitize-1-r2-015,phase=Complete job=None
28.6593,Job,MODIFIED,eval-sanitize-1-r2-015,
28.8185,Job,MODIFIED,eval-sanitize-1-r2-011,
28.8238,Job,MODIFIED,eval-sanitize-1-r2-008,
28.8272,Pod,MODIFIED,eval-sanitize-1-r2-011-5sw64,phase=Succeeded node=kind-worker4
28.8283,Job,MODIFIED,eval-sanitize-1-r2-011,
28.8334,Job,MODIFIED,eval-sanitize-1-r2-008,
28.8347,Pod,MODIFIED,eval-sanitize-1-r2-008-7hn5w,phase=Succeeded node=kind-worker4
29.0126,TaskRequest,ADDED,eval-sanitize-1-r2-029,phase=None job=None
29.0161,TaskRequest,MODIFIED,eval-sanitize-1-r2-029,phase=Pending job=None
29.0326,Job,ADDED,eval-sanitize-1-r2-029,
29.0365,TaskRequest,MODIFIED,eval-sanitize-1-r2-029,phase=Scheduled job=None
29.0398,Pod,ADDED,eval-sanitize-1-r2-029-gtlx7,phase=Pending node=None
29.0419,Job,MODIFIED,eval-sanitize-1-r2-029,
29.0437,Job,MODIFIED,eval-sanitize-1-r2-028,
29.0464,Pod,MODIFIED,eval-sanitize-1-r2-029-gtlx7,phase=Pending node=None
29.0465,TaskRequest,MODIFIED,eval-sanitize-1-r2-029,phase=Scheduled job=None
29.0468,Event,ADDED,eval-sanitize-1-r2-029.18d41fb75a5280c1,reason=SuccessfulCreate count=1 msg=Created pod: eval-sanitize-1-r2-029-gtlx7
29.047,Event,ADDED,eval-sanitize-1-r2-029-gtlx7.18d41fb75a5cea2c,"reason=FailedScheduling count=None msg=0/6 nodes are available: 6 node(s) had untolerated taint(s). no new claims to deallocate, preemption: 0/6 nodes are available: 6 Preemption is not helpful for scheduling."
29.0521,Job,MODIFIED,eval-sanitize-1-r2-028,
29.1712,Pod,MODIFIED,eval-sanitize-1-r2-018-4p7vs,phase=Running node=kind-worker2
29.1723,Job,MODIFIED,eval-sanitize-1-r2-016,
29.1818,Job,MODIFIED,eval-sanitize-1-r2-016,
29.2522,Pod,MODIFIED,eval-sanitize-1-r2-016-smvtd,phase=Succeeded node=kind-worker2
29.6263,Job,MODIFIED,eval-sanitize-1-r2-013,
29.6313,Job,MODIFIED,eval-sanitize-1-r2-013,
29.6374,Event,ADDED,eval-sanitize-1-r2-013.18d41fb77d9736ff,reason=Completed count=1 msg=Job completed
29.6432,Job,MODIFIED,eval-sanitize-1-r2-013,
29.6481,TaskRequest,MODIFIED,eval-sanitize-1-r2-013,phase=Complete job=None
29.6573,Job,MODIFIED,eval-sanitize-1-r2-013,
29.825,Job,MODIFIED,eval-sanitize-1-r2-011,
29.83,Job,MODIFIED,eval-sanitize-1-r2-008,
29.8325,Job,MODIFIED,eval-sanitize-1-r2-011,
29.8342,Job,MODIFIED,eval-sanitize-1-r2-008,
29.838,Event,ADDED,eval-sanitize-1-r2-011.18d41fb7899685ba,reason=Completed count=1 msg=Job completed
29.8447,Job,MODIFIED,eval-sanitize-1-r2-011,
29.8455,Event,ADDED,eval-sanitize-1-r2-008.18d41fb789b22d9f,reason=Completed count=1 msg=Job completed
29.8504,Job,MODIFIED,eval-sanitize-1-r2-008,
29.8514,TaskRequest,MODIFIED,eval-sanitize-1-r2-011,phase=Complete job=None
29.8561,TaskRequest,MODIFIED,eval-sanitize-1-r2-008,phase=Complete job=None
29.8617,Job,MODIFIED,eval-sanitize-1-r2-011,
29.8656,Job,MODIFIED,eval-sanitize-1-r2-008,
30.0148,TaskRequest,ADDED,eval-sanitize-1-r2-030,phase=None job=None
30.0187,TaskRequest,MODIFIED,eval-sanitize-1-r2-030,phase=Pending job=None
30.0362,Job,ADDED,eval-sanitize-1-r2-030,
30.0412,TaskRequest,MODIFIED,eval-sanitize-1-r2-030,phase=Scheduled job=None
30.044,Pod,ADDED,eval-sanitize-1-r2-030-zdt9c,phase=Pending node=None
30.0465,Job,MODIFIED,eval-sanitize-1-r2-029,
30.0472,Job,MODIFIED,eval-sanitize-1-r2-030,
30.0506,Event,ADDED,eval-sanitize-1-r2-030.18d41fb79632297a,reason=SuccessfulCreate count=1 msg=Created pod: eval-sanitize-1-r2-030-zdt9c
30.0512,Event,ADDED,eval-sanitize-1-r2-030-zdt9c.18d41fb7963d9332,"reason=FailedScheduling count=None msg=0/6 nodes are available: 6 node(s) had untolerated taint(s). no new claims to deallocate, preemption: 0/6 nodes are available: 6 Preemption is not helpful for scheduling."
30.0514,TaskRequest,MODIFIED,eval-sanitize-1-r2-030,phase=Scheduled job=None
30.0524,Pod,MODIFIED,eval-sanitize-1-r2-030-zdt9c,phase=Pending node=None
30.0569,Job,MODIFIED,eval-sanitize-1-r2-029,
30.1802,Job,MODIFIED,eval-sanitize-1-r2-018,
30.1819,Job,MODIFIED,eval-sanitize-1-r2-016,
30.1908,Job,MODIFIED,eval-sanitize-1-r2-018,
30.1937,Job,MODIFIED,eval-sanitize-1-r2-016,
30.195,Pod,MODIFIED,eval-sanitize-1-r2-016-smvtd,phase=Succeeded node=kind-worker2
30.3141,Pod,MODIFIED,eval-sanitize-1-r2-018-4p7vs,phase=Succeeded node=kind-worker2
30.4313,Node,MODIFIED,kind-worker3,taints=1
30.5329,Node,MODIFIED,kind-worker3,taints=1
31.0141,TaskRequest,ADDED,eval-sanitize-1-r2-031,phase=None job=None
31.0181,TaskRequest,MODIFIED,eval-sanitize-1-r2-031,phase=Pending job=None
31.0353,Job,ADDED,eval-sanitize-1-r2-031,
31.0386,Node,MODIFIED,kind-worker3,taints=0
31.044,Pod,ADDED,eval-sanitize-1-r2-031-bbfkd,phase=Pending node=None
31.0452,TaskRequest,MODIFIED,eval-sanitize-1-r2-031,phase=Scheduled job=None
31.0463,Pod,MODIFIED,eval-sanitize-1-r2-021-mkjc6,phase=Pending node=kind-worker3
31.0493,Job,MODIFIED,eval-sanitize-1-r2-031,
31.0542,Event,ADDED,eval-sanitize-1-r2-031.18d41fb7d1ced0e0,reason=SuccessfulCreate count=1 msg=Created pod: eval-sanitize-1-r2-031-bbfkd
31.0552,Pod,MODIFIED,eval-sanitize-1-r2-022-p9mtd,phase=Pending node=kind-worker3
31.0559,Job,MODIFIED,eval-sanitize-1-r2-030,
31.0574,Event,ADDED,eval-sanitize-1-r2-021-mkjc6.18d41fb7d1eaab3a,reason=Scheduled count=None msg=Successfully assigned compute/eval-sanitize-1-r2-021-mkjc6 to kind-worker3
31.0577,TaskRequest,MODIFIED,eval-sanitize-1-r2-031,phase=Scheduled job=None
31.0586,Pod,MODIFIED,eval-sanitize-1-r2-027-9rnn5,phase=Pending node=kind-worker3
31.0594,Pod,MODIFIED,eval-sanitize-1-r2-023-9f62p,phase=Pending node=None
31.0616,Event,ADDED,eval-sanitize-1-r2-023-9f62p.18d41fb7d239e9a1,"reason=FailedScheduling count=None msg=0/6 nodes are available: 1 c_wall violated: 1 conflicting context pair(s) with node memory, 5 node(s) had untolerated taint(s). no new claims to deallocate, preemption: 0/6 nodes are available: 1 No preemption victims found for incoming pod, 5 Preemption is not helpful for scheduling."
31.0633,Node,MODIFIED,kind-worker3,taints=0
31.0655,Event,ADDED,eval-sanitize-1-r2-022-p9mtd.18d41fb7d271856f,reason=Scheduled count=None msg=Successfully assigned compute/eval-sanitize-1-r2-022-p9mtd to kind-worker3
31.0659,Event,ADDED,eval-sanitize-1-r2-027-9rnn5.18d41fb7d2a43371,reason=Scheduled count=None msg=Successfully assigned compute/eval-sanitize-1-r2-027-9rnn5 to kind-worker3
31.0673,Pod,MODIFIED,eval-sanitize-1-r2-021-mkjc6,phase=Pending node=kind-worker3
31.0688,Job,MODIFIED,eval-sanitize-1-r2-030,
31.0699,Event,ADDED,eval-sanitize-1-r2-026-4lgk7.18d41fb7d2fc60b9,"reason=FailedScheduling count=None msg=0/6 nodes are available: 1 c_wall violated: 2 conflicting context pair(s) with node memory, 5 node(s) had untolerated taint(s). no new claims to deallocate, preemption: 0/6 nodes are available: 1 No preemption victims found for incoming pod, 5 Preemption is not helpful for scheduling."
31.0709,Pod,MODIFIED,eval-sanitize-1-r2-026-4lgk7,phase=Pending node=None
31.0759,Pod,MODIFIED,eval-sanitize-1-r2-027-9rnn5,phase=Pending node=kind-worker3
31.0796,Pod,MODIFIED,eval-sanitize-1-r2-028-dp77l,phase=Pending node=None
31.0811,Event,ADDED,eval-sanitize-1-r2-028-dp77l.18d41fb7d3a16e48,"reason=FailedScheduling count=None msg=0/6 nodes are available: 1 c_wall violated: 1 conflicting context pair(s) with node memory, 5 node(s) had untolerated taint(s). no new claims to deallocate, preemption: 0/6 nodes are available: 1 No preemption victims found for incoming pod, 5 Preemption is not helpful for scheduling."
31.0824,Pod,MODIFIED,eval-sanitize-1-r2-022-p9mtd,phase=Pending node=kind-worker3
31.0951,Node,MODIFIED,kind-worker3,taints=0
31.1222,Pod,MODIFIED,eval-sanitize-1-r2-029-gtlx7,phase=Pending node=None
31.1225,Event,ADDED,eval-sanitize-1-r2-029-gtlx7.18d41fb7d6087482,"reason=FailedScheduling count=None msg=0/6 nodes are available: 1 c_wall violated: 1 conflicting context pair(s) with node memory, 5 node(s) had untolerated taint(s). no new claims to deallocate, preemption: 0/6 nodes are available: 1 No preemption victims found for incoming pod, 5 Preemption is not helpful for scheduling."
31.1301,Pod,MODIFIED,eval-sanitize-1-r2-031-bbfkd,phase=Pending node=None
31.1315,Event,ADDED,eval-sanitize-1-r2-031-bbfkd.18d41fb7d6a95b60,"reason=FailedScheduling count=None msg=0/6 nodes are available: 1 c_wall violated: 1 conflicting context pair(s) with node memory, 5 node(s) had untolerated taint(s). no new claims to deallocate, preemption: 0/6 nodes are available: 1 No preemption victims found for incoming pod, 5 Preemption is not helpful for scheduling."
31.1381,Node,MODIFIED,kind-worker3,taints=0
31.1515,Pod,MODIFIED,eval-sanitize-1-r2-030-zdt9c,phase=Pending node=kind-worker3
31.1565,Event,ADDED,eval-sanitize-1-r2-023-9f62p.18d41fb7d81ae92b,"reason=FailedScheduling count=None msg=0/6 nodes are available: 1 c_wall violated: 1 conflicting context pair(s) with node memory, 5 node(s) had untolerated taint(s). no new claims to deallocate, preemption: 0/6 nodes are available: 1 No preemption victims found for incoming pod, 5 Preemption is not helpful for scheduling."
31.1574,Event,ADDED,eval-sanitize-1-r2-030-zdt9c.18d41fb7d8332600,reason=Scheduled count=None msg=Successfully assigned compute/eval-sanitize-1-r2-030-zdt9c to kind-worker3
31.1576,Event,ADDED,eval-sanitize-1-r2-026-4lgk7.18d41fb7d84320c1,"reason=FailedScheduling count=None msg=0/6 nodes are available: 1 c_wall violated: 2 conflicting context pair(s) with node memory, 5 node(s) had untolerated taint(s). no new claims to deallocate, preemption: 0/6 nodes are available: 1 No preemption victims found for incoming pod, 5 Preemption is not helpful for scheduling."
31.1602,Event,ADDED,eval-sanitize-1-r2-028-dp77l.18d41fb7d8749a72,"reason=FailedScheduling count=None msg=0/6 nodes are available: 1 c_wall violated: 1 conflicting context pair(s) with node memory, 5 node(s) had untolerated taint(s). no new claims to deallocate, preemption: 0/6 nodes are available: 1 No preemption victims found for incoming pod, 5 Preemption is not helpful for scheduling."
31.1643,Pod,MODIFIED,eval-sanitize-1-r2-030-zdt9c,phase=Pending node=kind-worker3
31.165,Event,ADDED,eval-sanitize-1-r2-029-gtlx7.18d41fb7d89e5b6d,"reason=FailedScheduling count=None msg=0/6 nodes are available: 1 c_wall violated: 1 conflicting context pair(s) with node memory, 5 node(s) had untolerated taint(s). no new claims to deallocate, preemption: 0/6 nodes are available: 1 No preemption victims found for incoming pod, 5 Preemption is not helpful for scheduling."
31.1848,Job,MODIFIED,eval-sanitize-1-r2-018,
31.1874,Job,MODIFIED,eval-sanitize-1-r2-016,
31.1916,Job,MODIFIED,eval-sanitize-1-r2-016,
31.1943,Pod,MODIFIED,eval-sanitize-1-r2-018-4p7vs,phase=Succeeded node=kind-worker2
31.1946,Event,ADDED,eval-sanitize-1-r2-031-bbfkd.18d41fb7da54ff26,"reason=FailedScheduling count=None msg=0/6 nodes are available: 1 c_wall violated: 1 conflicting context pair(s) with node memory, 5 node(s) had untolerated taint(s). no new claims to deallocate, preemption: 0/6 nodes are available: 1 No preemption victims found for incoming pod, 5 Preemption is not helpful for scheduling."
31.1954,Job,MODIFIED,eval-sanitize-1-r2-018,
31.1966,Event,ADDED,eval-sanitize-1-r2-016.18d41fb7da9e8035,reason=Completed count=1 msg=Job completed
31.2034,Job,MODIFIED,eval-sanitize-1-r2-016,
31.207,TaskRequest,MODIFIED,eval-sanitize-1-r2-016,phase=Complete job=None
31.216,Job,MODIFIED,eval-sanitize-1-r2-016,
31.2197,Event,MODIFIED,eval-sanitize-1-r2-023-9f62p.18d41fb7d81ae92b,"reason=FailedScheduling count=None msg=0/6 nodes are available: 1 c_wall violated: 1 conflicting context pair(s) with node memory, 5 node(s) had untolerated taint(s). no new claims to deallocate, preemption: 0/6 nodes are available: 1 No preemption victims found for incoming pod, 5 Preemption is not helpful for scheduling."
31.2225,Event,MODIFIED,eval-sanitize-1-r2-026-4lgk7.18d41fb7d84320c1,"reason=FailedScheduling count=None msg=0/6 nodes are available: 1 c_wall violated: 2 conflicting context pair(s) with node memory, 5 node(s) had untolerated taint(s). no new claims to deallocate, preemption: 0/6 nodes are available: 1 No preemption victims found for incoming pod, 5 Preemption is not helpful for scheduling."
31.2374,Node,MODIFIED,kind-worker3,taints=0
31.2519,Event,MODIFIED,eval-sanitize-1-r2-028-dp77l.18d41fb7d8749a72,"reason=FailedScheduling count=None msg=0/6 nodes are available: 1 c_wall violated: 1 conflicting context pair(s) with node memory, 5 node(s) had untolerated taint(s). no new claims to deallocate, preemption: 0/6 nodes are available: 1 No preemption victims found for incoming pod, 5 Preemption is not helpful for scheduling."
31.256,Event,MODIFIED,eval-sanitize-1-r2-029-gtlx7.18d41fb7d89e5b6d,"reason=FailedScheduling count=None msg=0/6 nodes are available: 1 c_wall violated: 1 conflicting context pair(s) with node memory, 5 node(s) had untolerated taint(s). no new claims to deallocate, preemption: 0/6 nodes are available: 1 No preemption victims found for incoming pod, 5 Preemption is not helpful for scheduling."
31.2903,Event,MODIFIED,eval-sanitize-1-r2-031-bbfkd.18d41fb7da54ff26,"reason=FailedScheduling count=None msg=0/6 nodes are available: 1 c_wall violated: 1 conflicting context pair(s) with node memory, 5 node(s) had untolerated taint(s). no new claims to deallocate, preemption: 0/6 nodes are available: 1 No preemption victims found for incoming pod, 5 Preemption is not helpful for scheduling."
31.3423,Node,MODIFIED,kind-worker,taints=1
31.4363,Node,MODIFIED,kind-worker,taints=1
31.4717,Event,ADDED,eval-sanitize-1-r2-021-mkjc6.18d41fb7eafcd996,"reason=Pulled count=1 msg=Container image ""busybox:musl"" already present on machine"
31.4827,Event,ADDED,eval-sanitize-1-r2-022-p9mtd.18d41fb7eba61576,"reason=Pulled count=1 msg=Container image ""busybox:musl"" already present on machine"
31.4867,Event,ADDED,eval-sanitize-1-r2-027-9rnn5.18d41fb7ebe4f43f,"reason=Pulled count=1 msg=Container image ""busybox:musl"" already present on machine"
31.5012,Event,ADDED,eval-sanitize-1-r2-021-mkjc6.18d41fb7ecb8f9de,reason=Created count=1 msg=Created container: task
31.5196,Event,ADDED,eval-sanitize-1-r2-022-p9mtd.18d41fb7edf14bde,reason=Created count=1 msg=Created container: task
31.5252,Event,ADDED,eval-sanitize-1-r2-027-9rnn5.18d41fb7ee4b1291,reason=Created count=1 msg=Created container: task
31.5734,Event,ADDED,eval-sanitize-1-r2-021-mkjc6.18d41fb7f10d5069,reason=Started count=1 msg=Started container task
31.5866,Event,ADDED,eval-sanitize-1-r2-027-9rnn5.18d41fb7f1d72fde,reason=Started count=1 msg=Started container task
31.593,Event,ADDED,eval-sanitize-1-r2-022-p9mtd.18d41fb7f1d78f03,reason=Started count=1 msg=Started container task
31.5966,Event,ADDED,eval-sanitize-1-r2-030-zdt9c.18d41fb7f25b8108,"reason=Pulled count=1 msg=Container image ""busybox:musl"" already present on machine"
31.6153,Event,ADDED,eval-sanitize-1-r2-030-zdt9c.18d41fb7f39eeda5,reason=Created count=1 msg=Created container: task
31.6631,Event,ADDED,eval-sanitize-1-r2-030-zdt9c.18d41fb7f65cdafc,reason=Started count=1 msg=Started container task
31.7452,Node,MODIFIED,kind-worker,taints=0
31.7543,Pod,MODIFIED,eval-sanitize-1-r2-029-gtlx7,phase=Pending node=kind-worker
31.7603,Pod,MODIFIED,eval-sanitize-1-r2-031-bbfkd,phase=Pending node=None
31.7607,Event,ADDED,eval-sanitize-1-r2-029-gtlx7.18d41fb7fc200067,reason=Scheduled count=None msg=Successfully assigned compute/eval-sanitize-1-r2-029-gtlx7 to kind-worker
31.7646,Node,MODIFIED,kind-worker,taints=0
31.7665,Pod,MODIFIED,eval-sanitize-1-r2-029-gtlx7,phase=Pending node=kind-worker
31.7706,Pod,MODIFIED,eval-sanitize-1-r2-023-9f62p,phase=Pending node=None
31.8183,Pod,MODIFIED,eval-sanitize-1-r2-026-4lgk7,phase=Pending node=kind-worker
31.8229,Event,ADDED,eval-sanitize-1-r2-026-4lgk7.18d41fb7fff486ae,reason=Scheduled count=None msg=Successfully assigned compute/eval-sanitize-1-r2-026-4lgk7 to kind-worker
31.8295,Node,MODIFIED,kind-worker,taints=0
31.831,Pod,MODIFIED,eval-sanitize-1-r2-026-4lgk7,phase=Pending node=kind-worker
31.8408,Node,MODIFIED,kind-worker,taints=0
31.8553,Pod,MODIFIED,eval-sanitize-1-r2-028-dp77l,phase=Pending node=kind-worker
31.8583,Event,ADDED,eval-sanitize-1-r2-031-bbfkd.18d41fb802241f27,"reason=FailedScheduling count=None msg=0/6 nodes are available: 2 c_wall violated: 1 conflicting context pair(s) with node memory, 4 node(s) had untolerated taint(s). no new claims to deallocate, preemption: 0/6 nodes are available: 2 No preemption victims found for incoming pod, 4 Preemption is not helpful for scheduling."
31.8604,Event,ADDED,eval-sanitize-1-r2-028-dp77l.18d41fb802262ae0,reason=Scheduled count=None msg=Successfully assigned compute/eval-sanitize-1-r2-028-dp77l to kind-worker
31.8646,Node,MODIFIED,kind-worker,taints=0
31.8656,Event,ADDED,eval-sanitize-1-r2-023-9f62p.18d41fb8027c65dd,"reason=FailedScheduling count=None msg=0/6 nodes are available: 2 c_wall violated: 1 conflicting context pair(s) with node memory, 4 node(s) had untolerated taint(s). no new claims to deallocate, preemption: 0/6 nodes are available: 2 No preemption victims found for incoming pod, 4 Preemption is not helpful for scheduling."
31.8669,Pod,MODIFIED,eval-sanitize-1-r2-028-dp77l,phase=Pending node=kind-worker
31.9374,Node,MODIFIED,kind-worker,taints=0
31.9527,Event,MODIFIED,eval-sanitize-1-r2-031-bbfkd.18d41fb802241f27,"reason=FailedScheduling count=None msg=0/6 nodes are available: 2 c_wall violated: 1 conflicting context pair(s) with node memory, 4 node(s) had untolerated taint(s). no new claims to deallocate, preemption: 0/6 nodes are available: 2 No preemption victims found for incoming pod, 4 Preemption is not helpful for scheduling."
31.9574,Event,MODIFIED,eval-sanitize-1-r2-023-9f62p.18d41fb8027c65dd,"reason=FailedScheduling count=None msg=0/6 nodes are available: 2 c_wall violated: 1 conflicting context pair(s) with node memory, 4 node(s) had untolerated taint(s). no new claims to deallocate, preemption: 0/6 nodes are available: 2 No preemption victims found for incoming pod, 4 Preemption is not helpful for scheduling."
32.0087,TaskRequest,ADDED,eval-sanitize-1-r2-032,phase=None job=None
32.0119,TaskRequest,MODIFIED,eval-sanitize-1-r2-032,phase=Pending job=None
32.027,Pod,MODIFIED,eval-sanitize-1-r2-022-p9mtd,phase=Running node=kind-worker3
32.0293,Job,ADDED,eval-sanitize-1-r2-032,
32.035,Pod,MODIFIED,eval-sanitize-1-r2-021-mkjc6,phase=Running node=kind-worker3
32.0367,TaskRequest,MODIFIED,eval-sanitize-1-r2-032,phase=Scheduled job=None
32.0376,Pod,ADDED,eval-sanitize-1-r2-032-2q5np,phase=Pending node=None
32.0392,Node,MODIFIED,kind-worker,taints=0
32.0405,Job,MODIFIED,eval-sanitize-1-r2-032,
32.0434,Pod,MODIFIED,eval-sanitize-1-r2-030-zdt9c,phase=Running node=kind-worker3
32.0441,Event,ADDED,eval-sanitize-1-r2-032.18d41fb80d02f440,reason=SuccessfulCreate count=1 msg=Created pod: eval-sanitize-1-r2-032-2q5np
32.0449,TaskRequest,MODIFIED,eval-sanitize-1-r2-032,phase=Scheduled job=None
32.0489,Job,MODIFIED,eval-sanitize-1-r2-031,
32.0512,Job,MODIFIED,eval-sanitize-1-r2-021,
32.0526,Pod,MODIFIED,eval-sanitize-1-r2-027-9rnn5,phase=Running node=kind-worker3
32.0582,Job,MODIFIED,eval-sanitize-1-r2-031,
32.0607,Job,MODIFIED,eval-sanitize-1-r2-030,
32.0615,Pod,MODIFIED,eval-sanitize-1-r2-032-2q5np,phase=Pending node=kind-worker3
32.0622,Job,MODIFIED,eval-sanitize-1-r2-022,
32.0629,Job,MODIFIED,eval-sanitize-1-r2-021,
32.0638,Job,MODIFIED,eval-sanitize-1-r2-027,
32.0671,Event,ADDED,eval-sanitize-1-r2-032-2q5np.18d41fb80e671f04,reason=Scheduled count=None msg=Successfully assigned compute/eval-sanitize-1-r2-032-2q5np to kind-worker3
32.0705,Job,MODIFIED,eval-sanitize-1-r2-030,
32.0741,Pod,MODIFIED,eval-sanitize-1-r2-032-2q5np,phase=Pending node=kind-worker3
32.1056,Job,MODIFIED,eval-sanitize-1-r2-022,
32.1381,Job,MODIFIED,eval-sanitize-1-r2-027,
32.1913,Job,MODIFIED,eval-sanitize-1-r2-018,
32.1967,Job,MODIFIED,eval-sanitize-1-r2-018,
32.2023,Event,ADDED,eval-sanitize-1-r2-018.18d41fb81682165b,reason=Completed count=1 msg=Job completed
32.2025,Event,ADDED,eval-sanitize-1-r2-029-gtlx7.18d41fb8169a57eb,"reason=Pulled count=1 msg=Container image ""busybox:musl"" already present on machine"
32.2094,Job,MODIFIED,eval-sanitize-1-r2-018,
32.2159,TaskRequest,MODIFIED,eval-sanitize-1-r2-018,phase=Complete job=None
32.2332,Job,MODIFIED,eval-sanitize-1-r2-018,
32.236,Event,ADDED,eval-sanitize-1-r2-029-gtlx7.18d41fb81885a27f,reason=Created count=1 msg=Created container: task
32.2445,Event,ADDED,eval-sanitize-1-r2-026-4lgk7.18d41fb819257236,"reason=Pulled count=1 msg=Container image ""busybox:musl"" already present on machine"
32.2602,Event,ADDED,eval-sanitize-1-r2-028-dp77l.18d41fb81a06f5e4,"reason=Pulled count=1 msg=Container image ""busybox:musl"" already present on machine"
32.2706,Event,ADDED,eval-sanitize-1-r2-026-4lgk7.18d41fb81ab65395,reason=Created count=1 msg=Created container: task
32.2766,Event,ADDED,eval-sanitize-1-r2-029-gtlx7.18d41fb81abb31a7,reason=Started count=1 msg=Started container task
32.2826,Event,ADDED,eval-sanitize-1-r2-028-dp77l.18d41fb81b6bd8c4,reason=Created count=1 msg=Created container: task
32.3045,Event,ADDED,eval-sanitize-1-r2-026-4lgk7.18d41fb81cac0b79,reason=Started count=1 msg=Started container task
32.3168,Event,ADDED,eval-sanitize-1-r2-028-dp77l.18d41fb81d5eae6c,reason=Started count=1 msg=Started container task
32.347,Node,MODIFIED,kind-worker4,taints=1
32.3495,Node,MODIFIED,kind-worker2,taints=1
32.4426,Node,MODIFIED,kind-worker4,taints=0
32.4546,Pod,MODIFIED,eval-sanitize-1-r2-023-9f62p,phase=Pending node=kind-worker4
32.4594,Event,ADDED,eval-sanitize-1-r2-023-9f62p.18d41fb825dbe44a,reason=Scheduled count=None msg=Successfully assigned compute/eval-sanitize-1-r2-023-9f62p to kind-worker4
32.4648,Node,MODIFIED,kind-worker4,taints=0
32.4666,Pod,MODIFIED,eval-sanitize-1-r2-031-bbfkd,phase=Pending node=kind-worker4
32.4687,Pod,MODIFIED,eval-sanitize-1-r2-023-9f62p,phase=Pending node=kind-worker4
32.4722,Event,ADDED,eval-sanitize-1-r2-031-bbfkd.18d41fb82695e575,reason=Scheduled count=None msg=Successfully assigned compute/eval-sanitize-1-r2-031-bbfkd to kind-worker4
32.4781,Node,MODIFIED,kind-worker4,taints=0
32.4829,Pod,MODIFIED,eval-sanitize-1-r2-031-bbfkd,phase=Pending node=kind-worker4
32.5006,Event,ADDED,eval-sanitize-1-r2-032-2q5np.18d41fb828654a23,"reason=Pulled count=1 msg=Container image ""busybox:musl"" already present on machine"
32.5168,Event,ADDED,eval-sanitize-1-r2-032-2q5np.18d41fb829683640,reason=Created count=1 msg=Created container: task
32.5422,Node,MODIFIED,kind-worker2,taints=1
32.5439,Node,MODIFIED,kind-worker4,taints=0
32.5513,Event,ADDED,eval-sanitize-1-r2-032-2q5np.18d41fb82b746c2e,reason=Started count=1 msg=Started container task
32.6235,Pod,MODIFIED,eval-sanitize-1-r2-026-4lgk7,phase=Running node=kind-worker
32.6312,Pod,MODIFIED,eval-sanitize-1-r2-028-dp77l,phase=Running node=kind-worker
32.6383,Pod,MODIFIED,eval-sanitize-1-r2-029-gtlx7,phase=Running node=kind-worker
32.6404,Node,MODIFIED,kind-worker4,taints=0
32.7452,Node,MODIFIED,kind-worker3,taints=1
32.8374,Node,MODIFIED,kind-worker3,taints=1
32.9233,Event,ADDED,eval-sanitize-1-r2-023-9f62p.18d41fb84182f31e,"reason=Pulled count=1 msg=Container image ""busybox:musl"" already present on machine"
32.9272,Event,ADDED,eval-sanitize-1-r2-031-bbfkd.18d41fb841c81372,"reason=Pulled count=1 msg=Container image ""busybox:musl"" already present on machine"
32.9405,Node,MODIFIED,kind-worker2,taints=0
32.9457,Event,ADDED,eval-sanitize-1-r2-023-9f62p.18d41fb842f1e105,reason=Created count=1 msg=Created container: task
32.9516,Event,ADDED,eval-sanitize-1-r2-031-bbfkd.18d41fb84348c3d9,reason=Created count=1 msg=Created container: task
32.9855,Event,ADDED,eval-sanitize-1-r2-023-9f62p.18d41fb845387f6a,reason=Started count=1 msg=Started container task
32.9889,Event,ADDED,eval-sanitize-1-r2-031-bbfkd.18d41fb845652623,reason=Started count=1 msg=Started container task
33.0062,TaskRequest,ADDED,eval-sanitize-1-r2-033,phase=None job=None
33.0097,TaskRequest,MODIFIED,eval-sanitize-1-r2-033,phase=Pending job=None
33.0252,Job,ADDED,eval-sanitize-1-r2-033,
33.03,TaskRequest,MODIFIED,eval-sanitize-1-r2-033,phase=Scheduled job=None
33.0334,Pod,ADDED,eval-sanitize-1-r2-033-jgr2l,phase=Pending node=None
33.0351,Node,MODIFIED,kind-worker2,taints=0
33.0381,Pod,MODIFIED,eval-sanitize-1-r2-032-2q5np,phase=Running node=kind-worker3
33.0388,Job,MODIFIED,eval-sanitize-1-r2-033,
33.0403,Event,ADDED,eval-sanitize-1-r2-033.18d41fb8485ecd86,reason=SuccessfulCreate count=1 msg=Created pod: eval-sanitize-1-r2-033-jgr2l
33.0404,TaskRequest,MODIFIED,eval-sanitize-1-r2-033,phase=Scheduled job=None
33.0426,Job,MODIFIED,eval-sanitize-1-r2-032,
33.0509,Job,MODIFIED,eval-sanitize-1-r2-032,
33.096,Pod,MODIFIED,eval-sanitize-1-r2-033-jgr2l,phase=Pending node=kind-worker2
33.0992,Event,ADDED,eval-sanitize-1-r2-033-jgr2l.18d41fb84c1ea644,reason=Scheduled count=None msg=Successfully assigned compute/eval-sanitize-1-r2-033-jgr2l to kind-worker2
33.1061,Pod,MODIFIED,eval-sanitize-1-r2-033-jgr2l,phase=Pending node=kind-worker2
33.1085,Node,MODIFIED,kind-worker2,taints=0
33.1361,Node,MODIFIED,kind-worker2,taints=0
33.2289,Node,MODIFIED,kind-worker,taints=1
33.3164,Node,MODIFIED,kind-worker,taints=1
33.5228,Event,ADDED,eval-sanitize-1-r2-033-jgr2l.18d41fb8654db9c1,"reason=Pulled count=1 msg=Container image ""busybox:musl"" already present on machine"
33.5399,Event,ADDED,eval-sanitize-1-r2-033-jgr2l.18d41fb8665ec20d,reason=Created count=1 msg=Created container: task
33.5729,Event,ADDED,eval-sanitize-1-r2-033-jgr2l.18d41fb86840c5d9,reason=Started count=1 msg=Started container task
33.6287,Job,MODIFIED,eval-sanitize-1-r2-026,
33.6348,Job,MODIFIED,eval-sanitize-1-r2-028,
33.6374,Job,MODIFIED,eval-sanitize-1-r2-026,
33.642,Job,MODIFIED,eval-sanitize-1-r2-029,
33.6435,Job,MODIFIED,eval-sanitize-1-r2-028,
33.6512,Job,MODIFIED,eval-sanitize-1-r2-029,
33.8237,Pod,MODIFIED,eval-sanitize-1-r2-023-9f62p,phase=Running node=kind-worker4
33.8298,Pod,MODIFIED,eval-sanitize-1-r2-031-bbfkd,phase=Running node=kind-worker4
33.9394,Node,MODIFIED,kind-worker4,taints=1
33.9511,Node,MODIFIED,kind-worker4,taints=1
34.0074,TaskRequest,ADDED,eval-sanitize-1-r2-034,phase=None job=None
34.0126,TaskRequest,MODIFIED,eval-sanitize-1-r2-034,phase=Pending job=None
34.0257,Job,ADDED,eval-sanitize-1-r2-034,
34.0316,TaskRequest,MODIFIED,eval-sanitize-1-r2-034,phase=Scheduled job=None
34.0345,Pod,ADDED,eval-sanitize-1-r2-034-k9rpq,phase=Pending node=None
34.0369,Job,MODIFIED,eval-sanitize-1-r2-034,
34.039,Job,MODIFIED,eval-sanitize-1-r2-033,
34.0405,Event,ADDED,eval-sanitize-1-r2-034.18d41fb88411a052,reason=SuccessfulCreate count=1 msg=Created pod: eval-sanitize-1-r2-034-k9rpq
34.0407,TaskRequest,MODIFIED,eval-sanitize-1-r2-034,phase=Scheduled job=None
34.043,Job,MODIFIED,eval-sanitize-1-r2-032,
34.0458,Pod,MODIFIED,eval-sanitize-1-r2-034-k9rpq,phase=Pending node=kind-worker2
34.0485,Job,MODIFIED,eval-sanitize-1-r2-033,
34.0489,Event,ADDED,eval-sanitize-1-r2-034-k9rpq.18d41fb884b62ca6,reason=Scheduled count=None msg=Successfully assigned compute/eval-sanitize-1-r2-034-k9rpq to kind-worker2
34.0523,Job,MODIFIED,eval-sanitize-1-r2-032,
34.0566,Node,MODIFIED,kind-worker2,taints=0
34.0584,Pod,MODIFIED,eval-sanitize-1-r2-034-k9rpq,phase=Pending node=kind-worker2
34.1364,Node,MODIFIED,kind-worker2,taints=0
34.1843,Pod,MODIFIED,eval-sanitize-1-r2-033-jgr2l,phase=Running node=kind-worker2
34.3312,Node,MODIFIED,kind-worker2,taints=1
34.4633,Event,ADDED,eval-sanitize-1-r2-034-k9rpq.18d41fb89d5b5978,"reason=Pulled count=1 msg=Container image ""busybox:musl"" already present on machine"
34.4827,Event,ADDED,eval-sanitize-1-r2-034-k9rpq.18d41fb89e6bea89,reason=Created count=1 msg=Created container: task
34.5584,Event,ADDED,eval-sanitize-1-r2-034-k9rpq.18d41fb8a30e44de,reason=Started count=1 msg=Started container task
34.7362,Node,MODIFIED,kind-worker2,taints=1
34.83,Job,MODIFIED,eval-sanitize-1-r2-023,
34.8337,Job,MODIFIED,eval-sanitize-1-r2-031,
34.8387,Job,MODIFIED,eval-sanitize-1-r2-023,
34.8416,Job,MODIFIED,eval-sanitize-1-r2-031,
35.008,TaskRequest,ADDED,eval-sanitize-1-r2-035,phase=None job=None
35.013,TaskRequest,MODIFIED,eval-sanitize-1-r2-035,phase=Pending job=None
35.0267,Job,ADDED,eval-sanitize-1-r2-035,
35.0334,Pod,ADDED,eval-sanitize-1-r2-035-cs7wf,phase=Pending node=None
35.0336,TaskRequest,MODIFIED,eval-sanitize-1-r2-035,phase=Scheduled job=None
35.0362,Job,MODIFIED,eval-sanitize-1-r2-035,
35.0404,Job,MODIFIED,eval-sanitize-1-r2-034,
35.0408,Event,ADDED,eval-sanitize-1-r2-035.18d41fb8bf9eae8c,reason=SuccessfulCreate count=1 msg=Created pod: eval-sanitize-1-r2-035-cs7wf
35.041,Event,ADDED,eval-sanitize-1-r2-035-cs7wf.18d41fb8bfa48c39,"reason=FailedScheduling count=None msg=0/6 nodes are available: 6 node(s) had untolerated taint(s). no new claims to deallocate, preemption: 0/6 nodes are available: 6 Preemption is not helpful for scheduling."
35.0418,Pod,MODIFIED,eval-sanitize-1-r2-035-cs7wf,phase=Pending node=None
35.0419,TaskRequest,MODIFIED,eval-sanitize-1-r2-035,phase=Scheduled job=None
35.0443,Job,MODIFIED,eval-sanitize-1-r2-033,
35.0486,Job,MODIFIED,eval-sanitize-1-r2-034,
35.0521,Job,MODIFIED,eval-sanitize-1-r2-033,
35.1872,Pod,MODIFIED,eval-sanitize-1-r2-034-k9rpq,phase=Running node=kind-worker2
36.0226,TaskRequest,ADDED,eval-sanitize-1-r2-036,phase=None job=None
36.0261,TaskRequest,MODIFIED,eval-sanitize-1-r2-036,phase=Pending job=None
36.039,Job,MODIFIED,eval-sanitize-1-r2-035,
36.0409,Job,ADDED,eval-sanitize-1-r2-036,
36.0452,Job,MODIFIED,eval-sanitize-1-r2-034,
36.048,Pod,ADDED,eval-sanitize-1-r2-036-9gqr8,phase=Pending node=None
36.0481,TaskRequest,MODIFIED,eval-sanitize-1-r2-036,phase=Scheduled job=None
36.0498,Job,MODIFIED,eval-sanitize-1-r2-036,
36.0561,Event,ADDED,eval-sanitize-1-r2-036.18d41fb8fc1bcc1b,reason=SuccessfulCreate count=1 msg=Created pod: eval-sanitize-1-r2-036-9gqr8
36.0562,TaskRequest,MODIFIED,eval-sanitize-1-r2-036,phase=Scheduled job=None
36.0565,Event,ADDED,eval-sanitize-1-r2-036-9gqr8.18d41fb8fc1bcc49,"reason=FailedScheduling count=None msg=0/6 nodes are available: 6 node(s) had untolerated taint(s). no new claims to deallocate, preemption: 0/6 nodes are available: 6 Preemption is not helpful for scheduling."
36.0573,Pod,MODIFIED,eval-sanitize-1-r2-036-9gqr8,phase=Pending node=None
36.0587,Job,MODIFIED,eval-sanitize-1-r2-035,
36.0593,Job,MODIFIED,eval-sanitize-1-r2-034,
37.0073,TaskRequest,ADDED,eval-sanitize-1-r2-037,phase=None job=None
37.0127,TaskRequest,MODIFIED,eval-sanitize-1-r2-037,phase=Pending job=None
37.0283,Job,ADDED,eval-sanitize-1-r2-037,
37.0334,TaskRequest,MODIFIED,eval-sanitize-1-r2-037,phase=Scheduled job=None
37.0363,Pod,ADDED,eval-sanitize-1-r2-037-mxbhp,phase=Pending node=None
37.0386,Job,MODIFIED,eval-sanitize-1-r2-037,
37.0443,Pod,MODIFIED,eval-sanitize-1-r2-037-mxbhp,phase=Pending node=None
37.0447,Event,ADDED,eval-sanitize-1-r2-037.18d41fb936fdbfe3,reason=SuccessfulCreate count=1 msg=Created pod: eval-sanitize-1-r2-037-mxbhp
37.045,Event,ADDED,eval-sanitize-1-r2-037-mxbhp.18d41fb937076735,"reason=FailedScheduling count=None msg=0/6 nodes are available: 6 node(s) had untolerated taint(s). no new claims to deallocate, preemption: 0/6 nodes are available: 6 Preemption is not helpful for scheduling."
37.0451,TaskRequest,MODIFIED,eval-sanitize-1-r2-037,phase=Scheduled job=None
37.0541,Job,MODIFIED,eval-sanitize-1-r2-036,
37.0628,Job,MODIFIED,eval-sanitize-1-r2-036,
37.5792,Pod,MODIFIED,eval-sanitize-1-r2-020-vzhm2,phase=Running node=kind-worker5
37.5863,Pod,MODIFIED,eval-sanitize-1-r2-024-49jtx,phase=Running node=kind-worker5
37.5923,Pod,MODIFIED,eval-sanitize-1-r2-025-2lqh8,phase=Running node=kind-worker5
37.5975,Pod,MODIFIED,eval-sanitize-1-r2-019-7bqxs,phase=Running node=kind-worker5
37.6037,Pod,MODIFIED,eval-sanitize-1-r2-017-w6mk9,phase=Running node=kind-worker5
38.0217,TaskRequest,ADDED,eval-sanitize-1-r2-038,phase=None job=None
38.027,TaskRequest,MODIFIED,eval-sanitize-1-r2-038,phase=Pending job=None
38.0424,Job,MODIFIED,eval-sanitize-1-r2-037,
38.0431,Job,ADDED,eval-sanitize-1-r2-038,
38.0497,Pod,ADDED,eval-sanitize-1-r2-038-pk954,phase=Pending node=None
38.0511,TaskRequest,MODIFIED,eval-sanitize-1-r2-038,phase=Scheduled job=None
38.0517,Job,MODIFIED,eval-sanitize-1-r2-038,
38.0559,Event,ADDED,eval-sanitize-1-r2-038.18d41fb973667779,reason=SuccessfulCreate count=1 msg=Created pod: eval-sanitize-1-r2-038-pk954
38.0561,Event,ADDED,eval-sanitize-1-r2-038-pk954.18d41fb973736b21,"reason=FailedScheduling count=None msg=0/6 nodes are available: 6 node(s) had untolerated taint(s). no new claims to deallocate, preemption: 0/6 nodes are available: 6 Preemption is not helpful for scheduling."
38.057,Pod,MODIFIED,eval-sanitize-1-r2-038-pk954,phase=Pending node=None
38.0596,TaskRequest,MODIFIED,eval-sanitize-1-r2-038,phase=Scheduled job=None
38.0624,Job,MODIFIED,eval-sanitize-1-r2-037,
38.5874,Job,MODIFIED,eval-sanitize-1-r2-020,
38.5927,Job,MODIFIED,eval-sanitize-1-r2-024,
38.5968,Job,MODIFIED,eval-sanitize-1-r2-025,
38.5992,Job,MODIFIED,eval-sanitize-1-r2-020,
38.6022,Job,MODIFIED,eval-sanitize-1-r2-024,
38.6041,Job,MODIFIED,eval-sanitize-1-r2-019,
38.6067,Job,MODIFIED,eval-sanitize-1-r2-025,
38.6094,Job,MODIFIED,eval-sanitize-1-r2-017,
38.6147,Job,MODIFIED,eval-sanitize-1-r2-019,
38.6185,Job,MODIFIED,eval-sanitize-1-r2-017,
38.7454,Pod,MODIFIED,eval-sanitize-1-r2-019-7bqxs,phase=Succeeded node=kind-worker5
38.7854,Pod,MODIFIED,eval-sanitize-1-r2-025-2lqh8,phase=Succeeded node=kind-worker5
38.7915,Pod,MODIFIED,eval-sanitize-1-r2-017-w6mk9,phase=Succeeded node=kind-worker5
38.7978,Pod,MODIFIED,eval-sanitize-1-r2-024-49jtx,phase=Succeeded node=kind-worker5
38.8034,Pod,MODIFIED,eval-sanitize-1-r2-020-vzhm2,phase=Succeeded node=kind-worker5
39.0085,TaskRequest,ADDED,eval-sanitize-1-r2-039,phase=None job=None
39.0135,TaskRequest,MODIFIED,eval-sanitize-1-r2-039,phase=Pending job=None
39.0286,Job,ADDED,eval-sanitize-1-r2-039,
39.0367,Pod,ADDED,eval-sanitize-1-r2-039-9fqnq,phase=Pending node=None
39.0368,TaskRequest,MODIFIED,eval-sanitize-1-r2-039,phase=Scheduled job=None
39.0387,Job,MODIFIED,eval-sanitize-1-r2-039,
39.043,Event,ADDED,eval-sanitize-1-r2-039.18d41fb9ae28d305,reason=SuccessfulCreate count=1 msg=Created pod: eval-sanitize-1-r2-039-9fqnq
39.0434,Event,ADDED,eval-sanitize-1-r2-039-9fqnq.18d41fb9ae3423f8,"reason=FailedScheduling count=None msg=0/6 nodes are available: 6 node(s) had untolerated taint(s). no new claims to deallocate, preemption: 0/6 nodes are available: 6 Preemption is not helpful for scheduling."
39.0445,Pod,MODIFIED,eval-sanitize-1-r2-039-9fqnq,phase=Pending node=None
39.0447,TaskRequest,MODIFIED,eval-sanitize-1-r2-039,phase=Scheduled job=None
39.0554,Job,MODIFIED,eval-sanitize-1-r2-038,
39.0649,Job,MODIFIED,eval-sanitize-1-r2-038,
39.5948,Job,MODIFIED,eval-sanitize-1-r2-020,
39.5973,Job,MODIFIED,eval-sanitize-1-r2-024,
39.6014,Job,MODIFIED,eval-sanitize-1-r2-025,
39.6057,Pod,MODIFIED,eval-sanitize-1-r2-020-vzhm2,phase=Succeeded node=kind-worker5
39.6074,Pod,MODIFIED,eval-sanitize-1-r2-024-49jtx,phase=Succeeded node=kind-worker5
39.6082,Job,MODIFIED,eval-sanitize-1-r2-020,
39.6092,Job,MODIFIED,eval-sanitize-1-r2-024,
39.6114,Pod,MODIFIED,eval-sanitize-1-r2-025-2lqh8,phase=Succeeded node=kind-worker5
39.6123,Job,MODIFIED,eval-sanitize-1-r2-019,
39.6134,Job,MODIFIED,eval-sanitize-1-r2-025,
39.6148,Job,MODIFIED,eval-sanitize-1-r2-017,
39.6198,Pod,MODIFIED,eval-sanitize-1-r2-019-7bqxs,phase=Succeeded node=kind-worker5
39.6211,Job,MODIFIED,eval-sanitize-1-r2-019,
39.6235,Pod,MODIFIED,eval-sanitize-1-r2-017-w6mk9,phase=Succeeded node=kind-worker5
39.6251,Job,MODIFIED,eval-sanitize-1-r2-017,
40.0075,TaskRequest,ADDED,eval-sanitize-1-r2-040,phase=None job=None
40.0114,TaskRequest,MODIFIED,eval-sanitize-1-r2-040,phase=Pending job=None
40.0282,Job,ADDED,eval-sanitize-1-r2-040,
40.0348,Pod,ADDED,eval-sanitize-1-r2-040-ztkxk,phase=Pending node=None
40.0349,TaskRequest,MODIFIED,eval-sanitize-1-r2-040,phase=Scheduled job=None
40.0379,Job,MODIFIED,eval-sanitize-1-r2-040,
40.0404,Pod,MODIFIED,eval-sanitize-1-r2-040-ztkxk,phase=Pending node=None
40.0412,Job,MODIFIED,eval-sanitize-1-r2-039,
40.0416,Event,ADDED,eval-sanitize-1-r2-040.18d41fb9e9b3e14a,reason=SuccessfulCreate count=1 msg=Created pod: eval-sanitize-1-r2-040-ztkxk
40.042,Event,ADDED,eval-sanitize-1-r2-040-ztkxk.18d41fb9e9c52632,"reason=FailedScheduling count=None msg=0/6 nodes are available: 6 node(s) had untolerated taint(s). no new claims to deallocate, preemption: 0/6 nodes are available: 6 Preemption is not helpful for scheduling."
40.0426,TaskRequest,MODIFIED,eval-sanitize-1-r2-040,phase=Scheduled job=None
40.0498,Job,MODIFIED,eval-sanitize-1-r2-039,
40.6042,Job,MODIFIED,eval-sanitize-1-r2-020,
40.6062,Job,MODIFIED,eval-sanitize-1-r2-024,
40.6069,Job,MODIFIED,eval-sanitize-1-r2-025,
40.6084,Job,MODIFIED,eval-sanitize-1-r2-020,
40.6108,Job,MODIFIED,eval-sanitize-1-r2-025,
40.6116,Job,MODIFIED,eval-sanitize-1-r2-024,
40.6134,Event,ADDED,eval-sanitize-1-r2-020.18d41fba0bec336c,reason=Completed count=1 msg=Job completed
40.6163,Job,MODIFIED,eval-sanitize-1-r2-019,
40.6199,Event,ADDED,eval-sanitize-1-r2-025.18d41fba0c0c00a1,reason=Completed count=1 msg=Job completed
40.6208,Job,MODIFIED,eval-sanitize-1-r2-020,
40.6216,Job,MODIFIED,eval-sanitize-1-r2-017,
40.6227,Job,MODIFIED,eval-sanitize-1-r2-019,
40.6238,Job,MODIFIED,eval-sanitize-1-r2-024,
40.6262,Event,ADDED,eval-sanitize-1-r2-024.18d41fba0c0cc424,reason=Completed count=1 msg=Job completed
40.6271,Job,MODIFIED,eval-sanitize-1-r2-017,
40.628,Job,MODIFIED,eval-sanitize-1-r2-025,
40.6287,TaskRequest,MODIFIED,eval-sanitize-1-r2-020,phase=Complete job=None
40.6319,Job,MODIFIED,eval-sanitize-1-r2-019,
40.6322,Event,ADDED,eval-sanitize-1-r2-019.18d41fba0ca3bb16,reason=Completed count=1 msg=Job completed
40.6345,TaskRequest,MODIFIED,eval-sanitize-1-r2-024,phase=Complete job=None
40.6352,Event,ADDED,eval-sanitize-1-r2-017.18d41fba0d036dbf,reason=Completed count=1 msg=Job completed
40.6389,Job,MODIFIED,eval-sanitize-1-r2-020,
40.6412,Job,MODIFIED,eval-sanitize-1-r2-017,
40.6985,TaskRequest,MODIFIED,eval-sanitize-1-r2-025,phase=Complete job=None
40.7036,TaskRequest,MODIFIED,eval-sanitize-1-r2-019,phase=Complete job=None
40.7065,Job,MODIFIED,eval-sanitize-1-r2-024,
40.7082,Job,MODIFIED,eval-sanitize-1-r2-025,
40.7084,TaskRequest,MODIFIED,eval-sanitize-1-r2-017,phase=Complete job=None
40.7127,Job,MODIFIED,eval-sanitize-1-r2-019,
40.7167,Job,MODIFIED,eval-sanitize-1-r2-017,
41.0088,TaskRequest,ADDED,eval-sanitize-1-r2-041,phase=None job=None
41.0125,TaskRequest,MODIFIED,eval-sanitize-1-r2-041,phase=Pending job=None
41.0289,Job,ADDED,eval-sanitize-1-r2-041,
41.0357,Pod,ADDED,eval-sanitize-1-r2-041-nbq6w,phase=Pending node=None
41.0359,TaskRequest,MODIFIED,eval-sanitize-1-r2-041,phase=Scheduled job=None
41.0401,Job,MODIFIED,eval-sanitize-1-r2-041,
41.0424,Event,ADDED,eval-sanitize-1-r2-041.18d41fba254f48c7,reason=SuccessfulCreate count=1 msg=Created pod: eval-sanitize-1-r2-041-nbq6w
41.0427,Event,ADDED,eval-sanitize-1-r2-041-nbq6w.18d41fba2554484c,"reason=FailedScheduling count=None msg=0/6 nodes are available: 6 node(s) had untolerated taint(s). no new claims to deallocate, preemption: 0/6 nodes are available: 6 Preemption is not helpful for scheduling."
41.0435,Job,MODIFIED,eval-sanitize-1-r2-040,
41.0444,Pod,MODIFIED,eval-sanitize-1-r2-041-nbq6w,phase=Pending node=None
41.0507,TaskRequest,MODIFIED,eval-sanitize-1-r2-041,phase=Scheduled job=None
41.0538,Job,MODIFIED,eval-sanitize-1-r2-040,
42.0098,TaskRequest,ADDED,eval-sanitize-1-r2-042,phase=None job=None
42.0152,TaskRequest,MODIFIED,eval-sanitize-1-r2-042,phase=Pending job=None
42.0294,Job,ADDED,eval-sanitize-1-r2-042,
42.0342,TaskRequest,MODIFIED,eval-sanitize-1-r2-042,phase=Scheduled job=None
42.0373,Pod,ADDED,eval-sanitize-1-r2-042-fhft6,phase=Pending node=None
42.0391,Job,MODIFIED,eval-sanitize-1-r2-042,
42.0421,Job,MODIFIED,eval-sanitize-1-r2-041,
42.0439,Event,ADDED,eval-sanitize-1-r2-042.18d41fba60fd12f8,reason=SuccessfulCreate count=1 msg=Created pod: eval-sanitize-1-r2-042-fhft6
42.0441,Event,ADDED,eval-sanitize-1-r2-042-fhft6.18d41fba6109c1c8,"reason=FailedScheduling count=None msg=0/6 nodes are available: 6 node(s) had untolerated taint(s). no new claims to deallocate, preemption: 0/6 nodes are available: 6 Preemption is not helpful for scheduling."
42.045,Pod,MODIFIED,eval-sanitize-1-r2-042-fhft6,phase=Pending node=None
42.0455,TaskRequest,MODIFIED,eval-sanitize-1-r2-042,phase=Scheduled job=None
42.0521,Pod,MODIFIED,eval-sanitize-1-r2-030-zdt9c,phase=Running node=kind-worker3
42.0528,Job,MODIFIED,eval-sanitize-1-r2-041,
42.0588,Pod,MODIFIED,eval-sanitize-1-r2-027-9rnn5,phase=Running node=kind-worker3
42.0658,Pod,MODIFIED,eval-sanitize-1-r2-021-mkjc6,phase=Running node=kind-worker3
42.0718,Pod,MODIFIED,eval-sanitize-1-r2-022-p9mtd,phase=Running node=kind-worker3
42.1426,Node,MODIFIED,kind-worker5,taints=1
42.1545,Node,MODIFIED,kind-worker5,taints=0
42.1595,Pod,MODIFIED,eval-sanitize-1-r2-035-cs7wf,phase=Pending node=kind-worker5
42.1627,Node,MODIFIED,kind-worker5,taints=0
42.1634,Event,ADDED,eval-sanitize-1-r2-035-cs7wf.18d41fba68444fad,reason=Scheduled count=None msg=Successfully assigned compute/eval-sanitize-1-r2-035-cs7wf to kind-worker5
42.1688,Pod,MODIFIED,eval-sanitize-1-r2-036-9gqr8,phase=Pending node=None
42.17,Event,ADDED,eval-sanitize-1-r2-036-9gqr8.18d41fba688d108e,"reason=FailedScheduling count=None msg=0/6 nodes are available: 1 c_wall violated: 1 conflicting context pair(s) with node memory, 5 node(s) had untolerated taint(s). no new claims to deallocate, preemption: 0/6 nodes are available: 1 No preemption victims found for incoming pod, 5 Preemption is not helpful for scheduling."
42.1716,Pod,MODIFIED,eval-sanitize-1-r2-035-cs7wf,phase=Pending node=kind-worker5
42.1769,Pod,MODIFIED,eval-sanitize-1-r2-037-mxbhp,phase=Pending node=kind-worker5
42.1799,Pod,MODIFIED,eval-sanitize-1-r2-038-pk954,phase=Pending node=None
42.1802,Event,ADDED,eval-sanitize-1-r2-038-pk954.18d41fba693510e3,"reason=FailedScheduling count=None msg=0/6 nodes are available: 1 c_wall violated: 1 conflicting context pair(s) with node memory, 5 node(s) had untolerated taint(s). no new claims to deallocate, preemption: 0/6 nodes are available: 1 No preemption victims found for incoming pod, 5 Preemption is not helpful for scheduling."
42.1826,Event,ADDED,eval-sanitize-1-r2-037-mxbhp.18d41fba694cbcbc,reason=Scheduled count=None msg=Successfully assigned compute/eval-sanitize-1-r2-037-mxbhp to kind-worker5
42.1888,Node,MODIFIED,kind-worker5,taints=0
42.1892,Event,ADDED,eval-sanitize-1-r2-039-9fqnq.18d41fba69b2f52c,"reason=FailedScheduling count=None msg=0/6 nodes are available: 1 c_wall violated: 1 conflicting context pair(s) with node memory, 5 node(s) had untolerated taint(s). no new claims to deallocate, preemption: 0/6 nodes are available: 1 No preemption victims found for incoming pod, 5 Preemption is not helpful for scheduling."
42.1902,Pod,MODIFIED,eval-sanitize-1-r2-039-9fqnq,phase=Pending node=None
42.1914,Pod,MODIFIED,eval-sanitize-1-r2-037-mxbhp,phase=Pending node=kind-worker5
42.1977,Pod,MODIFIED,eval-sanitize-1-r2-040-ztkxk,phase=Pending node=None
42.1979,Event,ADDED,eval-sanitize-1-r2-040-ztkxk.18d41fba6a452738,"reason=FailedScheduling count=None msg=0/6 nodes are available: 1 c_wall violated: 2 conflicting context pair(s) with node memory, 5 node(s) had untolerated taint(s). no new claims to deallocate, preemption: 0/6 nodes are available: 1 No preemption victims found for incoming pod, 5 Preemption is not helpful for scheduling."
42.2047,Pod,MODIFIED,eval-sanitize-1-r2-041-nbq6w,phase=Pending node=None
42.2051,Event,ADDED,eval-sanitize-1-r2-041-nbq6w.18d41fba6ab5b051,"reason=FailedScheduling count=None msg=0/6 nodes are available: 1 c_wall violated: 1 conflicting context pair(s) with node memory, 5 node(s) had untolerated taint(s). no new claims to deallocate, preemption: 0/6 nodes are available: 1 No preemption victims found for incoming pod, 5 Preemption is not helpful for scheduling."
42.215,Node,MODIFIED,kind-worker5,taints=0
42.2325,Node,MODIFIED,kind-worker5,taints=0
42.2425,Node,MODIFIED,kind-worker5,taints=0
42.2513,Pod,MODIFIED,eval-sanitize-1-r2-042-fhft6,phase=Pending node=None
42.2516,Event,ADDED,eval-sanitize-1-r2-042-fhft6.18d41fba6d7adf64,"reason=FailedScheduling count=None msg=0/6 nodes are available: 1 c_wall violated: 1 conflicting context pair(s) with node memory, 5 node(s) had untolerated taint(s). no new claims to deallocate, preemption: 0/6 nodes are available: 1 No preemption victims found for incoming pod, 5 Preemption is not helpful for scheduling."
42.2583,Pod,MODIFIED,eval-sanitize-1-r2-036-9gqr8,phase=Pending node=None
42.2585,Event,ADDED,eval-sanitize-1-r2-036-9gqr8.18d41fba6dede9ce,"reason=FailedScheduling count=None msg=0/6 nodes are available: 1 c_wall violated: 2 conflicting context pair(s) with node memory, 5 node(s) had untolerated taint(s). no new claims to deallocate, preemption: 0/6 nodes are available: 1 No preemption victims found for incoming pod, 5 Preemption is not helpful for scheduling."
42.2647,Event,ADDED,eval-sanitize-1-r2-038-pk954.18d41fba6e597394,"reason=FailedScheduling count=None msg=0/6 nodes are available: 1 c_wall violated: 1 conflicting context pair(s) with node memory, 5 node(s) had untolerated taint(s). no new claims to deallocate, preemption: 0/6 nodes are available: 1 No preemption victims found for incoming pod, 5 Preemption is not helpful for scheduling."
42.268,Event,ADDED,eval-sanitize-1-r2-039-9fqnq.18d41fba6e7eb81d,"reason=FailedScheduling count=None msg=0/6 nodes are available: 1 c_wall violated: 1 conflicting context pair(s) with node memory, 5 node(s) had untolerated taint(s). no new claims to deallocate, preemption: 0/6 nodes are available: 1 No preemption victims found for incoming pod, 5 Preemption is not helpful for scheduling."
42.2701,Event,ADDED,eval-sanitize-1-r2-040-ztkxk.18d41fba6eada202,"reason=FailedScheduling count=None msg=0/6 nodes are available: 1 c_wall violated: 2 conflicting context pair(s) with node memory, 5 node(s) had untolerated taint(s). no new claims to deallocate, preemption: 0/6 nodes are available: 1 No preemption victims found for incoming pod, 5 Preemption is not helpful for scheduling."
42.2896,Event,ADDED,eval-sanitize-1-r2-041-nbq6w.18d41fba6fd0a379,"reason=FailedScheduling count=None msg=0/6 nodes are available: 1 c_wall violated: 1 conflicting context pair(s) with node memory, 5 node(s) had untolerated taint(s). no new claims to deallocate, preemption: 0/6 nodes are available: 1 No preemption victims found for incoming pod, 5 Preemption is not helpful for scheduling."
42.293,Event,ADDED,eval-sanitize-1-r2-042-fhft6.18d41fba700086d1,"reason=FailedScheduling count=None msg=0/6 nodes are available: 1 c_wall violated: 1 conflicting context pair(s) with node memory, 5 node(s) had untolerated taint(s). no new claims to deallocate, preemption: 0/6 nodes are available: 1 No preemption victims found for incoming pod, 5 Preemption is not helpful for scheduling."
42.3222,Event,ADDED,eval-sanitize-1-r2-036-9gqr8.18d41fba71707c62,"reason=FailedScheduling count=None msg=0/6 nodes are available: 1 c_wall violated: 2 conflicting context pair(s) with node memory, 5 node(s) had untolerated taint(s). no new claims to deallocate, preemption: 0/6 nodes are available: 1 No preemption victims found for incoming pod, 5 Preemption is not helpful for scheduling."
42.5979,Event,ADDED,eval-sanitize-1-r2-035-cs7wf.18d41fba82282ad7,"reason=Pulled count=1 msg=Container image ""busybox:musl"" already present on machine"
42.6156,Event,ADDED,eval-sanitize-1-r2-035-cs7wf.18d41fba833f8c34,reason=Created count=1 msg=Created container: task
42.6497,Pod,MODIFIED,eval-sanitize-1-r2-026-4lgk7,phase=Running node=kind-worker
42.6501,Event,ADDED,eval-sanitize-1-r2-037-mxbhp.18d41fba84e330cf,"reason=Pulled count=1 msg=Container image ""busybox:musl"" already present on machine"
42.6565,Pod,MODIFIED,eval-sanitize-1-r2-029-gtlx7,phase=Running node=kind-worker
42.6568,Event,ADDED,eval-sanitize-1-r2-035-cs7wf.18d41fba856dc251,reason=Started count=1 msg=Started container task
42.6607,Event,MODIFIED,eval-sanitize-1-r2-038-pk954.18d41fba6e597394,"reason=FailedScheduling count=None msg=0/6 nodes are available: 1 c_wall violated: 1 conflicting context pair(s) with node memory, 5 node(s) had untolerated taint(s). no new claims to deallocate, preemption: 0/6 nodes are available: 1 No preemption victims found for incoming pod, 5 Preemption is not helpful for scheduling."
42.6646,Pod,MODIFIED,eval-sanitize-1-r2-028-dp77l,phase=Running node=kind-worker
42.665,Event,MODIFIED,eval-sanitize-1-r2-039-9fqnq.18d41fba6e7eb81d,"reason=FailedScheduling count=None msg=0/6 nodes are available: 1 c_wall violated: 1 conflicting context pair(s) with node memory, 5 node(s) had untolerated taint(s). no new claims to deallocate, preemption: 0/6 nodes are available: 1 No preemption victims found for incoming pod, 5 Preemption is not helpful for scheduling."
42.6695,Event,MODIFIED,eval-sanitize-1-r2-040-ztkxk.18d41fba6eada202,"reason=FailedScheduling count=None msg=0/6 nodes are available: 1 c_wall violated: 2 conflicting context pair(s) with node memory, 5 node(s) had untolerated taint(s). no new claims to deallocate, preemption: 0/6 nodes are available: 1 No preemption victims found for incoming pod, 5 Preemption is not helpful for scheduling."
42.6703,Event,MODIFIED,eval-sanitize-1-r2-041-nbq6w.18d41fba6fd0a379,"reason=FailedScheduling count=None msg=0/6 nodes are available: 1 c_wall violated: 1 conflicting context pair(s) with node memory, 5 node(s) had untolerated taint(s). no new claims to deallocate, preemption: 0/6 nodes are available: 1 No preemption victims found for incoming pod, 5 Preemption is not helpful for scheduling."
42.6705,Event,ADDED,eval-sanitize-1-r2-037-mxbhp.18d41fba867a430b,reason=Created count=1 msg=Created container: task
42.6728,Event,MODIFIED,eval-sanitize-1-r2-042-fhft6.18d41fba700086d1,"reason=FailedScheduling count=None msg=0/6 nodes are available: 1 c_wall violated: 1 conflicting context pair(s) with node memory, 5 node(s) had untolerated taint(s). no new claims to deallocate, preemption: 0/6 nodes are available: 1 No preemption victims found for incoming pod, 5 Preemption is not helpful for scheduling."
42.7474,Event,ADDED,eval-sanitize-1-r2-037-mxbhp.18d41fba8af82ffe,reason=Started count=1 msg=Started container task
42.7519,Event,MODIFIED,eval-sanitize-1-r2-036-9gqr8.18d41fba71707c62,"reason=FailedScheduling count=None msg=0/6 nodes are available: 1 c_wall violated: 2 conflicting context pair(s) with node memory, 5 node(s) had untolerated taint(s). no new claims to deallocate, preemption: 0/6 nodes are available: 1 No preemption victims found for incoming pod, 5 Preemption is not helpful for scheduling."
43.007,TaskRequest,ADDED,eval-sanitize-1-r2-043,phase=None job=None
43.0105,TaskRequest,MODIFIED,eval-sanitize-1-r2-043,phase=Pending job=None
43.0266,Job,ADDED,eval-sanitize-1-r2-043,
43.0313,TaskRequest,MODIFIED,eval-sanitize-1-r2-043,phase=Scheduled job=None
43.0335,Pod,ADDED,eval-sanitize-1-r2-043-jdhmk,phase=Pending node=None
43.0356,Job,MODIFIED,eval-sanitize-1-r2-043,
43.0397,Event,ADDED,eval-sanitize-1-r2-043.18d41fba9c5a4467,reason=SuccessfulCreate count=1 msg=Created pod: eval-sanitize-1-r2-043-jdhmk
43.0398,TaskRequest,MODIFIED,eval-sanitize-1-r2-043,phase=Scheduled job=None
43.0421,Job,MODIFIED,eval-sanitize-1-r2-042,
43.0435,Event,ADDED,eval-sanitize-1-r2-043-jdhmk.18d41fba9ca250f1,"reason=FailedScheduling count=None msg=0/6 nodes are available: 1 c_wall violated: 1 conflicting context pair(s) with node memory, 5 node(s) had untolerated taint(s). no new claims to deallocate, preemption: 0/6 nodes are available: 1 No preemption victims found for incoming pod, 5 Preemption is not helpful for scheduling."
43.0443,Pod,MODIFIED,eval-sanitize-1-r2-043-jdhmk,phase=Pending node=None
43.0513,Job,MODIFIED,eval-sanitize-1-r2-042,
43.0517,Event,ADDED,eval-sanitize-1-r2-043-jdhmk.18d41fba9d4086e0,"reason=FailedScheduling count=None msg=0/6 nodes are available: 1 c_wall violated: 1 conflicting context pair(s) with node memory, 5 node(s) had untolerated taint(s). no new claims to deallocate, preemption: 0/6 nodes are available: 1 No preemption victims found for incoming pod, 5 Preemption is not helpful for scheduling."
43.057,Job,MODIFIED,eval-sanitize-1-r2-030,
43.0605,Pod,MODIFIED,eval-sanitize-1-r2-032-2q5np,phase=Running node=kind-worker3
43.0634,Job,MODIFIED,eval-sanitize-1-r2-027,
43.0678,Job,MODIFIED,eval-sanitize-1-r2-030,
43.0711,Job,MODIFIED,eval-sanitize-1-r2-021,
43.0747,Job,MODIFIED,eval-sanitize-1-r2-027,
43.0765,Job,MODIFIED,eval-sanitize-1-r2-022,
43.1076,Job,MODIFIED,eval-sanitize-1-r2-021,
43.1096,Job,MODIFIED,eval-sanitize-1-r2-022,
43.1529,Event,MODIFIED,eval-sanitize-1-r2-043-jdhmk.18d41fba9d4086e0,"reason=FailedScheduling count=None msg=0/6 nodes are available: 1 c_wall violated: 1 conflicting context pair(s) with node memory, 5 node(s) had untolerated taint(s). no new claims to deallocate, preemption: 0/6 nodes are available: 1 No preemption victims found for incoming pod, 5 Preemption is not helpful for scheduling."
43.1898,Pod,MODIFIED,eval-sanitize-1-r2-021-mkjc6,phase=Succeeded node=kind-worker3
43.1968,Pod,MODIFIED,eval-sanitize-1-r2-027-9rnn5,phase=Succeeded node=kind-worker3
43.2031,Pod,MODIFIED,eval-sanitize-1-r2-030-zdt9c,phase=Succeeded node=kind-worker3
43.2227,Pod,MODIFIED,eval-sanitize-1-r2-022-p9mtd,phase=Succeeded node=kind-worker3
43.2399,Node,MODIFIED,kind-worker5,taints=1
43.253,Node,MODIFIED,kind-worker5,taints=1
43.2546,Pod,MODIFIED,eval-sanitize-1-r2-038-pk954,phase=Pending node=None
43.2594,Pod,MODIFIED,eval-sanitize-1-r2-039-9fqnq,phase=Pending node=None
43.2645,Pod,MODIFIED,eval-sanitize-1-r2-040-ztkxk,phase=Pending node=None
43.2695,Pod,MODIFIED,eval-sanitize-1-r2-041-nbq6w,phase=Pending node=None
43.2736,Pod,MODIFIED,eval-sanitize-1-r2-042-fhft6,phase=Pending node=None
43.2781,Pod,MODIFIED,eval-sanitize-1-r2-043-jdhmk,phase=Pending node=None
43.283,Pod,MODIFIED,eval-sanitize-1-r2-036-9gqr8,phase=Pending node=None
43.603,Pod,MODIFIED,eval-sanitize-1-r2-037-mxbhp,phase=Running node=kind-worker5
43.6082,Pod,MODIFIED,eval-sanitize-1-r2-035-cs7wf,phase=Running node=kind-worker5
43.6545,Job,MODIFIED,eval-sanitize-1-r2-026,
43.661,Job,MODIFIED,eval-sanitize-1-r2-029,
43.6635,Job,MODIFIED,eval-sanitize-1-r2-026,
43.6687,Job,MODIFIED,eval-sanitize-1-r2-028,
43.6703,Job,MODIFIED,eval-sanitize-1-r2-029,
43.6764,Job,MODIFIED,eval-sanitize-1-r2-028,
43.8443,Pod,MODIFIED,eval-sanitize-1-r2-031-bbfkd,phase=Running node=kind-worker4
43.851,Pod,MODIFIED,eval-sanitize-1-r2-023-9f62p,phase=Running node=kind-worker4
43.8645,Pod,MODIFIED,eval-sanitize-1-r2-028-dp77l,phase=Succeeded node=kind-worker
43.9953,Pod,MODIFIED,eval-sanitize-1-r2-026-4lgk7,phase=Succeeded node=kind-worker
44.0013,Pod,MODIFIED,eval-sanitize-1-r2-029-gtlx7,phase=Succeeded node=kind-worker
44.0088,TaskRequest,ADDED,eval-sanitize-1-r2-044,phase=None job=None
44.0123,TaskRequest,MODIFIED,eval-sanitize-1-r2-044,phase=Pending job=None
44.0273,Job,ADDED,eval-sanitize-1-r2-044,
44.0322,TaskRequest,MODIFIED,eval-sanitize-1-r2-044,phase=Scheduled job=None
44.0351,Pod,ADDED,eval-sanitize-1-r2-044-m2psh,phase=Pending node=None
44.0371,Job,MODIFIED,eval-sanitize-1-r2-044,
44.039,Job,MODIFIED,eval-sanitize-1-r2-043,
44.0408,Event,ADDED,eval-sanitize-1-r2-044.18d41fbad810927f,reason=SuccessfulCreate count=1 msg=Created pod: eval-sanitize-1-r2-044-m2psh
44.0411,Event,ADDED,eval-sanitize-1-r2-044-m2psh.18d41fbad81c2a73,"reason=FailedScheduling count=None msg=0/6 nodes are available: 6 node(s) had untolerated taint(s). no new claims to deallocate, preemption: 0/6 nodes are available: 6 Preemption is not helpful for scheduling."
44.0413,TaskRequest,MODIFIED,eval-sanitize-1-r2-044,phase=Scheduled job=None
44.0421,Pod,MODIFIED,eval-sanitize-1-r2-044-m2psh,phase=Pending node=None
44.0501,Job,MODIFIED,eval-sanitize-1-r2-043,
44.0619,Job,MODIFIED,eval-sanitize-1-r2-030,
44.064,Job,MODIFIED,eval-sanitize-1-r2-032,
44.0711,Job,MODIFIED,eval-sanitize-1-r2-027,
44.0726,Pod,MODIFIED,eval-sanitize-1-r2-030-zdt9c,phase=Succeeded node=kind-worker3
44.0737,Job,MODIFIED,eval-sanitize-1-r2-030,
44.0744,Job,MODIFIED,eval-sanitize-1-r2-032,
44.078,Job,MODIFIED,eval-sanitize-1-r2-021,
44.0814,Job,MODIFIED,eval-sanitize-1-r2-027,
44.0835,Pod,MODIFIED,eval-sanitize-1-r2-027-9rnn5,phase=Succeeded node=kind-worker3
44.0845,Job,MODIFIED,eval-sanitize-1-r2-022,
44.0891,Pod,MODIFIED,eval-sanitize-1-r2-021-mkjc6,phase=Succeeded node=kind-worker3
44.0899,Job,MODIFIED,eval-sanitize-1-r2-021,
44.0926,Pod,MODIFIED,eval-sanitize-1-r2-022-p9mtd,phase=Succeeded node=kind-worker3
44.0974,Job,MODIFIED,eval-sanitize-1-r2-022,
44.1008,Event,ADDED,eval-sanitize-1-r2-022.18d41fbadbb875fb,reason=Completed count=1 msg=Job completed
44.1415,Job,MODIFIED,eval-sanitize-1-r2-022,
44.1466,TaskRequest,MODIFIED,eval-sanitize-1-r2-022,phase=Complete job=None
44.1554,Job,MODIFIED,eval-sanitize-1-r2-022,
44.2021,Pod,MODIFIED,eval-sanitize-1-r2-033-jgr2l,phase=Running node=kind-worker2
44.2149,Pod,MODIFIED,eval-sanitize-1-r2-032-2q5np,phase=Succeeded node=kind-worker3
44.61,Job,MODIFIED,eval-sanitize-1-r2-037,
44.6128,Job,MODIFIED,eval-sanitize-1-r2-035,
44.6195,Job,MODIFIED,eval-sanitize-1-r2-037,
44.6218,Job,MODIFIED,eval-sanitize-1-r2-035,
44.6604,Job,MODIFIED,eval-sanitize-1-r2-026,
44.6659,Job,MODIFIED,eval-sanitize-1-r2-029,
44.6689,Pod,MODIFIED,eval-sanitize-1-r2-026-4lgk7,phase=Succeeded node=kind-worker
44.6701,Job,MODIFIED,eval-sanitize-1-r2-026,
44.6853,Pod,MODIFIED,eval-sanitize-1-r2-029-gtlx7,phase=Succeeded node=kind-worker
44.6882,Job,MODIFIED,eval-sanitize-1-r2-028,
44.6889,Job,MODIFIED,eval-sanitize-1-r2-029,
44.6966,Pod,MODIFIED,eval-sanitize-1-r2-028-dp77l,phase=Succeeded node=kind-worker
44.6986,Job,MODIFIED,eval-sanitize-1-r2-028,
44.735,Node,MODIFIED,kind-worker,taints=1
44.7499,Node,MODIFIED,kind-worker,taints=1
44.7577,Node,MODIFIED,kind-worker,taints=0
44.7633,Pod,MODIFIED,eval-sanitize-1-r2-038-pk954,phase=Pending node=kind-worker
44.7668,Pod,MODIFIED,eval-sanitize-1-r2-039-9fqnq,phase=Pending node=None
44.7671,Event,ADDED,eval-sanitize-1-r2-039-9fqnq.18d41fbb0363e0b0,"reason=FailedScheduling count=None msg=0/6 nodes are available: 1 c_wall violated: 1 conflicting context pair(s) with node memory, 5 node(s) had untolerated taint(s). no new claims to deallocate, preemption: 0/6 nodes are available: 1 No preemption victims found for incoming pod, 5 Preemption is not helpful for scheduling."
44.7673,Event,ADDED,eval-sanitize-1-r2-038-pk954.18d41fbb0376403a,reason=Scheduled count=None msg=Successfully assigned compute/eval-sanitize-1-r2-038-pk954 to kind-worker
44.7732,Pod,MODIFIED,eval-sanitize-1-r2-038-pk954,phase=Pending node=kind-worker
44.7755,Node,MODIFIED,kind-worker,taints=0
44.7761,Event,ADDED,eval-sanitize-1-r2-040-ztkxk.18d41fbb03ec80ed,"reason=FailedScheduling count=None msg=0/6 nodes are available: 1 c_wall violated: 1 conflicting context pair(s) with node memory, 5 node(s) had untolerated taint(s). no new claims to deallocate, preemption: 0/6 nodes are available: 1 No preemption victims found for incoming pod, 5 Preemption is not helpful for scheduling."
44.7768,Pod,MODIFIED,eval-sanitize-1-r2-040-ztkxk,phase=Pending node=None
44.786,Pod,MODIFIED,eval-sanitize-1-r2-041-nbq6w,phase=Pending node=None
44.787,Event,ADDED,eval-sanitize-1-r2-041-nbq6w.18d41fbb047d3284,"reason=FailedScheduling count=None msg=0/6 nodes are available: 1 c_wall violated: 1 conflicting context pair(s) with node memory, 5 node(s) had untolerated taint(s). no new claims to deallocate, preemption: 0/6 nodes are available: 1 No preemption victims found for incoming pod, 5 Preemption is not helpful for scheduling."
44.7929,Pod,MODIFIED,eval-sanitize-1-r2-042-fhft6,phase=Pending node=kind-worker
44.7985,Pod,MODIFIED,eval-sanitize-1-r2-043-jdhmk,phase=Pending node=kind-worker
44.8003,Event,ADDED,eval-sanitize-1-r2-042-fhft6.18d41fbb053de1ef,reason=Scheduled count=None msg=Successfully assigned compute/eval-sanitize-1-r2-042-fhft6 to kind-worker
44.8005,Event,ADDED,eval-sanitize-1-r2-036-9gqr8.18d41fbb055f172c,"reason=FailedScheduling count=None msg=0/6 nodes are available: 1 c_wall violated: 1 conflicting context pair(s) with node memory, 5 node(s) had untolerated taint(s). no new claims to deallocate, preemption: 0/6 nodes are available: 1 No preemption victims found for incoming pod, 5 Preemption is not helpful for scheduling."
44.8014,Pod,MODIFIED,eval-sanitize-1-r2-036-9gqr8,phase=Pending node=None
44.8026,Event,ADDED,eval-sanitize-1-r2-043-jdhmk.18d41fbb0595a351,reason=Scheduled count=None msg=Successfully assigned compute/eval-sanitize-1-r2-043-jdhmk to kind-worker
44.8068,Pod,MODIFIED,eval-sanitize-1-r2-042-fhft6,phase=Pending node=kind-worker
44.8125,Pod,MODIFIED,eval-sanitize-1-r2-043-jdhmk,phase=Pending node=kind-worker
44.8518,Job,MODIFIED,eval-sanitize-1-r2-031,
44.8527,Event,ADDED,eval-sanitize-1-r2-044-m2psh.18d41fbb08691559,"reason=FailedScheduling count=None msg=0/6 nodes are available: 1 c_wall violated: 1 conflicting context pair(s) with node memory, 5 node(s) had untolerated taint(s). no new claims to deallocate, preemption: 0/6 nodes are available: 1 No preemption victims found for incoming pod, 5 Preemption is not helpful for scheduling."
44.8538,Pod,MODIFIED,eval-sanitize-1-r2-044-m2psh,phase=Pending node=None
44.8558,Job,MODIFIED,eval-sanitize-1-r2-023,
44.8631,Job,MODIFIED,eval-sanitize-1-r2-031,
44.8634,Event,ADDED,eval-sanitize-1-r2-039-9fqnq.18d41fbb091ceb40,"reason=FailedScheduling count=None msg=0/6 nodes are available: 1 c_wall violated: 1 conflicting context pair(s) with node memory, 5 node(s) had untolerated taint(s). no new claims to deallocate, preemption: 0/6 nodes are available: 1 No preemption victims found for incoming pod, 5 Preemption is not helpful for scheduling."
44.8677,Job,MODIFIED,eval-sanitize-1-r2-023,
44.869,Event,ADDED,eval-sanitize-1-r2-040-ztkxk.18d41fbb09551f84,"reason=FailedScheduling count=None msg=0/6 nodes are available: 1 c_wall violated: 1 conflicting context pair(s) with node memory, 5 node(s) had untolerated taint(s). no new claims to deallocate, preemption: 0/6 nodes are available: 1 No preemption victims found for incoming pod, 5 Preemption is not helpful for scheduling."
44.8885,Event,ADDED,eval-sanitize-1-r2-041-nbq6w.18d41fbb09842783,"reason=FailedScheduling count=None msg=0/6 nodes are available: 1 c_wall violated: 1 conflicting context pair(s) with node memory, 5 node(s) had untolerated taint(s). no new claims to deallocate, preemption: 0/6 nodes are available: 1 No preemption victims found for incoming pod, 5 Preemption is not helpful for scheduling."
44.8891,Event,ADDED,eval-sanitize-1-r2-044-m2psh.18d41fbb0ac9c693,"reason=FailedScheduling count=None msg=0/6 nodes are available: 1 c_wall violated: 1 conflicting context pair(s) with node memory, 5 node(s) had untolerated taint(s). no new claims to deallocate, preemption: 0/6 nodes are available: 1 No preemption victims found for incoming pod, 5 Preemption is not helpful for scheduling."
44.8893,Event,ADDED,eval-sanitize-1-r2-036-9gqr8.18d41fbb09b0e2c0,"reason=FailedScheduling count=None msg=0/6 nodes are available: 1 c_wall violated: 1 conflicting context pair(s) with node memory, 5 node(s) had untolerated taint(s). no new claims to deallocate, preemption: 0/6 nodes are available: 1 No preemption victims found for incoming pod, 5 Preemption is not helpful for scheduling."
44.9349,Node,MODIFIED,kind-worker,taints=0
44.9487,Pod,MODIFIED,eval-sanitize-1-r2-023-9f62p,phase=Succeeded node=kind-worker4
44.9503,Node,MODIFIED,kind-worker,taints=0
44.9536,Event,MODIFIED,eval-sanitize-1-r2-039-9fqnq.18d41fbb091ceb40,"reason=FailedScheduling count=None msg=0/6 nodes are available: 1 c_wall violated: 1 conflicting context pair(s) with node memory, 5 node(s) had untolerated taint(s). no new claims to deallocate, preemption: 0/6 nodes are available: 1 No preemption victims found for incoming pod, 5 Preemption is not helpful for scheduling."
44.9544,Event,MODIFIED,eval-sanitize-1-r2-040-ztkxk.18d41fbb09551f84,"reason=FailedScheduling count=None msg=0/6 nodes are available: 1 c_wall violated: 1 conflicting context pair(s) with node memory, 5 node(s) had untolerated taint(s). no new claims to deallocate, preemption: 0/6 nodes are available: 1 No preemption victims found for incoming pod, 5 Preemption is not helpful for scheduling."
44.9573,Event,MODIFIED,eval-sanitize-1-r2-041-nbq6w.18d41fbb09842783,"reason=FailedScheduling count=None msg=0/6 nodes are available: 1 c_wall violated: 1 conflicting context pair(s) with node memory, 5 node(s) had untolerated taint(s). no new claims to deallocate, preemption: 0/6 nodes are available: 1 No preemption victims found for incoming pod, 5 Preemption is not helpful for scheduling."
44.9607,Event,MODIFIED,eval-sanitize-1-r2-036-9gqr8.18d41fbb09b0e2c0,"reason=FailedScheduling count=None msg=0/6 nodes are available: 1 c_wall violated: 1 conflicting context pair(s) with node memory, 5 node(s) had untolerated taint(s). no new claims to deallocate, preemption: 0/6 nodes are available: 1 No preemption victims found for incoming pod, 5 Preemption is not helpful for scheduling."
44.9639,Event,MODIFIED,eval-sanitize-1-r2-044-m2psh.18d41fbb0ac9c693,"reason=FailedScheduling count=None msg=0/6 nodes are available: 1 c_wall violated: 1 conflicting context pair(s) with node memory, 5 node(s) had untolerated taint(s). no new claims to deallocate, preemption: 0/6 nodes are available: 1 No preemption victims found for incoming pod, 5 Preemption is not helpful for scheduling."
44.9793,Pod,MODIFIED,eval-sanitize-1-r2-031-bbfkd,phase=Succeeded node=kind-worker4
45.0062,TaskRequest,ADDED,eval-sanitize-1-r2-045,phase=None job=None
45.0113,TaskRequest,MODIFIED,eval-sanitize-1-r2-045,phase=Pending job=None
45.0254,Job,ADDED,eval-sanitize-1-r2-045,
45.032,Pod,ADDED,eval-sanitize-1-r2-045-jvwch,phase=Pending node=None
45.033,TaskRequest,MODIFIED,eval-sanitize-1-r2-045,phase=Scheduled job=None
45.0357,Job,MODIFIED,eval-sanitize-1-r2-045,
45.036,Event,ADDED,eval-sanitize-1-r2-045.18d41fbb137c0b15,reason=SuccessfulCreate count=1 msg=Created pod: eval-sanitize-1-r2-045-jvwch
45.0396,Job,MODIFIED,eval-sanitize-1-r2-044,
45.0409,TaskRequest,MODIFIED,eval-sanitize-1-r2-045,phase=Scheduled job=None
45.0485,Job,MODIFIED,eval-sanitize-1-r2-044,
45.0539,Pod,MODIFIED,eval-sanitize-1-r2-045-jvwch,phase=Pending node=None
45.0542,Event,ADDED,eval-sanitize-1-r2-045-jvwch.18d41fbb14821e7d,"reason=FailedScheduling count=None msg=0/6 nodes are available: 1 c_wall violated: 1 conflicting context pair(s) with node memory, 5 node(s) had untolerated taint(s). no new claims to deallocate, preemption: 0/6 nodes are available: 1 No preemption victims found for incoming pod, 5 Preemption is not helpful for scheduling."
45.0686,Job,MODIFIED,eval-sanitize-1-r2-030,
45.0704,Job,MODIFIED,eval-sanitize-1-r2-032,
45.0728,Job,MODIFIED,eval-sanitize-1-r2-030,
45.0731,Event,ADDED,eval-sanitize-1-r2-045-jvwch.18d41fbb15a7bb8e,"reason=FailedScheduling count=None msg=0/6 nodes are available: 1 c_wall violated: 1 conflicting context pair(s) with node memory, 5 node(s) had untolerated taint(s). no new claims to deallocate, preemption: 0/6 nodes are available: 1 No preemption victims found for incoming pod, 5 Preemption is not helpful for scheduling."
45.0768,Job,MODIFIED,eval-sanitize-1-r2-027,
45.0794,Event,ADDED,eval-sanitize-1-r2-030.18d41fbb15ed1d5b,reason=Completed count=1 msg=Job completed
45.0809,Pod,MODIFIED,eval-sanitize-1-r2-032-2q5np,phase=Succeeded node=kind-worker3
45.084,Job,MODIFIED,eval-sanitize-1-r2-032,
45.0851,Job,MODIFIED,eval-sanitize-1-r2-027,
45.086,Job,MODIFIED,eval-sanitize-1-r2-021,
45.0885,Job,MODIFIED,eval-sanitize-1-r2-030,
45.0894,Event,ADDED,eval-sanitize-1-r2-027.18d41fbb168ffb9f,reason=Completed count=1 msg=Job completed
45.0934,Job,MODIFIED,eval-sanitize-1-r2-021,
45.0969,Event,ADDED,eval-sanitize-1-r2-021.18d41fbb17287dcf,reason=Completed count=1 msg=Job completed
45.1077,TaskRequest,MODIFIED,eval-sanitize-1-r2-030,phase=Complete job=None
45.1129,Job,MODIFIED,eval-sanitize-1-r2-027,
45.1138,Job,MODIFIED,eval-sanitize-1-r2-021,
45.1167,Job,MODIFIED,eval-sanitize-1-r2-030,
45.1203,TaskRequest,MODIFIED,eval-sanitize-1-r2-027,phase=Complete job=None
45.1318,Node,MODIFIED,kind-worker3,taints=1
45.1335,TaskRequest,MODIFIED,eval-sanitize-1-r2-021,phase=Complete job=None
45.1424,Job,MODIFIED,eval-sanitize-1-r2-027,
45.145,Job,MODIFIED,eval-sanitize-1-r2-021,
45.1487,Node,MODIFIED,kind-worker3,taints=0
45.1585,Node,MODIFIED,kind-worker3,taints=0
45.1599,Pod,MODIFIED,eval-sanitize-1-r2-039-9fqnq,phase=Pending node=kind-worker3
45.1643,Event,ADDED,eval-sanitize-1-r2-039-9fqnq.18d41fbb1b19c4bd,reason=Scheduled count=None msg=Successfully assigned compute/eval-sanitize-1-r2-039-9fqnq to kind-worker3
45.1709,Node,MODIFIED,kind-worker3,taints=0
45.1743,Pod,MODIFIED,eval-sanitize-1-r2-039-9fqnq,phase=Pending node=kind-worker3
45.1967,Event,ADDED,eval-sanitize-1-r2-038-pk954.18d41fbb1cfce9ac,"reason=Pulled count=1 msg=Container image ""busybox:musl"" already present on machine"
45.2079,Pod,MODIFIED,eval-sanitize-1-r2-034-k9rpq,phase=Running node=kind-worker2
45.209,Job,MODIFIED,eval-sanitize-1-r2-033,
45.2116,Event,ADDED,eval-sanitize-1-r2-042-fhft6.18d41fbb1de69e69,"reason=Pulled count=1 msg=Container image ""busybox:musl"" already present on machine"
45.2201,Job,MODIFIED,eval-sanitize-1-r2-033,
45.2246,Event,ADDED,eval-sanitize-1-r2-038-pk954.18d41fbb1e79a470,reason=Created count=1 msg=Created container: task
45.2263,Pod,MODIFIED,eval-sanitize-1-r2-040-ztkxk,phase=Pending node=kind-worker3
45.2297,Event,ADDED,eval-sanitize-1-r2-040-ztkxk.18d41fbb1efc38fe,reason=Scheduled count=None msg=Successfully assigned compute/eval-sanitize-1-r2-040-ztkxk to kind-worker3
45.2392,Node,MODIFIED,kind-worker3,taints=0
45.2413,Pod,MODIFIED,eval-sanitize-1-r2-040-ztkxk,phase=Pending node=kind-worker3
45.2417,Event,ADDED,eval-sanitize-1-r2-042-fhft6.18d41fbb1fa3b8f4,reason=Created count=1 msg=Created container: task
45.2462,Event,ADDED,eval-sanitize-1-r2-043-jdhmk.18d41fbb1fb001bc,"reason=Pulled count=1 msg=Container image ""busybox:musl"" already present on machine"
45.2507,Node,MODIFIED,kind-worker3,taints=0
45.2578,Pod,MODIFIED,eval-sanitize-1-r2-045-jvwch,phase=Pending node=None
45.2581,Event,MODIFIED,eval-sanitize-1-r2-045-jvwch.18d41fbb15a7bb8e,"reason=FailedScheduling count=None msg=0/6 nodes are available: 1 c_wall violated: 1 conflicting context pair(s) with node memory, 5 node(s) had untolerated taint(s). no new claims to deallocate, preemption: 0/6 nodes are available: 1 No preemption victims found for incoming pod, 5 Preemption is not helpful for scheduling."
45.2653,Event,ADDED,eval-sanitize-1-r2-043-jdhmk.18d41fbb212b702b,reason=Created count=1 msg=Created container: task
45.2701,Pod,MODIFIED,eval-sanitize-1-r2-041-nbq6w,phase=Pending node=None
45.3064,Event,ADDED,eval-sanitize-1-r2-043-jdhmk.18d41fbb2381fd9f,reason=Started count=1 msg=Started container task
45.317,Pod,MODIFIED,eval-sanitize-1-r2-033-jgr2l,phase=Succeeded node=kind-worker2
45.3188,Pod,MODIFIED,eval-sanitize-1-r2-036-9gqr8,phase=Pending node=kind-worker3
45.3196,Event,ADDED,eval-sanitize-1-r2-042-fhft6.18d41fbb2457bd61,reason=Started count=1 msg=Started container task
45.3231,Event,ADDED,eval-sanitize-1-r2-036-9gqr8.18d41fbb24951795,reason=Scheduled count=None msg=Successfully assigned compute/eval-sanitize-1-r2-036-9gqr8 to kind-worker3
45.324,Event,ADDED,eval-sanitize-1-r2-038-pk954.18d41fbb2457bd65,reason=Started count=1 msg=Started container task
45.3304,Pod,MODIFIED,eval-sanitize-1-r2-036-9gqr8,phase=Pending node=kind-worker3
45.3472,Node,MODIFIED,kind-worker3,taints=0
45.3558,Pod,MODIFIED,eval-sanitize-1-r2-044-m2psh,phase=Pending node=kind-worker3
45.3593,Event,ADDED,eval-sanitize-1-r2-044-m2psh.18d41fbb26c5d443,reason=Scheduled count=None msg=Successfully assigned compute/eval-sanitize-1-r2-044-m2psh to kind-worker3
45.3614,Event,ADDED,eval-sanitize-1-r2-045-jvwch.18d41fbb26d7f91d,"reason=FailedScheduling count=None msg=0/6 nodes are available: 2 c_wall violated: 1 conflicting context pair(s) with node memory, 4 node(s) had untolerated taint(s). no new claims to deallocate, preemption: 0/6 nodes are available: 2 No preemption victims found for incoming pod, 4 Preemption is not helpful for scheduling."
45.3672,Pod,MODIFIED,eval-sanitize-1-r2-044-m2psh,phase=Pending node=kind-worker3
45.4175,Event,ADDED,eval-sanitize-1-r2-041-nbq6w.18d41fbb2a3b5220,"reason=FailedScheduling count=None msg=0/6 nodes are available: 2 c_wall violated: 1 conflicting context pair(s) with node memory, 4 node(s) had untolerated taint(s). no new claims to deallocate, preemption: 0/6 nodes are available: 2 No preemption victims found for incoming pod, 4 Preemption is not helpful for scheduling."
45.4546,Event,MODIFIED,eval-sanitize-1-r2-045-jvwch.18d41fbb26d7f91d,"reason=FailedScheduling count=None msg=0/6 nodes are available: 2 c_wall violated: 1 conflicting context pair(s) with node memory, 4 node(s) had untolerated taint(s). no new claims to deallocate, preemption: 0/6 nodes are available: 2 No preemption victims found for incoming pod, 4 Preemption is not helpful for scheduling."
45.5663,Event,MODIFIED,eval-sanitize-1-r2-041-nbq6w.18d41fbb2a3b5220,"reason=FailedScheduling count=None msg=0/6 nodes are available: 2 c_wall violated: 1 conflicting context pair(s) with node memory, 4 node(s) had untolerated taint(s). no new claims to deallocate, preemption: 0/6 nodes are available: 2 No preemption victims found for incoming pod, 4 Preemption is not helpful for scheduling."
45.5936,Event,ADDED,eval-sanitize-1-r2-039-9fqnq.18d41fbb34b86ace,"reason=Pulled count=1 msg=Container image ""busybox:musl"" already present on machine"
45.6125,Event,ADDED,eval-sanitize-1-r2-039-9fqnq.18d41fbb35d9c491,reason=Created count=1 msg=Created container: task
45.6332,Event,ADDED,eval-sanitize-1-r2-040-ztkxk.18d41fbb37152b64,"reason=Pulled count=1 msg=Container image ""busybox:musl"" already present on machine"
45.6481,Event,ADDED,eval-sanitize-1-r2-039-9fqnq.18d41fbb37e16d9c,reason=Started count=1 msg=Started container task
45.6565,Event,ADDED,eval-sanitize-1-r2-040-ztkxk.18d41fbb387927ba,reason=Created count=1 msg=Created container: task
45.6604,Pod,MODIFIED,eval-sanitize-1-r2-038-pk954,phase=Running node=kind-worker
45.667,Job,MODIFIED,eval-sanitize-1-r2-026,
45.6714,Pod,MODIFIED,eval-sanitize-1-r2-042-fhft6,phase=Running node=kind-worker
45.6737,Job,MODIFIED,eval-sanitize-1-r2-029,
45.6746,Job,MODIFIED,eval-sanitize-1-r2-026,
45.6795,Event,ADDED,eval-sanitize-1-r2-026.18d41fbb39c05166,reason=Completed count=1 msg=Job completed
45.681,Pod,MODIFIED,eval-sanitize-1-r2-043-jdhmk,phase=Running node=kind-worker
45.6819,Job,MODIFIED,eval-sanitize-1-r2-029,
45.6857,Job,MODIFIED,eval-sanitize-1-r2-026,
45.686,Event,ADDED,eval-sanitize-1-r2-029.18d41fbb3a1e5363,reason=Completed count=1 msg=Job completed
45.6905,Job,MODIFIED,eval-sanitize-1-r2-029,
45.691,TaskRequest,MODIFIED,eval-sanitize-1-r2-026,phase=Complete job=None
45.6937,Job,MODIFIED,eval-sanitize-1-r2-028,
45.6984,Job,MODIFIED,eval-sanitize-1-r2-028,
45.7011,TaskRequest,MODIFIED,eval-sanitize-1-r2-029,phase=Complete job=None
45.7023,Event,ADDED,eval-sanitize-1-r2-028.18d41fbb3b395fcb,reason=Completed count=1 msg=Job completed
45.7058,Job,MODIFIED,eval-sanitize-1-r2-026,
45.7138,Job,MODIFIED,eval-sanitize-1-r2-029,
45.7156,Job,MODIFIED,eval-sanitize-1-r2-028,
45.7167,Event,ADDED,eval-sanitize-1-r2-040-ztkxk.18d41fbb3bf027fe,reason=Started count=1 msg=Started container task
45.7355,TaskRequest,MODIFIED,eval-sanitize-1-r2-028,phase=Complete job=None
45.7364,Event,ADDED,eval-sanitize-1-r2-036-9gqr8.18d41fbb3d3f0d60,"reason=Pulled count=1 msg=Container image ""busybox:musl"" already present on machine"
45.7454,Job,MODIFIED,eval-sanitize-1-r2-028,
45.757,Event,ADDED,eval-sanitize-1-r2-036-9gqr8.18d41fbb3e787780,reason=Created count=1 msg=Created container: task
45.7614,Event,ADDED,eval-sanitize-1-r2-044-m2psh.18d41fbb3eb828e5,"reason=Pulled count=1 msg=Container image ""busybox:musl"" already present on machine"
45.769,Job,MODIFIED,eval-sanitize-1-r2-038,
45.7781,Job,MODIFIED,eval-sanitize-1-r2-038,
45.7801,Event,ADDED,eval-sanitize-1-r2-044-m2psh.18d41fbb3fde9b42,reason=Created count=1 msg=Created container: task
45.7936,Event,ADDED,eval-sanitize-1-r2-036-9gqr8.18d41fbb40a5e4ed,reason=Started count=1 msg=Started container task
45.7978,Job,MODIFIED,eval-sanitize-1-r2-042,
45.8068,Job,MODIFIED,eval-sanitize-1-r2-042,
45.8152,Event,ADDED,eval-sanitize-1-r2-044-m2psh.18d41fbb41e97f94,reason=Started count=1 msg=Started container task
45.8576,Job,MODIFIED,eval-sanitize-1-r2-031,
45.8616,Job,MODIFIED,eval-sanitize-1-r2-023,
45.8657,Pod,MODIFIED,eval-sanitize-1-r2-031-bbfkd,phase=Succeeded node=kind-worker4
45.8679,Job,MODIFIED,eval-sanitize-1-r2-031,
45.8702,Pod,MODIFIED,eval-sanitize-1-r2-023-9f62p,phase=Succeeded node=kind-worker4
45.8719,Job,MODIFIED,eval-sanitize-1-r2-023,
45.9476,Node,MODIFIED,kind-worker,taints=1
45.9557,Pod,MODIFIED,eval-sanitize-1-r2-041-nbq6w,phase=Pending node=None
45.9629,Pod,MODIFIED,eval-sanitize-1-r2-045-jvwch,phase=Pending node=None
45.9689,Event,ADDED,eval-sanitize-1-r2-041-nbq6w.18d41fbb4b283041,"reason=FailedScheduling count=None msg=0/6 nodes are available: 1 c_wall violated: 1 conflicting context pair(s) with node memory, 5 node(s) had untolerated taint(s). no new claims to deallocate, preemption: 0/6 nodes are available: 1 No preemption victims found for incoming pod, 5 Preemption is not helpful for scheduling."
45.9709,Event,ADDED,eval-sanitize-1-r2-045-jvwch.18d41fbb4b4d8766,"reason=FailedScheduling count=None msg=0/6 nodes are available: 1 c_wall violated: 1 conflicting context pair(s) with node memory, 5 node(s) had untolerated taint(s). no new claims to deallocate, preemption: 0/6 nodes are available: 1 No preemption victims found for incoming pod, 5 Preemption is not helpful for scheduling."
46.0071,TaskRequest,ADDED,eval-sanitize-1-r2-046,phase=None job=None
46.0117,TaskRequest,MODIFIED,eval-sanitize-1-r2-046,phase=Pending job=None
46.0253,Job,ADDED,eval-sanitize-1-r2-046,
46.032,Pod,ADDED,eval-sanitize-1-r2-046-9tgn4,phase=Pending node=None
46.0337,TaskRequest,MODIFIED,eval-sanitize-1-r2-046,phase=Scheduled job=None
46.0366,Job,MODIFIED,eval-sanitize-1-r2-046,
46.0369,Event,ADDED,eval-sanitize-1-r2-046.18d41fbb4f19a834,reason=SuccessfulCreate count=1 msg=Created pod: eval-sanitize-1-r2-046-9tgn4
46.0377,Job,MODIFIED,eval-sanitize-1-r2-045,
46.0424,Pod,MODIFIED,eval-sanitize-1-r2-046-9tgn4,phase=Pending node=None
46.0429,Event,ADDED,eval-sanitize-1-r2-046-9tgn4.18d41fbb4f571505,"reason=FailedScheduling count=None msg=0/6 nodes are available: 1 c_wall violated: 2 conflicting context pair(s) with node memory, 5 node(s) had untolerated taint(s). no new claims to deallocate, preemption: 0/6 nodes are available: 1 No preemption victims found for incoming pod, 5 Preemption is not helpful for scheduling."
46.0431,TaskRequest,MODIFIED,eval-sanitize-1-r2-046,phase=Scheduled job=None
46.0462,Job,MODIFIED,eval-sanitize-1-r2-045,
46.05,Event,ADDED,eval-sanitize-1-r2-046-9tgn4.18d41fbb4ff73e73,"reason=FailedScheduling count=None msg=0/6 nodes are available: 1 c_wall violated: 2 conflicting context pair(s) with node memory, 5 node(s) had untolerated taint(s). no new claims to deallocate, preemption: 0/6 nodes are available: 1 No preemption victims found for incoming pod, 5 Preemption is not helpful for scheduling."
46.0805,Pod,MODIFIED,eval-sanitize-1-r2-036-9gqr8,phase=Running node=kind-worker3
46.0815,Job,MODIFIED,eval-sanitize-1-r2-032,
46.0861,Job,MODIFIED,eval-sanitize-1-r2-032,
46.0899,Pod,MODIFIED,eval-sanitize-1-r2-044-m2psh,phase=Running node=kind-worker3
46.0913,Event,MODIFIED,eval-sanitize-1-r2-041-nbq6w.18d41fbb4b283041,"reason=FailedScheduling count=None msg=0/6 nodes are available: 1 c_wall violated: 1 conflicting context pair(s) with node memory, 5 node(s) had untolerated taint(s). no new claims to deallocate, preemption: 0/6 nodes are available: 1 No preemption victims found for incoming pod, 5 Preemption is not helpful for scheduling."
46.0933,Event,MODIFIED,eval-sanitize-1-r2-045-jvwch.18d41fbb4b4d8766,"reason=FailedScheduling count=None msg=0/6 nodes are available: 1 c_wall violated: 1 conflicting context pair(s) with node memory, 5 node(s) had untolerated taint(s). no new claims to deallocate, preemption: 0/6 nodes are available: 1 No preemption victims found for incoming pod, 5 Preemption is not helpful for scheduling."
46.0944,Event,MODIFIED,eval-sanitize-1-r2-046-9tgn4.18d41fbb4ff73e73,"reason=FailedScheduling count=None msg=0/6 nodes are available: 1 c_wall violated: 2 conflicting context pair(s) with node memory, 5 node(s) had untolerated taint(s). no new claims to deallocate, preemption: 0/6 nodes are available: 1 No preemption victims found for incoming pod, 5 Preemption is not helpful for scheduling."
46.0981,Pod,MODIFIED,eval-sanitize-1-r2-039-9fqnq,phase=Running node=kind-worker3
46.0992,Job,MODIFIED,eval-sanitize-1-r2-032,
46.1049,Pod,MODIFIED,eval-sanitize-1-r2-040-ztkxk,phase=Running node=kind-worker3
46.1057,TaskRequest,MODIFIED,eval-sanitize-1-r2-032,phase=Complete job=None
46.1149,Job,MODIFIED,eval-sanitize-1-r2-032,
46.1334,Event,ADDED,eval-sanitize-1-r2-032.18d41fbb5252792a,reason=Completed count=1 msg=Job completed
46.2136,Node,MODIFIED,kind-worker,taints=1
46.2147,Job,MODIFIED,eval-sanitize-1-r2-034,
46.2294,Job,MODIFIED,eval-sanitize-1-r2-034,
46.2335,Job,MODIFIED,eval-sanitize-1-r2-033,
46.2363,Node,MODIFIED,kind-worker4,taints=1
46.2449,Job,MODIFIED,eval-sanitize-1-r2-033,
46.2887,Pod,MODIFIED,eval-sanitize-1-r2-033-jgr2l,phase=Succeeded node=kind-worker2
46.3378,Node,MODIFIED,kind-worker4,taints=1
46.4039,Pod,MODIFIED,eval-sanitize-1-r2-034-k9rpq,phase=Succeeded node=kind-worker2
46.6868,Job,MODIFIED,eval-sanitize-1-r2-043,
46.6953,Job,MODIFIED,eval-sanitize-1-r2-043,
46.7293,Node,MODIFIED,kind-worker4,taints=0
46.7387,Pod,MODIFIED,eval-sanitize-1-r2-045-jvwch,phase=Pending node=kind-worker4
46.7444,Pod,MODIFIED,eval-sanitize-1-r2-046-9tgn4,phase=Pending node=None
46.7447,Event,ADDED,eval-sanitize-1-r2-045-jvwch.18d41fbb7932550b,reason=Scheduled count=None msg=Successfully assigned compute/eval-sanitize-1-r2-045-jvwch to kind-worker4
46.7499,Pod,MODIFIED,eval-sanitize-1-r2-045-jvwch,phase=Pending node=kind-worker4
46.7512,Node,MODIFIED,kind-worker4,taints=0
46.756,Pod,MODIFIED,eval-sanitize-1-r2-041-nbq6w,phase=Pending node=kind-worker4
46.7606,Event,ADDED,eval-sanitize-1-r2-046-9tgn4.18d41fbb7a3fd277,"reason=FailedScheduling count=None msg=0/6 nodes are available: 1 c_wall violated: 1 conflicting context pair(s) with node memory, 1 c_wall violated: 2 conflicting context pair(s) with node memory, 4 node(s) had untolerated taint(s). no new claims to deallocate, preemption: 0/6 nodes are available: 2 No preemption victims found for incoming pod, 4 Preemption is not helpful for scheduling."
46.7612,Event,ADDED,eval-sanitize-1-r2-041-nbq6w.18d41fbb7a4368bf,reason=Scheduled count=None msg=Successfully assigned compute/eval-sanitize-1-r2-041-nbq6w to kind-worker4
46.7661,Pod,MODIFIED,eval-sanitize-1-r2-041-nbq6w,phase=Pending node=kind-worker4
46.8124,Node,MODIFIED,kind-worker4,taints=0
46.822,Event,MODIFIED,eval-sanitize-1-r2-046-9tgn4.18d41fbb7a3fd277,"reason=FailedScheduling count=None msg=0/6 nodes are available: 1 c_wall violated: 1 conflicting context pair(s) with node memory, 1 c_wall violated: 2 conflicting context pair(s) with node memory, 4 node(s) had untolerated taint(s). no new claims to deallocate, preemption: 0/6 nodes are available: 2 No preemption victims found for incoming pod, 4 Preemption is not helpful for scheduling."
46.8289,Node,MODIFIED,kind-worker3,taints=1
46.8387,Node,MODIFIED,kind-worker4,taints=0
46.8457,Node,MODIFIED,kind-worker3,taints=1
46.8525,Pod,MODIFIED,eval-sanitize-1-r2-046-9tgn4,phase=Pending node=None
46.8596,Event,ADDED,eval-sanitize-1-r2-046-9tgn4.18d41fbb802ec5f0,"reason=FailedScheduling count=None msg=0/6 nodes are available: 1 c_wall violated: 1 conflicting context pair(s) with node memory, 5 node(s) had untolerated taint(s). no new claims to deallocate, preemption: 0/6 nodes are available: 1 No preemption victims found for incoming pod, 5 Preemption is not helpful for scheduling."
46.8622,Job,MODIFIED,eval-sanitize-1-r2-031,
46.8654,Job,MODIFIED,eval-sanitize-1-r2-023,
46.8672,Job,MODIFIED,eval-sanitize-1-r2-031,
46.8694,Job,MODIFIED,eval-sanitize-1-r2-023,
46.8714,Event,ADDED,eval-sanitize-1-r2-031.18d41fbb80e863ba,reason=Completed count=1 msg=Job completed
46.8755,Event,ADDED,eval-sanitize-1-r2-023.18d41fbb8109d85e,reason=Completed count=1 msg=Job completed
46.878,Job,MODIFIED,eval-sanitize-1-r2-031,
46.8814,Job,MODIFIED,eval-sanitize-1-r2-023,
46.8821,TaskRequest,MODIFIED,eval-sanitize-1-r2-031,phase=Complete job=None
46.8874,TaskRequest,MODIFIED,eval-sanitize-1-r2-023,phase=Complete job=None
46.8917,Job,MODIFIED,eval-sanitize-1-r2-031,
46.8963,Job,MODIFIED,eval-sanitize-1-r2-023,
47.0078,TaskRequest,ADDED,eval-sanitize-1-r2-047,phase=None job=None
47.0115,TaskRequest,MODIFIED,eval-sanitize-1-r2-047,phase=Pending job=None
47.0264,Job,ADDED,eval-sanitize-1-r2-047,
47.0326,Pod,ADDED,eval-sanitize-1-r2-047-nwmdw,phase=Pending node=None
47.034,TaskRequest,MODIFIED,eval-sanitize-1-r2-047,phase=Scheduled job=None
47.0348,Job,MODIFIED,eval-sanitize-1-r2-047,
47.0383,Job,MODIFIED,eval-sanitize-1-r2-046,
47.0386,Event,ADDED,eval-sanitize-1-r2-047.18d41fbb8abe7804,reason=SuccessfulCreate count=1 msg=Created pod: eval-sanitize-1-r2-047-nwmdw
47.0417,Pod,MODIFIED,eval-sanitize-1-r2-047-nwmdw,phase=Pending node=kind-worker4
47.0419,TaskRequest,MODIFIED,eval-sanitize-1-r2-047,phase=Scheduled job=None
47.0476,Job,MODIFIED,eval-sanitize-1-r2-046,
47.048,Event,ADDED,eval-sanitize-1-r2-047-nwmdw.18d41fbb8b45e684,reason=Scheduled count=None msg=Successfully assigned compute/eval-sanitize-1-r2-047-nwmdw to kind-worker4
47.0541,Pod,MODIFIED,eval-sanitize-1-r2-046-9tgn4,phase=Pending node=None
47.0571,Event,MODIFIED,eval-sanitize-1-r2-046-9tgn4.18d41fbb802ec5f0,"reason=FailedScheduling count=None msg=0/6 nodes are available: 1 c_wall violated: 1 conflicting context pair(s) with node memory, 5 node(s) had untolerated taint(s). no new claims to deallocate, preemption: 0/6 nodes are available: 1 No preemption victims found for incoming pod, 5 Preemption is not helpful for scheduling."
47.0586,Node,MODIFIED,kind-worker4,taints=0
47.0597,Pod,MODIFIED,eval-sanitize-1-r2-047-nwmdw,phase=Pending node=kind-worker4
47.0628,Event,ADDED,eval-sanitize-1-r2-046-9tgn4.18d41fbb8c4d2cf8,"reason=FailedScheduling count=None msg=0/6 nodes are available: 1 c_wall violated: 2 conflicting context pair(s) with node memory, 5 node(s) had untolerated taint(s). no new claims to deallocate, preemption: 0/6 nodes are available: 1 No preemption victims found for incoming pod, 5 Preemption is not helpful for scheduling."
47.0687,Event,MODIFIED,eval-sanitize-1-r2-046-9tgn4.18d41fbb8c4d2cf8,"reason=FailedScheduling count=None msg=0/6 nodes are available: 1 c_wall violated: 2 conflicting context pair(s) with node memory, 5 node(s) had untolerated taint(s). no new claims to deallocate, preemption: 0/6 nodes are available: 1 No preemption victims found for incoming pod, 5 Preemption is not helpful for scheduling."
47.0848,Job,MODIFIED,eval-sanitize-1-r2-036,
47.0953,Job,MODIFIED,eval-sanitize-1-r2-036,
47.0977,Job,MODIFIED,eval-sanitize-1-r2-044,
47.1024,Job,MODIFIED,eval-sanitize-1-r2-039,
47.1073,Job,MODIFIED,eval-sanitize-1-r2-044,
47.1094,Job,MODIFIED,eval-sanitize-1-r2-040,
47.1113,Job,MODIFIED,eval-sanitize-1-r2-039,
47.1171,Job,MODIFIED,eval-sanitize-1-r2-040,
47.1331,Node,MODIFIED,kind-worker4,taints=0
47.1691,Event,ADDED,eval-sanitize-1-r2-045-jvwch.18d41fbb9299b288,"reason=Pulled count=1 msg=Container image ""busybox:musl"" already present on machine"
47.1833,Event,ADDED,eval-sanitize-1-r2-041-nbq6w.18d41fbb93622c97,"reason=Pulled count=1 msg=Container image ""busybox:musl"" already present on machine"
47.1894,Event,ADDED,eval-sanitize-1-r2-045-jvwch.18d41fbb93e56789,reason=Created count=1 msg=Created container: task
47.2015,Event,ADDED,eval-sanitize-1-r2-041-nbq6w.18d41fbb9490c784,reason=Created count=1 msg=Created container: task
47.2204,Job,MODIFIED,eval-sanitize-1-r2-034,
47.229,Pod,MODIFIED,eval-sanitize-1-r2-034-k9rpq,phase=Succeeded node=kind-worker2
47.23,Job,MODIFIED,eval-sanitize-1-r2-034,
47.2679,Event,ADDED,eval-sanitize-1-r2-041-nbq6w.18d41fbb98886a07,reason=Started count=1 msg=Started container task
47.2717,Event,ADDED,eval-sanitize-1-r2-045-jvwch.18d41fbb9888487c,reason=Started count=1 msg=Started container task
47.2832,Job,MODIFIED,eval-sanitize-1-r2-033,
47.2917,Job,MODIFIED,eval-sanitize-1-r2-033,
47.4645,Event,ADDED,eval-sanitize-1-r2-047-nwmdw.18d41fbba43ca9f4,"reason=Pulled count=1 msg=Container image ""busybox:musl"" already present on machine"
47.4829,Event,ADDED,eval-sanitize-1-r2-047-nwmdw.18d41fbba54cd60a,reason=Created count=1 msg=Created container: task
47.5145,Event,ADDED,eval-sanitize-1-r2-047-nwmdw.18d41fbba7393408,reason=Started count=1 msg=Started container task
47.8577,Pod,MODIFIED,eval-sanitize-1-r2-041-nbq6w,phase=Running node=kind-worker4
47.8663,Pod,MODIFIED,eval-sanitize-1-r2-047-nwmdw,phase=Running node=kind-worker4
47.8732,Pod,MODIFIED,eval-sanitize-1-r2-045-jvwch,phase=Running node=kind-worker4
48.0079,TaskRequest,ADDED,eval-sanitize-1-r2-048,phase=None job=None
48.0114,TaskRequest,MODIFIED,eval-sanitize-1-r2-048,phase=Pending job=None
48.0267,Job,ADDED,eval-sanitize-1-r2-048,
48.0309,TaskRequest,MODIFIED,eval-sanitize-1-r2-048,phase=Scheduled job=None
48.0338,Pod,ADDED,eval-sanitize-1-r2-048-7zqwg,phase=Pending node=None
48.0372,Job,MODIFIED,eval-sanitize-1-r2-048,
48.0388,Event,ADDED,eval-sanitize-1-r2-048.18d41fbbc66d397e,reason=SuccessfulCreate count=1 msg=Created pod: eval-sanitize-1-r2-048-7zqwg
48.039,TaskRequest,MODIFIED,eval-sanitize-1-r2-048,phase=Scheduled job=None
48.04,Job,MODIFIED,eval-sanitize-1-r2-047,
48.043,Pod,MODIFIED,eval-sanitize-1-r2-048-7zqwg,phase=Pending node=kind-worker4
48.0462,Event,ADDED,eval-sanitize-1-r2-048-7zqwg.18d41fbbc6f5a172,reason=Scheduled count=None msg=Successfully assigned compute/eval-sanitize-1-r2-048-7zqwg to kind-worker4
48.0497,Job,MODIFIED,eval-sanitize-1-r2-047,
48.0553,Pod,MODIFIED,eval-sanitize-1-r2-048-7zqwg,phase=Pending node=kind-worker4
48.2143,Node,MODIFIED,kind-worker4,taints=1
48.2175,Pod,MODIFIED,eval-sanitize-1-r2-046-9tgn4,phase=Pending node=None
48.2274,Job,MODIFIED,eval-sanitize-1-r2-034,
48.2309,Node,MODIFIED,kind-worker2,taints=1
48.2337,Job,MODIFIED,eval-sanitize-1-r2-034,
48.2359,Node,MODIFIED,kind-worker4,taints=1
48.2405,Event,ADDED,eval-sanitize-1-r2-034.18d41fbbd2653a38,reason=Completed count=1 msg=Job completed
48.2456,Job,MODIFIED,eval-sanitize-1-r2-034,
48.2502,TaskRequest,MODIFIED,eval-sanitize-1-r2-034,phase=Complete job=None
48.2588,Job,MODIFIED,eval-sanitize-1-r2-034,
48.2882,Job,MODIFIED,eval-sanitize-1-r2-033,
48.2912,TaskRequest,MODIFIED,eval-sanitize-1-r2-033,phase=Complete job=None
48.2921,Event,ADDED,eval-sanitize-1-r2-033.18d41fbbd5914b5b,reason=Completed count=1 msg=Job completed
48.3005,Job,MODIFIED,eval-sanitize-1-r2-033,
48.3346,Node,MODIFIED,kind-worker2,taints=1
48.4695,Event,ADDED,eval-sanitize-1-r2-048-7zqwg.18d41fbbe014fc10,"reason=Pulled count=1 msg=Container image ""busybox:musl"" already present on machine"
48.4849,Event,ADDED,eval-sanitize-1-r2-048-7zqwg.18d41fbbe1212293,reason=Created count=1 msg=Created container: task
48.5362,Event,ADDED,eval-sanitize-1-r2-048-7zqwg.18d41fbbe422a022,reason=Started count=1 msg=Started container task
48.7416,Node,MODIFIED,kind-worker2,taints=0
48.7471,Pod,MODIFIED,eval-sanitize-1-r2-046-9tgn4,phase=Pending node=kind-worker2
48.7502,Event,ADDED,eval-sanitize-1-r2-046-9tgn4.18d41fbbf0e9fcb3,reason=Scheduled count=None msg=Successfully assigned compute/eval-sanitize-1-r2-046-9tgn4 to kind-worker2
48.7566,Pod,MODIFIED,eval-sanitize-1-r2-046-9tgn4,phase=Pending node=kind-worker2
48.7588,Node,MODIFIED,kind-worker2,taints=0
48.847,Node,MODIFIED,kind-worker2,taints=0
48.8617,Pod,MODIFIED,eval-sanitize-1-r2-048-7zqwg,phase=Running node=kind-worker4
48.863,Job,MODIFIED,eval-sanitize-1-r2-041,
48.8713,Job,MODIFIED,eval-sanitize-1-r2-041,
48.8773,Job,MODIFIED,eval-sanitize-1-r2-045,
48.8853,Job,MODIFIED,eval-sanitize-1-r2-045,
48.9485,Node,MODIFIED,kind-worker2,taints=0
49.0164,TaskRequest,ADDED,eval-sanitize-1-r2-049,phase=None job=None
49.02,TaskRequest,MODIFIED,eval-sanitize-1-r2-049,phase=Pending job=None
49.0365,Job,ADDED,eval-sanitize-1-r2-049,
49.0386,Job,MODIFIED,eval-sanitize-1-r2-048,
49.0422,Pod,ADDED,eval-sanitize-1-r2-049-5r5p5,phase=Pending node=None
49.0436,TaskRequest,MODIFIED,eval-sanitize-1-r2-049,phase=Scheduled job=None
49.0465,Job,MODIFIED,eval-sanitize-1-r2-049,
49.0481,Event,ADDED,eval-sanitize-1-r2-049.18d41fbc028919f4,reason=SuccessfulCreate count=1 msg=Created pod: eval-sanitize-1-r2-049-5r5p5
49.0513,Pod,MODIFIED,eval-sanitize-1-r2-049-5r5p5,phase=Pending node=None
49.0525,Event,ADDED,eval-sanitize-1-r2-049-5r5p5.18d41fbc02d1986f,"reason=FailedScheduling count=None msg=0/6 nodes are available: 1 c_wall violated: 1 conflicting context pair(s) with node memory, 5 node(s) had untolerated taint(s). no new claims to deallocate, preemption: 0/6 nodes are available: 1 No preemption victims found for incoming pod, 5 Preemption is not helpful for scheduling."
49.0527,TaskRequest,MODIFIED,eval-sanitize-1-r2-049,phase=Scheduled job=None
49.0558,Job,MODIFIED,eval-sanitize-1-r2-048,
49.0583,Event,ADDED,eval-sanitize-1-r2-049-5r5p5.18d41fbc034e137b,"reason=FailedScheduling count=None msg=0/6 nodes are available: 1 c_wall violated: 1 conflicting context pair(s) with node memory, 5 node(s) had untolerated taint(s). no new claims to deallocate, preemption: 0/6 nodes are available: 1 No preemption victims found for incoming pod, 5 Preemption is not helpful for scheduling."
49.1832,Event,ADDED,eval-sanitize-1-r2-046-9tgn4.18d41fbc0ab131fb,"reason=Pulled count=1 msg=Container image ""busybox:musl"" already present on machine"
49.2015,Event,ADDED,eval-sanitize-1-r2-046-9tgn4.18d41fbc0bb56b3a,reason=Created count=1 msg=Created container: task
49.2558,Event,ADDED,eval-sanitize-1-r2-046-9tgn4.18d41fbc0f05802f,reason=Started count=1 msg=Started container task
50.0107,TaskRequest,ADDED,eval-sanitize-1-r2-050,phase=None job=None
50.0154,TaskRequest,MODIFIED,eval-sanitize-1-r2-050,phase=Pending job=None
50.0296,Job,ADDED,eval-sanitize-1-r2-050,
50.036,Pod,ADDED,eval-sanitize-1-r2-050-h7knl,phase=Pending node=None
50.0371,TaskRequest,MODIFIED,eval-sanitize-1-r2-050,phase=Scheduled job=None
50.0399,Job,MODIFIED,eval-sanitize-1-r2-050,
50.0413,Event,ADDED,eval-sanitize-1-r2-050.18d41fbc3dc80899,reason=SuccessfulCreate count=1 msg=Created pod: eval-sanitize-1-r2-050-h7knl
50.0452,Pod,MODIFIED,eval-sanitize-1-r2-050-h7knl,phase=Pending node=kind-worker2
50.0469,TaskRequest,MODIFIED,eval-sanitize-1-r2-050,phase=Scheduled job=None
50.0479,Job,MODIFIED,eval-sanitize-1-r2-049,
50.0504,Event,ADDED,eval-sanitize-1-r2-050-h7knl.18d41fbc3e4b5985,reason=Scheduled count=None msg=Successfully assigned compute/eval-sanitize-1-r2-050-h7knl to kind-worker2
50.056,Node,MODIFIED,kind-worker2,taints=0
50.0571,Event,MODIFIED,eval-sanitize-1-r2-049-5r5p5.18d41fbc034e137b,"reason=FailedScheduling count=None msg=0/6 nodes are available: 1 c_wall violated: 1 conflicting context pair(s) with node memory, 5 node(s) had untolerated taint(s). no new claims to deallocate, preemption: 0/6 nodes are available: 1 No preemption victims found for incoming pod, 5 Preemption is not helpful for scheduling."
50.0584,Pod,MODIFIED,eval-sanitize-1-r2-050-h7knl,phase=Pending node=kind-worker2
50.0594,Job,MODIFIED,eval-sanitize-1-r2-049,
50.1412,Node,MODIFIED,kind-worker2,taints=0
50.2292,Pod,MODIFIED,eval-sanitize-1-r2-046-9tgn4,phase=Running node=kind-worker2
50.4526,Node,MODIFIED,kind-worker2,taints=1
50.4584,Pod,MODIFIED,eval-sanitize-1-r2-049-5r5p5,phase=Pending node=None
50.4893,Event,ADDED,eval-sanitize-1-r2-050-h7knl.18d41fbc588a9efc,"reason=Pulled count=1 msg=Container image ""busybox:musl"" already present on machine"
50.5085,Event,ADDED,eval-sanitize-1-r2-050-h7knl.18d41fbc59bb7ed4,reason=Created count=1 msg=Created container: task
50.5555,Node,MODIFIED,kind-worker2,taints=1
50.5678,Event,ADDED,eval-sanitize-1-r2-050-h7knl.18d41fbc5d3d3141,reason=Started count=1 msg=Started container task
51.0091,TaskRequest,ADDED,eval-sanitize-1-r2-051,phase=None job=None
51.0127,TaskRequest,MODIFIED,eval-sanitize-1-r2-051,phase=Pending job=None
51.0296,Job,ADDED,eval-sanitize-1-r2-051,
51.0339,TaskRequest,MODIFIED,eval-sanitize-1-r2-051,phase=Scheduled job=None
51.0373,Pod,ADDED,eval-sanitize-1-r2-051-w5xsq,phase=Pending node=None
51.0394,Job,MODIFIED,eval-sanitize-1-r2-051,
51.0417,Job,MODIFIED,eval-sanitize-1-r2-050,
51.0434,Event,ADDED,eval-sanitize-1-r2-051.18d41fbc796f1ee2,reason=SuccessfulCreate count=1 msg=Created pod: eval-sanitize-1-r2-051-w5xsq
51.0436,Event,ADDED,eval-sanitize-1-r2-051-w5xsq.18d41fbc797ca637,"reason=FailedScheduling count=None msg=0/6 nodes are available: 6 node(s) had untolerated taint(s). no new claims to deallocate, preemption: 0/6 nodes are available: 6 Preemption is not helpful for scheduling."
51.0438,TaskRequest,MODIFIED,eval-sanitize-1-r2-051,phase=Scheduled job=None
51.0446,Pod,MODIFIED,eval-sanitize-1-r2-051-w5xsq,phase=Pending node=None
51.0502,Job,MODIFIED,eval-sanitize-1-r2-050,
51.2262,Pod,MODIFIED,eval-sanitize-1-r2-050-h7knl,phase=Running node=kind-worker2
51.2417,Job,MODIFIED,eval-sanitize-1-r2-046,
51.2511,Job,MODIFIED,eval-sanitize-1-r2-046,
52.0062,TaskRequest,ADDED,eval-sanitize-1-r2-052,phase=None job=None
52.0096,TaskRequest,MODIFIED,eval-sanitize-1-r2-052,phase=Pending job=None
52.0254,Job,ADDED,eval-sanitize-1-r2-052,
52.0324,Pod,ADDED,eval-sanitize-1-r2-052-75fkh,phase=Pending node=None
52.0341,Job,MODIFIED,eval-sanitize-1-r2-052,
52.0343,TaskRequest,MODIFIED,eval-sanitize-1-r2-052,phase=Scheduled job=None
52.0418,Event,ADDED,eval-sanitize-1-r2-052.18d41fbcb4c5c217,reason=SuccessfulCreate count=1 msg=Created pod: eval-sanitize-1-r2-052-75fkh
52.0421,Event,ADDED,eval-sanitize-1-r2-052-75fkh.18d41fbcb4cefbab,"reason=FailedScheduling count=None msg=0/6 nodes are available: 6 node(s) had untolerated taint(s). no new claims to deallocate, preemption: 0/6 nodes are available: 6 Preemption is not helpful for scheduling."
52.043,Pod,MODIFIED,eval-sanitize-1-r2-052-75fkh,phase=Pending node=None
52.0441,Job,MODIFIED,eval-sanitize-1-r2-051,
52.0442,TaskRequest,MODIFIED,eval-sanitize-1-r2-052,phase=Scheduled job=None
52.0462,Job,MODIFIED,eval-sanitize-1-r2-050,
52.0537,Job,MODIFIED,eval-sanitize-1-r2-051,
52.0553,Job,MODIFIED,eval-sanitize-1-r2-050,
53.0091,TaskRequest,ADDED,eval-sanitize-1-r2-053,phase=None job=None
53.0124,TaskRequest,MODIFIED,eval-sanitize-1-r2-053,phase=Pending job=None
53.0272,Job,ADDED,eval-sanitize-1-r2-053,
53.0313,TaskRequest,MODIFIED,eval-sanitize-1-r2-053,phase=Scheduled job=None
53.0359,Pod,ADDED,eval-sanitize-1-r2-053-srw2q,phase=Pending node=None
53.0386,Job,MODIFIED,eval-sanitize-1-r2-053,
53.0393,Job,MODIFIED,eval-sanitize-1-r2-052,
53.0413,TaskRequest,MODIFIED,eval-sanitize-1-r2-053,phase=Scheduled job=None
53.0468,Event,ADDED,eval-sanitize-1-r2-053.18d41fbcf09340d6,reason=SuccessfulCreate count=1 msg=Created pod: eval-sanitize-1-r2-053-srw2q
53.047,Event,ADDED,eval-sanitize-1-r2-053-srw2q.18d41fbcf09deef0,"reason=FailedScheduling count=None msg=0/6 nodes are available: 6 node(s) had untolerated taint(s). no new claims to deallocate, preemption: 0/6 nodes are available: 6 Preemption is not helpful for scheduling."
53.048,Pod,MODIFIED,eval-sanitize-1-r2-053-srw2q,phase=Pending node=None
53.0492,Job,MODIFIED,eval-sanitize-1-r2-052,
53.3468,Node,MODIFIED,kind-control-plane,taints=1
53.6242,Pod,MODIFIED,eval-sanitize-1-r2-037-mxbhp,phase=Running node=kind-worker5
53.6298,Pod,MODIFIED,eval-sanitize-1-r2-035-cs7wf,phase=Running node=kind-worker5
54.0064,TaskRequest,ADDED,eval-sanitize-1-r2-054,phase=None job=None
54.0111,TaskRequest,MODIFIED,eval-sanitize-1-r2-054,phase=Pending job=None
54.0243,Job,ADDED,eval-sanitize-1-r2-054,
54.0304,TaskRequest,MODIFIED,eval-sanitize-1-r2-054,phase=Scheduled job=None
54.0332,Pod,ADDED,eval-sanitize-1-r2-054-gvn48,phase=Pending node=None
54.0354,Job,MODIFIED,eval-sanitize-1-r2-054,
54.0396,Event,ADDED,eval-sanitize-1-r2-054.18d41fbd2c0d53fb,reason=SuccessfulCreate count=1 msg=Created pod: eval-sanitize-1-r2-054-gvn48
54.0398,Event,ADDED,eval-sanitize-1-r2-054-gvn48.18d41fbd2c16cc53,"reason=FailedScheduling count=None msg=0/6 nodes are available: 6 node(s) had untolerated taint(s). no new claims to deallocate, preemption: 0/6 nodes are available: 6 Preemption is not helpful for scheduling."
54.0398,TaskRequest,MODIFIED,eval-sanitize-1-r2-054,phase=Scheduled job=None
54.0407,Pod,MODIFIED,eval-sanitize-1-r2-054-gvn48,phase=Pending node=None
54.0419,Job,MODIFIED,eval-sanitize-1-r2-053,
54.0502,Job,MODIFIED,eval-sanitize-1-r2-053,
54.6334,Job,MODIFIED,eval-sanitize-1-r2-037,
54.6358,Job,MODIFIED,eval-sanitize-1-r2-035,
54.643,Job,MODIFIED,eval-sanitize-1-r2-037,
54.6468,Job,MODIFIED,eval-sanitize-1-r2-035,
54.7649,Pod,MODIFIED,eval-sanitize-1-r2-035-cs7wf,phase=Succeeded node=kind-worker5
54.7712,Pod,MODIFIED,eval-sanitize-1-r2-037-mxbhp,phase=Succeeded node=kind-worker5
55.0075,TaskRequest,ADDED,eval-sanitize-1-r2-055,phase=None job=None
55.013,TaskRequest,MODIFIED,eval-sanitize-1-r2-055,phase=Pending job=None
55.0268,Job,ADDED,eval-sanitize-1-r2-055,
55.0333,Pod,ADDED,eval-sanitize-1-r2-055-qtc8p,phase=Pending node=None
55.0351,TaskRequest,MODIFIED,eval-sanitize-1-r2-055,phase=Scheduled job=None
55.043,Job,MODIFIED,eval-sanitize-1-r2-055,
55.0528,Event,ADDED,eval-sanitize-1-r2-055.18d41fbd67a21b0d,reason=SuccessfulCreate count=1 msg=Created pod: eval-sanitize-1-r2-055-qtc8p
55.0531,Event,ADDED,eval-sanitize-1-r2-055-qtc8p.18d41fbd67ad24a4,"reason=FailedScheduling count=None msg=0/6 nodes are available: 6 node(s) had untolerated taint(s). no new claims to deallocate, preemption: 0/6 nodes are available: 6 Preemption is not helpful for scheduling."
55.0533,TaskRequest,MODIFIED,eval-sanitize-1-r2-055,phase=Scheduled job=None
55.0543,Job,MODIFIED,eval-sanitize-1-r2-054,
55.0553,Pod,MODIFIED,eval-sanitize-1-r2-055-qtc8p,phase=Pending node=None
55.0567,Node,MODIFIED,kind-worker5,taints=1
55.0636,Job,MODIFIED,eval-sanitize-1-r2-054,
55.1325,Node,MODIFIED,kind-worker5,taints=0
55.1386,Pod,MODIFIED,eval-sanitize-1-r2-049-5r5p5,phase=Pending node=kind-worker5
55.1408,Node,MODIFIED,kind-worker5,taints=0
55.1436,Event,ADDED,eval-sanitize-1-r2-051-w5xsq.18d41fbd6dc32cf4,"reason=FailedScheduling count=None msg=0/6 nodes are available: 1 c_wall violated: 1 conflicting context pair(s) with node memory, 5 node(s) had untolerated taint(s). no new claims to deallocate, preemption: 0/6 nodes are available: 1 No preemption victims found for incoming pod, 5 Preemption is not helpful for scheduling."
55.1445,Pod,MODIFIED,eval-sanitize-1-r2-051-w5xsq,phase=Pending node=None
55.1458,Event,ADDED,eval-sanitize-1-r2-049-5r5p5.18d41fbd6ddcae2f,reason=Scheduled count=None msg=Successfully assigned compute/eval-sanitize-1-r2-049-5r5p5 to kind-worker5
55.1501,Pod,MODIFIED,eval-sanitize-1-r2-049-5r5p5,phase=Pending node=kind-worker5
55.1528,Node,MODIFIED,kind-worker5,taints=0
55.1538,Pod,MODIFIED,eval-sanitize-1-r2-052-75fkh,phase=Pending node=kind-worker5
55.1569,Pod,MODIFIED,eval-sanitize-1-r2-053-srw2q,phase=Pending node=None
55.1597,Event,ADDED,eval-sanitize-1-r2-053-srw2q.18d41fbd6eaf2463,"reason=FailedScheduling count=None msg=0/6 nodes are available: 1 c_wall violated: 2 conflicting context pair(s) with node memory, 5 node(s) had untolerated taint(s). no new claims to deallocate, preemption: 0/6 nodes are available: 1 No preemption victims found for incoming pod, 5 Preemption is not helpful for scheduling."
55.1599,Event,ADDED,eval-sanitize-1-r2-052-75fkh.18d41fbd6ecb2a05,reason=Scheduled count=None msg=Successfully assigned compute/eval-sanitize-1-r2-052-75fkh to kind-worker5
55.166,Node,MODIFIED,kind-worker5,taints=0
55.1671,Event,ADDED,eval-sanitize-1-r2-054-gvn48.18d41fbd6f3f8d05,"reason=FailedScheduling count=None msg=0/6 nodes are available: 1 c_wall violated: 1 conflicting context pair(s) with node memory, 5 node(s) had untolerated taint(s). no new claims to deallocate, preemption: 0/6 nodes are available: 1 No preemption victims found for incoming pod, 5 Preemption is not helpful for scheduling."
55.168,Pod,MODIFIED,eval-sanitize-1-r2-054-gvn48,phase=Pending node=None
55.1691,Pod,MODIFIED,eval-sanitize-1-r2-052-75fkh,phase=Pending node=kind-worker5
55.1752,Pod,MODIFIED,eval-sanitize-1-r2-055-qtc8p,phase=Pending node=None
55.1764,Event,ADDED,eval-sanitize-1-r2-055-qtc8p.18d41fbd6fd99483,"reason=FailedScheduling count=None msg=0/6 nodes are available: 1 c_wall violated: 1 conflicting context pair(s) with node memory, 5 node(s) had untolerated taint(s). no new claims to deallocate, preemption: 0/6 nodes are available: 1 No preemption victims found for incoming pod, 5 Preemption is not helpful for scheduling."
55.1778,Node,MODIFIED,kind-worker5,taints=0
55.1885,Event,ADDED,eval-sanitize-1-r2-051-w5xsq.18d41fbd70b761b5,"reason=FailedScheduling count=None msg=0/6 nodes are available: 1 c_wall violated: 1 conflicting context pair(s) with node memory, 5 node(s) had untolerated taint(s). no new claims to deallocate, preemption: 0/6 nodes are available: 1 No preemption victims found for incoming pod, 5 Preemption is not helpful for scheduling."
55.1921,Event,ADDED,eval-sanitize-1-r2-053-srw2q.18d41fbd70e0e650,"reason=FailedScheduling count=None msg=0/6 nodes are available: 1 c_wall violated: 2 conflicting context pair(s) with node memory, 5 node(s) had untolerated taint(s). no new claims to deallocate, preemption: 0/6 nodes are available: 1 No preemption victims found for incoming pod, 5 Preemption is not helpful for scheduling."
55.2185,Event,ADDED,eval-sanitize-1-r2-054-gvn48.18d41fbd726cb994,"reason=FailedScheduling count=None msg=0/6 nodes are available: 1 c_wall violated: 1 conflicting context pair(s) with node memory, 5 node(s) had untolerated taint(s). no new claims to deallocate, preemption: 0/6 nodes are available: 1 No preemption victims found for incoming pod, 5 Preemption is not helpful for scheduling."
55.2367,Node,MODIFIED,kind-worker5,taints=0
55.2465,Node,MODIFIED,kind-worker5,taints=0
55.2506,Event,ADDED,eval-sanitize-1-r2-055-qtc8p.18d41fbd7468a923,"reason=FailedScheduling count=None msg=0/6 nodes are available: 1 c_wall violated: 1 conflicting context pair(s) with node memory, 5 node(s) had untolerated taint(s). no new claims to deallocate, preemption: 0/6 nodes are available: 1 No preemption victims found for incoming pod, 5 Preemption is not helpful for scheduling."
55.2544,Event,MODIFIED,eval-sanitize-1-r2-051-w5xsq.18d41fbd70b761b5,"reason=FailedScheduling count=None msg=0/6 nodes are available: 1 c_wall violated: 1 conflicting context pair(s) with node memory, 5 node(s) had untolerated taint(s). no new claims to deallocate, preemption: 0/6 nodes are available: 1 No preemption victims found for incoming pod, 5 Preemption is not helpful for scheduling."
55.2572,Event,MODIFIED,eval-sanitize-1-r2-053-srw2q.18d41fbd70e0e650,"reason=FailedScheduling count=None msg=0/6 nodes are available: 1 c_wall violated: 2 conflicting context pair(s) with node memory, 5 node(s) had untolerated taint(s). no new claims to deallocate, preemption: 0/6 nodes are available: 1 No preemption victims found for incoming pod, 5 Preemption is not helpful for scheduling."
55.2619,Event,MODIFIED,eval-sanitize-1-r2-054-gvn48.18d41fbd726cb994,"reason=FailedScheduling count=None msg=0/6 nodes are available: 1 c_wall violated: 1 conflicting context pair(s) with node memory, 5 node(s) had untolerated taint(s). no new claims to deallocate, preemption: 0/6 nodes are available: 1 No preemption victims found for incoming pod, 5 Preemption is not helpful for scheduling."
55.2626,Event,MODIFIED,eval-sanitize-1-r2-055-qtc8p.18d41fbd7468a923,"reason=FailedScheduling count=None msg=0/6 nodes are available: 1 c_wall violated: 1 conflicting context pair(s) with node memory, 5 node(s) had untolerated taint(s). no new claims to deallocate, preemption: 0/6 nodes are available: 1 No preemption victims found for incoming pod, 5 Preemption is not helpful for scheduling."
55.5879,Event,ADDED,eval-sanitize-1-r2-049-5r5p5.18d41fbd886ed546,"reason=Pulled count=1 msg=Container image ""busybox:musl"" already present on machine"
55.6037,Event,ADDED,eval-sanitize-1-r2-052-75fkh.18d41fbd89480076,"reason=Pulled count=1 msg=Container image ""busybox:musl"" already present on machine"
55.61,Event,ADDED,eval-sanitize-1-r2-049-5r5p5.18d41fbd89cfc1de,reason=Created count=1 msg=Created container: task
55.6227,Event,ADDED,eval-sanitize-1-r2-052-75fkh.18d41fbd8a888d7f,reason=Created count=1 msg=Created container: task
55.6388,Job,MODIFIED,eval-sanitize-1-r2-037,
55.6423,Job,MODIFIED,eval-sanitize-1-r2-035,
55.6448,Event,ADDED,eval-sanitize-1-r2-049-5r5p5.18d41fbd8bdd8376,reason=Started count=1 msg=Started container task
55.6494,Pod,MODIFIED,eval-sanitize-1-r2-037-mxbhp,phase=Succeeded node=kind-worker5
55.6505,Job,MODIFIED,eval-sanitize-1-r2-037,
55.6533,Pod,MODIFIED,eval-sanitize-1-r2-035-cs7wf,phase=Succeeded node=kind-worker5
55.6566,Job,MODIFIED,eval-sanitize-1-r2-035,
55.6878,Pod,MODIFIED,eval-sanitize-1-r2-038-pk954,phase=Running node=kind-worker
55.6977,Pod,MODIFIED,eval-sanitize-1-r2-042-fhft6,phase=Running node=kind-worker
55.705,Pod,MODIFIED,eval-sanitize-1-r2-043-jdhmk,phase=Running node=kind-worker
55.7124,Event,ADDED,eval-sanitize-1-r2-052-75fkh.18d41fbd8fe54726,reason=Started count=1 msg=Started container task
56.0087,TaskRequest,ADDED,eval-sanitize-1-r2-056,phase=None job=None
56.0122,TaskRequest,MODIFIED,eval-sanitize-1-r2-056,phase=Pending job=None
56.0271,Job,ADDED,eval-sanitize-1-r2-056,
56.0335,Pod,ADDED,eval-sanitize-1-r2-056-j4csr,phase=Pending node=None
56.0348,TaskRequest,MODIFIED,eval-sanitize-1-r2-056,phase=Scheduled job=None
56.0357,Job,MODIFIED,eval-sanitize-1-r2-056,
56.039,Event,ADDED,eval-sanitize-1-r2-056.18d41fbda34195a8,reason=SuccessfulCreate count=1 msg=Created pod: eval-sanitize-1-r2-056-j4csr
56.0398,Job,MODIFIED,eval-sanitize-1-r2-055,
56.0417,Pod,MODIFIED,eval-sanitize-1-r2-056-j4csr,phase=Pending node=None
56.042,Event,ADDED,eval-sanitize-1-r2-056-j4csr.18d41fbda37fd9fe,"reason=FailedScheduling count=None msg=0/6 nodes are available: 1 c_wall violated: 1 conflicting context pair(s) with node memory, 5 node(s) had untolerated taint(s). no new claims to deallocate, preemption: 0/6 nodes are available: 1 No preemption victims found for incoming pod, 5 Preemption is not helpful for scheduling."
56.0426,TaskRequest,MODIFIED,eval-sanitize-1-r2-056,phase=Scheduled job=None
56.0476,Job,MODIFIED,eval-sanitize-1-r2-055,
56.048,Event,ADDED,eval-sanitize-1-r2-056-j4csr.18d41fbda3f76b8c,"reason=FailedScheduling count=None msg=0/6 nodes are available: 1 c_wall violated: 1 conflicting context pair(s) with node memory, 5 node(s) had untolerated taint(s). no new claims to deallocate, preemption: 0/6 nodes are available: 1 No preemption victims found for incoming pod, 5 Preemption is not helpful for scheduling."
56.0988,Pod,MODIFIED,eval-sanitize-1-r2-036-9gqr8,phase=Running node=kind-worker3
56.1078,Pod,MODIFIED,eval-sanitize-1-r2-039-9fqnq,phase=Running node=kind-worker3
56.1145,Pod,MODIFIED,eval-sanitize-1-r2-040-ztkxk,phase=Running node=kind-worker3
56.1206,Pod,MODIFIED,eval-sanitize-1-r2-044-m2psh,phase=Running node=kind-worker3
56.1533,Node,MODIFIED,kind-worker5,taints=1
56.1647,Node,MODIFIED,kind-worker5,taints=1
56.1956,Pod,MODIFIED,eval-sanitize-1-r2-056-j4csr,phase=Pending node=None
56.196,Event,MODIFIED,eval-sanitize-1-r2-056-j4csr.18d41fbda3f76b8c,"reason=FailedScheduling count=None msg=0/6 nodes are available: 1 c_wall violated: 1 conflicting context pair(s) with node memory, 5 node(s) had untolerated taint(s). no new claims to deallocate, preemption: 0/6 nodes are available: 1 No preemption victims found for incoming pod, 5 Preemption is not helpful for scheduling."
56.2006,Pod,MODIFIED,eval-sanitize-1-r2-054-gvn48,phase=Pending node=None
56.205,Pod,MODIFIED,eval-sanitize-1-r2-055-qtc8p,phase=Pending node=None
56.211,Pod,MODIFIED,eval-sanitize-1-r2-051-w5xsq,phase=Pending node=None
56.2155,Pod,MODIFIED,eval-sanitize-1-r2-053-srw2q,phase=Pending node=None
56.6428,Pod,MODIFIED,eval-sanitize-1-r2-049-5r5p5,phase=Running node=kind-worker5
56.644,Job,MODIFIED,eval-sanitize-1-r2-037,
56.6479,Job,MODIFIED,eval-sanitize-1-r2-035,
56.6507,Job,MODIFIED,eval-sanitize-1-r2-037,
56.6526,Pod,MODIFIED,eval-sanitize-1-r2-052-75fkh,phase=Running node=kind-worker5
56.6535,Job,MODIFIED,eval-sanitize-1-r2-035,
56.6548,Event,ADDED,eval-sanitize-1-r2-037.18d41fbdc804039b,reason=Completed count=1 msg=Job completed
56.6607,Event,ADDED,eval-sanitize-1-r2-035.18d41fbdc82e0d4a,reason=Completed count=1 msg=Job completed
56.6629,Job,MODIFIED,eval-sanitize-1-r2-037,
56.6665,Job,MODIFIED,eval-sanitize-1-r2-035,
56.6676,TaskRequest,MODIFIED,eval-sanitize-1-r2-037,phase=Complete job=None
56.6732,TaskRequest,MODIFIED,eval-sanitize-1-r2-035,phase=Complete job=None
56.6779,Job,MODIFIED,eval-sanitize-1-r2-037,
56.6821,Job,MODIFIED,eval-sanitize-1-r2-035,
56.6933,Job,MODIFIED,eval-sanitize-1-r2-038,
56.7021,Job,MODIFIED,eval-sanitize-1-r2-042,
56.7043,Job,MODIFIED,eval-sanitize-1-r2-038,
56.7118,Job,MODIFIED,eval-sanitize-1-r2-043,
56.7141,Job,MODIFIED,eval-sanitize-1-r2-042,
56.7401,Job,MODIFIED,eval-sanitize-1-r2-043,
56.849,Pod,MODIFIED,eval-sanitize-1-r2-042-fhft6,phase=Succeeded node=kind-worker
56.8967,Pod,MODIFIED,eval-sanitize-1-r2-038-pk954,phase=Succeeded node=kind-worker
56.9031,Pod,MODIFIED,eval-sanitize-1-r2-043-jdhmk,phase=Succeeded node=kind-worker
57.0084,TaskRequest,ADDED,eval-sanitize-1-r2-057,phase=None job=None
57.0124,TaskRequest,MODIFIED,eval-sanitize-1-r2-057,phase=Pending job=None
57.0282,Job,ADDED,eval-sanitize-1-r2-057,
57.0349,TaskRequest,MODIFIED,eval-sanitize-1-r2-057,phase=Scheduled job=None
57.0361,Pod,ADDED,eval-sanitize-1-r2-057-76m4m,phase=Pending node=None
57.0376,Job,MODIFIED,eval-sanitize-1-r2-057,
57.0402,Job,MODIFIED,eval-sanitize-1-r2-056,
57.0428,Event,ADDED,eval-sanitize-1-r2-057.18d41fbddeffc3db,reason=SuccessfulCreate count=1 msg=Created pod: eval-sanitize-1-r2-057-76m4m
57.0431,Event,ADDED,eval-sanitize-1-r2-057-76m4m.18d41fbddf0a6ec6,"reason=FailedScheduling count=None msg=0/6 nodes are available: 6 node(s) had untolerated taint(s). no new claims to deallocate, preemption: 0/6 nodes are available: 6 Preemption is not helpful for scheduling."
57.0433,TaskRequest,MODIFIED,eval-sanitize-1-r2-057,phase=Scheduled job=None
57.0442,Pod,MODIFIED,eval-sanitize-1-r2-057-76m4m,phase=Pending node=None
57.0486,Job,MODIFIED,eval-sanitize-1-r2-056,
57.1061,Job,MODIFIED,eval-sanitize-1-r2-036,
57.1122,Job,MODIFIED,eval-sanitize-1-r2-039,
57.1159,Job,MODIFIED,eval-sanitize-1-r2-036,
57.1191,Job,MODIFIED,eval-sanitize-1-r2-040,
57.1216,Job,MODIFIED,eval-sanitize-1-r2-039,
57.1259,Job,MODIFIED,eval-sanitize-1-r2-044,
57.1313,Job,MODIFIED,eval-sanitize-1-r2-040,
57.1359,Job,MODIFIED,eval-sanitize-1-r2-044,
57.2562,Pod,MODIFIED,eval-sanitize-1-r2-039-9fqnq,phase=Succeeded node=kind-worker3
57.3056,Pod,MODIFIED,eval-sanitize-1-r2-044-m2psh,phase=Succeeded node=kind-worker3
57.3121,Pod,MODIFIED,eval-sanitize-1-r2-040-ztkxk,phase=Succeeded node=kind-worker3
57.3195,Pod,MODIFIED,eval-sanitize-1-r2-036-9gqr8,phase=Succeeded node=kind-worker3
57.6472,Job,MODIFIED,eval-sanitize-1-r2-049,
57.655,Job,MODIFIED,eval-sanitize-1-r2-052,
57.6566,Job,MODIFIED,eval-sanitize-1-r2-049,
57.6631,Job,MODIFIED,eval-sanitize-1-r2-052,
57.6991,Job,MODIFIED,eval-sanitize-1-r2-038,
57.7063,Job,MODIFIED,eval-sanitize-1-r2-042,
57.7104,Job,MODIFIED,eval-sanitize-1-r2-038,
57.7118,Pod,MODIFIED,eval-sanitize-1-r2-038-pk954,phase=Succeeded node=kind-worker
57.7149,Pod,MODIFIED,eval-sanitize-1-r2-042-fhft6,phase=Succeeded node=kind-worker
57.7168,Job,MODIFIED,eval-sanitize-1-r2-042,
57.7175,Job,MODIFIED,eval-sanitize-1-r2-043,
57.7251,Pod,MODIFIED,eval-sanitize-1-r2-043-jdhmk,phase=Succeeded node=kind-worker
57.7267,Job,MODIFIED,eval-sanitize-1-r2-043,
57.8823,Pod,MODIFIED,eval-sanitize-1-r2-045-jvwch,phase=Running node=kind-worker4
57.8883,Pod,MODIFIED,eval-sanitize-1-r2-047-nwmdw,phase=Running node=kind-worker4
57.8945,Pod,MODIFIED,eval-sanitize-1-r2-041-nbq6w,phase=Running node=kind-worker4
58.0075,TaskRequest,ADDED,eval-sanitize-1-r2-058,phase=None job=None
58.0108,TaskRequest,MODIFIED,eval-sanitize-1-r2-058,phase=Pending job=None
58.0258,Job,ADDED,eval-sanitize-1-r2-058,
58.0334,Pod,ADDED,eval-sanitize-1-r2-058-l8skl,phase=Pending node=None
58.0335,TaskRequest,MODIFIED,eval-sanitize-1-r2-058,phase=Scheduled job=None
58.0392,Node,MODIFIED,kind-worker,taints=1
58.0397,Event,ADDED,eval-sanitize-1-r2-058.18d41fbe1a7608a0,reason=SuccessfulCreate count=1 msg=Created pod: eval-sanitize-1-r2-058-l8skl
58.0399,Event,ADDED,eval-sanitize-1-r2-058-l8skl.18d41fbe1a837ca4,"reason=FailedScheduling count=None msg=0/6 nodes are available: 6 node(s) had untolerated taint(s). no new claims to deallocate, preemption: 0/6 nodes are available: 6 Preemption is not helpful for scheduling."
58.0407,Job,MODIFIED,eval-sanitize-1-r2-058,
58.0415,Pod,MODIFIED,eval-sanitize-1-r2-058-l8skl,phase=Pending node=None
58.0425,Job,MODIFIED,eval-sanitize-1-r2-057,
58.0427,TaskRequest,MODIFIED,eval-sanitize-1-r2-058,phase=Scheduled job=None
58.0466,Job,MODIFIED,eval-sanitize-1-r2-058,
58.0535,Job,MODIFIED,eval-sanitize-1-r2-057,
58.0557,Job,MODIFIED,eval-sanitize-1-r2-058,
58.0573,Node,MODIFIED,kind-worker,taints=0
58.0625,Pod,MODIFIED,eval-sanitize-1-r2-056-j4csr,phase=Pending node=kind-worker
58.0652,Node,MODIFIED,kind-worker,taints=0
58.0684,Pod,MODIFIED,eval-sanitize-1-r2-054-gvn48,phase=Pending node=kind-worker
58.0699,Event,ADDED,eval-sanitize-1-r2-056-j4csr.18d41fbe1c3488a1,reason=Scheduled count=None msg=Successfully assigned compute/eval-sanitize-1-r2-056-j4csr to kind-worker
58.0701,Event,ADDED,eval-sanitize-1-r2-055-qtc8p.18d41fbe1c47e4fb,"reason=FailedScheduling count=None msg=0/6 nodes are available: 1 c_wall violated: 1 conflicting context pair(s) with node memory, 5 node(s) had untolerated taint(s). no new claims to deallocate, preemption: 0/6 nodes are available: 1 No preemption victims found for incoming pod, 5 Preemption is not helpful for scheduling."
58.0709,Pod,MODIFIED,eval-sanitize-1-r2-055-qtc8p,phase=Pending node=None
58.075,Pod,MODIFIED,eval-sanitize-1-r2-056-j4csr,phase=Pending node=kind-worker
58.0753,Event,ADDED,eval-sanitize-1-r2-054-gvn48.18d41fbe1c90459d,reason=Scheduled count=None msg=Successfully assigned compute/eval-sanitize-1-r2-054-gvn48 to kind-worker
58.0802,Node,MODIFIED,kind-worker,taints=0
58.0841,Pod,MODIFIED,eval-sanitize-1-r2-051-w5xsq,phase=Pending node=kind-worker
58.0854,Pod,MODIFIED,eval-sanitize-1-r2-054-gvn48,phase=Pending node=kind-worker
58.0862,Pod,MODIFIED,eval-sanitize-1-r2-053-srw2q,phase=Pending node=kind-worker
58.0886,Pod,MODIFIED,eval-sanitize-1-r2-057-76m4m,phase=Pending node=kind-worker
58.0919,Event,ADDED,eval-sanitize-1-r2-051-w5xsq.18d41fbe1d63381b,reason=Scheduled count=None msg=Successfully assigned compute/eval-sanitize-1-r2-051-w5xsq to kind-worker
58.0922,Event,ADDED,eval-sanitize-1-r2-058-l8skl.18d41fbe1d8cc3f6,"reason=FailedScheduling count=None msg=0/6 nodes are available: 1 c_wall violated: 2 conflicting context pair(s) with node memory, 5 node(s) had untolerated taint(s). no new claims to deallocate, preemption: 0/6 nodes are available: 1 No preemption victims found for incoming pod, 5 Preemption is not helpful for scheduling."
58.093,Pod,MODIFIED,eval-sanitize-1-r2-058-l8skl,phase=Pending node=None
58.0955,Event,ADDED,eval-sanitize-1-r2-053-srw2q.18d41fbe1d87f0fb,reason=Scheduled count=None msg=Successfully assigned compute/eval-sanitize-1-r2-053-srw2q to kind-worker
58.0957,Event,ADDED,eval-sanitize-1-r2-057-76m4m.18d41fbe1dbc3a6e,reason=Scheduled count=None msg=Successfully assigned compute/eval-sanitize-1-r2-057-76m4m to kind-worker
58.1016,Node,MODIFIED,kind-worker,taints=0
58.1037,Pod,MODIFIED,eval-sanitize-1-r2-051-w5xsq,phase=Pending node=kind-worker
58.1099,Pod,MODIFIED,eval-sanitize-1-r2-053-srw2q,phase=Pending node=kind-worker
58.1111,Job,MODIFIED,eval-sanitize-1-r2-036,
58.1163,Pod,MODIFIED,eval-sanitize-1-r2-057-76m4m,phase=Pending node=kind-worker
58.118,Job,MODIFIED,eval-sanitize-1-r2-039,
58.1203,Pod,MODIFIED,eval-sanitize-1-r2-036-9gqr8,phase=Succeeded node=kind-worker3
58.1219,Job,MODIFIED,eval-sanitize-1-r2-036,
58.1243,Job,MODIFIED,eval-sanitize-1-r2-040,
58.1269,Pod,MODIFIED,eval-sanitize-1-r2-039-9fqnq,phase=Succeeded node=kind-worker3
58.1287,Job,MODIFIED,eval-sanitize-1-r2-039,
58.1301,Node,MODIFIED,kind-worker,taints=0
58.1325,Job,MODIFIED,eval-sanitize-1-r2-044,
58.1353,Pod,MODIFIED,eval-sanitize-1-r2-040-ztkxk,phase=Succeeded node=kind-worker3
58.1392,Job,MODIFIED,eval-sanitize-1-r2-040,
58.1416,Pod,MODIFIED,eval-sanitize-1-r2-044-m2psh,phase=Succeeded node=kind-worker3
58.1436,Node,MODIFIED,kind-worker,taints=0
58.1439,Event,ADDED,eval-sanitize-1-r2-040.18d41fbe20c85957,reason=Completed count=1 msg=Job completed
58.1481,Job,MODIFIED,eval-sanitize-1-r2-044,
58.1511,Pod,MODIFIED,eval-sanitize-1-r2-055-qtc8p,phase=Pending node=None
58.1514,Event,ADDED,eval-sanitize-1-r2-055-qtc8p.18d41fbe21353ef8,"reason=FailedScheduling count=None msg=0/6 nodes are available: 1 c_wall violated: 2 conflicting context pair(s) with node memory, 5 node(s) had untolerated taint(s). no new claims to deallocate, preemption: 0/6 nodes are available: 1 No preemption victims found for incoming pod, 5 Preemption is not helpful for scheduling."
58.1516,Event,ADDED,eval-sanitize-1-r2-044.18d41fbe214ea8e1,reason=Completed count=1 msg=Job completed
58.1576,Event,ADDED,eval-sanitize-1-r2-058-l8skl.18d41fbe21b0aa8e,"reason=FailedScheduling count=None msg=0/6 nodes are available: 1 c_wall violated: 2 conflicting context pair(s) with node memory, 5 node(s) had untolerated taint(s). no new claims to deallocate, preemption: 0/6 nodes are available: 1 No preemption victims found for incoming pod, 5 Preemption is not helpful for scheduling."
58.1609,Event,ADDED,eval-sanitize-1-r2-055-qtc8p.18d41fbe21db270d,"reason=FailedScheduling count=None msg=0/6 nodes are available: 1 c_wall violated: 2 conflicting context pair(s) with node memory, 5 node(s) had untolerated taint(s). no new claims to deallocate, preemption: 0/6 nodes are available: 1 No preemption victims found for incoming pod, 5 Preemption is not helpful for scheduling."
58.3056,Job,MODIFIED,eval-sanitize-1-r2-044,
58.3065,Job,MODIFIED,eval-sanitize-1-r2-040,
58.311,TaskRequest,MODIFIED,eval-sanitize-1-r2-044,phase=Complete job=None
58.3167,TaskRequest,MODIFIED,eval-sanitize-1-r2-040,phase=Complete job=None
58.3204,Job,MODIFIED,eval-sanitize-1-r2-044,
58.3277,Job,MODIFIED,eval-sanitize-1-r2-040,
58.3342,Node,MODIFIED,kind-worker3,taints=1
58.3356,Node,MODIFIED,kind-worker,taints=0
58.3439,Event,MODIFIED,eval-sanitize-1-r2-058-l8skl.18d41fbe21b0aa8e,"reason=FailedScheduling count=None msg=0/6 nodes are available: 1 c_wall violated: 2 conflicting context pair(s) with node memory, 5 node(s) had untolerated taint(s). no new claims to deallocate, preemption: 0/6 nodes are available: 1 No preemption victims found for incoming pod, 5 Preemption is not helpful for scheduling."
58.3471,Event,MODIFIED,eval-sanitize-1-r2-055-qtc8p.18d41fbe21db270d,"reason=FailedScheduling count=None msg=0/6 nodes are available: 1 c_wall violated: 2 conflicting context pair(s) with node memory, 5 node(s) had untolerated taint(s). no new claims to deallocate, preemption: 0/6 nodes are available: 1 No preemption victims found for incoming pod, 5 Preemption is not helpful for scheduling."
58.5289,Event,ADDED,eval-sanitize-1-r2-054-gvn48.18d41fbe37b59656,"reason=Pulled count=1 msg=Container image ""busybox:musl"" already present on machine"
58.5336,Event,ADDED,eval-sanitize-1-r2-056-j4csr.18d41fbe37ce6fd7,"reason=Pulled count=1 msg=Container image ""busybox:musl"" already present on machine"
58.5443,Node,MODIFIED,kind-worker3,taints=0
58.5564,Pod,MODIFIED,eval-sanitize-1-r2-055-qtc8p,phase=Pending node=kind-worker3
58.5614,Event,ADDED,eval-sanitize-1-r2-054-gvn48.18d41fbe39427d27,reason=Created count=1 msg=Created container: task
58.5631,Node,MODIFIED,kind-worker3,taints=0
58.5678,Event,ADDED,eval-sanitize-1-r2-055-qtc8p.18d41fbe39990c35,reason=Scheduled count=None msg=Successfully assigned compute/eval-sanitize-1-r2-055-qtc8p to kind-worker3
58.5681,Event,ADDED,eval-sanitize-1-r2-053-srw2q.18d41fbe397a6c91,"reason=Pulled count=1 msg=Container image ""busybox:musl"" already present on machine"
58.5691,Pod,MODIFIED,eval-sanitize-1-r2-058-l8skl,phase=Pending node=None
58.576,Pod,MODIFIED,eval-sanitize-1-r2-055-qtc8p,phase=Pending node=kind-worker3
58.5763,Event,ADDED,eval-sanitize-1-r2-057-76m4m.18d41fbe39a60e80,"reason=Pulled count=1 msg=Container image ""busybox:musl"" already present on machine"
58.5818,Event,ADDED,eval-sanitize-1-r2-051-w5xsq.18d41fbe39e00037,"reason=Pulled count=1 msg=Container image ""busybox:musl"" already present on machine"
58.5835,Event,ADDED,eval-sanitize-1-r2-058-l8skl.18d41fbe3acb03f6,"reason=FailedScheduling count=None msg=0/6 nodes are available: 1 c_wall violated: 1 conflicting context pair(s) with node memory, 1 c_wall violated: 2 conflicting context pair(s) with node memory, 4 node(s) had untolerated taint(s). no new claims to deallocate, preemption: 0/6 nodes are available: 2 No preemption victims found for incoming pod, 4 Preemption is not helpful for scheduling."
58.586,Event,ADDED,eval-sanitize-1-r2-056-j4csr.18d41fbe3a94b923,reason=Created count=1 msg=Created container: task
58.5909,Node,MODIFIED,kind-worker3,taints=0
58.6034,Event,ADDED,eval-sanitize-1-r2-053-srw2q.18d41fbe3c314efd,reason=Created count=1 msg=Created container: task
58.609,Event,ADDED,eval-sanitize-1-r2-051-w5xsq.18d41fbe3c909b03,reason=Created count=1 msg=Created container: task
58.6152,Event,ADDED,eval-sanitize-1-r2-057-76m4m.18d41fbe3cb40f02,reason=Created count=1 msg=Created container: task
58.6486,Node,MODIFIED,kind-worker3,taints=0
58.6539,Event,ADDED,eval-sanitize-1-r2-054-gvn48.18d41fbe3f1f89da,reason=Started count=1 msg=Started container task
58.6545,Event,MODIFIED,eval-sanitize-1-r2-058-l8skl.18d41fbe3acb03f6,"reason=FailedScheduling count=None msg=0/6 nodes are available: 1 c_wall violated: 1 conflicting context pair(s) with node memory, 1 c_wall violated: 2 conflicting context pair(s) with node memory, 4 node(s) had untolerated taint(s). no new claims to deallocate, preemption: 0/6 nodes are available: 2 No preemption victims found for incoming pod, 4 Preemption is not helpful for scheduling."
58.6703,Event,ADDED,eval-sanitize-1-r2-056-j4csr.18d41fbe4023cd4c,reason=Started count=1 msg=Started container task
58.6745,Event,ADDED,eval-sanitize-1-r2-057-76m4m.18d41fbe4023ccc4,reason=Started count=1 msg=Started container task
58.6795,Event,ADDED,eval-sanitize-1-r2-051-w5xsq.18d41fbe40244269,reason=Started count=1 msg=Started container task
58.6831,Event,ADDED,eval-sanitize-1-r2-053-srw2q.18d41fbe40244dfe,reason=Started count=1 msg=Started container task
58.6973,Pod,MODIFIED,eval-sanitize-1-r2-051-w5xsq,phase=Running node=kind-worker
58.7039,Pod,MODIFIED,eval-sanitize-1-r2-056-j4csr,phase=Running node=kind-worker
58.7051,Job,MODIFIED,eval-sanitize-1-r2-038,
58.7096,Job,MODIFIED,eval-sanitize-1-r2-038,
58.7117,Job,MODIFIED,eval-sanitize-1-r2-042,
58.713,Pod,MODIFIED,eval-sanitize-1-r2-057-76m4m,phase=Running node=kind-worker
58.7162,Event,ADDED,eval-sanitize-1-r2-038.18d41fbe42c722f3,reason=Completed count=1 msg=Job completed
58.7174,Job,MODIFIED,eval-sanitize-1-r2-042,
58.7201,Pod,MODIFIED,eval-sanitize-1-r2-053-srw2q,phase=Running node=kind-worker
58.7218,Job,MODIFIED,eval-sanitize-1-r2-038,
58.7221,Event,ADDED,eval-sanitize-1-r2-042.18d41fbe43378ce4,reason=Completed count=1 msg=Job completed
58.7229,Job,MODIFIED,eval-sanitize-1-r2-043,
58.7272,Job,MODIFIED,eval-sanitize-1-r2-043,
58.7302,Pod,MODIFIED,eval-sanitize-1-r2-054-gvn48,phase=Running node=kind-worker
58.7303,TaskRequest,MODIFIED,eval-sanitize-1-r2-038,phase=Complete job=None
58.7312,Job,MODIFIED,eval-sanitize-1-r2-042,
58.7316,Event,ADDED,eval-sanitize-1-r2-043.18d41fbe43c5167c,reason=Completed count=1 msg=Job completed
58.7359,Node,MODIFIED,kind-worker3,taints=0
58.7397,TaskRequest,MODIFIED,eval-sanitize-1-r2-042,phase=Complete job=None
58.7428,Job,MODIFIED,eval-sanitize-1-r2-038,
58.7438,Job,MODIFIED,eval-sanitize-1-r2-043,
58.7491,Job,MODIFIED,eval-sanitize-1-r2-042,
58.7501,TaskRequest,MODIFIED,eval-sanitize-1-r2-043,phase=Complete job=None
58.7603,Job,MODIFIED,eval-sanitize-1-r2-043,
58.889,Job,MODIFIED,eval-sanitize-1-r2-045,
58.8928,Pod,MODIFIED,eval-sanitize-1-r2-048-7zqwg,phase=Running node=kind-worker4
58.8936,Job,MODIFIED,eval-sanitize-1-r2-047,
58.9015,Job,MODIFIED,eval-sanitize-1-r2-041,
58.9032,Job,MODIFIED,eval-sanitize-1-r2-045,
58.9057,Job,MODIFIED,eval-sanitize-1-r2-047,
58.9146,Job,MODIFIED,eval-sanitize-1-r2-041,
59.0027,Event,ADDED,eval-sanitize-1-r2-055-qtc8p.18d41fbe53f2a16b,"reason=Pulled count=1 msg=Container image ""busybox:musl"" already present on machine"
59.0074,TaskRequest,ADDED,eval-sanitize-1-r2-059,phase=None job=None
59.0126,TaskRequest,MODIFIED,eval-sanitize-1-r2-059,phase=Pending job=None
59.0218,Event,ADDED,eval-sanitize-1-r2-055-qtc8p.18d41fbe552de325,reason=Created count=1 msg=Created container: task
59.0288,Job,ADDED,eval-sanitize-1-r2-059,
59.0327,TaskRequest,MODIFIED,eval-sanitize-1-r2-059,phase=Scheduled job=None
59.0355,Pod,ADDED,eval-sanitize-1-r2-059-fpnp6,phase=Pending node=None
59.0389,Job,MODIFIED,eval-sanitize-1-r2-059,
59.0406,Event,ADDED,eval-sanitize-1-r2-059.18d41fbe5637b27b,reason=SuccessfulCreate count=1 msg=Created pod: eval-sanitize-1-r2-059-fpnp6
59.0415,TaskRequest,MODIFIED,eval-sanitize-1-r2-059,phase=Scheduled job=None
59.0463,Job,MODIFIED,eval-sanitize-1-r2-057,
59.0487,Pod,MODIFIED,eval-sanitize-1-r2-059-fpnp6,phase=Pending node=kind-worker3
59.0522,Event,ADDED,eval-sanitize-1-r2-059-fpnp6.18d41fbe56f8f288,reason=Scheduled count=None msg=Successfully assigned compute/eval-sanitize-1-r2-059-fpnp6 to kind-worker3
59.0555,Job,MODIFIED,eval-sanitize-1-r2-057,
59.0586,Pod,MODIFIED,eval-sanitize-1-r2-059-fpnp6,phase=Pending node=kind-worker3
59.0686,Job,MODIFIED,eval-sanitize-1-r2-056,
59.0737,Job,MODIFIED,eval-sanitize-1-r2-054,
59.0802,Pod,MODIFIED,eval-sanitize-1-r2-045-jvwch,phase=Succeeded node=kind-worker4
59.084,Job,MODIFIED,eval-sanitize-1-r2-056,
59.0848,Job,MODIFIED,eval-sanitize-1-r2-054,
59.0901,Job,MODIFIED,eval-sanitize-1-r2-051,
59.0935,Job,MODIFIED,eval-sanitize-1-r2-053,
59.0967,Pod,MODIFIED,eval-sanitize-1-r2-041-nbq6w,phase=Succeeded node=kind-worker4
59.0972,Event,ADDED,eval-sanitize-1-r2-055-qtc8p.18d41fbe599839c6,reason=Started count=1 msg=Started container task
59.0995,Job,MODIFIED,eval-sanitize-1-r2-051,
59.1047,Pod,MODIFIED,eval-sanitize-1-r2-047-nwmdw,phase=Succeeded node=kind-worker4
59.1059,Job,MODIFIED,eval-sanitize-1-r2-053,
59.1161,Pod,MODIFIED,eval-sanitize-1-r2-055-qtc8p,phase=Running node=kind-worker3
59.1175,Job,MODIFIED,eval-sanitize-1-r2-036,
59.122,Job,MODIFIED,eval-sanitize-1-r2-039,
59.1238,Job,MODIFIED,eval-sanitize-1-r2-036,
59.1256,Job,MODIFIED,eval-sanitize-1-r2-039,
59.1278,Event,ADDED,eval-sanitize-1-r2-036.18d41fbe5b789165,reason=Completed count=1 msg=Job completed
59.1317,Event,ADDED,eval-sanitize-1-r2-039.18d41fbe5b99bcf0,reason=Completed count=1 msg=Job completed
59.135,Job,MODIFIED,eval-sanitize-1-r2-036,
59.1369,Job,MODIFIED,eval-sanitize-1-r2-039,
59.1411,Node,MODIFIED,kind-worker,taints=1
59.1412,TaskRequest,MODIFIED,eval-sanitize-1-r2-036,phase=Complete job=None
59.1455,TaskRequest,MODIFIED,eval-sanitize-1-r2-039,phase=Complete job=None
59.1508,Job,MODIFIED,eval-sanitize-1-r2-036,
59.1539,Node,MODIFIED,kind-worker,taints=1
59.1555,Job,MODIFIED,eval-sanitize-1-r2-039,
59.1583,Pod,MODIFIED,eval-sanitize-1-r2-058-l8skl,phase=Pending node=None
59.2237,Event,ADDED,eval-sanitize-1-r2-058-l8skl.18d41fbe6125ec2b,"reason=FailedScheduling count=None msg=0/6 nodes are available: 1 c_wall violated: 1 conflicting context pair(s) with node memory, 5 node(s) had untolerated taint(s). no new claims to deallocate, preemption: 0/6 nodes are available: 1 No preemption victims found for incoming pod, 5 Preemption is not helpful for scheduling."
59.4965,Event,ADDED,eval-sanitize-1-r2-059-fpnp6.18d41fbe716f97e1,"reason=Pulled count=1 msg=Container image ""busybox:musl"" already present on machine"
59.5163,Event,ADDED,eval-sanitize-1-r2-059-fpnp6.18d41fbe72970b20,reason=Created count=1 msg=Created container: task
59.5725,Event,ADDED,eval-sanitize-1-r2-059-fpnp6.18d41fbe75f597f5,reason=Started count=1 msg=Started container task
59.6438,Node,MODIFIED,kind-worker3,taints=1
59.6539,Pod,MODIFIED,eval-sanitize-1-r2-058-l8skl,phase=Pending node=None
59.6569,Node,MODIFIED,kind-worker3,taints=1
59.6574,Event,MODIFIED,eval-sanitize-1-r2-058-l8skl.18d41fbe6125ec2b,"reason=FailedScheduling count=None msg=0/6 nodes are available: 1 c_wall violated: 1 conflicting context pair(s) with node memory, 5 node(s) had untolerated taint(s). no new claims to deallocate, preemption: 0/6 nodes are available: 1 No preemption victims found for incoming pod, 5 Preemption is not helpful for scheduling."
59.8943,Job,MODIFIED,eval-sanitize-1-r2-045,
59.8964,Job,MODIFIED,eval-sanitize-1-r2-048,
59.9004,Job,MODIFIED,eval-sanitize-1-r2-047,
59.9033,Pod,MODIFIED,eval-sanitize-1-r2-045-jvwch,phase=Succeeded node=kind-worker4
59.9047,Job,MODIFIED,eval-sanitize-1-r2-045,
59.9074,Job,MODIFIED,eval-sanitize-1-r2-048,
59.9081,Job,MODIFIED,eval-sanitize-1-r2-041,
59.9113,Job,MODIFIED,eval-sanitize-1-r2-047,
59.9128,Pod,MODIFIED,eval-sanitize-1-r2-047-nwmdw,phase=Succeeded node=kind-worker4
59.9162,Pod,MODIFIED,eval-sanitize-1-r2-041-nbq6w,phase=Succeeded node=kind-worker4
59.9176,Job,MODIFIED,eval-sanitize-1-r2-041,
59.9797,Pod,MODIFIED,eval-sanitize-1-r2-048-7zqwg,phase=Succeeded node=kind-worker4
60.0067,TaskRequest,ADDED,eval-sanitize-1-r2-060,phase=None job=None
60.0105,TaskRequest,MODIFIED,eval-sanitize-1-r2-060,phase=Pending job=None
60.0168,Node,ADDED,kind-control-plane,taints=1
60.0186,Node,ADDED,kind-worker,taints=1
60.0192,TaskRequest,ADDED,eval-sanitize-1-r2-000,phase=Complete job=None
60.0216,Node,ADDED,kind-worker2,taints=1
60.0226,Job,ADDED,eval-sanitize-1-r2-000,
60.0228,TaskRequest,ADDED,eval-sanitize-1-r2-001,phase=Complete job=None
60.0229,TaskRequest,ADDED,eval-sanitize-1-r2-002,phase=Complete job=None
60.0236,Event,ADDED,eval-sanitize-1-r0-007-8kfn5.18d41f2469875ef6,"reason=FailedScheduling count=None msg=0/6 nodes are available: 1 c_wall violated: 1 conflicting context pair(s) with node memory, 5 node(s) had untolerated taint(s). no new claims to deallocate, preemption: 0/6 nodes are available: 1 No preemption victims found for incoming pod, 5 Preemption is not helpful for scheduling."
60.0238,TaskRequest,ADDED,eval-sanitize-1-r2-003,phase=Complete job=None
60.0239,TaskRequest,ADDED,eval-sanitize-1-r2-004,phase=Complete job=None
60.024,TaskRequest,ADDED,eval-sanitize-1-r2-005,phase=Complete job=None
60.0256,Node,ADDED,kind-worker3,taints=1
60.026,Event,ADDED,eval-sanitize-1-r0-007-8kfn5.18d41f24a79a6a54,"reason=FailedScheduling count=None msg=0/6 nodes are available: 1 c_wall violated: 1 conflicting context pair(s) with node memory, 1 c_wall violated: 2 conflicting context pair(s) with node memory, 4 node(s) had untolerated taint(s). no new claims to deallocate, preemption: 0/6 nodes are available: 2 No preemption victims found for incoming pod, 4 Preemption is not helpful for scheduling."
60.0262,Event,ADDED,eval-sanitize-1-r0-009-9mtfx.18d41f2469b2aada,"reason=FailedScheduling count=None msg=0/6 nodes are available: 1 c_wall violated: 3 conflicting context pair(s) with node memory, 5 node(s) had untolerated taint(s). no new claims to deallocate, preemption: 0/6 nodes are available: 1 No preemption victims found for incoming pod, 5 Preemption is not helpful for scheduling."
60.0265,Event,ADDED,eval-sanitize-1-r0-011-l58zp.18d41f2469dbc96c,"reason=FailedScheduling count=None msg=0/6 nodes are available: 1 c_wall violated: 1 conflicting context pair(s) with node memory, 5 node(s) had untolerated taint(s). no new claims to deallocate, preemption: 0/6 nodes are available: 1 No preemption victims found for incoming pod, 5 Preemption is not helpful for scheduling."
60.0275,Job,ADDED,eval-sanitize-1-r2-001,
60.0276,TaskRequest,ADDED,eval-sanitize-1-r2-006,phase=Complete job=None
60.0276,TaskRequest,ADDED,eval-sanitize-1-r2-007,phase=Complete job=None
60.0276,TaskRequest,ADDED,eval-sanitize-1-r2-008,phase=Complete job=None
60.0285,Job,ADDED,eval-sanitize-1-r2-002,
60.0286,TaskRequest,ADDED,eval-sanitize-1-r2-009,phase=Complete job=None
60.0287,TaskRequest,ADDED,eval-sanitize-1-r2-010,phase=Complete job=None
60.0302,Node,ADDED,kind-worker4,taints=1
60.0306,Event,ADDED,eval-sanitize-1-r0-011-l58zp.18d41f24a1836fcb,"reason=FailedScheduling count=None msg=0/6 nodes are available: 1 c_wall violated: 1 conflicting context pair(s) with node memory, 1 c_wall violated: 2 conflicting context pair(s) with node memory, 4 node(s) had untolerated taint(s). no new claims to deallocate, preemption: 0/6 nodes are available: 2 No preemption victims found for incoming pod, 4 Preemption is not helpful for scheduling."
60.0308,Event,ADDED,eval-sanitize-1-r0-012-dscsx.18d41f246a0b0109,"reason=FailedScheduling count=None msg=0/6 nodes are available: 1 c_wall violated: 3 conflicting context pair(s) with node memory, 5 node(s) had untolerated taint(s). no new claims to deallocate, preemption: 0/6 nodes are available: 1 No preemption victims found for incoming pod, 5 Preemption is not helpful for scheduling."
60.0315,Event,ADDED,eval-sanitize-1-r0-013-gvtcp.18d41f246a30abdb,"reason=FailedScheduling count=None msg=0/6 nodes are available: 1 c_wall violated: 3 conflicting context pair(s) with node memory, 5 node(s) had untolerated taint(s). no new claims to deallocate, preemption: 0/6 nodes are available: 1 No preemption victims found for incoming pod, 5 Preemption is not helpful for scheduling."
60.0317,Event,ADDED,eval-sanitize-1-r0-014-7wkn9.18d41f2471a1a06c,"reason=FailedScheduling count=None msg=0/6 nodes are available: 1 c_wall violated: 3 conflicting context pair(s) with node memory, 5 node(s) had untolerated taint(s). no new claims to deallocate, preemption: 0/6 nodes are available: 1 No preemption victims found for incoming pod, 5 Preemption is not helpful for scheduling."
60.0319,Event,ADDED,eval-sanitize-1-r0-015-66n9t.18d41f24ad37b516,"reason=FailedScheduling count=None msg=0/6 nodes are available: 1 c_wall violated: 1 conflicting context pair(s) with node memory, 1 c_wall violated: 2 conflicting context pair(s) with node memory, 4 node(s) had untolerated taint(s). no new claims to deallocate, preemption: 0/6 nodes are available: 2 No preemption victims found for incoming pod, 4 Preemption is not helpful for scheduling."
60.032,TaskRequest,ADDED,eval-sanitize-1-r2-011,phase=Complete job=None
60.032,TaskRequest,ADDED,eval-sanitize-1-r2-012,phase=Complete job=None
60.032,TaskRequest,ADDED,eval-sanitize-1-r2-013,phase=Complete job=None
60.0329,Job,ADDED,eval-sanitize-1-r2-003,
60.035,Node,ADDED,kind-worker5,taints=1
60.0354,Event,ADDED,eval-sanitize-1-r0-016-dwbgm.18d41f24e8c6e494,"reason=FailedScheduling count=None msg=0/6 nodes are available: 1 c_wall violated: 1 conflicting context pair(s) with node memory, 5 node(s) had untolerated taint(s). no new claims to deallocate, preemption: 0/6 nodes are available: 1 No preemption victims found for incoming pod, 5 Preemption is not helpful for scheduling."
60.0356,Event,ADDED,eval-sanitize-1-r0-017-46n92.18d41f2524bd48e5,"reason=FailedScheduling count=None msg=0/6 nodes are available: 1 c_wall violated: 1 conflicting context pair(s) with node memory, 5 node(s) had untolerated taint(s). no new claims to deallocate, preemption: 0/6 nodes are available: 1 No preemption victims found for incoming pod, 5 Preemption is not helpful for scheduling."
60.0358,Event,ADDED,eval-sanitize-1-r0-018-jnpxh.18d41f278e17553a,"reason=FailedScheduling count=None msg=0/6 nodes are available: 1 c_wall violated: 3 conflicting context pair(s) with node memory, 5 node(s) had untolerated taint(s). no new claims to deallocate, preemption: 0/6 nodes are available: 1 No preemption victims found for incoming pod, 5 Preemption is not helpful for scheduling."
60.0359,TaskRequest,ADDED,eval-sanitize-1-r2-014,phase=Complete job=None
60.0359,TaskRequest,ADDED,eval-sanitize-1-r2-015,phase=Complete job=None
60.036,TaskRequest,ADDED,eval-sanitize-1-r2-016,phase=Complete job=None
60.0369,Job,ADDED,eval-sanitize-1-r2-004,
60.0374,Event,ADDED,eval-sanitize-1-r0-021-m5vhs.18d41f278d612610,"reason=FailedScheduling count=None msg=0/6 nodes are available: 1 c_wall violated: 2 conflicting context pair(s) with node memory, 5 node(s) had untolerated taint(s). no new claims to deallocate, preemption: 0/6 nodes are available: 1 No preemption victims found for incoming pod, 5 Preemption is not helpful for scheduling."
60.0377,Event,ADDED,eval-sanitize-1-r0-023-gdrzz.18d41f278d95d885,"reason=FailedScheduling count=None msg=0/6 nodes are available: 1 c_wall violated: 1 conflicting context pair(s) with node memory, 5 node(s) had untolerated taint(s). no new claims to deallocate, preemption: 0/6 nodes are available: 1 No preemption victims found for incoming pod, 5 Preemption is not helpful for scheduling."
60.038,Event,ADDED,eval-sanitize-1-r0-025-srtmj.18d41f278dbf61d2,"reason=FailedScheduling count=None msg=0/6 nodes are available: 1 c_wall violated: 3 conflicting context pair(s) with node memory, 5 node(s) had untolerated taint(s). no new claims to deallocate, preemption: 0/6 nodes are available: 1 No preemption victims found for incoming pod, 5 Preemption is not helpful for scheduling."
60.038,TaskRequest,ADDED,eval-sanitize-1-r2-017,phase=Complete job=None
60.0381,TaskRequest,ADDED,eval-sanitize-1-r2-018,phase=Complete job=None
60.0381,TaskRequest,ADDED,eval-sanitize-1-r2-019,phase=Complete job=None
60.0382,TaskRequest,ADDED,eval-sanitize-1-r2-020,phase=Complete job=None
60.0382,TaskRequest,ADDED,eval-sanitize-1-r2-021,phase=Complete job=None
60.0385,Event,ADDED,eval-sanitize-1-r0-027-fjtkj.18d41f278decc228,"reason=FailedScheduling count=None msg=0/6 nodes are available: 1 c_wall violated: 3 conflicting context pair(s) with node memory, 5 node(s) had untolerated taint(s). no new claims to deallocate, preemption: 0/6 nodes are available: 1 No preemption victims found for incoming pod, 5 Preemption is not helpful for scheduling."
60.0387,Event,ADDED,eval-sanitize-1-r0-027-fjtkj.18d41f27ba511b41,"reason=FailedScheduling count=None msg=0/6 nodes are available: 1 c_wall violated: 3 conflicting context pair(s) with node memory, 2 c_wall violated: 2 conflicting context pair(s) with node memory, 3 node(s) had untolerated taint(s). no new claims to deallocate, preemption: 0/6 nodes are available: 3 No preemption victims found for incoming pod, 3 Preemption is not helpful for scheduling."
60.039,Event,ADDED,eval-sanitize-1-r0-033-dp7bb.18d41f2aa76152f8,"reason=FailedScheduling count=None msg=0/6 nodes are available: 1 c_wall violated: 2 conflicting context pair(s) with node memory, 5 node(s) had untolerated taint(s). no new claims to deallocate, preemption: 0/6 nodes are available: 1 No preemption victims found for incoming pod, 5 Preemption is not helpful for scheduling."
60.04,Job,ADDED,eval-sanitize-1-r2-005,
60.0401,TaskRequest,ADDED,eval-sanitize-1-r2-022,phase=Complete job=None
60.0401,TaskRequest,ADDED,eval-sanitize-1-r2-023,phase=Complete job=None
60.0413,Pod,ADDED,eval-sanitize-1-r2-000-d9psq,phase=Succeeded node=kind-worker5
60.0416,Event,ADDED,eval-sanitize-1-r0-034-nw2dw.18d41f2aa916ee11,"reason=FailedScheduling count=None msg=0/6 nodes are available: 1 c_wall violated: 3 conflicting context pair(s) with node memory, 5 node(s) had untolerated taint(s). no new claims to deallocate, preemption: 0/6 nodes are available: 1 No preemption victims found for incoming pod, 5 Preemption is not helpful for scheduling."
60.0418,Event,ADDED,eval-sanitize-1-r0-035-4tnf8.18d41f2aa6b0fc20,"reason=FailedScheduling count=None msg=0/6 nodes are available: 1 c_wall violated: 1 conflicting context pair(s) with node memory, 5 node(s) had untolerated taint(s). no new claims to deallocate, preemption: 0/6 nodes are available: 1 No preemption victims found for incoming pod, 5 Preemption is not helpful for scheduling."
60.0427,Job,ADDED,eval-sanitize-1-r2-006,
60.0428,TaskRequest,ADDED,eval-sanitize-1-r2-024,phase=Complete job=None
60.0428,TaskRequest,ADDED,eval-sanitize-1-r2-025,phase=Complete job=None
60.0429,TaskRequest,ADDED,eval-sanitize-1-r2-026,phase=Complete job=None
60.0429,TaskRequest,ADDED,eval-sanitize-1-r2-027,phase=Complete job=None
60.0429,TaskRequest,ADDED,eval-sanitize-1-r2-028,phase=Complete job=None
60.043,TaskRequest,ADDED,eval-sanitize-1-r2-029,phase=Complete job=None
60.0431,TaskRequest,ADDED,eval-sanitize-1-r2-030,phase=Complete job=None
60.0432,TaskRequest,ADDED,eval-sanitize-1-r2-031,phase=Complete job=None
60.0434,Event,ADDED,eval-sanitize-1-r0-035-4tnf8.18d41f2ac51a4990,"reason=FailedScheduling count=None msg=0/6 nodes are available: 2 c_wall violated: 1 conflicting context pair(s) with node memory, 4 node(s) had untolerated taint(s). no new claims to deallocate, preemption: 0/6 nodes are available: 2 No preemption victims found for incoming pod, 4 Preemption is not helpful for scheduling."
60.0436,Event,ADDED,eval-sanitize-1-r0-036-pmf44.18d41f2aa96ba9aa,"reason=FailedScheduling count=None msg=0/6 nodes are available: 1 c_wall violated: 3 conflicting context pair(s) with node memory, 5 node(s) had untolerated taint(s). no new claims to deallocate, preemption: 0/6 nodes are available: 1 No preemption victims found for incoming pod, 5 Preemption is not helpful for scheduling."
60.0439,Event,ADDED,eval-sanitize-1-r0-041-p92cv.18d41f2ac70eddfd,"reason=FailedScheduling count=None msg=0/6 nodes are available: 1 c_wall violated: 1 conflicting context pair(s) with node memory, 1 c_wall violated: 3 conflicting context pair(s) with node memory, 4 node(s) had untolerated taint(s). no new claims to deallocate, preemption: 0/6 nodes are available: 2 No preemption victims found for incoming pod, 4 Preemption is not helpful for scheduling."
60.0447,Job,ADDED,eval-sanitize-1-r2-007,
60.0464,Pod,ADDED,eval-sanitize-1-r2-001-65npq,phase=Succeeded node=kind-worker3
60.0466,TaskRequest,ADDED,eval-sanitize-1-r2-032,phase=Complete job=None
60.0467,TaskRequest,ADDED,eval-sanitize-1-r2-033,phase=Complete job=None
60.0467,TaskRequest,ADDED,eval-sanitize-1-r2-034,phase=Complete job=None
60.0473,Event,ADDED,eval-sanitize-1-r0-045-q5j2g.18d41f2db8ef6668,"reason=FailedScheduling count=None msg=0/6 nodes are available: 1 c_wall violated: 2 conflicting context pair(s) with node memory, 5 node(s) had untolerated taint(s). no new claims to deallocate, preemption: 0/6 nodes are available: 1 No preemption victims found for incoming pod, 5 Preemption is not helpful for scheduling."
60.0476,Event,ADDED,eval-sanitize-1-r0-045-q5j2g.18d41f2dd7c1f209,"reason=FailedScheduling count=None msg=0/6 nodes are available: 2 c_wall violated: 2 conflicting context pair(s) with node memory, 4 node(s) had untolerated taint(s). no new claims to deallocate, preemption: 0/6 nodes are available: 2 No preemption victims found for incoming pod, 4 Preemption is not helpful for scheduling."
60.0478,Event,ADDED,eval-sanitize-1-r0-045-q5j2g.18d41f2de9a59c78,"reason=FailedScheduling count=None msg=0/6 nodes are available: 1 c_wall violated: 2 conflicting context pair(s) with node memory, 5 node(s) had untolerated taint(s). no new claims to deallocate, preemption: 0/6 nodes are available: 1 No preemption victims found for incoming pod, 5 Preemption is not helpful for scheduling."
60.0492,Pod,ADDED,eval-sanitize-1-r2-002-8p5db,phase=Succeeded node=kind-worker
60.0493,TaskRequest,ADDED,eval-sanitize-1-r2-035,phase=Complete job=None
60.0494,TaskRequest,ADDED,eval-sanitize-1-r2-036,phase=Complete job=None
60.0494,TaskRequest,ADDED,eval-sanitize-1-r2-037,phase=Complete job=None
60.0502,Job,ADDED,eval-sanitize-1-r2-008,
60.0506,Event,ADDED,eval-sanitize-1-r0-047-5cj5r.18d41f2db8429170,"reason=FailedScheduling count=None msg=0/6 nodes are available: 1 c_wall violated: 1 conflicting context pair(s) with node memory, 5 node(s) had untolerated taint(s). no new claims to deallocate, preemption: 0/6 nodes are available: 1 No preemption victims found for incoming pod, 5 Preemption is not helpful for scheduling."
60.0509,Event,ADDED,eval-sanitize-1-r0-047-5cj5r.18d41f2dd9c864e5,"reason=FailedScheduling count=None msg=0/6 nodes are available: 2 c_wall violated: 1 conflicting context pair(s) with node memory, 4 node(s) had untolerated taint(s). no new claims to deallocate, preemption: 0/6 nodes are available: 2 No preemption victims found for incoming pod, 4 Preemption is not helpful for scheduling."
60.0511,Event,ADDED,eval-sanitize-1-r0-047-5cj5r.18d41f2de97778ec,"reason=FailedScheduling count=None msg=0/6 nodes are available: 1 c_wall violated: 1 conflicting context pair(s) with node memory, 5 node(s) had untolerated taint(s). no new claims to deallocate, preemption: 0/6 nodes are available: 1 No preemption victims found for incoming pod, 5 Preemption is not helpful for scheduling."
60.0515,Event,ADDED,eval-sanitize-1-r0-048-2l2zl.18d41f2db876a84a,"reason=FailedScheduling count=None msg=0/6 nodes are available: 1 c_wall violated: 2 conflicting context pair(s) with node memory, 5 node(s) had untolerated taint(s). no new claims to deallocate, preemption: 0/6 nodes are available: 1 No preemption victims found for incoming pod, 5 Preemption is not helpful for scheduling."
60.0518,Event,ADDED,eval-sanitize-1-r0-052-kgdq7.18d41f2db8a03281,"reason=FailedScheduling count=None msg=0/6 nodes are available: 1 c_wall violated: 2 conflicting context pair(s) with node memory, 5 node(s) had untolerated taint(s). no new claims to deallocate, preemption: 0/6 nodes are available: 1 No preemption victims found for incoming pod, 5 Preemption is not helpful for scheduling."
60.052,Event,ADDED,eval-sanitize-1-r0-053-pgppj.18d41f2db8c977f1,"reason=FailedScheduling count=None msg=0/6 nodes are available: 1 c_wall violated: 2 conflicting context pair(s) with node memory, 5 node(s) had untolerated taint(s). no new claims to deallocate, preemption: 0/6 nodes are available: 1 No preemption victims found for incoming pod, 5 Preemption is not helpful for scheduling."
60.0521,TaskRequest,ADDED,eval-sanitize-1-r2-038,phase=Complete job=None
60.0521,TaskRequest,ADDED,eval-sanitize-1-r2-039,phase=Complete job=None
60.0529,Job,ADDED,eval-sanitize-1-r2-009,
60.0541,Pod,ADDED,eval-sanitize-1-r2-003-9x5tt,phase=Succeeded node=kind-worker4
60.0544,Event,ADDED,eval-sanitize-1-r0-055-djfzn.18d41f2e1cab1aa9,"reason=FailedScheduling count=None msg=0/6 nodes are available: 1 c_wall violated: 1 conflicting context pair(s) with node memory, 5 node(s) had untolerated taint(s). no new claims to deallocate, preemption: 0/6 nodes are available: 1 No preemption victims found for incoming pod, 5 Preemption is not helpful for scheduling."
60.0547,Event,ADDED,eval-sanitize-1-r0-057-gwjmb.18d41f2e93302015,"reason=FailedScheduling count=None msg=0/6 nodes are available: 1 c_wall violated: 1 conflicting context pair(s) with node memory, 5 node(s) had untolerated taint(s). no new claims to deallocate, preemption: 0/6 nodes are available: 1 No preemption victims found for incoming pod, 5 Preemption is not helpful for scheduling."
60.0547,TaskRequest,ADDED,eval-sanitize-1-r2-040,phase=Complete job=None
60.0548,TaskRequest,ADDED,eval-sanitize-1-r2-041,phase=Scheduled job=None
60.0548,TaskRequest,ADDED,eval-sanitize-1-r2-042,phase=Complete job=None
60.0559,Job,ADDED,eval-sanitize-1-r2-010,
60.0562,Event,ADDED,eval-sanitize-1-r0-058-gxw45.18d41f311c1b96e6,"reason=FailedScheduling count=None msg=0/6 nodes are available: 1 c_wall violated: 1 conflicting context pair(s) with node memory, 1 c_wall violated: 2 conflicting context pair(s) with node memory, 4 node(s) had untolerated taint(s). no new claims to deallocate, preemption: 0/6 nodes are available: 2 No preemption victims found for incoming pod, 4 Preemption is not helpful for scheduling."
60.0564,Event,ADDED,eval-sanitize-1-r0-058-gxw45.18d41f3175d342fc,"reason=FailedScheduling count=None msg=0/6 nodes are available: 1 c_wall violated: 2 conflicting context pair(s) with node memory, 5 node(s) had untolerated taint(s). no new claims to deallocate, preemption: 0/6 nodes are available: 1 No preemption victims found for incoming pod, 5 Preemption is not helpful for scheduling."
60.0566,Event,ADDED,eval-sanitize-1-r0-060-fs5lb.18d41f3120101964,"reason=FailedScheduling count=None msg=0/6 nodes are available: 1 c_wall violated: 1 conflicting context pair(s) with node memory, 1 c_wall violated: 2 conflicting context pair(s) with node memory, 4 node(s) had untolerated taint(s). no new claims to deallocate, preemption: 0/6 nodes are available: 2 No preemption victims found for incoming pod, 4 Preemption is not helpful for scheduling."
60.0568,TaskRequest,ADDED,eval-sanitize-1-r2-043,phase=Complete job=None
60.0568,TaskRequest,ADDED,eval-sanitize-1-r2-044,phase=Complete job=None
60.0579,Event,ADDED,eval-sanitize-1-r0-060-fs5lb.18d41f31455e336c,"reason=FailedScheduling count=None msg=0/6 nodes are available: 1 c_wall violated: 2 conflicting context pair(s) with node memory, 5 node(s) had untolerated taint(s). no new claims to deallocate, preemption: 0/6 nodes are available: 1 No preemption victims found for incoming pod, 5 Preemption is not helpful for scheduling."
60.0582,Event,ADDED,eval-sanitize-1-r0-060-fs5lb.18d41f317605c516,"reason=FailedScheduling count=None msg=0/6 nodes are available: 1 c_wall violated: 2 conflicting context pair(s) with node memory, 5 node(s) had untolerated taint(s). no new claims to deallocate, preemption: 0/6 nodes are available: 1 No preemption victims found for incoming pod, 5 Preemption is not helpful for scheduling."
60.0585,Event,ADDED,eval-sanitize-1-r0-063-tshsq.18d41f3110139346,"reason=FailedScheduling count=None msg=0/6 nodes are available: 1 c_wall violated: 1 conflicting context pair(s) with node memory, 1 c_wall violated: 2 conflicting context pair(s) with node memory, 4 node(s) had untolerated taint(s). no new claims to deallocate, preemption: 0/6 nodes are available: 2 No preemption victims found for incoming pod, 4 Preemption is not helpful for scheduling."
60.0586,TaskRequest,ADDED,eval-sanitize-1-r2-045,phase=Scheduled job=None
60.0587,TaskRequest,ADDED,eval-sanitize-1-r2-046,phase=Scheduled job=None
60.0587,TaskRequest,ADDED,eval-sanitize-1-r2-047,phase=Scheduled job=None
60.0603,Pod,ADDED,eval-sanitize-1-r2-004-bhlgt,phase=Succeeded node=kind-worker2
60.0612,Job,ADDED,eval-sanitize-1-r2-011,
60.062,Event,ADDED,eval-sanitize-1-r0-063-tshsq.18d41f3145b471b3,"reason=FailedScheduling count=None msg=0/6 nodes are available: 1 c_wall violated: 2 conflicting context pair(s) with node memory, 5 node(s) had untolerated taint(s). no new claims to deallocate, preemption: 0/6 nodes are available: 1 No preemption victims found for incoming pod, 5 Preemption is not helpful for scheduling."
60.0624,Event,ADDED,eval-sanitize-1-r0-063-tshsq.18d41f317634735a,"reason=FailedScheduling count=None msg=0/6 nodes are available: 1 c_wall violated: 2 conflicting context pair(s) with node memory, 5 node(s) had untolerated taint(s). no new claims to deallocate, preemption: 0/6 nodes are available: 1 No preemption victims found for incoming pod, 5 Preemption is not helpful for scheduling."
60.0627,Event,ADDED,eval-sanitize-1-r0-064-ck955.18d41f311064395d,"reason=FailedScheduling count=None msg=0/6 nodes are available: 2 c_wall violated: 2 conflicting context pair(s) with node memory, 4 node(s) had untolerated taint(s). no new claims to deallocate, preemption: 0/6 nodes are available: 2 No preemption victims found for incoming pod, 4 Preemption is not helpful for scheduling."
60.0628,TaskRequest,ADDED,eval-sanitize-1-r2-048,phase=Scheduled job=None
60.0629,TaskRequest,ADDED,eval-sanitize-1-r2-049,phase=Scheduled job=None
60.0629,TaskRequest,ADDED,eval-sanitize-1-r2-050,phase=Scheduled job=None
60.0639,Job,ADDED,eval-sanitize-1-r2-012,
60.0648,Event,ADDED,eval-sanitize-1-r0-064-ck955.18d41f3145e17543,"reason=FailedScheduling count=None msg=0/6 nodes are available: 1 c_wall violated: 2 conflicting context pair(s) with node memory, 5 node(s) had untolerated taint(s). no new claims to deallocate, preemption: 0/6 nodes are available: 1 No preemption victims found for incoming pod, 5 Preemption is not helpful for scheduling."
60.065,Event,ADDED,eval-sanitize-1-r0-065-6v8q6.18d41f3110b80296,"reason=FailedScheduling count=None msg=0/6 nodes are available: 2 c_wall violated: 2 conflicting context pair(s) with node memory, 4 node(s) had untolerated taint(s). no new claims to deallocate, preemption: 0/6 nodes are available: 2 No preemption victims found for incoming pod, 4 Preemption is not helpful for scheduling."
60.0652,Event,ADDED,eval-sanitize-1-r0-065-6v8q6.18d41f314611a257,"reason=FailedScheduling count=None msg=0/6 nodes are available: 1 c_wall violated: 2 conflicting context pair(s) with node memory, 5 node(s) had untolerated taint(s). no new claims to deallocate, preemption: 0/6 nodes are available: 1 No preemption victims found for incoming pod, 5 Preemption is not helpful for scheduling."
60.0653,TaskRequest,ADDED,eval-sanitize-1-r2-051,phase=Scheduled job=None
60.0654,TaskRequest,ADDED,eval-sanitize-1-r2-052,phase=Scheduled job=None
60.0654,TaskRequest,ADDED,eval-sanitize-1-r2-053,phase=Scheduled job=None
60.0668,Pod,ADDED,eval-sanitize-1-r2-005-2bx8m,phase=Succeeded node=kind-worker5
60.0681,Pod,ADDED,eval-sanitize-1-r2-006-hjp5g,phase=Succeeded node=kind-worker5
60.0684,Event,ADDED,eval-sanitize-1-r0-066-gsqwg.18d41f311633513e,"reason=FailedScheduling count=None msg=0/6 nodes are available: 1 c_wall violated: 1 conflicting context pair(s) with node memory, 1 c_wall violated: 2 conflicting context pair(s) with node memory, 4 node(s) had untolerated taint(s). no new claims to deallocate, preemption: 0/6 nodes are available: 2 No preemption victims found for incoming pod, 4 Preemption is not helpful for scheduling."
60.0687,Event,ADDED,eval-sanitize-1-r0-067-h6pnc.18d41f311a34379b,"reason=FailedScheduling count=None msg=0/6 nodes are available: 1 c_wall violated: 1 conflicting context pair(s) with node memory, 1 c_wall violated: 2 conflicting context pair(s) with node memory, 4 node(s) had untolerated taint(s). no new claims to deallocate, preemption: 0/6 nodes are available: 2 No preemption victims found for incoming pod, 4 Preemption is not helpful for scheduling."
60.0687,TaskRequest,ADDED,eval-sanitize-1-r2-054,phase=Scheduled job=None
60.0688,TaskRequest,ADDED,eval-sanitize-1-r2-055,phase=Scheduled job=None
60.0701,Job,ADDED,eval-sanitize-1-r2-013,
60.0709,Job,ADDED,eval-sanitize-1-r2-014,
60.071,TaskRequest,ADDED,eval-sanitize-1-r2-056,phase=Scheduled job=None
60.0711,TaskRequest,ADDED,eval-sanitize-1-r2-057,phase=Scheduled job=None
60.0711,TaskRequest,ADDED,eval-sanitize-1-r2-058,phase=Scheduled job=None
60.0718,Event,ADDED,eval-sanitize-1-r0-068-d8nm2.18d41f3116874714,"reason=FailedScheduling count=None msg=0/6 nodes are available: 2 c_wall violated: 2 conflicting context pair(s) with node memory, 4 node(s) had untolerated taint(s). no new claims to deallocate, preemption: 0/6 nodes are available: 2 No preemption victims found for incoming pod, 4 Preemption is not helpful for scheduling."
60.072,Event,ADDED,eval-sanitize-1-r0-069-cvks5.18d41f3175a6189d,"reason=FailedScheduling count=None msg=0/6 nodes are available: 1 c_wall violated: 1 conflicting context pair(s) with node memory, 5 node(s) had untolerated taint(s). no new claims to deallocate, preemption: 0/6 nodes are available: 1 No preemption victims found for incoming pod, 5 Preemption is not helpful for scheduling."
60.0723,Event,ADDED,eval-sanitize-1-r0-070-lhjss.18d41f317c7ce7be,"reason=FailedScheduling count=None msg=0/6 nodes are available: 1 c_wall violated: 2 conflicting context pair(s) with node memory, 5 node(s) had untolerated taint(s). no new claims to deallocate, preemption: 0/6 nodes are available: 1 No preemption victims found for incoming pod, 5 Preemption is not helpful for scheduling."
60.0738,Pod,ADDED,eval-sanitize-1-r2-007-fzlg7,phase=Succeeded node=kind-worker5
60.075,Pod,ADDED,eval-sanitize-1-r2-008-7hn5w,phase=Succeeded node=kind-worker4
60.076,TaskRequest,ADDED,eval-sanitize-1-r2-059,phase=Scheduled job=None
60.076,TaskRequest,ADDED,eval-sanitize-1-r2-060,phase=Pending job=None
60.0769,Job,ADDED,eval-sanitize-1-r2-015,
60.0772,Event,ADDED,eval-sanitize-1-r0-073-frs5s.18d41f33e431632c,"reason=FailedScheduling count=None msg=0/6 nodes are available: 1 c_wall violated: 2 conflicting context pair(s) with node memory, 5 node(s) had untolerated taint(s). no new claims to deallocate, preemption: 0/6 nodes are available: 1 No preemption victims found for incoming pod, 5 Preemption is not helpful for scheduling."
60.0774,Event,ADDED,eval-sanitize-1-r0-075-qxvn5.18d41f33dee28983,"reason=FailedScheduling count=None msg=0/6 nodes are available: 1 c_wall violated: 1 conflicting context pair(s) with node memory, 5 node(s) had untolerated taint(s). no new claims to deallocate, preemption: 0/6 nodes are available: 1 No preemption victims found for incoming pod, 5 Preemption is not helpful for scheduling."
60.0777,Event,ADDED,eval-sanitize-1-r0-075-qxvn5.18d41f3422dcab91,"reason=FailedScheduling count=None msg=0/6 nodes are available: 1 c_wall violated: 2 conflicting context pair(s) with node memory, 5 node(s) had untolerated taint(s). no new claims to deallocate, preemption: 0/6 nodes are available: 1 No preemption victims found for incoming pod, 5 Preemption is not helpful for scheduling."
60.0789,Pod,ADDED,eval-sanitize-1-r2-009-4dhzg,phase=Succeeded node=kind-worker5
60.0789,TaskRequest,MODIFIED,eval-sanitize-1-r2-060,phase=Scheduled job=None
60.079,TaskRequest,MODIFIED,eval-sanitize-1-r2-060,phase=Scheduled job=None
60.0793,Event,ADDED,eval-sanitize-1-r0-076-b6sl7.18d41f33df07d162,"reason=FailedScheduling count=None msg=0/6 nodes are available: 1 c_wall violated: 1 conflicting context pair(s) with node memory, 5 node(s) had untolerated taint(s). no new claims to deallocate, preemption: 0/6 nodes are available: 1 No preemption victims found for incoming pod, 5 Preemption is not helpful for scheduling."
60.0796,Event,ADDED,eval-sanitize-1-r0-077-rprg7.18d41f33df2f8e13,"reason=FailedScheduling count=None msg=0/6 nodes are available: 1 c_wall violated: 1 conflicting context pair(s) with node memory, 5 node(s) had untolerated taint(s). no new claims to deallocate, preemption: 0/6 nodes are available: 1 No preemption victims found for incoming pod, 5 Preemption is not helpful for scheduling."
60.0798,Event,ADDED,eval-sanitize-1-r0-078-p7p96.18d41f33e394be8d,"reason=FailedScheduling count=None msg=0/6 nodes are available: 1 c_wall violated: 2 conflicting context pair(s) with node memory, 5 node(s) had untolerated taint(s). no new claims to deallocate, preemption: 0/6 nodes are available: 1 No preemption victims found for incoming pod, 5 Preemption is not helpful for scheduling."
60.081,Pod,ADDED,eval-sanitize-1-r2-010-wsghf,phase=Succeeded node=kind-worker5
60.0818,Job,ADDED,eval-sanitize-1-r2-016,
60.0822,Event,ADDED,eval-sanitize-1-r0-079-fgs9f.18d41f33e3d4fce0,"reason=FailedScheduling count=None msg=0/6 nodes are available: 1 c_wall violated: 1 conflicting context pair(s) with node memory, 5 node(s) had untolerated taint(s). no new claims to deallocate, preemption: 0/6 nodes are available: 1 No preemption victims found for incoming pod, 5 Preemption is not helpful for scheduling."
60.0824,Event,ADDED,eval-sanitize-1-r0-080-sbxzs.18d41f33e405bf38,"reason=FailedScheduling count=None msg=0/6 nodes are available: 1 c_wall violated: 1 conflicting context pair(s) with node memory, 5 node(s) had untolerated taint(s). no new claims to deallocate, preemption: 0/6 nodes are available: 1 No preemption victims found for incoming pod, 5 Preemption is not helpful for scheduling."
60.0826,Event,ADDED,eval-sanitize-1-r0-081-78f85.18d41f340b4ed876,"reason=FailedScheduling count=None msg=0/6 nodes are available: 1 c_wall violated: 2 conflicting context pair(s) with node memory, 5 node(s) had untolerated taint(s). no new claims to deallocate, preemption: 0/6 nodes are available: 1 No preemption victims found for incoming pod, 5 Preemption is not helpful for scheduling."
60.0839,Pod,ADDED,eval-sanitize-1-r2-011-5sw64,phase=Succeeded node=kind-worker4
60.0843,Event,ADDED,eval-sanitize-1-r0-082-9hftz.18d41f344746ab5a,"reason=FailedScheduling count=None msg=0/6 nodes are available: 1 c_wall violated: 1 conflicting context pair(s) with node memory, 5 node(s) had untolerated taint(s). no new claims to deallocate, preemption: 0/6 nodes are available: 1 No preemption victims found for incoming pod, 5 Preemption is not helpful for scheduling."
60.0847,Event,ADDED,eval-sanitize-1-r0-082-9hftz.18d41f35b3673492,"reason=FailedScheduling count=None msg=0/6 nodes are available: 1 c_wall violated: 2 conflicting context pair(s) with node memory, 5 node(s) had untolerated taint(s). no new claims to deallocate, preemption: 0/6 nodes are available: 1 No preemption victims found for incoming pod, 5 Preemption is not helpful for scheduling."
60.0855,Job,ADDED,eval-sanitize-1-r2-017,
60.0867,Pod,ADDED,eval-sanitize-1-r2-012-jmcgx,phase=Succeeded node=kind-worker3
60.087,Event,ADDED,eval-sanitize-1-r0-082-9hftz.18d41f35d028d021,"reason=FailedScheduling count=None msg=0/6 nodes are available: 1 c_wall violated: 1 conflicting context pair(s) with node memory, 1 c_wall violated: 2 conflicting context pair(s) with node memory, 4 node(s) had untolerated taint(s). no new claims to deallocate, preemption: 0/6 nodes are available: 2 No preemption victims found for incoming pod, 4 Preemption is not helpful for scheduling."
60.0874,Event,ADDED,eval-sanitize-1-r0-083-brzw2.18d41f35bb145f03,"reason=FailedScheduling count=None msg=0/6 nodes are available: 1 c_wall violated: 3 conflicting context pair(s) with node memory, 5 node(s) had untolerated taint(s). no new claims to deallocate, preemption: 0/6 nodes are available: 1 No preemption victims found for incoming pod, 5 Preemption is not helpful for scheduling."
60.0876,Event,ADDED,eval-sanitize-1-r0-086-5sfbh.18d41f35babb2dd0,"reason=FailedScheduling count=None msg=0/6 nodes are available: 1 c_wall violated: 3 conflicting context pair(s) with node memory, 5 node(s) had untolerated taint(s). no new claims to deallocate, preemption: 0/6 nodes are available: 1 No preemption victims found for incoming pod, 5 Preemption is not helpful for scheduling."
60.0888,Job,ADDED,eval-sanitize-1-r2-018,
60.0897,Job,ADDED,eval-sanitize-1-r2-019,
60.0912,Pod,ADDED,eval-sanitize-1-r2-013-kl8tg,phase=Succeeded node=kind-worker
60.092,Job,ADDED,eval-sanitize-1-r2-020,
60.0926,Event,ADDED,eval-sanitize-1-r0-089-sgfqw.18d41f35e881fa87,"reason=FailedScheduling count=None msg=0/6 nodes are available: 1 c_wall violated: 1 conflicting context pair(s) with node memory, 1 c_wall violated: 2 conflicting context pair(s) with node memory, 4 node(s) had untolerated taint(s). no new claims to deallocate, preemption: 0/6 nodes are available: 2 No preemption victims found for incoming pod, 4 Preemption is not helpful for scheduling."
60.0928,Event,ADDED,eval-sanitize-1-r0-094-ldwkb.18d41f378d3f5258,"reason=FailedScheduling count=None msg=0/6 nodes are available: 1 c_wall violated: 3 conflicting context pair(s) with node memory, 5 node(s) had untolerated taint(s). no new claims to deallocate, preemption: 0/6 nodes are available: 1 No preemption victims found for incoming pod, 5 Preemption is not helpful for scheduling."
60.093,Event,ADDED,eval-sanitize-1-r2-000-d9psq.18d41fb09c7c1b39,reason=Scheduled count=None msg=Successfully assigned compute/eval-sanitize-1-r2-000-d9psq to kind-worker5
60.0943,Pod,ADDED,eval-sanitize-1-r2-014-k7rkd,phase=Succeeded node=kind-worker3
60.0952,Job,ADDED,eval-sanitize-1-r2-021,
60.0956,Event,ADDED,eval-sanitize-1-r2-000-d9psq.18d41fb0b52c66f4,"reason=Pulled count=1 msg=Container image ""busybox:musl"" already present on machine"
60.0959,Event,ADDED,eval-sanitize-1-r2-000-d9psq.18d41fb0b6472bc8,reason=Created count=1 msg=Created container: task
60.0961,Event,ADDED,eval-sanitize-1-r2-000-d9psq.18d41fb0b84a52ef,reason=Started count=1 msg=Started container task
60.0963,Event,ADDED,eval-sanitize-1-r2-000.18d41fb09b979839,reason=SuccessfulCreate count=1 msg=Created pod: eval-sanitize-1-r2-000-d9psq
60.0971,Job,ADDED,eval-sanitize-1-r2-022,
60.0986,Pod,ADDED,eval-sanitize-1-r2-015-tqkls,phase=Succeeded node=kind-worker
60.0989,Event,ADDED,eval-sanitize-1-r2-000.18d41fb3f9b176cc,reason=Completed count=1 msg=Job completed
60.0991,Event,ADDED,eval-sanitize-1-r2-001-65npq.18d41fb0d5c7a3d2,reason=Scheduled count=None msg=Successfully assigned compute/eval-sanitize-1-r2-001-65npq to kind-worker3
60.0993,Event,ADDED,eval-sanitize-1-r2-001-65npq.18d41fb0ef4f0598,"reason=Pulled count=1 msg=Container image ""busybox:musl"" already present on machine"
60.0995,Event,ADDED,eval-sanitize-1-r2-001-65npq.18d41fb0f07a32b1,reason=Created count=1 msg=Created container: task
60.0999,Event,ADDED,eval-sanitize-1-r2-001-65npq.18d41fb0f2961cc6,reason=Started count=1 msg=Started container task
60.1001,Event,ADDED,eval-sanitize-1-r2-001.18d41fb0d50f0885,reason=SuccessfulCreate count=1 msg=Created pod: eval-sanitize-1-r2-001-65npq
60.1003,Event,ADDED,eval-sanitize-1-r2-001.18d41fb415e4044f,reason=Completed count=1 msg=Job completed
60.1014,Pod,ADDED,eval-sanitize-1-r2-016-smvtd,phase=Succeeded node=kind-worker2
60.1024,Job,ADDED,eval-sanitize-1-r2-023,
60.1027,Event,ADDED,eval-sanitize-1-r2-002-8p5db.18d41fb111c91d5a,reason=Scheduled count=None msg=Successfully assigned compute/eval-sanitize-1-r2-002-8p5db to kind-worker
60.1029,Event,ADDED,eval-sanitize-1-r2-002-8p5db.18d41fb12c493c45,"reason=Pulled count=1 msg=Container image ""busybox:musl"" already present on machine"
60.1032,Event,ADDED,eval-sanitize-1-r2-002-8p5db.18d41fb12d583da1,reason=Created count=1 msg=Created container: task
60.1034,Event,ADDED,eval-sanitize-1-r2-002-8p5db.18d41fb12f5a5231,reason=Started count=1 msg=Started container task
60.1037,Event,ADDED,eval-sanitize-1-r2-002.18d41fb111112c57,reason=SuccessfulCreate count=1 msg=Created pod: eval-sanitize-1-r2-002-8p5db
60.1039,Event,ADDED,eval-sanitize-1-r2-002.18d41fb4753d9f68,reason=Completed count=1 msg=Job completed
60.1041,Event,ADDED,eval-sanitize-1-r2-003-9x5tt.18d41fb14dc4b7b8,reason=Scheduled count=None msg=Successfully assigned compute/eval-sanitize-1-r2-003-9x5tt to kind-worker4
60.1043,Event,ADDED,eval-sanitize-1-r2-003-9x5tt.18d41fb168210e74,"reason=Pulled count=1 msg=Container image ""busybox:musl"" already present on machine"
60.1053,Job,ADDED,eval-sanitize-1-r2-024,
60.1066,Pod,ADDED,eval-sanitize-1-r2-017-w6mk9,phase=Succeeded node=kind-worker5
60.1068,Event,ADDED,eval-sanitize-1-r2-003-9x5tt.18d41fb1692a6072,reason=Created count=1 msg=Created container: task
60.1071,Event,ADDED,eval-sanitize-1-r2-003-9x5tt.18d41fb16d25a810,reason=Started count=1 msg=Started container task
60.1073,Event,ADDED,eval-sanitize-1-r2-003.18d41fb14d492ca3,reason=SuccessfulCreate count=1 msg=Created pod: eval-sanitize-1-r2-003-9x5tt
60.1075,Event,ADDED,eval-sanitize-1-r2-003.18d41fb480dc8b33,reason=Completed count=1 msg=Job completed
60.1077,Event,ADDED,eval-sanitize-1-r2-004-bhlgt.18d41fb188925167,reason=Scheduled count=None msg=Successfully assigned compute/eval-sanitize-1-r2-004-bhlgt to kind-worker2
60.1079,Event,ADDED,eval-sanitize-1-r2-004-bhlgt.18d41fb1a2617d6f,"reason=Pulled count=1 msg=Container image ""busybox:musl"" already present on machine"
60.1081,Event,ADDED,eval-sanitize-1-r2-004-bhlgt.18d41fb1a37d1b30,reason=Created count=1 msg=Created container: task
60.1093,Pod,ADDED,eval-sanitize-1-r2-018-4p7vs,phase=Succeeded node=kind-worker2
60.1101,Job,ADDED,eval-sanitize-1-r2-025,
60.1104,Event,ADDED,eval-sanitize-1-r2-004-bhlgt.18d41fb1a578d690,reason=Started count=1 msg=Started container task
60.1106,Event,ADDED,eval-sanitize-1-r2-004.18d41fb18835a719,reason=SuccessfulCreate count=1 msg=Created pod: eval-sanitize-1-r2-004-bhlgt
60.1108,Event,ADDED,eval-sanitize-1-r2-004.18d41fb4d2962d0a,reason=Completed count=1 msg=Job completed
60.111,Event,ADDED,eval-sanitize-1-r2-005-2bx8m.18d41fb1c385c4e2,"reason=FailedScheduling count=None msg=0/6 nodes are available: 6 node(s) had untolerated taint(s). no new claims to deallocate, preemption: 0/6 nodes are available: 6 Preemption is not helpful for scheduling."
60.1112,Event,ADDED,eval-sanitize-1-r2-005-2bx8m.18d41fb3c55231a3,reason=Scheduled count=None msg=Successfully assigned compute/eval-sanitize-1-r2-005-2bx8m to kind-worker5
60.1115,Event,ADDED,eval-sanitize-1-r2-005-2bx8m.18d41fb3e03cdc6e,"reason=Pulled count=1 msg=Container image ""busybox:musl"" already present on machine"
60.1117,Event,ADDED,eval-sanitize-1-r2-005-2bx8m.18d41fb3e19204e5,reason=Created count=1 msg=Created container: task
60.1149,Pod,ADDED,eval-sanitize-1-r2-019-7bqxs,phase=Succeeded node=kind-worker5
60.1152,Event,ADDED,eval-sanitize-1-r2-005-2bx8m.18d41fb3e579a1cb,reason=Started count=1 msg=Started container task
60.1154,Event,ADDED,eval-sanitize-1-r2-005.18d41fb1c3795b2d,reason=SuccessfulCreate count=1 msg=Created pod: eval-sanitize-1-r2-005-2bx8m
60.1156,Event,ADDED,eval-sanitize-1-r2-005.18d41fb703957b82,reason=Completed count=1 msg=Job completed
60.1158,Event,ADDED,eval-sanitize-1-r2-006-hjp5g.18d41fb1ff2758ce,"reason=FailedScheduling count=None msg=0/6 nodes are available: 6 node(s) had untolerated taint(s). no new claims to deallocate, preemption: 0/6 nodes are available: 6 Preemption is not helpful for scheduling."
60.1164,Job,ADDED,eval-sanitize-1-r2-026,
60.118,Pod,ADDED,eval-sanitize-1-r2-020-vzhm2,phase=Succeeded node=kind-worker5
60.1184,Event,ADDED,eval-sanitize-1-r2-006-hjp5g.18d41fb3c5a7db80,reason=Scheduled count=None msg=Successfully assigned compute/eval-sanitize-1-r2-006-hjp5g to kind-worker5
60.1188,Event,ADDED,eval-sanitize-1-r2-006-hjp5g.18d41fb3e1e0afa3,"reason=Pulled count=1 msg=Container image ""busybox:musl"" already present on machine"
60.1194,Event,ADDED,eval-sanitize-1-r2-006-hjp5g.18d41fb3e4a2f712,reason=Created count=1 msg=Created container: task
60.1204,Job,ADDED,eval-sanitize-1-r2-027,
60.1207,Event,ADDED,eval-sanitize-1-r2-006-hjp5g.18d41fb3e7341721,reason=Started count=1 msg=Started container task
60.1209,Event,ADDED,eval-sanitize-1-r2-006.18d41fb1ff1be355,reason=SuccessfulCreate count=1 msg=Created pod: eval-sanitize-1-r2-006-hjp5g
60.1211,Event,ADDED,eval-sanitize-1-r2-006.18d41fb7036c018b,reason=Completed count=1 msg=Job completed
60.1214,Event,ADDED,eval-sanitize-1-r2-007-fzlg7.18d41fb23acd839d,"reason=FailedScheduling count=None msg=0/6 nodes are available: 6 node(s) had untolerated taint(s). no new claims to deallocate, preemption: 0/6 nodes are available: 6 Preemption is not helpful for scheduling."
60.123,Pod,ADDED,eval-sanitize-1-r2-021-mkjc6,phase=Succeeded node=kind-worker3
60.1242,Job,ADDED,eval-sanitize-1-r2-028,
60.1245,Event,ADDED,eval-sanitize-1-r2-007-fzlg7.18d41fb3c5cbf8a9,reason=Scheduled count=None msg=Successfully assigned compute/eval-sanitize-1-r2-007-fzlg7 to kind-worker5
60.1247,Event,ADDED,eval-sanitize-1-r2-007-fzlg7.18d41fb3e20de4bd,"reason=Pulled count=1 msg=Container image ""busybox:musl"" already present on machine"
60.1249,Event,ADDED,eval-sanitize-1-r2-007-fzlg7.18d41fb3e4c9170f,reason=Created count=1 msg=Created container: task
60.1251,Event,ADDED,eval-sanitize-1-r2-007-fzlg7.18d41fb3e734170e,reason=Started count=1 msg=Started container task
60.1265,Pod,ADDED,eval-sanitize-1-r2-022-p9mtd,phase=Succeeded node=kind-worker3
60.1268,Event,ADDED,eval-sanitize-1-r2-007.18d41fb23ac5eca0,reason=SuccessfulCreate count=1 msg=Created pod: eval-sanitize-1-r2-007-fzlg7
60.127,Event,ADDED,eval-sanitize-1-r2-007.18d41fb7025674aa,reason=Completed count=1 msg=Job completed
60.1272,Event,ADDED,eval-sanitize-1-r2-008-7hn5w.18d41fb27690ba09,"reason=FailedScheduling count=None msg=0/6 nodes are available: 6 node(s) had untolerated taint(s). no new claims to deallocate, preemption: 0/6 nodes are available: 6 Preemption is not helpful for scheduling."
60.1283,Pod,ADDED,eval-sanitize-1-r2-023-9f62p,phase=Succeeded node=kind-worker4
60.1291,Job,ADDED,eval-sanitize-1-r2-029,
60.1294,Event,ADDED,eval-sanitize-1-r2-008-7hn5w.18d41fb3c59e1ab2,"reason=FailedScheduling count=None msg=0/6 nodes are available: 1 c_wall violated: 2 conflicting context pair(s) with node memory, 5 node(s) had untolerated taint(s). no new claims to deallocate, preemption: 0/6 nodes are available: 1 No preemption victims found for incoming pod, 5 Preemption is not helpful for scheduling."
60.1296,Event,ADDED,eval-sanitize-1-r2-008-7hn5w.18d41fb3cdb0a001,"reason=FailedScheduling count=None msg=0/6 nodes are available: 1 c_wall violated: 3 conflicting context pair(s) with node memory, 5 node(s) had untolerated taint(s). no new claims to deallocate, preemption: 0/6 nodes are available: 1 No preemption victims found for incoming pod, 5 Preemption is not helpful for scheduling."
60.1298,Event,ADDED,eval-sanitize-1-r2-008-7hn5w.18d41fb3cec3cd7b,"reason=FailedScheduling count=None msg=0/6 nodes are available: 1 c_wall violated: 3 conflicting context pair(s) with node memory, 5 node(s) had untolerated taint(s). no new claims to deallocate, preemption: 0/6 nodes are available: 1 No preemption victims found for incoming pod, 5 Preemption is not helpful for scheduling."
60.1309,Pod,ADDED,eval-sanitize-1-r2-024-49jtx,phase=Succeeded node=kind-worker5
60.1325,Job,ADDED,eval-sanitize-1-r2-030,
60.1329,Event,ADDED,eval-sanitize-1-r2-008-7hn5w.18d41fb3e2b4aae0,"reason=FailedScheduling count=None msg=0/6 nodes are available: 1 c_wall violated: 2 conflicting context pair(s) with node memory, 1 c_wall violated: 3 conflicting context pair(s) with node memory, 4 node(s) had untolerated taint(s). no new claims to deallocate, preemption: 0/6 nodes are available: 2 No preemption victims found for incoming pod, 4 Preemption is not helpful for scheduling."
60.1331,Event,ADDED,eval-sanitize-1-r2-008-7hn5w.18d41fb3e8db4316,"reason=FailedScheduling count=None msg=0/6 nodes are available: 1 c_wall violated: 2 conflicting context pair(s) with node memory, 1 c_wall violated: 3 conflicting context pair(s) with node memory, 4 node(s) had untolerated taint(s). no new claims to deallocate, preemption: 0/6 nodes are available: 2 No preemption victims found for incoming pod, 4 Preemption is not helpful for scheduling."
60.1335,Event,ADDED,eval-sanitize-1-r2-008-7hn5w.18d41fb40c382ef2,"reason=FailedScheduling count=None msg=0/6 nodes are available: 1 c_wall violated: 2 conflicting context pair(s) with node memory, 5 node(s) had untolerated taint(s). no new claims to deallocate, preemption: 0/6 nodes are available: 1 No preemption victims found for incoming pod, 5 Preemption is not helpful for scheduling."
60.1341,Event,ADDED,eval-sanitize-1-r2-008-7hn5w.18d41fb42397f18c,reason=Scheduled count=None msg=Successfully assigned compute/eval-sanitize-1-r2-008-7hn5w to kind-worker4
60.1344,Event,ADDED,eval-sanitize-1-r2-008-7hn5w.18d41fb43ef890af,"reason=Pulled count=1 msg=Container image ""busybox:musl"" already present on machine"
60.1347,Event,ADDED,eval-sanitize-1-r2-008-7hn5w.18d41fb4404de4bf,reason=Created count=1 msg=Created container: task
60.1349,Event,ADDED,eval-sanitize-1-r2-008-7hn5w.18d41fb444a24f89,reason=Started count=1 msg=Started container task
60.1367,Pod,ADDED,eval-sanitize-1-r2-025-2lqh8,phase=Succeeded node=kind-worker5
60.1376,Job,ADDED,eval-sanitize-1-r2-031,
60.1381,Event,ADDED,eval-sanitize-1-r2-008.18d41fb276856e53,reason=SuccessfulCreate count=1 msg=Created pod: eval-sanitize-1-r2-008-7hn5w
60.1384,Event,ADDED,eval-sanitize-1-r2-008.18d41fb789b22d9f,reason=Completed count=1 msg=Job completed
60.1386,Event,ADDED,eval-sanitize-1-r2-009-4dhzg.18d41fb2b25b4ac6,"reason=FailedScheduling count=None msg=0/6 nodes are available: 6 node(s) had untolerated taint(s). no new claims to deallocate, preemption: 0/6 nodes are available: 6 Preemption is not helpful for scheduling."
60.1398,Pod,ADDED,eval-sanitize-1-r2-026-4lgk7,phase=Succeeded node=kind-worker
60.1407,Job,ADDED,eval-sanitize-1-r2-032,
60.141,Event,ADDED,eval-sanitize-1-r2-009-4dhzg.18d41fb3c6c586e5,reason=Scheduled count=None msg=Successfully assigned compute/eval-sanitize-1-r2-009-4dhzg to kind-worker5
60.1412,Event,ADDED,eval-sanitize-1-r2-009-4dhzg.18d41fb3e1c628cc,"reason=Pulled count=1 msg=Container image ""busybox:musl"" already present on machine"
60.1414,Event,ADDED,eval-sanitize-1-r2-009-4dhzg.18d41fb3e3ab2d2f,reason=Created count=1 msg=Created container: task
60.1416,Event,ADDED,eval-sanitize-1-r2-009-4dhzg.18d41fb3e61795b4,reason=Started count=1 msg=Started container task
60.1431,Pod,ADDED,eval-sanitize-1-r2-027-9rnn5,phase=Succeeded node=kind-worker3
60.1434,Event,ADDED,eval-sanitize-1-r2-009.18d41fb2b2515cd8,reason=SuccessfulCreate count=1 msg=Created pod: eval-sanitize-1-r2-009-4dhzg
60.1436,Event,ADDED,eval-sanitize-1-r2-009.18d41fb702391256,reason=Completed count=1 msg=Job completed
60.1438,Event,ADDED,eval-sanitize-1-r2-010-wsghf.18d41fb2edd03934,"reason=FailedScheduling count=None msg=0/6 nodes are available: 6 node(s) had untolerated taint(s). no new claims to deallocate, preemption: 0/6 nodes are available: 6 Preemption is not helpful for scheduling."
60.1439,Event,ADDED,eval-sanitize-1-r2-010-wsghf.18d41fb3c6f3b34c,reason=Scheduled count=None msg=Successfully assigned compute/eval-sanitize-1-r2-010-wsghf to kind-worker5
60.1443,Event,ADDED,eval-sanitize-1-r2-010-wsghf.18d41fb3e22c09c0,"reason=Pulled count=1 msg=Container image ""busybox:musl"" already present on machine"
60.1446,Event,ADDED,eval-sanitize-1-r2-010-wsghf.18d41fb3e53e753d,reason=Created count=1 msg=Created container: task
60.1448,Event,ADDED,eval-sanitize-1-r2-010-wsghf.18d41fb3e757cbf4,reason=Started count=1 msg=Started container task
60.1457,Job,ADDED,eval-sanitize-1-r2-033,
60.1463,Event,ADDED,eval-sanitize-1-r2-010.18d41fb2edc3b85c,reason=SuccessfulCreate count=1 msg=Created pod: eval-sanitize-1-r2-010-wsghf
60.1466,Event,ADDED,eval-sanitize-1-r2-010.18d41fb702e27721,reason=Completed count=1 msg=Job completed
60.1468,Event,ADDED,eval-sanitize-1-r2-011-5sw64.18d41fb3293605f4,"reason=FailedScheduling count=None msg=0/6 nodes are available: 6 node(s) had untolerated taint(s). no new claims to deallocate, preemption: 0/6 nodes are available: 6 Preemption is not helpful for scheduling."
60.1469,Event,ADDED,eval-sanitize-1-r2-011-5sw64.18d41fb3c6e11c93,"reason=FailedScheduling count=None msg=0/6 nodes are available: 1 c_wall violated: 3 conflicting context pair(s) with node memory, 5 node(s) had untolerated taint(s). no new claims to deallocate, preemption: 0/6 nodes are available: 1 No preemption victims found for incoming pod, 5 Preemption is not helpful for scheduling."
60.1482,Pod,ADDED,eval-sanitize-1-r2-028-dp77l,phase=Succeeded node=kind-worker
60.149,Job,ADDED,eval-sanitize-1-r2-034,
60.1494,Event,ADDED,eval-sanitize-1-r2-011-5sw64.18d41fb3ce2f7ff9,"reason=FailedScheduling count=None msg=0/6 nodes are available: 1 c_wall violated: 3 conflicting context pair(s) with node memory, 5 node(s) had untolerated taint(s). no new claims to deallocate, preemption: 0/6 nodes are available: 1 No preemption victims found for incoming pod, 5 Preemption is not helpful for scheduling."
60.1496,Event,ADDED,eval-sanitize-1-r2-011-5sw64.18d41fb3e3682423,"reason=FailedScheduling count=None msg=0/6 nodes are available: 1 c_wall violated: 2 conflicting context pair(s) with node memory, 1 c_wall violated: 3 conflicting context pair(s) with node memory, 4 node(s) had untolerated taint(s). no new claims to deallocate, preemption: 0/6 nodes are available: 2 No preemption victims found for incoming pod, 4 Preemption is not helpful for scheduling."
60.1499,Event,ADDED,eval-sanitize-1-r2-011-5sw64.18d41fb3e921c4f9,"reason=FailedScheduling count=None msg=0/6 nodes are available: 1 c_wall violated: 2 conflicting context pair(s) with node memory, 1 c_wall violated: 3 conflicting context pair(s) with node memory, 4 node(s) had untolerated taint(s). no new claims to deallocate, preemption: 0/6 nodes are available: 2 No preemption victims found for incoming pod, 4 Preemption is not helpful for scheduling."
60.1501,Event,ADDED,eval-sanitize-1-r2-011-5sw64.18d41fb40c61e87b,"reason=FailedScheduling count=None msg=0/6 nodes are available: 1 c_wall violated: 2 conflicting context pair(s) with node memory, 5 node(s) had untolerated taint(s). no new claims to deallocate, preemption: 0/6 nodes are available: 1 No preemption victims found for incoming pod, 5 Preemption is not helpful for scheduling."
60.1504,Event,ADDED,eval-sanitize-1-r2-011-5sw64.18d41fb423c7e51f,reason=Scheduled count=None msg=Successfully assigned compute/eval-sanitize-1-r2-011-5sw64 to kind-worker4
60.1507,Event,ADDED,eval-sanitize-1-r2-011-5sw64.18d41fb43f197b16,"reason=Pulled count=1 msg=Container image ""busybox:musl"" already present on machine"
60.1512,Event,ADDED,eval-sanitize-1-r2-011-5sw64.18d41fb440bc848f,reason=Created count=1 msg=Created container: task
60.1514,Event,ADDED,eval-sanitize-1-r2-011-5sw64.18d41fb444e94adb,reason=Started count=1 msg=Started container task
60.1517,Event,ADDED,eval-sanitize-1-r2-011.18d41fb329299b31,reason=SuccessfulCreate count=1 msg=Created pod: eval-sanitize-1-r2-011-5sw64
60.152,Event,ADDED,eval-sanitize-1-r2-011.18d41fb7899685ba,reason=Completed count=1 msg=Job completed
60.1529,Job,ADDED,eval-sanitize-1-r2-035,
60.1546,Pod,ADDED,eval-sanitize-1-r2-029-gtlx7,phase=Succeeded node=kind-worker
60.1549,Event,ADDED,eval-sanitize-1-r2-012-jmcgx.18d41fb364fdff2b,"reason=FailedScheduling count=None msg=0/6 nodes are available: 6 node(s) had untolerated taint(s). no new claims to deallocate, preemption: 0/6 nodes are available: 6 Preemption is not helpful for scheduling."
60.1551,Event,ADDED,eval-sanitize-1-r2-012-jmcgx.18d41fb3cabe6c3e,"reason=FailedScheduling count=None msg=0/6 nodes are available: 1 c_wall violated: 1 conflicting context pair(s) with node memory, 5 node(s) had untolerated taint(s). no new claims to deallocate, preemption: 0/6 nodes are available: 1 No preemption victims found for incoming pod, 5 Preemption is not helpful for scheduling."
60.1554,Event,ADDED,eval-sanitize-1-r2-012-jmcgx.18d41fb3ce5e5362,"reason=FailedScheduling count=None msg=0/6 nodes are available: 1 c_wall violated: 1 conflicting context pair(s) with node memory, 5 node(s) had untolerated taint(s). no new claims to deallocate, preemption: 0/6 nodes are available: 1 No preemption victims found for incoming pod, 5 Preemption is not helpful for scheduling."
60.1563,Job,ADDED,eval-sanitize-1-r2-036,
60.1577,Pod,ADDED,eval-sanitize-1-r2-030-zdt9c,phase=Succeeded node=kind-worker3
60.158,Event,ADDED,eval-sanitize-1-r2-012-jmcgx.18d41fb3d6f95c56,reason=Scheduled count=None msg=Successfully assigned compute/eval-sanitize-1-r2-012-jmcgx to kind-worker3
60.1582,Event,ADDED,eval-sanitize-1-r2-012-jmcgx.18d41fb3eff433e1,"reason=Pulled count=1 msg=Container image ""busybox:musl"" already present on machine"
60.1584,Event,ADDED,eval-sanitize-1-r2-012-jmcgx.18d41fb3f1286ed5,reason=Created count=1 msg=Created container: task
60.1589,Event,ADDED,eval-sanitize-1-r2-012-jmcgx.18d41fb3f31cd0b7,reason=Started count=1 msg=Started container task
60.159,Event,ADDED,eval-sanitize-1-r2-012.18d41fb364eae792,reason=SuccessfulCreate count=1 msg=Created pod: eval-sanitize-1-r2-012-jmcgx
60.1592,Event,ADDED,eval-sanitize-1-r2-012.18d41fb6e37dd886,reason=Completed count=1 msg=Job completed
60.1595,Event,ADDED,eval-sanitize-1-r2-013-kl8tg.18d41fb3a0a18dc1,"reason=FailedScheduling count=None msg=0/6 nodes are available: 6 node(s) had untolerated taint(s). no new claims to deallocate, preemption: 0/6 nodes are available: 6 Preemption is not helpful for scheduling."
60.1602,Job,ADDED,eval-sanitize-1-r2-037,
60.1615,Pod,ADDED,eval-sanitize-1-r2-031-bbfkd,phase=Succeeded node=kind-worker4
60.1626,Job,ADDED,eval-sanitize-1-r2-038,
60.1637,Pod,ADDED,eval-sanitize-1-r2-032-2q5np,phase=Succeeded node=kind-worker3
60.1639,Event,ADDED,eval-sanitize-1-r2-013-kl8tg.18d41fb3cd2c60c9,"reason=FailedScheduling count=None msg=0/6 nodes are available: 1 c_wall violated: 1 conflicting context pair(s) with node memory, 5 node(s) had untolerated taint(s). no new claims to deallocate, preemption: 0/6 nodes are available: 1 No preemption victims found for incoming pod, 5 Preemption is not helpful for scheduling."
60.1642,Event,ADDED,eval-sanitize-1-r2-013-kl8tg.18d41fb3ce926220,"reason=FailedScheduling count=None msg=0/6 nodes are available: 1 c_wall violated: 1 conflicting context pair(s) with node memory, 5 node(s) had untolerated taint(s). no new claims to deallocate, preemption: 0/6 nodes are available: 1 No preemption victims found for incoming pod, 5 Preemption is not helpful for scheduling."
60.1644,Event,ADDED,eval-sanitize-1-r2-013-kl8tg.18d41fb3de5cf296,"reason=FailedScheduling count=None msg=0/6 nodes are available: 2 c_wall violated: 1 conflicting context pair(s) with node memory, 4 node(s) had untolerated taint(s). no new claims to deallocate, preemption: 0/6 nodes are available: 2 No preemption victims found for incoming pod, 4 Preemption is not helpful for scheduling."
60.1656,Job,ADDED,eval-sanitize-1-r2-039,
60.1659,Event,ADDED,eval-sanitize-1-r2-013-kl8tg.18d41fb40c992774,"reason=FailedScheduling count=None msg=0/6 nodes are available: 1 c_wall violated: 1 conflicting context pair(s) with node memory, 5 node(s) had untolerated taint(s). no new claims to deallocate, preemption: 0/6 nodes are available: 1 No preemption victims found for incoming pod, 5 Preemption is not helpful for scheduling."
60.1661,Event,ADDED,eval-sanitize-1-r2-013-kl8tg.18d41fb423ae7e45,"reason=FailedScheduling count=None msg=0/6 nodes are available: 1 c_wall violated: 1 conflicting context pair(s) with node memory, 5 node(s) had untolerated taint(s). no new claims to deallocate, preemption: 0/6 nodes are available: 1 No preemption victims found for incoming pod, 5 Preemption is not helpful for scheduling."
60.1664,Event,ADDED,eval-sanitize-1-r2-013-kl8tg.18d41fb424dbe7b1,"reason=FailedScheduling count=None msg=0/6 nodes are available: 1 c_wall violated: 1 conflicting context pair(s) with node memory, 5 node(s) had untolerated taint(s). no new claims to deallocate, preemption: 0/6 nodes are available: 1 No preemption victims found for incoming pod, 5 Preemption is not helpful for scheduling."
60.1676,Pod,ADDED,eval-sanitize-1-r2-033-jgr2l,phase=Succeeded node=kind-worker2
60.1684,Job,ADDED,eval-sanitize-1-r2-040,
60.1687,Event,ADDED,eval-sanitize-1-r2-013-kl8tg.18d41fb436526afb,reason=Scheduled count=None msg=Successfully assigned compute/eval-sanitize-1-r2-013-kl8tg to kind-worker
60.1689,Event,ADDED,eval-sanitize-1-r2-013-kl8tg.18d41fb44fe6caf0,"reason=Pulled count=1 msg=Container image ""busybox:musl"" already present on machine"
60.1691,Event,ADDED,eval-sanitize-1-r2-013-kl8tg.18d41fb45169be5d,reason=Created count=1 msg=Created container: task
60.1702,Pod,ADDED,eval-sanitize-1-r2-034-k9rpq,phase=Succeeded node=kind-worker2
60.171,Job,ADDED,eval-sanitize-1-r2-041,
60.1713,Event,ADDED,eval-sanitize-1-r2-013-kl8tg.18d41fb453e8b3c8,reason=Started count=1 msg=Started container task
60.1715,Event,ADDED,eval-sanitize-1-r2-013.18d41fb3a0924ea6,reason=SuccessfulCreate count=1 msg=Created pod: eval-sanitize-1-r2-013-kl8tg
60.1717,Event,ADDED,eval-sanitize-1-r2-013.18d41fb77d9736ff,reason=Completed count=1 msg=Job completed
60.172,Event,ADDED,eval-sanitize-1-r2-014-k7rkd.18d41fb3de2b57b0,reason=Scheduled count=None msg=Successfully assigned compute/eval-sanitize-1-r2-014-k7rkd to kind-worker3
60.1737,Pod,ADDED,eval-sanitize-1-r2-035-cs7wf,phase=Succeeded node=kind-worker5
60.174,Event,ADDED,eval-sanitize-1-r2-014-k7rkd.18d41fb3f554955f,"reason=Pulled count=1 msg=Container image ""busybox:musl"" already present on machine"
60.1742,Event,ADDED,eval-sanitize-1-r2-014-k7rkd.18d41fb3f6680ca9,reason=Created count=1 msg=Created container: task
60.1744,Event,ADDED,eval-sanitize-1-r2-014-k7rkd.18d41fb40067b8b6,reason=Started count=1 msg=Started container task
60.1746,Event,ADDED,eval-sanitize-1-r2-014.18d41fb3dc8e5f35,reason=SuccessfulCreate count=1 msg=Created pod: eval-sanitize-1-r2-014-k7rkd
60.1755,Job,ADDED,eval-sanitize-1-r2-042,
60.1767,Pod,ADDED,eval-sanitize-1-r2-036-9gqr8,phase=Succeeded node=kind-worker3
60.1769,Event,ADDED,eval-sanitize-1-r2-014.18d41fb6e3560ad4,reason=Completed count=1 msg=Job completed
60.1771,Event,ADDED,eval-sanitize-1-r2-015-tqkls.18d41fb41a3e9b05,"reason=FailedScheduling count=None msg=0/6 nodes are available: 6 node(s) had untolerated taint(s). no new claims to deallocate, preemption: 0/6 nodes are available: 6 Preemption is not helpful for scheduling."
60.1773,Event,ADDED,eval-sanitize-1-r2-015-tqkls.18d41fb4245cd06e,"reason=FailedScheduling count=None msg=0/6 nodes are available: 1 c_wall violated: 2 conflicting context pair(s) with node memory, 5 node(s) had untolerated taint(s). no new claims to deallocate, preemption: 0/6 nodes are available: 1 No preemption victims found for incoming pod, 5 Preemption is not helpful for scheduling."
60.1785,Job,ADDED,eval-sanitize-1-r2-043,
60.1788,Event,ADDED,eval-sanitize-1-r2-015-tqkls.18d41fb425204773,"reason=FailedScheduling count=None msg=0/6 nodes are available: 1 c_wall violated: 2 conflicting context pair(s) with node memory, 5 node(s) had untolerated taint(s). no new claims to deallocate, preemption: 0/6 nodes are available: 1 No preemption victims found for incoming pod, 5 Preemption is not helpful for scheduling."
60.179,Event,ADDED,eval-sanitize-1-r2-015-tqkls.18d41fb436f9486e,reason=Scheduled count=None msg=Successfully assigned compute/eval-sanitize-1-r2-015-tqkls to kind-worker
60.1792,Event,ADDED,eval-sanitize-1-r2-015-tqkls.18d41fb4504964cb,"reason=Pulled count=1 msg=Container image ""busybox:musl"" already present on machine"
60.1802,Job,ADDED,eval-sanitize-1-r2-044,
60.1805,Event,ADDED,eval-sanitize-1-r2-015-tqkls.18d41fb451d607cf,reason=Created count=1 msg=Created container: task
60.1807,Event,ADDED,eval-sanitize-1-r2-015-tqkls.18d41fb4543d637e,reason=Started count=1 msg=Started container task
60.1809,Event,ADDED,eval-sanitize-1-r2-015.18d41fb41a3a7b95,reason=SuccessfulCreate count=1 msg=Created pod: eval-sanitize-1-r2-015-tqkls
60.1811,Event,ADDED,eval-sanitize-1-r2-015.18d41fb742670246,reason=Completed count=1 msg=Job completed
60.1825,Pod,ADDED,eval-sanitize-1-r2-037-mxbhp,phase=Succeeded node=kind-worker5
60.1833,Job,ADDED,eval-sanitize-1-r2-045,
60.1835,Event,ADDED,eval-sanitize-1-r2-016-smvtd.18d41fb454f62bce,"reason=FailedScheduling count=None msg=0/6 nodes are available: 2 c_wall violated: 2 conflicting context pair(s) with node memory, 4 node(s) had untolerated taint(s). no new claims to deallocate, preemption: 0/6 nodes are available: 2 No preemption victims found for incoming pod, 4 Preemption is not helpful for scheduling."
60.1838,Event,ADDED,eval-sanitize-1-r2-016-smvtd.18d41fb457eaaf6b,"reason=FailedScheduling count=None msg=0/6 nodes are available: 2 c_wall violated: 2 conflicting context pair(s) with node memory, 4 node(s) had untolerated taint(s). no new claims to deallocate, preemption: 0/6 nodes are available: 2 No preemption victims found for incoming pod, 4 Preemption is not helpful for scheduling."
60.184,Event,ADDED,eval-sanitize-1-r2-016-smvtd.18d41fb4611feb9c,"reason=FailedScheduling count=None msg=0/6 nodes are available: 1 c_wall violated: 2 conflicting context pair(s) with node memory, 5 node(s) had untolerated taint(s). no new claims to deallocate, preemption: 0/6 nodes are available: 1 No preemption victims found for incoming pod, 5 Preemption is not helpful for scheduling."
60.1853,Pod,ADDED,eval-sanitize-1-r2-038-pk954,phase=Succeeded node=kind-worker
60.1859,Job,ADDED,eval-sanitize-1-r2-046,
60.1862,Event,ADDED,eval-sanitize-1-r2-016-smvtd.18d41fb48f6f7966,reason=Scheduled count=None msg=Successfully assigned compute/eval-sanitize-1-r2-016-smvtd to kind-worker2
60.1864,Event,ADDED,eval-sanitize-1-r2-016-smvtd.18d41fb4aa2537b4,"reason=Pulled count=1 msg=Container image ""busybox:musl"" already present on machine"
60.1866,Event,ADDED,eval-sanitize-1-r2-016-smvtd.18d41fb4ab3098a6,reason=Created count=1 msg=Created container: task
60.1868,Event,ADDED,eval-sanitize-1-r2-016-smvtd.18d41fb4aef58b59,reason=Started count=1 msg=Started container task
60.1882,Pod,ADDED,eval-sanitize-1-r2-039-9fqnq,phase=Succeeded node=kind-worker3
60.1897,Pod,ADDED,eval-sanitize-1-r2-040-ztkxk,phase=Succeeded node=kind-worker3
60.1901,Event,ADDED,eval-sanitize-1-r2-016.18d41fb45474a416,reason=SuccessfulCreate count=1 msg=Created pod: eval-sanitize-1-r2-016-smvtd
60.1903,Event,ADDED,eval-sanitize-1-r2-016.18d41fb7da9e8035,reason=Completed count=1 msg=Job completed
60.1905,Event,ADDED,eval-sanitize-1-r2-017-w6mk9.18d41fb48f168e7e,"reason=FailedScheduling count=None msg=0/6 nodes are available: 1 c_wall violated: 1 conflicting context pair(s) with node memory, 5 node(s) had untolerated taint(s). no new claims to deallocate, preemption: 0/6 nodes are available: 1 No preemption victims found for incoming pod, 5 Preemption is not helpful for scheduling."
60.1912,Job,ADDED,eval-sanitize-1-r2-047,
60.1917,Event,ADDED,eval-sanitize-1-r2-017-w6mk9.18d41fb48fdfb5e7,"reason=FailedScheduling count=None msg=0/6 nodes are available: 1 c_wall violated: 1 conflicting context pair(s) with node memory, 5 node(s) had untolerated taint(s). no new claims to deallocate, preemption: 0/6 nodes are available: 1 No preemption victims found for incoming pod, 5 Preemption is not helpful for scheduling."
60.1919,Event,ADDED,eval-sanitize-1-r2-017-w6mk9.18d41fb6b40eca09,reason=Scheduled count=None msg=Successfully assigned compute/eval-sanitize-1-r2-017-w6mk9 to kind-worker5
60.1921,Event,ADDED,eval-sanitize-1-r2-017-w6mk9.18d41fb6cecbfb0a,"reason=Pulled count=1 msg=Container image ""busybox:musl"" already present on machine"
60.1928,Job,ADDED,eval-sanitize-1-r2-048,
60.194,Pod,ADDED,eval-sanitize-1-r2-041-nbq6w,phase=Succeeded node=kind-worker4
60.1943,Event,ADDED,eval-sanitize-1-r2-017-w6mk9.18d41fb6d08a0cb7,reason=Created count=1 msg=Created container: task
60.1946,Event,ADDED,eval-sanitize-1-r2-017-w6mk9.18d41fb6d2effa9e,reason=Started count=1 msg=Started container task
60.1948,Event,ADDED,eval-sanitize-1-r2-017.18d41fb48edcc231,reason=SuccessfulCreate count=1 msg=Created pod: eval-sanitize-1-r2-017-w6mk9
60.1949,Event,ADDED,eval-sanitize-1-r2-017.18d41fba0d036dbf,reason=Completed count=1 msg=Job completed
60.1952,Event,ADDED,eval-sanitize-1-r2-018-4p7vs.18d41fb4cb44b178,reason=Scheduled count=None msg=Successfully assigned compute/eval-sanitize-1-r2-018-4p7vs to kind-worker2
60.1961,Job,ADDED,eval-sanitize-1-r2-049,
60.1963,Event,ADDED,eval-sanitize-1-r2-018-4p7vs.18d41fb4e5799038,"reason=Pulled count=1 msg=Container image ""busybox:musl"" already present on machine"
60.1965,Event,ADDED,eval-sanitize-1-r2-018-4p7vs.18d41fb4e692bada,reason=Created count=1 msg=Created container: task
60.1967,Event,ADDED,eval-sanitize-1-r2-018-4p7vs.18d41fb4e89a1436,reason=Started count=1 msg=Started container task
60.198,Pod,ADDED,eval-sanitize-1-r2-042-fhft6,phase=Succeeded node=kind-worker
60.1988,Job,ADDED,eval-sanitize-1-r2-050,
60.199,Event,ADDED,eval-sanitize-1-r2-018.18d41fb4caac7dd3,reason=SuccessfulCreate count=1 msg=Created pod: eval-sanitize-1-r2-018-4p7vs
60.1993,Event,ADDED,eval-sanitize-1-r2-018.18d41fb81682165b,reason=Completed count=1 msg=Job completed
60.1995,Event,ADDED,eval-sanitize-1-r2-019-7bqxs.18d41fb50699c77e,"reason=FailedScheduling count=None msg=0/6 nodes are available: 6 node(s) had untolerated taint(s). no new claims to deallocate, preemption: 0/6 nodes are available: 6 Preemption is not helpful for scheduling."
60.2006,Pod,ADDED,eval-sanitize-1-r2-043-jdhmk,phase=Succeeded node=kind-worker
60.2019,Pod,ADDED,eval-sanitize-1-r2-044-m2psh,phase=Succeeded node=kind-worker3
60.2022,Event,ADDED,eval-sanitize-1-r2-019-7bqxs.18d41fb6b495b587,reason=Scheduled count=None msg=Successfully assigned compute/eval-sanitize-1-r2-019-7bqxs to kind-worker5
60.2025,Event,ADDED,eval-sanitize-1-r2-019-7bqxs.18d41fb6cff0d841,"reason=Pulled count=1 msg=Container image ""busybox:musl"" already present on machine"
60.2027,Event,ADDED,eval-sanitize-1-r2-019-7bqxs.18d41fb6d1c3c90f,reason=Created count=1 msg=Created container: task
60.2029,Event,ADDED,eval-sanitize-1-r2-019-7bqxs.18d41fb6d667dc1c,reason=Started count=1 msg=Started container task
60.2035,Job,ADDED,eval-sanitize-1-r2-051,
60.2041,Job,ADDED,eval-sanitize-1-r2-052,
60.2044,Event,ADDED,eval-sanitize-1-r2-019.18d41fb5068f1f58,reason=SuccessfulCreate count=1 msg=Created pod: eval-sanitize-1-r2-019-7bqxs
60.2046,Event,ADDED,eval-sanitize-1-r2-019.18d41fba0ca3bb16,reason=Completed count=1 msg=Job completed
60.2048,Event,ADDED,eval-sanitize-1-r2-020-vzhm2.18d41fb5419a706d,"reason=FailedScheduling count=None msg=0/6 nodes are available: 6 node(s) had untolerated taint(s). no new claims to deallocate, preemption: 0/6 nodes are available: 6 Preemption is not helpful for scheduling."
60.205,Event,ADDED,eval-sanitize-1-r2-020-vzhm2.18d41fb6b4f57f76,reason=Scheduled count=None msg=Successfully assigned compute/eval-sanitize-1-r2-020-vzhm2 to kind-worker5
60.2062,Pod,ADDED,eval-sanitize-1-r2-045-jvwch,phase=Succeeded node=kind-worker4
60.2076,Pod,ADDED,eval-sanitize-1-r2-046-9tgn4,phase=Running node=kind-worker2
60.2084,Job,ADDED,eval-sanitize-1-r2-053,
60.2086,Event,ADDED,eval-sanitize-1-r2-020-vzhm2.18d41fb6cfd0e525,"reason=Pulled count=1 msg=Container image ""busybox:musl"" already present on machine"
60.2089,Event,ADDED,eval-sanitize-1-r2-020-vzhm2.18d41fb6d21bc480,reason=Created count=1 msg=Created container: task
60.2091,Event,ADDED,eval-sanitize-1-r2-020-vzhm2.18d41fb6d90c15ac,reason=Started count=1 msg=Started container task
60.2102,Job,ADDED,eval-sanitize-1-r2-054,
60.2105,Event,ADDED,eval-sanitize-1-r2-020.18d41fb5418c9c1e,reason=SuccessfulCreate count=1 msg=Created pod: eval-sanitize-1-r2-020-vzhm2
60.2107,Event,ADDED,eval-sanitize-1-r2-020.18d41fba0bec336c,reason=Completed count=1 msg=Job completed
60.2108,Event,ADDED,eval-sanitize-1-r2-021-mkjc6.18d41fb57e336209,"reason=FailedScheduling count=None msg=0/6 nodes are available: 6 node(s) had untolerated taint(s). no new claims to deallocate, preemption: 0/6 nodes are available: 6 Preemption is not helpful for scheduling."
60.211,Event,ADDED,eval-sanitize-1-r2-021-mkjc6.18d41fb6b4a79538,"reason=FailedScheduling count=None msg=0/6 nodes are available: 1 c_wall violated: 1 conflicting context pair(s) with node memory, 5 node(s) had untolerated taint(s). no new claims to deallocate, preemption: 0/6 nodes are available: 1 No preemption victims found for incoming pod, 5 Preemption is not helpful for scheduling."
60.2122,Pod,ADDED,eval-sanitize-1-r2-047-nwmdw,phase=Succeeded node=kind-worker4
60.2125,Event,ADDED,eval-sanitize-1-r2-021-mkjc6.18d41fb6ba8f0879,"reason=FailedScheduling count=None msg=0/6 nodes are available: 1 c_wall violated: 2 conflicting context pair(s) with node memory, 5 node(s) had untolerated taint(s). no new claims to deallocate, preemption: 0/6 nodes are available: 1 No preemption victims found for incoming pod, 5 Preemption is not helpful for scheduling."
60.2128,Event,ADDED,eval-sanitize-1-r2-021-mkjc6.18d41fb6bfbcccb3,"reason=FailedScheduling count=None msg=0/6 nodes are available: 1 c_wall violated: 2 conflicting context pair(s) with node memory, 5 node(s) had untolerated taint(s). no new claims to deallocate, preemption: 0/6 nodes are available: 1 No preemption victims found for incoming pod, 5 Preemption is not helpful for scheduling."
60.213,Event,ADDED,eval-sanitize-1-r2-021-mkjc6.18d41fb7d1eaab3a,reason=Scheduled count=None msg=Successfully assigned compute/eval-sanitize-1-r2-021-mkjc6 to kind-worker3
60.2142,Pod,ADDED,eval-sanitize-1-r2-048-7zqwg,phase=Succeeded node=kind-worker4
60.2149,Job,ADDED,eval-sanitize-1-r2-055,
60.2152,Event,ADDED,eval-sanitize-1-r2-021-mkjc6.18d41fb7eafcd996,"reason=Pulled count=1 msg=Container image ""busybox:musl"" already present on machine"
60.2154,Event,ADDED,eval-sanitize-1-r2-021-mkjc6.18d41fb7ecb8f9de,reason=Created count=1 msg=Created container: task
60.2156,Event,ADDED,eval-sanitize-1-r2-021-mkjc6.18d41fb7f10d5069,reason=Started count=1 msg=Started container task
60.2157,Event,ADDED,eval-sanitize-1-r2-021.18d41fb57e28bc1c,reason=SuccessfulCreate count=1 msg=Created pod: eval-sanitize-1-r2-021-mkjc6
60.2173,Pod,ADDED,eval-sanitize-1-r2-049-5r5p5,phase=Running node=kind-worker5
60.2179,Job,ADDED,eval-sanitize-1-r2-056,
60.2182,Event,ADDED,eval-sanitize-1-r2-021.18d41fbb17287dcf,reason=Completed count=1 msg=Job completed
60.2184,Event,ADDED,eval-sanitize-1-r2-022-p9mtd.18d41fb5b916597e,"reason=FailedScheduling count=None msg=0/6 nodes are available: 6 node(s) had untolerated taint(s). no new claims to deallocate, preemption: 0/6 nodes are available: 6 Preemption is not helpful for scheduling."
60.2186,Event,ADDED,eval-sanitize-1-r2-022-p9mtd.18d41fb6b55e637a,"reason=FailedScheduling count=None msg=0/6 nodes are available: 1 c_wall violated: 1 conflicting context pair(s) with node memory, 5 node(s) had untolerated taint(s). no new claims to deallocate, preemption: 0/6 nodes are available: 1 No preemption victims found for incoming pod, 5 Preemption is not helpful for scheduling."
60.2197,Pod,ADDED,eval-sanitize-1-r2-050-h7knl,phase=Running node=kind-worker2
60.22,Event,ADDED,eval-sanitize-1-r2-022-p9mtd.18d41fb6baff214a,"reason=FailedScheduling count=None msg=0/6 nodes are available: 1 c_wall violated: 1 conflicting context pair(s) with node memory, 5 node(s) had untolerated taint(s). no new claims to deallocate, preemption: 0/6 nodes are available: 1 No preemption victims found for incoming pod, 5 Preemption is not helpful for scheduling."
60.2202,Event,ADDED,eval-sanitize-1-r2-022-p9mtd.18d41fb7d271856f,reason=Scheduled count=None msg=Successfully assigned compute/eval-sanitize-1-r2-022-p9mtd to kind-worker3
60.2204,Event,ADDED,eval-sanitize-1-r2-022-p9mtd.18d41fb7eba61576,"reason=Pulled count=1 msg=Container image ""busybox:musl"" already present on machine"
60.221,Job,ADDED,eval-sanitize-1-r2-057,
60.2221,Pod,ADDED,eval-sanitize-1-r2-051-w5xsq,phase=Running node=kind-worker
60.2224,Event,ADDED,eval-sanitize-1-r2-022-p9mtd.18d41fb7edf14bde,reason=Created count=1 msg=Created container: task
60.2226,Event,ADDED,eval-sanitize-1-r2-022-p9mtd.18d41fb7f1d78f03,reason=Started count=1 msg=Started container task
60.2228,Event,ADDED,eval-sanitize-1-r2-022.18d41fb5b90f23c2,reason=SuccessfulCreate count=1 msg=Created pod: eval-sanitize-1-r2-022-p9mtd
60.223,Event,ADDED,eval-sanitize-1-r2-022.18d41fbadbb875fb,reason=Completed count=1 msg=Job completed
60.2236,Job,ADDED,eval-sanitize-1-r2-058,
60.2254,Pod,ADDED,eval-sanitize-1-r2-052-75fkh,phase=Running node=kind-worker5
60.2257,Event,ADDED,eval-sanitize-1-r2-023-9f62p.18d41fb5f4b874f7,"reason=FailedScheduling count=None msg=0/6 nodes are available: 6 node(s) had untolerated taint(s). no new claims to deallocate, preemption: 0/6 nodes are available: 6 Preemption is not helpful for scheduling."
60.2259,Event,ADDED,eval-sanitize-1-r2-023-9f62p.18d41fb6b5e78104,"reason=FailedScheduling count=None msg=0/6 nodes are available: 1 c_wall violated: 2 conflicting context pair(s) with node memory, 5 node(s) had untolerated taint(s). no new claims to deallocate, preemption: 0/6 nodes are available: 1 No preemption victims found for incoming pod, 5 Preemption is not helpful for scheduling."
60.2261,Event,ADDED,eval-sanitize-1-r2-023-9f62p.18d41fb6bb32da0e,"reason=FailedScheduling count=None msg=0/6 nodes are available: 1 c_wall violated: 2 conflicting context pair(s) with node memory, 5 node(s) had untolerated taint(s). no new claims to deallocate, preemption: 0/6 nodes are available: 1 No preemption victims found for incoming pod, 5 Preemption is not helpful for scheduling."
60.2263,Event,ADDED,eval-sanitize-1-r2-023-9f62p.18d41fb7d239e9a1,"reason=FailedScheduling count=None msg=0/6 nodes are available: 1 c_wall violated: 1 conflicting context pair(s) with node memory, 5 node(s) had untolerated taint(s). no new claims to deallocate, preemption: 0/6 nodes are available: 1 No preemption victims found for incoming pod, 5 Preemption is not helpful for scheduling."
60.2266,Event,ADDED,eval-sanitize-1-r2-023-9f62p.18d41fb7d81ae92b,"reason=FailedScheduling count=None msg=0/6 nodes are available: 1 c_wall violated: 1 conflicting context pair(s) with node memory, 5 node(s) had untolerated taint(s). no new claims to deallocate, preemption: 0/6 nodes are available: 1 No preemption victims found for incoming pod, 5 Preemption is not helpful for scheduling."
60.2268,Event,ADDED,eval-sanitize-1-r2-023-9f62p.18d41fb8027c65dd,"reason=FailedScheduling count=None msg=0/6 nodes are available: 2 c_wall violated: 1 conflicting context pair(s) with node memory, 4 node(s) had untolerated taint(s). no new claims to deallocate, preemption: 0/6 nodes are available: 2 No preemption victims found for incoming pod, 4 Preemption is not helpful for scheduling."
60.2272,Event,ADDED,eval-sanitize-1-r2-023-9f62p.18d41fb825dbe44a,reason=Scheduled count=None msg=Successfully assigned compute/eval-sanitize-1-r2-023-9f62p to kind-worker4
60.2274,Event,ADDED,eval-sanitize-1-r2-023-9f62p.18d41fb84182f31e,"reason=Pulled count=1 msg=Container image ""busybox:musl"" already present on machine"
60.2276,Event,ADDED,eval-sanitize-1-r2-023-9f62p.18d41fb842f1e105,reason=Created count=1 msg=Created container: task
60.2278,Event,ADDED,eval-sanitize-1-r2-023-9f62p.18d41fb845387f6a,reason=Started count=1 msg=Started container task
60.2284,Job,ADDED,eval-sanitize-1-r2-059,
60.229,Job,ADDED,eval-sanitize-1-r2-060,
60.2294,Event,ADDED,eval-sanitize-1-r2-023.18d41fb5f4a93579,reason=SuccessfulCreate count=1 msg=Created pod: eval-sanitize-1-r2-023-9f62p
60.2297,Event,ADDED,eval-sanitize-1-r2-023.18d41fbb8109d85e,reason=Completed count=1 msg=Job completed
60.23,Event,ADDED,eval-sanitize-1-r2-024-49jtx.18d41fb6301098c5,"reason=FailedScheduling count=None msg=0/6 nodes are available: 6 node(s) had untolerated taint(s). no new claims to deallocate, preemption: 0/6 nodes are available: 6 Preemption is not helpful for scheduling."
60.2311,Pod,ADDED,eval-sanitize-1-r2-053-srw2q,phase=Running node=kind-worker
60.2314,Event,ADDED,eval-sanitize-1-r2-024-49jtx.18d41fb6b6adc380,reason=Scheduled count=None msg=Successfully assigned compute/eval-sanitize-1-r2-024-49jtx to kind-worker5
60.2317,Event,ADDED,eval-sanitize-1-r2-024-49jtx.18d41fb6d11aaa36,"reason=Pulled count=1 msg=Container image ""busybox:musl"" already present on machine"
60.2319,Event,ADDED,eval-sanitize-1-r2-024-49jtx.18d41fb6d31beed7,reason=Created count=1 msg=Created container: task
60.2321,Event,ADDED,eval-sanitize-1-r2-024-49jtx.18d41fb6d90c3e0c,reason=Started count=1 msg=Started container task
60.2327,Job,MODIFIED,eval-sanitize-1-r2-060,
60.2341,Pod,ADDED,eval-sanitize-1-r2-054-gvn48,phase=Running node=kind-worker
60.2343,Event,ADDED,eval-sanitize-1-r2-024.18d41fb6300716f4,reason=SuccessfulCreate count=1 msg=Created pod: eval-sanitize-1-r2-024-49jtx
60.2346,Event,ADDED,eval-sanitize-1-r2-024.18d41fba0c0cc424,reason=Completed count=1 msg=Job completed
60.2348,Event,ADDED,eval-sanitize-1-r2-025-2lqh8.18d41fb66bebca9f,"reason=FailedScheduling count=None msg=0/6 nodes are available: 6 node(s) had untolerated taint(s). no new claims to deallocate, preemption: 0/6 nodes are available: 6 Preemption is not helpful for scheduling."
60.2362,Pod,ADDED,eval-sanitize-1-r2-055-qtc8p,phase=Running node=kind-worker3
60.2369,Job,MODIFIED,eval-sanitize-1-r2-059,
60.2372,Event,ADDED,eval-sanitize-1-r2-025-2lqh8.18d41fb6ba4023d8,reason=Scheduled count=None msg=Successfully assigned compute/eval-sanitize-1-r2-025-2lqh8 to kind-worker5
60.2375,Event,ADDED,eval-sanitize-1-r2-025-2lqh8.18d41fb6d2714998,"reason=Pulled count=1 msg=Container image ""busybox:musl"" already present on machine"
60.2378,Event,ADDED,eval-sanitize-1-r2-025-2lqh8.18d41fb6d3d8d6cd,reason=Created count=1 msg=Created container: task
60.238,Event,ADDED,eval-sanitize-1-r2-025-2lqh8.18d41fb6d5ded2ac,reason=Started count=1 msg=Started container task
60.2396,Pod,ADDED,eval-sanitize-1-r2-056-j4csr,phase=Running node=kind-worker
60.2402,Job,MODIFIED,eval-sanitize-1-r2-059,
60.2414,Job,MODIFIED,eval-sanitize-1-r2-055,
60.2417,Event,ADDED,eval-sanitize-1-r2-025.18d41fb66bd4bb34,reason=SuccessfulCreate count=1 msg=Created pod: eval-sanitize-1-r2-025-2lqh8
60.2419,Event,ADDED,eval-sanitize-1-r2-025.18d41fba0c0c00a1,reason=Completed count=1 msg=Job completed
60.242,Event,ADDED,eval-sanitize-1-r2-026-4lgk7.18d41fb6a7df8e42,"reason=FailedScheduling count=None msg=0/6 nodes are available: 6 node(s) had untolerated taint(s). no new claims to deallocate, preemption: 0/6 nodes are available: 6 Preemption is not helpful for scheduling."
60.2422,Event,ADDED,eval-sanitize-1-r2-026-4lgk7.18d41fb6ba1334be,"reason=FailedScheduling count=None msg=0/6 nodes are available: 1 c_wall violated: 2 conflicting context pair(s) with node memory, 5 node(s) had untolerated taint(s). no new claims to deallocate, preemption: 0/6 nodes are available: 1 No preemption victims found for incoming pod, 5 Preemption is not helpful for scheduling."
60.2436,Pod,ADDED,eval-sanitize-1-r2-057-76m4m,phase=Running node=kind-worker
60.2439,Event,ADDED,eval-sanitize-1-r2-026-4lgk7.18d41fb6bb6321be,"reason=FailedScheduling count=None msg=0/6 nodes are available: 1 c_wall violated: 2 conflicting context pair(s) with node memory, 5 node(s) had untolerated taint(s). no new claims to deallocate, preemption: 0/6 nodes are available: 1 No preemption victims found for incoming pod, 5 Preemption is not helpful for scheduling."
60.2442,Event,ADDED,eval-sanitize-1-r2-026-4lgk7.18d41fb7d2fc60b9,"reason=FailedScheduling count=None msg=0/6 nodes are available: 1 c_wall violated: 2 conflicting context pair(s) with node memory, 5 node(s) had untolerated taint(s). no new claims to deallocate, preemption: 0/6 nodes are available: 1 No preemption victims found for incoming pod, 5 Preemption is not helpful for scheduling."
60.2446,Event,ADDED,eval-sanitize-1-r2-026-4lgk7.18d41fb7d84320c1,"reason=FailedScheduling count=None msg=0/6 nodes are available: 1 c_wall violated: 2 conflicting context pair(s) with node memory, 5 node(s) had untolerated taint(s). no new claims to deallocate, preemption: 0/6 nodes are available: 1 No preemption victims found for incoming pod, 5 Preemption is not helpful for scheduling."
60.2448,Event,ADDED,eval-sanitize-1-r2-026-4lgk7.18d41fb7fff486ae,reason=Scheduled count=None msg=Successfully assigned compute/eval-sanitize-1-r2-026-4lgk7 to kind-worker
60.245,Event,ADDED,eval-sanitize-1-r2-026-4lgk7.18d41fb819257236,"reason=Pulled count=1 msg=Container image ""busybox:musl"" already present on machine"
60.2452,Event,ADDED,eval-sanitize-1-r2-026-4lgk7.18d41fb81ab65395,reason=Created count=1 msg=Created container: task
60.246,Pod,ADDED,eval-sanitize-1-r2-058-l8skl,phase=Pending node=None
60.2466,Job,MODIFIED,eval-sanitize-1-r2-055,
60.2469,Event,ADDED,eval-sanitize-1-r2-026-4lgk7.18d41fb81cac0b79,reason=Started count=1 msg=Started container task
60.2472,Event,ADDED,eval-sanitize-1-r2-026.18d41fb6a7d79078,reason=SuccessfulCreate count=1 msg=Created pod: eval-sanitize-1-r2-026-4lgk7
60.2475,Event,ADDED,eval-sanitize-1-r2-026.18d41fbb39c05166,reason=Completed count=1 msg=Job completed
60.2477,Event,ADDED,eval-sanitize-1-r2-027-9rnn5.18d41fb6e36335fd,"reason=FailedScheduling count=None msg=0/6 nodes are available: 1 c_wall violated: 2 conflicting context pair(s) with node memory, 5 node(s) had untolerated taint(s). no new claims to deallocate, preemption: 0/6 nodes are available: 1 No preemption victims found for incoming pod, 5 Preemption is not helpful for scheduling."
60.2487,Pod,ADDED,eval-sanitize-1-r2-059-fpnp6,phase=Pending node=kind-worker3
60.249,Event,ADDED,eval-sanitize-1-r2-027-9rnn5.18d41fb6e405ff18,"reason=FailedScheduling count=None msg=0/6 nodes are available: 1 c_wall violated: 2 conflicting context pair(s) with node memory, 5 node(s) had untolerated taint(s). no new claims to deallocate, preemption: 0/6 nodes are available: 1 No preemption victims found for incoming pod, 5 Preemption is not helpful for scheduling."
60.2492,Event,ADDED,eval-sanitize-1-r2-027-9rnn5.18d41fb7d2a43371,reason=Scheduled count=None msg=Successfully assigned compute/eval-sanitize-1-r2-027-9rnn5 to kind-worker3
60.2494,Event,ADDED,eval-sanitize-1-r2-027-9rnn5.18d41fb7ebe4f43f,"reason=Pulled count=1 msg=Container image ""busybox:musl"" already present on machine"
60.25,Pod,ADDED,eval-sanitize-1-r2-060-6ckxn,phase=Pending node=None
60.2503,Event,ADDED,eval-sanitize-1-r2-027-9rnn5.18d41fb7ee4b1291,reason=Created count=1 msg=Created container: task
60.2505,Event,ADDED,eval-sanitize-1-r2-027-9rnn5.18d41fb7f1d72fde,reason=Started count=1 msg=Started container task
60.2507,Event,ADDED,eval-sanitize-1-r2-027.18d41fb6e311f8b7,reason=SuccessfulCreate count=1 msg=Created pod: eval-sanitize-1-r2-027-9rnn5
60.2512,Event,ADDED,eval-sanitize-1-r2-027.18d41fbb168ffb9f,reason=Completed count=1 msg=Job completed
60.2517,Event,ADDED,eval-sanitize-1-r2-028-dp77l.18d41fb71ea73cd2,"reason=FailedScheduling count=None msg=0/6 nodes are available: 6 node(s) had untolerated taint(s). no new claims to deallocate, preemption: 0/6 nodes are available: 6 Preemption is not helpful for scheduling."
60.252,Event,ADDED,eval-sanitize-1-r2-028-dp77l.18d41fb7d3a16e48,"reason=FailedScheduling count=None msg=0/6 nodes are available: 1 c_wall violated: 1 conflicting context pair(s) with node memory, 5 node(s) had untolerated taint(s). no new claims to deallocate, preemption: 0/6 nodes are available: 1 No preemption victims found for incoming pod, 5 Preemption is not helpful for scheduling."
60.2522,Event,ADDED,eval-sanitize-1-r2-028-dp77l.18d41fb7d8749a72,"reason=FailedScheduling count=None msg=0/6 nodes are available: 1 c_wall violated: 1 conflicting context pair(s) with node memory, 5 node(s) had untolerated taint(s). no new claims to deallocate, preemption: 0/6 nodes are available: 1 No preemption victims found for incoming pod, 5 Preemption is not helpful for scheduling."
60.2563,Pod,MODIFIED,eval-sanitize-1-r2-060-6ckxn,phase=Pending node=None
60.2566,Event,ADDED,eval-sanitize-1-r2-028-dp77l.18d41fb802262ae0,reason=Scheduled count=None msg=Successfully assigned compute/eval-sanitize-1-r2-028-dp77l to kind-worker
60.2571,Event,ADDED,eval-sanitize-1-r2-028-dp77l.18d41fb81a06f5e4,"reason=Pulled count=1 msg=Container image ""busybox:musl"" already present on machine"
60.2575,Event,ADDED,eval-sanitize-1-r2-028-dp77l.18d41fb81b6bd8c4,reason=Created count=1 msg=Created container: task
60.2587,Pod,MODIFIED,eval-sanitize-1-r2-059-fpnp6,phase=Running node=kind-worker3
60.259,Event,ADDED,eval-sanitize-1-r2-028-dp77l.18d41fb81d5eae6c,reason=Started count=1 msg=Started container task
60.2592,Event,ADDED,eval-sanitize-1-r2-028.18d41fb71ea106af,reason=SuccessfulCreate count=1 msg=Created pod: eval-sanitize-1-r2-028-dp77l
60.2594,Event,ADDED,eval-sanitize-1-r2-028.18d41fbb3b395fcb,reason=Completed count=1 msg=Job completed
60.2596,Event,ADDED,eval-sanitize-1-r2-029-gtlx7.18d41fb75a5cea2c,"reason=FailedScheduling count=None msg=0/6 nodes are available: 6 node(s) had untolerated taint(s). no new claims to deallocate, preemption: 0/6 nodes are available: 6 Preemption is not helpful for scheduling."
60.2599,Event,ADDED,eval-sanitize-1-r2-029-gtlx7.18d41fb7d6087482,"reason=FailedScheduling count=None msg=0/6 nodes are available: 1 c_wall violated: 1 conflicting context pair(s) with node memory, 5 node(s) had untolerated taint(s). no new claims to deallocate, preemption: 0/6 nodes are available: 1 No preemption victims found for incoming pod, 5 Preemption is not helpful for scheduling."
60.2601,Event,ADDED,eval-sanitize-1-r2-029-gtlx7.18d41fb7d89e5b6d,"reason=FailedScheduling count=None msg=0/6 nodes are available: 1 c_wall violated: 1 conflicting context pair(s) with node memory, 5 node(s) had untolerated taint(s). no new claims to deallocate, preemption: 0/6 nodes are available: 1 No preemption victims found for incoming pod, 5 Preemption is not helpful for scheduling."
60.2603,Event,ADDED,eval-sanitize-1-r2-029-gtlx7.18d41fb7fc200067,reason=Scheduled count=None msg=Successfully assigned compute/eval-sanitize-1-r2-029-gtlx7 to kind-worker
60.2615,Pod,MODIFIED,eval-sanitize-1-r2-046-9tgn4,phase=Running node=kind-worker2
60.2619,Event,ADDED,eval-sanitize-1-r2-029-gtlx7.18d41fb8169a57eb,"reason=Pulled count=1 msg=Container image ""busybox:musl"" already present on machine"
60.2622,Event,ADDED,eval-sanitize-1-r2-029-gtlx7.18d41fb81885a27f,reason=Created count=1 msg=Created container: task
60.2625,Event,ADDED,eval-sanitize-1-r2-029-gtlx7.18d41fb81abb31a7,reason=Started count=1 msg=Started container task
60.2627,Event,ADDED,eval-sanitize-1-r2-029.18d41fb75a5280c1,reason=SuccessfulCreate count=1 msg=Created pod: eval-sanitize-1-r2-029-gtlx7
60.2631,Event,ADDED,eval-sanitize-1-r2-029.18d41fbb3a1e5363,reason=Completed count=1 msg=Job completed
60.2633,Event,ADDED,eval-sanitize-1-r2-030-zdt9c.18d41fb7963d9332,"reason=FailedScheduling count=None msg=0/6 nodes are available: 6 node(s) had untolerated taint(s). no new claims to deallocate, preemption: 0/6 nodes are available: 6 Preemption is not helpful for scheduling."
60.2635,Event,ADDED,eval-sanitize-1-r2-030-zdt9c.18d41fb7d8332600,reason=Scheduled count=None msg=Successfully assigned compute/eval-sanitize-1-r2-030-zdt9c to kind-worker3
60.2638,Event,ADDED,eval-sanitize-1-r2-030-zdt9c.18d41fb7f25b8108,"reason=Pulled count=1 msg=Container image ""busybox:musl"" already present on machine"
60.264,Event,ADDED,eval-sanitize-1-r2-030-zdt9c.18d41fb7f39eeda5,reason=Created count=1 msg=Created container: task
60.2642,Event,ADDED,eval-sanitize-1-r2-030-zdt9c.18d41fb7f65cdafc,reason=Started count=1 msg=Started container task
60.2644,Event,ADDED,eval-sanitize-1-r2-030.18d41fb79632297a,reason=SuccessfulCreate count=1 msg=Created pod: eval-sanitize-1-r2-030-zdt9c
60.2647,Event,ADDED,eval-sanitize-1-r2-030.18d41fbb15ed1d5b,reason=Completed count=1 msg=Job completed
60.2649,Event,ADDED,eval-sanitize-1-r2-031-bbfkd.18d41fb7d6a95b60,"reason=FailedScheduling count=None msg=0/6 nodes are available: 1 c_wall violated: 1 conflicting context pair(s) with node memory, 5 node(s) had untolerated taint(s). no new claims to deallocate, preemption: 0/6 nodes are available: 1 No preemption victims found for incoming pod, 5 Preemption is not helpful for scheduling."
60.2651,Event,ADDED,eval-sanitize-1-r2-031-bbfkd.18d41fb7da54ff26,"reason=FailedScheduling count=None msg=0/6 nodes are available: 1 c_wall violated: 1 conflicting context pair(s) with node memory, 5 node(s) had untolerated taint(s). no new claims to deallocate, preemption: 0/6 nodes are available: 1 No preemption victims found for incoming pod, 5 Preemption is not helpful for scheduling."
60.2654,Event,ADDED,eval-sanitize-1-r2-031-bbfkd.18d41fb802241f27,"reason=FailedScheduling count=None msg=0/6 nodes are available: 2 c_wall violated: 1 conflicting context pair(s) with node memory, 4 node(s) had untolerated taint(s). no new claims to deallocate, preemption: 0/6 nodes are available: 2 No preemption victims found for incoming pod, 4 Preemption is not helpful for scheduling."
60.2656,Event,ADDED,eval-sanitize-1-r2-031-bbfkd.18d41fb82695e575,reason=Scheduled count=None msg=Successfully assigned compute/eval-sanitize-1-r2-031-bbfkd to kind-worker4
60.2658,Event,ADDED,eval-sanitize-1-r2-031-bbfkd.18d41fb841c81372,"reason=Pulled count=1 msg=Container image ""busybox:musl"" already present on machine"
60.266,Event,ADDED,eval-sanitize-1-r2-031-bbfkd.18d41fb84348c3d9,reason=Created count=1 msg=Created container: task
60.2663,Event,ADDED,eval-sanitize-1-r2-031-bbfkd.18d41fb845652623,reason=Started count=1 msg=Started container task
60.2665,Event,ADDED,eval-sanitize-1-r2-031.18d41fb7d1ced0e0,reason=SuccessfulCreate count=1 msg=Created pod: eval-sanitize-1-r2-031-bbfkd
60.2667,Event,ADDED,eval-sanitize-1-r2-031.18d41fbb80e863ba,reason=Completed count=1 msg=Job completed
60.2671,Event,ADDED,eval-sanitize-1-r2-032-2q5np.18d41fb80e671f04,reason=Scheduled count=None msg=Successfully assigned compute/eval-sanitize-1-r2-032-2q5np to kind-worker3
60.2673,Event,ADDED,eval-sanitize-1-r2-032-2q5np.18d41fb828654a23,"reason=Pulled count=1 msg=Container image ""busybox:musl"" already present on machine"
60.2675,Event,ADDED,eval-sanitize-1-r2-032-2q5np.18d41fb829683640,reason=Created count=1 msg=Created container: task
60.2678,Event,ADDED,eval-sanitize-1-r2-032-2q5np.18d41fb82b746c2e,reason=Started count=1 msg=Started container task
60.2682,Event,ADDED,eval-sanitize-1-r2-032.18d41fb80d02f440,reason=SuccessfulCreate count=1 msg=Created pod: eval-sanitize-1-r2-032-2q5np
60.2684,Event,ADDED,eval-sanitize-1-r2-032.18d41fbb5252792a,reason=Completed count=1 msg=Job completed
60.2686,Event,ADDED,eval-sanitize-1-r2-033-jgr2l.18d41fb84c1ea644,reason=Scheduled count=None msg=Successfully assigned compute/eval-sanitize-1-r2-033-jgr2l to kind-worker2
60.2688,Event,ADDED,eval-sanitize-1-r2-033-jgr2l.18d41fb8654db9c1,"reason=Pulled count=1 msg=Container image ""busybox:musl"" already present on machine"
60.2691,Event,ADDED,eval-sanitize-1-r2-033-jgr2l.18d41fb8665ec20d,reason=Created count=1 msg=Created container: task
60.2693,Event,ADDED,eval-sanitize-1-r2-033-jgr2l.18d41fb86840c5d9,reason=Started count=1 msg=Started container task
60.2695,Event,ADDED,eval-sanitize-1-r2-033.18d41fb8485ecd86,reason=SuccessfulCreate count=1 msg=Created pod: eval-sanitize-1-r2-033-jgr2l
60.2698,Event,ADDED,eval-sanitize-1-r2-033.18d41fbbd5914b5b,reason=Completed count=1 msg=Job completed
60.27,Event,ADDED,eval-sanitize-1-r2-034-k9rpq.18d41fb884b62ca6,reason=Scheduled count=None msg=Successfully assigned compute/eval-sanitize-1-r2-034-k9rpq to kind-worker2
60.2702,Event,ADDED,eval-sanitize-1-r2-034-k9rpq.18d41fb89d5b5978,"reason=Pulled count=1 msg=Container image ""busybox:musl"" already present on machine"
60.2704,Event,ADDED,eval-sanitize-1-r2-034-k9rpq.18d41fb89e6bea89,reason=Created count=1 msg=Created container: task
60.2706,Event,ADDED,eval-sanitize-1-r2-034-k9rpq.18d41fb8a30e44de,reason=Started count=1 msg=Started container task
60.2708,Event,ADDED,eval-sanitize-1-r2-034.18d41fb88411a052,reason=SuccessfulCreate count=1 msg=Created pod: eval-sanitize-1-r2-034-k9rpq
60.271,Event,ADDED,eval-sanitize-1-r2-034.18d41fbbd2653a38,reason=Completed count=1 msg=Job completed
60.2712,Event,ADDED,eval-sanitize-1-r2-035-cs7wf.18d41fb8bfa48c39,"reason=FailedScheduling count=None msg=0/6 nodes are available: 6 node(s) had untolerated taint(s). no new claims to deallocate, preemption: 0/6 nodes are available: 6 Preemption is not helpful for scheduling."
60.2715,Event,ADDED,eval-sanitize-1-r2-035-cs7wf.18d41fba68444fad,reason=Scheduled count=None msg=Successfully assigned compute/eval-sanitize-1-r2-035-cs7wf to kind-worker5
60.2717,Event,ADDED,eval-sanitize-1-r2-035-cs7wf.18d41fba82282ad7,"reason=Pulled count=1 msg=Container image ""busybox:musl"" already present on machine"
60.2719,Event,ADDED,eval-sanitize-1-r2-035-cs7wf.18d41fba833f8c34,reason=Created count=1 msg=Created container: task
60.2722,Event,ADDED,eval-sanitize-1-r2-035-cs7wf.18d41fba856dc251,reason=Started count=1 msg=Started container task
60.2724,Event,ADDED,eval-sanitize-1-r2-035.18d41fb8bf9eae8c,reason=SuccessfulCreate count=1 msg=Created pod: eval-sanitize-1-r2-035-cs7wf
60.2726,Event,ADDED,eval-sanitize-1-r2-035.18d41fbdc82e0d4a,reason=Completed count=1 msg=Job completed
60.2728,Event,ADDED,eval-sanitize-1-r2-036-9gqr8.18d41fb8fc1bcc49,"reason=FailedScheduling count=None msg=0/6 nodes are available: 6 node(s) had untolerated taint(s). no new claims to deallocate, preemption: 0/6 nodes are available: 6 Preemption is not helpful for scheduling."
60.273,Event,ADDED,eval-sanitize-1-r2-036-9gqr8.18d41fba688d108e,"reason=FailedScheduling count=None msg=0/6 nodes are available: 1 c_wall violated: 1 conflicting context pair(s) with node memory, 5 node(s) had untolerated taint(s). no new claims to deallocate, preemption: 0/6 nodes are available: 1 No preemption victims found for incoming pod, 5 Preemption is not helpful for scheduling."
60.2732,Event,ADDED,eval-sanitize-1-r2-036-9gqr8.18d41fba6dede9ce,"reason=FailedScheduling count=None msg=0/6 nodes are available: 1 c_wall violated: 2 conflicting context pair(s) with node memory, 5 node(s) had untolerated taint(s). no new claims to deallocate, preemption: 0/6 nodes are available: 1 No preemption victims found for incoming pod, 5 Preemption is not helpful for scheduling."
60.2735,Event,ADDED,eval-sanitize-1-r2-036-9gqr8.18d41fba71707c62,"reason=FailedScheduling count=None msg=0/6 nodes are available: 1 c_wall violated: 2 conflicting context pair(s) with node memory, 5 node(s) had untolerated taint(s). no new claims to deallocate, preemption: 0/6 nodes are available: 1 No preemption victims found for incoming pod, 5 Preemption is not helpful for scheduling."
60.2738,Event,ADDED,eval-sanitize-1-r2-036-9gqr8.18d41fbb055f172c,"reason=FailedScheduling count=None msg=0/6 nodes are available: 1 c_wall violated: 1 conflicting context pair(s) with node memory, 5 node(s) had untolerated taint(s). no new claims to deallocate, preemption: 0/6 nodes are available: 1 No preemption victims found for incoming pod, 5 Preemption is not helpful for scheduling."
60.274,Event,ADDED,eval-sanitize-1-r2-036-9gqr8.18d41fbb09b0e2c0,"reason=FailedScheduling count=None msg=0/6 nodes are available: 1 c_wall violated: 1 conflicting context pair(s) with node memory, 5 node(s) had untolerated taint(s). no new claims to deallocate, preemption: 0/6 nodes are available: 1 No preemption victims found for incoming pod, 5 Preemption is not helpful for scheduling."
60.2742,Event,ADDED,eval-sanitize-1-r2-036-9gqr8.18d41fbb24951795,reason=Scheduled count=None msg=Successfully assigned compute/eval-sanitize-1-r2-036-9gqr8 to kind-worker3
60.2746,Event,ADDED,eval-sanitize-1-r2-036-9gqr8.18d41fbb3d3f0d60,"reason=Pulled count=1 msg=Container image ""busybox:musl"" already present on machine"
60.2748,Event,ADDED,eval-sanitize-1-r2-036-9gqr8.18d41fbb3e787780,reason=Created count=1 msg=Created container: task
60.275,Event,ADDED,eval-sanitize-1-r2-036-9gqr8.18d41fbb40a5e4ed,reason=Started count=1 msg=Started container task
60.2752,Event,ADDED,eval-sanitize-1-r2-036.18d41fb8fc1bcc1b,reason=SuccessfulCreate count=1 msg=Created pod: eval-sanitize-1-r2-036-9gqr8
60.2755,Event,ADDED,eval-sanitize-1-r2-036.18d41fbe5b789165,reason=Completed count=1 msg=Job completed
60.2757,Event,ADDED,eval-sanitize-1-r2-037-mxbhp.18d41fb937076735,"reason=FailedScheduling count=None msg=0/6 nodes are available: 6 node(s) had untolerated taint(s). no new claims to deallocate, preemption: 0/6 nodes are available: 6 Preemption is not helpful for scheduling."
60.2759,Event,ADDED,eval-sanitize-1-r2-037-mxbhp.18d41fba694cbcbc,reason=Scheduled count=None msg=Successfully assigned compute/eval-sanitize-1-r2-037-mxbhp to kind-worker5
60.2762,Event,ADDED,eval-sanitize-1-r2-037-mxbhp.18d41fba84e330cf,"reason=Pulled count=1 msg=Container image ""busybox:musl"" already present on machine"
60.2764,Event,ADDED,eval-sanitize-1-r2-037-mxbhp.18d41fba867a430b,reason=Created count=1 msg=Created container: task
60.2766,Event,ADDED,eval-sanitize-1-r2-037-mxbhp.18d41fba8af82ffe,reason=Started count=1 msg=Started container task
60.2768,Event,ADDED,eval-sanitize-1-r2-037.18d41fb936fdbfe3,reason=SuccessfulCreate count=1 msg=Created pod: eval-sanitize-1-r2-037-mxbhp
60.2771,Event,ADDED,eval-sanitize-1-r2-037.18d41fbdc804039b,reason=Completed count=1 msg=Job completed
60.2773,Event,ADDED,eval-sanitize-1-r2-038-pk954.18d41fb973736b21,"reason=FailedScheduling count=None msg=0/6 nodes are available: 6 node(s) had untolerated taint(s). no new claims to deallocate, preemption: 0/6 nodes are available: 6 Preemption is not helpful for scheduling."
60.2775,Event,ADDED,eval-sanitize-1-r2-038-pk954.18d41fba693510e3,"reason=FailedScheduling count=None msg=0/6 nodes are available: 1 c_wall violated: 1 conflicting context pair(s) with node memory, 5 node(s) had untolerated taint(s). no new claims to deallocate, preemption: 0/6 nodes are available: 1 No preemption victims found for incoming pod, 5 Preemption is not helpful for scheduling."
60.2778,Event,ADDED,eval-sanitize-1-r2-038-pk954.18d41fba6e597394,"reason=FailedScheduling count=None msg=0/6 nodes are available: 1 c_wall violated: 1 conflicting context pair(s) with node memory, 5 node(s) had untolerated taint(s). no new claims to deallocate, preemption: 0/6 nodes are available: 1 No preemption victims found for incoming pod, 5 Preemption is not helpful for scheduling."
60.278,Event,ADDED,eval-sanitize-1-r2-038-pk954.18d41fbb0376403a,reason=Scheduled count=None msg=Successfully assigned compute/eval-sanitize-1-r2-038-pk954 to kind-worker
60.2781,Event,ADDED,eval-sanitize-1-r2-038-pk954.18d41fbb1cfce9ac,"reason=Pulled count=1 msg=Container image ""busybox:musl"" already present on machine"
60.2783,Event,ADDED,eval-sanitize-1-r2-038-pk954.18d41fbb1e79a470,reason=Created count=1 msg=Created container: task
60.2786,Event,ADDED,eval-sanitize-1-r2-038-pk954.18d41fbb2457bd65,reason=Started count=1 msg=Started container task
60.2788,Event,ADDED,eval-sanitize-1-r2-038.18d41fb973667779,reason=SuccessfulCreate count=1 msg=Created pod: eval-sanitize-1-r2-038-pk954
60.2789,Event,ADDED,eval-sanitize-1-r2-038.18d41fbe42c722f3,reason=Completed count=1 msg=Job completed
60.2792,Event,ADDED,eval-sanitize-1-r2-039-9fqnq.18d41fb9ae3423f8,"reason=FailedScheduling count=None msg=0/6 nodes are available: 6 node(s) had untolerated taint(s). no new claims to deallocate, preemption: 0/6 nodes are available: 6 Preemption is not helpful for scheduling."
60.2794,Event,ADDED,eval-sanitize-1-r2-039-9fqnq.18d41fba69b2f52c,"reason=FailedScheduling count=None msg=0/6 nodes are available: 1 c_wall violated: 1 conflicting context pair(s) with node memory, 5 node(s) had untolerated taint(s). no new claims to deallocate, preemption: 0/6 nodes are available: 1 No preemption victims found for incoming pod, 5 Preemption is not helpful for scheduling."
60.2796,Event,ADDED,eval-sanitize-1-r2-039-9fqnq.18d41fba6e7eb81d,"reason=FailedScheduling count=None msg=0/6 nodes are available: 1 c_wall violated: 1 conflicting context pair(s) with node memory, 5 node(s) had untolerated taint(s). no new claims to deallocate, preemption: 0/6 nodes are available: 1 No preemption victims found for incoming pod, 5 Preemption is not helpful for scheduling."
60.2799,Event,ADDED,eval-sanitize-1-r2-039-9fqnq.18d41fbb0363e0b0,"reason=FailedScheduling count=None msg=0/6 nodes are available: 1 c_wall violated: 1 conflicting context pair(s) with node memory, 5 node(s) had untolerated taint(s). no new claims to deallocate, preemption: 0/6 nodes are available: 1 No preemption victims found for incoming pod, 5 Preemption is not helpful for scheduling."
60.2802,Event,ADDED,eval-sanitize-1-r2-039-9fqnq.18d41fbb091ceb40,"reason=FailedScheduling count=None msg=0/6 nodes are available: 1 c_wall violated: 1 conflicting context pair(s) with node memory, 5 node(s) had untolerated taint(s). no new claims to deallocate, preemption: 0/6 nodes are available: 1 No preemption victims found for incoming pod, 5 Preemption is not helpful for scheduling."
60.2804,Event,ADDED,eval-sanitize-1-r2-039-9fqnq.18d41fbb1b19c4bd,reason=Scheduled count=None msg=Successfully assigned compute/eval-sanitize-1-r2-039-9fqnq to kind-worker3
60.2806,Event,ADDED,eval-sanitize-1-r2-039-9fqnq.18d41fbb34b86ace,"reason=Pulled count=1 msg=Container image ""busybox:musl"" already present on machine"
60.2809,Event,ADDED,eval-sanitize-1-r2-039-9fqnq.18d41fbb35d9c491,reason=Created count=1 msg=Created container: task
60.2811,Event,ADDED,eval-sanitize-1-r2-039-9fqnq.18d41fbb37e16d9c,reason=Started count=1 msg=Started container task
60.2813,Event,ADDED,eval-sanitize-1-r2-039.18d41fb9ae28d305,reason=SuccessfulCreate count=1 msg=Created pod: eval-sanitize-1-r2-039-9fqnq
60.2817,Event,ADDED,eval-sanitize-1-r2-039.18d41fbe5b99bcf0,reason=Completed count=1 msg=Job completed
60.2819,Event,ADDED,eval-sanitize-1-r2-040-ztkxk.18d41fb9e9c52632,"reason=FailedScheduling count=None msg=0/6 nodes are available: 6 node(s) had untolerated taint(s). no new claims to deallocate, preemption: 0/6 nodes are available: 6 Preemption is not helpful for scheduling."
60.2821,Event,ADDED,eval-sanitize-1-r2-040-ztkxk.18d41fba6a452738,"reason=FailedScheduling count=None msg=0/6 nodes are available: 1 c_wall violated: 2 conflicting context pair(s) with node memory, 5 node(s) had untolerated taint(s). no new claims to deallocate, preemption: 0/6 nodes are available: 1 No preemption victims found for incoming pod, 5 Preemption is not helpful for scheduling."
60.2824,Event,ADDED,eval-sanitize-1-r2-040-ztkxk.18d41fba6eada202,"reason=FailedScheduling count=None msg=0/6 nodes are available: 1 c_wall violated: 2 conflicting context pair(s) with node memory, 5 node(s) had untolerated taint(s). no new claims to deallocate, preemption: 0/6 nodes are available: 1 No preemption victims found for incoming pod, 5 Preemption is not helpful for scheduling."
60.2826,Event,ADDED,eval-sanitize-1-r2-040-ztkxk.18d41fbb03ec80ed,"reason=FailedScheduling count=None msg=0/6 nodes are available: 1 c_wall violated: 1 conflicting context pair(s) with node memory, 5 node(s) had untolerated taint(s). no new claims to deallocate, preemption: 0/6 nodes are available: 1 No preemption victims found for incoming pod, 5 Preemption is not helpful for scheduling."
60.2828,Event,ADDED,eval-sanitize-1-r2-040-ztkxk.18d41fbb09551f84,"reason=FailedScheduling count=None msg=0/6 nodes are available: 1 c_wall violated: 1 conflicting context pair(s) with node memory, 5 node(s) had untolerated taint(s). no new claims to deallocate, preemption: 0/6 nodes are available: 1 No preemption victims found for incoming pod, 5 Preemption is not helpful for scheduling."
60.283,Event,ADDED,eval-sanitize-1-r2-040-ztkxk.18d41fbb1efc38fe,reason=Scheduled count=None msg=Successfully assigned compute/eval-sanitize-1-r2-040-ztkxk to kind-worker3
60.2833,Event,ADDED,eval-sanitize-1-r2-040-ztkxk.18d41fbb37152b64,"reason=Pulled count=1 msg=Container image ""busybox:musl"" already present on machine"
60.2835,Event,ADDED,eval-sanitize-1-r2-040-ztkxk.18d41fbb387927ba,reason=Created count=1 msg=Created container: task
60.2837,Event,ADDED,eval-sanitize-1-r2-040-ztkxk.18d41fbb3bf027fe,reason=Started count=1 msg=Started container task
60.284,Event,ADDED,eval-sanitize-1-r2-040.18d41fb9e9b3e14a,reason=SuccessfulCreate count=1 msg=Created pod: eval-sanitize-1-r2-040-ztkxk
60.2843,Event,ADDED,eval-sanitize-1-r2-040.18d41fbe20c85957,reason=Completed count=1 msg=Job completed
60.2846,Event,ADDED,eval-sanitize-1-r2-041-nbq6w.18d41fba2554484c,"reason=FailedScheduling count=None msg=0/6 nodes are available: 6 node(s) had untolerated taint(s). no new claims to deallocate, preemption: 0/6 nodes are available: 6 Preemption is not helpful for scheduling."
60.2848,Event,ADDED,eval-sanitize-1-r2-041-nbq6w.18d41fba6ab5b051,"reason=FailedScheduling count=None msg=0/6 nodes are available: 1 c_wall violated: 1 conflicting context pair(s) with node memory, 5 node(s) had untolerated taint(s). no new claims to deallocate, preemption: 0/6 nodes are available: 1 No preemption victims found for incoming pod, 5 Preemption is not helpful for scheduling."
60.2851,Event,ADDED,eval-sanitize-1-r2-041-nbq6w.18d41fba6fd0a379,"reason=FailedScheduling count=None msg=0/6 nodes are available: 1 c_wall violated: 1 conflicting context pair(s) with node memory, 5 node(s) had untolerated taint(s). no new claims to deallocate, preemption: 0/6 nodes are available: 1 No preemption victims found for incoming pod, 5 Preemption is not helpful for scheduling."
60.2853,Event,ADDED,eval-sanitize-1-r2-041-nbq6w.18d41fbb047d3284,"reason=FailedScheduling count=None msg=0/6 nodes are available: 1 c_wall violated: 1 conflicting context pair(s) with node memory, 5 node(s) had untolerated taint(s). no new claims to deallocate, preemption: 0/6 nodes are available: 1 No preemption victims found for incoming pod, 5 Preemption is not helpful for scheduling."
60.2857,Event,ADDED,eval-sanitize-1-r2-041-nbq6w.18d41fbb09842783,"reason=FailedScheduling count=None msg=0/6 nodes are available: 1 c_wall violated: 1 conflicting context pair(s) with node memory, 5 node(s) had untolerated taint(s). no new claims to deallocate, preemption: 0/6 nodes are available: 1 No preemption victims found for incoming pod, 5 Preemption is not helpful for scheduling."
60.2859,Event,ADDED,eval-sanitize-1-r2-041-nbq6w.18d41fbb2a3b5220,"reason=FailedScheduling count=None msg=0/6 nodes are available: 2 c_wall violated: 1 conflicting context pair(s) with node memory, 4 node(s) had untolerated taint(s). no new claims to deallocate, preemption: 0/6 nodes are available: 2 No preemption victims found for incoming pod, 4 Preemption is not helpful for scheduling."
60.2861,Event,ADDED,eval-sanitize-1-r2-041-nbq6w.18d41fbb4b283041,"reason=FailedScheduling count=None msg=0/6 nodes are available: 1 c_wall violated: 1 conflicting context pair(s) with node memory, 5 node(s) had untolerated taint(s). no new claims to deallocate, preemption: 0/6 nodes are available: 1 No preemption victims found for incoming pod, 5 Preemption is not helpful for scheduling."
60.2863,Event,ADDED,eval-sanitize-1-r2-041-nbq6w.18d41fbb7a4368bf,reason=Scheduled count=None msg=Successfully assigned compute/eval-sanitize-1-r2-041-nbq6w to kind-worker4
60.2868,Event,ADDED,eval-sanitize-1-r2-041-nbq6w.18d41fbb93622c97,"reason=Pulled count=1 msg=Container image ""busybox:musl"" already present on machine"
60.287,Event,ADDED,eval-sanitize-1-r2-041-nbq6w.18d41fbb9490c784,reason=Created count=1 msg=Created container: task
60.2872,Event,ADDED,eval-sanitize-1-r2-041-nbq6w.18d41fbb98886a07,reason=Started count=1 msg=Started container task
60.2877,Event,ADDED,eval-sanitize-1-r2-041.18d41fba254f48c7,reason=SuccessfulCreate count=1 msg=Created pod: eval-sanitize-1-r2-041-nbq6w
60.2879,Event,ADDED,eval-sanitize-1-r2-042-fhft6.18d41fba6109c1c8,"reason=FailedScheduling count=None msg=0/6 nodes are available: 6 node(s) had untolerated taint(s). no new claims to deallocate, preemption: 0/6 nodes are available: 6 Preemption is not helpful for scheduling."
60.2881,Event,ADDED,eval-sanitize-1-r2-042-fhft6.18d41fba6d7adf64,"reason=FailedScheduling count=None msg=0/6 nodes are available: 1 c_wall violated: 1 conflicting context pair(s) with node memory, 5 node(s) had untolerated taint(s). no new claims to deallocate, preemption: 0/6 nodes are available: 1 No preemption victims found for incoming pod, 5 Preemption is not helpful for scheduling."
60.2884,Event,ADDED,eval-sanitize-1-r2-042-fhft6.18d41fba700086d1,"reason=FailedScheduling count=None msg=0/6 nodes are available: 1 c_wall violated: 1 conflicting context pair(s) with node memory, 5 node(s) had untolerated taint(s). no new claims to deallocate, preemption: 0/6 nodes are available: 1 No preemption victims found for incoming pod, 5 Preemption is not helpful for scheduling."
60.2886,Event,ADDED,eval-sanitize-1-r2-042-fhft6.18d41fbb053de1ef,reason=Scheduled count=None msg=Successfully assigned compute/eval-sanitize-1-r2-042-fhft6 to kind-worker
60.2888,Event,ADDED,eval-sanitize-1-r2-042-fhft6.18d41fbb1de69e69,"reason=Pulled count=1 msg=Container image ""busybox:musl"" already present on machine"
60.2889,Event,ADDED,eval-sanitize-1-r2-042-fhft6.18d41fbb1fa3b8f4,reason=Created count=1 msg=Created container: task
60.2893,Event,ADDED,eval-sanitize-1-r2-042-fhft6.18d41fbb2457bd61,reason=Started count=1 msg=Started container task
60.2895,Event,ADDED,eval-sanitize-1-r2-042.18d41fba60fd12f8,reason=SuccessfulCreate count=1 msg=Created pod: eval-sanitize-1-r2-042-fhft6
60.2897,Event,ADDED,eval-sanitize-1-r2-042.18d41fbe43378ce4,reason=Completed count=1 msg=Job completed
60.2903,Event,ADDED,eval-sanitize-1-r2-043-jdhmk.18d41fba9ca250f1,"reason=FailedScheduling count=None msg=0/6 nodes are available: 1 c_wall violated: 1 conflicting context pair(s) with node memory, 5 node(s) had untolerated taint(s). no new claims to deallocate, preemption: 0/6 nodes are available: 1 No preemption victims found for incoming pod, 5 Preemption is not helpful for scheduling."
60.2907,Event,ADDED,eval-sanitize-1-r2-043-jdhmk.18d41fba9d4086e0,"reason=FailedScheduling count=None msg=0/6 nodes are available: 1 c_wall violated: 1 conflicting context pair(s) with node memory, 5 node(s) had untolerated taint(s). no new claims to deallocate, preemption: 0/6 nodes are available: 1 No preemption victims found for incoming pod, 5 Preemption is not helpful for scheduling."
60.2909,Event,ADDED,eval-sanitize-1-r2-043-jdhmk.18d41fbb0595a351,reason=Scheduled count=None msg=Successfully assigned compute/eval-sanitize-1-r2-043-jdhmk to kind-worker
60.291,Event,ADDED,eval-sanitize-1-r2-043-jdhmk.18d41fbb1fb001bc,"reason=Pulled count=1 msg=Container image ""busybox:musl"" already present on machine"
60.2913,Event,ADDED,eval-sanitize-1-r2-043-jdhmk.18d41fbb212b702b,reason=Created count=1 msg=Created container: task
60.2915,Event,ADDED,eval-sanitize-1-r2-043-jdhmk.18d41fbb2381fd9f,reason=Started count=1 msg=Started container task
60.2917,Event,ADDED,eval-sanitize-1-r2-043.18d41fba9c5a4467,reason=SuccessfulCreate count=1 msg=Created pod: eval-sanitize-1-r2-043-jdhmk
60.292,Event,ADDED,eval-sanitize-1-r2-043.18d41fbe43c5167c,reason=Completed count=1 msg=Job completed
60.2922,Event,ADDED,eval-sanitize-1-r2-044-m2psh.18d41fbad81c2a73,"reason=FailedScheduling count=None msg=0/6 nodes are available: 6 node(s) had untolerated taint(s). no new claims to deallocate, preemption: 0/6 nodes are available: 6 Preemption is not helpful for scheduling."
60.2924,Event,ADDED,eval-sanitize-1-r2-044-m2psh.18d41fbb08691559,"reason=FailedScheduling count=None msg=0/6 nodes are available: 1 c_wall violated: 1 conflicting context pair(s) with node memory, 5 node(s) had untolerated taint(s). no new claims to deallocate, preemption: 0/6 nodes are available: 1 No preemption victims found for incoming pod, 5 Preemption is not helpful for scheduling."
60.2926,Event,ADDED,eval-sanitize-1-r2-044-m2psh.18d41fbb0ac9c693,"reason=FailedScheduling count=None msg=0/6 nodes are available: 1 c_wall violated: 1 conflicting context pair(s) with node memory, 5 node(s) had untolerated taint(s). no new claims to deallocate, preemption: 0/6 nodes are available: 1 No preemption victims found for incoming pod, 5 Preemption is not helpful for scheduling."
60.2929,Event,ADDED,eval-sanitize-1-r2-044-m2psh.18d41fbb26c5d443,reason=Scheduled count=None msg=Successfully assigned compute/eval-sanitize-1-r2-044-m2psh to kind-worker3
60.2931,Event,ADDED,eval-sanitize-1-r2-044-m2psh.18d41fbb3eb828e5,"reason=Pulled count=1 msg=Container image ""busybox:musl"" already present on machine"
60.2933,Event,ADDED,eval-sanitize-1-r2-044-m2psh.18d41fbb3fde9b42,reason=Created count=1 msg=Created container: task
60.2936,Event,ADDED,eval-sanitize-1-r2-044-m2psh.18d41fbb41e97f94,reason=Started count=1 msg=Started container task
60.2938,Event,ADDED,eval-sanitize-1-r2-044.18d41fbad810927f,reason=SuccessfulCreate count=1 msg=Created pod: eval-sanitize-1-r2-044-m2psh
60.294,Event,ADDED,eval-sanitize-1-r2-044.18d41fbe214ea8e1,reason=Completed count=1 msg=Job completed
60.2941,Event,ADDED,eval-sanitize-1-r2-045-jvwch.18d41fbb14821e7d,"reason=FailedScheduling count=None msg=0/6 nodes are available: 1 c_wall violated: 1 conflicting context pair(s) with node memory, 5 node(s) had untolerated taint(s). no new claims to deallocate, preemption: 0/6 nodes are available: 1 No preemption victims found for incoming pod, 5 Preemption is not helpful for scheduling."
60.2944,Event,ADDED,eval-sanitize-1-r2-045-jvwch.18d41fbb15a7bb8e,"reason=FailedScheduling count=None msg=0/6 nodes are available: 1 c_wall violated: 1 conflicting context pair(s) with node memory, 5 node(s) had untolerated taint(s). no new claims to deallocate, preemption: 0/6 nodes are available: 1 No preemption victims found for incoming pod, 5 Preemption is not helpful for scheduling."
60.2947,Event,ADDED,eval-sanitize-1-r2-045-jvwch.18d41fbb26d7f91d,"reason=FailedScheduling count=None msg=0/6 nodes are available: 2 c_wall violated: 1 conflicting context pair(s) with node memory, 4 node(s) had untolerated taint(s). no new claims to deallocate, preemption: 0/6 nodes are available: 2 No preemption victims found for incoming pod, 4 Preemption is not helpful for scheduling."
60.295,Event,ADDED,eval-sanitize-1-r2-045-jvwch.18d41fbb4b4d8766,"reason=FailedScheduling count=None msg=0/6 nodes are available: 1 c_wall violated: 1 conflicting context pair(s) with node memory, 5 node(s) had untolerated taint(s). no new claims to deallocate, preemption: 0/6 nodes are available: 1 No preemption victims found for incoming pod, 5 Preemption is not helpful for scheduling."
60.2952,Event,ADDED,eval-sanitize-1-r2-045-jvwch.18d41fbb7932550b,reason=Scheduled count=None msg=Successfully assigned compute/eval-sanitize-1-r2-045-jvwch to kind-worker4
60.2955,Event,ADDED,eval-sanitize-1-r2-045-jvwch.18d41fbb9299b288,"reason=Pulled count=1 msg=Container image ""busybox:musl"" already present on machine"
60.2958,Event,ADDED,eval-sanitize-1-r2-045-jvwch.18d41fbb93e56789,reason=Created count=1 msg=Created container: task
60.2961,Event,ADDED,eval-sanitize-1-r2-045-jvwch.18d41fbb9888487c,reason=Started count=1 msg=Started container task
60.2963,Event,ADDED,eval-sanitize-1-r2-045.18d41fbb137c0b15,reason=SuccessfulCreate count=1 msg=Created pod: eval-sanitize-1-r2-045-jvwch
60.2965,Event,ADDED,eval-sanitize-1-r2-046-9tgn4.18d41fbb4f571505,"reason=FailedScheduling count=None msg=0/6 nodes are available: 1 c_wall violated: 2 conflicting context pair(s) with node memory, 5 node(s) had untolerated taint(s). no new claims to deallocate, preemption: 0/6 nodes are available: 1 No preemption victims found for incoming pod, 5 Preemption is not helpful for scheduling."
60.2968,Event,ADDED,eval-sanitize-1-r2-046-9tgn4.18d41fbb4ff73e73,"reason=FailedScheduling count=None msg=0/6 nodes are available: 1 c_wall violated: 2 conflicting context pair(s) with node memory, 5 node(s) had untolerated taint(s). no new claims to deallocate, preemption: 0/6 nodes are available: 1 No preemption victims found for incoming pod, 5 Preemption is not helpful for scheduling."
60.2971,Event,ADDED,eval-sanitize-1-r2-046-9tgn4.18d41fbb7a3fd277,"reason=FailedScheduling count=None msg=0/6 nodes are available: 1 c_wall violated: 1 conflicting context pair(s) with node memory, 1 c_wall violated: 2 conflicting context pair(s) with node memory, 4 node(s) had untolerated taint(s). no new claims to deallocate, preemption: 0/6 nodes are available: 2 No preemption victims found for incoming pod, 4 Preemption is not helpful for scheduling."
60.2973,Event,ADDED,eval-sanitize-1-r2-046-9tgn4.18d41fbb802ec5f0,"reason=FailedScheduling count=None msg=0/6 nodes are available: 1 c_wall violated: 1 conflicting context pair(s) with node memory, 5 node(s) had untolerated taint(s). no new claims to deallocate, preemption: 0/6 nodes are available: 1 No preemption victims found for incoming pod, 5 Preemption is not helpful for scheduling."
60.2976,Event,ADDED,eval-sanitize-1-r2-046-9tgn4.18d41fbb8c4d2cf8,"reason=FailedScheduling count=None msg=0/6 nodes are available: 1 c_wall violated: 2 conflicting context pair(s) with node memory, 5 node(s) had untolerated taint(s). no new claims to deallocate, preemption: 0/6 nodes are available: 1 No preemption victims found for incoming pod, 5 Preemption is not helpful for scheduling."
60.2977,Event,ADDED,eval-sanitize-1-r2-046-9tgn4.18d41fbbf0e9fcb3,reason=Scheduled count=None msg=Successfully assigned compute/eval-sanitize-1-r2-046-9tgn4 to kind-worker2
60.2979,Event,ADDED,eval-sanitize-1-r2-046-9tgn4.18d41fbc0ab131fb,"reason=Pulled count=1 msg=Container image ""busybox:musl"" already present on machine"
60.2981,Event,ADDED,eval-sanitize-1-r2-046-9tgn4.18d41fbc0bb56b3a,reason=Created count=1 msg=Created container: task
60.2984,Event,ADDED,eval-sanitize-1-r2-046-9tgn4.18d41fbc0f05802f,reason=Started count=1 msg=Started container task
60.2986,Event,ADDED,eval-sanitize-1-r2-046.18d41fbb4f19a834,reason=SuccessfulCreate count=1 msg=Created pod: eval-sanitize-1-r2-046-9tgn4
60.2987,Event,ADDED,eval-sanitize-1-r2-047-nwmdw.18d41fbb8b45e684,reason=Scheduled count=None msg=Successfully assigned compute/eval-sanitize-1-r2-047-nwmdw to kind-worker4
60.299,Event,ADDED,eval-sanitize-1-r2-047-nwmdw.18d41fbba43ca9f4,"reason=Pulled count=1 msg=Container image ""busybox:musl"" already present on machine"
60.2992,Event,ADDED,eval-sanitize-1-r2-047-nwmdw.18d41fbba54cd60a,reason=Created count=1 msg=Created container: task
60.2993,Event,ADDED,eval-sanitize-1-r2-047-nwmdw.18d41fbba7393408,reason=Started count=1 msg=Started container task
60.2995,Event,ADDED,eval-sanitize-1-r2-047.18d41fbb8abe7804,reason=SuccessfulCreate count=1 msg=Created pod: eval-sanitize-1-r2-047-nwmdw
60.2997,Event,ADDED,eval-sanitize-1-r2-048-7zqwg.18d41fbbc6f5a172,reason=Scheduled count=None msg=Successfully assigned compute/eval-sanitize-1-r2-048-7zqwg to kind-worker4
60.2999,Event,ADDED,eval-sanitize-1-r2-048-7zqwg.18d41fbbe014fc10,"reason=Pulled count=1 msg=Container image ""busybox:musl"" already present on machine"
60.3001,Event,ADDED,eval-sanitize-1-r2-048-7zqwg.18d41fbbe1212293,reason=Created count=1 msg=Created container: task
60.3003,Event,ADDED,eval-sanitize-1-r2-048-7zqwg.18d41fbbe422a022,reason=Started count=1 msg=Started container task
60.3004,Event,ADDED,eval-sanitize-1-r2-048.18d41fbbc66d397e,reason=SuccessfulCreate count=1 msg=Created pod: eval-sanitize-1-r2-048-7zqwg
60.3006,Event,ADDED,eval-sanitize-1-r2-049-5r5p5.18d41fbc02d1986f,"reason=FailedScheduling count=None msg=0/6 nodes are available: 1 c_wall violated: 1 conflicting context pair(s) with node memory, 5 node(s) had untolerated taint(s). no new claims to deallocate, preemption: 0/6 nodes are available: 1 No preemption victims found for incoming pod, 5 Preemption is not helpful for scheduling."
60.3008,Event,ADDED,eval-sanitize-1-r2-049-5r5p5.18d41fbc034e137b,"reason=FailedScheduling count=None msg=0/6 nodes are available: 1 c_wall violated: 1 conflicting context pair(s) with node memory, 5 node(s) had untolerated taint(s). no new claims to deallocate, preemption: 0/6 nodes are available: 1 No preemption victims found for incoming pod, 5 Preemption is not helpful for scheduling."
60.3015,Event,ADDED,eval-sanitize-1-r2-049-5r5p5.18d41fbd6ddcae2f,reason=Scheduled count=None msg=Successfully assigned compute/eval-sanitize-1-r2-049-5r5p5 to kind-worker5
60.3017,Event,ADDED,eval-sanitize-1-r2-049-5r5p5.18d41fbd886ed546,"reason=Pulled count=1 msg=Container image ""busybox:musl"" already present on machine"
60.3019,Event,ADDED,eval-sanitize-1-r2-049-5r5p5.18d41fbd89cfc1de,reason=Created count=1 msg=Created container: task
60.3022,Event,ADDED,eval-sanitize-1-r2-049-5r5p5.18d41fbd8bdd8376,reason=Started count=1 msg=Started container task
60.3023,Event,ADDED,eval-sanitize-1-r2-049.18d41fbc028919f4,reason=SuccessfulCreate count=1 msg=Created pod: eval-sanitize-1-r2-049-5r5p5
60.3025,Event,ADDED,eval-sanitize-1-r2-050-h7knl.18d41fbc3e4b5985,reason=Scheduled count=None msg=Successfully assigned compute/eval-sanitize-1-r2-050-h7knl to kind-worker2
60.3027,Event,ADDED,eval-sanitize-1-r2-050-h7knl.18d41fbc588a9efc,"reason=Pulled count=1 msg=Container image ""busybox:musl"" already present on machine"
60.3029,Event,ADDED,eval-sanitize-1-r2-050-h7knl.18d41fbc59bb7ed4,reason=Created count=1 msg=Created container: task
60.3031,Event,ADDED,eval-sanitize-1-r2-050-h7knl.18d41fbc5d3d3141,reason=Started count=1 msg=Started container task
60.3033,Event,ADDED,eval-sanitize-1-r2-050.18d41fbc3dc80899,reason=SuccessfulCreate count=1 msg=Created pod: eval-sanitize-1-r2-050-h7knl
60.3036,Event,ADDED,eval-sanitize-1-r2-051-w5xsq.18d41fbc797ca637,"reason=FailedScheduling count=None msg=0/6 nodes are available: 6 node(s) had untolerated taint(s). no new claims to deallocate, preemption: 0/6 nodes are available: 6 Preemption is not helpful for scheduling."
60.3038,Event,ADDED,eval-sanitize-1-r2-051-w5xsq.18d41fbd6dc32cf4,"reason=FailedScheduling count=None msg=0/6 nodes are available: 1 c_wall violated: 1 conflicting context pair(s) with node memory, 5 node(s) had untolerated taint(s). no new claims to deallocate, preemption: 0/6 nodes are available: 1 No preemption victims found for incoming pod, 5 Preemption is not helpful for scheduling."
60.304,Event,ADDED,eval-sanitize-1-r2-051-w5xsq.18d41fbd70b761b5,"reason=FailedScheduling count=None msg=0/6 nodes are available: 1 c_wall violated: 1 conflicting context pair(s) with node memory, 5 node(s) had untolerated taint(s). no new claims to deallocate, preemption: 0/6 nodes are available: 1 No preemption victims found for incoming pod, 5 Preemption is not helpful for scheduling."
60.3041,Event,ADDED,eval-sanitize-1-r2-051-w5xsq.18d41fbe1d63381b,reason=Scheduled count=None msg=Successfully assigned compute/eval-sanitize-1-r2-051-w5xsq to kind-worker
60.3044,Event,ADDED,eval-sanitize-1-r2-051-w5xsq.18d41fbe39e00037,"reason=Pulled count=1 msg=Container image ""busybox:musl"" already present on machine"
60.3046,Event,ADDED,eval-sanitize-1-r2-051-w5xsq.18d41fbe3c909b03,reason=Created count=1 msg=Created container: task
60.3048,Event,ADDED,eval-sanitize-1-r2-051-w5xsq.18d41fbe40244269,reason=Started count=1 msg=Started container task
60.305,Event,ADDED,eval-sanitize-1-r2-051.18d41fbc796f1ee2,reason=SuccessfulCreate count=1 msg=Created pod: eval-sanitize-1-r2-051-w5xsq
60.3051,Event,ADDED,eval-sanitize-1-r2-052-75fkh.18d41fbcb4cefbab,"reason=FailedScheduling count=None msg=0/6 nodes are available: 6 node(s) had untolerated taint(s). no new claims to deallocate, preemption: 0/6 nodes are available: 6 Preemption is not helpful for scheduling."
60.3053,Event,ADDED,eval-sanitize-1-r2-052-75fkh.18d41fbd6ecb2a05,reason=Scheduled count=None msg=Successfully assigned compute/eval-sanitize-1-r2-052-75fkh to kind-worker5
60.3055,Event,ADDED,eval-sanitize-1-r2-052-75fkh.18d41fbd89480076,"reason=Pulled count=1 msg=Container image ""busybox:musl"" already present on machine"
60.3057,Event,ADDED,eval-sanitize-1-r2-052-75fkh.18d41fbd8a888d7f,reason=Created count=1 msg=Created container: task
60.3058,Event,ADDED,eval-sanitize-1-r2-052-75fkh.18d41fbd8fe54726,reason=Started count=1 msg=Started container task
60.3061,Event,ADDED,eval-sanitize-1-r2-052.18d41fbcb4c5c217,reason=SuccessfulCreate count=1 msg=Created pod: eval-sanitize-1-r2-052-75fkh
60.3062,Event,ADDED,eval-sanitize-1-r2-053-srw2q.18d41fbcf09deef0,"reason=FailedScheduling count=None msg=0/6 nodes are available: 6 node(s) had untolerated taint(s). no new claims to deallocate, preemption: 0/6 nodes are available: 6 Preemption is not helpful for scheduling."
60.3064,Event,ADDED,eval-sanitize-1-r2-053-srw2q.18d41fbd6eaf2463,"reason=FailedScheduling count=None msg=0/6 nodes are available: 1 c_wall violated: 2 conflicting context pair(s) with node memory, 5 node(s) had untolerated taint(s). no new claims to deallocate, preemption: 0/6 nodes are available: 1 No preemption victims found for incoming pod, 5 Preemption is not helpful for scheduling."
60.3067,Event,ADDED,eval-sanitize-1-r2-053-srw2q.18d41fbd70e0e650,"reason=FailedScheduling count=None msg=0/6 nodes are available: 1 c_wall violated: 2 conflicting context pair(s) with node memory, 5 node(s) had untolerated taint(s). no new claims to deallocate, preemption: 0/6 nodes are available: 1 No preemption victims found for incoming pod, 5 Preemption is not helpful for scheduling."
60.3069,Event,ADDED,eval-sanitize-1-r2-053-srw2q.18d41fbe1d87f0fb,reason=Scheduled count=None msg=Successfully assigned compute/eval-sanitize-1-r2-053-srw2q to kind-worker
60.3071,Event,ADDED,eval-sanitize-1-r2-053-srw2q.18d41fbe397a6c91,"reason=Pulled count=1 msg=Container image ""busybox:musl"" already present on machine"
60.3074,Event,ADDED,eval-sanitize-1-r2-053-srw2q.18d41fbe3c314efd,reason=Created count=1 msg=Created container: task
60.3076,Event,ADDED,eval-sanitize-1-r2-053-srw2q.18d41fbe40244dfe,reason=Started count=1 msg=Started container task
60.3078,Event,ADDED,eval-sanitize-1-r2-053.18d41fbcf09340d6,reason=SuccessfulCreate count=1 msg=Created pod: eval-sanitize-1-r2-053-srw2q
60.3079,Event,ADDED,eval-sanitize-1-r2-054-gvn48.18d41fbd2c16cc53,"reason=FailedScheduling count=None msg=0/6 nodes are available: 6 node(s) had untolerated taint(s). no new claims to deallocate, preemption: 0/6 nodes are available: 6 Preemption is not helpful for scheduling."
60.3081,Event,ADDED,eval-sanitize-1-r2-054-gvn48.18d41fbd6f3f8d05,"reason=FailedScheduling count=None msg=0/6 nodes are available: 1 c_wall violated: 1 conflicting context pair(s) with node memory, 5 node(s) had untolerated taint(s). no new claims to deallocate, preemption: 0/6 nodes are available: 1 No preemption victims found for incoming pod, 5 Preemption is not helpful for scheduling."
60.3083,Event,ADDED,eval-sanitize-1-r2-054-gvn48.18d41fbd726cb994,"reason=FailedScheduling count=None msg=0/6 nodes are available: 1 c_wall violated: 1 conflicting context pair(s) with node memory, 5 node(s) had untolerated taint(s). no new claims to deallocate, preemption: 0/6 nodes are available: 1 No preemption victims found for incoming pod, 5 Preemption is not helpful for scheduling."
60.3085,Event,ADDED,eval-sanitize-1-r2-054-gvn48.18d41fbe1c90459d,reason=Scheduled count=None msg=Successfully assigned compute/eval-sanitize-1-r2-054-gvn48 to kind-worker
60.3087,Event,ADDED,eval-sanitize-1-r2-054-gvn48.18d41fbe37b59656,"reason=Pulled count=1 msg=Container image ""busybox:musl"" already present on machine"
60.3089,Event,ADDED,eval-sanitize-1-r2-054-gvn48.18d41fbe39427d27,reason=Created count=1 msg=Created container: task
60.3091,Event,ADDED,eval-sanitize-1-r2-054-gvn48.18d41fbe3f1f89da,reason=Started count=1 msg=Started container task
60.3092,Event,ADDED,eval-sanitize-1-r2-054.18d41fbd2c0d53fb,reason=SuccessfulCreate count=1 msg=Created pod: eval-sanitize-1-r2-054-gvn48
60.3095,Event,ADDED,eval-sanitize-1-r2-055-qtc8p.18d41fbd67ad24a4,"reason=FailedScheduling count=None msg=0/6 nodes are available: 6 node(s) had untolerated taint(s). no new claims to deallocate, preemption: 0/6 nodes are available: 6 Preemption is not helpful for scheduling."
60.3096,Event,ADDED,eval-sanitize-1-r2-055-qtc8p.18d41fbd6fd99483,"reason=FailedScheduling count=None msg=0/6 nodes are available: 1 c_wall violated: 1 conflicting context pair(s) with node memory, 5 node(s) had untolerated taint(s). no new claims to deallocate, preemption: 0/6 nodes are available: 1 No preemption victims found for incoming pod, 5 Preemption is not helpful for scheduling."
60.3098,Event,ADDED,eval-sanitize-1-r2-055-qtc8p.18d41fbd7468a923,"reason=FailedScheduling count=None msg=0/6 nodes are available: 1 c_wall violated: 1 conflicting context pair(s) with node memory, 5 node(s) had untolerated taint(s). no new claims to deallocate, preemption: 0/6 nodes are available: 1 No preemption victims found for incoming pod, 5 Preemption is not helpful for scheduling."
60.31,Event,ADDED,eval-sanitize-1-r2-055-qtc8p.18d41fbe1c47e4fb,"reason=FailedScheduling count=None msg=0/6 nodes are available: 1 c_wall violated: 1 conflicting context pair(s) with node memory, 5 node(s) had untolerated taint(s). no new claims to deallocate, preemption: 0/6 nodes are available: 1 No preemption victims found for incoming pod, 5 Preemption is not helpful for scheduling."
60.3102,Event,ADDED,eval-sanitize-1-r2-055-qtc8p.18d41fbe21353ef8,"reason=FailedScheduling count=None msg=0/6 nodes are available: 1 c_wall violated: 2 conflicting context pair(s) with node memory, 5 node(s) had untolerated taint(s). no new claims to deallocate, preemption: 0/6 nodes are available: 1 No preemption victims found for incoming pod, 5 Preemption is not helpful for scheduling."
60.3103,Event,ADDED,eval-sanitize-1-r2-055-qtc8p.18d41fbe21db270d,"reason=FailedScheduling count=None msg=0/6 nodes are available: 1 c_wall violated: 2 conflicting context pair(s) with node memory, 5 node(s) had untolerated taint(s). no new claims to deallocate, preemption: 0/6 nodes are available: 1 No preemption victims found for incoming pod, 5 Preemption is not helpful for scheduling."
60.3106,Event,ADDED,eval-sanitize-1-r2-055-qtc8p.18d41fbe39990c35,reason=Scheduled count=None msg=Successfully assigned compute/eval-sanitize-1-r2-055-qtc8p to kind-worker3
60.3108,Event,ADDED,eval-sanitize-1-r2-055-qtc8p.18d41fbe53f2a16b,"reason=Pulled count=1 msg=Container image ""busybox:musl"" already present on machine"
60.311,Event,ADDED,eval-sanitize-1-r2-055-qtc8p.18d41fbe552de325,reason=Created count=1 msg=Created container: task
60.3114,Event,ADDED,eval-sanitize-1-r2-055-qtc8p.18d41fbe599839c6,reason=Started count=1 msg=Started container task
60.3117,Event,ADDED,eval-sanitize-1-r2-055.18d41fbd67a21b0d,reason=SuccessfulCreate count=1 msg=Created pod: eval-sanitize-1-r2-055-qtc8p
60.3119,Event,ADDED,eval-sanitize-1-r2-056-j4csr.18d41fbda37fd9fe,"reason=FailedScheduling count=None msg=0/6 nodes are available: 1 c_wall violated: 1 conflicting context pair(s) with node memory, 5 node(s) had untolerated taint(s). no new claims to deallocate, preemption: 0/6 nodes are available: 1 No preemption victims found for incoming pod, 5 Preemption is not helpful for scheduling."
60.3123,Event,ADDED,eval-sanitize-1-r2-056-j4csr.18d41fbda3f76b8c,"reason=FailedScheduling count=None msg=0/6 nodes are available: 1 c_wall violated: 1 conflicting context pair(s) with node memory, 5 node(s) had untolerated taint(s). no new claims to deallocate, preemption: 0/6 nodes are available: 1 No preemption victims found for incoming pod, 5 Preemption is not helpful for scheduling."
60.3125,Event,ADDED,eval-sanitize-1-r2-056-j4csr.18d41fbe1c3488a1,reason=Scheduled count=None msg=Successfully assigned compute/eval-sanitize-1-r2-056-j4csr to kind-worker
60.3127,Event,ADDED,eval-sanitize-1-r2-056-j4csr.18d41fbe37ce6fd7,"reason=Pulled count=1 msg=Container image ""busybox:musl"" already present on machine"
60.3129,Event,ADDED,eval-sanitize-1-r2-056-j4csr.18d41fbe3a94b923,reason=Created count=1 msg=Created container: task
60.3133,Event,ADDED,eval-sanitize-1-r2-056-j4csr.18d41fbe4023cd4c,reason=Started count=1 msg=Started container task
60.3135,Event,ADDED,eval-sanitize-1-r2-056.18d41fbda34195a8,reason=SuccessfulCreate count=1 msg=Created pod: eval-sanitize-1-r2-056-j4csr
60.3137,Event,ADDED,eval-sanitize-1-r2-057-76m4m.18d41fbddf0a6ec6,"reason=FailedScheduling count=None msg=0/6 nodes are available: 6 node(s) had untolerated taint(s). no new claims to deallocate, preemption: 0/6 nodes are available: 6 Preemption is not helpful for scheduling."
60.3139,Event,ADDED,eval-sanitize-1-r2-057-76m4m.18d41fbe1dbc3a6e,reason=Scheduled count=None msg=Successfully assigned compute/eval-sanitize-1-r2-057-76m4m to kind-worker
60.3142,Event,ADDED,eval-sanitize-1-r2-057-76m4m.18d41fbe39a60e80,"reason=Pulled count=1 msg=Container image ""busybox:musl"" already present on machine"
60.3144,Event,ADDED,eval-sanitize-1-r2-057-76m4m.18d41fbe3cb40f02,reason=Created count=1 msg=Created container: task
60.3146,Event,ADDED,eval-sanitize-1-r2-057-76m4m.18d41fbe4023ccc4,reason=Started count=1 msg=Started container task
60.3149,Event,ADDED,eval-sanitize-1-r2-057.18d41fbddeffc3db,reason=SuccessfulCreate count=1 msg=Created pod: eval-sanitize-1-r2-057-76m4m
60.3151,Event,ADDED,eval-sanitize-1-r2-058-l8skl.18d41fbe1a837ca4,"reason=FailedScheduling count=None msg=0/6 nodes are available: 6 node(s) had untolerated taint(s). no new claims to deallocate, preemption: 0/6 nodes are available: 6 Preemption is not helpful for scheduling."
60.3152,Event,ADDED,eval-sanitize-1-r2-058-l8skl.18d41fbe1d8cc3f6,"reason=FailedScheduling count=None msg=0/6 nodes are available: 1 c_wall violated: 2 conflicting context pair(s) with node memory, 5 node(s) had untolerated taint(s). no new claims to deallocate, preemption: 0/6 nodes are available: 1 No preemption victims found for incoming pod, 5 Preemption is not helpful for scheduling."
60.3155,Event,ADDED,eval-sanitize-1-r2-058-l8skl.18d41fbe21b0aa8e,"reason=FailedScheduling count=None msg=0/6 nodes are available: 1 c_wall violated: 2 conflicting context pair(s) with node memory, 5 node(s) had untolerated taint(s). no new claims to deallocate, preemption: 0/6 nodes are available: 1 No preemption victims found for incoming pod, 5 Preemption is not helpful for scheduling."
60.3158,Event,ADDED,eval-sanitize-1-r2-058-l8skl.18d41fbe3acb03f6,"reason=FailedScheduling count=None msg=0/6 nodes are available: 1 c_wall violated: 1 conflicting context pair(s) with node memory, 1 c_wall violated: 2 conflicting context pair(s) with node memory, 4 node(s) had untolerated taint(s). no new claims to deallocate, preemption: 0/6 nodes are available: 2 No preemption victims found for incoming pod, 4 Preemption is not helpful for scheduling."
60.316,Event,ADDED,eval-sanitize-1-r2-058-l8skl.18d41fbe6125ec2b,"reason=FailedScheduling count=None msg=0/6 nodes are available: 1 c_wall violated: 1 conflicting context pair(s) with node memory, 5 node(s) had untolerated taint(s). no new claims to deallocate, preemption: 0/6 nodes are available: 1 No preemption victims found for incoming pod, 5 Preemption is not helpful for scheduling."
60.3162,Event,ADDED,eval-sanitize-1-r2-058.18d41fbe1a7608a0,reason=SuccessfulCreate count=1 msg=Created pod: eval-sanitize-1-r2-058-l8skl
60.3165,Event,ADDED,eval-sanitize-1-r2-059-fpnp6.18d41fbe56f8f288,reason=Scheduled count=None msg=Successfully assigned compute/eval-sanitize-1-r2-059-fpnp6 to kind-worker3
60.3167,Event,ADDED,eval-sanitize-1-r2-059-fpnp6.18d41fbe716f97e1,"reason=Pulled count=1 msg=Container image ""busybox:musl"" already present on machine"
60.3169,Event,ADDED,eval-sanitize-1-r2-059-fpnp6.18d41fbe72970b20,reason=Created count=1 msg=Created container: task
60.3171,Event,ADDED,eval-sanitize-1-r2-059-fpnp6.18d41fbe75f597f5,reason=Started count=1 msg=Started container task
60.3172,Event,ADDED,eval-sanitize-1-r2-059.18d41fbe5637b27b,reason=SuccessfulCreate count=1 msg=Created pod: eval-sanitize-1-r2-059-fpnp6
60.3177,Event,ADDED,eval-sanitize-1-r2-060.18d41fbe91c8262b,reason=SuccessfulCreate count=1 msg=Created pod: eval-sanitize-1-r2-060-6ckxn
60.318,Event,ADDED,eval-sanitize-1-r2-060-6ckxn.18d41fbe91d30718,"reason=FailedScheduling count=None msg=0/6 nodes are available: 6 node(s) had untolerated taint(s). no new claims to deallocate, preemption: 0/6 nodes are available: 6 Preemption is not helpful for scheduling."
60.7367,Node,MODIFIED,kind-worker4,taints=1
60.7521,Node,MODIFIED,kind-worker4,taints=0
60.7586,Pod,MODIFIED,eval-sanitize-1-r2-058-l8skl,phase=Pending node=kind-worker4
60.7614,Pod,MODIFIED,eval-sanitize-1-r2-060-6ckxn,phase=Pending node=None
60.7632,Node,MODIFIED,kind-worker4,taints=0
60.7648,Event,ADDED,eval-sanitize-1-r2-058-l8skl.18d41fbebccec2ee,reason=Scheduled count=None msg=Successfully assigned compute/eval-sanitize-1-r2-058-l8skl to kind-worker4
60.7655,Event,ADDED,eval-sanitize-1-r2-060-6ckxn.18d41fbebcb08e13,"reason=FailedScheduling count=None msg=0/6 nodes are available: 1 c_wall violated: 1 conflicting context pair(s) with node memory, 5 node(s) had untolerated taint(s). no new claims to deallocate, preemption: 0/6 nodes are available: 1 No preemption victims found for incoming pod, 5 Preemption is not helpful for scheduling."
60.7717,Pod,MODIFIED,eval-sanitize-1-r2-058-l8skl,phase=Pending node=kind-worker4
60.772,Event,MODIFIED,eval-sanitize-1-r2-060-6ckxn.18d41fbebcb08e13,"reason=FailedScheduling count=None msg=0/6 nodes are available: 1 c_wall violated: 1 conflicting context pair(s) with node memory, 5 node(s) had untolerated taint(s). no new claims to deallocate, preemption: 0/6 nodes are available: 1 No preemption victims found for incoming pod, 5 Preemption is not helpful for scheduling."
60.7759,Event,ADDED,eval-sanitize-1-r2-060-6ckxn.18d41fbebdb6cb9f,"reason=FailedScheduling count=None msg=0/6 nodes are available: 1 c_wall violated: 1 conflicting context pair(s) with node memory, 5 node(s) had untolerated taint(s). no new claims to deallocate, preemption: 0/6 nodes are available: 1 No preemption victims found for incoming pod, 5 Preemption is not helpful for scheduling."
60.7855,Node,MODIFIED,kind-worker4,taints=0
60.8299,Node,MODIFIED,kind-worker4,taints=0
60.845,Node,MODIFIED,kind-worker4,taints=0
60.9105,Job,MODIFIED,eval-sanitize-1-r2-045,
60.9127,Job,MODIFIED,eval-sanitize-1-r2-048,
60.9135,Job,MODIFIED,eval-sanitize-1-r2-047,
60.9156,Job,MODIFIED,eval-sanitize-1-r2-041,
60.9167,Job,MODIFIED,eval-sanitize-1-r2-045,
60.9178,Job,MODIFIED,eval-sanitize-1-r2-047,
60.9207,Job,MODIFIED,eval-sanitize-1-r2-041,
60.9258,Pod,MODIFIED,eval-sanitize-1-r2-048-7zqwg,phase=Succeeded node=kind-worker4
60.9266,Job,MODIFIED,eval-sanitize-1-r2-048,
60.9282,Job,MODIFIED,eval-sanitize-1-r2-047,
60.9285,Event,ADDED,eval-sanitize-1-r2-045.18d41fbec6472185,reason=Completed count=1 msg=Job completed
60.932,Job,MODIFIED,eval-sanitize-1-r2-045,
60.9334,Event,ADDED,eval-sanitize-1-r2-047.18d41fbec65f7e21,reason=Completed count=1 msg=Job completed
60.9343,Job,MODIFIED,eval-sanitize-1-r2-041,
60.9353,TaskRequest,MODIFIED,eval-sanitize-1-r2-047,phase=Complete job=None
60.9366,Event,ADDED,eval-sanitize-1-r2-041.18d41fbec68f9aae,reason=Completed count=1 msg=Job completed
60.9392,TaskRequest,MODIFIED,eval-sanitize-1-r2-045,phase=Complete job=None
60.9443,TaskRequest,MODIFIED,eval-sanitize-1-r2-041,phase=Complete job=None
60.9471,Job,MODIFIED,eval-sanitize-1-r2-047,
60.9487,Job,MODIFIED,eval-sanitize-1-r2-045,
61.0051,Job,MODIFIED,eval-sanitize-1-r2-041,
61.0061,TaskRequest,ADDED,eval-sanitize-1-r2-061,phase=None job=None
61.0093,TaskRequest,MODIFIED,eval-sanitize-1-r2-061,phase=Pending job=None
61.0234,Job,ADDED,eval-sanitize-1-r2-061,
61.0277,TaskRequest,MODIFIED,eval-sanitize-1-r2-061,phase=Scheduled job=None
61.0305,Pod,ADDED,eval-sanitize-1-r2-061-jwl5f,phase=Pending node=None
61.0342,Job,MODIFIED,eval-sanitize-1-r2-061,
61.0356,Event,ADDED,eval-sanitize-1-r2-061.18d41fbecd24326b,reason=SuccessfulCreate count=1 msg=Created pod: eval-sanitize-1-r2-061-jwl5f
61.0375,TaskRequest,MODIFIED,eval-sanitize-1-r2-061,phase=Scheduled job=None
61.0403,Pod,MODIFIED,eval-sanitize-1-r2-061-jwl5f,phase=Pending node=kind-worker4
61.0411,Job,MODIFIED,eval-sanitize-1-r2-060,
61.0444,Event,ADDED,eval-sanitize-1-r2-061-jwl5f.18d41fbecdb66236,reason=Scheduled count=None msg=Successfully assigned compute/eval-sanitize-1-r2-061-jwl5f to kind-worker4
61.0493,Pod,MODIFIED,eval-sanitize-1-r2-060-6ckxn,phase=Pending node=None
61.0515,Pod,MODIFIED,eval-sanitize-1-r2-061-jwl5f,phase=Pending node=kind-worker4
61.0525,Job,MODIFIED,eval-sanitize-1-r2-060,
61.0538,Node,MODIFIED,kind-worker4,taints=0
61.0545,Job,MODIFIED,eval-sanitize-1-r2-059,
61.0568,Event,ADDED,eval-sanitize-1-r2-060-6ckxn.18d41fbece75b5f5,"reason=FailedScheduling count=None msg=0/6 nodes are available: 1 c_wall violated: 2 conflicting context pair(s) with node memory, 5 node(s) had untolerated taint(s). no new claims to deallocate, preemption: 0/6 nodes are available: 1 No preemption victims found for incoming pod, 5 Preemption is not helpful for scheduling."
61.0627,Node,MODIFIED,kind-worker4,taints=0
61.063,Event,MODIFIED,eval-sanitize-1-r2-060-6ckxn.18d41fbece75b5f5,"reason=FailedScheduling count=None msg=0/6 nodes are available: 1 c_wall violated: 2 conflicting context pair(s) with node memory, 5 node(s) had untolerated taint(s). no new claims to deallocate, preemption: 0/6 nodes are available: 1 No preemption victims found for incoming pod, 5 Preemption is not helpful for scheduling."
61.0638,Job,MODIFIED,eval-sanitize-1-r2-059,
61.1964,Event,ADDED,eval-sanitize-1-r2-058-l8skl.18d41fbed6a785bf,"reason=Pulled count=1 msg=Container image ""busybox:musl"" already present on machine"
61.2112,Event,ADDED,eval-sanitize-1-r2-058-l8skl.18d41fbed7b2e07d,reason=Created count=1 msg=Created container: task
61.2469,Pod,MODIFIED,eval-sanitize-1-r2-050-h7knl,phase=Running node=kind-worker2
61.248,Job,MODIFIED,eval-sanitize-1-r2-046,
61.2576,Job,MODIFIED,eval-sanitize-1-r2-046,
61.2903,Event,ADDED,eval-sanitize-1-r2-058-l8skl.18d41fbedc57be51,reason=Started count=1 msg=Started container task
61.3527,Pod,MODIFIED,eval-sanitize-1-r2-046-9tgn4,phase=Succeeded node=kind-worker2
61.5108,Event,ADDED,eval-sanitize-1-r2-061-jwl5f.18d41fbee97142d2,"reason=Pulled count=1 msg=Container image ""busybox:musl"" already present on machine"
61.5278,Event,ADDED,eval-sanitize-1-r2-061-jwl5f.18d41fbeea8fb95a,reason=Created count=1 msg=Created container: task
61.5625,Event,ADDED,eval-sanitize-1-r2-061-jwl5f.18d41fbeec992a82,reason=Started count=1 msg=Started container task
61.8383,Node,MODIFIED,kind-worker4,taints=1
61.8436,Pod,MODIFIED,eval-sanitize-1-r2-060-6ckxn,phase=Pending node=None
61.8508,Node,MODIFIED,kind-worker4,taints=1
61.8999,Pod,MODIFIED,eval-sanitize-1-r2-058-l8skl,phase=Running node=kind-worker4
61.906,Pod,MODIFIED,eval-sanitize-1-r2-061-jwl5f,phase=Running node=kind-worker4
61.9187,Job,MODIFIED,eval-sanitize-1-r2-048,
61.9232,Job,MODIFIED,eval-sanitize-1-r2-048,
61.9257,Event,ADDED,eval-sanitize-1-r2-048.18d41fbf024e3a47,reason=Completed count=1 msg=Job completed
61.9345,Job,MODIFIED,eval-sanitize-1-r2-048,
61.9399,TaskRequest,MODIFIED,eval-sanitize-1-r2-048,phase=Complete job=None
61.949,Job,MODIFIED,eval-sanitize-1-r2-048,
62.0077,TaskRequest,ADDED,eval-sanitize-1-r2-062,phase=None job=None
62.0126,TaskRequest,MODIFIED,eval-sanitize-1-r2-062,phase=Pending job=None
62.0276,Job,ADDED,eval-sanitize-1-r2-062,
62.0319,TaskRequest,MODIFIED,eval-sanitize-1-r2-062,phase=Scheduled job=None
62.0356,Pod,ADDED,eval-sanitize-1-r2-062-j5hlr,phase=Pending node=None
62.0372,Job,MODIFIED,eval-sanitize-1-r2-061,
62.0378,Job,MODIFIED,eval-sanitize-1-r2-062,
62.0494,Event,ADDED,eval-sanitize-1-r2-062.18d41fbf08fd15a8,reason=SuccessfulCreate count=1 msg=Created pod: eval-sanitize-1-r2-062-j5hlr
62.0497,Event,ADDED,eval-sanitize-1-r2-062-j5hlr.18d41fbf090af734,"reason=FailedScheduling count=None msg=0/6 nodes are available: 6 node(s) had untolerated taint(s). no new claims to deallocate, preemption: 0/6 nodes are available: 6 Preemption is not helpful for scheduling."
62.0498,TaskRequest,MODIFIED,eval-sanitize-1-r2-062,phase=Scheduled job=None
62.0507,Pod,MODIFIED,eval-sanitize-1-r2-062-j5hlr,phase=Pending node=None
62.0517,Job,MODIFIED,eval-sanitize-1-r2-061,
62.2545,Job,MODIFIED,eval-sanitize-1-r2-050,
62.2565,Job,MODIFIED,eval-sanitize-1-r2-046,
62.2668,Job,MODIFIED,eval-sanitize-1-r2-050,
62.2701,Job,MODIFIED,eval-sanitize-1-r2-046,
62.272,Pod,MODIFIED,eval-sanitize-1-r2-046-9tgn4,phase=Succeeded node=kind-worker2
62.4298,Pod,MODIFIED,eval-sanitize-1-r2-050-h7knl,phase=Succeeded node=kind-worker2
62.5335,Node,MODIFIED,kind-worker2,taints=1
62.5476,Node,MODIFIED,kind-worker2,taints=0
62.5534,Pod,MODIFIED,eval-sanitize-1-r2-060-6ckxn,phase=Pending node=kind-worker2
62.5561,Pod,MODIFIED,eval-sanitize-1-r2-062-j5hlr,phase=Pending node=None
62.5598,Event,ADDED,eval-sanitize-1-r2-062-j5hlr.18d41fbf27c595f2,"reason=FailedScheduling count=None msg=0/6 nodes are available: 1 c_wall violated: 1 conflicting context pair(s) with node memory, 5 node(s) had untolerated taint(s). no new claims to deallocate, preemption: 0/6 nodes are available: 1 No preemption victims found for incoming pod, 5 Preemption is not helpful for scheduling."
62.5601,Event,ADDED,eval-sanitize-1-r2-060-6ckxn.18d41fbf27e07ff7,reason=Scheduled count=None msg=Successfully assigned compute/eval-sanitize-1-r2-060-6ckxn to kind-worker2
62.5616,Node,MODIFIED,kind-worker2,taints=0
62.5658,Event,MODIFIED,eval-sanitize-1-r2-062-j5hlr.18d41fbf27c595f2,"reason=FailedScheduling count=None msg=0/6 nodes are available: 1 c_wall violated: 1 conflicting context pair(s) with node memory, 5 node(s) had untolerated taint(s). no new claims to deallocate, preemption: 0/6 nodes are available: 1 No preemption victims found for incoming pod, 5 Preemption is not helpful for scheduling."
62.5671,Pod,MODIFIED,eval-sanitize-1-r2-060-6ckxn,phase=Pending node=kind-worker2
62.5712,Event,ADDED,eval-sanitize-1-r2-062-j5hlr.18d41fbf28bfa3c2,"reason=FailedScheduling count=None msg=0/6 nodes are available: 1 c_wall violated: 1 conflicting context pair(s) with node memory, 5 node(s) had untolerated taint(s). no new claims to deallocate, preemption: 0/6 nodes are available: 1 No preemption victims found for incoming pod, 5 Preemption is not helpful for scheduling."
62.5764,Event,MODIFIED,eval-sanitize-1-r2-062-j5hlr.18d41fbf28bfa3c2,"reason=FailedScheduling count=None msg=0/6 nodes are available: 1 c_wall violated: 1 conflicting context pair(s) with node memory, 5 node(s) had untolerated taint(s). no new claims to deallocate, preemption: 0/6 nodes are available: 1 No preemption victims found for incoming pod, 5 Preemption is not helpful for scheduling."
62.586,Node,MODIFIED,kind-worker2,taints=0
62.6308,Node,MODIFIED,kind-worker2,taints=0
62.6447,Node,MODIFIED,kind-worker2,taints=0
62.9054,Job,MODIFIED,eval-sanitize-1-r2-058,
62.9139,Job,MODIFIED,eval-sanitize-1-r2-058,
62.977,Event,ADDED,eval-sanitize-1-r2-060-6ckxn.18d41fbf40e6a414,"reason=Pulled count=1 msg=Container image ""busybox:musl"" already present on machine"
62.994,Event,ADDED,eval-sanitize-1-r2-060-6ckxn.18d41fbf41f8302c,reason=Created count=1 msg=Created container: task
63.0066,TaskRequest,ADDED,eval-sanitize-1-r2-063,phase=None job=None
63.0119,TaskRequest,MODIFIED,eval-sanitize-1-r2-063,phase=Pending job=None
63.0261,Event,ADDED,eval-sanitize-1-r2-060-6ckxn.18d41fbf43d60461,reason=Started count=1 msg=Started container task
63.0284,Job,ADDED,eval-sanitize-1-r2-063,
63.0315,TaskRequest,MODIFIED,eval-sanitize-1-r2-063,phase=Scheduled job=None
63.0347,Pod,ADDED,eval-sanitize-1-r2-063-lrx2f,phase=Pending node=None
63.0378,Job,MODIFIED,eval-sanitize-1-r2-063,
63.0397,Event,ADDED,eval-sanitize-1-r2-063.18d41fbf4498555d,reason=SuccessfulCreate count=1 msg=Created pod: eval-sanitize-1-r2-063-lrx2f
63.0398,TaskRequest,MODIFIED,eval-sanitize-1-r2-063,phase=Scheduled job=None
63.0405,Job,MODIFIED,eval-sanitize-1-r2-062,
63.0438,Pod,MODIFIED,eval-sanitize-1-r2-063-lrx2f,phase=Pending node=None
63.0441,Event,ADDED,eval-sanitize-1-r2-063-lrx2f.18d41fbf44d76d1b,"reason=FailedScheduling count=None msg=0/6 nodes are available: 1 c_wall violated: 1 conflicting context pair(s) with node memory, 5 node(s) had untolerated taint(s). no new claims to deallocate, preemption: 0/6 nodes are available: 1 No preemption victims found for incoming pod, 5 Preemption is not helpful for scheduling."
63.0496,Job,MODIFIED,eval-sanitize-1-r2-062,
63.0515,Event,ADDED,eval-sanitize-1-r2-063-lrx2f.18d41fbf455a10c2,"reason=FailedScheduling count=None msg=0/6 nodes are available: 1 c_wall violated: 1 conflicting context pair(s) with node memory, 5 node(s) had untolerated taint(s). no new claims to deallocate, preemption: 0/6 nodes are available: 1 No preemption victims found for incoming pod, 5 Preemption is not helpful for scheduling."
63.2609,Pod,MODIFIED,eval-sanitize-1-r2-060-6ckxn,phase=Running node=kind-worker2
63.2622,Job,MODIFIED,eval-sanitize-1-r2-050,
63.2632,Job,MODIFIED,eval-sanitize-1-r2-046,
63.2666,Job,MODIFIED,eval-sanitize-1-r2-046,
63.2706,Pod,MODIFIED,eval-sanitize-1-r2-050-h7knl,phase=Succeeded node=kind-worker2
63.2711,Event,ADDED,eval-sanitize-1-r2-046.18d41fbf52672f44,reason=Completed count=1 msg=Job completed
63.2736,Job,MODIFIED,eval-sanitize-1-r2-050,
63.2751,Event,MODIFIED,eval-sanitize-1-r2-063-lrx2f.18d41fbf455a10c2,"reason=FailedScheduling count=None msg=0/6 nodes are available: 1 c_wall violated: 1 conflicting context pair(s) with node memory, 5 node(s) had untolerated taint(s). no new claims to deallocate, preemption: 0/6 nodes are available: 1 No preemption victims found for incoming pod, 5 Preemption is not helpful for scheduling."
63.2762,Job,MODIFIED,eval-sanitize-1-r2-046,
63.2811,TaskRequest,MODIFIED,eval-sanitize-1-r2-046,phase=Complete job=None
63.2929,Job,MODIFIED,eval-sanitize-1-r2-046,
63.5595,Job,MODIFIED,eval-sanitize-1-r2-060,
63.5682,Job,MODIFIED,eval-sanitize-1-r2-060,
63.5709,Node,MODIFIED,kind-worker2,taints=1
63.5759,Pod,MODIFIED,eval-sanitize-1-r2-062-j5hlr,phase=Pending node=None
